Workbook

Sheet BOM
A1: ROW | B1: Наименование1 | C1: Тип матер. | D1: Артикул | E1: Номенклатура | F1: Цена лист | G1: Цена нетто KZT | H1: Сумма KZT | I1: Qty | J1: Ед.изм. | K1: Завод | L1: malz(тутар) | M1: мал.группа
B2: =E2 -> ВРУ1-13-20 УХЛ4 — Вводная панель (2 ввода 315А, без счетчик) | E2: ВРУ1-13-20 УХЛ4 — Вводная панель (2 ввода 315А, без счетчик) | F2: =2.3*H20 -> 681152.85 | G2: =0.7*F2 -> 476806.99 | I2: 1 | J2: комплект
A3: 1 | C3: korpus | D3: 719-15043 | E3: Мет. Щит ВРУ 1700х800х450+10CM База | F3: 155000 | G3: =0.6*F3 -> 93000 | H3: =G3*I3 -> 93000 | I3: 1 | J3: шт | K3: kaztek | L3: =H3 -> 93000 | M3: Ввод
A4: 2 | C4: rubilnik | D4: 270100161_ | E4: Рубильник ВР-32-37 В71250-400А на 2 направления (+6камер) UNIT (1/6) | F4: 21950 | G4: =F4 -> 21950 | H4: =G4*I4 -> 21950 | I4: 1 | J4: шт | K4: pys | L4: =H4 -> 21950 | M4: Ввод
A5: 3 | C5: fu | D5: 521368 | E5: Держатель плавкой вставки RT36-2-400, габарит 2, 400А — замена основания ППН-37 (2 ввода x 3 фазы) | F5: 7443 | G5: =F5*INDEX(Kurallar!$B$16:$B$26,MATCH(K5,Kurallar!$A$16:$A$26,0)) -> 4465.8 | H5: =G5*I5 -> 26794.8 | I5: 6 | J5: шт | K5: CHINT | L5: =H5 -> 26794.8 | M5: Ввод
A6: 4 | C6: fu | D6: 521215 | E6: Плавкая вставка предохранителя RT36-2-400, габарит 2, 315А — замена ППН-37 315А (2 ввода x 3 фазы) | F6: 4969 | G6: =F6*INDEX(Kurallar!$B$16:$B$26,MATCH(K6,Kurallar!$A$16:$A$26,0)) -> 2981.4 | H6: =G6*I6 -> 17888.4 | I6: 6 | J6: шт | K6: CHINT | L6: =H6 -> 17888.4 | M6: Ввод
A7: 5 | C7: sayac | D7: IA | E7: ДАЛА СА4У-Э720 R TX OP П RS1 Д W (3x220/380V 5-7,5A) | F7: 88000 | G7: =F7*INDEX(Kurallar!$B$16:$B$26,MATCH(K7,Kurallar!$A$16:$A$26,0)) -> 88000 | H7: =G7*I7 -> 0 | I7: 0 | J7: шт | K7: SAIMAN | L7: =H7 -> 0 | M7: Учет
A8: 6 | C8: tt | D8: VP | E8: Трансформатор тока ТШП-0,66 У3, кл.точн. 0,5, 300/5А — замена ТК-300/5 (3 шт на счетчик) | F8: 6000 | G8: =F8 -> 6000 | H8: =G8*I8 -> 36000 | I8: 6 | J8: шт | K8: pys | L8: =H8 -> 36000 | M8: Учет
A9: 7 | C9: OTO | D9: 814014 | E9: Авт. выкл. NXB-63 1P 16A 6кА х-ка C — замена АЕ1031 (цепь освещения/сервиса панели) | F9: 1389 | G9: =F9*INDEX(Kurallar!$B$16:$B$26,MATCH(K9,Kurallar!$A$16:$A$26,0)) -> 833.4 | H9: =G9*I9 -> 1666.8 | I9: 2 | J9: шт | K9: CHINT | L9: =H9 -> 1666.8 | M9: Ввод
A10: 8 | C10: Sinyal Lambası | D10: 593075 | E10: Индикатор ND16-22D/2 красный AC/DC 230В — замена НВ2У (сигнализация ввода) | F10: 571 | G10: =F10*INDEX(Kurallar!$B$16:$B$26,MATCH(K10,Kurallar!$A$16:$A$26,0)) -> 342.6 | H10: =G10*I10 -> 685.2 | I10: 2 | J10: шт | K10: CHINT | L10: =H10 -> 685.2 | M10: Ввод
A11: 9 | C11: LOOBAR | D11: 130200153_ | E11: Шина алюм АД31Т 4х40х4000 | F11: 1297 | G11: =F11*INDEX(Kurallar!$B$16:$B$26,MATCH(K11,Kurallar!$A$16:$A$26,0)) -> 1297 | H11: =G11*I11 -> 10376 | I11: 8 | J11: м | K11: EKT | L11: =H11 -> 10376 | M11: Бара
A12: 10 | C12: LOOBAR | D12: 130300473_ | E12: Шина медн.3х20х4000 | F12: 5538 | G12: =F12*INDEX(Kurallar!$B$16:$B$26,MATCH(K12,Kurallar!$A$16:$A$26,0)) -> 5538 | H12: =G12*I12 -> 8307 | I12: 1.5 | J12: м | K12: EKT | L12: =H12 -> 8307 | M12: Бара
A13: 11 | C13: LOOBAR | D13: 130500106_ | E13: Изолятор SM40 с болтом М8, 475А, 12кВ UNIT — опоры шин | F13: 324 | G13: =F13*INDEX(Kurallar!$B$16:$B$26,MATCH(K13,Kurallar!$A$16:$A$26,0)) -> 324 | H13: =G13*I13 -> 1296 | I13: 4 | J13: шт | K13: IEK/UNIT | L13: =H13 -> 1296 | M13: Бара
A14: 12 | C14: Klemens | D14: 130301157_ | E14: Клемма ЗНИ 16 мм² (100А) серая UNIT — цепи учета, управления, сигнализации | F14: 235 | G14: =F14*INDEX(Kurallar!$B$16:$B$26,MATCH(K14,Kurallar!$A$16:$A$26,0)) -> 235 | H14: =G14*I14 -> 2820 | I14: 12 | J14: шт | K14: IEK/UNIT | L14: =H14 -> 2820 | M14: Клемма
A15: 13 | C15: Klemens | D15: 130301156_ | E15: Клемма ЗНИ 10 мм² (70А) синяя UNIT — нулевые цепи учета | F15: 144 | G15: =F15*INDEX(Kurallar!$B$16:$B$26,MATCH(K15,Kurallar!$A$16:$A$26,0)) -> 144 | H15: =G15*I15 -> 864 | I15: 6 | J15: шт | K15: IEK/UNIT | L15: =H15 -> 864 | M15: Клемма
A16: 14 | C16: montajный материал | D16: 570003 | E16: DIN-рейка оцинкованная TH35-7.5, 1000 мм | F16: 869 | G16: =F16*INDEX(Kurallar!$B$16:$B$26,MATCH(K16,Kurallar!$A$16:$A$26,0)) -> 521.4 | H16: =G16*I16 -> 1564.2 | I16: 3 | J16: м | K16: CHINT | L16: =H16 -> 1564.2 | M16: Монтаж
A17: 15 | C17: montajный материал | D17: 280100020_ | E17: Кабель-канал перфорированный 40х40 ИМПАКТ IEK | F17: 1486 | G17: =F17*INDEX(Kurallar!$B$16:$B$26,MATCH(K17,Kurallar!$A$16:$A$26,0)) -> 1486 | H17: =G17*I17 -> 11888 | I17: 8 | J17: м | K17: IEK/UNIT | L17: =H17 -> 11888 | M17: Монтаж
A18: 16 | C18: montajный материал | E18: Монтажные материалы: крепеж, шпильки, наконечники ТМЛ/НШВИ, провод ПВ3, бирки/маркировка, стяжки, лак, изолента — %% от материала панели | G18: =SUM(H3:H17)*Kurallar!$B$10 -> 7053.012 | H18: =G18*I18 -> 7053.012 | I18: 1 | J18: шт | L18: =H18 -> 7053.012
A19: 17 | C19: montajная работа | E19: Сборка, монтаж, шинный монтаж, маркировка, испытание и контроль (по нормам времени, лист Kurallar) | F19: 9 | G19: =Kurallar!$B$11 -> 100 | H19: =G19*I19 -> 54000 | I19: =60*F19 -> 540 | J19: мин | M19: işçilik
B20: Toplam ВРУ1-13-20 УХЛ4 — Вводная панель (2 ввода 315А, учет, ПЦ) | H20: =SUBTOTAL(9,H3:H19) -> 296153.41 | L20: =SUBTOTAL(9,L3:L19) -> 242153.41
B21: =E21 -> ВРУ1-47-00 УХЛ4 — Распределительная панель без счетчик (8 линий: C1-C4, C6-C9) | E21: ВРУ1-47-00 УХЛ4 — Распределительная панель без счетчик (8 линий: C1-C4, C6-C9) | F21: =2.3*H40 -> 454492.78 | G21: =0.7*F21 -> 318144.95 | I21: 1 | J21: комплект
A22: 18 | C22: korpus | D22: 719-156 | E22: Мет. Щит Пустой (1700x710x350)+10см база IP31 | F22: 140000 | G22: =0.6*F22 -> 84000 | H22: =G22*I22 -> 84000 | I22: 1 | J22: шт | K22: EKT | L22: =H22 -> 84000 | M22: Распред
A23: 19 | C23: fu | D23: 521260 | E23: Держатель плавкой вставки RT36-00-160, габарит 00, 160А | F23: 2038 | G23: =F23*INDEX(Kurallar!$B$16:$B$26,MATCH(K23,Kurallar!$A$16:$A$26,0)) -> 1222.8 | H23: =G23*I23 -> 22010.4 | I23: 18 | J23: шт | K23: CHINT | L23: =H23 -> 22010.4 | M23: Распред
A24: 20 | C24: fu | D24: 521236 | E24: Плавкая вставка предохранителя RT36-0-160, габарит 0, 160А | F24: 2225 | G24: =F24*INDEX(Kurallar!$B$16:$B$26,MATCH(K24,Kurallar!$A$16:$A$26,0)) -> 1335 | H24: =G24*I24 -> 8010 | I24: 6 | J24: шт | K24: CHINT | L24: =H24 -> 8010 | M24: C1,C7
A25: 21 | C25: fu | D25: 521234 | E25: Плавкая вставка предохранителя RT36-0-160, габарит 0, 125А | F25: 2225 | G25: =F25*INDEX(Kurallar!$B$16:$B$26,MATCH(K25,Kurallar!$A$16:$A$26,0)) -> 1335 | H25: =G25*I25 -> 8010 | I25: 6 | J25: шт | K25: CHINT | L25: =H25 -> 8010 | M25: C2,C8
A26: 22 | C26: fu | D26: 521232 | E26: Плавкая вставка предохранителя RT36-0-160, габарит 0, 100А | F26: 2210 | G26: =F26*INDEX(Kurallar!$B$16:$B$26,MATCH(K26,Kurallar!$A$16:$A$26,0)) -> 1326 | H26: =G26*I26 -> 7956 | I26: 6 | J26: шт | K26: CHINT | L26: =H26 -> 7956 | M26: C3,C6
A27: 23 | C27: fu | D27: 521260 | E27: Держатель плавкой вставки RT36-00-160, габарит 00, 160А — замена основания ППН-33 (2 линии x 3 фазы) | F27: 2038 | G27: =F27*INDEX(Kurallar!$B$16:$B$26,MATCH(K27,Kurallar!$A$16:$A$26,0)) -> 1222.8 | H27: =G27*I27 -> 7336.8 | I27: 6 | J27: шт | K27: CHINT | L27: =H27 -> 7336.8 | M27: C4,C9
A28: 24 | C28: fu | D28: 521339 | E28: Плавкая вставка RT36-00-160, габарит 00, 20А — ППН-33 20А, линии C4 и C9 (2 x 3 фазы) | F28: 1545 | G28: =F28*INDEX(Kurallar!$B$16:$B$26,MATCH(K28,Kurallar!$A$16:$A$26,0)) -> 927 | H28: =G28*I28 -> 5562 | I28: 6 | J28: шт | K28: CHINT | L28: =H28 -> 5562 | M28: C4,C9
A29: 5 | C29: sayac | D29: NC | E29: Дала TX П СА4-Э720 (3x220/380V 5-60A) | F29: 36900 | G29: =F29*INDEX(Kurallar!$B$16:$B$26,MATCH(K29,Kurallar!$A$16:$A$26,0)) -> 36900 | H29: =G29*I29 -> 0 | I29: 0 | J29: шт | K29: SAIMAN | L29: =H29 -> 0 | M29: Учет
A30: 25 | C30: montajный материал | D30: 521371 | E30: Рукоятка для съема плавкой вставки серии RT36 | F30: 1473 | G30: =F30*INDEX(Kurallar!$B$16:$B$26,MATCH(K30,Kurallar!$A$16:$A$26,0)) -> 883.8 | H30: =G30*I30 -> 883.8 | I30: 1 | J30: шт | K30: CHINT | L30: =H30 -> 883.8 | M30: Монтаж
A31: 27 | C31: LOOBAR | D31: 130200153_ | E31: Шина алюм АД31Т 4х40х4000 | F31: 1297 | G31: =F31*INDEX(Kurallar!$B$16:$B$26,MATCH(K31,Kurallar!$A$16:$A$26,0)) -> 1297 | H31: =G31*I31 -> 5188 | I31: 4 | J31: м | K31: EKT | L31: =H31 -> 5188 | M31: Бара
A32: 28 | C32: LOOBAR | D32: 130300473_ | E32: Шина медн.3х20х4000 | F32: 5538 | G32: =F32*INDEX(Kurallar!$B$16:$B$26,MATCH(K32,Kurallar!$A$16:$A$26,0)) -> 5538 | H32: =G32*I32 -> 6645.6 | I32: 1.2 | J32: м | K32: EKT | L32: =H32 -> 6645.6 | M32: Бара
A33: 29 | C33: LOOBAR | D33: 130500106_ | E33: Изолятор SM40 с болтом М8, 475А, 12кВ UNIT — опоры шин | F33: 324 | G33: =F33*INDEX(Kurallar!$B$16:$B$26,MATCH(K33,Kurallar!$A$16:$A$26,0)) -> 324 | H33: =G33*I33 -> 1296 | I33: 4 | J33: шт | K33: IEK/UNIT | L33: =H33 -> 1296 | M33: Бара
A34: 30 | C34: Klemens | D34: 130301157_ | E34: Клемма ЗНИ 16 мм² (100А) серая UNIT — цепи учета и вторичной коммутации | F34: 235 | G34: =F34*INDEX(Kurallar!$B$16:$B$26,MATCH(K34,Kurallar!$A$16:$A$26,0)) -> 235 | H34: =G34*I34 -> 0 | I34: 0 | J34: шт | K34: IEK/UNIT | L34: =H34 -> 0 | M34: Клемма
... A37: 33 | C37: montajный материал | D37: 280100020_ | E37: Кабель-канал перфорированный 40х40 ИМПАКТ IEK | F37: 1486 | G37: =F37*INDEX(Kurallar!$B$16:$B$26,MATCH(K37,Kurallar!$A$16:$A$26,0)) -> 1486 | H37: =G37*I37 -> 0 | I37: 0 | J37: м | K37: IEK/UNIT | L37: =H37 -> 0 | M37: Монтаж
A38: 34 | C38: montajный материал | E38: Монтажные материалы: крепеж, шпильки, наконечники ТМЛ/НШВИ, провод ПВ3, бирки/маркировка, стяжки, лак, изолента — %% от материала панели | G38: =SUM(H22:H37)*Kurallar!$B$10 -> 4706.958 | H38: =G38*I38 -> 4706.958 | I38: 1 | J38: шт | L38: =H38 -> 4706.958
A39: 35 | C39: montajная работа | E39: Сборка, монтаж, шинный монтаж, маркировка, испытание и контроль (по нормам времени, лист Kurallar) | F39: 6 | G39: =Kurallar!$B$11 -> 100 | H39: =G39*I39 -> 36000 | I39: =60*F39 -> 360 | J39: мин | M39: işçilik
B40: Toplam ВРУ1-47-00 УХЛ4 — Распределительная панель (8 линий: C1-C4, C6-C9) | H40: =SUBTOTAL(9,H22:H39) -> 197605.56 | L40: =SUBTOTAL(9,L22:L39) -> 161605.56
B41: =E41 -> Блок автоматического управления освещением на 14 групп (SF1...SF30) | E41: Блок автоматического управления освещением на 14 групп (SF1...SF30) | I41: 1 | J41: комплект
A42: 36 | C42: korpus | D42: 250200159_ | E42: Корпус ВРУ-1-50 (1700x800x440) пустой щит, металл, IP31 | F42: 82950 | G42: =F42*INDEX(Kurallar!$B$16:$B$26,MATCH(K42,Kurallar!$A$16:$A$26,0)) -> 82950 | H42: =G42*I42 -> 82950 | I42: 1 | J42: шт | K42: EKT | L42: =H42 -> 82950 | M42: Освещ.
...

Sheet СВОД
A1: СВОД ПО ПАНЕЛЯМ — 260730 M.AKAY ARIF (silocu), ВРУ-1, CHINT
A3: № | B3: Панель | C3: Материал, KZT | D3: Работа, мин | E3: Работа, KZT | F3: ИТОГО, KZT | G3: Кол-во компл. | H3: Статус
A4: 1 | B4: =BOM!E2 -> ВРУ1-13-20 УХЛ4 — Вводная панель (2 ввода 315А, без счетчик) | C4: =BOM!L20 -> 242153.41 | D4: =BOM!I19 -> 540 | E4: =BOM!H19 -> 54000 | F4: =BOM!H20 -> 296153.41 | G4: =BOM!I2 -> 1 | H4: ПОЛНАЯ
A5: 2 | B5: =BOM!E21 -> ВРУ1-47-00 УХЛ4 — Распределительная панель без счетчик (8 линий: C1-C4, C6-C9) | C5: =BOM!L40 -> 161605.56 | D5: =BOM!I39 -> 360 | E5: =BOM!H39 -> 36000 | F5: =BOM!H40 -> 197605.56 | G5: =BOM!I21 -> 1 | H5: ПОЛНАЯ
A6: 3 | B6: =BOM!E41 -> Блок автоматического управления освещением на 14 групп (SF1...SF30) | C6: =BOM!L47 -> 103966.55 | D6: =BOM!I46 -> 0 | E6: =BOM!H46 -> 0 | F6: =BOM!H47 -> 103966.55 | G6: =BOM!I41 -> 1 | H6: НЕПОЛНАЯ — см. Kurallar
B7: ИТОГО ПО ПРОЕКТУ | C7: =SUM(C4:C6) -> 507725.52 | D7: =SUM(D4:D6) -> 900 | E7: =SUM(E4:E6) -> 90000 | F7: =SUM(F4:F6) -> 597725.52
B9: Работа, часов (справочно) | D9: =D7/60 -> 15
B10: Панель 3 укомплектована не полностью: внутреннее оборудование блока АУО освещения (SF1...SF30 / 14 групп) не задано на чертеже. См. раздел KONTROL в листе BOM и лист Kurallar.
B11: Прайс-лист EKT от 17.06.2025 — YAS_DURUM = "ВНИМАНИЕ" (>12 мес). Корпуса, шина, клеммы, кабель-канал, изоляторы. Запросить прайс EKT 2026 до выдачи цены клиенту.

Sheet Kurallar
A1: KURALLAR / ПАРАМЕТРЫ — YSF HICH BOM ROBOTU
A2: Желтые ячейки = редактируемые параметры | Sari hucreler = duzenlenebilir parametreler | E2: ВРУ1-13-20 УХЛ4 — Вводная панель (2 ввода 315А, без счетчик) | F2: =2.3*H20 -> 0 | G2: =0.7*F2 -> 0
A3: Проект / Proje | B3: 260730 M.AKAY ARIF (silocu) — ВРУ-1 | D3: 719-15043 | E3: Мет. Щит ВРУ 1700х800х450+10CM База | F3: 155000 | G3: =0.6*F3 -> 93000 | K3: kaztek
A4: Дата BOM | B4: 46233 | D4: 270100161_ | E4: Рубильник ВР-32-37 В71250-400А на 2 направления (+6камер) UNIT (1/6) | F4: 21950 | G4: =F4 -> 21950 | K4: pys
A5: Основной бренд / Ana marka | B5: CHINT
A6: Порог "ВНИМАНИЕ", мес | B6: 12
A7: Порог "ЗАПРЕЩЕНО", мес | B7: 18 | D7: IA | E7: ДАЛА СА4У-Э720 R TX OP П RS1 Д W (3x220/380V 5-7,5A) | F7: 88000 | I7: 0
A8: Курс EUR/KZT | C8: в этом BOM не используется (нет позиций ABB / Schneider) | F8: 6000 | G8: =F8 -> 6000 | K8: pys
A9: Курс TL/KZT | C9: в этом BOM не используется
A10: Монтажные материалы, % от материала | B10: 0.03
A11: Ставка работы, KZT/мин | B11: 100 | D11: 130200153_ | E11: Шина алюм АД31Т 4х40х4000 | F11: 1297 | I11: 8
A12: Коэф. испытание/маркировка/контроль | B12: 1.15 | D12: 130300473_ | E12: Шина медн.3х20х4000 | F12: 5538 | I12: 1.5
I13: 4
A14: АУДИТ ПРАЙС-ЛИСТОВ / FİYAT LİSTESİ YAŞ DENETİMİ
A15: Марка | B15: Коэффициент | C15: Дата прайса | D15: Возраст, мес | E15: YAS_DURUM | F15: Примечание
A16: CHINT | B16: 0.6 | C16: 46186 | D16: =ROUND(($B$4-C16)/30.44,1) -> 1.5 | E16: =IF(D16>$B$7,"ЗАПРЕЩЕНО",IF(D16>=$B$6,"ВНИМАНИЕ","АКТУАЛЬНО")) -> АКТУАЛЬНО | F16: Прайс + остатки. Основной бренд BOM.
A17: SAIMAN | B17: 1 | C17: 46023 | D17: =ROUND(($B$4-C17)/30.44,1) -> 6.9 | E17: =IF(D17>$B$7,"ЗАПРЕЩЕНО",IF(D17>=$B$6,"ВНИМАНИЕ","АКТУАЛЬНО")) -> АКТУАЛЬНО | F17: Счетчики Дала / ТТ ТШП. Актуально.
A18: EKT | B18: 1 | C18: 45825 | D18: =ROUND(($B$4-C18)/30.44,1) -> 13.4 | E18: =IF(D18>$B$7,"ЗАПРЕЩЕНО",IF(D18>=$B$6,"ВНИМАНИЕ","АКТУАЛЬНО")) -> ВНИМАНИЕ | F18: Корпуса ВРУ, шина, клеммы, кабель-канал.
A19: IEK/UNIT | B19: 1 | C19: 45825 | D19: =ROUND(($B$4-C19)/30.44,1) -> 13.4 | E19: =IF(D19>$B$7,"ЗАПРЕЩЕНО",IF(D19>=$B$6,"ВНИМАНИЕ","АКТУАЛЬНО")) -> ВНИМАНИЕ | F19: 9 | I19: =60*F19 -> 540
A20: ABB | B20: 0.3 | C20: 45962 | D20: =ROUND(($B$4-C20)/30.44,1) -> 8.9 | E20: =IF(D20>$B$7,"ЗАПРЕЩЕНО",IF(D20>=$B$6,"ВНИМАНИЕ","АКТУАЛЬНО")) -> АКТУАЛЬНО | F20: Станд. x0.30 / ACB ayarlı-açık tip x0.23. Не исп.
A21: SCHNEIDER | B21: 0.6 | C21: 45839 | D21: =ROUND(($B$4-C21)/30.44,1) -> 12.9 | E21: ВРУ1-47-00 УХЛ4 — Распределительная панель без счетчик (8 линий: C1-C4, C6-C9) | F21: =2.3*H40 -> 0 | G21: =0.7*F21 -> 0
A22: LEGRAND | B22: 1 | C22: 45931 | D22: 719-156 | E22: Мет. Щит Пустой (1700x710x350)+10см база IP31 | F22: 140000 | G22: =0.6*F22 -> 84000
A23: CNC | B23: 0.55 | C23: 45692 | D23: 521260 | E23: Держатель плавкой вставки RT36-00-160, габарит 00, 160А | F23: 2038 | I23: 18
A24: KLEMSAN | B24: 1 | C24: 44866 | D24: 521236 | E24: Плавкая вставка предохранителя RT36-0-160, габарит 0, 160А | F24: 2225
A25: ONKA | B25: 1 | C25: 44743 | D25: 521234 | E25: Плавкая вставка предохранителя RT36-0-160, габарит 0, 125А | F25: 2225
A26: EKF | B26: 1 | C26: 44614 | D26: 521232 | E26: Плавкая вставка предохранителя RT36-0-160, габарит 0, 100А | F26: 2210
A28: НОРМЫ ВРЕМЕНИ / İŞÇİLİK ZAMAN NORMLARI
A29: Порог "ЗАПРЕЩЕНО", мес | B29: 18 | D29: NC | E29: Дала TX П СА4-Э720 (3x220/380V 5-60A) | F29: 36900 | I29: 0
A30: Операция | B30: Норма | C30: Ед.
A31: Корпус средний — подготовка | B31: 45 | C31: мин/шт | D31: 130200153_ | E31: Шина алюм АД31Т 4х40х4000 | F31: 1297 | I31: 4
A32: Корпус малый — подготовка | B32: 30 | C32: мин/шт | D32: 130300473_ | E32: Шина медн.3х20х4000 | F32: 5538 | I32: 1.2
A33: Рубильник / перекидной рубильник 250-630А | B33: 90 | C33: мин/шт | I33: 4
A34: Автомат TMS (MCCB) до 250А | B34: 60 | C34: мин/шт | I34: 0
A35: Автомат TMS (MCCB) 315-630А | B35: 90 | C35: мин/шт | I35: 0
A36: Автомат OTO 1P | B36: 10 | C36: мин/шт | I36: 0
A37: Автомат OTO 3P | B37: 18 | C37: мин/шт | I37: 0
A38: Держатель предохранителя габарит 2 (400А) | B38: 30 | C38: мин/шт
A39: Держатель предохранителя габарит 1 (250А) | B39: 20 | C39: мин/шт | F39: 6 | I39: =60*F39 -> 360
A40: Держатель предохранителя габарит 00 (160А) | B40: 12 | C40: мин/шт
A41: Плавкая вставка — установка | B41: 2 | C41: мин/шт
...
