Workbook

Sheet ПАРАМЕТРЫ
A1: ПАРАМЕТРЫ — Проект 260608 — ABB
A2: Параметр | B2: Значение (ред.) | C2: Описание
A3: EUR/KZT курс | B3: 590 | C3: Обновить с XE.com
A4: Коэф.скидки ABB (0.33) | B4: 0.3 | C4: Скидка на покупку
A5: Коэф.надбавки (ABB EUR) | B5: 1.33 | C5: Транспорт + накладные (только для EUR)
A6: Монтажные материалы % | B6: 12 | C6: % от суммы компонентов
A7: Монтажная работа % | B7: 15 | C7: % от суммы компонентов
A9: Ключ | B9: Цена (список) (ред.) | C9: Наименование / Артикул | D9: Цена нетто KZT (формула)
A10: S201-C6 | B10: 12.92 | C10: Авт.выкл. 1P C6 S201-C6 [2CDS251001R0064] | D10: =ПАРАМЕТРЫ!B10*ПАРАМЕТРЫ!B4*ПАРАМЕТРЫ!B5*ПАРАМЕТРЫ!B3 -> 3041.4972
A11: S201-C10 | B11: 10.77 | C11: Авт.выкл. 1P C10 S201-C10 [2CDS251001R0104] | D11: =ПАРАМЕТРЫ!B11*ПАРАМЕТРЫ!B4*ПАРАМЕТРЫ!B5*ПАРАМЕТРЫ!B3 -> 2535.3657
A12: S201-C16 | B12: 10.77 | C12: Авт.выкл. 1P C16 S201-C16 [2CDS251001R0164] | D12: =ПАРАМЕТРЫ!B12*ПАРАМЕТРЫ!B4*ПАРАМЕТРЫ!B5*ПАРАМЕТРЫ!B3 -> 2535.3657
A13: S201-C20 | B13: 10.77 | C13: Авт.выкл. 1P C20 S201-C20 [2CDS251001R0204] | D13: =ПАРАМЕТРЫ!B13*ПАРАМЕТРЫ!B4*ПАРАМЕТРЫ!B5*ПАРАМЕТРЫ!B3 -> 2535.3657
A14: S201-C25 | B14: 10.77 | C14: Авт.выкл. 1P C25 S201-C25 [2CDS251001R0254] | D14: =ПАРАМЕТРЫ!B14*ПАРАМЕТРЫ!B4*ПАРАМЕТРЫ!B5*ПАРАМЕТРЫ!B3 -> 2535.3657
A15: S201-C32 | B15: 13.46 | C15: Авт.выкл. 1P C32 S201-C32 [2CDS251001R0324] | D15: =ПАРАМЕТРЫ!B15*ПАРАМЕТРЫ!B4*ПАРАМЕТРЫ!B5*ПАРАМЕТРЫ!B3 -> 3168.6186
A16: S203-C6 | B16: 58.16 | C16: Авт.выкл. 3P C6 S203-C6 [2CDS253001R0064] | D16: =ПАРАМЕТРЫ!B16*ПАРАМЕТРЫ!B4*ПАРАМЕТРЫ!B5*ПАРАМЕТРЫ!B3 -> 13691.446
A17: S203-C10 | B17: 48.51 | C17: Авт.выкл. 3P C10 S203-C10 [2CDS253001R0104] | D17: =ПАРАМЕТРЫ!B17*ПАРАМЕТРЫ!B4*ПАРАМЕТРЫ!B5*ПАРАМЕТРЫ!B3 -> 11419.739
A18: S203-C16 | B18: 48.51 | C18: Авт.выкл. 3P C16 S203-C16 [2CDS253001R0164] | D18: =ПАРАМЕТРЫ!B18*ПАРАМЕТРЫ!B4*ПАРАМЕТРЫ!B5*ПАРАМЕТРЫ!B3 -> 11419.739
A19: S203-C20 | B19: 48.51 | C19: Авт.выкл. 3P C20 S203-C20 [2CDS253001R0204] | D19: =ПАРАМЕТРЫ!B19*ПАРАМЕТРЫ!B4*ПАРАМЕТРЫ!B5*ПАРАМЕТРЫ!B3 -> 11419.739
A20: S203-C25 | B20: 48.51 | C20: Авт.выкл. 3P C25 S203-C25 [2CDS253001R0254] | D20: =ПАРАМЕТРЫ!B20*ПАРАМЕТРЫ!B4*ПАРАМЕТРЫ!B5*ПАРАМЕТРЫ!B3 -> 11419.739
A21: S203-C32 | B21: 60.59 | C21: Авт.выкл. 3P C32 S203-C32 [2CDS253001R0324] | D21: =ПАРАМЕТРЫ!B21*ПАРАМЕТРЫ!B4*ПАРАМЕТРЫ!B5*ПАРАМЕТРЫ!B3 -> 14263.492
A22: DS201-C10-30 | B22: 93.71 | C22: Диф.авт. 1P+N C10 30мА DS201 C10 AC30 [2CSR255080R1104] | D22: =ПАРАМЕТРЫ!B22*ПАРАМЕТРЫ!B4*ПАРАМЕТРЫ!B5*ПАРАМЕТРЫ!B3 -> 22060.271
A23: DS201-C16-30 | B23: 87.63 | C23: Диф.авт. 1P+N C16 30мА DS201 C16 AC30 [2CSR255080R1164] | D23: =ПАРАМЕТРЫ!B23*ПАРАМЕТРЫ!B4*ПАРАМЕТРЫ!B5*ПАРАМЕТРЫ!B3 -> 20628.978
A24: DS201-C20-30 | B24: 87.63 | C24: Диф.авт. 1P+N C20 30мА DS201 C20 AC30 [2CSR255080R1204] | D24: =ПАРАМЕТРЫ!B24*ПАРАМЕТРЫ!B4*ПАРАМЕТРЫ!B5*ПАРАМЕТРЫ!B3 -> 20628.978
A25: DS203NC-C10-30 | B25: 292 | C25: Диф.авт. 3P+N C10 30мА DS203NC C10 AC30 [2CSR256040R1104] | D25: =ПАРАМЕТРЫ!B25*ПАРАМЕТРЫ!B4*ПАРАМЕТРЫ!B5*ПАРАМЕТРЫ!B3 -> 68739.72
A26: DS203NC-C16-30 | B26: 292 | C26: Диф.авт. 3P+N C16 30мА DS203NC C16 AC30 [2CSR256040R1164] | D26: =ПАРАМЕТРЫ!B26*ПАРАМЕТРЫ!B4*ПАРАМЕТРЫ!B5*ПАРАМЕТРЫ!B3 -> 68739.72
A27: OT25F3 | B27: 36.68 | C27: Выкл.-разъед. 3P 25А OT25F3 [1SCA104857R1001] | D27: =ПАРАМЕТРЫ!B27*ПАРАМЕТРЫ!B4*ПАРАМЕТРЫ!B5*ПАРАМЕТРЫ!B3 -> 8634.8388
A28: OT63F3 | B28: 67.89 | C28: Выкл.-разъед. 3P 63А OT63F3 [1SCA105332R1001] | D28: =ПАРАМЕТРЫ!B28*ПАРАМЕТРЫ!B4*ПАРАМЕТРЫ!B5*ПАРАМЕТРЫ!B3 -> 15981.985
A29: OT100F3 | B29: 100.1 | C29: Выкл.-разъед. 3P 100А OT100F3 [1SCA105004R1001] | D29: =ПАРАМЕТРЫ!B29*ПАРАМЕТРЫ!B4*ПАРАМЕТРЫ!B5*ПАРАМЕТРЫ!B3 -> 23564.541
A30: XT1N-80A | B30: 210 | C30: Авт.выкл. 3P 80А XT1N 160 TMD [1SDA067---] | D30: =ПАРАМЕТРЫ!B30*ПАРАМЕТРЫ!B4*ПАРАМЕТРЫ!B5*ПАРАМЕТРЫ!B3 -> 49436.1
A31: XT1N-100A | B31: 246.1 | C31: Авт.выкл. 3P 100А XT1N 160 TMD [1SDA067416R1] | D31: =ПАРАМЕТРЫ!B31*ПАРАМЕТРЫ!B4*ПАРАМЕТРЫ!B5*ПАРАМЕТРЫ!B3 -> 57934.401
A32: XT1N-125A | B32: 308.8 | C32: Авт.выкл. 3P 125А XT1N 160 TMD [1SDA067417R1] | D32: =ПАРАМЕТРЫ!B32*ПАРАМЕТРЫ!B4*ПАРАМЕТРЫ!B5*ПАРАМЕТРЫ!B3 -> 72694.608
A33: ESB16-11N | B33: 41.58 | C33: Контактор 16А ESB16-11N 230В [1SBE111111R0611] | D33: =ПАРАМЕТРЫ!B33*ПАРАМЕТРЫ!B4*ПАРАМЕТРЫ!B5*ПАРАМЕТРЫ!B3 -> 9788.3478
A34: ESB20-11N | B34: 47.51 | C34: Контактор 20А ESB20-11N 230В [1SBE121111R0611] | D34: =ПАРАМЕТРЫ!B34*ПАРАМЕТРЫ!B4*ПАРАМЕТРЫ!B5*ПАРАМЕТРЫ!B3 -> 11184.329
A35: OTM125 | B35: 1285 | C35: АВР 3P 125А OTM125F3CMA230V [1SCA120070R1001] | D35: =ПАРАМЕТРЫ!B35*ПАРАМЕТРЫ!B4*ПАРАМЕТРЫ!B5*ПАРАМЕТРЫ!B3 -> 302501.85
A36: S3C-A1 | B36: 62.93 | C36: Независимый расцепитель S3C-A1 AC/DC 12-110V [2CDS200982R0001] | D36: =ПАРАМЕТРЫ!B36*ПАРАМЕТРЫ!B4*ПАРАМЕТРЫ!B5*ПАРАМЕТРЫ!B3 -> 14814.351
A37: КЛЕММНИК | B37: 1.5 | C37: Клеммник монтажный (аналог NSYTRV162) [—] | D37: =ПАРАМЕТРЫ!B37*ПАРАМЕТРЫ!B4*ПАРАМЕТРЫ!B5*ПАРАМЕТРЫ!B3 -> 353.115
A38: ЯТП-IEK | B38: 29812 | C38: ЯТП-0,25 230/36В IEK (MTT12-036-0250) [MTT12-036-0250] | D38: =ПАРАМЕТРЫ!B38*ПАРАМЕТРЫ!B4 -> 8943.6
A39: УКРМ-10 | B39: 0 | C39: УКРМ 10кВАр 400В, 800×700×250мм [По запросу] | D39: =ПАРАМЕТРЫ!B39*ПАРАМЕТРЫ!B5 -> 0
A40: S 203-C 80 | B40: 193.8 | C40: Авт.выкл. 3P C80 S 203-C 80 2CDS253001R0804 | D40: =ПАРАМЕТРЫ!B40*ПАРАМЕТРЫ!B4*ПАРАМЕТРЫ!B5*ПАРАМЕТРЫ!B3 -> 45622.458
A41: S 203-C 100 | B41: 242.2 | C41: Авт.выкл. 3P C80 S 203-C 100 2CDS253001R0824 | D41: =ПАРАМЕТРЫ!B41*ПАРАМЕТРЫ!B4*ПАРАМЕТРЫ!B5*ПАРАМЕТРЫ!B3 -> 57016.302

Sheet BOM
C1: СПЕЦИФИКАЦИЯ ОБОРУДОВАНИЯ — Проект 260608 — г.Атырау — ABB | Формула: KZT = EUR_list × 0.33 × 1.30 × EUR/KZT | Параметры → лист ПАРАМЕТРЫ (синие ячейки)
A2: № | B2: Наименование и техническая характеристика | C2: Тип / Марка / Артикул | D2: Источник (PDF альбом) | E2: Ед. | F2: Кол. | G2: Цена список | H2: KZT нетто | I2: Сумма KZT | J2: Примечание
C3: ─── ЭОМ — ГАРАЖ ───
A4: =B4 -> КОМПЛЕКТ 1. ГРЩ (ЩМП-18.8.4-0 36 УХЛ3 IP31) | Альбом 7.4 ЭОМ (Гараж) | B4: КОМПЛЕКТ 1. ГРЩ (ЩМП-18.8.4-0 36 УХЛ3 IP31) | Альбом 7.4 ЭОМ (Гараж)
A5: 1.1 | B5: Корпус — ЩМП-18.8.4,5+1 bz-0 36 УХЛ3 IP31 | C5: Teksan f | D5: Альбом 7.4 ЭОМ (Гараж) | E5: шт | F5: 2 | G5: — | H5: — | I5: 0 | J5: Teksan f — цена TBD
A6: 1.2 | B6: Авт.выкл. 3P 125А XT1N 160 TMD | C6: 1SDA067417R1 | D6: Альбом 7.4 ЭОМ (Гараж) | E6: шт | F6: 4 | G6: =ПАРАМЕТРЫ!B32 -> 308.8 | H6: =ПАРАМЕТРЫ!D32 -> 72694.608 | I6: =F6*H6 -> 290778.43 | J6: DPX3 125А / вводной аналог
A7: 1.3 | B7: Авт.выкл. 3P 100А XT1N 160 TMD | C7: 1SDA067416R1 | D7: Альбом 7.4 ЭОМ (Гараж) | E7: шт | F7: 1 | G7: =ПАРАМЕТРЫ!B31 -> 246.1 | H7: =ПАРАМЕТРЫ!D31 -> 57934.401 | I7: =F7*H7 -> 57934.401 | J7: Резервный ввод
A8: 1.4 | B8: Авт.выкл. 3P C20 S203-C20 | C8: 2CDS253001R0204 | D8: Альбом 7.4 ЭОМ (Гараж) | E8: шт | F8: 5 | G8: =ПАРАМЕТРЫ!B19 -> 48.51 | H8: =ПАРАМЕТРЫ!D19 -> 11419.739 | I8: =F8*H8 -> 57098.696 | J8: TX3 20A 3P
A9: 1.5 | B9: Авт.выкл. 3P C25 S203-C25 | C9: 2CDS253001R0254 | D9: Альбом 7.4 ЭОМ (Гараж) | E9: шт | F9: 1 | G9: =ПАРАМЕТРЫ!B20 -> 48.51 | H9: =ПАРАМЕТРЫ!D20 -> 11419.739 | I9: =F9*H9 -> 11419.739 | J9: TX3 25A 3P
A10: 1.6 | B10: Авт.выкл. 1P C6 S201-C6 | C10: 2CDS251001R0064 | D10: Альбом 7.4 ЭОМ (Гараж) | E10: шт | F10: 4 | G10: =ПАРАМЕТРЫ!B10 -> 12.92 | H10: =ПАРАМЕТРЫ!D10 -> 3041.4972 | I10: =F10*H10 -> 12165.989 | J10: TX3 6A 1P
A11: 1.7 | B11: АВР 3P 125А OTM125F3CMA230V | C11: 1SCA120070R1001 | D11: Альбом 7.4 ЭОМ (Гараж) | E11: шт | F11: 2 | G11: =ПАРАМЕТРЫ!B35 -> 1285 | H11: =ПАРАМЕТРЫ!D35 -> 302501.85 | I11: =F11*H11 -> 605003.7 | J11: АВР TransferPact аналог
A12: 1.8 | B12: УКРМ 10кВАр 400В, 800×700×250мм | C12: По запросу | D12: Альбом 7.4 ЭОМ (Гараж) | E12: шт | F12: 2 | G12: — | H12: — | I12: 0 | J12: КРМ — 2 шт (ввод1+ввод2) — цена TBD
A13: 1.9 | B13: Счётчик электроэнергии 3ф 100А 380В | C13: Энергомера СЕ 303 S31 746-JPVZ PLC 1111, 100А, 380В | D13: Альбом 7.4 ЭОМ (Гараж) | E13: шт | F13: 3 | G13: — | H13: — | I13: 0 | J13: Счётчик/прибор — 3 шт — по одному на каждый ввод ГРЩ — цена По запросу
A14: 1.10 | B14: Монтажный материал | D14: Альбом 7.4 ЭОМ (Гараж) | E14: компл | F14: 1 | G14: — | H14: =ПАРАМЕТРЫ!B6&"%" -> 12% | I14: =(I6+I7+I8+I9+I10+I11)*ПАРАМЕТРЫ!B6/100 -> 124128.11 | J14: % от суммы компонентов
A15: 1.11 | B15: Монтажная работа | D15: Альбом 7.4 ЭОМ (Гараж) | E15: компл | F15: 1 | G15: — | H15: =ПАРАМЕТРЫ!B7&"%" -> 15% | I15: =(I6+I7+I8+I9+I10+I11)*ПАРАМЕТРЫ!B7/100 -> 155160.14 | J15: % от суммы компонентов
A16: Итого по ГРЩ (ЩМП-18.8.4-0 36 УХЛ3 IP31) (без корпуса Teksan f): | I16: =I6+I7+I8+I9+I10+I11+I14+I15 -> 1313689.2
A17: КОМПЛЕКТ 2. ЩС-В (ЩРн-12з-0 36 УХЛ3 IP54) | Альбом 7.4 ЭОМ (Гараж) | B17: =A17 -> КОМПЛЕКТ 2. ЩС-В (ЩРн-12з-0 36 УХЛ3 IP54) | Альбом 7.4 ЭОМ (Гараж)
A18: 2.1 | B18: Корпус — ЩРн-24з-0 36 УХЛ3 IP54 | C18: Teksan f | D18: Альбом 7.4 ЭОМ (Гараж) | E18: шт | F18: 1 | G18: — | H18: — | I18: 0 | J18: Teksan f — цена TBD
A19: 2.2 | B19: Авт.выкл. 3P C20 S203-C20 | C19: 2CDS253001R0204 | D19: Альбом 7.4 ЭОМ (Гараж) | E19: шт | F19: 1 | G19: =ПАРАМЕТРЫ!B19 -> 48.51 | H19: =ПАРАМЕТРЫ!D19 -> 11419.739 | I19: =F19*H19 -> 11419.739 | J19: Ввод QF1 20А 3P
A20: 2.3 | B20: Авт.выкл. 1P C16 S201-C16 | C20: 2CDS251001R0164 | D20: Альбом 7.4 ЭОМ (Гараж) | E20: шт | F20: 2 | G20: =ПАРАМЕТРЫ!B12 -> 10.77 | H20: =ПАРАМЕТРЫ!D12 -> 2535.3657 | I20: =F20*H20 -> 5070.7314 | J20: SF2, SF3
A21: 2.4 | B21: Авт.выкл. 3P C16 S203-C16 | C21: 2CDS253001R0164 | D21: Альбом 7.4 ЭОМ (Гараж) | E21: шт | F21: 1 | G21: =ПАРАМЕТРЫ!B18 -> 48.51 | H21: =ПАРАМЕТРЫ!D18 -> 11419.739 | I21: =F21*H21 -> 11419.739 | J21: TX3 16А 3P
A22: 2.5 | B22: Контактор 16А ESB16-11N 230В | C22: 1SBE111111R0611 | D22: Альбом 7.4 ЭОМ (Гараж) | E22: шт | F22: 3 | G22: =ПАРАМЕТРЫ!B33 -> 41.58 | H22: =ПАРАМЕТРЫ!D33 -> 9788.3478 | I22: =F22*H22 -> 29365.043 | J22: КМИ 10910 9А — В1+В2+В3
A23: 2.6 | B23: Независимый расцепитель S3C-A1 AC/DC 12-110V | C23: 2CDS200982R0001 | D23: Альбом 7.4 ЭОМ (Гараж) | E23: шт | F23: 1 | G23: =ПАРАМЕТРЫ!B36 -> 62.93 | H23: =ПАРАМЕТРЫ!D36 -> 14814.351 | I23: =F23*H23 -> 14814.351 | J23: Независимый расцепитель DRX — пожарный сигнал
A24: 2.7 | B24: Монтажный материал | D24: Альбом 7.4 ЭОМ (Гараж) | E24: компл | F24: 1 | G24: — | H24: =ПАРАМЕТРЫ!B6&"%" -> 12% | I24: =(I19+I20+I22+I23)*ПАРАМЕТРЫ!B6/100 -> 7280.3838 | J24: % от суммы компонентов
A25: 2.8 | B25: Монтажная работа | D25: Альбом 7.4 ЭОМ (Гараж) | E25: компл | F25: 1 | G25: — | H25: =ПАРАМЕТРЫ!B7&"%" -> 15% | I25: =(I19+I20+I22+I23)*ПАРАМЕТРЫ!B7/100 -> 9100.4798 | J25: % от суммы компонентов
A26: Итого по ЩС-В (ЩРн-12з-0 36 УХЛ3 IP54) (без корпуса Teksan f): | I26: =I19+I20+I22+I23+I24+I25 -> 77050.729
A27: КОМПЛЕКТ 3. ЩС-П (ЩРн-24з-0 36 УХЛ3 IP54) | Альбом 7.4 ЭОМ (Гараж) | B27: =A27 -> КОМПЛЕКТ 3. ЩС-П (ЩРн-24з-0 36 УХЛ3 IP54) | Альбом 7.4 ЭОМ (Гараж)
A28: 3.1 | B28: Корпус — ЩРн-24з-0 36 УХЛ3 IP54 | C28: Teksan f | D28: Альбом 7.4 ЭОМ (Гараж) | E28: шт | F28: 1 | G28: — | H28: — | I28: 0 | J28: Teksan f — цена TBD
A29: 3.2 | B29: S203-C25 | C29: 2CDS253001R0254 | D29: Альбом 7.4 ЭОМ (Гараж) | E29: шт | F29: 1 | G29: =ПАРАМЕТРЫ!B20 -> 48.51 | H29: =ПАРАМЕТРЫ!D20 -> 11419.739 | I29: =F29*H29 -> 11419.739 | J29: ВН-32 25А
A30: 3.3 | B30: Диф.авт. 1P+N C16 30мА DS201 C16 AC30 | C30: 2CSR255080R1164 | D30: Альбом 7.4 ЭОМ (Гараж) | E30: шт | F30: 7 | G30: =ПАРАМЕТРЫ!B23 -> 87.63 | H30: =ПАРАМЕТРЫ!D23 -> 20628.978 | I30: =F30*H30 -> 144402.85 | J30: АВДТ DX3 1P+N 16А 30мА
A31: 3.4 | B31: Авт.выкл. 3P C16 S203-C16 | C31: 2CDS253001R0164 | D31: Альбом 7.4 ЭОМ (Гараж) | E31: шт | F31: 0 | G31: =ПАРАМЕТРЫ!B18 -> 48.51 | H31: =ПАРАМЕТРЫ!D18 -> 11419.739 | I31: =F31*H31 -> 0 | J31: TX3 16А 3P
A32: 3.5 | B32: Авт.выкл. 1P C16 S201-C16 | C32: 2CDS251001R0164 | D32: Альбом 7.4 ЭОМ (Гараж) | E32: шт | F32: 1 | G32: =ПАРАМЕТРЫ!B12 -> 10.77 | H32: =ПАРАМЕТРЫ!D12 -> 2535.3657 | I32: =F32*H32 -> 2535.3657 | J32: TX3 16А 1P
A33: 3.6 | B33: Монтажный материал | D33: Альбом 7.4 ЭОМ (Гараж) | E33: компл | F33: 1 | G33: — | H33: =ПАРАМЕТРЫ!B6&"%" -> 12% | I33: =(I29+I30+I31+I32)*ПАРАМЕТРЫ!B6/100 -> 19002.954 | J33: % от суммы компонентов
A34: 3.7 | B34: Монтажная работа | D34: Альбом 7.4 ЭОМ (Гараж) | E34: компл | F34: 1 | G34: — | H34: =ПАРАМЕТРЫ!B7&"%" -> 15% | I34: =(I29+I30+I31+I32)*ПАРАМЕТРЫ!B7/100 -> 23753.693 | J34: % от суммы компонентов
A35: Итого по ЩС-П (ЩРн-24з-0 36 УХЛ3 IP54) (без корпуса Teksan f): | I35: =I29+I30+I31+I32+I33+I34 -> 201114.6
A36: КОМПЛЕКТ 4. ЩС-ПО (ЩРн-12з-0 36 УХЛ3 IP54) | Альбом 7.4 ЭОМ (Гараж) | B36: =A36 -> КОМПЛЕКТ 4. ЩС-ПО (ЩРн-12з-0 36 УХЛ3 IP54) | Альбом 7.4 ЭОМ (Гараж)
A37: 4.1 | B37: Корпус — ЩРн-12з-0 36 УХЛ3 IP54 | C37: Teksan f | D37: Альбом 7.4 ЭОМ (Гараж) | E37: шт | F37: 1 | G37: — | H37: — | I37: 0 | J37: Teksan f — цена TBD
A38: 4.2 | B38: S 203-C 100 | C38: 2CDS253001R0824 | D38: Альбом 7.4 ЭОМ (Гараж) | E38: шт | F38: 1 | G38: =ПАРАМЕТРЫ!B29 -> 100.1 | H38: =ПАРАМЕТРЫ!D29 -> 23564.541 | I38: =F38*H38 -> 23564.541 | J38: ВН-32 100А
A39: 4.3 | B39: S 203-C 80 | C39: 2CDS253001R0824 | D39: Альбом 7.4 ЭОМ (Гараж) | E39: шт | F39: 1 | G39: =ПАРАМЕТРЫ!B40 -> 193.8 | H39: =ПАРАМЕТРЫ!D40 -> 45622.458 | I39: =F39*H39 -> 45622.458 | J39: DPX3 80А — Дп1
A40: 4.4 | B40: Авт.выкл. 3P C16 S203-C16 | C40: 2CDS253001R0164 | D40: Альбом 7.4 ЭОМ (Гараж) | E40: шт | F40: 1 | G40: =ПАРАМЕТРЫ!B18 -> 48.51 | H40: =ПАРАМЕТРЫ!D18 -> 11419.739 | I40: =F40*H40 -> 11419.739 | J40: TX3 16А 3P
...

Sheet СВОДНАЯ
A1: СВОДНАЯ ВЕДОМОСТЬ — Проект 260608 — ABB
A2: Раздел / Источник PDF | B2: Итого KZT | C2: Корпус Teksan f | D2: Щитов
A3: ЭОМ — ГАРАЖ | B3: =BOM!I16+BOM!I26+BOM!I35+BOM!I44+BOM!I51+BOM!I58+BOM!I66 -> 1903224.5 | C3: По запросу | D3: 7
A4: ЭО — КОНЦЕРТНЫЙ ЗАЛ | B4: =BOM!I77+BOM!I87+BOM!I97+BOM!I107+BOM!I117+BOM!I127+BOM!I137+BOM!I147+BOM!I157+BOM!I164+BOM!I171+BOM!I178+BOM!I185+BOM!I192+BOM!I199+BOM!I206 -> 1936035.6 | C4: По запросу | D4: 16
A5: ЭО — МУЗЕЙ | B5: =BOM!I217+BOM!I227+BOM!I237+BOM!I247+BOM!I257+BOM!I266+BOM!I275+BOM!I284+BOM!I293+BOM!I302+BOM!I309+BOM!I316+BOM!I323+BOM!I330+BOM!I337+BOM!I344+BOM!I351+BOM!I358+BOM!I365+BOM!I372 -> 1325307.2 | C5: По запросу | D5: 20
A6: ЭО — ГАЛЕРЕЯ | B6: =BOM!I383+BOM!I390 -> 132288.56 | C6: По запросу | D6: 2
A7: ЭН — НАРУЖНОЕ ОСВЕЩЕНИЕ | B7: =BOM!I401+BOM!I408 -> 250489.61 | C7: По запросу | D7: 2
A8: ФО — ФАСАД | B8: =BOM!I419+BOM!I428+BOM!I435+BOM!I442+BOM!I449+BOM!I456 -> 4804817.9 | C8: По запросу | D8: 6
A9: ИТОГО: | B9: =B3+B4+B5+B6+B7+B8 -> 10352163 | C9: TBD | D9: 53
A11: EUR/KZT, %, цены → лист ПАРАМЕТРЫ (синие ячейки)
