Workbook

Sheet ПАРАМЕТРЫ
A1: ПАРАМЕТРЫ — Проект 260608 — ABB
A2: Параметр | B2: Описание | C2: Значение (ред.)
A3: EUR/KZT курс | B3: Обновить с XE.com | C3: 590
A4: Коэф.скидки ABB (0.33) | B4: Скидка на покупку | C4: 0.3
A5: Коэф.надбавки (ABB EUR) | B5: Транспорт + накладные (только для EUR) | C5: 1.33
A6: Монтажные материалы % | B6: % от суммы компонентов | C6: 12
A7: Монтажная работа % | B7: % от суммы компонентов | C7: 15
A9: Ключ | B9: Наименование / Артикул | C9: Цена (список) (ред.) | D9: Цена нетто KZT (формула)
A10: S201-C6 | B10: Авт.выкл. 1P C6 S201-C6 [2CDS251001R0064] | C10: 12.92 | D10: =ПАРАМЕТРЫ!C10*ПАРАМЕТРЫ!$C$4*ПАРАМЕТРЫ!$C$5*ПАРАМЕТРЫ!$C$3 -> 3041.4972
A11: S201-C10 | B11: Авт.выкл. 1P C10 S201-C10 [2CDS251001R0104] | C11: 10.77 | D11: =ПАРАМЕТРЫ!C11*ПАРАМЕТРЫ!$C$4*ПАРАМЕТРЫ!$C$5*ПАРАМЕТРЫ!$C$3 -> 2535.3657
A12: S201-C16 | B12: Авт.выкл. 1P C16 S201-C16 [2CDS251001R0164] | C12: 10.77 | D12: =ПАРАМЕТРЫ!C12*ПАРАМЕТРЫ!$C$4*ПАРАМЕТРЫ!$C$5*ПАРАМЕТРЫ!$C$3 -> 2535.3657
A13: S201-C20 | B13: Авт.выкл. 1P C20 S201-C20 [2CDS251001R0204] | C13: 10.77 | D13: =ПАРАМЕТРЫ!C13*ПАРАМЕТРЫ!$C$4*ПАРАМЕТРЫ!$C$5*ПАРАМЕТРЫ!$C$3 -> 2535.3657
A14: S201-C25 | B14: Авт.выкл. 1P C25 S201-C25 [2CDS251001R0254] | C14: 10.77 | D14: =ПАРАМЕТРЫ!C14*ПАРАМЕТРЫ!$C$4*ПАРАМЕТРЫ!$C$5*ПАРАМЕТРЫ!$C$3 -> 2535.3657
A15: S201-C32 | B15: Авт.выкл. 1P C32 S201-C32 [2CDS251001R0324] | C15: 13.46 | D15: =ПАРАМЕТРЫ!C15*ПАРАМЕТРЫ!$C$4*ПАРАМЕТРЫ!$C$5*ПАРАМЕТРЫ!$C$3 -> 3168.6186
A16: S203-C6 | B16: Авт.выкл. 3P C6 S203-C6 [2CDS253001R0064] | C16: 58.16 | D16: =ПАРАМЕТРЫ!C16*ПАРАМЕТРЫ!$C$4*ПАРАМЕТРЫ!$C$5*ПАРАМЕТРЫ!$C$3 -> 13691.446
A17: S203-C10 | B17: Авт.выкл. 3P C10 S203-C10 [2CDS253001R0104] | C17: 48.51 | D17: =ПАРАМЕТРЫ!C17*ПАРАМЕТРЫ!$C$4*ПАРАМЕТРЫ!$C$5*ПАРАМЕТРЫ!$C$3 -> 11419.739
A18: S203-C16 | B18: Авт.выкл. 3P C16 S203-C16 [2CDS253001R0164] | C18: 48.51 | D18: =ПАРАМЕТРЫ!C18*ПАРАМЕТРЫ!$C$4*ПАРАМЕТРЫ!$C$5*ПАРАМЕТРЫ!$C$3 -> 11419.739
A19: S203-C20 | B19: Авт.выкл. 3P C20 S203-C20 [2CDS253001R0204] | C19: 48.51 | D19: =ПАРАМЕТРЫ!C19*ПАРАМЕТРЫ!$C$4*ПАРАМЕТРЫ!$C$5*ПАРАМЕТРЫ!$C$3 -> 11419.739
A20: S203-C25 | B20: Авт.выкл. 3P C25 S203-C25 [2CDS253001R0254] | C20: 48.51 | D20: =ПАРАМЕТРЫ!C20*ПАРАМЕТРЫ!$C$4*ПАРАМЕТРЫ!$C$5*ПАРАМЕТРЫ!$C$3 -> 11419.739
A21: S203-C32 | B21: Авт.выкл. 3P C32 S203-C32 [2CDS253001R0324] | C21: 60.59 | D21: =ПАРАМЕТРЫ!C21*ПАРАМЕТРЫ!$C$4*ПАРАМЕТРЫ!$C$5*ПАРАМЕТРЫ!$C$3 -> 14263.492
... A51: TL1 | B51: Фотореле TL1 * 2CSM229921R1341 | C51: 136.7 | D51: =ПАРАМЕТРЫ!C51*ПАРАМЕТРЫ!$C$4*ПАРАМЕТРЫ!$C$5*ПАРАМЕТРЫ!$C$3 -> 32180.547
A52: JXB24A | B52: Зажим наборный ЗНИ-2,5мм2 (серый) JXB24A | D52: =ПАРАМЕТРЫ!C52*ПАРАМЕТРЫ!$C$4*ПАРАМЕТРЫ!$C$5*ПАРАМЕТРЫ!$C$3 -> 0
A53: S 203-C 40 | B53: Авт.выкл. 3P C40 S 203-C 40 2CDS253001R0404 | C53: 63.02 | D53: =ПАРАМЕТРЫ!C53*ПАРАМЕТРЫ!$C$4*ПАРАМЕТРЫ!$C$5*ПАРАМЕТРЫ!$C$3 -> 14835.538
A54: DS301C C10 | B54: DS301C C10 AC30 2CSR255063R1104 | C54: 180.4 | D54: =ПАРАМЕТРЫ!C54*ПАРАМЕТРЫ!$C$4*ПАРАМЕТРЫ!$C$5*ПАРАМЕТРЫ!$C$3 -> 42467.964
A55: DS301C C10 | B55: DS301C C10 AC30 2CSR255063R1104 | C55: 180.4 | D55: =ПАРАМЕТРЫ!C55*ПАРАМЕТРЫ!$C$4*ПАРАМЕТРЫ!$C$5*ПАРАМЕТРЫ!$C$3 -> 42467.964
A56: 1SDA066460R1 | B56: MOD motor 220...250 V AC/DC | C56: 675.1 | D56: =ПАРАМЕТРЫ!C56*ПАРАМЕТРЫ!$C$4*ПАРАМЕТРЫ!$C$5*ПАРАМЕТРЫ!$C$3 -> 158925.29

Sheet BOM
C1: СПЕЦИФИКАЦИЯ ОБОРУДОВАНИЯ — Проект 260608 — г.Атырау — ABB | Формула: KZT = EUR_list × 0.33 × 1.30 × EUR/KZT | Параметры → лист ПАРАМЕТРЫ (синие ячейки)
A2: pano ismi | B2: № | C2: Тип / Марка / Артикул | D2: Наименование и техническая характеристика | E2: Цена список | F2: KZT нетто | G2: Сумма KZT | H2: Ед. | I2: Кол. | J2: Примечание | K2: Источник (PDF альбом)
A3: =D3 -> КОМПЛЕКТ 1. ГРЩ (ЩМП-18.8.4-0 36 УХЛ3 IP31) | Альбом 7.4 ЭОМ (Гараж) | B3: =D3 -> КОМПЛЕКТ 1. ГРЩ (ЩМП-18.8.4-0 36 УХЛ3 IP31) | Альбом 7.4 ЭОМ (Гараж) | D3: КОМПЛЕКТ 1. ГРЩ (ЩМП-18.8.4-0 36 УХЛ3 IP31) | Альбом 7.4 ЭОМ (Гараж) | H3: компл. | I3: 1
A4: =A3 -> КОМПЛЕКТ 1. ГРЩ (ЩМП-18.8.4-0 36 УХЛ3 IP31) | Альбом 7.4 ЭОМ (Гараж) | B4: 1.1 | C4: Teksan f | D4: Корпус — ЩМП-18.8.4,5+1 bz-0 36 УХЛ3 IP31 | E4: 165000 | F4: =0.6*E4 -> 99000 | G4: =F4*I4 -> 99000 | H4: шт | I4: 1 | J4: Teksan f — цена TBD | K4: Альбом 7.4 ЭОМ (Гараж)
A5: =A4 -> КОМПЛЕКТ 1. ГРЩ (ЩМП-18.8.4-0 36 УХЛ3 IP31) | Альбом 7.4 ЭОМ (Гараж) | B5: 1.2 | C5: 1SDA067417R1 | D5: Авт.выкл. 3P 125А XT1N 160 TMD | E5: =ПАРАМЕТРЫ!C32 -> 308.8 | F5: =E5*0.3*1.33*590 -> 72694.608 | G5: =I5*F5 -> 290778.43 | H5: шт | I5: 4 | J5: DPX3 125А / вводной аналог | K5: Альбом 7.4 ЭОМ (Гараж)
A6: =A5 -> КОМПЛЕКТ 1. ГРЩ (ЩМП-18.8.4-0 36 УХЛ3 IP31) | Альбом 7.4 ЭОМ (Гараж) | B6: 1.3 | C6: 1SDA066460R1 | D6: MOD motor 220...250 V AC/DC | E6: 675.1 | F6: =E6*0.3*1.33*590 -> 158925.29 | G6: =I6*F6 -> 635701.16 | H6: шт | I6: 4 | J6: Motor | K6: Альбом 7.4 ЭОМ (Гараж)
A7: =A6 -> КОМПЛЕКТ 1. ГРЩ (ЩМП-18.8.4-0 36 УХЛ3 IP31) | Альбом 7.4 ЭОМ (Гараж) | B7: 1.3 | C7: 1SDA066325R1 | D7: SOR-C 220-240V AC/220-250V DC | E7: 115.1 | F7: =E7*0.3*1.33*590 -> 27095.691 | G7: =I7*F7 -> 54191.382 | H7: шт | I7: 2 | J7: Açtırma Bobini | K7: Альбом 7.4 ЭОМ (Гараж)
A8: =A7 -> КОМПЛЕКТ 1. ГРЩ (ЩМП-18.8.4-0 36 УХЛ3 IP31) | Альбом 7.4 ЭОМ (Гараж) | B8: 1.3 | C8: 1SDA066399R1 | D8: UVR-C 220-240V AC/220-250V DC | E8: 132.3 | F8: =E8*0.3*1.33*590 -> 31144.743 | G8: =I8*F8 -> 62289.486 | H8: шт | I8: 2 | J8: Düsük Gerilim Bobini | K8: Альбом 7.4 ЭОМ (Гараж)
A9: =A8 -> КОМПЛЕКТ 1. ГРЩ (ЩМП-18.8.4-0 36 УХЛ3 IP31) | Альбом 7.4 ЭОМ (Гараж) | B9: 1.3 | C9: 1SDA066431R1 | D9: AUX-C 1A/K+1SY 250V AC/DC | E9: 72.77 | F9: =E9*0.3*1.33*590 -> 17130.786 | G9: =I9*F9 -> 34261.571 | H9: шт | I9: 2 | J9: Düsük Gerilim Bobini | K9: Альбом 7.4 ЭОМ (Гараж)
A10: =A9 -> КОМПЛЕКТ 1. ГРЩ (ЩМП-18.8.4-0 36 УХЛ3 IP31) | Альбом 7.4 ЭОМ (Гараж) | B10: 1.3 | C10: 1SDA067416R1 | D10: Авт.выкл. 3P 100А XT1N 160 TMD | E10: =ПАРАМЕТРЫ!C31 -> 246.1 | F10: =E10*0.3*1.33*590 -> 57934.401 | G10: =I10*F10 -> 57934.401 | H10: шт | I10: 1 | J10: Резервный ввод | K10: Альбом 7.4 ЭОМ (Гараж)
A11: =A10 -> КОМПЛЕКТ 1. ГРЩ (ЩМП-18.8.4-0 36 УХЛ3 IP31) | Альбом 7.4 ЭОМ (Гараж) | B11: 1.4 | C11: 2CDS213001R0204 | D11: Авт.выкл. 3P C20 SH 203-C 20 | E11: 36.42 | F11: =E11*0.3*1.33*590 -> 8573.6322 | G11: =I11*F11 -> 42868.161 | H11: шт | I11: 5 | J11: TX3 20A 3P | K11: Альбом 7.4 ЭОМ (Гараж)
A12: =A11 -> КОМПЛЕКТ 1. ГРЩ (ЩМП-18.8.4-0 36 УХЛ3 IP31) | Альбом 7.4 ЭОМ (Гараж) | B12: 1.5 | C12: 2CDS213001R0254 | D12: Авт.выкл. 3P C25 SH 203-C 25 | E12: 36.42 | F12: =E12*0.3*1.33*590 -> 8573.6322 | G12: =I12*F12 -> 17147.264 | H12: шт | I12: 2 | J12: TX3 25A 3P | K12: Альбом 7.4 ЭОМ (Гараж)
A13: =A12 -> КОМПЛЕКТ 1. ГРЩ (ЩМП-18.8.4-0 36 УХЛ3 IP31) | Альбом 7.4 ЭОМ (Гараж) | B13: 1.6 | C13: 2CDS211001R0064 | D13: Авт.выкл. 1P C6 SH 201-C 6 | E13: 9.71 | F13: =E13*0.3*1.33*590 -> 2285.8311 | G13: =I13*F13 -> 6857.4933 | H13: шт | I13: 3 | J13: TX3 6A 1P | K13: Альбом 7.4 ЭОМ (Гараж)
A14: =A13 -> КОМПЛЕКТ 1. ГРЩ (ЩМП-18.8.4-0 36 УХЛ3 IP31) | Альбом 7.4 ЭОМ (Гараж) | B14: 1.7 | C14: 1SCA120070R1001 | D14: АВР 3P 125А OTM125F3CMA230V | E14: =ПАРАМЕТРЫ!C35 -> 1285 | F14: =E14*0.3*1.33*590 -> 302501.85 | G14: =I14*F14 -> 302501.85 | H14: шт | I14: 1 | J14: АВР TransferPact аналог | K14: Альбом 7.4 ЭОМ (Гараж)
A15: =A14 -> КОМПЛЕКТ 1. ГРЩ (ЩМП-18.8.4-0 36 УХЛ3 IP31) | Альбом 7.4 ЭОМ (Гараж) | B15: 1.8 | C15: По запросу | D15: УКРМ 10кВАр 400В, 800×700×250мм | E15: — | F15: — | G15: 0 | H15: шт | I15: 2 | J15: КРМ — 2 шт (ввод1+ввод2) — цена TBD | K15: Альбом 7.4 ЭОМ (Гараж)
A16: =A15 -> КОМПЛЕКТ 1. ГРЩ (ЩМП-18.8.4-0 36 УХЛ3 IP31) | Альбом 7.4 ЭОМ (Гараж) | B16: 1.9 | C16: Энергомера СЕ 303 S31 746-JPVZ PLC 1111, 100А, 380В | D16: Счётчик электроэнергии 3ф 100А 380В | E16: 100000 | F16: =E16 -> 100000 | G16: =F16*I16 -> 300000 | H16: шт | I16: 3 | J16: Счётчик/прибор — 3 шт — по одному на каждый ввод ГРЩ — цена По запросу | K16: Альбом 7.4 ЭОМ (Гараж)
A17: =A16 -> КОМПЛЕКТ 1. ГРЩ (ЩМП-18.8.4-0 36 УХЛ3 IP31) | Альбом 7.4 ЭОМ (Гараж) | B17: 1.10 | D17: Монтажный материал | E17: — | F17: =ПАРАМЕТРЫ!C6&"%" -> 12% | G17: =(G5+G10+G11+G12+G13+G14+G15+G16)*ПАРАМЕТРЫ!C6/100 -> 122170.51 | H17: шт | I17: 1 | J17: % от суммы компонентов | K17: Альбом 7.4 ЭОМ (Гараж)
A18: =A17 -> КОМПЛЕКТ 1. ГРЩ (ЩМП-18.8.4-0 36 УХЛ3 IP31) | Альбом 7.4 ЭОМ (Гараж) | B18: 1.11 | D18: Монтажная работа | E18: — | F18: =ПАРАМЕТРЫ!C7&"%" -> 15% | G18: =(G5+G10+G11+G12+G13+G14+G15+G16)*ПАРАМЕТРЫ!C7/100 -> 152713.14 | H18: шт | I18: 1 | J18: % от суммы компонентов | K18: Альбом 7.4 ЭОМ (Гараж)
A19: =D19 -> КОМПЛЕКТ 2. ЩС-В (ЩРн-12з-0 36 УХЛ3 IP54) | Альбом 7.4 ЭОМ (Гараж) | B19: КОМПЛЕКТ 2. ЩС-В (ЩРн-12з-0 36 УХЛ3 IP54) | Альбом 7.4 ЭОМ (Гараж) | D19: КОМПЛЕКТ 2. ЩС-В (ЩРн-12з-0 36 УХЛ3 IP54) | Альбом 7.4 ЭОМ (Гараж) | H19: компл. | I19: 1
A20: =A19 -> КОМПЛЕКТ 2. ЩС-В (ЩРн-12з-0 36 УХЛ3 IP54) | Альбом 7.4 ЭОМ (Гараж) | B20: 2.1 | C20: Teksan f | D20: Корпус — ЩРн-12з-0 36 УХЛ3 IP54 | E20: 10500 | F20: =0.6*E20 -> 6300 | G20: =F20*I20 -> 6300 | H20: шт | I20: 1 | J20: Teksan f — цена TBD | K20: Альбом 7.4 ЭОМ (Гараж)
A21: =A20 -> КОМПЛЕКТ 2. ЩС-В (ЩРн-12з-0 36 УХЛ3 IP54) | Альбом 7.4 ЭОМ (Гараж) | B21: 2.2 | C21: 2CDS253001R0204 | D21: Авт.выкл. 3P C20 S 203-C 20 | E21: 48.51 | F21: =E21*0.3*1.33*590 -> 11419.739 | G21: =I21*F21 -> 11419.739 | H21: шт | I21: 1 | J21: Ввод QF1 20А 3P | K21: Альбом 7.4 ЭОМ (Гараж)
A22: =A21 -> КОМПЛЕКТ 2. ЩС-В (ЩРн-12з-0 36 УХЛ3 IP54) | Альбом 7.4 ЭОМ (Гараж) | B22: 2.3 | C22: 2CDS211001R0164 | D22: Авт.выкл. 1P C16 SH 201-C 16 | E22: 8.09 | F22: =E22*0.3*1.33*590 -> 1904.4669 | G22: =I22*F22 -> 3808.9338 | H22: шт | I22: 2 | J22: SF2, SF3 | K22: Альбом 7.4 ЭОМ (Гараж)
A23: =A22 -> КОМПЛЕКТ 2. ЩС-В (ЩРн-12з-0 36 УХЛ3 IP54) | Альбом 7.4 ЭОМ (Гараж) | B23: 2.4 | C23: 2CDS213001R0164 | D23: Авт.выкл. 3P C16 SH 203-C 16 | E23: 36.42 | F23: =E23*0.3*1.33*590 -> 8573.6322 | G23: =I23*F23 -> 8573.6322 | H23: шт | I23: 1 | J23: TX3 16А 3P | K23: Альбом 7.4 ЭОМ (Гараж)
A24: =A23 -> КОМПЛЕКТ 2. ЩС-В (ЩРн-12з-0 36 УХЛ3 IP54) | Альбом 7.4 ЭОМ (Гараж) | B24: 2.5 | C24: 1SBE111111R0611 | D24: Контактор 16А ESB16-11N 230В | E24: =ПАРАМЕТРЫ!C33 -> 41.58 | F24: =E24*0.3*1.33*590 -> 9788.3478 | G24: =I24*F24 -> 0 | H24: шт | I24: 0 | J24: КМИ 10910 9А — В1+В2+В3 | K24: Альбом 7.4 ЭОМ (Гараж)
A25: =A24 -> КОМПЛЕКТ 2. ЩС-В (ЩРн-12з-0 36 УХЛ3 IP54) | Альбом 7.4 ЭОМ (Гараж) | B25: 2.6 | C25: 2CDS200982R0001 | D25: Независимый расцепитель S3C-A1 AC/DC 12-110V | E25: =ПАРАМЕТРЫ!C36 -> 62.93 | F25: =E25*0.3*1.33*590 -> 14814.351 | G25: =I25*F25 -> 14814.351 | H25: шт | I25: 1 | J25: Независимый расцепитель DRX — пожарный сигнал | K25: Альбом 7.4 ЭОМ (Гараж)
A26: =A25 -> КОМПЛЕКТ 2. ЩС-В (ЩРн-12з-0 36 УХЛ3 IP54) | Альбом 7.4 ЭОМ (Гараж) | B26: 2.7 | D26: Монтажный материал | E26: — | F26: =ПАРАМЕТРЫ!C6&"%" -> 12% | G26: =(G21+G22+G24+G25+G23)*ПАРАМЕТРЫ!C6/100 -> 4633.9988 | H26: шт | I26: 1 | J26: % от суммы компонентов | K26: Альбом 7.4 ЭОМ (Гараж)
A27: =A26 -> КОМПЛЕКТ 2. ЩС-В (ЩРн-12з-0 36 УХЛ3 IP54) | Альбом 7.4 ЭОМ (Гараж) | B27: 2.8 | D27: Монтажная работа | E27: — | F27: =ПАРАМЕТРЫ!C7&"%" -> 15% | G27: =(G21+G22+G24+G25+G23)*ПАРАМЕТРЫ!C7/100 -> 5792.4985 | H27: шт | I27: 1 | J27: % от суммы компонентов | K27: Альбом 7.4 ЭОМ (Гараж)
A28: =D28 -> КОМПЛЕКТ 3. ЩС-П (ЩРн-24з-0 36 УХЛ3 IP54) | Альбом 7.4 ЭОМ (Гараж) | B28: КОМПЛЕКТ 3. ЩС-П (ЩРн-24з-0 36 УХЛ3 IP54) | Альбом 7.4 ЭОМ (Гараж) | D28: КОМПЛЕКТ 3. ЩС-П (ЩРн-24з-0 36 УХЛ3 IP54) | Альбом 7.4 ЭОМ (Гараж) | H28: компл. | I28: 1
A29: =A28 -> КОМПЛЕКТ 3. ЩС-П (ЩРн-24з-0 36 УХЛ3 IP54) | Альбом 7.4 ЭОМ (Гараж) | B29: 3.1 | C29: Teksan f | D29: Корпус — ЩРн-24з-0 36 УХЛ3 IP54 | E29: 15500 | F29: =0.6*E29 -> 9300 | G29: =F29*I29 -> 9300 | H29: шт | I29: 1 | J29: Teksan f — цена TBD | K29: Альбом 7.4 ЭОМ (Гараж)
A30: =A29 -> КОМПЛЕКТ 3. ЩС-П (ЩРн-24з-0 36 УХЛ3 IP54) | Альбом 7.4 ЭОМ (Гараж) | B30: 3.2 | C30: 2CDS213001R0254 | D30: SH 203-C 25 | E30: =ПАРАМЕТРЫ!C20 -> 48.51 | F30: =E30*0.3*1.33*590 -> 11419.739 | G30: =I30*F30 -> 11419.739 | H30: шт | I30: 1 | J30: ВН-32 25А | K30: Альбом 7.4 ЭОМ (Гараж)
A31: =A30 -> КОМПЛЕКТ 3. ЩС-П (ЩРн-24з-0 36 УХЛ3 IP54) | Альбом 7.4 ЭОМ (Гараж) | B31: 3.3 | C31: 2CSR255080R1164 | D31: Диф.авт. 1P+N C16 30мА DS201 C16 AC30 | E31: =ПАРАМЕТРЫ!C23 -> 87.63 | F31: =E31*0.3*1.33*590 -> 20628.978 | G31: =I31*F31 -> 144402.85 | H31: шт | I31: 7 | J31: АВДТ DX3 1P+N 16А 30мА | K31: Альбом 7.4 ЭОМ (Гараж)
A32: =A31 -> КОМПЛЕКТ 3. ЩС-П (ЩРн-24з-0 36 УХЛ3 IP54) | Альбом 7.4 ЭОМ (Гараж) | B32: 3.5 | C32: 2CDS211001R0164 | D32: Авт.выкл. 1P C16 SH 201-C 16 | E32: 8.09 | F32: =E32*0.3*1.33*590 -> 1904.4669 | G32: =I32*F32 -> 1904.4669 | H32: шт | I32: 1 | J32: TX3 16А 1P | K32: Альбом 7.4 ЭОМ (Гараж)
A33: =A32 -> КОМПЛЕКТ 3. ЩС-П (ЩРн-24з-0 36 УХЛ3 IP54) | Альбом 7.4 ЭОМ (Гараж) | B33: 3.6 | D33: Монтажный материал | E33: — | F33: =ПАРАМЕТРЫ!C6&"%" -> 12% | G33: 9000 | H33: шт | I33: 1 | J33: % от суммы компонентов | K33: Альбом 7.4 ЭОМ (Гараж)
A34: =A33 -> КОМПЛЕКТ 3. ЩС-П (ЩРн-24з-0 36 УХЛ3 IP54) | Альбом 7.4 ЭОМ (Гараж) | B34: 3.7 | D34: Монтажная работа | E34: — | F34: =ПАРАМЕТРЫ!C7&"%" -> 15% | G34: 9000 | H34: шт | I34: 1 | J34: % от суммы компонентов | K34: Альбом 7.4 ЭОМ (Гараж)
A35: =D35 -> КОМПЛЕКТ 4. ЩС-ПО (ЩРн-12з-0 36 УХЛ3 IP54) | Альбом 7.4 ЭОМ (Гараж) | B35: КОМПЛЕКТ 4. ЩС-ПО (ЩРн-12з-0 36 УХЛ3 IP54) | Альбом 7.4 ЭОМ (Гараж) | D35: КОМПЛЕКТ 4. ЩС-ПО (ЩРн-12з-0 36 УХЛ3 IP54) | Альбом 7.4 ЭОМ (Гараж) | H35: компл. | I35: 1
A36: =A35 -> КОМПЛЕКТ 4. ЩС-ПО (ЩРн-12з-0 36 УХЛ3 IP54) | Альбом 7.4 ЭОМ (Гараж) | B36: 4.1 | C36: Teksan f | D36: Корпус — ЩРн-18з-0 36 УХЛ3 IP54 | E36: 10500 | F36: =0.6*E36 -> 6300 | G36: =F36*I36 -> 6300 | H36: шт | I36: 1 | J36: Teksan f — цена TBD | K36: Альбом 7.4 ЭОМ (Гараж)
A37: =A36 -> КОМПЛЕКТ 4. ЩС-ПО (ЩРн-12з-0 36 УХЛ3 IP54) | Альбом 7.4 ЭОМ (Гараж) | B37: 4.2 | C37: 2CDS253001R0824 | D37: S 203-C 100 | E37: =ПАРАМЕТРЫ!C29 -> 100.1 | F37: =E37*0.3*1.33*590 -> 23564.541 | G37: =I37*F37 -> 23564.541 | H37: шт | I37: 1 | J37: ВН-32 100А | K37: Альбом 7.4 ЭОМ (Гараж)
A38: =A37 -> КОМПЛЕКТ 4. ЩС-ПО (ЩРн-12з-0 36 УХЛ3 IP54) | Альбом 7.4 ЭОМ (Гараж) | B38: 4.3 | C38: 2CDS253001R0824 | D38: S 203-C 80 | E38: =ПАРАМЕТРЫ!C40 -> 193.8 | F38: =E38*0.3*1.33*590 -> 45622.458 | G38: =I38*F38 -> 45622.458 | H38: шт | I38: 1 | J38: DPX3 80А — Дп1 | K38: Альбом 7.4 ЭОМ (Гараж)
A39: =A38 -> КОМПЛЕКТ 4. ЩС-ПО (ЩРн-12з-0 36 УХЛ3 IP54) | Альбом 7.4 ЭОМ (Гараж) | B39: 4.4 | C39: 2CDS213001R0164 | D39: Авт.выкл. 3P C16 SH 203-C 16 | E39: 36.42 | F39: =E39*0.3*1.33*590 -> 8573.6322 | G39: =I39*F39 -> 8573.6322 | H39: шт | I39: 1 | J39: TX3 16А 3P | K39: Альбом 7.4 ЭОМ (Гараж)
A40: =A39 -> КОМПЛЕКТ 4. ЩС-ПО (ЩРн-12з-0 36 УХЛ3 IP54) | Альбом 7.4 ЭОМ (Гараж) | B40: 4.5 | C40: 2CDS211001R0164 | D40: Авт.выкл. 1P C16 SH 201-C 16 | E40: 8.09 | F40: =E40*0.3*1.33*590 -> 1904.4669 | G40: =I40*F40 -> 1904.4669 | H40: шт | I40: 1 | J40: TX3 16А 1P | K40: Альбом 7.4 ЭОМ (Гараж)
...

Sheet Sayfa1
C1: СПЕЦИФИКАЦИЯ ОБОРУДОВАНИЯ — Проект 260608 — г.Атырау — ABB | Формула: KZT = EUR_list × 0.33 × 1.30 × EUR/KZT | Параметры → лист ПАРАМЕТРЫ (синие ячейки)
A2: pano ismi | B2: № | C2: Тип / Марка / Артикул | D2: Наименование и техническая характеристика | E2: Цена список | F2: KZT нетто | G2: Сумма KZT | H2: Ед. | I2: Кол. | J2: Примечание | K2: Источник (PDF альбом)
C3: ─── ЭОМ — ГАРАЖ ───
A4: =D4 -> КОМПЛЕКТ 1. ГРЩ (ЩМП-18.8.4-0 36 УХЛ3 IP31) | Альбом 7.4 ЭОМ (Гараж) | B4: =D4 -> КОМПЛЕКТ 1. ГРЩ (ЩМП-18.8.4-0 36 УХЛ3 IP31) | Альбом 7.4 ЭОМ (Гараж) | D4: КОМПЛЕКТ 1. ГРЩ (ЩМП-18.8.4-0 36 УХЛ3 IP31) | Альбом 7.4 ЭОМ (Гараж) | H4: компл. | I4: 1
A5: =A4 -> КОМПЛЕКТ 1. ГРЩ (ЩМП-18.8.4-0 36 УХЛ3 IP31) | Альбом 7.4 ЭОМ (Гараж) | B5: 1.1 | C5: Teksan f | D5: Корпус — ЩМП-18.8.4,5+1 bz-0 36 УХЛ3 IP31 | E5: — | F5: — | G5: 0 | H5: шт | I5: 2 | J5: Teksan f — цена TBD | K5: Альбом 7.4 ЭОМ (Гараж)
A6: =A5 -> КОМПЛЕКТ 1. ГРЩ (ЩМП-18.8.4-0 36 УХЛ3 IP31) | Альбом 7.4 ЭОМ (Гараж) | B6: 1.2 | C6: 1SDA067417R1 | D6: Авт.выкл. 3P 125А XT1N 160 TMD | E6: =ПАРАМЕТРЫ!C32 -> 308.8 | F6: =E6*0.3*1.33*590 -> 72694.608 | G6: =I6*F6 -> 290778.43 | H6: шт | I6: 4 | J6: DPX3 125А / вводной аналог | K6: Альбом 7.4 ЭОМ (Гараж)
A7: =A6 -> КОМПЛЕКТ 1. ГРЩ (ЩМП-18.8.4-0 36 УХЛ3 IP31) | Альбом 7.4 ЭОМ (Гараж) | B7: 1.3 | C7: 1SDA066460R1 | D7: MOD motor 220...250 V AC/DC | E7: 675.1 | F7: =E7*0.3*1.33*590 -> 158925.29 | G7: =I7*F7 -> 635701.16 | H7: шт | I7: 4 | J7: Motor | K7: Альбом 7.4 ЭОМ (Гараж)
A8: =A7 -> КОМПЛЕКТ 1. ГРЩ (ЩМП-18.8.4-0 36 УХЛ3 IP31) | Альбом 7.4 ЭОМ (Гараж) | B8: 1.3 | C8: 1SDA066325R1 | D8: SOR-C 220-240V AC/220-250V DC | E8: 115.1 | F8: =E8*0.3*1.33*590 -> 27095.691 | G8: =I8*F8 -> 54191.382 | H8: шт | I8: 2 | J8: Açtırma Bobini | K8: Альбом 7.4 ЭОМ (Гараж)
A9: =A8 -> КОМПЛЕКТ 1. ГРЩ (ЩМП-18.8.4-0 36 УХЛ3 IP31) | Альбом 7.4 ЭОМ (Гараж) | B9: 1.3 | C9: 1SDA066399R1 | D9: UVR-C 220-240V AC/220-250V DC | E9: 132.3 | F9: =E9*0.3*1.33*590 -> 31144.743 | G9: =I9*F9 -> 62289.486 | H9: шт | I9: 2 | J9: Düsük Gerilim Bobini | K9: Альбом 7.4 ЭОМ (Гараж)
A10: =A9 -> КОМПЛЕКТ 1. ГРЩ (ЩМП-18.8.4-0 36 УХЛ3 IP31) | Альбом 7.4 ЭОМ (Гараж) | B10: 1.3 | C10: 1SDA066431R1 | D10: AUX-C 1A/K+1SY 250V AC/DC | E10: 72.77 | F10: =E10*0.3*1.33*590 -> 17130.786 | G10: =I10*F10 -> 34261.571 | H10: шт | I10: 2 | J10: Düsük Gerilim Bobini | K10: Альбом 7.4 ЭОМ (Гараж)
A11: =A10 -> КОМПЛЕКТ 1. ГРЩ (ЩМП-18.8.4-0 36 УХЛ3 IP31) | Альбом 7.4 ЭОМ (Гараж) | B11: 1.3 | C11: 1SDA067416R1 | D11: Авт.выкл. 3P 100А XT1N 160 TMD | E11: =ПАРАМЕТРЫ!C31 -> 246.1 | F11: =E11*0.3*1.33*590 -> 57934.401 | G11: =I11*F11 -> 57934.401 | H11: шт | I11: 1 | J11: Резервный ввод | K11: Альбом 7.4 ЭОМ (Гараж)
A12: =A11 -> КОМПЛЕКТ 1. ГРЩ (ЩМП-18.8.4-0 36 УХЛ3 IP31) | Альбом 7.4 ЭОМ (Гараж) | B12: 1.4 | C12: 2CDS213001R0204 | D12: Авт.выкл. 3P C20 SH 203-C 20 | E12: 36.42 | F12: =E12*0.3*1.33*590 -> 8573.6322 | G12: =I12*F12 -> 42868.161 | H12: шт | I12: 5 | J12: TX3 20A 3P | K12: Альбом 7.4 ЭОМ (Гараж)
A13: =A12 -> КОМПЛЕКТ 1. ГРЩ (ЩМП-18.8.4-0 36 УХЛ3 IP31) | Альбом 7.4 ЭОМ (Гараж) | B13: 1.5 | C13: 2CDS213001R0254 | D13: Авт.выкл. 3P C25 SH 203-C 25 | E13: 36.42 | F13: =E13*0.3*1.33*590 -> 8573.6322 | G13: =I13*F13 -> 17147.264 | H13: шт | I13: 2 | J13: TX3 25A 3P | K13: Альбом 7.4 ЭОМ (Гараж)
A14: =A13 -> КОМПЛЕКТ 1. ГРЩ (ЩМП-18.8.4-0 36 УХЛ3 IP31) | Альбом 7.4 ЭОМ (Гараж) | B14: 1.6 | C14: 2CDS211001R0064 | D14: Авт.выкл. 1P C6 SH 201-C 6 | E14: 9.71 | F14: =E14*0.3*1.33*590 -> 2285.8311 | G14: =I14*F14 -> 6857.4933 | H14: шт | I14: 3 | J14: TX3 6A 1P | K14: Альбом 7.4 ЭОМ (Гараж)
A15: =A14 -> КОМПЛЕКТ 1. ГРЩ (ЩМП-18.8.4-0 36 УХЛ3 IP31) | Альбом 7.4 ЭОМ (Гараж) | B15: 1.7 | C15: 1SCA120070R1001 | D15: АВР 3P 125А OTM125F3CMA230V | E15: =ПАРАМЕТРЫ!C35 -> 1285 | F15: =E15*0.3*1.33*590 -> 302501.85 | G15: =I15*F15 -> 302501.85 | H15: шт | I15: 1 | J15: АВР TransferPact аналог | K15: Альбом 7.4 ЭОМ (Гараж)
A16: =A15 -> КОМПЛЕКТ 1. ГРЩ (ЩМП-18.8.4-0 36 УХЛ3 IP31) | Альбом 7.4 ЭОМ (Гараж) | B16: 1.8 | C16: По запросу | D16: УКРМ 10кВАр 400В, 800×700×250мм | E16: — | F16: — | G16: 0 | H16: шт | I16: 2 | J16: КРМ — 2 шт (ввод1+ввод2) — цена TBD | K16: Альбом 7.4 ЭОМ (Гараж)
A17: =A16 -> КОМПЛЕКТ 1. ГРЩ (ЩМП-18.8.4-0 36 УХЛ3 IP31) | Альбом 7.4 ЭОМ (Гараж) | B17: 1.9 | C17: Энергомера СЕ 303 S31 746-JPVZ PLC 1111, 100А, 380В | D17: Счётчик электроэнергии 3ф 100А 380В | E17: — | F17: — | G17: 0 | H17: шт | I17: 3 | J17: Счётчик/прибор — 3 шт — по одному на каждый ввод ГРЩ — цена По запросу | K17: Альбом 7.4 ЭОМ (Гараж)
A18: =A17 -> КОМПЛЕКТ 1. ГРЩ (ЩМП-18.8.4-0 36 УХЛ3 IP31) | Альбом 7.4 ЭОМ (Гараж) | B18: 1.10 | D18: Монтажный материал | E18: — | F18: =ПАРАМЕТРЫ!C6&"%" -> 12% | G18: =(G6+G11+G12+G13+G14+G15+G16+G17)*ПАРАМЕТРЫ!C6/100 -> 86170.512 | H18: шт | I18: 1 | J18: % от суммы компонентов | K18: Альбом 7.4 ЭОМ (Гараж)
A19: =A18 -> КОМПЛЕКТ 1. ГРЩ (ЩМП-18.8.4-0 36 УХЛ3 IP31) | Альбом 7.4 ЭОМ (Гараж) | B19: 1.11 | D19: Монтажная работа | E19: — | F19: =ПАРАМЕТРЫ!C7&"%" -> 15% | G19: =(G6+G11+G12+G13+G14+G15+G16+G17)*ПАРАМЕТРЫ!C7/100 -> 107713.14 | H19: шт | I19: 1 | J19: % от суммы компонентов | K19: Альбом 7.4 ЭОМ (Гараж)
A20: =D20 -> КОМПЛЕКТ 2. ЩС-В (ЩРн-12з-0 36 УХЛ3 IP54) | Альбом 7.4 ЭОМ (Гараж) | B20: КОМПЛЕКТ 2. ЩС-В (ЩРн-12з-0 36 УХЛ3 IP54) | Альбом 7.4 ЭОМ (Гараж) | D20: КОМПЛЕКТ 2. ЩС-В (ЩРн-12з-0 36 УХЛ3 IP54) | Альбом 7.4 ЭОМ (Гараж) | H20: компл. | I20: 1
A21: =A20 -> КОМПЛЕКТ 2. ЩС-В (ЩРн-12з-0 36 УХЛ3 IP54) | Альбом 7.4 ЭОМ (Гараж) | B21: 2.1 | C21: Teksan f | D21: Корпус — ЩРн-24з-0 36 УХЛ3 IP54 | E21: — | F21: — | G21: 0 | H21: шт | I21: 1 | J21: Teksan f — цена TBD | K21: Альбом 7.4 ЭОМ (Гараж)
A22: =A21 -> КОМПЛЕКТ 2. ЩС-В (ЩРн-12з-0 36 УХЛ3 IP54) | Альбом 7.4 ЭОМ (Гараж) | B22: 2.2 | C22: 2CDS253001R0204 | D22: Авт.выкл. 3P C20 S 203-C 20 | E22: 48.51 | F22: =E22*0.3*1.33*590 -> 11419.739 | G22: =I22*F22 -> 11419.739 | H22: шт | I22: 1 | J22: Ввод QF1 20А 3P | K22: Альбом 7.4 ЭОМ (Гараж)
A23: =A22 -> КОМПЛЕКТ 2. ЩС-В (ЩРн-12з-0 36 УХЛ3 IP54) | Альбом 7.4 ЭОМ (Гараж) | B23: 2.3 | C23: 2CDS211001R0164 | D23: Авт.выкл. 1P C16 SH 201-C 16 | E23: 8.09 | F23: =E23*0.3*1.33*590 -> 1904.4669 | G23: =I23*F23 -> 3808.9338 | H23: шт | I23: 2 | J23: SF2, SF3 | K23: Альбом 7.4 ЭОМ (Гараж)
A24: =A23 -> КОМПЛЕКТ 2. ЩС-В (ЩРн-12з-0 36 УХЛ3 IP54) | Альбом 7.4 ЭОМ (Гараж) | B24: 2.4 | C24: 2CDS213001R0164 | D24: Авт.выкл. 3P C16 SH 203-C 16 | E24: 36.42 | F24: =E24*0.3*1.33*590 -> 8573.6322 | G24: =I24*F24 -> 8573.6322 | H24: шт | I24: 1 | J24: TX3 16А 3P | K24: Альбом 7.4 ЭОМ (Гараж)
A25: =A24 -> КОМПЛЕКТ 2. ЩС-В (ЩРн-12з-0 36 УХЛ3 IP54) | Альбом 7.4 ЭОМ (Гараж) | B25: 2.5 | C25: 1SBE111111R0611 | D25: Контактор 16А ESB16-11N 230В | E25: =ПАРАМЕТРЫ!C33 -> 41.58 | F25: =E25*0.3*1.33*590 -> 9788.3478 | G25: =I25*F25 -> 29365.043 | H25: шт | I25: 3 | J25: КМИ 10910 9А — В1+В2+В3 | K25: Альбом 7.4 ЭОМ (Гараж)
A26: =A25 -> КОМПЛЕКТ 2. ЩС-В (ЩРн-12з-0 36 УХЛ3 IP54) | Альбом 7.4 ЭОМ (Гараж) | B26: 2.6 | C26: 2CDS200982R0001 | D26: Независимый расцепитель S3C-A1 AC/DC 12-110V | E26: =ПАРАМЕТРЫ!C36 -> 62.93 | F26: =E26*0.3*1.33*590 -> 14814.351 | G26: =I26*F26 -> 14814.351 | H26: шт | I26: 1 | J26: Независимый расцепитель DRX — пожарный сигнал | K26: Альбом 7.4 ЭОМ (Гараж)
A27: =A26 -> КОМПЛЕКТ 2. ЩС-В (ЩРн-12з-0 36 УХЛ3 IP54) | Альбом 7.4 ЭОМ (Гараж) | B27: 2.7 | D27: Монтажный материал | E27: — | F27: =ПАРАМЕТРЫ!C6&"%" -> 12% | G27: =(G22+G23+G25+G26+G24)*ПАРАМЕТРЫ!C6/100 -> 8157.804 | H27: шт | I27: 1 | J27: % от суммы компонентов | K27: Альбом 7.4 ЭОМ (Гараж)
A28: =A27 -> КОМПЛЕКТ 2. ЩС-В (ЩРн-12з-0 36 УХЛ3 IP54) | Альбом 7.4 ЭОМ (Гараж) | B28: 2.8 | D28: Монтажная работа | E28: — | F28: =ПАРАМЕТРЫ!C7&"%" -> 15% | G28: =(G22+G23+G25+G26+G24)*ПАРАМЕТРЫ!C7/100 -> 10197.255 | H28: шт | I28: 1 | J28: % от суммы компонентов | K28: Альбом 7.4 ЭОМ (Гараж)
A29: =D29 -> КОМПЛЕКТ 3. ЩС-П (ЩРн-24з-0 36 УХЛ3 IP54) | Альбом 7.4 ЭОМ (Гараж) | B29: КОМПЛЕКТ 3. ЩС-П (ЩРн-24з-0 36 УХЛ3 IP54) | Альбом 7.4 ЭОМ (Гараж) | D29: КОМПЛЕКТ 3. ЩС-П (ЩРн-24з-0 36 УХЛ3 IP54) | Альбом 7.4 ЭОМ (Гараж) | H29: компл. | I29: 1
A30: =A29 -> КОМПЛЕКТ 3. ЩС-П (ЩРн-24з-0 36 УХЛ3 IP54) | Альбом 7.4 ЭОМ (Гараж) | B30: 3.1 | C30: Teksan f | D30: Корпус — ЩРн-24з-0 36 УХЛ3 IP54 | E30: — | F30: — | G30: 0 | H30: шт | I30: 1 | J30: Teksan f — цена TBD | K30: Альбом 7.4 ЭОМ (Гараж)
A31: =A30 -> КОМПЛЕКТ 3. ЩС-П (ЩРн-24з-0 36 УХЛ3 IP54) | Альбом 7.4 ЭОМ (Гараж) | B31: 3.2 | C31: 2CDS213001R0254 | D31: SH 203-C 25 | E31: =ПАРАМЕТРЫ!C20 -> 48.51 | F31: =E31*0.3*1.33*590 -> 11419.739 | G31: =I31*F31 -> 11419.739 | H31: шт | I31: 1 | J31: ВН-32 25А | K31: Альбом 7.4 ЭОМ (Гараж)
A32: =A31 -> КОМПЛЕКТ 3. ЩС-П (ЩРн-24з-0 36 УХЛ3 IP54) | Альбом 7.4 ЭОМ (Гараж) | B32: 3.3 | C32: 2CSR255080R1164 | D32: Диф.авт. 1P+N C16 30мА DS201 C16 AC30 | E32: =ПАРАМЕТРЫ!C23 -> 87.63 | F32: =E32*0.3*1.33*590 -> 20628.978 | G32: =I32*F32 -> 144402.85 | H32: шт | I32: 7 | J32: АВДТ DX3 1P+N 16А 30мА | K32: Альбом 7.4 ЭОМ (Гараж)
A33: =A32 -> КОМПЛЕКТ 3. ЩС-П (ЩРн-24з-0 36 УХЛ3 IP54) | Альбом 7.4 ЭОМ (Гараж) | B33: 3.5 | C33: 2CDS211001R0164 | D33: Авт.выкл. 1P C16 SH 201-C 16 | E33: 8.09 | F33: =E33*0.3*1.33*590 -> 1904.4669 | G33: =I33*F33 -> 1904.4669 | H33: шт | I33: 1 | J33: TX3 16А 1P | K33: Альбом 7.4 ЭОМ (Гараж)
A34: =A33 -> КОМПЛЕКТ 3. ЩС-П (ЩРн-24з-0 36 УХЛ3 IP54) | Альбом 7.4 ЭОМ (Гараж) | B34: 3.6 | D34: Монтажный материал | E34: — | F34: =ПАРАМЕТРЫ!C6&"%" -> 12% | G34: =(G31+G32+#REF!+G33)*ПАРАМЕТРЫ!C6/100 -> #REF! | H34: шт | I34: 1 | J34: % от суммы компонентов | K34: Альбом 7.4 ЭОМ (Гараж)
A35: =A34 -> КОМПЛЕКТ 3. ЩС-П (ЩРн-24з-0 36 УХЛ3 IP54) | Альбом 7.4 ЭОМ (Гараж) | B35: 3.7 | D35: Монтажная работа | E35: — | F35: =ПАРАМЕТРЫ!C7&"%" -> 15% | G35: =(G31+G32+#REF!+G33)*ПАРАМЕТРЫ!C7/100 -> #REF! | H35: шт | I35: 1 | J35: % от суммы компонентов | K35: Альбом 7.4 ЭОМ (Гараж)
A36: =D36 -> КОМПЛЕКТ 4. ЩС-ПО (ЩРн-12з-0 36 УХЛ3 IP54) | Альбом 7.4 ЭОМ (Гараж) | B36: КОМПЛЕКТ 4. ЩС-ПО (ЩРн-12з-0 36 УХЛ3 IP54) | Альбом 7.4 ЭОМ (Гараж) | D36: КОМПЛЕКТ 4. ЩС-ПО (ЩРн-12з-0 36 УХЛ3 IP54) | Альбом 7.4 ЭОМ (Гараж) | H36: компл. | I36: 1
A37: =A36 -> КОМПЛЕКТ 4. ЩС-ПО (ЩРн-12з-0 36 УХЛ3 IP54) | Альбом 7.4 ЭОМ (Гараж) | B37: 4.1 | C37: Teksan f | D37: Корпус — ЩРн-12з-0 36 УХЛ3 IP54 | E37: — | F37: — | G37: 0 | H37: шт | I37: 1 | J37: Teksan f — цена TBD | K37: Альбом 7.4 ЭОМ (Гараж)
A38: =A37 -> КОМПЛЕКТ 4. ЩС-ПО (ЩРн-12з-0 36 УХЛ3 IP54) | Альбом 7.4 ЭОМ (Гараж) | B38: 4.2 | C38: 2CDS253001R0824 | D38: S 203-C 100 | E38: =ПАРАМЕТРЫ!C29 -> 100.1 | F38: =E38*0.3*1.33*590 -> 23564.541 | G38: =I38*F38 -> 23564.541 | H38: шт | I38: 1 | J38: ВН-32 100А | K38: Альбом 7.4 ЭОМ (Гараж)
A39: =A38 -> КОМПЛЕКТ 4. ЩС-ПО (ЩРн-12з-0 36 УХЛ3 IP54) | Альбом 7.4 ЭОМ (Гараж) | B39: 4.3 | C39: 2CDS253001R0824 | D39: S 203-C 80 | E39: =ПАРАМЕТРЫ!C40 -> 193.8 | F39: =E39*0.3*1.33*590 -> 45622.458 | G39: =I39*F39 -> 45622.458 | H39: шт | I39: 1 | J39: DPX3 80А — Дп1 | K39: Альбом 7.4 ЭОМ (Гараж)
A40: =A39 -> КОМПЛЕКТ 4. ЩС-ПО (ЩРн-12з-0 36 УХЛ3 IP54) | Альбом 7.4 ЭОМ (Гараж) | B40: 4.4 | C40: 2CDS213001R0164 | D40: Авт.выкл. 3P C16 SH 203-C 16 | E40: 36.42 | F40: =E40*0.3*1.33*590 -> 8573.6322 | G40: =I40*F40 -> 8573.6322 | H40: шт | I40: 1 | J40: TX3 16А 3P | K40: Альбом 7.4 ЭОМ (Гараж)
...

Sheet СВОДНАЯ
A1: СВОДНАЯ ВЕДОМОСТЬ — Проект 260608 — ABB
A2: Раздел / Источник PDF | B2: Итого KZT | C2: Корпус Teksan f | D2: Щитов
A3: ЭОМ — ГАРАЖ | B3: =BOM!#REF!+BOM!#REF!+BOM!#REF!+BOM!#REF!+BOM!#REF!+BOM!#REF!+BOM!#REF! -> #REF! | C3: По запросу | D3: 7
A4: ЭО — КОНЦЕРТНЫЙ ЗАЛ | B4: =BOM!#REF!+BOM!#REF!+BOM!#REF!+BOM!#REF!+BOM!#REF!+BOM!#REF!+BOM!#REF!+BOM!#REF!+BOM!#REF!+BOM!#REF!+BOM!#REF!+BOM!#REF!+BOM!#REF!+BOM!#REF!+BOM!#REF!+BOM!#REF! -> #REF! | C4: По запросу | D4: 16
A5: ЭО — МУЗЕЙ | B5: =BOM!#REF!+BOM!#REF!+BOM!#REF!+BOM!#REF!+BOM!#REF!+BOM!#REF!+BOM!#REF!+BOM!#REF!+BOM!#REF!+BOM!#REF!+BOM!#REF!+BOM!#REF!+BOM!#REF!+BOM!#REF!+BOM!#REF!+BOM!#REF!+BOM!#REF!+BOM!#REF!+BOM!#REF!+BOM!#REF! -> #REF! | C5: По запросу | D5: 20
A6: ЭО — ГАЛЕРЕЯ | B6: =BOM!#REF!+BOM!#REF! -> #REF! | C6: По запросу | D6: 2
A7: ЭН — НАРУЖНОЕ ОСВЕЩЕНИЕ | B7: =BOM!#REF!+BOM!#REF! -> #REF! | C7: По запросу | D7: 2
A8: ФО — ФАСАД | B8: =BOM!#REF!+BOM!#REF!+BOM!#REF!+BOM!#REF!+BOM!#REF!+BOM!#REF! -> #REF! | C8: По запросу | D8: 6
A9: ИТОГО: | B9: =B3+B4+B5+B6+B7+B8 -> #REF! | C9: TBD | D9: 53
A11: EUR/KZT, %, цены → лист ПАРАМЕТРЫ (синие ячейки)
