Workbook

Sheet ПАРАМЕТРЫ
A1: ПАРАМЕТРЫ — Проект 260608 — Chint
A2: Параметр | B2: Значение (ред.) | C2: Описание
A3: EUR/KZT курс | B3: 520 | C3: Обновить с XE.com
A4: Коэф.скидки Chint (0.60) | B4: 0.6 | C4: Скидка на покупку
A5: Коэф.надбавки (ABB EUR) | B5: 1.3 | C5: Транспорт + накладные (только для EUR)
A6: Монтажные материалы % | B6: 7 | C6: % от суммы компонентов
A7: Монтажная работа % | B7: 15 | C7: % от суммы компонентов
A9: Ключ | B9: Цена (список) (ред.) | C9: Наименование / Артикул | D9: Цена нетто KZT (формула)
A10: NB1-1P-C6 | B10: 3077 | C10: Авт.выкл. NB1-63 1P C6 6кА [179626] | D10: =ПАРАМЕТРЫ!B10*ПАРАМЕТРЫ!B4 -> 1846.2
A11: NB1-1P-C10 | B11: 2768 | C11: Авт.выкл. NB1-63 1P C10 6кА [179614] | D11: =ПАРАМЕТРЫ!B11*ПАРАМЕТРЫ!B4 -> 1660.8
A12: NB1-1P-C16 | B12: 2818 | C12: Авт.выкл. NB1-63 1P C16 6кА [179616] | D12: =ПАРАМЕТРЫ!B12*ПАРАМЕТРЫ!B4 -> 1690.8
A13: NB1-1P-C20 | B13: 2869 | C13: Авт.выкл. NB1-63 1P C20 6кА [179618] | D13: =ПАРАМЕТРЫ!B13*ПАРАМЕТРЫ!B4 -> 1721.4
A14: NB1-1P-C25 | B14: 2869 | C14: Авт.выкл. NB1-63 1P C25 6кА [179619] | D14: =ПАРАМЕТРЫ!B14*ПАРАМЕТРЫ!B4 -> 1721.4
A15: NB1-1P-C32 | B15: 2869 | C15: Авт.выкл. NB1-63 1P C32 6кА [179621] | D15: =ПАРАМЕТРЫ!B15*ПАРАМЕТРЫ!B4 -> 1721.4
A16: NB1-3P-C10 | B16: 7510 | C16: Авт.выкл. NB1-63 3P C10 6кА [179698] | D16: =ПАРАМЕТРЫ!B16*ПАРАМЕТРЫ!B4 -> 4506
A17: NB1-3P-C16 | B17: 7697 | C17: Авт.выкл. NB1-63 3P C16 6кА [179700] | D17: =ПАРАМЕТРЫ!B17*ПАРАМЕТРЫ!B4 -> 4618.2
A18: NB1-3P-C20 | B18: 7829 | C18: Авт.выкл. NB1-63 3P C20 6кА [179702] | D18: =ПАРАМЕТРЫ!B18*ПАРАМЕТРЫ!B4 -> 4697.4
A19: NB1-3P-C25 | B19: 7907 | C19: Авт.выкл. NB1-63 3P C25 6кА [179703] | D19: =ПАРАМЕТРЫ!B19*ПАРАМЕТРЫ!B4 -> 4744.2
A20: NB1-3P-C32 | B20: 7856 | C20: Авт.выкл. NB1-63 3P C32 6кА [179705] | D20: =ПАРАМЕТРЫ!B20*ПАРАМЕТРЫ!B4 -> 4713.6
A21: NB1L-1PN-C16 | B21: 13008 | C21: Диф.авт. NB1L 1P+N C16 30мА 6кА [203019] | D21: =ПАРАМЕТРЫ!B21*ПАРАМЕТРЫ!B4 -> 7804.8
A22: NB1L-1PN-C10 | B22: 13634 | C22: Диф.авт. NB1L 1P+N C10 30мА 10кА [203105] | D22: =ПАРАМЕТРЫ!B22*ПАРАМЕТРЫ!B4 -> 8180.4
A23: NB1L-4P-C16 | B23: 23195 | C23: Диф.авт. NB1L-40 4P C16 30мА 6кА [198111] | D23: =ПАРАМЕТРЫ!B23*ПАРАМЕТРЫ!B4 -> 13917
A24: NH4-3P-32 | B24: 7468 | C24: Выкл.нагрузки NH4 3P 32А [398043] | D24: =ПАРАМЕТРЫ!B24*ПАРАМЕТРЫ!B4 -> 4480.8
A25: NH4-3P-100 | B25: 9814 | C25: Выкл.нагрузки NH4 3P 100А [398042] | D25: =ПАРАМЕТРЫ!B25*ПАРАМЕТРЫ!B4 -> 5888.4
A26: NH40-3P-125 | B26: 37976 | C26: Выкл.-разъед. NH40-125/3 3P 125А [393261] | D26: =ПАРАМЕТРЫ!B26*ПАРАМЕТРЫ!B4 -> 22785.6
A27: NM8N-3P-80 | B27: 64129 | C27: Авт.выкл. NM8N-125C TM 3P 80А 36кА [271538] | D27: =ПАРАМЕТРЫ!B27*ПАРАМЕТРЫ!B4 -> 38477.4
A28: NM8N-3P-100 | B28: 64169 | C28: Авт.выкл. NM8N-125C TM 3P 100А 36кА [271539] | D28: =ПАРАМЕТРЫ!B28*ПАРАМЕТРЫ!B4 -> 38501.4
A29: NM8N-3P-125 | B29: 67739 | C29: Авт.выкл. NM8N-125S TM 3P 125А 50кА [271590] | D29: =ПАРАМЕТРЫ!B29*ПАРАМЕТРЫ!B4 -> 40643.4
A30: NXC-09-220 | B30: 5214 | C30: Контактор NXC-09 9А 220В/АС3 [836704] | D30: =ПАРАМЕТРЫ!B30*ПАРАМЕТРЫ!B4 -> 3128.4
A31: NXC-12-220 | B31: 5341 | C31: Контактор NXC-12 12А 220В/АС3 [836712] | D31: =ПАРАМЕТРЫ!B31*ПАРАМЕТРЫ!B4 -> 3204.6
A32: LW32-125 | B32: 37702 | C32: Кулачк.переключатель LW32-125/3 125А 3Р [425042] | D32: =ПАРАМЕТРЫ!B32*ПАРАМЕТРЫ!B4 -> 22621.2
A33: S9-NB1 | B33: 8404 | C33: Независимый расцепитель S9 для NB1-63 [184986] | D33: =ПАРАМЕТРЫ!B33*ПАРАМЕТРЫ!B4 -> 5042.4
A34: КЛЕММНИК | B34: 0 | C34: Клеммник монтажный (аналог NSYTRV162) [—] | D34: По запросу
A35: ЯТП-IEK | B35: 29812 | C35: ЯТП-0,25 230/36В IEK (MTT12-036-0250) [MTT12-036-0250] | D35: =ПАРАМЕТРЫ!B35*ПАРАМЕТРЫ!B4 -> 17887.2
A36: УКРМ-10 | B36: 0 | C36: УКРМ 10кВАр 400В, 800×700×250мм [По запросу] | D36: По запросу

Sheet BOM
A1: СПЕЦИФИКАЦИЯ ОБОРУДОВАНИЯ — Проект 260608 — г.Атырау — Chint | Формула: KZT_нетто = KZT_список × 0.60 | Параметры → лист ПАРАМЕТРЫ (синие ячейки)
A2: № | B2: Наименование и техническая характеристика | C2: Тип / Марка / Артикул | D2: Источник (PDF альбом) | E2: Ед. | F2: Кол. | G2: Цена список | H2: KZT нетто | I2: Сумма KZT | J2: Примечание
A3: ─── ЭОМ — ГАРАЖ ───
A4: КОМПЛЕКТ 1. ГРЩ (ЩМП-18.8.4-0 36 УХЛ3 IP31) | Альбом 7.4 ЭОМ (Гараж)
A5: 1.1 | B5: Корпус — ЩМП-18.8.4-0 36 УХЛ3 IP31 | C5: Teksan f | D5: Альбом 7.4 ЭОМ (Гараж) | E5: шт | F5: 1 | G5: — | H5: — | I5: 0 | J5: Teksan f — цена TBD
A6: 1.2 | B6: Авт.выкл. NM8N-125S TM 3P 125А 50кА | C6: 271590 | D6: Альбом 7.4 ЭОМ (Гараж) | E6: шт | F6: 3 | G6: =ПАРАМЕТРЫ!B29 -> 67739 | H6: =ПАРАМЕТРЫ!D29 -> 40643.4 | I6: =F6*H6 -> 121930.2 | J6: DPX3 125А / вводной аналог
A7: 1.3 | B7: Авт.выкл. NM8N-125C TM 3P 100А 36кА | C7: 271539 | D7: Альбом 7.4 ЭОМ (Гараж) | E7: шт | F7: 1 | G7: =ПАРАМЕТРЫ!B28 -> 64169 | H7: =ПАРАМЕТРЫ!D28 -> 38501.4 | I7: =F7*H7 -> 38501.4 | J7: Резервный ввод
A8: 1.4 | B8: Авт.выкл. NB1-63 3P C20 6кА | C8: 179702 | D8: Альбом 7.4 ЭОМ (Гараж) | E8: шт | F8: 2 | G8: =ПАРАМЕТРЫ!B18 -> 7829 | H8: =ПАРАМЕТРЫ!D18 -> 4697.4 | I8: =F8*H8 -> 9394.8 | J8: TX3 20A 3P
A9: 1.5 | B9: Авт.выкл. NB1-63 3P C25 6кА | C9: 179703 | D9: Альбом 7.4 ЭОМ (Гараж) | E9: шт | F9: 1 | G9: =ПАРАМЕТРЫ!B19 -> 7907 | H9: =ПАРАМЕТРЫ!D19 -> 4744.2 | I9: =F9*H9 -> 4744.2 | J9: TX3 25A 3P
A10: 1.6 | B10: Авт.выкл. NB1-63 1P C6 6кА | C10: 179626 | D10: Альбом 7.4 ЭОМ (Гараж) | E10: шт | F10: 1 | G10: =ПАРАМЕТРЫ!B10 -> 3077 | H10: =ПАРАМЕТРЫ!D10 -> 1846.2 | I10: =F10*H10 -> 1846.2 | J10: TX3 6A 1P
A11: 1.7 | B11: Кулачк.переключатель LW32-125/3 125А 3Р | C11: 425042 | D11: Альбом 7.4 ЭОМ (Гараж) | E11: шт | F11: 1 | G11: =ПАРАМЕТРЫ!B32 -> 37702 | H11: =ПАРАМЕТРЫ!D32 -> 22621.2 | I11: =F11*H11 -> 22621.2 | J11: АВР TransferPact аналог
A12: 1.8 | B12: УКРМ 10кВАр 400В, 800×700×250мм | C12: По запросу | D12: Альбом 7.4 ЭОМ (Гараж) | E12: шт | F12: 2 | G12: — | H12: — | I12: 0 | J12: КРМ — 2 шт (ввод1+ввод2) — цена TBD
A13: 1.9 | B13: Счётчик электроэнергии 3ф 100А 380В | C13: Энергомера СЕ 303 S31 746-JPVZ PLC 1111, 100А, 380В | D13: Альбом 7.4 ЭОМ (Гараж) | E13: шт | F13: 3 | G13: — | H13: — | I13: 0 | J13: Счётчик/прибор — 3 шт — по одному на каждый ввод ГРЩ — цена По запросу
A14: 1.10 | B14: Монтажный материал | D14: Альбом 7.4 ЭОМ (Гараж) | E14: компл | F14: 1 | G14: — | H14: =ПАРАМЕТРЫ!B6&"%" -> 7% | I14: =(I6+I7+I8+I9+I10+I11)*ПАРАМЕТРЫ!B6/100 -> 13932.66 | J14: % от суммы компонентов
A15: 1.11 | B15: Монтажная работа | D15: Альбом 7.4 ЭОМ (Гараж) | E15: компл | F15: 1 | G15: — | H15: =ПАРАМЕТРЫ!B7&"%" -> 15% | I15: =(I6+I7+I8+I9+I10+I11)*ПАРАМЕТРЫ!B7/100 -> 29855.7 | J15: % от суммы компонентов
A16: Итого по ГРЩ (ЩМП-18.8.4-0 36 УХЛ3 IP31) (без корпуса Teksan f): | I16: =I6+I7+I8+I9+I10+I11+I14+I15 -> 242826.36
A18: КОМПЛЕКТ 2. ЩС-В (ЩРн-12з-0 36 УХЛ3 IP54) | Альбом 7.4 ЭОМ (Гараж)
A19: 2.1 | B19: Корпус — ЩРн-12з-0 36 УХЛ3 IP54 | C19: Teksan f | D19: Альбом 7.4 ЭОМ (Гараж) | E19: шт | F19: 1 | G19: — | H19: — | I19: 0 | J19: Teksan f — цена TBD
A20: 2.2 | B20: Авт.выкл. NB1-63 3P C20 6кА | C20: 179702 | D20: Альбом 7.4 ЭОМ (Гараж) | E20: шт | F20: 1 | G20: =ПАРАМЕТРЫ!B18 -> 7829 | H20: =ПАРАМЕТРЫ!D18 -> 4697.4 | I20: =F20*H20 -> 4697.4 | J20: Ввод QF1 20А 3P
A21: 2.3 | B21: Авт.выкл. NB1-63 1P C16 6кА | C21: 179616 | D21: Альбом 7.4 ЭОМ (Гараж) | E21: шт | F21: 2 | G21: =ПАРАМЕТРЫ!B12 -> 2818 | H21: =ПАРАМЕТРЫ!D12 -> 1690.8 | I21: =F21*H21 -> 3381.6 | J21: SF2, SF3
A22: 2.4 | B22: Контактор NXC-09 9А 220В/АС3 | C22: 836704 | D22: Альбом 7.4 ЭОМ (Гараж) | E22: шт | F22: 3 | G22: =ПАРАМЕТРЫ!B30 -> 5214 | H22: =ПАРАМЕТРЫ!D30 -> 3128.4 | I22: =F22*H22 -> 9385.2 | J22: КМИ 10910 9А — В1+В2+В3
A23: 2.5 | B23: Независимый расцепитель S9 для NB1-63 | C23: 184986 | D23: Альбом 7.4 ЭОМ (Гараж) | E23: шт | F23: 1 | G23: =ПАРАМЕТРЫ!B33 -> 8404 | H23: =ПАРАМЕТРЫ!D33 -> 5042.4 | I23: =F23*H23 -> 5042.4 | J23: Независимый расцепитель DRX — пожарный сигнал
A24: 2.6 | B24: Монтажный материал | D24: Альбом 7.4 ЭОМ (Гараж) | E24: компл | F24: 1 | G24: — | H24: =ПАРАМЕТРЫ!B6&"%" -> 7% | I24: =(I20+I21+I22+I23)*ПАРАМЕТРЫ!B6/100 -> 1575.462 | J24: % от суммы компонентов
A25: 2.7 | B25: Монтажная работа | D25: Альбом 7.4 ЭОМ (Гараж) | E25: компл | F25: 1 | G25: — | H25: =ПАРАМЕТРЫ!B7&"%" -> 15% | I25: =(I20+I21+I22+I23)*ПАРАМЕТРЫ!B7/100 -> 3375.99 | J25: % от суммы компонентов
A26: Итого по ЩС-В (ЩРн-12з-0 36 УХЛ3 IP54) (без корпуса Teksan f): | I26: =I20+I21+I22+I23+I24+I25 -> 27458.052
A28: КОМПЛЕКТ 3. ЩС-П (ЩРн-24з-0 36 УХЛ3 IP54) | Альбом 7.4 ЭОМ (Гараж)
A29: 3.1 | B29: Корпус — ЩРн-24з-0 36 УХЛ3 IP54 | C29: Teksan f | D29: Альбом 7.4 ЭОМ (Гараж) | E29: шт | F29: 1 | G29: — | H29: — | I29: 0 | J29: Teksan f — цена TBD
A30: 3.2 | B30: Выкл.нагрузки NH4 3P 32А | C30: 398043 | D30: Альбом 7.4 ЭОМ (Гараж) | E30: шт | F30: 1 | G30: =ПАРАМЕТРЫ!B24 -> 7468 | H30: =ПАРАМЕТРЫ!D24 -> 4480.8 | I30: =F30*H30 -> 4480.8 | J30: ВН-32 25А
A31: 3.3 | B31: Диф.авт. NB1L 1P+N C16 30мА 6кА | C31: 203019 | D31: Альбом 7.4 ЭОМ (Гараж) | E31: шт | F31: 2 | G31: =ПАРАМЕТРЫ!B21 -> 13008 | H31: =ПАРАМЕТРЫ!D21 -> 7804.8 | I31: =F31*H31 -> 15609.6 | J31: АВДТ DX3 1P+N 16А 30мА
A32: 3.4 | B32: Авт.выкл. NB1-63 3P C16 6кА | C32: 179700 | D32: Альбом 7.4 ЭОМ (Гараж) | E32: шт | F32: 1 | G32: =ПАРАМЕТРЫ!B17 -> 7697 | H32: =ПАРАМЕТРЫ!D17 -> 4618.2 | I32: =F32*H32 -> 4618.2 | J32: TX3 16А 3P
A33: 3.5 | B33: Авт.выкл. NB1-63 1P C16 6кА | C33: 179616 | D33: Альбом 7.4 ЭОМ (Гараж) | E33: шт | F33: 1 | G33: =ПАРАМЕТРЫ!B12 -> 2818 | H33: =ПАРАМЕТРЫ!D12 -> 1690.8 | I33: =F33*H33 -> 1690.8 | J33: TX3 16А 1P
A34: 3.6 | B34: Монтажный материал | D34: Альбом 7.4 ЭОМ (Гараж) | E34: компл | F34: 1 | G34: — | H34: =ПАРАМЕТРЫ!B6&"%" -> 7% | I34: =(I30+I31+I32+I33)*ПАРАМЕТРЫ!B6/100 -> 1847.958 | J34: % от суммы компонентов
A35: 3.7 | B35: Монтажная работа | D35: Альбом 7.4 ЭОМ (Гараж) | E35: компл | F35: 1 | G35: — | H35: =ПАРАМЕТРЫ!B7&"%" -> 15% | I35: =(I30+I31+I32+I33)*ПАРАМЕТРЫ!B7/100 -> 3959.91 | J35: % от суммы компонентов
A36: Итого по ЩС-П (ЩРн-24з-0 36 УХЛ3 IP54) (без корпуса Teksan f): | I36: =I30+I31+I32+I33+I34+I35 -> 32207.268
A38: КОМПЛЕКТ 4. ЩС-ПО (ЩРн-12з-0 36 УХЛ3 IP54) | Альбом 7.4 ЭОМ (Гараж)
A39: 4.1 | B39: Корпус — ЩРн-12з-0 36 УХЛ3 IP54 | C39: Teksan f | D39: Альбом 7.4 ЭОМ (Гараж) | E39: шт | F39: 1 | G39: — | H39: — | I39: 0 | J39: Teksan f — цена TBD
A40: 4.2 | B40: Выкл.нагрузки NH4 3P 100А | C40: 398042 | D40: Альбом 7.4 ЭОМ (Гараж) | E40: шт | F40: 1 | G40: =ПАРАМЕТРЫ!B25 -> 9814 | H40: =ПАРАМЕТРЫ!D25 -> 5888.4 | I40: =F40*H40 -> 5888.4 | J40: ВН-32 100А
A41: 4.3 | B41: Авт.выкл. NM8N-125C TM 3P 80А 36кА | C41: 271538 | D41: Альбом 7.4 ЭОМ (Гараж) | E41: шт | F41: 1 | G41: =ПАРАМЕТРЫ!B27 -> 64129 | H41: =ПАРАМЕТРЫ!D27 -> 38477.4 | I41: =F41*H41 -> 38477.4 | J41: DPX3 80А — Дп1
A42: 4.4 | B42: Авт.выкл. NB1-63 3P C16 6кА | C42: 179700 | D42: Альбом 7.4 ЭОМ (Гараж) | E42: шт | F42: 1 | G42: =ПАРАМЕТРЫ!B17 -> 7697 | H42: =ПАРАМЕТРЫ!D17 -> 4618.2 | I42: =F42*H42 -> 4618.2 | J42: TX3 16А 3P
A43: 4.5 | B43: Авт.выкл. NB1-63 1P C16 6кА | C43: 179616 | D43: Альбом 7.4 ЭОМ (Гараж) | E43: шт | F43: 1 | G43: =ПАРАМЕТРЫ!B12 -> 2818 | H43: =ПАРАМЕТРЫ!D12 -> 1690.8 | I43: =F43*H43 -> 1690.8 | J43: TX3 16А 1P
...

Sheet СВОДНАЯ
A1: СВОДНАЯ ВЕДОМОСТЬ — Проект 260608 — Chint
A2: Раздел / Источник PDF | B2: Итого KZT | C2: Корпус Teksan f | D2: Щитов
A3: ЭОМ — ГАРАЖ | B3: =BOM!I16+BOM!I26+BOM!I36+BOM!I46+BOM!I54+BOM!I62+BOM!I71 -> 480011.2 | C3: По запросу | D3: 7
A4: ЭО — КОНЦЕРТНЫЙ ЗАЛ | B4: =BOM!I83+BOM!I94+BOM!I105+BOM!I116+BOM!I127+BOM!I138+BOM!I149+BOM!I160+BOM!I171+BOM!I179+BOM!I187+BOM!I195+BOM!I203+BOM!I211+BOM!I219+BOM!I227 -> 805971.53 | C4: По запросу | D4: 16
A5: ЭО — МУЗЕЙ | B5: =BOM!I239+BOM!I250+BOM!I261+BOM!I272+BOM!I283+BOM!I293+BOM!I303+BOM!I313+BOM!I323+BOM!I333+BOM!I341+BOM!I349+BOM!I357+BOM!I365+BOM!I373+BOM!I381+BOM!I389+BOM!I397+BOM!I405+BOM!I413 -> 609334.37 | C5: По запросу | D5: 20
A6: ЭО — ГАЛЕРЕЯ | B6: =BOM!I425+BOM!I433 -> 58237.92 | C6: По запросу | D6: 2
A7: ЭН — НАРУЖНОЕ ОСВЕЩЕНИЕ | B7: =BOM!I445+BOM!I453 -> 96510.54 | C7: По запросу | D7: 2
A8: ФО — ФАСАД | B8: =BOM!I465+BOM!I475+BOM!I483+BOM!I491+BOM!I499+BOM!I507 -> 967856.26 | C8: По запросу | D8: 6
A9: ИТОГО: | B9: =B3+B4+B5+B6+B7+B8 -> 3017921.8 | C9: TBD | D9: 53
A11: EUR/KZT, %, цены → лист ПАРАМЕТРЫ (синие ячейки)
