Workbook

Sheet BOM
A1: ROW | B1: Наименование1 | C1: Tip | D1: Артикул | E1: Номенклатура | F1: Цена liste (KZT) | G1: Цена net (KZT) | H1: Сумма (KZT) | I1: Кол-во | J1: Ед.изм. | K1: Завод | M1: Kaynak (dosya/satır) | N1: Сумма (KZT)
A2: 1 | B2: =E2 -> ЩО-1 (ЩРВ-24) | E2: ЩО-1 (ЩРВ-24) | I2: 1 | J2: комплект
A3: 2 | B3: =B2 -> ЩО-1 (ЩРВ-24) | C3: korpus | D3: 713-15010 | E3: Pano met.ShRv-24b/o(320х405х120)S/A36IP31(TS) | F3: 15500 | G3: =0.6*F3 -> 9300 | H3: =G3*I3 -> 9300 | I3: 1 | J3: шт. | K3: teksan f | M3: EKT (19.06.2025) / panolar s.9 | N3: 9300
A4: 3 | B4: =B3 -> ЩО-1 (ЩРВ-24) | C4: OTO | D4: 814172 | E4: Авт. выкл. NXB-63 3P 25A 6кА х-ка C | F4: 5334 | G4: =F4*Kurallar!$B$2 -> 3200.4 | H4: =G4*I4 -> 3200.4 | I4: 1 | J4: шт. | K4: CHINT | M4: CHINT (13.06.2026) / satır 326 | N4: 3200.4
A5: 4 | B5: =B4 -> ЩО-1 (ЩРВ-24) | C5: OTO | D5: 814014 | E5: Авт. выкл. NXB-63 1P 16A 6кА х-ка C | F5: 1389 | G5: =F5*Kurallar!$B$2 -> 833.4 | H5: =G5*I5 -> 10000.8 | I5: 12 | J5: шт. | K5: CHINT | M5: CHINT (13.06.2026) / satır 277 | N5: 10000.8
A6: 5 | B6: =B5 -> ЩО-1 (ЩРВ-24) | C6: DİF | D6: 515381 | E6: Диф. авт. выкл. NXBLE-63YH 1P+N C16 30mA тип A, 6kA (R) | F6: 5104 | G6: =F6*Kurallar!$B$2 -> 3062.4 | H6: =G6*I6 -> 6124.8 | I6: 2 | J6: шт. | K6: CHINT | M6: CHINT (13.06.2026) / satır 754 | N6: 6124.8
A7: 6 | B7: =B6 -> ЩО-1 (ЩРВ-24) | C7: LOOBAR | D7: 130200355_ | E7: Шина N (PEN) 6х9мм 14/1 на изоляторах | F7: 415 | G7: =F7*Kurallar!$B$3 -> 415 | H7: =G7*I7 -> 415 | I7: 1 | J7: шт. | K7: pys | M7: EKT (19.06.2025) / bara s.5 | N7: 415
A8: 7 | B8: =B7 -> ЩО-1 (ЩРВ-24) | C8: LOOBAR | D8: 130200401_ | E8: Шина PE ШНИ 6х9 12-К-З на DIN-рейку | F8: 547 | G8: =F8*Kurallar!$B$3 -> 547 | H8: =G8*I8 -> 547 | I8: 1 | J8: шт. | K8: pys | M8: EKT (19.06.2025) / bara s.21 | N8: 547
A9: 8 | B9: =B8 -> ЩО-1 (ЩРВ-24) | C9: DIN ray | D9: 570003 | E9: DIN-рейка оцинкованная TH35-7.5 100cm | F9: 869 | G9: =F9*Kurallar!$B$2 -> 521.4 | H9: =G9*I9 -> 521.4 | I9: 1 | J9: шт. | K9: CHINT | M9: CHINT (13.06.2026) / satır 26 | N9: 521.4
A10: 9 | B10: =B9 -> ЩО-1 (ЩРВ-24) | C10: kanal | D10: 270300079_ | E10: Кабель-канал перф. 25х40 ИМПАКТ IEK (2м) | F10: 1094 | G10: =F10*Kurallar!$B$3 -> 1094 | H10: =G10*I10 -> 1094 | I10: 1 | J10: шт. | K10: EKT | M10: EKT (19.06.2025) / kablo kanali s.6 | N10: 1094
A11: 10 | B11: =B10 -> ЩО-1 (ЩРВ-24) | C11: montajный материал | E11: Montaj malzemesi (materyal toplamı × Kurallar!B5) | G11: =SUM(H3:H10)*Kurallar!$B$5 -> 936.102 | H11: =G11*I11 -> 936.102 | I11: 1 | J11: шт. | K11: montajный материал | N11: 936.102
A12: 11 | B12: =B11 -> ЩО-1 (ЩРВ-24) | C12: montajная работа | E12: Montaj işçiliği (materyal toplamı × Kurallar!B6) | G12: =SUM(H3:H10)*Kurallar!$B$6+200 -> 6440.68 | H12: =G12*I12 -> 6440.68 | I12: 1 | J12: шт. | K12: montajная работа | N12: 6440.68
A13: 12 | B13: Toplam ЩО-1 (ЩРВ-24) (1 компл.) | H13: =SUBTOTAL(9,H3:H12) -> 38580.182 | N13: 38580.182
A14: 13 | B14: =E14 -> ЩО-2 (ЩРВ-24) | E14: ЩО-2 (ЩРВ-24) | I14: 1 | J14: комплект
A15: 14 | B15: =B14 -> ЩО-2 (ЩРВ-24) | C15: korpus | D15: 713-15010 | E15: Pano met.ShRv-24b/o(320х405х120)S/A36IP31(TS) | F15: 15500 | G15: =0.6*F15 -> 9300 | H15: =G15*I15 -> 9300 | I15: 1 | J15: шт. | K15: teksan f | M15: EKT (19.06.2025) / panolar s.9 | N15: 9300
A16: 15 | B16: =B15 -> ЩО-2 (ЩРВ-24) | C16: OTO | D16: 814172 | E16: Авт. выкл. NXB-63 3P 25A 6кА х-ка C | F16: 5334 | G16: =F16*Kurallar!$B$2 -> 3200.4 | H16: =G16*I16 -> 3200.4 | I16: 1 | J16: шт. | K16: CHINT | M16: CHINT (13.06.2026) / satır 326 | N16: 3200.4
A17: 16 | B17: =B16 -> ЩО-2 (ЩРВ-24) | C17: OTO | D17: 814014 | E17: Авт. выкл. NXB-63 1P 16A 6кА х-ка C | F17: 1389 | G17: =F17*Kurallar!$B$2 -> 833.4 | H17: =G17*I17 -> 7500.6 | I17: 9 | J17: шт. | K17: CHINT | M17: CHINT (13.06.2026) / satır 277 | N17: 7500.6
A18: 17 | B18: =B17 -> ЩО-2 (ЩРВ-24) | C18: DİF | D18: 515381 | E18: Диф. авт. выкл. NXBLE-63YH 1P+N C16 30mA тип A, 6kA (R) | F18: 5104 | G18: =F18*Kurallar!$B$2 -> 3062.4 | H18: =G18*I18 -> 6124.8 | I18: 2 | J18: шт. | K18: CHINT | M18: CHINT (13.06.2026) / satır 754 | N18: 6124.8
A19: 18 | B19: =B18 -> ЩО-2 (ЩРВ-24) | C19: LOOBAR | D19: 130200355_ | E19: Шина N (PEN) 6х9мм 14/1 на изоляторах | F19: 415 | G19: =F19*Kurallar!$B$3 -> 415 | H19: =G19*I19 -> 415 | I19: 1 | J19: шт. | K19: pys | M19: EKT (19.06.2025) / bara s.5 | N19: 415
A20: 19 | B20: =B19 -> ЩО-2 (ЩРВ-24) | C20: LOOBAR | D20: 130200401_ | E20: Шина PE ШНИ 6х9 12-К-З на DIN-рейку | F20: 547 | G20: =F20*Kurallar!$B$3 -> 547 | H20: =G20*I20 -> 547 | I20: 1 | J20: шт. | K20: pys | M20: EKT (19.06.2025) / bara s.21 | N20: 547
A21: 20 | B21: =B20 -> ЩО-2 (ЩРВ-24) | C21: DIN ray | D21: 570003 | E21: DIN-рейка оцинкованная TH35-7.5 100cm | F21: 869 | G21: =F21*Kurallar!$B$2 -> 521.4 | H21: =G21*I21 -> 521.4 | I21: 1 | J21: шт. | K21: CHINT | M21: CHINT (13.06.2026) / satır 26 | N21: 521.4
A22: 21 | B22: =B21 -> ЩО-2 (ЩРВ-24) | C22: kanal | D22: 270300079_ | E22: Кабель-канал перф. 25х40 ИМПАКТ IEK (2м) | F22: 1094 | G22: =F22*Kurallar!$B$3 -> 1094 | H22: =G22*I22 -> 1094 | I22: 1 | J22: шт. | K22: EKT | M22: EKT (19.06.2025) / kablo kanali s.6 | N22: 1094
A23: 22 | B23: =B22 -> ЩО-2 (ЩРВ-24) | C23: montajный материал | E23: Montaj malzemesi (materyal toplamı × Kurallar!B5) | G23: =SUM(H15:H22)*Kurallar!$B$5 -> 861.096 | H23: =G23*I23 -> 861.096 | I23: 1 | J23: шт. | K23: montajный материал | N23: 861.096
A24: 23 | B24: =B23 -> ЩО-2 (ЩРВ-24) | C24: montajная работа | E24: Montaj işçiliği (materyal toplamı × Kurallar!B6) | G24: =SUM(H15:H22)*Kurallar!$B$6+600 -> 6340.64 | H24: =G24*I24 -> 6340.64 | I24: 1 | J24: шт. | K24: montajная работа | N24: 6340.64
A25: 24 | B25: Toplam ЩО-2 (ЩРВ-24) (1 компл.) | H25: =SUBTOTAL(9,H15:H24) -> 35904.936 | N25: 35904.936
A26: 25 | B26: =E26 -> ЩО-3 (ЩРВ-24) | E26: ЩО-3 (ЩРВ-24) | I26: 1 | J26: комплект
A27: 26 | B27: =B26 -> ЩО-3 (ЩРВ-24) | C27: korpus | D27: 713-15010 | E27: Pano met.ShRv-24b/o(320х405х120)S/A36IP31(TS) | F27: 15500 | G27: =0.6*F27 -> 9300 | H27: =G27*I27 -> 9300 | I27: 1 | J27: шт. | K27: teksan f | M27: EKT (19.06.2025) / panolar s.9 | N27: 9300
A28: 27 | B28: =B27 -> ЩО-3 (ЩРВ-24) | C28: OTO | D28: 814172 | E28: Авт. выкл. NXB-63 3P 25A 6кА х-ка C | F28: 5334 | G28: =F28*Kurallar!$B$2 -> 3200.4 | H28: =G28*I28 -> 3200.4 | I28: 1 | J28: шт. | K28: CHINT | M28: CHINT (13.06.2026) / satır 326 | N28: 3200.4
A29: 28 | B29: =B28 -> ЩО-3 (ЩРВ-24) | C29: OTO | D29: 814014 | E29: Авт. выкл. NXB-63 1P 16A 6кА х-ка C | F29: 1389 | G29: =F29*Kurallar!$B$2 -> 833.4 | H29: =G29*I29 -> 10000.8 | I29: 12 | J29: шт. | K29: CHINT | M29: CHINT (13.06.2026) / satır 277 | N29: 10000.8
A30: 29 | B30: =B29 -> ЩО-3 (ЩРВ-24) | C30: DİF | D30: 515381 | E30: Диф. авт. выкл. NXBLE-63YH 1P+N C16 30mA тип A, 6kA (R) | F30: 5104 | G30: =F30*Kurallar!$B$2 -> 3062.4 | H30: =G30*I30 -> 6124.8 | I30: 2 | J30: шт. | K30: CHINT | M30: CHINT (13.06.2026) / satır 754 | N30: 6124.8
A31: 30 | B31: =B30 -> ЩО-3 (ЩРВ-24) | C31: LOOBAR | D31: 130200355_ | E31: Шина N (PEN) 6х9мм 14/1 на изоляторах | F31: 415 | G31: =F31*Kurallar!$B$3 -> 415 | H31: =G31*I31 -> 415 | I31: 1 | J31: шт. | K31: pys | M31: EKT (19.06.2025) / bara s.5 | N31: 415
A32: 31 | B32: =B31 -> ЩО-3 (ЩРВ-24) | C32: LOOBAR | D32: 130200401_ | E32: Шина PE ШНИ 6х9 12-К-З на DIN-рейку | F32: 547 | G32: =F32*Kurallar!$B$3 -> 547 | H32: =G32*I32 -> 547 | I32: 1 | J32: шт. | K32: pys | M32: EKT (19.06.2025) / bara s.21 | N32: 547
A33: 32 | B33: =B32 -> ЩО-3 (ЩРВ-24) | C33: DIN ray | D33: 570003 | E33: DIN-рейка оцинкованная TH35-7.5 100cm | F33: 869 | G33: =F33*Kurallar!$B$2 -> 521.4 | H33: =G33*I33 -> 521.4 | I33: 1 | J33: шт. | K33: CHINT | M33: CHINT (13.06.2026) / satır 26 | N33: 521.4
A34: 33 | B34: =B33 -> ЩО-3 (ЩРВ-24) | C34: kanal | D34: 270300079_ | E34: Кабель-канал перф. 25х40 ИМПАКТ IEK (2м) | F34: 1094 | G34: =F34*Kurallar!$B$3 -> 1094 | H34: =G34*I34 -> 1094 | I34: 1 | J34: шт. | K34: EKT | M34: EKT (19.06.2025) / kablo kanali s.6 | N34: 1094
A35: 34 | B35: =B34 -> ЩО-3 (ЩРВ-24) | C35: montajный материал | E35: Montaj malzemesi (materyal toplamı × Kurallar!B5) | G35: =SUM(H27:H34)*Kurallar!$B$5 -> 936.102 | H35: =G35*I35 -> 936.102 | I35: 1 | J35: шт. | K35: montajный материал | N35: 936.102
A36: 35 | B36: =B35 -> ЩО-3 (ЩРВ-24) | C36: montajная работа | E36: Montaj işçiliği (materyal toplamı × Kurallar!B6) | G36: =SUM(H27:H34)*Kurallar!$B$6+100 -> 6340.68 | H36: =G36*I36 -> 6340.68 | I36: 1 | J36: шт. | K36: montajная работа | N36: 6340.68
A37: 36 | B37: Toplam ЩО-3 (ЩРВ-24) (1 компл.) | H37: =SUBTOTAL(9,H27:H36) -> 38480.182 | N37: 38480.182
A38: 37 | B38: =E38 -> ЩО-4 (ЩРВ-24) | E38: ЩО-4 (ЩРВ-24) | I38: 1 | J38: комплект
A39: 38 | B39: =B38 -> ЩО-4 (ЩРВ-24) | C39: korpus | D39: 713-15010 | E39: Pano met.ShRv-24b/o(320х405х120)S/A36IP31(TS) | F39: 15500 | G39: =0.6*F39 -> 9300 | H39: =G39*I39 -> 9300 | I39: 1 | J39: шт. | K39: teksan f | M39: EKT (19.06.2025) / panolar s.9 | N39: 9300
A40: 39 | B40: =B39 -> ЩО-4 (ЩРВ-24) | C40: OTO | D40: 814172 | E40: Авт. выкл. NXB-63 3P 25A 6кА х-ка C | F40: 5334 | G40: =F40*Kurallar!$B$2 -> 3200.4 | H40: =G40*I40 -> 3200.4 | I40: 1 | J40: шт. | K40: CHINT | M40: CHINT (13.06.2026) / satır 326 | N40: 3200.4
...

Sheet Sayfa1
A1: Артикул | B1: Номенклатура | C1: Цена liste (KZT) | D1: Цена net (KZT) | E1: Сумма (KZT) | F1: Кол-во | G1: Ед.изм. | H1: Завод | J1: Kaynak (dosya/satır) | K1: Сумма (KZT) | L1: 2.3
B2: ЩО-1 (ЩРВ-24) | C2: =ROUNDUP(L2,-3) -> 89000 | D2: =C2*0.7 -> 62300 | E2: =D2*F2 -> 62300 | F2: 1 | G2: комплект | K2: 38580.182 | L2: =2.3*K2 -> 88734.419
B3: ЩО-2 (ЩРВ-24) | C3: =ROUNDUP(L3,-3) -> 83000 | D3: =C3*0.7 -> 58100 | E3: =D3*F3 -> 58100 | F3: 1 | G3: комплект | K3: 35904.936 | L3: =2.3*K3 -> 82581.353
B4: ЩО-3 (ЩРВ-24) | C4: =ROUNDUP(L4,-3) -> 89000 | D4: =C4*0.7 -> 62300 | E4: =D4*F4 -> 62300 | F4: 1 | G4: комплект | K4: 38480.182 | L4: =2.3*K4 -> 88504.419
B5: ЩО-4 (ЩРВ-24) | C5: =ROUNDUP(L5,-3) -> 91000 | D5: =C5*0.7 -> 63700 | E5: =D5*F5 -> 63700 | F5: 1 | G5: комплект | K5: 39405.264 | L5: =2.3*K5 -> 90632.107
B6: ЩАО-1 (ЩРВ-9) | C6: =ROUNDUP(L6,-3) -> 50000 | D6: =C6*0.7 -> 35000 | E6: =D6*F6 -> 35000 | F6: 1 | G6: комплект | K6: 21456.022 | L6: =2.3*K6 -> 49348.851
B7: ЩАО-2 (ЩРВ-9) | C7: =ROUNDUP(L7,-3) -> 47000 | D7: =C7*0.7 -> 32900 | E7: =D7*F7 -> 32900 | F7: 1 | G7: комплект | K7: 20430.94 | L7: =2.3*K7 -> 46991.162
B8: ЩС-1 (ЩРВ-36) | C8: =ROUNDUP(L8,-3) -> 129000 | D8: =C8*0.7 -> 90300 | E8: =D8*F8 -> 90300 | F8: 1 | G8: комплект | K8: 55701.784 | L8: =2.3*K8 -> 128114.1
B9: ЩС-2 (ЩРВ-48) | C9: =ROUNDUP(L9,-3) -> 165000 | D9: =C9*0.7 -> 115500 | E9: =D9*F9 -> 115500 | F9: 1 | G9: комплект | K9: 71706.324 | L9: =2.3*K9 -> 164924.55
B10: ЩС-3 (ЩРВ-54) | C10: =ROUNDUP(L10,-3) -> 186000 | D10: =C10*0.7 -> 130200 | E10: =D10*F10 -> 130200 | F10: 1 | G10: комплект | K10: 80535.756 | L10: =2.3*K10 -> 185232.24
B11: ЩС-4 (ЩРВ-48, büyütüldü) | C11: =ROUNDUP(L11,-3) -> 198000 | D11: =C11*0.7 -> 138600 | E11: =D11*F11 -> 138600 | F11: 1 | G11: комплект | K11: 85971.096 | L11: =2.3*K11 -> 197733.52
B12: ЩС-5 (ЩСВ) (ЩРВ-36) | C12: =ROUNDUP(L12,-3) -> 132000 | D12: =C12*0.7 -> 92400 | E12: =D12*F12 -> 92400 | F12: 1 | G12: комплект | K12: 57008.78 | L12: =2.3*K12 -> 131120.19
B13: ЩС-6 (ЩСВ) (ЩРВ-24, büyütüldü) | C13: =ROUNDUP(L13,-3) -> 103000 | D13: =C13*0.7 -> 72100 | E13: =D13*F13 -> 72100 | F13: 1 | G13: комплект | K13: 44687.868 | L13: =2.3*K13 -> 102782.1
... B20: Ящик управления (Я5111-2674, Iн=5А) | C20: =ROUNDUP(L20,-3) -> 51000 | D20: =C20*0.7 -> 35700 | E20: =D20*F20 -> 107100 | F20: 3 | G20: комплект | K20: 22108.266 | L20: =2.3*K20 -> 50849.012
C21: =ROUNDUP(L21,-3) -> 4020000 | D21: =C21*0.7 -> 2814000 | E21: =SUM(E2:E20) -> 2890300 | K21: =SUM(K2:K20) -> 1747504.8 | L21: =SUM(L2:L20) -> 4019261.1
D26: =15*K21 -> 26212573

Sheet СВОД
A1: № | B1: Наименование щита | C1: Кол-во, компл. | D1: Цена за компл. (KZT) | E1: Сумма (KZT)
A2: 1 | B2: ЩО-1 (ЩРВ-24) | C2: 1 | D2: =BOM!H13 -> 38580.182 | E2: =C2*D2 -> 38580.182
A3: 2 | B3: ЩО-2 (ЩРВ-24) | C3: 1 | D3: =BOM!H25 -> 35904.936 | E3: =C3*D3 -> 35904.936
A4: 3 | B4: ЩО-3 (ЩРВ-24) | C4: 1 | D4: =BOM!H37 -> 38480.182 | E4: =C4*D4 -> 38480.182
A5: 4 | B5: ЩО-4 (ЩРВ-24) | C5: 1 | D5: =BOM!H49 -> 39405.264 | E5: =C5*D5 -> 39405.264
A6: 5 | B6: ЩАО-1 (ЩРВ-9) | C6: 1 | D6: =BOM!H60 -> 21456.022 | E6: =C6*D6 -> 21456.022
A7: 6 | B7: ЩАО-2 (ЩРВ-9) | C7: 1 | D7: =BOM!H71 -> 20430.94 | E7: =C7*D7 -> 20430.94
A8: 7 | B8: ЩС-1 (ЩРВ-36) | C8: 1 | D8: =BOM!H82 -> 55701.784 | E8: =C8*D8 -> 55701.784
A9: 8 | B9: ЩС-2 (ЩРВ-48) | C9: 1 | D9: =BOM!H94 -> 71706.324 | E9: =C9*D9 -> 71706.324
A10: 9 | B10: ЩС-3 (ЩРВ-54) | C10: 1 | D10: =BOM!H107 -> 80535.756 | E10: =C10*D10 -> 80535.756
A11: 10 | B11: ЩС-4 (ЩРВ-48, büyütüldü) | C11: 1 | D11: =BOM!H126 -> 85971.096 | E11: =C11*D11 -> 85971.096
A12: 11 | B12: ЩС-5 (ЩСВ) (ЩРВ-36) | C12: 1 | D12: =BOM!H140 -> 57008.78 | E12: =C12*D12 -> 57008.78
A13: 12 | B13: ЩС-6 (ЩСВ) (ЩРВ-24, büyütüldü) | C13: 1 | D13: =BOM!H152 -> 44687.868 | E13: =C13*D13 -> 44687.868
A14: 13 | B14: ВРУ1-11-10 | C14: 1 | D14: =BOM!H165 -> 513188.43 | E14: =C14*D14 -> 513188.43
A15: 14 | B15: ВРУ1-47-00 №1 (2x25А+1x40А+2x50А) | C15: 1 | D15: =BOM!H177 -> 206346.38 | E15: =C15*D15 -> 206346.38
A16: 15 | B16: ВРУ1-47-00 №2 (1x32А+2x40А+2x50А) | C16: 1 | D16: =BOM!H189 -> 206346.38 | E16: =C16*D16 -> 206346.38
A17: 16 | B17: ЯАВР (АВР, proje: ЯАВР-160А — KONTROL) | C17: 1 | D17: =BOM!H195 -> 165429.72 | E17: =C17*D17 -> 165429.72
A18: 17 | B18: Ящик управления (Я5411-1874, Iн=1А) | C18: 1 | D18: =BOM!H205 -> 22108.266 | E18: =C18*D18 -> 22108.266
A19: 18 | B19: Ящик управления (Я5111-2274, Iн=2А) | C19: 1 | D19: =BOM!H215 -> 22108.266 | E19: =C19*D19 -> 22108.266
A20: 19 | B20: Ящик управления (Я5111-2674, Iн=5А) | C20: 3 | D20: =BOM!H225 -> 22108.266 | E20: =C20*D20 -> 66324.798
B21: GENEL TOPLAM | E21: =SUM(E2:E20) -> 1791721.4

Sheet Kurallar
A1: KURALLAR — sarı hücreler düzenlenebilir
A2: CHINT katsayı (net = liste × katsayı) | B2: 0.6
A3: EKT katsayı | B3: 1
A4: Saiman katsayı | B4: 1
A5: Montaj malzemesi % | B5: 0.03
A6: Montaj işçilik % | B6: 0.2
A9: FİYAT KAYNAKLARI ve TAZELİK (BOM tarihi: 13.07.2026):
A10: CHINT — 260613 chint Остатки...xlsx, 13.06.2026 (güncel). Net = liste × B2.
A11: EKT — 19062025 EKT PRICE.xlsx, 17.06.2025 (~13 ay, UYARI bandı 12-18 ay). Net = liste × B3.
A12: Saiman — САЙМАН 2026 прайс, 2026 (güncel, onaylı tarife). Net = liste × B4.
A13: Kaynak sütununda dosya/sayfa/satır no verilmiştir; fiyat güncellemesinde aynı satıra bakınız.
A15: NOTLAR:
A16: ЩС-4: modül hesabı 34 mod + %20 > 36 → korpus ЩРВ-48'e büyütüldü (projede ЩРВ-36).
A17: ЩС-6: 18 mod + %20 > 18 → korpus ЩРВ-24'e büyütüldü (projede ЩРВ-18).
A18: ВРУ1-11-10: rubilnik 200А yerine ВР-32-35 250А (200А 2-yönlü EKT/CHINT'te yok).
A19: АВР: proje ЯАВР-160А; giriş akımı 58,44А → АВР 100А DEK önerildi (KONTROL).
A20: Sayaç СА4У-Э412 5А → Saiman Дала СА4У-Э720 5-7,5А (trafo bağlantılı) muadili.
A21: Ящик upravleniya Я5411/Я5111 → ЩМП-1-1 + NXC-09 + NXR-25 + buton/lamba olarak komple edildi (TECHNICAL).
