Workbook

Sheet BOM
A1: ROW | B1: Наименование1 | C1: Тип | D1: Артикул | E1: Номенклатура | F1: Цена (прайс) | G1: Цена нетто | H1: Сумма | I1: Кол-во | J1: Ед.изм. | K1: Завод | L1: MALZ
A2: 1 | B2: ADP-CELALABAD/K | C2: korpus | D2: 719-15626 | E2: Мет. Щит 1700x700x400 + 10 см база, IP54, dikili, dış ortam | F2: =Kurallar!$C$58 -> 117250 | G2: =F2*Kurallar!$C$11 -> 117250 | H2: =G2*I2 -> 117250 | I2: 1 | J2: шт. | K2: KAZTEK | L2: 117250
A3: 2 | B3: ADP-CELALABAD/K | C3: TMŞ | D3: 131367 | E3: Авт. выкл. NXM-250S/3Р 200A 36кА (R) | F3: 34800 | G3: =F3*Kurallar!$C$10 -> 20880 | H3: =G3*I3 -> 41760 | I3: 2 | J3: шт. | K3: chint | L3: 41760
A4: 3 | B4: ADP-CELALABAD/K | C4: blok | D4: 946972 | E4: Независимый расцепитель SHT-M3 A1 L для NXM(LE)-320(250) AC230V (левый) (R) | F4: 6054 | G4: =F4*Kurallar!$C$10 -> 3632.4 | H4: =G4*I4 -> 3632.4 | I4: 1 | J4: шт. | K4: chint | L4: 3632.4
A5: 4 | B5: ADP-CELALABAD/K | C5: buton | D5: 574862 | E5: Кнопка управления «Грибок» Φ40 с фиксацией NP2-BS542, красная 1НЗ IP40 | F5: 1799 | G5: =F5*Kurallar!$C$10 -> 1079.4 | H5: =G5*I5 -> 1079.4 | I5: 1 | J5: шт. | K5: chint | L5: 1079.4
A6: 5 | B6: ADP-CELALABAD/K | C6: OTO | D6: 813875 | E6: Авт. выкл. NXB-63H 3P 40A 10кА х-ка C (R) | F6: 11002 | G6: =F6*Kurallar!$C$10 -> 6601.2 | H6: =G6*I6 -> 26404.8 | I6: 4 | J6: шт. | K6: chint | L6: 26404.8
A7: 6 | B7: ADP-CELALABAD/K | C7: OTO | D7: 813874 | E7: Авт. выкл. NXB-63H 3P 32A 10кА х-ка C (R) | F7: 11771 | G7: =F7*Kurallar!$C$10 -> 7062.6 | H7: =G7*I7 -> 21187.8 | I7: 3 | J7: шт. | K7: chint | L7: 21187.8
A8: 7 | B8: ADP-CELALABAD/K | C8: OTO | D8: 813873 | E8: Авт. выкл. NXB-63H 3P 25A 10кА х-ка C (R) | F8: 10552 | G8: =F8*Kurallar!$C$10 -> 6331.2 | H8: =G8*I8 -> 6331.2 | I8: 1 | J8: шт. | K8: chint | L8: 6331.2
A9: 8 | B9: ADP-CELALABAD/K | C9: OTO | D9: 814171 | E9: Авт. выкл. NXB-63 3P 20A 6кА х-ка C (R) [шема: 10 кА] | F9: 5884 | G9: =F9*Kurallar!$C$10 -> 3530.4 | H9: =G9*I9 -> 3530.4 | I9: 1 | J9: шт. | K9: chint | L9: 3530.4
A10: 9 | B10: ADP-CELALABAD/K | C10: OTO | D10: 296695 | E10: Авт. выкл. NXB-63S 1P 6А 4.5kA х-ка B (R) | F10: 1094 | G10: =F10*Kurallar!$C$10 -> 656.4 | H10: =G10*I10 -> 1969.2 | I10: 3 | J10: шт. | K10: chint | L10: 1969.2
A11: 10 | B11: ADP-CELALABAD/K | C11: DİF | D11: 280934 | E11: УЗО NXL-63 10kA 3P+N 63A 300mA AC (R) | F11: 15688 | G11: =F11*Kurallar!$C$10 -> 9412.8 | H11: =G11*I11 -> 9412.8 | I11: 1 | J11: шт. | K11: chint | L11: 9412.8
A12: 11 | B12: ADP-CELALABAD/K | C12: DİF | D12: 280931 | E12: УЗО NXL-63 10kA 3P+N 25A 300mA AC (R) | F12: 14942 | G12: =F12*Kurallar!$C$10 -> 8965.2 | H12: =G12*I12 -> 8965.2 | I12: 1 | J12: шт. | K12: chint | L12: 8965.2
A13: 12 | B13: ADP-CELALABAD/K | C13: opn | D13: 308602 | E13: Ограничитель имп. перенапр. NXU-I+II 4P In=25kA Uc=385В Iimp=12.5kA (R) | F13: 56704 | G13: =F13*Kurallar!$C$10 -> 34022.4 | H13: =G13*I13 -> 34022.4 | I13: 1 | J13: шт. | K13: chint | L13: 34022.4
A14: 13 | B14: ADP-CELALABAD/K | C14: fu | D14: 521366 | E14: Держатель плавкой вставки RT36-0-160, габарит 0, 160А | F14: 3100 | G14: =F14*Kurallar!$C$10 -> 1860 | H14: =G14*I14 -> 7440 | I14: 4 | J14: шт. | K14: chint | L14: 7440
... A20: 19 | B20: ADP-CELALABAD/K | C20: lamb | D20: 593075 | E20: Индикатор ND16-22D/2 красный AC/DC230В (R) [L3] | F20: 571 | G20: =F20*Kurallar!$C$10 -> 342.6 | H20: =G20*I20 -> 342.6 | I20: 1 | J20: шт. | K20: chint | L20: 342.6
A21: 20 | B21: ADP-CELALABAD/K | C21: LOOBAR | D21: 718-42016 | E21: Шина медная нулевая 8х12 мм, 1 м | F21: 7415 | G21: =F21*Kurallar!$C$11 -> 7415 | H21: =G21*I21 -> 29660 | I21: 4 | J21: м | K21: PYS | L21: 29660
A22: 21 | B22: ADP-CELALABAD/K | C22: Klemens | D22: 718-42040 | E22: Клеммник на DIN-рейку 35 мм² | F22: 825 | G22: =F22*Kurallar!$C$11 -> 825 | H22: =G22*I22 -> 4125 | I22: 5 | J22: шт. | K22: PYS | L22: 4125
A23: 22 | B23: ADP-CELALABAD/K | C23: Klemens | D23: 718-42033 | E23: Клеммник на DIN-рейку 16 мм² | F23: 260 | G23: =F23*Kurallar!$C$11 -> 260 | H23: =G23*I23 -> 7800 | I23: 30 | J23: шт. | K23: PYS | L23: 7800
A24: 23 | B24: ADP-CELALABAD/K | C24: Klemens | D24: 718-42030 | E24: Клеммник на DIN-рейку 6 мм² | F24: 445 | G24: =F24*Kurallar!$C$11 -> 445 | H24: =G24*I24 -> 11125 | I24: 25 | J24: шт. | K24: PYS | L24: 11125
A25: 24 | B25: ADP-CELALABAD/K | C25: LOOBAR | D25: 718-84009 | E25: Шина «N» нулевая 4х11 групп на DIN-рейку в корпусе IEK | F25: 4610 | G25: =F25*Kurallar!$C$11 -> 4610 | H25: =G25*I25 -> 4610 | I25: 1 | J25: шт. | K25: IEK | L25: 4610
A26: 26 | B26: ADP-CELALABAD/K | C26: montaj | D26: 408-15050 | E26: Кабель-канал перфорированный 60x40 | F26: 385 | G26: =F26*Kurallar!$C$11 -> 385 | H26: =G26*I26 -> 770 | I26: 2 | J26: м | K26: PYS | L26: 770
A27: 27 | B27: ADP-CELALABAD/K | C27: montajный материал | D27: — | E27: Монтажный материал (клеммы NSHVI, маркировка, крепёж, провод) | F27: =ROUND(SUM(H2:H26)*Kurallar!$C$12,0) -> 10488 | G27: =F27 -> 10488 | H27: =G27*I27 -> 10.488 | I27: 0.001 | J27: шт. | K27: TEKLED | L27: 10.488
A28: 28 | B28: ADP-CELALABAD/K | C28: montajная работа | D28: — | E28: Монтажные работы (сборка, маркировка, испытание) | F28: =ROUND(I28/60,1) -> 6.9 | G28: =Kurallar!$C$13 -> 100 | H28: =G28*I28 -> 41300 | I28: =ROUND((Kurallar!$C$53+Kurallar!$C$32*2+Kurallar!$C$42*1+Kurallar!$C$31*9+Kurallar!$C$30*3+Kurallar!$C$34*2+Kurallar!$C$35*1+Kurallar!$C$36*8+Kurallar!$C$41*3+Kurallar!$C$50*4+Kurallar!$C$45*60+Kurallar!$C$47*2+Kurallar!$C$48*4+Kurallar!$C$49*8)*Kurallar!$C$54,0)/3 -> 413 | J28: мин. | K28: TEKLED | L28: 61950
A29: 29 | B29: ПОДВАЛ-ELP | C29: korpus | D29: özel imalat | E29: Özel imalat sıva altı 500x800x180, üstten girişli, klemens bölmesi 30 cm | F29: =Kurallar!$C$59 -> 55000 | G29: =F29*Kurallar!$C$11 -> 55000 | H29: =G29*I29 -> 55000 | I29: 1 | J29: шт. | K29: KAZTEK | L29: 55000
A30: 30 | B30: ПОДВАЛ-ELP | C30: OTO | D30: 814172 | E30: Авт. выкл. NXB-63 3P 25A 6кА х-ка C (R) [giriş] | F30: 5334 | G30: =F30*Kurallar!$C$10 -> 3200.4 | H30: =G30*I30 -> 3200.4 | I30: 1 | J30: шт. | K30: chint | L30: 3200.4
A31: 31 | B31: ПОДВАЛ-ELP | C31: OTO | D31: 296695 | E31: Авт. выкл. NXB-63S 1P 6А 4.5kA х-ка B (R) | F31: 1094 | G31: =F31*Kurallar!$C$10 -> 656.4 | H31: =G31*I31 -> 1969.2 | I31: 3 | J31: шт. | K31: chint | L31: 1969.2
A32: 32 | B32: ПОДВАЛ-ELP | C32: DİF | D32: 280721 | E32: УЗО NXL-63 6kA 1P+N 25A 30mA AC (R) | F32: 7422 | G32: =F32*Kurallar!$C$10 -> 4453.2 | H32: =G32*I32 -> 8906.4 | I32: 2 | J32: шт. | K32: chint | L32: 8906.4
A33: 33 | B33: ПОДВАЛ-ELP | C33: DİF | D33: 280789 | E33: УЗО NXL-63 6kA 3P+N 25A 30mA AC (R) | F33: 13357 | G33: =F33*Kurallar!$C$10 -> 8014.2 | H33: =G33*I33 -> 16028.4 | I33: 2 | J33: шт. | K33: chint | L33: 16028.4
A34: 34 | B34: ПОДВАЛ-ELP | C34: DİF | D34: 280791 | E34: УЗО NXL-63 6kA 3P+N 40A 30mA AC (R) | F34: 13357 | G34: =F34*Kurallar!$C$10 -> 8014.2 | H34: =G34*I34 -> 8014.2 | I34: 1 | J34: шт. | K34: chint | L34: 8014.2
A35: 35 | B35: ПОДВАЛ-ELP | C35: OTO | D35: 296696 | E35: Авт. выкл. NXB-63S 1P 10А 4.5kA х-ка B (R) | F35: 897 | G35: =F35*Kurallar!$C$10 -> 538.2 | H35: =G35*I35 -> 2152.8 | I35: 4 | J35: шт. | K35: chint | L35: 2152.8
A36: 36 | B36: ПОДВАЛ-ELP | C36: OTO | D36: 296710 | E36: Авт. выкл. NXB-63S 1P 16А 4.5kA х-ка C (R) | F36: 783 | G36: =F36*Kurallar!$C$10 -> 469.8 | H36: =G36*I36 -> 3288.6 | I36: 7 | J36: шт. | K36: chint | L36: 3288.6
A37: 37 | B37: ПОДВАЛ-ELP | C37: OTO | D37: 296827 | E37: Авт. выкл. NXB-63S 3P 16А 4.5kA х-ка C (R) | F37: 2337 | G37: =F37*Kurallar!$C$10 -> 1402.2 | H37: =G37*I37 -> 2804.4 | I37: 2 | J37: шт. | K37: chint | L37: 2804.4
A38: 38 | B38: ПОДВАЛ-ELP | C38: lamb | D38: 593076 | E38: Индикатор ND16-22D/2 желтый AC/DC230В (R) [L1] | F38: 571 | G38: =F38*Kurallar!$C$10 -> 342.6 | H38: =G38*I38 -> 342.6 | I38: 1 | J38: шт. | K38: chint | L38: 342.6
A39: 39 | B39: ПОДВАЛ-ELP | C39: lamb | D39: 593077 | E39: Индикатор ND16-22D/2 зеленый AC/DC230В (R) [L2] | F39: 589 | G39: =F39*Kurallar!$C$10 -> 353.4 | H39: =G39*I39 -> 353.4 | I39: 1 | J39: шт. | K39: chint | L39: 353.4
A40: 40 | B40: ПОДВАЛ-ELP | C40: lamb | D40: 593075 | E40: Индикатор ND16-22D/2 красный AC/DC230В (R) [L3] | F40: 571 | G40: =F40*Kurallar!$C$10 -> 342.6 | H40: =G40*I40 -> 342.6 | I40: 1 | J40: шт. | K40: chint | L40: 342.6
A41: 41 | B41: ПОДВАЛ-ELP | C41: LOOBAR | D41: 811000 | E41: Шина соединительная типа PIN 1P, 63А, L=1000 мм (R) | F41: 4465 | G41: =F41*Kurallar!$C$10 -> 2679 | H41: =G41*I41 -> 2679 | I41: 1 | J41: шт. | K41: chint | L41: 2679
A42: 42 | B42: ПОДВАЛ-ELP | C42: Klemens | D42: 718-42025 | E42: Клеммник на DIN-рейку 2,5 мм² | F42: 130 | G42: =F42*Kurallar!$C$11 -> 130 | H42: =G42*I42 -> 3900 | I42: 30 | J42: шт. | K42: PYS | L42: 5850
A43: 43 | B43: ПОДВАЛ-ELP | C43: Klemens | D43: 718-42030 | E43: Клеммник на DIN-рейку 6 мм² [giriş 5x4 мм²] | F43: 445 | G43: =F43*Kurallar!$C$11 -> 445 | H43: =G43*I43 -> 2225 | I43: 5 | J43: шт. | K43: PYS | L43: 2225
A44: 44 | B44: ПОДВАЛ-ELP | C44: LOOBAR | D44: 718-84018 | E44: Шина «N» нулевая 4х7 групп на DIN-рейку в корпусе IEK | F44: 3610 | G44: =F44*Kurallar!$C$11 -> 3610 | H44: =G44*I44 -> 3610 | I44: 1 | J44: шт. | K44: IEK | L44: 7220
A45: 46 | B45: ПОДВАЛ-ELP | C45: montaj | D45: 408-15040 | E45: Кабель-канал перфорированный 40x25 | F45: 210 | G45: =F45*Kurallar!$C$11 -> 210 | H45: =G45*I45 -> 1260 | I45: 6 | J45: м | K45: PYS | L45: 1260
...

Sheet FIYAT

Sheet Kurallar
A1: KURALLAR / PARAMETRELER — Celalabad Kız Yurdu (CHINT)
A3: 1. PROJE
A4: BOM tarihi | C4: 04.08.2026
A5: Proje | C5: Celalabad Kız Yurdu — C.Doğan
A6: Marka | C6: CHINT (korpus: TEKLED / özel imalat)
A7: Kaynak şema | C7: Celalabad_Kiz_Tek_Hat_Semalari-01_08_2026
A9: 2. FİYAT KATSAYILARI
A10: CHINT net katsayı | C10: 0.6 | D10: liste × 0,60 (%40 indirim)
A11: TEKLED/IEK/MUTLUSAN katsayı | C11: 1 | D11: liste × 1,00
A12: Montaj malzemesi oranı | C12: 0.03 | D12: pano malzeme ara toplamının %3'ü
A13: İşçilik birim (KZT/dakika) | C13: 100
A15: 3. FİYAT LİSTESİ YAŞ DURUMU
A16: Liste | B16: Tarih | C16: Yaş (ay) | D16: Durum
A17: CHINT stok+fiyat | B17: 13.06.2026 | C17: 2 | D17: KULLANILDI — güncel
A18: Kaztek/TEKLED pano | B18: 15.07.2026 | C18: 1 | D18: KULLANILDI — güncel
A19: Sayman | B19: 2026 | C19: 0 | D19: kullanılmadı
A20: ABB | B20: 11.2025 | C20: 9 | D20: kullanılmadı
A21: Legrand | B21: 10.2025 | C21: 10 | D21: kullanılmadı
A22: Schneider | B22: 07.2025 | C22: 13 | D22: UYARI — kullanılmadı
A23: EKT | B23: 06.2025 | C23: 14 | D23: UYARI — kullanılmadı
A24: CNC | B24: 02.2025 | C24: 18 | D24: UYARI — kullanılmadı
A25: Klemsan | B25: 11.2022 | C25: 45 | D25: YASAK — fiyatlamada kullanılamaz
A26: ONKA | B26: 07.2022 | C26: 49 | D26: YASAK — fiyatlamada kullanılamaz
A27: EKF | B27: 02.2022 | C27: 54 | D27: YASAK — fiyatlamada kullanılamaz
A29: 4. İŞÇİLİK ZAMAN NORMLARI (dakika)
A30: MCB 1 kutup | C30: 10
A31: MCB 3 kutup | C31: 18
A32: MCCB / kompakt şalter ≤250A | C32: 60
A33: RCCB / UZO 2 kutup | C33: 14
A34: RCCB / UZO 4 kutup | C34: 18
A35: Parafudr (SPD) | C35: 15
A36: Sigorta yuvası + buşon | C36: 10 | D36: yuva başına
A37: Kontaktör | C37: 20
A38: Termik röle | C38: 12
A39: Zaman saati / röle | C39: 15
A40: Pako şalter | C40: 20
A41: Sinyal lambası | C41: 8
A42: Buton (mantar/acil) | C42: 10
A43: Faz kontrol rölesi | C43: 15
A44: Frekans konvertörü (VFD) | C44: 60
...

Sheet СВОД
A1: № | B1: Наименование | C1: Сумма | D1: Кол-во | E1: Ед.изм. | F1: MALZ
A2: 1 | B2: MAIN PANEL | C2: =BOM!#REF! -> #REF! | D2: 1 | E2: комплект | F2: =BOM!#REF! -> #REF!
A3: 2 | B3: ПОДВАЛ-ELP | C3: =BOM!#REF! -> #REF! | D3: 1 | E3: комплект | F3: =BOM!#REF! -> #REF!
A4: 3 | B4: АДМИНИСТРАЦИЯ-ELP | C4: =BOM!#REF! -> #REF! | D4: 1 | E4: комплект | F4: =BOM!#REF! -> #REF!
A5: 4 | B5: ZK-ELP | C5: =BOM!#REF! -> #REF! | D5: 1 | E5: комплект | F5: =BOM!#REF! -> #REF!
A6: 5 | B6: 2K-ELP | C6: =BOM!#REF! -> #REF! | D6: 1 | E6: комплект | F6: =BOM!#REF! -> #REF!
A7: 6 | B7: КРЫША-ELP | C7: =BOM!#REF! -> #REF! | D7: 1 | E7: комплект | F7: =BOM!#REF! -> #REF!
A8: 7 | B8: КОТЕЛЬНАЯ-ELP | C8: =BOM!#REF! -> #REF! | D8: 1 | E8: комплект | F8: =BOM!#REF! -> #REF!
B9: ИТОГО | C9: =SUM(C2:C8) -> #REF! | F9: =SUM(F2:F8) -> #REF!
