Workbook

Sheet BOM
A1: ROW | B1: Наименование1 | C1: Тип | D1: Артикул | E1: Номенклатура | F1: Цена (лист) | G1: Цена нетто KZT | H1: Сумма KZT | I1: Кол-во | J1: Ед.изм. | K1: Завод
A2: 1 | B2: =E2 -> ЩУ-1 (нагрев 20 кВт + вентилятор 3 кВт) | E2: ЩУ-1 (нагрев 20 кВт + вентилятор 3 кВт) | I2: 4 | J2: комплект
A3: 2 | C3: korpus | D3: 719-15 | E3: Мет. ЩМП-3 (650х500х220) IP54 | F3: =IFERROR(INDEX(FIYAT_KAYNAK!$F$3:$F$26,MATCH("KAZTEK|714-15120",FIYAT_KAYNAK!$A$3:$A$26,0)),"") -> 29525 | G3: =0.6*F3 -> 17715 | H3: =IF(OR(G3="",I3=""),"",G3*I3) -> 17715 | I3: 1 | J3: шт | K3: KAZTEK
A4: 4 | C4: OTO | D4: A9F79320 | E4: Автоматический выключатель Acti9 iC60N 3P 20A, характеристика C, 6кА — нагреватель, ступени 1 и 2 | F4: =IFERROR(INDEX(FIYAT_KAYNAK!$F$3:$F$26,MATCH("SCHNEIDER|A9F79320",FIYAT_KAYNAK!$A$3:$A$26,0)),"") -> 1884 | G4: =IFERROR(INDEX(FIYAT_KAYNAK!$J$3:$J$26,MATCH("SCHNEIDER|A9F79320",FIYAT_KAYNAK!$A$3:$A$26,0)),"") -> 12321.36 | H4: =IF(OR(G4="",I4=""),"",G4*I4) -> 24642.72 | I4: 2 | J4: шт | K4: SCHNEIDER
A5: 6 | C5: OTO | D5: A9F79110 | E5: Автоматический выключатель Acti9 iC60N 1P 10A, характеристика C, 6кА — освещение | F5: =IFERROR(INDEX(FIYAT_KAYNAK!$F$3:$F$26,MATCH("SCHNEIDER|A9F79110",FIYAT_KAYNAK!$A$3:$A$26,0)),"") -> 446.8 | G5: =IFERROR(INDEX(FIYAT_KAYNAK!$J$3:$J$26,MATCH("SCHNEIDER|A9F79110",FIYAT_KAYNAK!$A$3:$A$26,0)),"") -> 2922.072 | H5: =IF(OR(G5="",I5=""),"",G5*I5) -> 2922.072 | I5: 1 | J5: шт | K5: SCHNEIDER
A6: 7 | C6: OTO | D6: A9F79106 | E6: Автоматический выключатель Acti9 iC60N 1P 6A, характеристика C, 6кА — обратный клапан и цепь термостата/управления | F6: =IFERROR(INDEX(FIYAT_KAYNAK!$F$3:$F$26,MATCH("SCHNEIDER|A9F79106",FIYAT_KAYNAK!$A$3:$A$26,0)),"") -> 446.8 | G6: =IFERROR(INDEX(FIYAT_KAYNAK!$J$3:$J$26,MATCH("SCHNEIDER|A9F79106",FIYAT_KAYNAK!$A$3:$A$26,0)),"") -> 2922.072 | H6: =IF(OR(G6="",I6=""),"",G6*I6) -> 5844.144 | I6: 2 | J6: шт | K6: SCHNEIDER
A7: 8 | C7: kontaktör | D7: LC1E1810M5 | E7: Контактор Easy TeSys LC1E1810M5 3P, катушка 220В AC 50Гц — ступени нагревателя 1 и 2 (10 кВт каждая) | F7: =IFERROR(INDEX(FIYAT_KAYNAK!$F$3:$F$26,MATCH("SCHNEIDER|LC1E1810M5",FIYAT_KAYNAK!$A$3:$A$26,0)),"") -> 1628 | G7: =IFERROR(INDEX(FIYAT_KAYNAK!$J$3:$J$26,MATCH("SCHNEIDER|LC1E1810M5",FIYAT_KAYNAK!$A$3:$A$26,0)),"") -> 10647.12 | H7: =IF(OR(G7="",I7=""),"",G7*I7) -> 21294.24 | I7: 2 | J7: шт | K7: SCHNEIDER
A8: 9 | C8: kontaktör | D8: LC1E0910M5 | E8: Контактор Easy TeSys LC1E0910M5 3P, катушка 220В AC 50Гц — вентилятор 3 кВт | F8: =IFERROR(INDEX(FIYAT_KAYNAK!$F$3:$F$26,MATCH("SCHNEIDER|LC1E0910M5",FIYAT_KAYNAK!$A$3:$A$26,0)),"") -> 1217 | G8: =IFERROR(INDEX(FIYAT_KAYNAK!$J$3:$J$26,MATCH("SCHNEIDER|LC1E0910M5",FIYAT_KAYNAK!$A$3:$A$26,0)),"") -> 7959.18 | H8: =IF(OR(G8="",I8=""),"",G8*I8) -> 7959.18 | I8: 1 | J8: шт | K8: SCHNEIDER
A9: 10 | C9: kontaktör | D9: LC1E0610M5 | E9: Контактор Easy TeSys LC1E0610M5 3P 6A, катушка 220В AC 50Гц — реле освещения и реле обратного клапана | F9: =IFERROR(INDEX(FIYAT_KAYNAK!$F$3:$F$26,MATCH("SCHNEIDER|LC1E0610M5",FIYAT_KAYNAK!$A$3:$A$26,0)),"") -> 1154 | G9: =IFERROR(INDEX(FIYAT_KAYNAK!$J$3:$J$26,MATCH("SCHNEIDER|LC1E0610M5",FIYAT_KAYNAK!$A$3:$A$26,0)),"") -> 7547.16 | H9: =IF(OR(G9="",I9=""),"",G9*I9) -> 15094.32 | I9: 2 | J9: шт | K9: SCHNEIDER
A10: 11 | C10: Sinyal Lambası | D10: 593012 | E10: Индикатор ND16-22DS/4 красный АС230В, Ø22 мм, на дверь | F10: =IFERROR(INDEX(FIYAT_KAYNAK!$F$3:$F$26,MATCH("CHINT|593012",FIYAT_KAYNAK!$A$3:$A$26,0)),"") -> 836 | G10: =IFERROR(INDEX(FIYAT_KAYNAK!$J$3:$J$26,MATCH("CHINT|593012",FIYAT_KAYNAK!$A$3:$A$26,0)),"") -> 501.6 | H10: =IF(OR(G10="",I10=""),"",G10*I10) -> 1504.8 | I10: 3 | J10: шт | K10: CHINT
A11: 12 | C11: Klemens | D11: 130301157_ | E11: ЗНИ 16мм² (100А) серый UNIT — ввод L1/L2/L3 | F11: =IFERROR(INDEX(FIYAT_KAYNAK!$F$3:$F$26,MATCH("EKT|130301157_",FIYAT_KAYNAK!$A$3:$A$26,0)),"") -> 235 | G11: =IFERROR(INDEX(FIYAT_KAYNAK!$J$3:$J$26,MATCH("EKT|130301157_",FIYAT_KAYNAK!$A$3:$A$26,0)),"") -> 235 | H11: =IF(OR(G11="",I11=""),"",G11*I11) -> 705 | I11: 3 | J11: шт | K11: EKT
A12: 13 | C12: Klemens | D12: 130301158_ | E12: ЗНИ 16мм² (100А) синий UNIT — ввод N | F12: =IFERROR(INDEX(FIYAT_KAYNAK!$F$3:$F$26,MATCH("EKT|130301158_",FIYAT_KAYNAK!$A$3:$A$26,0)),"") -> 269 | G12: =IFERROR(INDEX(FIYAT_KAYNAK!$J$3:$J$26,MATCH("EKT|130301158_",FIYAT_KAYNAK!$A$3:$A$26,0)),"") -> 269 | H12: =IF(OR(G12="",I12=""),"",G12*I12) -> 269 | I12: 1 | J12: шт | K12: EKT
A13: 14 | C13: Klemens | D13: 130300227_ | E13: ЗНИ 10PEN 10мм² (JXB-земля) IEK E-PRO — шина PE | F13: =IFERROR(INDEX(FIYAT_KAYNAK!$F$3:$F$26,MATCH("EKT|130300227_",FIYAT_KAYNAK!$A$3:$A$26,0)),"") -> 155 | G13: =IFERROR(INDEX(FIYAT_KAYNAK!$J$3:$J$26,MATCH("EKT|130300227_",FIYAT_KAYNAK!$A$3:$A$26,0)),"") -> 155 | H13: =IF(OR(G13="",I13=""),"",G13*I13) -> 775 | I13: 5 | J13: шт | K13: EKT
A14: 15 | C14: Klemens | D14: 130301154_ | E14: ЗНИ 6мм² серый UNIT — выход на нагреватели (2 ступени × 4) | F14: =IFERROR(INDEX(FIYAT_KAYNAK!$F$3:$F$26,MATCH("EKT|130301154_",FIYAT_KAYNAK!$A$3:$A$26,0)),"") -> 111 | G14: =IFERROR(INDEX(FIYAT_KAYNAK!$J$3:$J$26,MATCH("EKT|130301154_",FIYAT_KAYNAK!$A$3:$A$26,0)),"") -> 111 | H14: =IF(OR(G14="",I14=""),"",G14*I14) -> 888 | I14: 8 | J14: шт | K14: EKT
A15: 16 | C15: Klemens | D15: 130301153_ | E15: ЗНИ 4мм² (35А) серый UNIT — выход на вентилятор | F15: =IFERROR(INDEX(FIYAT_KAYNAK!$F$3:$F$26,MATCH("EKT|130301153_",FIYAT_KAYNAK!$A$3:$A$26,0)),"") -> 90 | G15: =IFERROR(INDEX(FIYAT_KAYNAK!$J$3:$J$26,MATCH("EKT|130301153_",FIYAT_KAYNAK!$A$3:$A$26,0)),"") -> 90 | H15: =IF(OR(G15="",I15=""),"",G15*I15) -> 360 | I15: 4 | J15: шт | K15: EKT
A16: 17 | C16: Klemens | D16: 130301152_ | E16: ЗНИ 2.5мм² (24А) серый UNIT — цепи управления, лампа, обратный клапан, термостат, резерв | F16: =IFERROR(INDEX(FIYAT_KAYNAK!$F$3:$F$26,MATCH("EKT|130301152_",FIYAT_KAYNAK!$A$3:$A$26,0)),"") -> 90 | G16: =IFERROR(INDEX(FIYAT_KAYNAK!$J$3:$J$26,MATCH("EKT|130301152_",FIYAT_KAYNAK!$A$3:$A$26,0)),"") -> 90 | H16: =IF(OR(G16="",I16=""),"",G16*I16) -> 2700 | I16: 30 | J16: шт | K16: EKT
A17: 18 | C17: montajный материал | D17: 570002 | E17: DIN-рейка оцинкованная TH35-7.5, длина 2000 мм | F17: =IFERROR(INDEX(FIYAT_KAYNAK!$F$3:$F$26,MATCH("CHINT|570002",FIYAT_KAYNAK!$A$3:$A$26,0)),"") -> 2232 | G17: =IFERROR(INDEX(FIYAT_KAYNAK!$J$3:$J$26,MATCH("CHINT|570002",FIYAT_KAYNAK!$A$3:$A$26,0)),"") -> 1339.2 | H17: =IF(OR(G17="",I17=""),"",G17*I17) -> 1339.2 | I17: 1 | J17: шт | K17: CHINT
A18: 19 | C18: montajный материал | D18: 280100020_ | E18: Кабель-канал перфорированный 40х40 ИМПАКТ IEK, длина 2000 мм | F18: =IFERROR(INDEX(FIYAT_KAYNAK!$F$3:$F$26,MATCH("EKT|280100020_",FIYAT_KAYNAK!$A$3:$A$26,0)),"") -> 1486 | G18: =IFERROR(INDEX(FIYAT_KAYNAK!$J$3:$J$26,MATCH("EKT|280100020_",FIYAT_KAYNAK!$A$3:$A$26,0)),"") -> 1486 | H18: =IF(OR(G18="",I18=""),"",G18*I18) -> 2972 | I18: 2 | J18: шт | K18: EKT
A19: 20 | C19: montajный материал | D19: 270300079_ | E19: Кабель-канал перфорированный 25х40 ИМПАКТ IEK, длина 2000 мм | F19: =IFERROR(INDEX(FIYAT_KAYNAK!$F$3:$F$26,MATCH("EKT|270300079_",FIYAT_KAYNAK!$A$3:$A$26,0)),"") -> 1094 | G19: =IFERROR(INDEX(FIYAT_KAYNAK!$J$3:$J$26,MATCH("EKT|270300079_",FIYAT_KAYNAK!$A$3:$A$26,0)),"") -> 1094 | H19: =IF(OR(G19="",I19=""),"",G19*I19) -> 1094 | I19: 1 | J19: шт | K19: EKT
A20: 21 | C20: montajный материал | E20: Монтажные материалы (крепёж, маркировка, наконечники) | G20: =SUM(H3:H19)*Kurallar!$B$13 -> 3242.3603 | H20: =G20*I20 -> 3242.3603 | I20: 1 | J20: компл. | K20: —
A21: 22 | C21: montajная работа | E21: Сборка щита (норма времени, см. лист «Kurallar») | F21: =I21/60 -> 5.26125 | G21: =Kurallar!$B$11 -> 100 | H21: =G21*I21 -> 31567.5 | I21: =Kurallar!$D$41 -> 315.675 | J21: мин | K21: YSF
B22: Toplam ЩУ-1 (нагрев 20 кВт + вентилятор 3 кВт) | H22: =SUBTOTAL(9,H3:H21) -> 17715 | I22: 4 | J22: компл.
A23: 23 | B23: =E23 -> ЩУ-2 (нагрев 26 кВт + вентилятор 8 кВт) | E23: ЩУ-2 (нагрев 26 кВт + вентилятор 8 кВт) | I23: 10 | J23: комплект
A24: 24 | C24: korpus | D24: 719-15 | E24: Мет. ЩМП-3 (650х500х220) IP54 | F24: =IFERROR(INDEX(FIYAT_KAYNAK!$F$3:$F$26,MATCH("KAZTEK|714-15120",FIYAT_KAYNAK!$A$3:$A$26,0)),"") -> 29525 | G24: =0.6*F24 -> 17715 | H24: =IF(OR(G24="",I24=""),"",G24*I24) -> 17715 | I24: 1 | J24: шт | K24: KAZTEK
A25: 25 | C25: OTO | D25: A9F79363 | E25: Автоматический выключатель Acti9 iC60N 3P 63A, характеристика C, 6кА — вводной | F25: =IFERROR(INDEX(FIYAT_KAYNAK!$F$3:$F$26,MATCH("SCHNEIDER|A9F79363",FIYAT_KAYNAK!$A$3:$A$26,0)),"") -> 3335 | G25: =IFERROR(INDEX(FIYAT_KAYNAK!$J$3:$J$26,MATCH("SCHNEIDER|A9F79363",FIYAT_KAYNAK!$A$3:$A$26,0)),"") -> 21810.9 | H25: =IF(OR(G25="",I25=""),"",G25*I25) -> 21810.9 | I25: 1 | J25: шт | K25: SCHNEIDER
A26: 26 | C26: OTO | D26: A9F79325 | E26: Автоматический выключатель Acti9 iC60N 3P 25A, характеристика C, 6кА — нагреватель, ступени 1 и 2 | F26: =IFERROR(INDEX(FIYAT_KAYNAK!$F$3:$F$26,MATCH("SCHNEIDER|A9F79325",FIYAT_KAYNAK!$A$3:$A$26,0)),"") -> 1884 | G26: =IFERROR(INDEX(FIYAT_KAYNAK!$J$3:$J$26,MATCH("SCHNEIDER|A9F79325",FIYAT_KAYNAK!$A$3:$A$26,0)),"") -> 12321.36 | H26: =IF(OR(G26="",I26=""),"",G26*I26) -> 24642.72 | I26: 2 | J26: шт | K26: SCHNEIDER
A27: 27 | C27: Motor Koruma | D27: GV2ME20 | E27: Автоматический выключатель защиты двигателя TeSys GV2ME20 3P, диапазон уставки 13...18 А — вентилятор 8 кВт, тепловая + магнитная защита | F27: =IFERROR(INDEX(FIYAT_KAYNAK!$F$3:$F$26,MATCH("SCHNEIDER|GV2ME20",FIYAT_KAYNAK!$A$3:$A$26,0)),"") -> 4163 | G27: =IFERROR(INDEX(FIYAT_KAYNAK!$J$3:$J$26,MATCH("SCHNEIDER|GV2ME20",FIYAT_KAYNAK!$A$3:$A$26,0)),"") -> 27226.02 | H27: =IF(OR(G27="",I27=""),"",G27*I27) -> 27226.02 | I27: 1 | J27: шт | K27: SCHNEIDER
A28: 28 | C28: OTO | D28: A9F79110 | E28: Автоматический выключатель Acti9 iC60N 1P 10A, характеристика C, 6кА — освещение | F28: =IFERROR(INDEX(FIYAT_KAYNAK!$F$3:$F$26,MATCH("SCHNEIDER|A9F79110",FIYAT_KAYNAK!$A$3:$A$26,0)),"") -> 446.8 | G28: =IFERROR(INDEX(FIYAT_KAYNAK!$J$3:$J$26,MATCH("SCHNEIDER|A9F79110",FIYAT_KAYNAK!$A$3:$A$26,0)),"") -> 2922.072 | H28: =IF(OR(G28="",I28=""),"",G28*I28) -> 2922.072 | I28: 1 | J28: шт | K28: SCHNEIDER
A29: 29 | C29: OTO | D29: A9F79106 | E29: Автоматический выключатель Acti9 iC60N 1P 6A, характеристика C, 6кА — обратный клапан и цепь термостата/управления | F29: =IFERROR(INDEX(FIYAT_KAYNAK!$F$3:$F$26,MATCH("SCHNEIDER|A9F79106",FIYAT_KAYNAK!$A$3:$A$26,0)),"") -> 446.8 | G29: =IFERROR(INDEX(FIYAT_KAYNAK!$J$3:$J$26,MATCH("SCHNEIDER|A9F79106",FIYAT_KAYNAK!$A$3:$A$26,0)),"") -> 2922.072 | H29: =IF(OR(G29="",I29=""),"",G29*I29) -> 5844.144 | I29: 2 | J29: шт | K29: SCHNEIDER
A30: 30 | C30: kontaktör | D30: LC1E2510M5 | E30: Контактор Easy TeSys LC1E2510M5 3P, катушка 220В AC 50Гц — ступени нагревателя 1 и 2 (13 кВт каждая) | F30: =IFERROR(INDEX(FIYAT_KAYNAK!$F$3:$F$26,MATCH("SCHNEIDER|LC1E2510M5",FIYAT_KAYNAK!$A$3:$A$26,0)),"") -> 2182 | G30: =IFERROR(INDEX(FIYAT_KAYNAK!$J$3:$J$26,MATCH("SCHNEIDER|LC1E2510M5",FIYAT_KAYNAK!$A$3:$A$26,0)),"") -> 14270.28 | H30: =IF(OR(G30="",I30=""),"",G30*I30) -> 28540.56 | I30: 2 | J30: шт | K30: SCHNEIDER
A31: 31 | C31: kontaktör | D31: LC1E2510M5 | E31: Контактор Easy TeSys LC1E2510M5 3P, катушка 220В AC 50Гц — вентилятор 8 кВт | F31: =IFERROR(INDEX(FIYAT_KAYNAK!$F$3:$F$26,MATCH("SCHNEIDER|LC1E2510M5",FIYAT_KAYNAK!$A$3:$A$26,0)),"") -> 2182 | G31: =IFERROR(INDEX(FIYAT_KAYNAK!$J$3:$J$26,MATCH("SCHNEIDER|LC1E2510M5",FIYAT_KAYNAK!$A$3:$A$26,0)),"") -> 14270.28 | H31: =IF(OR(G31="",I31=""),"",G31*I31) -> 14270.28 | I31: 1 | J31: шт | K31: SCHNEIDER
A32: 32 | C32: kontaktör | D32: LC1E0610M5 | E32: Контактор Easy TeSys LC1E0610M5 3P 6A, катушка 220В AC 50Гц — реле освещения и реле обратного клапана | F32: =IFERROR(INDEX(FIYAT_KAYNAK!$F$3:$F$26,MATCH("SCHNEIDER|LC1E0610M5",FIYAT_KAYNAK!$A$3:$A$26,0)),"") -> 1154 | G32: =IFERROR(INDEX(FIYAT_KAYNAK!$J$3:$J$26,MATCH("SCHNEIDER|LC1E0610M5",FIYAT_KAYNAK!$A$3:$A$26,0)),"") -> 7547.16 | H32: =IF(OR(G32="",I32=""),"",G32*I32) -> 15094.32 | I32: 2 | J32: шт | K32: SCHNEIDER
A33: 33 | C33: Sinyal Lambası | D33: 593012 | E33: Индикатор ND16-22DS/4 красный АС230В, Ø22 мм, на дверь | F33: =IFERROR(INDEX(FIYAT_KAYNAK!$F$3:$F$26,MATCH("CHINT|593012",FIYAT_KAYNAK!$A$3:$A$26,0)),"") -> 836 | G33: =IFERROR(INDEX(FIYAT_KAYNAK!$J$3:$J$26,MATCH("CHINT|593012",FIYAT_KAYNAK!$A$3:$A$26,0)),"") -> 501.6 | H33: =IF(OR(G33="",I33=""),"",G33*I33) -> 1504.8 | I33: 3 | J33: шт | K33: CHINT
A34: 34 | C34: Klemens | D34: 130301157_ | E34: ЗНИ 16мм² (100А) серый UNIT — ввод L1/L2/L3 | F34: =IFERROR(INDEX(FIYAT_KAYNAK!$F$3:$F$26,MATCH("EKT|130301157_",FIYAT_KAYNAK!$A$3:$A$26,0)),"") -> 235 | G34: =IFERROR(INDEX(FIYAT_KAYNAK!$J$3:$J$26,MATCH("EKT|130301157_",FIYAT_KAYNAK!$A$3:$A$26,0)),"") -> 235 | H34: =IF(OR(G34="",I34=""),"",G34*I34) -> 705 | I34: 3 | J34: шт | K34: EKT
A35: 35 | C35: Klemens | D35: 130301158_ | E35: ЗНИ 16мм² (100А) синий UNIT — ввод N | F35: =IFERROR(INDEX(FIYAT_KAYNAK!$F$3:$F$26,MATCH("EKT|130301158_",FIYAT_KAYNAK!$A$3:$A$26,0)),"") -> 269 | G35: =IFERROR(INDEX(FIYAT_KAYNAK!$J$3:$J$26,MATCH("EKT|130301158_",FIYAT_KAYNAK!$A$3:$A$26,0)),"") -> 269 | H35: =IF(OR(G35="",I35=""),"",G35*I35) -> 269 | I35: 1 | J35: шт | K35: EKT
A36: 36 | C36: Klemens | D36: 130300227_ | E36: ЗНИ 10PEN 10мм² (JXB-земля) IEK E-PRO — шина PE | F36: =IFERROR(INDEX(FIYAT_KAYNAK!$F$3:$F$26,MATCH("EKT|130300227_",FIYAT_KAYNAK!$A$3:$A$26,0)),"") -> 155 | G36: =IFERROR(INDEX(FIYAT_KAYNAK!$J$3:$J$26,MATCH("EKT|130300227_",FIYAT_KAYNAK!$A$3:$A$26,0)),"") -> 155 | H36: =IF(OR(G36="",I36=""),"",G36*I36) -> 775 | I36: 5 | J36: шт | K36: EKT
A37: 37 | C37: Klemens | D37: 130301154_ | E37: ЗНИ 6мм² серый UNIT — выход на нагреватели (2 ступени × 4) | F37: =IFERROR(INDEX(FIYAT_KAYNAK!$F$3:$F$26,MATCH("EKT|130301154_",FIYAT_KAYNAK!$A$3:$A$26,0)),"") -> 111 | G37: =IFERROR(INDEX(FIYAT_KAYNAK!$J$3:$J$26,MATCH("EKT|130301154_",FIYAT_KAYNAK!$A$3:$A$26,0)),"") -> 111 | H37: =IF(OR(G37="",I37=""),"",G37*I37) -> 888 | I37: 8 | J37: шт | K37: EKT
A38: 38 | C38: Klemens | D38: 130301153_ | E38: ЗНИ 4мм² (35А) серый UNIT — выход на вентилятор | F38: =IFERROR(INDEX(FIYAT_KAYNAK!$F$3:$F$26,MATCH("EKT|130301153_",FIYAT_KAYNAK!$A$3:$A$26,0)),"") -> 90 | G38: =IFERROR(INDEX(FIYAT_KAYNAK!$J$3:$J$26,MATCH("EKT|130301153_",FIYAT_KAYNAK!$A$3:$A$26,0)),"") -> 90 | H38: =IF(OR(G38="",I38=""),"",G38*I38) -> 360 | I38: 4 | J38: шт | K38: EKT
A39: 39 | C39: Klemens | D39: 130301152_ | E39: ЗНИ 2.5мм² (24А) серый UNIT — цепи управления, лампа, обратный клапан, термостат, резерв | F39: =IFERROR(INDEX(FIYAT_KAYNAK!$F$3:$F$26,MATCH("EKT|130301152_",FIYAT_KAYNAK!$A$3:$A$26,0)),"") -> 90 | G39: =IFERROR(INDEX(FIYAT_KAYNAK!$J$3:$J$26,MATCH("EKT|130301152_",FIYAT_KAYNAK!$A$3:$A$26,0)),"") -> 90 | H39: =IF(OR(G39="",I39=""),"",G39*I39) -> 2700 | I39: 30 | J39: шт | K39: EKT
A40: 40 | C40: montajный материал | D40: 570002 | E40: DIN-рейка оцинкованная TH35-7.5, длина 2000 мм | F40: =IFERROR(INDEX(FIYAT_KAYNAK!$F$3:$F$26,MATCH("CHINT|570002",FIYAT_KAYNAK!$A$3:$A$26,0)),"") -> 2232 | G40: =IFERROR(INDEX(FIYAT_KAYNAK!$J$3:$J$26,MATCH("CHINT|570002",FIYAT_KAYNAK!$A$3:$A$26,0)),"") -> 1339.2 | H40: =IF(OR(G40="",I40=""),"",G40*I40) -> 1339.2 | I40: 1 | J40: шт | K40: CHINT
...

Sheet СВОД
A1: Щиты управления электронагревателями (ЩУ-1 / ЩУ-2 / ЩУ-3) — Schneider Electric — СВОДНАЯ ВЕДОМОСТЬ
A2: Rev. R4 · 2026-08-14
A4: Щит | B4: Кол-во компл. | C4: Цена за 1 компл. KZT | D4: Сумма KZT | E4: Модули исп. | F4: Модули всего | G4: Заполнение | H4: Статус
A5: ЩУ-1 (нагрев 20 кВт + вентилятор 3 кВт) | B5: 4 | C5: =BOM!H22 -> 17715 | D5: =B5*C5 -> 70860 | E5: 77.7 | F5: 100 | G5: =E5/F5 -> 0.777 | H5: =IF(E5/F5>1,"⛔ КОРПУС МАЛ",IF(E5/F5>0.8,"⚠ РЕЗЕРВ <20%","✅ OK")) -> ✅ OK
A6: ЩУ-2 (нагрев 26 кВт + вентилятор 8 кВт) | B6: 10 | C6: =BOM!H45 -> 17715 | D6: =B6*C6 -> 177150 | E6: 77.7 | F6: 100 | G6: =E6/F6 -> 0.777 | H6: =IF(E6/F6>1,"⛔ КОРПУС МАЛ",IF(E6/F6>0.8,"⚠ РЕЗЕРВ <20%","✅ OK")) -> ✅ OK
A7: ЩУ-3 (нагрев 22 кВт + вентилятор 8 кВт) | B7: 1 | C7: =BOM!H68 -> 17715 | D7: =B7*C7 -> 17715 | E7: 77.7 | F7: 100 | G7: =E7/F7 -> 0.777 | H7: =IF(E7/F7>1,"⛔ КОРПУС МАЛ",IF(E7/F7>0.8,"⚠ РЕЗЕРВ <20%","✅ OK")) -> ✅ OK
A8: ИТОГО | D8: =SUM(D5:D7) -> 265725

Sheet SATINALMA
A1: ОБЩАЯ ПОТРЕБНОСТЬ НА ЗАКУПКУ — 15 ЩИТОВ (R4)
A2: Цены связаны с листами FIYAT_KAYNAK и Kurallar — изменение курса или коэффициента обновляет страницу автоматически. Монтажные материалы и работы сюда НЕ входят.
A4: Завод | B4: Артикул | C4: Номенклатура | D4: Кол-во | E4: Ед.изм. | F4: Цена (лист) | G4: Цена нетто KZT | H4: Сумма KZT
A5: KAZTEK | B5: 714-15120 | C5: =IFERROR(INDEX(FIYAT_KAYNAK!$D$3:$D$26,MATCH("KAZTEK|714-15120",FIYAT_KAYNAK!$A$3:$A$26,0)),"") -> Мет. ЩМП-3 (650х500х220) IP54 | D5: 15 | E5: =IFERROR(INDEX(FIYAT_KAYNAK!$E$3:$E$26,MATCH("KAZTEK|714-15120",FIYAT_KAYNAK!$A$3:$A$26,0)),"") -> ШТ | F5: =IFERROR(INDEX(FIYAT_KAYNAK!$F$3:$F$26,MATCH("KAZTEK|714-15120",FIYAT_KAYNAK!$A$3:$A$26,0)),"") -> 29525 | G5: =IFERROR(INDEX(FIYAT_KAYNAK!$J$3:$J$26,MATCH("KAZTEK|714-15120",FIYAT_KAYNAK!$A$3:$A$26,0)),"") -> 17715 | H5: =IF(OR(G5="",D5=""),"",G5*D5) -> 265725
A6: SCHNEIDER | B6: A9F79340 | C6: =IFERROR(INDEX(FIYAT_KAYNAK!$D$3:$D$26,MATCH("SCHNEIDER|A9F79340",FIYAT_KAYNAK!$A$3:$A$26,0)),"") -> Автоматический выключатель Acti9 iC60N 3P 40A, характеристика C, 6кА [KZ/RU артикул; идентичен TR-коду A9F74340] | D6: 4 | E6: =IFERROR(INDEX(FIYAT_KAYNAK!$E$3:$E$26,MATCH("SCHNEIDER|A9F79340",FIYAT_KAYNAK!$A$3:$A$26,0)),"") -> шт | F6: =IFERROR(INDEX(FIYAT_KAYNAK!$F$3:$F$26,MATCH("SCHNEIDER|A9F79340",FIYAT_KAYNAK!$A$3:$A$26,0)),"") -> 2247 | G6: =IFERROR(INDEX(FIYAT_KAYNAK!$J$3:$J$26,MATCH("SCHNEIDER|A9F79340",FIYAT_KAYNAK!$A$3:$A$26,0)),"") -> 14695.38 | H6: =IF(OR(G6="",D6=""),"",G6*D6) -> 58781.52
A7: SCHNEIDER | B7: A9F79320 | C7: =IFERROR(INDEX(FIYAT_KAYNAK!$D$3:$D$26,MATCH("SCHNEIDER|A9F79320",FIYAT_KAYNAK!$A$3:$A$26,0)),"") -> Автоматический выключатель Acti9 iC60N 3P 20A, характеристика C, 6кА [KZ/RU артикул; идентичен TR-коду A9F74320] | D7: 10 | E7: =IFERROR(INDEX(FIYAT_KAYNAK!$E$3:$E$26,MATCH("SCHNEIDER|A9F79320",FIYAT_KAYNAK!$A$3:$A$26,0)),"") -> шт | F7: =IFERROR(INDEX(FIYAT_KAYNAK!$F$3:$F$26,MATCH("SCHNEIDER|A9F79320",FIYAT_KAYNAK!$A$3:$A$26,0)),"") -> 1884 | G7: =IFERROR(INDEX(FIYAT_KAYNAK!$J$3:$J$26,MATCH("SCHNEIDER|A9F79320",FIYAT_KAYNAK!$A$3:$A$26,0)),"") -> 12321.36 | H7: =IF(OR(G7="",D7=""),"",G7*D7) -> 123213.6
A8: SCHNEIDER | B8: GV2ME14 | C8: =IFERROR(INDEX(FIYAT_KAYNAK!$D$3:$D$26,MATCH("SCHNEIDER|GV2ME14",FIYAT_KAYNAK!$A$3:$A$26,0)),"") -> Автоматический выключатель защиты двигателя TeSys GV2ME14 3P, диапазон уставки 6...10 А, Pn 4 кВт (380/400В), Icu 15…100кА | D8: 4 | E8: =IFERROR(INDEX(FIYAT_KAYNAK!$E$3:$E$26,MATCH("SCHNEIDER|GV2ME14",FIYAT_KAYNAK!$A$3:$A$26,0)),"") -> шт | F8: =IFERROR(INDEX(FIYAT_KAYNAK!$F$3:$F$26,MATCH("SCHNEIDER|GV2ME14",FIYAT_KAYNAK!$A$3:$A$26,0)),"") -> 3634 | G8: =IFERROR(INDEX(FIYAT_KAYNAK!$J$3:$J$26,MATCH("SCHNEIDER|GV2ME14",FIYAT_KAYNAK!$A$3:$A$26,0)),"") -> 23766.36 | H8: =IF(OR(G8="",D8=""),"",G8*D8) -> 95065.44
A9: SCHNEIDER | B9: A9F79110 | C9: =IFERROR(INDEX(FIYAT_KAYNAK!$D$3:$D$26,MATCH("SCHNEIDER|A9F79110",FIYAT_KAYNAK!$A$3:$A$26,0)),"") -> Автоматический выключатель Acti9 iC60N 1P 10A, характеристика C, 6кА [KZ/RU артикул; идентичен TR-коду A9F74110] | D9: 15 | E9: =IFERROR(INDEX(FIYAT_KAYNAK!$E$3:$E$26,MATCH("SCHNEIDER|A9F79110",FIYAT_KAYNAK!$A$3:$A$26,0)),"") -> шт | F9: =IFERROR(INDEX(FIYAT_KAYNAK!$F$3:$F$26,MATCH("SCHNEIDER|A9F79110",FIYAT_KAYNAK!$A$3:$A$26,0)),"") -> 446.8 | G9: =IFERROR(INDEX(FIYAT_KAYNAK!$J$3:$J$26,MATCH("SCHNEIDER|A9F79110",FIYAT_KAYNAK!$A$3:$A$26,0)),"") -> 2922.072 | H9: =IF(OR(G9="",D9=""),"",G9*D9) -> 43831.08
A10: SCHNEIDER | B10: A9F79106 | C10: =IFERROR(INDEX(FIYAT_KAYNAK!$D$3:$D$26,MATCH("SCHNEIDER|A9F79106",FIYAT_KAYNAK!$A$3:$A$26,0)),"") -> Автоматический выключатель Acti9 iC60N 1P 6A, характеристика C, 6кА [KZ/RU артикул; идентичен TR-коду A9F74106] | D10: 30 | E10: =IFERROR(INDEX(FIYAT_KAYNAK!$E$3:$E$26,MATCH("SCHNEIDER|A9F79106",FIYAT_KAYNAK!$A$3:$A$26,0)),"") -> шт | F10: =IFERROR(INDEX(FIYAT_KAYNAK!$F$3:$F$26,MATCH("SCHNEIDER|A9F79106",FIYAT_KAYNAK!$A$3:$A$26,0)),"") -> 446.8 | G10: =IFERROR(INDEX(FIYAT_KAYNAK!$J$3:$J$26,MATCH("SCHNEIDER|A9F79106",FIYAT_KAYNAK!$A$3:$A$26,0)),"") -> 2922.072 | H10: =IF(OR(G10="",D10=""),"",G10*D10) -> 87662.16
A11: SCHNEIDER | B11: LC1E1810M5 | C11: =IFERROR(INDEX(FIYAT_KAYNAK!$D$3:$D$26,MATCH("SCHNEIDER|LC1E1810M5",FIYAT_KAYNAK!$A$3:$A$26,0)),"") -> Контактор Easy TeSys LC1E1810M5 3P 18A (AC-3) 7.5кВт 380/400В, доп.контакты 1NO+0NC, катушка 220В AC 50Гц | D11: 10 | E11: =IFERROR(INDEX(FIYAT_KAYNAK!$E$3:$E$26,MATCH("SCHNEIDER|LC1E1810M5",FIYAT_KAYNAK!$A$3:$A$26,0)),"") -> шт | F11: =IFERROR(INDEX(FIYAT_KAYNAK!$F$3:$F$26,MATCH("SCHNEIDER|LC1E1810M5",FIYAT_KAYNAK!$A$3:$A$26,0)),"") -> 1628 | G11: =IFERROR(INDEX(FIYAT_KAYNAK!$J$3:$J$26,MATCH("SCHNEIDER|LC1E1810M5",FIYAT_KAYNAK!$A$3:$A$26,0)),"") -> 10647.12 | H11: =IF(OR(G11="",D11=""),"",G11*D11) -> 106471.2
A12: SCHNEIDER | B12: LC1E0910M5 | C12: =IFERROR(INDEX(FIYAT_KAYNAK!$D$3:$D$26,MATCH("SCHNEIDER|LC1E0910M5",FIYAT_KAYNAK!$A$3:$A$26,0)),"") -> Контактор Easy TeSys LC1E0910M5 3P 9A (AC-3) 4кВт 380/400В, доп.контакты 1NO+0NC, катушка 220В AC 50Гц | D12: 4 | E12: =IFERROR(INDEX(FIYAT_KAYNAK!$E$3:$E$26,MATCH("SCHNEIDER|LC1E0910M5",FIYAT_KAYNAK!$A$3:$A$26,0)),"") -> шт | F12: =IFERROR(INDEX(FIYAT_KAYNAK!$F$3:$F$26,MATCH("SCHNEIDER|LC1E0910M5",FIYAT_KAYNAK!$A$3:$A$26,0)),"") -> 1217 | G12: =IFERROR(INDEX(FIYAT_KAYNAK!$J$3:$J$26,MATCH("SCHNEIDER|LC1E0910M5",FIYAT_KAYNAK!$A$3:$A$26,0)),"") -> 7959.18 | H12: =IF(OR(G12="",D12=""),"",G12*D12) -> 31836.72
A13: SCHNEIDER | B13: LC1E0610M5 | C13: =IFERROR(INDEX(FIYAT_KAYNAK!$D$3:$D$26,MATCH("SCHNEIDER|LC1E0610M5",FIYAT_KAYNAK!$A$3:$A$26,0)),"") -> Контактор Easy TeSys LC1E0610M5 3P 6A (AC-3) 2.2кВт 380/400В, доп.контакты 1NO+0NC, катушка 220В AC 50Гц | D13: 30 | E13: =IFERROR(INDEX(FIYAT_KAYNAK!$E$3:$E$26,MATCH("SCHNEIDER|LC1E0610M5",FIYAT_KAYNAK!$A$3:$A$26,0)),"") -> шт | F13: =IFERROR(INDEX(FIYAT_KAYNAK!$F$3:$F$26,MATCH("SCHNEIDER|LC1E0610M5",FIYAT_KAYNAK!$A$3:$A$26,0)),"") -> 1154 | G13: =IFERROR(INDEX(FIYAT_KAYNAK!$J$3:$J$26,MATCH("SCHNEIDER|LC1E0610M5",FIYAT_KAYNAK!$A$3:$A$26,0)),"") -> 7547.16 | H13: =IF(OR(G13="",D13=""),"",G13*D13) -> 226414.8
A14: CHINT | B14: 593012 | C14: =IFERROR(INDEX(FIYAT_KAYNAK!$D$3:$D$26,MATCH("CHINT|593012",FIYAT_KAYNAK!$A$3:$A$26,0)),"") -> Индикатор ND16-22DS/4 красный АС230В (R) | D14: 45 | E14: =IFERROR(INDEX(FIYAT_KAYNAK!$E$3:$E$26,MATCH("CHINT|593012",FIYAT_KAYNAK!$A$3:$A$26,0)),"") -> шт | F14: =IFERROR(INDEX(FIYAT_KAYNAK!$F$3:$F$26,MATCH("CHINT|593012",FIYAT_KAYNAK!$A$3:$A$26,0)),"") -> 836 | G14: =IFERROR(INDEX(FIYAT_KAYNAK!$J$3:$J$26,MATCH("CHINT|593012",FIYAT_KAYNAK!$A$3:$A$26,0)),"") -> 501.6 | H14: =IF(OR(G14="",D14=""),"",G14*D14) -> 22572
A15: EKT | B15: 130301157_ | C15: =IFERROR(INDEX(FIYAT_KAYNAK!$D$3:$D$26,MATCH("EKT|130301157_",FIYAT_KAYNAK!$A$3:$A$26,0)),"") -> ЗНИ 16мм ² (100А) серый UNIT (50/1000) | D15: 45 | E15: =IFERROR(INDEX(FIYAT_KAYNAK!$E$3:$E$26,MATCH("EKT|130301157_",FIYAT_KAYNAK!$A$3:$A$26,0)),"") -> шт | F15: =IFERROR(INDEX(FIYAT_KAYNAK!$F$3:$F$26,MATCH("EKT|130301157_",FIYAT_KAYNAK!$A$3:$A$26,0)),"") -> 235 | G15: =IFERROR(INDEX(FIYAT_KAYNAK!$J$3:$J$26,MATCH("EKT|130301157_",FIYAT_KAYNAK!$A$3:$A$26,0)),"") -> 235 | H15: =IF(OR(G15="",D15=""),"",G15*D15) -> 10575
A16: EKT | B16: 130301158_ | C16: =IFERROR(INDEX(FIYAT_KAYNAK!$D$3:$D$26,MATCH("EKT|130301158_",FIYAT_KAYNAK!$A$3:$A$26,0)),"") -> ЗНИ 16мм ² (100А) синий UNIT (50/1000) | D16: 15 | E16: =IFERROR(INDEX(FIYAT_KAYNAK!$E$3:$E$26,MATCH("EKT|130301158_",FIYAT_KAYNAK!$A$3:$A$26,0)),"") -> шт | F16: =IFERROR(INDEX(FIYAT_KAYNAK!$F$3:$F$26,MATCH("EKT|130301158_",FIYAT_KAYNAK!$A$3:$A$26,0)),"") -> 269 | G16: =IFERROR(INDEX(FIYAT_KAYNAK!$J$3:$J$26,MATCH("EKT|130301158_",FIYAT_KAYNAK!$A$3:$A$26,0)),"") -> 269 | H16: =IF(OR(G16="",D16=""),"",G16*D16) -> 4035
A17: EKT | B17: 130300227_ | C17: =IFERROR(INDEX(FIYAT_KAYNAK!$D$3:$D$26,MATCH("EKT|130300227_",FIYAT_KAYNAK!$A$3:$A$26,0)),"") -> ЗНИ 10PEN 10мм2 (JXB-земля) IEK E-PRO | D17: 75 | E17: =IFERROR(INDEX(FIYAT_KAYNAK!$E$3:$E$26,MATCH("EKT|130300227_",FIYAT_KAYNAK!$A$3:$A$26,0)),"") -> шт | F17: =IFERROR(INDEX(FIYAT_KAYNAK!$F$3:$F$26,MATCH("EKT|130300227_",FIYAT_KAYNAK!$A$3:$A$26,0)),"") -> 155 | G17: =IFERROR(INDEX(FIYAT_KAYNAK!$J$3:$J$26,MATCH("EKT|130300227_",FIYAT_KAYNAK!$A$3:$A$26,0)),"") -> 155 | H17: =IF(OR(G17="",D17=""),"",G17*D17) -> 11625
A18: EKT | B18: 130301154_ | C18: =IFERROR(INDEX(FIYAT_KAYNAK!$D$3:$D$26,MATCH("EKT|130301154_",FIYAT_KAYNAK!$A$3:$A$26,0)),"") -> ЗНИ 6мм ² серый UNIT (50/2000) | D18: 120 | E18: =IFERROR(INDEX(FIYAT_KAYNAK!$E$3:$E$26,MATCH("EKT|130301154_",FIYAT_KAYNAK!$A$3:$A$26,0)),"") -> шт | F18: =IFERROR(INDEX(FIYAT_KAYNAK!$F$3:$F$26,MATCH("EKT|130301154_",FIYAT_KAYNAK!$A$3:$A$26,0)),"") -> 111 | G18: =IFERROR(INDEX(FIYAT_KAYNAK!$J$3:$J$26,MATCH("EKT|130301154_",FIYAT_KAYNAK!$A$3:$A$26,0)),"") -> 111 | H18: =IF(OR(G18="",D18=""),"",G18*D18) -> 13320
A19: EKT | B19: 130301153_ | C19: =IFERROR(INDEX(FIYAT_KAYNAK!$D$3:$D$26,MATCH("EKT|130301153_",FIYAT_KAYNAK!$A$3:$A$26,0)),"") -> ЗНИ 4мм ² (35А) серый UNIT (50/2500) | D19: 60 | E19: =IFERROR(INDEX(FIYAT_KAYNAK!$E$3:$E$26,MATCH("EKT|130301153_",FIYAT_KAYNAK!$A$3:$A$26,0)),"") -> шт | F19: =IFERROR(INDEX(FIYAT_KAYNAK!$F$3:$F$26,MATCH("EKT|130301153_",FIYAT_KAYNAK!$A$3:$A$26,0)),"") -> 90 | G19: =IFERROR(INDEX(FIYAT_KAYNAK!$J$3:$J$26,MATCH("EKT|130301153_",FIYAT_KAYNAK!$A$3:$A$26,0)),"") -> 90 | H19: =IF(OR(G19="",D19=""),"",G19*D19) -> 5400
A20: EKT | B20: 130301152_ | C20: =IFERROR(INDEX(FIYAT_KAYNAK!$D$3:$D$26,MATCH("EKT|130301152_",FIYAT_KAYNAK!$A$3:$A$26,0)),"") -> ЗНИ 2.5мм ² (24А) серый UNIT (50/2500) | D20: 450 | E20: =IFERROR(INDEX(FIYAT_KAYNAK!$E$3:$E$26,MATCH("EKT|130301152_",FIYAT_KAYNAK!$A$3:$A$26,0)),"") -> шт | F20: =IFERROR(INDEX(FIYAT_KAYNAK!$F$3:$F$26,MATCH("EKT|130301152_",FIYAT_KAYNAK!$A$3:$A$26,0)),"") -> 90 | G20: =IFERROR(INDEX(FIYAT_KAYNAK!$J$3:$J$26,MATCH("EKT|130301152_",FIYAT_KAYNAK!$A$3:$A$26,0)),"") -> 90 | H20: =IF(OR(G20="",D20=""),"",G20*D20) -> 40500
A21: CHINT | B21: 570002 | C21: =IFERROR(INDEX(FIYAT_KAYNAK!$D$3:$D$26,MATCH("CHINT|570002",FIYAT_KAYNAK!$A$3:$A$26,0)),"") -> DIN-рейка оцинкованная TH35-7.5 200cm | D21: 15 | E21: =IFERROR(INDEX(FIYAT_KAYNAK!$E$3:$E$26,MATCH("CHINT|570002",FIYAT_KAYNAK!$A$3:$A$26,0)),"") -> шт | F21: =IFERROR(INDEX(FIYAT_KAYNAK!$F$3:$F$26,MATCH("CHINT|570002",FIYAT_KAYNAK!$A$3:$A$26,0)),"") -> 2232 | G21: =IFERROR(INDEX(FIYAT_KAYNAK!$J$3:$J$26,MATCH("CHINT|570002",FIYAT_KAYNAK!$A$3:$A$26,0)),"") -> 1339.2 | H21: =IF(OR(G21="",D21=""),"",G21*D21) -> 20088
A22: EKT | B22: 280100020_ | C22: =IFERROR(INDEX(FIYAT_KAYNAK!$D$3:$D$26,MATCH("EKT|280100020_",FIYAT_KAYNAK!$A$3:$A$26,0)),"") -> Кабель.канал перф. 40х40 ИМПАКТ IEK (36) | D22: 30 | E22: =IFERROR(INDEX(FIYAT_KAYNAK!$E$3:$E$26,MATCH("EKT|280100020_",FIYAT_KAYNAK!$A$3:$A$26,0)),"") -> шт | F22: =IFERROR(INDEX(FIYAT_KAYNAK!$F$3:$F$26,MATCH("EKT|280100020_",FIYAT_KAYNAK!$A$3:$A$26,0)),"") -> 1486 | G22: =IFERROR(INDEX(FIYAT_KAYNAK!$J$3:$J$26,MATCH("EKT|280100020_",FIYAT_KAYNAK!$A$3:$A$26,0)),"") -> 1486 | H22: =IF(OR(G22="",D22=""),"",G22*D22) -> 44580
A23: EKT | B23: 270300079_ | C23: =IFERROR(INDEX(FIYAT_KAYNAK!$D$3:$D$26,MATCH("EKT|270300079_",FIYAT_KAYNAK!$A$3:$A$26,0)),"") -> Кабель.канал перф. 25х40 ИМПАКТ IEK (60) | D23: 15 | E23: =IFERROR(INDEX(FIYAT_KAYNAK!$E$3:$E$26,MATCH("EKT|270300079_",FIYAT_KAYNAK!$A$3:$A$26,0)),"") -> шт | F23: =IFERROR(INDEX(FIYAT_KAYNAK!$F$3:$F$26,MATCH("EKT|270300079_",FIYAT_KAYNAK!$A$3:$A$26,0)),"") -> 1094 | G23: =IFERROR(INDEX(FIYAT_KAYNAK!$J$3:$J$26,MATCH("EKT|270300079_",FIYAT_KAYNAK!$A$3:$A$26,0)),"") -> 1094 | H23: =IF(OR(G23="",D23=""),"",G23*D23) -> 16410
A24: SCHNEIDER | B24: A9F79363 | C24: =IFERROR(INDEX(FIYAT_KAYNAK!$D$3:$D$26,MATCH("SCHNEIDER|A9F79363",FIYAT_KAYNAK!$A$3:$A$26,0)),"") -> Автоматический выключатель Acti9 iC60N 3P 63A, характеристика C, 6кА [KZ/RU артикул; идентичен TR-коду A9F74363] | D24: 10 | E24: =IFERROR(INDEX(FIYAT_KAYNAK!$E$3:$E$26,MATCH("SCHNEIDER|A9F79363",FIYAT_KAYNAK!$A$3:$A$26,0)),"") -> шт | F24: =IFERROR(INDEX(FIYAT_KAYNAK!$F$3:$F$26,MATCH("SCHNEIDER|A9F79363",FIYAT_KAYNAK!$A$3:$A$26,0)),"") -> 3335 | G24: =IFERROR(INDEX(FIYAT_KAYNAK!$J$3:$J$26,MATCH("SCHNEIDER|A9F79363",FIYAT_KAYNAK!$A$3:$A$26,0)),"") -> 21810.9 | H24: =IF(OR(G24="",D24=""),"",G24*D24) -> 218109
A25: SCHNEIDER | B25: A9F79325 | C25: =IFERROR(INDEX(FIYAT_KAYNAK!$D$3:$D$26,MATCH("SCHNEIDER|A9F79325",FIYAT_KAYNAK!$A$3:$A$26,0)),"") -> Автоматический выключатель Acti9 iC60N 3P 25A, характеристика C, 6кА [KZ/RU артикул; идентичен TR-коду A9F74325] | D25: 20 | E25: =IFERROR(INDEX(FIYAT_KAYNAK!$E$3:$E$26,MATCH("SCHNEIDER|A9F79325",FIYAT_KAYNAK!$A$3:$A$26,0)),"") -> шт | F25: =IFERROR(INDEX(FIYAT_KAYNAK!$F$3:$F$26,MATCH("SCHNEIDER|A9F79325",FIYAT_KAYNAK!$A$3:$A$26,0)),"") -> 1884 | G25: =IFERROR(INDEX(FIYAT_KAYNAK!$J$3:$J$26,MATCH("SCHNEIDER|A9F79325",FIYAT_KAYNAK!$A$3:$A$26,0)),"") -> 12321.36 | H25: =IF(OR(G25="",D25=""),"",G25*D25) -> 246427.2
A26: SCHNEIDER | B26: GV2ME20 | C26: =IFERROR(INDEX(FIYAT_KAYNAK!$D$3:$D$26,MATCH("SCHNEIDER|GV2ME20",FIYAT_KAYNAK!$A$3:$A$26,0)),"") -> Автоматический выключатель защиты двигателя TeSys GV2ME20 3P, диапазон уставки 13...18 А, Pn 7,5 кВт (380/400В), Icu 15…100кА | D26: 11 | E26: =IFERROR(INDEX(FIYAT_KAYNAK!$E$3:$E$26,MATCH("SCHNEIDER|GV2ME20",FIYAT_KAYNAK!$A$3:$A$26,0)),"") -> шт | F26: =IFERROR(INDEX(FIYAT_KAYNAK!$F$3:$F$26,MATCH("SCHNEIDER|GV2ME20",FIYAT_KAYNAK!$A$3:$A$26,0)),"") -> 4163 | G26: =IFERROR(INDEX(FIYAT_KAYNAK!$J$3:$J$26,MATCH("SCHNEIDER|GV2ME20",FIYAT_KAYNAK!$A$3:$A$26,0)),"") -> 27226.02 | H26: =IF(OR(G26="",D26=""),"",G26*D26) -> 299486.22
A27: SCHNEIDER | B27: LC1E2510M5 | C27: =IFERROR(INDEX(FIYAT_KAYNAK!$D$3:$D$26,MATCH("SCHNEIDER|LC1E2510M5",FIYAT_KAYNAK!$A$3:$A$26,0)),"") -> Контактор Easy TeSys LC1E2510M5 3P 25A (AC-3) 11кВт 380/400В, доп.контакты 1NO+0NC, катушка 220В AC 50Гц | D27: 31 | E27: =IFERROR(INDEX(FIYAT_KAYNAK!$E$3:$E$26,MATCH("SCHNEIDER|LC1E2510M5",FIYAT_KAYNAK!$A$3:$A$26,0)),"") -> шт | F27: =IFERROR(INDEX(FIYAT_KAYNAK!$F$3:$F$26,MATCH("SCHNEIDER|LC1E2510M5",FIYAT_KAYNAK!$A$3:$A$26,0)),"") -> 2182 | G27: =IFERROR(INDEX(FIYAT_KAYNAK!$J$3:$J$26,MATCH("SCHNEIDER|LC1E2510M5",FIYAT_KAYNAK!$A$3:$A$26,0)),"") -> 14270.28 | H27: =IF(OR(G27="",D27=""),"",G27*D27) -> 442378.68
A28: SCHNEIDER | B28: A9F79350 | C28: =IFERROR(INDEX(FIYAT_KAYNAK!$D$3:$D$26,MATCH("SCHNEIDER|A9F79350",FIYAT_KAYNAK!$A$3:$A$26,0)),"") -> Автоматический выключатель Acti9 iC60N 3P 50A, характеристика C, 6кА [KZ/RU артикул; идентичен TR-коду A9F74350] | D28: 1 | E28: =IFERROR(INDEX(FIYAT_KAYNAK!$E$3:$E$26,MATCH("SCHNEIDER|A9F79350",FIYAT_KAYNAK!$A$3:$A$26,0)),"") -> шт | F28: =IFERROR(INDEX(FIYAT_KAYNAK!$F$3:$F$26,MATCH("SCHNEIDER|A9F79350",FIYAT_KAYNAK!$A$3:$A$26,0)),"") -> 2836 | G28: =IFERROR(INDEX(FIYAT_KAYNAK!$J$3:$J$26,MATCH("SCHNEIDER|A9F79350",FIYAT_KAYNAK!$A$3:$A$26,0)),"") -> 18547.44 | H28: =IF(OR(G28="",D28=""),"",G28*D28) -> 18547.44
A29: ИТОГО МАТЕРИАЛ (без монтажных материалов и работ) | H29: =SUM(H5:H28) -> 2453055.1

Sheet Kurallar
A1: Щиты управления электронагревателями (ЩУ-1 / ЩУ-2 / ЩУ-3) — Schneider Electric — KURAL VE PARAMETRE TABLOSU
A2: SARI hücreler düzenlenebilir. Değiştirince BOM ve СВОД otomatik güncellenir.
A4: Proje kodu | B4: 260814_YSF_HICH_Isitici_Kumanda_Panolari
A5: Revizyon | B5: R4
A6: Tarih | B6: 2026-08-14
A7: Sorumlu | B7: Yusuf
A8: Müşteri | B8: TEKLED Electric / YSF HICH
A10: PARAMETRELER
A11: ISCILIK_KZT_DK | B11: 100 | C11: KZT / dakika (işveren yükü dahil)
A12: TEST_ETIKET_KATS | B12: 1.15 | C12: Toplam işçilik dakikasına çarpan
A13: MONTAJ_MALZ_YUZDE | B13: 0.03 | C13: Pano malzeme ara toplamının yüzdesi
A14: KUTUP_EK_DK | B14: 2 | C14: Bilgi/tohum değeri. CANLI değer norm tablosundaki "OTO/DİF kutup eki" satırının NORM_DK hücresidir — değişiklik orada yapılır.
A16: İŞÇİLİK ZAMAN NORMLARI (dakika) — her pano için ayrı sütun
A17: TİP | B17: NORM_DK | C17: ЩУ-1 (нагрев 20 кВт + вентилятор 3 кВт) adet | D17: ЩУ-1 (нагрев 20 кВт + вентилятор 3 кВт) dk | E17: ЩУ-2 (нагрев 26 кВт + вентилятор 8 кВт) adet | F17: ЩУ-2 (нагрев 26 кВт + вентилятор 8 кВт) dk | G17: ЩУ-3 (нагрев 22 кВт + вентилятор 8 кВт) adet | H17: ЩУ-3 (нагрев 22 кВт + вентилятор 8 кВт) dk | I17: AÇIKLAMA
A18: korpus | B18: 60 | C18: 1 | D18: =$B18*C18 -> 60 | E18: 1 | F18: =$B18*E18 -> 60 | G18: 1 | H18: =$B18*G18 -> 60 | I18: Korpus hazırlık, DIN ray, montaj plakası
A19: TMŞ | B19: 25 | C19: 0 | D19: =$B19*C19 -> 0 | E19: 0 | F19: =$B19*E19 -> 0 | G19: 0 | H19: =$B19*G19 -> 0 | I19: MCCB montaj + kablolama
A20: Motor Koruma | B20: 15 | C20: 1 | D20: =$B20*C20 -> 15 | E20: 1 | F20: =$B20*E20 -> 15 | G20: 1 | H20: =$B20*G20 -> 15 | I20: GV2/GV3 motor koruma şalteri: montaj, kablolama, akım ayarı
A21: OTO | B21: 4 | C21: 6 | D21: =$B21*C21 -> 24 | E21: 6 | F21: =$B21*E21 -> 24 | G21: 6 | H21: =$B21*G21 -> 24 | I21: MCB 1P; her ek kutup için +2 dk (kutup katsayısı)
A22: DİF | B22: 6 | C22: 0 | D22: =$B22*C22 -> 0 | E22: 0 | F22: =$B22*E22 -> 0 | G22: 0 | H22: =$B22*G22 -> 0 | I22: RCBO / УЗО
A23: rubilnik | B23: 20 | C23: 0 | D23: =$B23*C23 -> 0 | E23: 0 | F23: =$B23*E23 -> 0 | G23: 0 | H23: =$B23*G23 -> 0 | I23: Yük ayırıcı
A24: fu | B24: 5 | C24: 0 | D24: =$B24*C24 -> 0 | E24: 0 | F24: =$B24*E24 -> 0 | G24: 0 | H24: =$B24*G24 -> 0 | I24: Sigorta + yuva
A25: kontaktör | B25: 12 | C25: 5 | D25: =$B25*C25 -> 60 | E25: 5 | F25: =$B25*E25 -> 60 | G25: 5 | H25: =$B25*G25 -> 60
A26: blok | B26: 3 | C26: 0 | D26: =$B26*C26 -> 0 | E26: 0 | F26: =$B26*E26 -> 0 | G26: 0 | H26: =$B26*G26 -> 0 | I26: Yardımcı kontak / interlok
A27: Röle | B27: 6 | C27: 0 | D27: =$B27*C27 -> 0 | E27: 0 | F27: =$B27*E27 -> 0 | G27: 0 | H27: =$B27*G27 -> 0
A28: Röle Altlığı | B28: 3 | C28: 0 | D28: =$B28*C28 -> 0 | E28: 0 | F28: =$B28*E28 -> 0 | G28: 0 | H28: =$B28*G28 -> 0
A29: İmpuls | B29: 6 | C29: 0 | D29: =$B29*C29 -> 0 | E29: 0 | F29: =$B29*E29 -> 0 | G29: 0 | H29: =$B29*G29 -> 0
A30: Sinyal Lambası | B30: 5 | C30: 3 | D30: =$B30*C30 -> 15 | E30: 3 | F30: =$B30*E30 -> 15 | G30: 3 | H30: =$B30*G30 -> 15
A31: lamb | B31: 5 | C31: 0 | D31: =$B31*C31 -> 0 | E31: 0 | F31: =$B31*E31 -> 0 | G31: 0 | H31: =$B31*G31 -> 0
A32: Klemens | B32: 1.5 | C32: 51 | D32: =$B32*C32 -> 76.5 | E32: 51 | F32: =$B32*E32 -> 76.5 | G32: 51 | H32: =$B32*G32 -> 76.5 | I32: Adet başına
A33: LOOBAR | B33: 8 | C33: 0 | D33: =$B33*C33 -> 0 | E33: 0 | F33: =$B33*E33 -> 0 | G33: 0 | H33: =$B33*G33 -> 0 | I33: HAZIR DIN barası (ШНИ/ШНК) montaj + bağlantı, adet başına. ⚠ İMALAT bara (kesim, delme, bükme, kalaylama) için bu norm YETERSİZ — 30-45 dk/adet ayrıca hesaplanmalı
A34: tt | B34: 10 | C34: 0 | D34: =$B34*C34 -> 0 | E34: 0 | F34: =$B34*E34 -> 0 | G34: 0 | H34: =$B34*G34 -> 0 | I34: Akım trafosu
A35: sayac | B35: 20 | C35: 0 | D35: =$B35*C35 -> 0 | E35: 0 | F35: =$B35*E35 -> 0 | G35: 0 | H35: =$B35*G35 -> 0 | I35: Sayaç montaj + bağlantı
A36: opn | B36: 8 | C36: 0 | D36: =$B36*C36 -> 0 | E36: 0 | F36: =$B36*E36 -> 0 | G36: 0 | H36: =$B36*G36 -> 0 | I36: Parafudr
A37: montajный материал | B37: 3 | C37: 4 | D37: =$B37*C37 -> 12 | E37: 4 | F37: =$B37*E37 -> 12 | G37: 4 | H37: =$B37*G37 -> 12 | I37: Kanal/DIN ray, metre başına
A38: OTO/DİF kutup eki | B38: 2 | C38: 6 | D38: =$B38*C38 -> 12 | E38: 6 | F38: =$B38*E38 -> 12 | G38: 6 | H38: =$B38*G38 -> 12 | I38: Her EK kutup için. Adet = Σ(kutup−1)×adet. 1P=0, 3P=2 ek kutup
A40: TEST/ETİKET ÖNCESİ TOPLAM (dk) | D40: =SUM(D18:D38) -> 274.5 | F40: =SUM(F18:F38) -> 274.5 | H40: =SUM(H18:H38) -> 274.5
A41: TEST/ETİKET KATSAYILI (dk) | D41: =Kurallar!$D$40*Kurallar!$B$12 -> 315.675 | F41: =Kurallar!$F$40*Kurallar!$B$12 -> 315.675 | H41: =Kurallar!$H$40*Kurallar!$B$12 -> 315.675
A43: DÖVİZ KURLARI (BOM günü)
A44: EUR | B44: 590 | C44: EUR/KZT
A45: TL | B45: 10.9 | C45: TL/KZT
...

Sheet FIYAT_KAYNAK
A1: Bu sayfa birleşik fiyat listesinden kopyalanmıştır. Elle değiştirmeyin.
A2: ANAHTAR | B2: MARKA | C2: ARTIKUL | D2: ACIKLAMA | E2: BIRIM | F2: LISTE | G2: PARA | H2: KATSAYI | I2: KUR | J2: NET_KZT | K2: KAYNAK
A3: KAZTEK|714-15120 | B3: KAZTEK | C3: 719-15 | D3: Мет. ЩМП-3 (650х500х220) IP54 | E3: ШТ | F3: 29525 | G3: KZT | H3: 0.6 | I3: =IFERROR(INDEX(Kurallar!$B$44:$B$47,MATCH(G3,Kurallar!$A$44:$A$47,0)),"") -> 1 | J3: =IF(OR(F3="",H3="",H3=0,I3=""),"",F3*H3*I3) -> 17715 | K3: Kaztek 15.07.2026
A4: SCHNEIDER|A9F79340 | B4: SCHNEIDER | C4: A9F79340 | D4: Автоматический выключатель Acti9 iC60N 3P 40A, характеристика C, 6кА [KZ/RU артикул; идентичен TR-коду A9F74340] | E4: шт | F4: 2247 | G4: TL | H4: =IFERROR(INDEX(Kurallar!$B$51:$B$54,MATCH(B4,Kurallar!$A$51:$A$54,0)),"") -> 0.6 | I4: =IFERROR(INDEX(Kurallar!$B$44:$B$47,MATCH(G4,Kurallar!$A$44:$A$47,0)),"") -> 10.9 | J4: =IF(OR(F4="",H4="",H4=0,I4=""),"",F4*H4*I4) -> 14695.38 | K4: Schneider TR 23.07.2025 (цена по A9F74340, SE FAQ000234158)
A5: SCHNEIDER|A9F79320 | B5: SCHNEIDER | C5: A9F79320 | D5: Автоматический выключатель Acti9 iC60N 3P 20A, характеристика C, 6кА [KZ/RU артикул; идентичен TR-коду A9F74320] | E5: шт | F5: 1884 | G5: TL | H5: =IFERROR(INDEX(Kurallar!$B$51:$B$54,MATCH(B5,Kurallar!$A$51:$A$54,0)),"") -> 0.6 | I5: =IFERROR(INDEX(Kurallar!$B$44:$B$47,MATCH(G5,Kurallar!$A$44:$A$47,0)),"") -> 10.9 | J5: =IF(OR(F5="",H5="",H5=0,I5=""),"",F5*H5*I5) -> 12321.36 | K5: Schneider TR 23.07.2025 (цена по A9F74320, SE FAQ000234158)
A6: SCHNEIDER|GV2ME14 | B6: SCHNEIDER | C6: GV2ME14 | D6: Автоматический выключатель защиты двигателя TeSys GV2ME14 3P, диапазон уставки 6...10 А, Pn 4 кВт (380/400В), Icu 15…100кА | E6: шт | F6: 3634 | G6: TL | H6: =IFERROR(INDEX(Kurallar!$B$51:$B$54,MATCH(B6,Kurallar!$A$51:$A$54,0)),"") -> 0.6 | I6: =IFERROR(INDEX(Kurallar!$B$44:$B$47,MATCH(G6,Kurallar!$A$44:$A$47,0)),"") -> 10.9 | J6: =IF(OR(F6="",H6="",H6=0,I6=""),"",F6*H6*I6) -> 23766.36 | K6: Schneider TR 23.07.2025 s.073 (списке как "GV2-ME4")
A7: SCHNEIDER|A9F79110 | B7: SCHNEIDER | C7: A9F79110 | D7: Автоматический выключатель Acti9 iC60N 1P 10A, характеристика C, 6кА [KZ/RU артикул; идентичен TR-коду A9F74110] | E7: шт | F7: 446.8 | G7: TL | H7: =IFERROR(INDEX(Kurallar!$B$51:$B$54,MATCH(B7,Kurallar!$A$51:$A$54,0)),"") -> 0.6 | I7: =IFERROR(INDEX(Kurallar!$B$44:$B$47,MATCH(G7,Kurallar!$A$44:$A$47,0)),"") -> 10.9 | J7: =IF(OR(F7="",H7="",H7=0,I7=""),"",F7*H7*I7) -> 2922.072 | K7: Schneider TR 23.07.2025 (цена по A9F74110, SE FAQ000234158)
A8: SCHNEIDER|A9F79106 | B8: SCHNEIDER | C8: A9F79106 | D8: Автоматический выключатель Acti9 iC60N 1P 6A, характеристика C, 6кА [KZ/RU артикул; идентичен TR-коду A9F74106] | E8: шт | F8: 446.8 | G8: TL | H8: =IFERROR(INDEX(Kurallar!$B$51:$B$54,MATCH(B8,Kurallar!$A$51:$A$54,0)),"") -> 0.6 | I8: =IFERROR(INDEX(Kurallar!$B$44:$B$47,MATCH(G8,Kurallar!$A$44:$A$47,0)),"") -> 10.9 | J8: =IF(OR(F8="",H8="",H8=0,I8=""),"",F8*H8*I8) -> 2922.072 | K8: Schneider TR 23.07.2025 (цена по A9F74106, SE FAQ000234158)
A9: SCHNEIDER|LC1E1810M5 | B9: SCHNEIDER | C9: LC1E1810M5 | D9: Контактор Easy TeSys LC1E1810M5 3P 18A (AC-3) 7.5кВт 380/400В, доп.контакты 1NO+0NC, катушка 220В AC 50Гц | E9: шт | F9: 1628 | G9: TL | H9: =IFERROR(INDEX(Kurallar!$B$51:$B$54,MATCH(B9,Kurallar!$A$51:$A$54,0)),"") -> 0.6 | I9: =IFERROR(INDEX(Kurallar!$B$44:$B$47,MATCH(G9,Kurallar!$A$44:$A$47,0)),"") -> 10.9 | J9: =IF(OR(F9="",H9="",H9=0,I9=""),"",F9*H9*I9) -> 10647.12 | K9: Schneider TR 23.07.2025 s.064
A10: SCHNEIDER|LC1E0910M5 | B10: SCHNEIDER | C10: LC1E0910M5 | D10: Контактор Easy TeSys LC1E0910M5 3P 9A (AC-3) 4кВт 380/400В, доп.контакты 1NO+0NC, катушка 220В AC 50Гц | E10: шт | F10: 1217 | G10: TL | H10: =IFERROR(INDEX(Kurallar!$B$51:$B$54,MATCH(B10,Kurallar!$A$51:$A$54,0)),"") -> 0.6 | I10: =IFERROR(INDEX(Kurallar!$B$44:$B$47,MATCH(G10,Kurallar!$A$44:$A$47,0)),"") -> 10.9 | J10: =IF(OR(F10="",H10="",H10=0,I10=""),"",F10*H10*I10) -> 7959.18 | K10: Schneider TR 23.07.2025 s.064
A11: SCHNEIDER|LC1E0610M5 | B11: SCHNEIDER | C11: LC1E0610M5 | D11: Контактор Easy TeSys LC1E0610M5 3P 6A (AC-3) 2.2кВт 380/400В, доп.контакты 1NO+0NC, катушка 220В AC 50Гц | E11: шт | F11: 1154 | G11: TL | H11: =IFERROR(INDEX(Kurallar!$B$51:$B$54,MATCH(B11,Kurallar!$A$51:$A$54,0)),"") -> 0.6 | I11: =IFERROR(INDEX(Kurallar!$B$44:$B$47,MATCH(G11,Kurallar!$A$44:$A$47,0)),"") -> 10.9 | J11: =IF(OR(F11="",H11="",H11=0,I11=""),"",F11*H11*I11) -> 7547.16 | K11: Schneider TR 23.07.2025 s.064
A12: CHINT|593012 | B12: CHINT | C12: 593012 | D12: Индикатор ND16-22DS/4 красный АС230В (R) | E12: шт | F12: 836 | G12: KZT | H12: =IFERROR(INDEX(Kurallar!$B$51:$B$54,MATCH(B12,Kurallar!$A$51:$A$54,0)),"") -> 0.6 | I12: =IFERROR(INDEX(Kurallar!$B$44:$B$47,MATCH(G12,Kurallar!$A$44:$A$47,0)),"") -> 1 | J12: =IF(OR(F12="",H12="",H12=0,I12=""),"",F12*H12*I12) -> 501.6 | K12: CHINT 13.06.2026
A13: EKT|130301157_ | B13: EKT | C13: 130301157_ | D13: ЗНИ 16мм ² (100А) серый UNIT (50/1000) | E13: шт | F13: 235 | G13: KZT | H13: =IFERROR(INDEX(Kurallar!$B$51:$B$54,MATCH(B13,Kurallar!$A$51:$A$54,0)),"") -> 1 | I13: =IFERROR(INDEX(Kurallar!$B$44:$B$47,MATCH(G13,Kurallar!$A$44:$A$47,0)),"") -> 1 | J13: =IF(OR(F13="",H13="",H13=0,I13=""),"",F13*H13*I13) -> 235 | K13: EKT 19.06.2025
A14: EKT|130301158_ | B14: EKT | C14: 130301158_ | D14: ЗНИ 16мм ² (100А) синий UNIT (50/1000) | E14: шт | F14: 269 | G14: KZT | H14: =IFERROR(INDEX(Kurallar!$B$51:$B$54,MATCH(B14,Kurallar!$A$51:$A$54,0)),"") -> 1 | I14: =IFERROR(INDEX(Kurallar!$B$44:$B$47,MATCH(G14,Kurallar!$A$44:$A$47,0)),"") -> 1 | J14: =IF(OR(F14="",H14="",H14=0,I14=""),"",F14*H14*I14) -> 269 | K14: EKT 19.06.2025
A15: EKT|130300227_ | B15: EKT | C15: 130300227_ | D15: ЗНИ 10PEN 10мм2 (JXB-земля) IEK E-PRO | E15: шт | F15: 155 | G15: KZT | H15: =IFERROR(INDEX(Kurallar!$B$51:$B$54,MATCH(B15,Kurallar!$A$51:$A$54,0)),"") -> 1 | I15: =IFERROR(INDEX(Kurallar!$B$44:$B$47,MATCH(G15,Kurallar!$A$44:$A$47,0)),"") -> 1 | J15: =IF(OR(F15="",H15="",H15=0,I15=""),"",F15*H15*I15) -> 155 | K15: EKT 19.06.2025
... A26: SCHNEIDER|A9F79350 | B26: SCHNEIDER | C26: A9F79350 | D26: Автоматический выключатель Acti9 iC60N 3P 50A, характеристика C, 6кА [KZ/RU артикул; идентичен TR-коду A9F74350] | E26: шт | F26: 2836 | G26: TL | H26: =IFERROR(INDEX(Kurallar!$B$51:$B$54,MATCH(B26,Kurallar!$A$51:$A$54,0)),"") -> 0.6 | I26: =IFERROR(INDEX(Kurallar!$B$44:$B$47,MATCH(G26,Kurallar!$A$44:$A$47,0)),"") -> 10.9 | J26: =IF(OR(F26="",H26="",H26=0,I26=""),"",F26*H26*I26) -> 18547.44 | K26: Schneider TR 23.07.2025 (цена по A9F74350, SE FAQ000234158)

Sheet QA_CANLI
A1: CANLI DENETİM — her kontrol BOM verisinden BAĞIMSIZ yeniden hesaplanır
A2: Kurallar sayfasında kur, katsayı veya norm değiştirilirse bu sayfa da yeniden hesaplanır. Herhangi bir satır HATA gösterirse dosya teklife verilmez.
A4: # | B4: KONTROL | C4: BEKLENEN (bağımsız hesap) | D4: DOSYADAKİ DEĞER | E4: SONUÇ | F4: AÇIKLAMA
A5: K01 | B5: SATINALMA ↔ BOM malzeme mutabakatı | C5: =SUM(BOM!H3:H19)*4+SUM(BOM!H24:H42)*10+SUM(BOM!H47:H65)*1 -> 2299208.1 | D5: =SATINALMA!$H$29 -> 2453055.1 | E5: =IF(OR(C5="",D5=""),"VERİ YOK",IF(ABS(N(C5)-N(D5))<0.51,"✓ OK","✖ HATA")) -> ✖ HATA | F5: İki liste ayrı yoldan kurulur: BOM satır satır, SATINALMA artikül bazında toplanır. Eşit olmalı.
A6: K02 | B6: GENEL TOPLAM = Σ(pano toplamı × komplekt) | C6: =BOM!H22*4+BOM!H45*10+BOM!H68*1 -> 265725 | D6: =BOM!H69 -> 265725 | E6: =IF(OR(C6="",D6=""),"VERİ YOK",IF(ABS(N(C6)-N(D6))<0.51,"✓ OK","✖ HATA")) -> ✓ OK | F6: Genel toplam formülü bağımsız çarpımla karşılaştırılır.
A7: K03 | B7: СВОД ↔ BOM tutarlılığı | C7: =BOM!H69 -> 265725 | D7: =СВОД!D8 -> 265725 | E7: =IF(OR(C7="",D7=""),"VERİ YOK",IF(ABS(N(C7)-N(D7))<0.51,"✓ OK","✖ HATA")) -> ✓ OK | F7: СВОД sayfasındaki İTOGO ile BOM genel toplamı aynı olmalı.
A8: K04 | B8: Klemens adedi (1 pano × komplekt) | C8: =SUMIF(BOM!$C$3:$C$19,"Klemens",BOM!$I$3:$I$19)*4+SUMIF(BOM!$C$24:$C$42,"Klemens",BOM!$I$24:$I$42)*10+SUMIF(BOM!$C$47:$C$65,"Klemens",BOM!$I$47:$I$65)*1 -> 765 | D8: =765 -> 765 | E8: =IF(OR(C8="",D8=""),"VERİ YOK",IF(ABS(N(C8)-N(D8))<0.51,"✓ OK","✖ HATA")) -> ✓ OK | F8: BOM satırlarından SUMIF ile sayılır; beklenen 51 × 15 = 765.
A9: K05 | B9: İşçilik dakikası = norm tablosu × test katsayısı | C9: =Kurallar!D40*Kurallar!B12 -> 315.675 | D9: =BOM!I21 -> 315.675 | E9: =IF(OR(C9="",D9=""),"VERİ YOK",IF(ABS(N(C9)-N(D9))<0.51,"✓ OK","✖ HATA")) -> ✓ OK | F9: Norm ara toplamı (Kurallar!D40) × TEST_ETIKET_KATS. Norm hücresi değişince BOM da değişir.
A10: K06 | B10: İşçilik tutarı = dakika × KZT/dk | C10: =BOM!I21*Kurallar!B11 -> 31567.5 | D10: =BOM!H21 -> 31567.5 | E10: =IF(OR(C10="",D10=""),"VERİ YOK",IF(ABS(N(C10)-N(D10))<0.51,"✓ OK","✖ HATA")) -> ✓ OK | F10: ЩУ-1 satırı üzerinden doğrulanır.
A11: K07 | B11: Montaj malzemesi = malzeme ara toplamı × oran | C11: =SUM(BOM!H3:H19)*Kurallar!B13 -> 3242.3603 | D11: =BOM!H20 -> 3242.3603 | E11: =IF(OR(C11="",D11=""),"VERİ YOK",IF(ABS(N(C11)-N(D11))<0.51,"✓ OK","✖ HATA")) -> ✓ OK | F11: ЩУ-1 satırı üzerinden doğrulanır (MONTAJ_MALZ_YUZDE).
A12: K08 | B12: Schneider net fiyat zinciri (örnek: A9F79340) | C12: =IFERROR(INDEX(FIYAT_KAYNAK!$F$3:$F$26,MATCH("SCHNEIDER|A9F79340",FIYAT_KAYNAK!$A$3:$A$26,0))*Kurallar!$B$54*Kurallar!$B$45,"") -> 14695.38 | D12: =IFERROR(INDEX(FIYAT_KAYNAK!$J$3:$J$26,MATCH("SCHNEIDER|A9F79340",FIYAT_KAYNAK!$A$3:$A$26,0)),"") -> 14695.38 | E12: =IF(OR(C12="",D12=""),"VERİ YOK",IF(ABS(N(C12)-N(D12))<0.51,"✓ OK","✖ HATA")) -> ✓ OK | F12: liste × marka katsayısı × kur. Katsayı veya kur değişince ikisi birlikte değişmeli.
A13: K09 | B13: Boş fiyat hücresi (artikülü var, fiyatı yok) | C13: =0 -> 0 | D13: =SUMPRODUCT((BOM!D3:D19<>"")*(BOM!G3:G19=""))+SUMPRODUCT((BOM!D24:D42<>"")*(BOM!G24:G42=""))+SUMPRODUCT((BOM!D47:D65<>"")*(BOM!G47:G65="")) -> 0 | E13: =IF(OR(C13="",D13=""),"VERİ YOK",IF(ABS(N(C13)-N(D13))<0.51,"✓ OK","✖ HATA")) -> ✓ OK | F13: Artikülü olup net fiyatı boş kalan satır sayısı. 0 olmalı; değilse eksik fiyat vardır.
A14: K10 | B14: Sıfır yazılmış fiyat hücresi | C14: =0 -> 0 | D14: =COUNTIF(BOM!G3:G19,0)+COUNTIF(BOM!G24:G42,0)+COUNTIF(BOM!G47:G65,0) -> 0 | E14: =IF(OR(C14="",D14=""),"VERİ YOK",IF(ABS(N(C14)-N(D14))<0.51,"✓ OK","✖ HATA")) -> ✓ OK | F14: Kural: fiyat yoksa hücre BOŞ kalır, asla 0 yazılmaz.
B16: GENEL SONUÇ | E16: =IF(COUNTIF(E5:E14,"✓ OK")=10,"✅ TEMİZ — teslim edilebilir","⛔ BULGU VAR — teslim etme") -> ⛔ BULGU VAR — teslim etme
