Workbook

Sheet 01_BOM_Ana_Format
A1: Malzeme | B1: Kod | C1: Açıklama ve Teknik Özellikler | D1: Fiyat | E1: Toplam Fiyat | F1: Üretici Firma | G1: Birim | H1: Miktar
A2: ГРЩ | C2: ГРЩ ana dağıtım pano komplekti; 380/220V; Ру=65,402 кВт; Рр=63,333 кВт; Iр=104,72A; IP31 | D2: 0 | E2: =D2*H2 -> 0 | F2: TEKLED | G2: компл. | H2: 1
A3: Корпус металлический | B3: TEKSAN 800x650x250 | C3: ГРЩ korpusu, IP31, УХЛ3; projedeki ЩМП-4-2 ölçüsüne göre | D3: 0 | E3: =D3*H3 -> 0 | F3: TEKSAN | G3: шт | H3: 1
A4: Автоматический выключатель MCCB | B4: NXM-125S/3P 125A 25kA | C4: 3P, 125A, 25kA, 380/400V; IEK ВА88-32 3P 125A 25kA muadili | D4: 0 | E4: =D4*H4 -> 0 | F4: CHINT | G4: шт | H4: 1
A5: Автоматический выключатель | B5: NXB-125 / NB1-125 3P C100A 15kA | C5: 3P, C100A, 15kA, 380/400V; ВА47-150 3P 100A 15kA muadili | D5: 0 | E5: =D5*H5 -> 0 | F5: CHINT | G5: шт | H5: 1
A6: Автоматический выключатель | B6: NB1-63 3P C50A 6kA | C6: 3P, C50A, 6kA, 380/400V; ЩР1 besleme çıkışı | D6: 0 | E6: =D6*H6 -> 0 | F6: CHINT | G6: шт | H6: 1
A7: Автоматический выключатель | B7: NB1-63 3P C16A 6kA | C7: 3P, C16A, 6kA, 380/400V; ЩУз/zadvijka besleme çıkışı | D7: 0 | E7: =D7*H7 -> 0 | F7: CHINT | G7: шт | H7: 1
A8: Автоматический выключатель | B8: NB1-63 1P C6A 6kA | C8: 1P, C6A, 6kA, 230V; ППС/yardımcı besleme çıkışı | D8: 0 | E8: =D8*H8 -> 0 | F8: CHINT | G8: шт | H8: 1
A9: Шина N/PE | B9: N/PE set | C9: ГРЩ için N ve PE bara seti; akım ve kesit üretimde kontrol edilecek | D9: 0 | E9: =D9*H9 -> 0 | F9: EKT / Onka / Klemsan | G9: компл. | H9: 1
A10: монтажный материал | C10: DIN ray, kablo kanalı, klemens, etiketleme, kablo ucu, bağlantı sarfı | D10: 0 | E10: =D10*H10 -> 0 | F10: EKT / Onka / Klemsan | G10: компл. | H10: 1
A11: монтажная работа | C11: ГРЩ pano montaj işçiliği ve test | D11: 0 | E11: =D11*H11 -> 0 | F11: TEKLED | G11: компл. | H11: 1
A12: ЩР1 | C12: ЩР1 dağıtım pano komplekti; Ру=20,691 кВт; Рр=18,622 кВт; Iр=30,8A; IP31 | D12: 0 | E12: =D12*H12 -> 0 | F12: TEKLED | G12: компл. | H12: 1
A13: Корпус металлический | B13: TEKSAN ЩРн-36 / 585x310x130 | C13: 36 modül, IP31, УХЛ3; projedeki ЩРн-36з-0 ölçüsüne göre | D13: 0 | E13: =D13*H13 -> 0 | F13: TEKSAN | G13: шт | H13: 1
A14: Автоматический выключатель | B14: NB1-63 3P C40A 6kA | C14: 3P, C40A, 6kA, 380/400V; ЩР1 giriş otomatiği | D14: 0 | E14: =D14*H14 -> 0 | F14: CHINT | G14: шт | H14: 1
A15: Автоматический выключатель | B15: NB1-63 1P C6A 6kA | C15: 1P, C6A, 6kA, 230V; aydınlatma grupları Гр.1-Гр.5 | D15: 0 | E15: =D15*H15 -> 0 | F15: CHINT | G15: шт | H15: 5
A16: Дифференциальный автомат | B16: NXBLE-32 1P+N C20A 30mA 6kA | C16: 2P / 1P+N, C20A, 30mA, 6kA, 230V; АВДТ32 C20 muadili | D16: 0 | E16: =D16*H16 -> 0 | F16: CHINT | G16: шт | H16: 3
A17: Дифференциальный автомат | B17: NXBLE-32 1P+N C16A 30mA 6kA | C17: 2P / 1P+N, C16A, 30mA, 6kA, 230V; АВДТ32 C16 muadili | D17: 0 | E17: =D17*H17 -> 0 | F17: CHINT | G17: шт | H17: 6
A18: Шина N/PE | B18: N/PE set | C18: ЩР1 için N ve PE bara seti | D18: 0 | E18: =D18*H18 -> 0 | F18: EKT / Onka / Klemsan | G18: компл. | H18: 1
A19: DIN рейка | B19: TH35 | C19: DIN ray; 36 modül pano için | D19: 0 | E19: =D19*H19 -> 0 | F19: EKT / Onka | G19: м | H19: 1
A20: Кабельный канал | B20: 25x40 / 40x40 | C20: Pano içi kablo kanalı | D20: 0 | E20: =D20*H20 -> 0 | F20: EKT | G20: м | H20: 1
A21: монтажный материал | C21: Klemens, etiketleme, köprüleme, kablo ucu ve bağlantı sarfı | D21: 0 | E21: =D21*H21 -> 0 | F21: EKT / Onka / Klemsan | G21: компл. | H21: 1
A22: монтажная работа | C22: ЩР1 pano montaj işçiliği ve test | D22: 0 | E22: =D22*H22 -> 0 | F22: TEKLED | G22: компл. | H22: 1
A23: ЩВ1 | C23: ЩВ1 havalandırma pano komplekti; Ру=44,34 кВт; Рр=44,34 кВт; Iр=70,53A; IP31 | D23: 0 | E23: =D23*H23 -> 0 | F23: TEKLED | G23: компл. | H23: 1
A24: Корпус металлический | B24: TEKSAN 400x210x150 / KONTROL | C24: Projede ЩМП-4.2.1-0, 400x210x150 mm; NXM-125 + shunt için yerleşim kontrol edilecek | D24: 0 | E24: =D24*H24 -> 0 | F24: TEKSAN | G24: шт | H24: 1
A25: Автоматический выключатель MCCB | B25: NXM-125S/3P 80A 25kA | C25: 3P, 80A, 25kA, 380/400V; giriş/firen trip hattı; ВА47-150 3P 80A 15kA muadili | D25: 0 | E25: =D25*H25 -> 0 | F25: CHINT | G25: шт | H25: 1
A26: Независимый расцепитель | B26: SHT-M1 A1 L AC230V | C26: NXM-125 uyumlu shunt release, AC230V; РН47-150 muadili | D26: 0 | E26: =D26*H26 -> 0 | F26: CHINT | G26: шт | H26: 1
A27: Автоматический выключатель | B27: NXB-125 3P C80A 10kA | C27: 3P, C80A, 10kA, 380/400V; воздухонагреватель 42kW çıkışı; ВА47-100 3P 80A muadili | D27: 0 | E27: =D27*H27 -> 0 | F27: CHINT | G27: шт | H27: 1
A28: Автоматический выключатель | B28: NB1-63 3P C10A 6kA | C28: 3P, C10A, 6kA, 380/400V; radyal fan çıkışları | D28: 0 | E28: =D28*H28 -> 0 | F28: CHINT | G28: шт | H28: 2
A29: Автоматический выключатель | B29: NB1-63 1P C6A 6kA | C29: 1P, C6A, 6kA, 230V; kanal fan devresi | D29: 0 | E29: =D29*H29 -> 0 | F29: CHINT | G29: шт | H29: 1
A30: Шина N/PE | B30: N/PE set | C30: ЩВ1 için N ve PE bara seti | D30: 0 | E30: =D30*H30 -> 0 | F30: EKT / Onka / Klemsan | G30: компл. | H30: 1
A31: DIN рейка | B31: TH35 | C31: DIN ray | D31: 0 | E31: =D31*H31 -> 0 | F31: EKT / Onka | G31: м | H31: 1
A32: Кабельный канал | B32: 25x40 / 40x40 | C32: Pano içi kablo kanalı | D32: 0 | E32: =D32*H32 -> 0 | F32: EKT | G32: м | H32: 1
A33: монтажный материал | C33: Klemens, etiketleme, kablo ucu, köprüleme ve bağlantı sarfı | D33: 0 | E33: =D33*H33 -> 0 | F33: EKT / Onka / Klemsan | G33: компл. | H33: 1
A34: монтажная работа | C34: ЩВ1 pano montaj işçiliği ve test | D34: 0 | E34: =D34*H34 -> 0 | F34: TEKLED | G34: компл. | H34: 1
A35: ЩУз | C35: Ящик управления задвижкой РУСМ5411-1874УХЛ2; 380V; reversif motor kumanda; IP54 | D35: 0 | E35: =D35*H35 -> 0 | F35: TEKLED | G35: компл. | H35: 1
A36: Корпус металлический | B36: TEKSAN 400x300x220 IP54 | C36: Duvar tipi metal korpus, montaj plakalı; ölçü üretimde kontrol edilecek | D36: 0 | E36: =D36*H36 -> 0 | F36: TEKSAN | G36: шт | H36: 1
A37: Автомат защиты двигателя / MKS | B37: NS2-25 0.4-0.63A | C37: 3P motor koruma şalteri; QF1; motor 0,18kW / yaklaşık 0,724A için ayar kontrol edilecek | D37: 0 | E37: =D37*H37 -> 0 | F37: CHINT | G37: шт | H37: 1
A38: Пускатель магнитный / контактор | B38: NC1-0910 AC230V | C38: 9A kontaktör, bobin AC230V; KM1/KM2 reversif çalışma | D38: 0 | E38: =D38*H38 -> 0 | F38: CHINT | G38: шт | H38: 2
A39: Механическая блокировка | B39: NC1M09-32 | C39: KM1-KM2 kontaktörleri için mekanik kilit | D39: 0 | E39: =D39*H39 -> 0 | F39: CHINT | G39: шт | H39: 1
A40: Реле электротепловое | B40: NR2-11.5 0.4-0.63A | C40: Termik röle; KK1; motor aşırı yük koruması | D40: 0 | E40: =D40*H40 -> 0 | F40: CHINT | G40: шт | H40: 1
...

Sheet 02_Muhendislik_BOM
A1: Pano | B1: Kategori | C1: Malzeme | D1: Kod | E1: Açıklama | F1: Üretici | G1: Birim | H1: Miktar | I1: Kaynak | J1: Kontrol Notu
A2: ГРЩ | B2: pano | C2: ГРЩ | E2: ГРЩ ana dağıtım pano komplekti; 380/220V; Ру=65,402 кВт; Рр=63,333 кВт; Iр=104,72A; IP31 | F2: TEKLED | G2: компл. | H2: 1 | I2: PDF s.4 ve s.12
A3: ГРЩ | B3: korpus | C3: Корпус металлический | D3: TEKSAN 800x650x250 | E3: ГРЩ korpusu, IP31, УХЛ3; projedeki ЩМП-4-2 ölçüsüne göre | F3: TEKSAN | G3: шт | H3: 1 | I3: PDF s.4 ve s.12
A4: ГРЩ | B4: TMS | C4: Автоматический выключатель MCCB | D4: NXM-125S/3P 125A 25kA | E4: 3P, 125A, 25kA, 380/400V; IEK ВА88-32 3P 125A 25kA muadili | F4: CHINT | G4: шт | H4: 1 | I4: PDF s.4 ve s.12
A5: ГРЩ | B5: OTO | C5: Автоматический выключатель | D5: NXB-125 / NB1-125 3P C100A 15kA | E5: 3P, C100A, 15kA, 380/400V; ВА47-150 3P 100A 15kA muadili | F5: CHINT | G5: шт | H5: 1 | I5: PDF s.4 ve s.12
A6: ГРЩ | B6: OTO | C6: Автоматический выключатель | D6: NB1-63 3P C50A 6kA | E6: 3P, C50A, 6kA, 380/400V; ЩР1 besleme çıkışı | F6: CHINT | G6: шт | H6: 1 | I6: PDF s.4 ve s.12
A7: ГРЩ | B7: OTO | C7: Автоматический выключатель | D7: NB1-63 3P C16A 6kA | E7: 3P, C16A, 6kA, 380/400V; ЩУз/zadvijka besleme çıkışı | F7: CHINT | G7: шт | H7: 1 | I7: PDF s.4 ve s.12
A8: ГРЩ | B8: OTO | C8: Автоматический выключатель | D8: NB1-63 1P C6A 6kA | E8: 1P, C6A, 6kA, 230V; ППС/yardımcı besleme çıkışı | F8: CHINT | G8: шт | H8: 1 | I8: PDF s.4 ve s.12
A9: ГРЩ | B9: BARA | C9: Шина N/PE | D9: N/PE set | E9: ГРЩ için N ve PE bara seti; akım ve kesit üretimde kontrol edilecek | F9: EKT / Onka / Klemsan | G9: компл. | H9: 1 | I9: PDF s.4 ve s.12 | J9: KONTROL EDİLECEK
A10: ГРЩ | B10: MONTAJ | C10: монтажный материал | E10: DIN ray, kablo kanalı, klemens, etiketleme, kablo ucu, bağlantı sarfı | F10: EKT / Onka / Klemsan | G10: компл. | H10: 1 | I10: PDF s.4 ve s.12
A11: ГРЩ | B11: MONTAJ | C11: монтажная работа | E11: ГРЩ pano montaj işçiliği ve test | F11: TEKLED | G11: компл. | H11: 1 | I11: PDF s.4 ve s.12
A12: ЩР1 | B12: pano | C12: ЩР1 | E12: ЩР1 dağıtım pano komplekti; Ру=20,691 кВт; Рр=18,622 кВт; Iр=30,8A; IP31 | F12: TEKLED | G12: компл. | H12: 1 | I12: PDF s.5-s.6 ve s.12
A13: ЩР1 | B13: korpus | C13: Корпус металлический | D13: TEKSAN ЩРн-36 / 585x310x130 | E13: 36 modül, IP31, УХЛ3; projedeki ЩРн-36з-0 ölçüsüne göre | F13: TEKSAN | G13: шт | H13: 1 | I13: PDF s.5-s.6 ve s.12
A14: ЩР1 | B14: OTO | C14: Автоматический выключатель | D14: NB1-63 3P C40A 6kA | E14: 3P, C40A, 6kA, 380/400V; ЩР1 giriş otomatiği | F14: CHINT | G14: шт | H14: 1 | I14: PDF s.5-s.6 ve s.12
A15: ЩР1 | B15: OTO | C15: Автоматический выключатель | D15: NB1-63 1P C6A 6kA | E15: 1P, C6A, 6kA, 230V; aydınlatma grupları Гр.1-Гр.5 | F15: CHINT | G15: шт | H15: 5 | I15: PDF s.5-s.6 ve s.12
A16: ЩР1 | B16: DIF | C16: Дифференциальный автомат | D16: NXBLE-32 1P+N C20A 30mA 6kA | E16: 2P / 1P+N, C20A, 30mA, 6kA, 230V; АВДТ32 C20 muadili | F16: CHINT | G16: шт | H16: 3 | I16: PDF s.5-s.6 ve s.12
A17: ЩР1 | B17: DIF | C17: Дифференциальный автомат | D17: NXBLE-32 1P+N C16A 30mA 6kA | E17: 2P / 1P+N, C16A, 30mA, 6kA, 230V; АВДТ32 C16 muadili | F17: CHINT | G17: шт | H17: 6 | I17: PDF s.5-s.6 ve s.12
A18: ЩР1 | B18: BARA | C18: Шина N/PE | D18: N/PE set | E18: ЩР1 için N ve PE bara seti | F18: EKT / Onka / Klemsan | G18: компл. | H18: 1 | I18: PDF s.5-s.6 ve s.12
A19: ЩР1 | B19: DIN | C19: DIN рейка | D19: TH35 | E19: DIN ray; 36 modül pano için | F19: EKT / Onka | G19: м | H19: 1 | I19: PDF s.5-s.6 ve s.12
A20: ЩР1 | B20: KANAL | C20: Кабельный канал | D20: 25x40 / 40x40 | E20: Pano içi kablo kanalı | F20: EKT | G20: м | H20: 1 | I20: PDF s.5-s.6 ve s.12
A21: ЩР1 | B21: MONTAJ | C21: монтажный материал | E21: Klemens, etiketleme, köprüleme, kablo ucu ve bağlantı sarfı | F21: EKT / Onka / Klemsan | G21: компл. | H21: 1 | I21: PDF s.5-s.6 ve s.12
A22: ЩР1 | B22: MONTAJ | C22: монтажная работа | E22: ЩР1 pano montaj işçiliği ve test | F22: TEKLED | G22: компл. | H22: 1 | I22: PDF s.5-s.6 ve s.12
A23: ЩВ1 | B23: pano | C23: ЩВ1 | E23: ЩВ1 havalandırma pano komplekti; Ру=44,34 кВт; Рр=44,34 кВт; Iр=70,53A; IP31 | F23: TEKLED | G23: компл. | H23: 1 | I23: PDF s.7 ve s.12
A24: ЩВ1 | B24: korpus | C24: Корпус металлический | D24: TEKSAN 400x210x150 / KONTROL | E24: Projede ЩМП-4.2.1-0, 400x210x150 mm; NXM-125 + shunt için yerleşim kontrol edilecek | F24: TEKSAN | G24: шт | H24: 1 | I24: PDF s.7 ve s.12 | J24: KONTROL EDİLECEK
A25: ЩВ1 | B25: TMS | C25: Автоматический выключатель MCCB | D25: NXM-125S/3P 80A 25kA | E25: 3P, 80A, 25kA, 380/400V; giriş/firen trip hattı; ВА47-150 3P 80A 15kA muadili | F25: CHINT | G25: шт | H25: 1 | I25: PDF s.7 ve s.12
A26: ЩВ1 | B26: SHUNT | C26: Независимый расцепитель | D26: SHT-M1 A1 L AC230V | E26: NXM-125 uyumlu shunt release, AC230V; РН47-150 muadili | F26: CHINT | G26: шт | H26: 1 | I26: PDF s.7 ve s.12
A27: ЩВ1 | B27: OTO | C27: Автоматический выключатель | D27: NXB-125 3P C80A 10kA | E27: 3P, C80A, 10kA, 380/400V; воздухонагреватель 42kW çıkışı; ВА47-100 3P 80A muadili | F27: CHINT | G27: шт | H27: 1 | I27: PDF s.7 ve s.12
A28: ЩВ1 | B28: OTO | C28: Автоматический выключатель | D28: NB1-63 3P C10A 6kA | E28: 3P, C10A, 6kA, 380/400V; radyal fan çıkışları | F28: CHINT | G28: шт | H28: 2 | I28: PDF s.7 ve s.12
A29: ЩВ1 | B29: OTO | C29: Автоматический выключатель | D29: NB1-63 1P C6A 6kA | E29: 1P, C6A, 6kA, 230V; kanal fan devresi | F29: CHINT | G29: шт | H29: 1 | I29: PDF s.7 ve s.12
A30: ЩВ1 | B30: BARA | C30: Шина N/PE | D30: N/PE set | E30: ЩВ1 için N ve PE bara seti | F30: EKT / Onka / Klemsan | G30: компл. | H30: 1 | I30: PDF s.7 ve s.12
A31: ЩВ1 | B31: DIN | C31: DIN рейка | D31: TH35 | E31: DIN ray | F31: EKT / Onka | G31: м | H31: 1 | I31: PDF s.7 ve s.12
A32: ЩВ1 | B32: KANAL | C32: Кабельный канал | D32: 25x40 / 40x40 | E32: Pano içi kablo kanalı | F32: EKT | G32: м | H32: 1 | I32: PDF s.7 ve s.12
A33: ЩВ1 | B33: MONTAJ | C33: монтажный материал | E33: Klemens, etiketleme, kablo ucu, köprüleme ve bağlantı sarfı | F33: EKT / Onka / Klemsan | G33: компл. | H33: 1 | I33: PDF s.7 ve s.12
A34: ЩВ1 | B34: MONTAJ | C34: монтажная работа | E34: ЩВ1 pano montaj işçiliği ve test | F34: TEKLED | G34: компл. | H34: 1 | I34: PDF s.7 ve s.12
A35: ЩУз | B35: pano | C35: ЩУз | E35: Ящик управления задвижкой РУСМ5411-1874УХЛ2; 380V; reversif motor kumanda; IP54 | F35: TEKLED | G35: компл. | H35: 1 | I35: PDF s.8 ve s.12
A36: ЩУз | B36: korpus | C36: Корпус металлический | D36: TEKSAN 400x300x220 IP54 | E36: Duvar tipi metal korpus, montaj plakalı; ölçü üretimde kontrol edilecek | F36: TEKSAN | G36: шт | H36: 1 | I36: PDF s.8 ve s.12 | J36: KONTROL EDİLECEK
A37: ЩУз | B37: CIHAZ | C37: Автомат защиты двигателя / MKS | D37: NS2-25 0.4-0.63A | E37: 3P motor koruma şalteri; QF1; motor 0,18kW / yaklaşık 0,724A için ayar kontrol edilecek | F37: CHINT | G37: шт | H37: 1 | I37: PDF s.8 ve s.12 | J37: KONTROL EDİLECEK
A38: ЩУз | B38: KONTAKTOR | C38: Пускатель магнитный / контактор | D38: NC1-0910 AC230V | E38: 9A kontaktör, bobin AC230V; KM1/KM2 reversif çalışma | F38: CHINT | G38: шт | H38: 2 | I38: PDF s.8 ve s.12
A39: ЩУз | B39: CIHAZ | C39: Механическая блокировка | D39: NC1M09-32 | E39: KM1-KM2 kontaktörleri için mekanik kilit | F39: CHINT | G39: шт | H39: 1 | I39: PDF s.8 ve s.12
A40: ЩУз | B40: TERMIK/RELAY | C40: Реле электротепловое | D40: NR2-11.5 0.4-0.63A | E40: Termik röle; KK1; motor aşırı yük koruması | F40: CHINT | G40: шт | H40: 1 | I40: PDF s.8 ve s.12
...

Sheet 03_Teklif_BOM
A1: Pano | B1: Açıklama | C1: Birim | D1: Miktar | E1: Malzeme Toplamı | F1: Montaj/İşçilik Dahil Toplam | G1: KDV % | H1: KDV Tutarı | I1: Genel Toplam | J1: Not
A2: ГРЩ | B2: Ana dağıtım pano komplekti | C2: компл. | D2: 1 | E2: =SUM('01_BOM_Ana_Format'!E2:E11) -> 0 | F2: =E2 -> 0 | G2: 12 | H2: =F2*G2/100 -> 0 | I2: =F2+H2 -> 0 | J2: Fiyat listesi eklenince otomatik hesap için BOM fiyat kolonunu doldur
A3: ЩР1 | B3: Dağıtım pano komplekti | C3: компл. | D3: 1 | E3: =SUM('01_BOM_Ana_Format'!E12:E22) -> 0 | F3: =E3 -> 0 | G3: 12 | H3: =F3*G3/100 -> 0 | I3: =F3+H3 -> 0 | J3: Fiyat listesi eklenince otomatik hesap için BOM fiyat kolonunu doldur
A4: ЩВ1 | B4: Havalandırma pano komplekti | C4: компл. | D4: 1 | E4: =SUM('01_BOM_Ana_Format'!E23:E34) -> 0 | F4: =E4 -> 0 | G4: 12 | H4: =F4*G4/100 -> 0 | I4: =F4+H4 -> 0 | J4: Fiyat listesi eklenince otomatik hesap için BOM fiyat kolonunu doldur
A5: ЩУз | B5: Zadvijka kumanda kutusu | C5: компл. | D5: 1 | E5: =SUM('01_BOM_Ana_Format'!E35:E52) -> 0 | F5: =E5 -> 0 | G5: 12 | H5: =F5*G5/100 -> 0 | I5: =F5+H5 -> 0 | J5: Fiyat listesi eklenince otomatik hesap için BOM fiyat kolonunu doldur
A6: ИПБ | B6: UPS ekipmanı | C6: компл. | D6: 1 | E6: =SUM('01_BOM_Ana_Format'!E53:E54) -> 0 | F6: =E6 -> 0 | G6: 12 | H6: =F6*G6/100 -> 0 | I6: =F6+H6 -> 0 | J6: Fiyat listesi eklenince otomatik hesap için BOM fiyat kolonunu doldur
A7: TOPLAM | E7: =SUM(E2:E6) -> 0 | F7: =SUM(F2:F6) -> 0 | H7: =SUM(H2:H6) -> 0 | I7: =SUM(I2:I6) -> 0

Sheet 04_Satinalma_Ozet
A1: Malzeme | B1: Kod | C1: Açıklama ve Teknik Özellikler | D1: Fiyat | E1: Toplam Fiyat | F1: Üretici Firma | G1: Birim | H1: Miktar
A2: Корпус металлический | B2: TEKSAN 800x650x250 | C2: ГРЩ korpusu, IP31, УХЛ3; projedeki ЩМП-4-2 ölçüsüne göre | D2: 0 | E2: =D2*H2 -> 0 | F2: TEKSAN | G2: шт | H2: 1
A3: Автоматический выключатель MCCB | B3: NXM-125S/3P 125A 25kA | C3: 3P, 125A, 25kA, 380/400V; IEK ВА88-32 3P 125A 25kA muadili | D3: 0 | E3: =D3*H3 -> 0 | F3: CHINT | G3: шт | H3: 1
A4: Автоматический выключатель | B4: NXB-125 / NB1-125 3P C100A 15kA | C4: 3P, C100A, 15kA, 380/400V; ВА47-150 3P 100A 15kA muadili | D4: 0 | E4: =D4*H4 -> 0 | F4: CHINT | G4: шт | H4: 1
A5: Автоматический выключатель | B5: NB1-63 3P C50A 6kA | C5: 3P, C50A, 6kA, 380/400V; ЩР1 besleme çıkışı | D5: 0 | E5: =D5*H5 -> 0 | F5: CHINT | G5: шт | H5: 1
A6: Автоматический выключатель | B6: NB1-63 3P C16A 6kA | C6: 3P, C16A, 6kA, 380/400V; ЩУз/zadvijka besleme çıkışı | D6: 0 | E6: =D6*H6 -> 0 | F6: CHINT | G6: шт | H6: 1
A7: Автоматический выключатель | B7: NB1-63 1P C6A 6kA | C7: 1P, C6A, 6kA, 230V; ППС/yardımcı besleme çıkışı | D7: 0 | E7: =D7*H7 -> 0 | F7: CHINT | G7: шт | H7: 1
A8: Шина N/PE | B8: N/PE set | C8: ГРЩ için N ve PE bara seti; akım ve kesit üretimde kontrol edilecek | D8: 0 | E8: =D8*H8 -> 0 | F8: EKT / Onka / Klemsan | G8: компл. | H8: 1
A9: монтажный материал | C9: DIN ray, kablo kanalı, klemens, etiketleme, kablo ucu, bağlantı sarfı | D9: 0 | E9: =D9*H9 -> 0 | F9: EKT / Onka / Klemsan | G9: компл. | H9: 1
A10: Корпус металлический | B10: TEKSAN ЩРн-36 / 585x310x130 | C10: 36 modül, IP31, УХЛ3; projedeki ЩРн-36з-0 ölçüsüne göre | D10: 0 | E10: =D10*H10 -> 0 | F10: TEKSAN | G10: шт | H10: 1
A11: Автоматический выключатель | B11: NB1-63 3P C40A 6kA | C11: 3P, C40A, 6kA, 380/400V; ЩР1 giriş otomatiği | D11: 0 | E11: =D11*H11 -> 0 | F11: CHINT | G11: шт | H11: 1
A12: Автоматический выключатель | B12: NB1-63 1P C6A 6kA | C12: 1P, C6A, 6kA, 230V; aydınlatma grupları Гр.1-Гр.5 | D12: 0 | E12: =D12*H12 -> 0 | F12: CHINT | G12: шт | H12: 5
A13: Дифференциальный автомат | B13: NXBLE-32 1P+N C20A 30mA 6kA | C13: 2P / 1P+N, C20A, 30mA, 6kA, 230V; АВДТ32 C20 muadili | D13: 0 | E13: =D13*H13 -> 0 | F13: CHINT | G13: шт | H13: 3
A14: Дифференциальный автомат | B14: NXBLE-32 1P+N C16A 30mA 6kA | C14: 2P / 1P+N, C16A, 30mA, 6kA, 230V; АВДТ32 C16 muadili | D14: 0 | E14: =D14*H14 -> 0 | F14: CHINT | G14: шт | H14: 6
A15: Шина N/PE | B15: N/PE set | C15: ЩР1 için N ve PE bara seti | D15: 0 | E15: =D15*H15 -> 0 | F15: EKT / Onka / Klemsan | G15: компл. | H15: 1
A16: DIN рейка | B16: TH35 | C16: DIN ray; 36 modül pano için | D16: 0 | E16: =D16*H16 -> 0 | F16: EKT / Onka | G16: м | H16: 1
A17: Кабельный канал | B17: 25x40 / 40x40 | C17: Pano içi kablo kanalı | D17: 0 | E17: =D17*H17 -> 0 | F17: EKT | G17: м | H17: 3
A18: монтажный материал | C18: Klemens, etiketleme, köprüleme, kablo ucu ve bağlantı sarfı | D18: 0 | E18: =D18*H18 -> 0 | F18: EKT / Onka / Klemsan | G18: компл. | H18: 1
A19: Корпус металлический | B19: TEKSAN 400x210x150 / KONTROL | C19: Projede ЩМП-4.2.1-0, 400x210x150 mm; NXM-125 + shunt için yerleşim kontrol edilecek | D19: 0 | E19: =D19*H19 -> 0 | F19: TEKSAN | G19: шт | H19: 1
A20: Автоматический выключатель MCCB | B20: NXM-125S/3P 80A 25kA | C20: 3P, 80A, 25kA, 380/400V; giriş/firen trip hattı; ВА47-150 3P 80A 15kA muadili | D20: 0 | E20: =D20*H20 -> 0 | F20: CHINT | G20: шт | H20: 1
A21: Независимый расцепитель | B21: SHT-M1 A1 L AC230V | C21: NXM-125 uyumlu shunt release, AC230V; РН47-150 muadili | D21: 0 | E21: =D21*H21 -> 0 | F21: CHINT | G21: шт | H21: 1
A22: Автоматический выключатель | B22: NXB-125 3P C80A 10kA | C22: 3P, C80A, 10kA, 380/400V; воздухонагреватель 42kW çıkışı; ВА47-100 3P 80A muadili | D22: 0 | E22: =D22*H22 -> 0 | F22: CHINT | G22: шт | H22: 1
A23: Автоматический выключатель | B23: NB1-63 3P C10A 6kA | C23: 3P, C10A, 6kA, 380/400V; radyal fan çıkışları | D23: 0 | E23: =D23*H23 -> 0 | F23: CHINT | G23: шт | H23: 2
A24: Автоматический выключатель | B24: NB1-63 1P C6A 6kA | C24: 1P, C6A, 6kA, 230V; kanal fan devresi | D24: 0 | E24: =D24*H24 -> 0 | F24: CHINT | G24: шт | H24: 1
A25: Шина N/PE | B25: N/PE set | C25: ЩВ1 için N ve PE bara seti | D25: 0 | E25: =D25*H25 -> 0 | F25: EKT / Onka / Klemsan | G25: компл. | H25: 1
A26: DIN рейка | B26: TH35 | C26: DIN ray | D26: 0 | E26: =D26*H26 -> 0 | F26: EKT / Onka | G26: м | H26: 2
A27: монтажный материал | C27: Klemens, etiketleme, kablo ucu, köprüleme ve bağlantı sarfı | D27: 0 | E27: =D27*H27 -> 0 | F27: EKT / Onka / Klemsan | G27: компл. | H27: 1
A28: Корпус металлический | B28: TEKSAN 400x300x220 IP54 | C28: Duvar tipi metal korpus, montaj plakalı; ölçü üretimde kontrol edilecek | D28: 0 | E28: =D28*H28 -> 0 | F28: TEKSAN | G28: шт | H28: 1
A29: Автомат защиты двигателя / MKS | B29: NS2-25 0.4-0.63A | C29: 3P motor koruma şalteri; QF1; motor 0,18kW / yaklaşık 0,724A için ayar kontrol edilecek | D29: 0 | E29: =D29*H29 -> 0 | F29: CHINT | G29: шт | H29: 1
A30: Пускатель магнитный / контактор | B30: NC1-0910 AC230V | C30: 9A kontaktör, bobin AC230V; KM1/KM2 reversif çalışma | D30: 0 | E30: =D30*H30 -> 0 | F30: CHINT | G30: шт | H30: 2
A31: Механическая блокировка | B31: NC1M09-32 | C31: KM1-KM2 kontaktörleri için mekanik kilit | D31: 0 | E31: =D31*H31 -> 0 | F31: CHINT | G31: шт | H31: 1
A32: Реле электротепловое | B32: NR2-11.5 0.4-0.63A | C32: Termik röle; KK1; motor aşırı yük koruması | D32: 0 | E32: =D32*H32 -> 0 | F32: CHINT | G32: шт | H32: 1
A33: Переключатель универсальный | B33: NP2-BD33 / NP2-ED33 | C33: SA1, 3 pozisyonlu seçici anahtar: местн / 0 / авт | D33: 0 | E33: =D33*H33 -> 0 | F33: CHINT | G33: шт | H33: 1
A34: Кнопка, толкатель красный | B34: NP2-BA42 | C34: Ф22 kırmızı buton; SB1 | D34: 0 | E34: =D34*H34 -> 0 | F34: CHINT | G34: шт | H34: 1
A35: Кнопка, толкатель черный | B35: NP2-BA31 | C35: Ф22 siyah buton; SB2 | D35: 0 | E35: =D35*H35 -> 0 | F35: CHINT | G35: шт | H35: 1
A36: Арматура светосигнальная | B36: ND16-22DS/230V | C36: 230V LED sinyal lambası; HLR1/HLR2 | D36: 0 | E36: =D36*H36 -> 0 | F36: CHINT | G36: шт | H36: 2
A37: Выключатель конечный | B37: SQ / CHINT muadil | C37: Limit switch; SQ1/SQ2/SQ3/SQ4; zadvijka üzerinde/harici montaj | D37: 0 | E37: =D37*H37 -> 0 | F37: CHINT / muadil | G37: шт | H37: 4
A38: Пост управления с одной кнопкой | B38: ПКЕ-212/1 / NP2 box 1 button | C38: Harici tek butonlu kumanda postu; ПК1-SB...ПК3-SB; spec ile adet kontrol edilecek | D38: 0 | E38: =D38*H38 -> 0 | F38: CHINT / IEK muadil | G38: шт | H38: 3
A39: Клемма проходная 2.5 мм² | B39: CTS 2.5 / PYK 2.5 | C39: X1/X2 klemens grubu için geçiş klemensi | D39: 0 | E39: =D39*H39 -> 0 | F39: Klemsan / Onka | G39: шт | H39: 25
A40: Клемма PE 2.5 мм² | B40: CTS 2.5 PE | C40: Topraklama klemensi | D40: 0 | E40: =D40*H40 -> 0 | F40: Klemsan / Onka | G40: шт | H40: 2
...

Sheet 05_Kontrol_Listesi
A1: No | B1: Seviye | C1: Pano | D1: Kontrol Konusu | E1: Açıklama | F1: Durum
A2: 1 | B2: UYARI | C2: Tüm panolar | D2: Fiyat kaynağı | E2: Güncel CHINT/TEKSAN/EKT/Onka/Klemsan fiyat listesi eklenmediği için ana BOM fiyatları 0 bırakıldı. | F2: KONTROL EDİLECEK
A3: 2 | B3: UYARI | C3: ЩВ1 | D3: Korpus ölçüsü | E3: Projede 400x210x150 mm verilmiş. NXM-125S/3P 80A + shunt release ve NXB-125 çıkışla yerleşim sıkışabilir. | F3: KONTROL EDİLECEK
A4: 3 | B4: UYARI | C4: ЩУз | D4: ПКЕ-212/1 adet farkı | E4: Şema sayfasında ПК1-SB...ПК3-SB olarak 3 adet okunuyor; spesifikasyonda 2 adet görünüyor. BOM'da şemaya göre 3 adet kullanıldı. | F4: KONTROL EDİLECEK
A5: 4 | B5: BİLGİ | C5: ЩУз | D5: QF1 / motor koruma | E5: Zadvijka kumanda şemasında QF1 gösterildiği için CHINT NS2-25 0.4-0.63A MKS olarak açıldı. | F5: OK
A6: 5 | B6: BİLGİ | C6: ГРЩ | D6: 1P 6A devre | E6: Besleme şemasında ППС için ВА47-60M 1P 6A görüldüğü için ГРЩ BOM'a eklendi. | F6: OK
A7: 6 | B7: BİLGİ | C7: Ana BOM | D7: Format | E7: Ana BOM sayfasında sadece sabit 8 kolon kullanıldı; mühendislik/kontrol detayları ayrı sayfalara alındı. | F7: OK

Sheet 06_Fiyat_Kontrol
A1: Kural | B1: Uygulama | C1: Not
A2: Şalt marka | B2: CHINT | C2: Aksi belirtilmedikçe varsayılan marka
A3: Korpus | B3: TEKSAN | C3: Projede verilen ölçüler esas alındı; gerekirse üretim ölçüsü kontrol edilecek
A4: Sarf | B4: EKT / Onka / Klemsan | C4: Klemens, DIN ray, kablo kanalı, N/PE, uç/etiket sarfı
A5: Kablo | B5: Harmony | C5: Bu BOM pano içi ve pano ekipmanı içindir; saha kabloları ayrıca istenirse açılır
A6: Fiyat | B6: 0 | C6: Güncel fiyat listesi verilmedi; fiyat sütunu format bozulmasın diye 0 bırakıldı
A7: Toplam Fiyat | B7: Formül | C7: Ana BOM ve satın alma sayfalarında Toplam Fiyat = Fiyat x Miktar
