Workbook

Sheet BOM_CHINT
A1: Pano | B1: Kategori | C1: Код товара | D1: Название продукта / Описание | E1: цена | F1: цена2 | G1: сумм. | H1: Технические характеристики | I1: Количество | J1: Единица | K1: Бренд/Поставщик | L1: Kaynak | M1: Not | N1: Tahmini modül | O1: malz
A2: ГРЩ | B2: pano | D2: ГРЩ ana dağıtım pano komplekti | H2: Ру=65,402 кВт; Рр=63,333 кВт; Ip=104,72A; 380/220V; IP31 | I2: 1 | J2: компл. | K2: TEKSAN | L2: PDF s.2, s.10 | M2: İç malzemeler 1 pano içindir
A3: ГРЩ | B3: korpus | C3: 719-15450 | D3: Корпус ЩМП5 (1000x650x300) ip54 | E3: 42500 | F3: =E3*0.6 -> 25500 | G3: =BOM_CHINT!$F3*BOM_CHINT!$I3 -> 25500 | H3: IP31, UХЛ3, 800x650x250 mm | I3: 1 | J3: шт | K3: teksan f | L3: PDF s.10 | M3: Projede IEK ЩМП-4-2 verilmiş; üretim TEKSAN yapılacaksa ölçü korunabilir | O3: 25500
A4: ГРЩ | B4: tms | C4: 131363 | D4: Авт. выкл. NXM-125S/3Р 125A 25кА (R) | E4: 19760 | F4: =0.6*BOM_CHINT!$E4 -> 11856 | G4: =BOM_CHINT!$F4*BOM_CHINT!$I4 -> 11856 | H4: 3P, 125A, ≥25kA, 380/400V | I4: 1 | J4: шт | K4: CHINT | L4: PDF s.2, s.10 | M4: IEK ВА88-32 3P 125A 25kA muadili; kesin seri stok/fiyat listesine göre seçilecek | O4: 11856
A5: ГРЩ | B5: oto | C5: 131362 | D5: Авт. выкл. NXM-125S/3Р 100A 25кА (R) | E5: 19443 | F5: =0.6*BOM_CHINT!$E5 -> 11665.8 | G5: =BOM_CHINT!$F5*BOM_CHINT!$I5 -> 11665.8 | H5: 3P, C100A, ≥15kA, 380/400V | I5: 1 | J5: шт | K5: CHINT | L5: PDF s.2, s.10 | M5: Projede ВА47-150 3P 100A 15kA görünüyor | N5: 4.5 | O5: 11665.8
A6: ГРЩ | B6: oto | C6: 814175 | D6: Авт. выкл. NXB-63 3P 50A 6кА х-ка C (R) | E6: 5719 | F6: =0.6*BOM_CHINT!$E6 -> 3431.4 | G6: =BOM_CHINT!$F6*BOM_CHINT!$I6 -> 3431.4 | H6: 3P, C50A, 6kA, 380/400V | I6: 1 | J6: шт | K6: CHINT | L6: PDF s.2, s.10 | M6: ЩР1 besleme çıkışı; projede ВА47-60M 3P 50A | N6: 3 | O6: 3431.4
A7: ГРЩ | B7: oto | C7: 296708 | D7: Авт. выкл. NXB-63S 1P 6А 4.5kA х-ка C (R) | E7: 975 | F7: =0.6*BOM_CHINT!$E7 -> 585 | G7: =BOM_CHINT!$F7*BOM_CHINT!$I7 -> 585 | H7: 1P, C6A, 6kA, 230V | I7: 1 | J7: шт | K7: CHINT | L7: PDF s.2, s.10 | N7: 3 | O7: 585
A8: ГРЩ | B8: oto | C8: 814170 | D8: Авт. выкл. NXB-63 3P 16A 6кА х-ка C (R) | E8: 5462 | F8: =0.6*BOM_CHINT!$E8 -> 3277.2 | G8: =BOM_CHINT!$F8*BOM_CHINT!$I8 -> 3277.2 | H8: 3P, C16A, 6kA, 380/400V | I8: 1 | J8: шт | K8: CHINT | L8: PDF s.2, s.10 | M8: Задвижка/ЩУз besleme; projede ВА47-60M 3P 16A | N8: 3 | O8: 3277.2
A9: ГРЩ | B9: mont. matryal | D9: монтажный материал | E9: =OFFSET(BOM_CHINT!$E9,1,2) -> 24000 | F9: =BOM_CHINT!$E9 -> 24000 | G9: =BOM_CHINT!$F9*BOM_CHINT!$I9 -> 24000 | H9: DIN ray, klemens, kablo kanalı, bara/dağıtım, etiketleme, bağlantı sarfı | I9: 1 | J9: шт | K9: pys | L9: Proje | M9: Küçük sarf malzemeler bu satırda toplandı | O9: 24000
A10: ГРЩ | B10: mont. rab. | D10: монтажная работа | E10: 4 | F10: 100 | G10: =BOM_CHINT!$F10*BOM_CHINT!$I10 -> 24000 | H10: ГРЩ pano montaj işçiliği | I10: =60*BOM_CHINT!$E10 -> 240 | J10: mont. rab. | K10: TEKLED | L10: Proje | O10: 24000
A11: Toplam ГРЩ | G11: =SUBTOTAL(9,G2:G10) -> 0 | O11: 104315.4
A12: ЩР1 | B12: pano | D12: ЩР1 dağıtım pano komplekti | H12: Ру=20,691 кВт; Рр=18,622 кВт; Ip=30,8A; IP31 | I12: 1 | J12: компл. | K12: TEKSAN | L12: PDF s.3, s.4, s.10 | M12: İç malzemeler 1 pano içindir
A13: ЩР1 | B13: korpus | C13: 714-15015 | D13: Щит мет.ЩРн-36 б/o (312х540х120)S/U 36 IP31 (TS) | E13: 18500 | F13: =E13*0.6 -> 11100 | G13: =BOM_CHINT!$F13*BOM_CHINT!$I13 -> 11100 | H13: 36 modül, IP31, UХЛ3, 585x310x130 mm | I13: 1 | J13: шт | K13: teksan f | L13: PDF s.3, s.10 | M13: Projede 36 modül; CHINT cihazlarla modül kontrolü yeterli görünüyor | N13: 36 | O13: 11100
A14: ЩР1 | B14: oto | C14: 814174 | D14: Авт. выкл. NXB-63 3P 40A 6кА х-ка C (R) | E14: 5647 | F14: =0.6*BOM_CHINT!$E14 -> 3388.2 | G14: =BOM_CHINT!$F14*BOM_CHINT!$I14 -> 3388.2 | H14: 3P, C40A, 6kA, 380/400V | I14: 1 | J14: шт | K14: CHINT | L14: PDF s.3, s.10 | M14: ЩР1 giriş otomatiği; projede ВА47-60M 3P 40A | N14: 3 | O14: 3388.2
A15: ЩР1 | B15: oto | C15: 296708 | D15: Авт. выкл. NXB-63S 1P 6А 4.5kA х-ка C (R) | E15: 975 | F15: =0.6*BOM_CHINT!$E15 -> 585 | G15: =BOM_CHINT!$F15*BOM_CHINT!$I15 -> 2925 | H15: 1P, C6A, 6kA, 230V | I15: 5 | J15: шт | K15: CHINT | L15: PDF s.3, s.10 | M15: Aydınlatma grupları Гр.1-Гр.5 | N15: 5 | O15: 2925
A16: ЩР1 | B16: dif | C16: 515388 | D16: Диф. авт. выкл. NXBLE-63YH 1P+N C20 30mA тип A, 6kA (R) | E16: 5632 | F16: =0.6*BOM_CHINT!$E16 -> 3379.2 | G16: =BOM_CHINT!$F16*BOM_CHINT!$I16 -> 10137.6 | H16: 2P / 1P+N, C20A, 30mA, 6kA, 230V | I16: 3 | J16: шт | K16: CHINT | L16: PDF s.3, s.4, s.10 | M16: Projede АВДТ32 C20 toplam 3 adet | N16: 6 | O16: 10137.6
A17: ЩР1 | B17: dif | C17: 515381 | D17: Диф. авт. выкл. NXBLE-63YH 1P+N C16 30mA тип A, 6kA (R) | E17: 5104 | F17: =0.6*BOM_CHINT!$E17 -> 3062.4 | G17: =BOM_CHINT!$F17*BOM_CHINT!$I17 -> 18374.4 | H17: 2P / 1P+N, C16A, 30mA, 6kA, 230V | I17: 6 | J17: шт | K17: CHINT | L17: PDF s.3, s.4, s.10 | M17: Projede АВДТ32 C16 toplam 6 adet | N17: 12 | O17: 18374.4
A18: ЩР1 | B18: mont. matryal | D18: монтажный материал | E18: =OFFSET(BOM_CHINT!$E18,1,2) -> 15000 | F18: =BOM_CHINT!$E18 -> 15000 | G18: =BOM_CHINT!$F18*BOM_CHINT!$I18 -> 15000 | H18: N/PE baraları, DIN ray, klemens, kablo kanalı, bağlantı sarfı, etiketleme | I18: 1 | J18: шт | K18: pys | L18: Proje | M18: Küçük sarf malzemeler bu satırda toplandı | O18: 15000
A19: ЩР1 | B19: mont. rab. | D19: монтажная работа | E19: 2.5 | F19: 100 | G19: =BOM_CHINT!$F19*BOM_CHINT!$I19 -> 15000 | H19: ЩР1 pano montaj işçiliği | I19: =60*BOM_CHINT!$E19 -> 150 | J19: mont. rab. | K19: TEKLED | L19: Proje | O19: 15000
A20: Toplam ЩР1 | G20: =SUBTOTAL(9,G12:G19) -> 0 | O20: 75925.2
A21: ЩВ1 | B21: pano | D21: ЩВ1 havalandırma pano komplekti | H21: Ру=44,34 кВт; Рр=44,34 кВт; Ip=70,53A; IP31 | I21: 1 | J21: компл. | K21: TEKSAN | L21: PDF s.5, s.10 | M21: İç malzemeler 1 pano içindir
A22: ЩВ1 | B22: korpus | C22: 719-15450 | D22: Корпус ЩМП5 (1000x650x300) ip54 | E22: 42500 | F22: =E22*0.6 -> 25500 | G22: =BOM_CHINT!$F22*BOM_CHINT!$I22 -> 25500 | H22: IP31, UХЛ3, 400x210x150 mm | I22: 1 | J22: шт | K22: teksan f | L22: PDF s.5, s.10 | M22: CHINT NXB-125 + shunt için yerleşim üretimde kontrol edilmeli; gerekirse 400x300x150 seç | O22: 25500
A23: ЩВ1 | B23: oto | C23: 131361 | D23: Авт. выкл. NXM-125S/3Р 80A 25кА (R) | E23: 19418 | F23: =0.6*BOM_CHINT!$E23 -> 11650.8 | G23: =BOM_CHINT!$F23*BOM_CHINT!$I23 -> 11650.8 | H23: 3P, C80A, 10kA, 380/400V | I23: 1 | J23: шт | K23: CHINT | L23: PDF s.5, s.10 | M23: Воздухонагреватель 42kW çıkışı; projede ВА47-100 3P 80A 10kA | N23: 4.5 | O23: 11650.8
A24: ЩВ1 | B24: tms | C24: 816139 | D24: Авт. выкл. NXB-125 3P 80A 10кА х-ка C (R) | E24: 10949 | F24: =0.6*BOM_CHINT!$E24 -> 6569.4 | G24: =BOM_CHINT!$F24*BOM_CHINT!$I24 -> 6569.4 | H24: 3P, C80A, ≥15kA, 380/400V | I24: 1 | J24: шт | K24: CHINT | L24: PDF s.5, s.10 | M24: ЩВ1 giriş/firen trip; projede ВА47-150 3P 80A 15kA | N24: 4.5 | O24: 6569.4
A25: ЩВ1 | B25: nh47 | C25: 946996 | D25: Независимый расцепитель SHT-M1 A1 L для NXM-125(63)/NXMLE-125 AC230В (левый) (R) | E25: 10000 | F25: =E25 -> 10000 | G25: =BOM_CHINT!$F25*BOM_CHINT!$I25 -> 10000 | H25: NXB-125/NB1-125 uyumlu, 230V AC | I25: 1 | J25: шт | K25: CHINT bs | L25: PDF s.5, s.10 | M25: Projede РН47-150; yangında havalandırma panosu devre dışı bırakma için | N25: 1 | O25: 10000
A26: ЩВ1 | B26: oto | C26: 814169 | D26: Авт. выкл. NXB-63 3P 10A 6кА х-ка C (R) | E26: 5878 | F26: =0.6*BOM_CHINT!$E26 -> 3526.8 | G26: =BOM_CHINT!$F26*BOM_CHINT!$I26 -> 7053.6 | H26: 3P, C10A, 6kA, 380/400V | I26: 2 | J26: шт | K26: CHINT | L26: PDF s.5, s.10 | M26: 2 adet radyal fan çıkışı; projede ВА47-60M 3P 10A | N26: 6 | O26: 7053.6
A27: ЩВ1 | B27: oto | C27: 814012 | D27: Авт. выкл. NXB-63 1P 6A 6кА х-ка C (R) | E27: 1436 | F27: =0.6*BOM_CHINT!$E27 -> 861.6 | G27: =BOM_CHINT!$F27*BOM_CHINT!$I27 -> 861.6 | H27: 1P, C6A, 6kA, 230V | I27: 1 | J27: шт | K27: CHINT | L27: PDF s.5, s.10 | M27: Kanal fan devresi; projede ВА47-60M 1P 6A | N27: 1 | O27: 861.6
A28: ЩВ1 | B28: mont. matryal | D28: монтажный материал | E28: =OFFSET(BOM_CHINT!$E28,1,2) -> 18000 | F28: =BOM_CHINT!$E28 -> 18000 | G28: =BOM_CHINT!$F28*BOM_CHINT!$I28 -> 18000 | H28: N/PE baraları, DIN ray, klemens, kablo kanalı, bağlantı sarfı, etiketleme | I28: 1 | J28: шт | K28: pys | L28: Proje | M28: Küçük sarf malzemeler bu satırda toplandı | O28: 18000
A29: ЩВ1 | B29: mont. rab. | D29: монтажная работа | E29: 3 | F29: 100 | G29: =BOM_CHINT!$F29*BOM_CHINT!$I29 -> 18000 | H29: ЩВ1 pano montaj işçiliği | I29: =60*BOM_CHINT!$E29 -> 180 | J29: mont. rab. | K29: TEKLED | L29: Proje | O29: 18000
A30: Toplam ЩВ1 | G30: =SUBTOTAL(9,G21:G29) -> 0 | O30: 97635.4
A31: ЩУз | B31: pano | D31: ЩУз (РУСМ5411-1874УХЛ2) | H31: Elektrikli sürgülü vana kontrol kutusu komplekti | I31: 1 | J31: компл. | K31: TEKSAN | L31: PDF s.6, s.10 | M31: İç kontrol devresi ayrı kırılmadı; proje komple ürün olarak vermiş
A32: ЩУз | B32: korpus | C32: 719-15425 | D32: Мет.Корпус ЩМП-2 (500x400x220) IP54 | E32: 16770 | F32: =0.6*BOM_CHINT!$E32 -> 10062 | G32: =BOM_CHINT!$F32*BOM_CHINT!$I32 -> 10062 | I32: 1 | J32: шт | K32: teksan f | L32: PDF s.5, s.10 | M32: Воздухонагреватель 42kW çıkışı; projede ВА47-100 3P 80A 10kA | N32: 4.5 | O32: 10062
A33: ЩУз | B33: kontaktor | C33: 221033 | D33: Контактор NC1-0910 9А 230В/АС3 1НО 50Гц (R) | E33: 4800 | F33: =0.6*BOM_CHINT!$E33 -> 2880 | G33: =BOM_CHINT!$F33*BOM_CHINT!$I33 -> 5760 | H33: NC1-0910 AC230V | I33: 2 | J33: шт | K33: CHINT | L33: PDF s.5, s.10 | M33: Воздухонагреватель 42kW çıkışı; projede ВА47-100 3P 80A 10kA | N33: 4.5 | O33: 5760
A34: ЩУз | B34: dop kontaktor | C34: 257022 | D34: Приставка доп.контакты F4-11 к контактору NC1 и NC2 (R) | E34: 1176 | F34: =0.6*BOM_CHINT!$E34 -> 705.6 | G34: =BOM_CHINT!$F34*BOM_CHINT!$I34 -> 705.6 | H34: NC1M09-32 | I34: 1 | J34: шт | K34: CHINT | L34: PDF s.5, s.10 | M34: Воздухонагреватель 42kW çıkışı; projede ВА47-100 3P 80A 10kA | N34: 4.5 | O34: 705.6
A35: ЩУз | B35: sinyal lamb | C35: 593075 | D35: Индикатор ND16-22D/2 красный AC/DC230В (R) | E35: 589 | F35: =0.6*BOM_CHINT!$E35 -> 353.4 | G35: =BOM_CHINT!$F35*BOM_CHINT!$I35 -> 353.4 | H35: NR2-11.5 0.4-0.63A | I35: 1 | J35: шт | K35: CHINT | L35: PDF s.5, s.10 | M35: Воздухонагреватель 42kW çıkışı; projede ВА47-100 3P 80A 10kA | N35: 4.5 | O35: 353.4
A36: ЩУз | B36: buttom | C36: 573763 | D36: Кнопка управления NP2-BA35 без подсветки зеленая, 1НЗ +1НО IP40 | E36: 1750 | F36: =0.6*BOM_CHINT!$E36 -> 1050 | G36: =BOM_CHINT!$F36*BOM_CHINT!$I36 -> 1050 | H36: NP2-BD33 / NP2-ED33 | I36: 1 | J36: шт | K36: CHINT | L36: PDF s.5, s.10 | M36: Воздухонагреватель 42kW çıkışı; projede ВА47-100 3P 80A 10kA | N36: 4.5 | O36: 1050
A37: ЩУз | B37: teplo rele | C37: 837100 | D37: Тепловое реле NXR-12 2.5-4A (R) | E37: 4560 | F37: =0.6*BOM_CHINT!$E37 -> 2736 | G37: =BOM_CHINT!$F37*BOM_CHINT!$I37 -> 2736 | H37: NP2-BA42 | I37: 1 | J37: шт | K37: CHINT | L37: PDF s.5, s.10 | M37: Воздухонагреватель 42kW çıkışı; projede ВА47-100 3P 80A 10kA | N37: 4.5 | O37: 2736
A38: ЩУз | B38: oto | C38: 296704 | D38: Авт. выкл. NXB-63S 1P C1А 4.5kA х-ка C (R) | E38: 1030 | F38: =0.6*BOM_CHINT!$E38 -> 618 | G38: =BOM_CHINT!$F38*BOM_CHINT!$I38 -> 618 | H38: NP2-BA31 | I38: 1 | J38: шт | K38: CHINT | L38: PDF s.5, s.10 | M38: Воздухонагреватель 42kW çıkışı; projede ВА47-100 3P 80A 10kA | N38: 4.5 | O38: 618
A39: ЩУз | B39: buttom | C39: 573764 | D39: Кнопка управления NP2-BA45 без подсветки красная, 1НЗ +1НО IP40 | E39: 1620 | F39: =0.6*BOM_CHINT!$E39 -> 972 | G39: =BOM_CHINT!$F39*BOM_CHINT!$I39 -> 972 | H39: ND16-22DS/230V | I39: 1 | J39: шт | K39: CHINT | L39: PDF s.5, s.10 | M39: Воздухонагреватель 42kW çıkışı; projede ВА47-100 3P 80A 10kA | N39: 4.5 | O39: 972
A40: ЩУз | B40: mech blok | C40: 256717 | D40: Механическая блокировка MI-5 для NC1-09-32, NXC-09-38 (R) | E40: 1100 | F40: =0.6*BOM_CHINT!$E40 -> 660 | G40: =BOM_CHINT!$F40*BOM_CHINT!$I40 -> 660 | H40: SQ | I40: 1 | J40: шт | K40: CHINT | L40: PDF s.5, s.10 | M40: Воздухонагреватель 42kW çıkışı; projede ВА47-100 3P 80A 10kA | N40: 4.5 | O40: 660
...

Sheet fiyat tekl
A1: Код товара | B1: Название продукта / Описание | C1: цена | D1: цена2 | E1: сумм. | F1: Технические характеристики | G1: Количество | H1: Единица | I1: Бренд/Поставщик | J1: Kaynak | K1: Not | L1: Tahmini modül | M1: malz | N1: 2.3
B2: ГРЩ ana dağıtım pano komplekti | C2: =ROUNDUP(N2,-3) -> 240000 | D2: =0.7*C2 -> 168000 | E2: =D2*G2 -> 168000 | F2: Ру=65,402 кВт; Рр=63,333 кВт; Ip=104,72A; 380/220V; IP31 | G2: 1 | H2: компл. | I2: TEKSAN | J2: PDF s.2, s.10 | K2: İç malzemeler 1 pano içindir | M2: 104315.4 | N2: =2.3*M2 -> 239925.42
B3: ЩР1 dağıtım pano komplekti | C3: =ROUNDUP(N3,-3) -> 175000 | D3: =0.7*C3 -> 122500 | E3: =D3*G3 -> 122500 | F3: Ру=20,691 кВт; Рр=18,622 кВт; Ip=30,8A; IP31 | G3: 1 | H3: компл. | I3: TEKSAN | J3: PDF s.3, s.4, s.10 | K3: İç malzemeler 1 pano içindir | M3: 75925.2 | N3: =2.3*M3 -> 174627.96
B4: ЩВ1 havalandırma pano komplekti | C4: =ROUNDUP(N4,-3) -> 225000 | D4: =0.7*C4 -> 157500 | E4: =D4*G4 -> 157500 | F4: Ру=44,34 кВт; Рр=44,34 кВт; Ip=70,53A; IP31 | G4: 1 | H4: компл. | I4: TEKSAN | J4: PDF s.5, s.10 | K4: İç malzemeler 1 pano içindir | M4: 97635.4 | N4: =2.3*M4 -> 224561.42
B5: ЩУз (РУСМ5411-1874УХЛ2) | C5: =ROUNDUP(N5,-3) -> 141000 | D5: =0.7*C5 -> 98700 | E5: =D5*G5 -> 98700 | F5: Elektrikli sürgülü vana kontrol kutusu komplekti | G5: 1 | H5: компл. | I5: TEKSAN | J5: PDF s.6, s.10 | K5: İç kontrol devresi ayrı kırılmadı; proje komple ürün olarak vermiş | M5: 60987 | N5: =2.3*M5 -> 140270.1
B6: Источник бесперебойного питания SVC GT33-10KVA | C6: =ROUNDUP(N6,-3) -> 0 | D6: =0.7*C6 -> 0 | E6: =D6*G6 -> 0 | F6: UPS, 380V, 10kVA | G6: 1 | H6: компл. | I6: SVC | J6: PDF s.2, s.10 | K6: Projede komple ürün | M6: 0 | N6: =2.3*M6 -> 0
B7: Пост управления с одной кнопкой ПКЕ-212/1 | C7: =ROUNDUP(N7,-3) -> 0 | D7: =0.7*C7 -> 0 | E7: =D7*G7 -> 0 | F7: Tek butonlu kumanda istasyonu | G7: 2 | H7: компл. | I7: TEKSAN | J7: PDF s.6, s.10 | K7: Sayfa 6 şema/tabloda 2-3 adet okuma riski var; kesin adet üretim öncesi kontrol | M7: 0 | N7: =2.3*M7 -> 0

Sheet ups ve post upravlenıa
A1: ЩУз | B1: komple cihaz | D1: Источник бесперебойного питания SVC GT33-10KVA | E1: UPS, 380V, 10kVA | I1: 1 | J1: шт | K1: SVC | L1: PDF s.2, s.10 | M1: Projede komple ürün
A2: ЩУз | B2: cihaz | D2: Пост управления с одной кнопкой ПКЕ-212/1 | E2: Tek butonlu kumanda istasyonu | I2: 2 | J2: шт | K2: Proje / CHINT NP2 alternatifi kontrol | L2: PDF s.6, s.10 | M2: Sayfa 6 şema/tabloda 2-3 adet okuma riski var; kesin adet üretim öncesi kontrol

Sheet ЩУз gp
A1: Malzeme | B1: Kod | C1: Açıklama ve Teknik Özellikler | D1: Fiyat | E1: Toplam Fiyat | F1: Üretici Firma | G1: Birim | H1: Miktar
A2: ЩУз | B2: РУСМ5411-1874УХЛ2 | C2: Ящик управления задвижкой, 380В, reversif motor kumanda, IP54, комплект | E2: 0 | F2: TEKLED | G2: компл. | H2: 1
A3: Автомат защиты двигателя / MKS | B3: NS2-25 0.4-0.63A | C3: Motor koruma şalteri, 3P, 0.4-0.63A, QF1 için | E3: 0 | F3: CHINT | G3: шт | H3: 1
A4: Пускатель магнитный / контактор | B4: NC1-0910 AC230V | C4: Kontaktör, 9A, 1NO, bobin 230V AC, KM1/KM2 | E4: 0 | F4: CHINT | G4: шт | H4: 2
A5: Механическая блокировка | B5: NC1M09-32 | C5: İki kontaktör arası mekanik kilit, reversif çalışma için | E5: 0 | F5: CHINT | G5: шт | H5: 1
A6: Реле электротепловое | B6: NR2-11.5 0.4-0.63A | C6: Termik röle, KK1, motor aşırı yük koruması | E6: 0 | F6: CHINT | G6: шт | H6: 1
A7: Переключатель универсальный | B7: NP2-BD33 / NP2-ED33 | C7: SA1, 3 pozisyonlu seçici anahtar, местн / 0 / авт | E7: 0 | F7: CHINT | G7: шт | H7: 1
A8: Кнопка, толкатель красный | B8: NP2-BA42 | C8: Ф22 kırmızı buton, SB1 | E8: 0 | F8: CHINT | G8: шт | H8: 1
A9: Кнопка, толкатель серый / черный | B9: NP2-BA31 | C9: Ф22 gri/siyah buton, SB2 | E9: 0 | F9: CHINT | G9: шт | H9: 1
A10: Арматура светосигнальная | B10: ND16-22DS/230V | C10: 230V LED sinyal lambası, HLR1/HLR2 | E10: 0 | F10: CHINT | G10: шт | H10: 2
A11: Выключатель конечный | B11: SQ | C11: Limit switch, SQ1/SQ2/SQ3/SQ4; genelde zadvijka üzerinde gelir | E11: 0 | F11: CHINT / muadil | G11: шт | H11: 4
A12: Пост управления с одной кнопкой | B12: ПКЕ-212/1 / NP2 box 1 button | C12: Harici tek butonlu kumanda postu, ПК1-SB…ПК3-SB | E12: 0 | F12: CHINT / IEK muadil | G12: шт | H12: 3
A13: Клемма проходная 2.5 мм² | B13: CTS 2.5 / PYK 2.5 | C13: X1/X2 klemens grubu için geçiş klemensi | E13: 0 | F13: Klemsan / Onka | G13: шт | H13: 25
... A20: монтажная работа | B20: компл. | C20: Pano montaj işçiliği ve test | E20: 0 | F20: TEKLED | G20: монтажная работа | H20: 1
A22: Панель | B22: Группа | C22: Тип / тех.значение | D22: Код | E22: Наименование | F22: Кол-во | G22: Ед.изм | H22: Производитель | I22: Примечание
A23: ЩУз | B23: external | C23: SQ | E23: Выключатель конечный задвижки | F23: 4 | G23: шт | H23: Комплект задвижки / поставщик | I23: Genelde zadvijka üzerinde gelir, ayrıca alınacaksa eklenir
A24: ЩУз | B24: external | C24: ПКЕ-212/1 | D24: ПКЕ-212/1 | E24: Пост управления с одной кнопкой | F24: 2 | G24: шт | H24: IEK/CHINT muadil | I24: Spesifikasyonda 2 adet; şemada ПК1-SB...ПК3-SB yazdığı için adet kontrol edilmeli
A25: ЩУз | B25: cable | C25: ВВГнг 5х2,5 | E25: Кабель к эл. двигателю задвижки | F25: 3 | G25: м | I25: Panel dışı saha kablosu
A26: ЩУз | B26: cable | C26: ВВГнг 2х1,5 | E26: Кабель к кнопкам SB1-SB2 | F26: 54 | G26: м | I26: Panel dışı saha kablosu

Sheet Satinalma_Ozet
A1: Kategori | B1: Ürün Kodu | C1: Ürün İsmi / Açıklama | D1: Teknik Özellik | E1: Toplam Miktar | F1: Birim | G1: Marka/Tedarikçi | H1: Panolar | I1: Not
A2: cihaz | C2: CHINT shunt release / bağımsız açtırma bobini | D2: NXB-125/NB1-125 uyumlu, 230V AC | E2: 1 | F2: шт | G2: CHINT | H2: ЩВ1 | I2: Ürün kodu/stok kodu fiyat listesine göre kontrol edilecek
A3: cihaz | C3: Пост управления с одной кнопкой ПКЕ-212/1 | D3: Tek butonlu kumanda istasyonu | E3: 2 | F3: шт | G3: Proje / CHINT NP2 alternatifi kontrol | H3: ЩУз | I3: Ürün kodu/stok kodu fiyat listesine göre kontrol edilecek
A4: dif | C4: CHINT NXBLE-32 diferansiyel otomatik | D4: 2P / 1P+N, C20A, 30mA, 6kA, 230V | E4: 3 | F4: шт | G4: CHINT | H4: ЩР1 | I4: Ürün kodu/stok kodu fiyat listesine göre kontrol edilecek
A5: dif | C5: CHINT NXBLE-32 diferansiyel otomatik | D5: 2P / 1P+N, C16A, 30mA, 6kA, 230V | E5: 6 | F5: шт | G5: CHINT | H5: ЩР1 | I5: Ürün kodu/stok kodu fiyat listesine göre kontrol edilecek
A6: komple cihaz | C6: Источник бесперебойного питания SVC GT33-10KVA | D6: UPS, 380V, 10kVA | E6: 1 | F6: шт | G6: SVC | H6: ЩУз
A7: komple cihaz | C7: Ящик управления задвижкой РУСМ5411-1874УХЛ2 | D7: Elektrikli sürgülü vana kontrol kutusu komplekti | E7: 1 | F7: шт | G7: Proje / komple ürün | H7: ЩУз
A8: korpus | C8: Korpus metal / ЩМП-4-2 | D8: IP31, UХЛ3, 800x650x250 mm | E8: 1 | F8: шт | G8: TEKSAN / Proje | H8: ГРЩ
A9: korpus | C9: Korpus metal / ЩМП-4.2.1-0 | D9: IP31, UХЛ3, 400x210x150 mm | E9: 1 | F9: шт | G9: TEKSAN / Proje | H9: ЩВ1
A10: korpus | C10: Korpus metal / ЩРн-36з-0 | D10: 36 modül, IP31, UХЛ3, 585x310x130 mm | E10: 1 | F10: шт | G10: TEKSAN / Proje | H10: ЩР1
A11: mont. matryal | C11: монтажный материал | D11: DIN ray, klemens, kablo kanalı, bara/dağıtım, etiketleme, bağlantı sarfı | E11: 1 | F11: компл. | G11: EKT / Onka / Klemsan / TEKLED | H11: ГРЩ
A12: mont. matryal | C12: монтажный материал | D12: N/PE baraları, DIN ray, klemens, kablo kanalı, bağlantı sarfı, etiketleme | E12: 2 | F12: компл. | G12: EKT / Onka / Klemsan / TEKLED | H12: ЩВ1, ЩР1
A13: mont. matryal | C13: монтажный материал | D13: Klemens, etiketleme, küçük sarf, bağlantı kablosu uçları | E13: 1 | F13: компл. | G13: EKT / Onka / Klemsan / TEKLED | H13: ЩУз
A14: mont. rab. | C14: монтажная работа | D14: ГРЩ pano montaj işçiliği | E14: 1 | F14: компл. | G14: TEKLED | H14: ГРЩ
A15: mont. rab. | C15: монтажная работа | D15: ЩР1 pano montaj işçiliği | E15: 1 | F15: компл. | G15: TEKLED | H15: ЩР1
A16: mont. rab. | C16: монтажная работа | D16: ЩВ1 pano montaj işçiliği | E16: 1 | F16: компл. | G16: TEKLED | H16: ЩВ1
A17: mont. rab. | C17: монтажная работа | D17: ЩУз montaj/kontrol işçiliği | E17: 1 | F17: компл. | G17: TEKLED | H17: ЩУз
A18: oto | C18: CHINT NB1-63 otomatik | D18: 3P, C50A, 6kA, 380/400V | E18: 1 | F18: шт | G18: CHINT | H18: ГРЩ | I18: Ürün kodu/stok kodu fiyat listesine göre kontrol edilecek
A19: oto | C19: CHINT NB1-63 otomatik | D19: 3P, C16A, 6kA, 380/400V | E19: 1 | F19: шт | G19: CHINT | H19: ГРЩ | I19: Ürün kodu/stok kodu fiyat listesine göre kontrol edilecek
A20: oto | C20: CHINT NB1-63 otomatik | D20: 3P, C40A, 6kA, 380/400V | E20: 1 | F20: шт | G20: CHINT | H20: ЩР1 | I20: Ürün kodu/stok kodu fiyat listesine göre kontrol edilecek
A21: oto | C21: CHINT NB1-63 otomatik | D21: 1P, C6A, 6kA, 230V | E21: 6 | F21: шт | G21: CHINT | H21: ЩВ1, ЩР1 | I21: Ürün kodu/stok kodu fiyat listesine göre kontrol edilecek
A22: oto | C22: CHINT NB1-63 otomatik | D22: 3P, C10A, 6kA, 380/400V | E22: 2 | F22: шт | G22: CHINT | H22: ЩВ1 | I22: Ürün kodu/stok kodu fiyat listesine göre kontrol edilecek
A23: oto | C23: CHINT NXB-125 / NB1-125 otomatik | D23: 3P, C100A, ≥15kA, 380/400V | E23: 1 | F23: шт | G23: CHINT | H23: ГРЩ | I23: Ürün kodu/stok kodu fiyat listesine göre kontrol edilecek
A24: oto | C24: CHINT NXB-125 / NB1-125 otomatik | D24: 3P, C80A, ≥15kA, 380/400V | E24: 1 | F24: шт | G24: CHINT | H24: ЩВ1 | I24: Ürün kodu/stok kodu fiyat listesine göre kontrol edilecek
A25: oto | B25: 816139 | C25: CHINT NXB-125 otomatik | D25: 3P, C80A, 10kA, 380/400V | E25: 1 | F25: шт | G25: CHINT | H25: ЩВ1
A26: pano | C26: ГРЩ ana dağıtım pano komplekti | D26: Ру=65,402 кВт; Рр=63,333 кВт; Ip=104,72A; 380/220V; IP31 | E26: 1 | F26: компл. | G26: Proje | H26: ГРЩ
A27: pano | C27: ЩВ1 havalandırma pano komplekti | D27: Ру=44,34 кВт; Рр=44,34 кВт; Ip=70,53A; IP31 | E27: 1 | F27: компл. | G27: Proje | H27: ЩВ1
A28: pano | C28: ЩР1 dağıtım pano komplekti | D28: Ру=20,691 кВт; Рр=18,622 кВт; Ip=30,8A; IP31 | E28: 1 | F28: компл. | G28: Proje | H28: ЩР1
A29: tms | C29: CHINT NXM / NM1 MCCB kompakt şalter | D29: 3P, 125A, ≥25kA, 380/400V | E29: 1 | F29: шт | G29: CHINT | H29: ГРЩ | I29: Ürün kodu/stok kodu fiyat listesine göre kontrol edilecek

Sheet Kaynak_Not
A1: Dosya/Kaynak | B1: Kapsam | C1: Not
A2: ЭОМ Том 6. Электроосвещение и электрооборудование.pdf | B2: Sayfa 2-6 ve 10: besleme şeması, ЩР1, ЩВ1, ЩУз ve spesifikasyon | C2: Miktarlar proje PDF’inden alındı; orijinal marka IEK, şalt CHINT muadiliyle değiştirildi.
A3: CHINT NB1-63 resmi ürün sayfası | B3: NB1-63 MCB; 6kA; B/C/D eğrileri; 1-63A | C3: https://www.chintglobal.com/global/en/products/low-voltage/iec/final-power-distribution/nb1-63.html
A4: CHINT NXBLE-32 resmi sayfa | B4: NXBLE-32 RCBO; 6-32A; 30mA; 1P+N/3P+N; 6kA | C4: https://chint.ru/catalog/oborudovanie_nizkogo_napryazheniya/modulnye_apparaty_differentsialnoy_zashchity/differentsialnye_avtomaticheskie_vyklyuchateli/nxble_32/
A5: CHINT NXB-125 resmi ürün sayfası | B5: NXB-125; 63-125A; 230/400V; kesme kapasitesi 20kA’a kadar | C5: https://www.chintglobal.com/global/en/products/low-voltage/iec/final-power-distribution/nxb-125.html
A6: CHINT NXM resmi ürün sayfası | B6: NXM MCCB; 63-1600A; kesme kapasitesi 70kA’a kadar | C6: https://www.chintglobal.com/global/en/products/low-voltage/iec/secondary-power-distribution/nxm.html
A7: Kontrol noktası | B7: ЩУз kumanda istasyonu adedi | C7: PDF sayfa 6 şema/tabloda 2 ile 3 adet arasında okuma riski var; satın alma öncesi proje müellifi/plan üzerinden teyit edilmeli.
A8: Kontrol noktası | B8: ЩВ1 korpus ölçüsü | C8: Projede 400x210x150 mm verilmiş; CHINT NXB-125 + shunt yerleşimi nedeniyle üretim çizimiyle kontrol edilmeli.
