Workbook
Name ALUM_KG_KZT: KURALLAR!$B$122
Name BAKIR_KG_KZT: KURALLAR!$B$121
Name BARA_BOY_M: KURALLAR!$B$93
Name BARA_DERATING: KURALLAR!$B$88
Name BARA_FIRE: KURALLAR!$B$89
Name BARA_KOPRU_M: KURALLAR!$B$92
Name BARA_N_ORANI: KURALLAR!$B$90
Name BARA_PE_ORANI: KURALLAR!$B$91
Name DINRAY_FIRE: KURALLAR!$B$97
Name DURUM_LIST: KURALLAR!$J$125:$J$134
Name FIYAT_ACK: FIYAT!$D$2:$D$34
Name FIYAT_ART: FIYAT!$R$2:$R$34
Name FIYAT_KOD: FIYAT!$C$2:$C$34
Name FIYAT_LISTE: FIYAT!$E$2:$E$34
Name FIYAT_MARKA: FIYAT!$J$2:$J$34
Name FIYAT_MODUL: FIYAT!$Q$2:$Q$34
Name FIYAT_NET: FIYAT!$F$2:$F$34
Name GARANTI: KURALLAR!$B$115
Name ISCILIK_CARPANI: KURALLAR!$B$36
Name ISCILIK_DK_UCRETI: KURALLAR!$B$35
Name ISCILIK_SAAT_UCRETI: KURALLAR!$B$34
Name ISKONTO: KURALLAR!$B$110
Name KABLO_FIRE: KURALLAR!$B$94
Name KABLO_M_MCCB: KURALLAR!$B$96
Name KABLO_M_MODULER: KURALLAR!$B$95
Name KANAL_FIRE: KURALLAR!$B$98
Name KAR_ORANI: KURALLAR!$B$109
Name KLEMENS_YEDEK: KURALLAR!$B$99
Name KORPUS_GENISLIK_TOPLAM_MM: KURALLAR!$B$104
Name KORPUS_KULLANILABILIR_ORAN: KURALLAR!$B$103
Name KORPUS_YUKSEKLIK_MM: KURALLAR!$B$105
Name KUR_AD: KURALLAR!$A$6:$A$9
Name KUR_DEG: KURALLAR!$B$6:$B$9
Name MARKA_AD: KURALLAR!$A$14:$A$29
Name MARKA_KAT: KURALLAR!$E$14:$E$29
Name MARKA_PARA: KURALLAR!$B$14:$B$29
Name MARKA_TIP: KURALLAR!$F$14:$F$29
Name MODUL_GENISLIK_MM: KURALLAR!$B$101
Name NDS_ORANI: KURALLAR!$B$111
Name NORM_AD: KURALLAR!$A$41:$A$75
Name NORM_DK: KURALLAR!$B$41:$B$75
Name ODEME_SARTI: KURALLAR!$B$114
Name SIRA_YUKSEKLIK_MM: KURALLAR!$B$102
Name TARAK_MOD_ADET: KURALLAR!$B$100
Name TEKLIF_GECERLILIK: KURALLAR!$B$112
Name TEST_ETIKET_CARPANI: KURALLAR!$B$37
Name URETIM_SURESI: KURALLAR!$B$113

Sheet KURALLAR
A1: KURALLAR — TEK GERÇEK KAYNAK
A2: 260911 MGS Mahir Bey — CCA / Almaty Costa Coffee — COSTA-LSP panosu — ABB BOM (motor v16)
A4: BLOK 1 — KUR TABLOSU
A5: PARA | B5: KZT | C5: TARIH
A6: KZT | B6: 1
A7: USD | B7: 505 | C7: 2026-08-27
A8: EUR | B8: 585 | C8: 2026-08-27
A9: TRY | B9: 13.5 | C9: 2026-08-27
A10: NOT: | B10: KUR VARSAYIM — bu oturumda güncel kur verilmedi; birlesik.csv kurulumunda kullanılan son bilinen kur taşındı. Teklif öncesi güncelleyin.
A12: BLOK 2 — MARKA KURAL TABLOSU
A13: MARKA | B13: PARA | C13: KATSAYI1 | D13: KATSAYI2 | E13: TOPLAM | F13: GIRDI_TIPI | G13: NOT
A14: ABB | B14: EUR | C14: 1.35 | D14: 0.3 | E14: =C14*D14 -> 0.405 | F14: LISTE | G14: standart (System pro M, E-serisi vb.)
A15: ABB-ACIK | B15: EUR | C15: 1.35 | D15: 0.23 | E15: =C15*D15 -> 0.3105 | F15: LISTE | G15: ayar sahalı / açık tip (Tmax XT vb.)
A16: SCHNEIDER | B16: EUR | C16: 0.6 | D16: 1 | E16: =C16*D16 -> 0.6 | F16: LISTE
A17: CHINT | B17: KZT | C17: 0.6 | D17: 1 | E17: =C17*D17 -> 0.6 | F17: LISTE
A18: CNC | B18: KZT | C18: 0.55 | D18: 1 | E18: =C18*D18 -> 0.55 | F18: LISTE | G18: liste 2025-02-04, güvenilmez
A19: LEGRAND | B19: TRY | C19: 0.5 | D19: 1 | E19: =C19*D19 -> 0.5 | F19: LISTE | G19: teyitsiz
A20: IEK | B20: KZT | C20: 1 | D20: 1 | E20: =C20*D20 -> 1 | F20: LISTE
A21: EKF | B21: KZT | C21: 1 | D21: 1 | E21: =C21*D21 -> 1 | F21: LISTE | G21: referans, fiyat yasak
A22: EKT | B22: KZT | C22: 1 | D22: 1 | E22: =C22*D22 -> 1 | F22: LISTE | G22: jenerik malzeme (klemens/kanal/aksesuar)
A23: SAIMAN | B23: KZT | C23: 1 | D23: 1 | E23: =C23*D23 -> 1 | F23: LISTE
A24: KAZTEK | B24: KZT | C24: 0.6 | D24: 1 | E24: =C24*D24 -> 0.6 | F24: LISTE | G24: korpus
A25: HARMONY | B25: KZT | C25: 1 | D25: 1 | E25: =C25*D25 -> 1 | F25: LISTE | G25: pano içi kablo — liste tarihi bilinmiyor, TEYİT ET
A26: BAKIR-BARA | B26: KZT | C26: 1 | D26: 1 | E26: =C26*D26 -> 1 | F26: NET | G26: kg fiyatından hesaplanır
A27: ALUM-BARA | B27: KZT | C27: 1 | D27: 1 | E27: =C27*D27 -> 1 | F27: NET | G27: kg fiyatından hesaplanır
A28: MUADIL-NET | B28: KZT | C28: 1 | D28: 1 | E28: =C28*D28 -> 1 | F28: NET
A29: ISCILIK | B29: KZT | C29: 1 | D29: 1 | E29: =C29*D29 -> 1 | F29: NET
A31: YENİ MARKA: tablonun sonuna satır ekle, başka yere dokunma.
A33: BLOK 3 — İŞÇİLİK NORMLARI (kalıcı, satır satır, değiştirilebilir — sarı)
A34: ISCILIK_SAAT_UCRETI (KZT/saat) | B34: 3500
A35: ISCILIK_DK_UCRETI (KZT/dk, =saat/60) | B35: =B34/60 -> 58.333333
A36: ISCILIK_CARPANI | B36: 1
A37: TEST_ETIKET_CARPANI | B37: 1.15
A38: VARSAYIM: saat ücreti ve çarpanlar örnek/öngörülen değerdir — atölye ölçümüyle güncelleyin.
A40: NORM ANAHTARI | B40: dk/birim (SARI — değiştirilebilir) | C40: AÇIKLAMA
A41: MCB_1P | B41: 10 | C41: 1P MCB/oto — adet
A42: MCB_2P | B42: 14 | C42: 2P MCB/oto — adet
A43: MCB_3P | B43: 18 | C43: 3P MCB/oto — adet
A44: MCB_4P | B44: 22 | C44: 4P MCB/oto — adet
A45: DIF_1PN | B45: 15 | C45: Dif.avt./АВДТ 1P+N — adet
...

Sheet FIYAT
A1: SIRA | B1: TIP | C1: ARTIKUL | D1: ACIKLAMA | E1: LISTE_FIYAT | F1: NET_KZT | G1: TOPLAM_ADET | H1: TOPLAM_TUTAR | I1: PARA | J1: MARKA | K1: KATSAYI | L1: BIRIM | M1: KAYNAK | N1: DURUM | O1: NOT | P1: PANO(LAR) | Q1: MODUL | R1: KOD (SISTEM ANAHTARI - DOKUNMA)
A2: 1 | B2: korpus | C2: 719-15696 | D2: Shit 2000x800x450+100mm | E2: 172785 | F2: =IF($E2="","",IF(INDEX(MARKA_TIP,MATCH($J2,MARKA_AD,0))="NET",$E2,$E2*INDEX(MARKA_KAT,MATCH($J2,MARKA_AD,0))*INDEX(KUR_DEG,MATCH($I2,KUR_AD,0)))) -> 103671 | G2: =SUMIF(BOM!$P:$P,$R2,BOM!$I:$I) -> 1 | H2: =IF($F2="","",$F2*$G2) -> 103671 | I2: =IF($E2="","",INDEX(MARKA_PARA,MATCH($J2,MARKA_AD,0))) -> KZT | J2: KAZTEK | K2: =IF($E2="","",INDEX(MARKA_KAT,MATCH($J2,MARKA_AD,0))) -> 0.6 | L2: adet | M2: Kaztek resmi liste (2607 15 Kaztek pano fiyat listesi.XLSX) ARTIKUL 719-15684 | N2: VARSAYIM | O2: 2 bölümlü pano; H=2000 toplam W=1600(2x800) D=400 — DWFX pano görünüşünden okundu | P2: =IF(COUNTIF(BOM!$P$3:$P$42,$R2)>0,"COSTA-LSP","") -> COSTA-LSP | Q2: 0 | R2: KAZTEK-719-15684
A3: 2 | B3: TMŞ | C3: 1SDA067415R1 | D3: ABB Tmax XT1N 160 TMD — 3P In=80A 36kA (ana giriş şalteri, ayar sahalı) | E3: 246.1 | F3: =IF($E3="","",IF(INDEX(MARKA_TIP,MATCH($J3,MARKA_AD,0))="NET",$E3,$E3*INDEX(MARKA_KAT,MATCH($J3,MARKA_AD,0))*INDEX(KUR_DEG,MATCH($I3,KUR_AD,0)))) -> 44702.219 | G3: =SUMIF(BOM!$P:$P,$R3,BOM!$I:$I) -> 1 | H3: =IF($F3="","",$F3*$G3) -> 44702.219 | I3: =IF($E3="","",INDEX(MARKA_PARA,MATCH($J3,MARKA_AD,0))) -> EUR | J3: ABB-ACIK | K3: =IF($E3="","",INDEX(MARKA_KAT,MATCH($J3,MARKA_AD,0))) -> 0.3105 | L3: adet | M3: 260602 ABB Elektrifikasyon Fiyat Listesi Kasım-2025 | N3: OK | O3: Şema: 3x80A ana giriş | P3: =IF(COUNTIF(BOM!$P$3:$P$42,$R3)>0,"COSTA-LSP","") -> COSTA-LSP | Q3: 3 | R3: ABB-1SDA067415R1
A4: 3 | B4: sigorta yuvası | C4: 2CSM204753R1801 | D4: ABB E93/32 — 3P sigorta yuvası 10.3x38mm | E4: 24.89 | F4: =IF($E4="","",IF(INDEX(MARKA_TIP,MATCH($J4,MARKA_AD,0))="NET",$E4,$E4*INDEX(MARKA_KAT,MATCH($J4,MARKA_AD,0))*INDEX(KUR_DEG,MATCH($I4,KUR_AD,0)))) -> 5897.0633 | G4: =SUMIF(BOM!$P:$P,$R4,BOM!$I:$I) -> 2 | H4: =IF($F4="","",$F4*$G4) -> 11794.127 | I4: =IF($E4="","",INDEX(MARKA_PARA,MATCH($J4,MARKA_AD,0))) -> EUR | J4: ABB | K4: =IF($E4="","",INDEX(MARKA_KAT,MATCH($J4,MARKA_AD,0))) -> 0.405 | L4: adet | M4: 260602 ABB Elektrifikasyon Fiyat Listesi Kasım-2025 | N4: OK | O4: Sayaç gerilim + faz gösterge devresi için 2 adet gerekir | P4: =IF(COUNTIF(BOM!$P$3:$P$42,$R4)>0,"COSTA-LSP","") -> COSTA-LSP | Q4: 3 | R4: ABB-2CSM204753R1801
A5: 4 | B5: sigorta | C5: 2CSM256363R1801 | D5: ABB E9F10 GG6 — gG 6A sigorta 10.3x38mm | E5: 3.81 | F5: =IF($E5="","",IF(INDEX(MARKA_TIP,MATCH($J5,MARKA_AD,0))="NET",$E5,$E5*INDEX(MARKA_KAT,MATCH($J5,MARKA_AD,0))*INDEX(KUR_DEG,MATCH($I5,KUR_AD,0)))) -> 902.68425 | G5: =SUMIF(BOM!$P:$P,$R5,BOM!$I:$I) -> 6 | H5: =IF($F5="","",$F5*$G5) -> 5416.1055 | I5: =IF($E5="","",INDEX(MARKA_PARA,MATCH($J5,MARKA_AD,0))) -> EUR | J5: ABB | K5: =IF($E5="","",INDEX(MARKA_KAT,MATCH($J5,MARKA_AD,0))) -> 0.405 | L5: adet | M5: 260602 ABB Elektrifikasyon Fiyat Listesi Kasım-2025 | N5: OK | O5: Şema: 3(6)A x2 grup = 6 adet | P5: =IF(COUNTIF(BOM!$P$3:$P$42,$R5)>0,"COSTA-LSP","") -> COSTA-LSP | Q5: 0 | R5: ABB-2CSM256363R1801
A6: 5 | B6: tt | C6: 270300099_ | D6: Трансформатор тока ТТИ-А 100/5А 5ВА класс 0,5 IEK | E6: 5300 | F6: =IF($E6="","",IF(INDEX(MARKA_TIP,MATCH($J6,MARKA_AD,0))="NET",$E6,$E6*INDEX(MARKA_KAT,MATCH($J6,MARKA_AD,0))*INDEX(KUR_DEG,MATCH($I6,KUR_AD,0)))) -> 5300 | G6: =SUMIF(BOM!$P:$P,$R6,BOM!$I:$I) -> 3 | H6: =IF($F6="","",$F6*$G6) -> 15900 | I6: =IF($E6="","",INDEX(MARKA_PARA,MATCH($J6,MARKA_AD,0))) -> KZT | J6: ekt | K6: =IF($E6="","",INDEX(MARKA_KAT,MATCH($J6,MARKA_AD,0))) -> 1 | L6: adet | M6: 260602 ABB Elektrifikasyon Fiyat Listesi Kasım-2026 | N6: FIYAT_YOK | O6: ABB listesinde 80/5A CT yok; en yakın ABB 1SEP408149R0001 (160/5A, EUR284.10) 80A ana şaltere göre AŞIRI BÜYÜK. CHINT/Mercury 100/5A CT önerilir. | P6: =IF(COUNTIF(BOM!$P$3:$P$42,$R6)>0,"COSTA-LSP","") -> COSTA-LSP | Q6: 0 | R6: TT-ABB-80-5-YOK
A7: 6 | B7: sayac | C7: IB | D7: ДАЛА СА4-Э720 R TX OP P П RS1 Д W (3x220/380V 5-100A) | E7: 98000 | F7: =IF($E7="","",IF(INDEX(MARKA_TIP,MATCH($J7,MARKA_AD,0))="NET",$E7,$E7*INDEX(MARKA_KAT,MATCH($J7,MARKA_AD,0))*INDEX(KUR_DEG,MATCH($I7,KUR_AD,0)))) -> 98000 | G7: =SUMIF(BOM!$P:$P,$R7,BOM!$I:$I) -> 1 | H7: =IF($F7="","",$F7*$G7) -> 98000 | I7: =IF($E7="","",INDEX(MARKA_PARA,MATCH($J7,MARKA_AD,0))) -> KZT | J7: SAIMAN | K7: =IF($E7="","",INDEX(MARKA_KAT,MATCH($J7,MARKA_AD,0))) -> 1 | L7: adet | M7: 260602 ABB Elektrifikasyon Fiyat Listesi Kasım-2025 | N7: OK | O7: Şema CT=80/5A gösteriyor; haberleşme fonksiyonu müşteri şartıyla teyit edilmeli | P7: =IF(COUNTIF(BOM!$P$3:$P$42,$R7)>0,"COSTA-LSP","") -> COSTA-LSP | Q7: 8 | R7: ABB-2CMA100178R1000
A8: 7 | B8: lamb | C8: 2CCA703402R0001 | D8: ABB E219-D — yeşil LED faz var lambası 115-250VAC, 22mm | E8: 20.81 | F8: =IF($E8="","",IF(INDEX(MARKA_TIP,MATCH($J8,MARKA_AD,0))="NET",$E8,$E8*INDEX(MARKA_KAT,MATCH($J8,MARKA_AD,0))*INDEX(KUR_DEG,MATCH($I8,KUR_AD,0)))) -> 4930.4093 | G8: =SUMIF(BOM!$P:$P,$R8,BOM!$I:$I) -> 3 | H8: =IF($F8="","",$F8*$G8) -> 14791.228 | I8: =IF($E8="","",INDEX(MARKA_PARA,MATCH($J8,MARKA_AD,0))) -> EUR | J8: ABB | K8: =IF($E8="","",INDEX(MARKA_KAT,MATCH($J8,MARKA_AD,0))) -> 0.405 | L8: adet | M8: 260602 ABB Elektrifikasyon Fiyat Listesi Kasım-2025 | N8: OK | O8: 3 faz göstergesi | P8: =IF(COUNTIF(BOM!$P$3:$P$42,$R8)>0,"COSTA-LSP","") -> COSTA-LSP | Q8: 0 | R8: ABB-2CCA703402R0001
A9: 8 | B9: sigorta yuvası | C9: 2CSM277502R1801 | D9: ABB E93/125 — 3P sigorta yuvası 22x58mm | E9: 214.7 | F9: =IF($E9="","",IF(INDEX(MARKA_TIP,MATCH($J9,MARKA_AD,0))="NET",$E9,$E9*INDEX(MARKA_KAT,MATCH($J9,MARKA_AD,0))*INDEX(KUR_DEG,MATCH($I9,KUR_AD,0)))) -> 50867.798 | G9: =SUMIF(BOM!$P:$P,$R9,BOM!$I:$I) -> 1 | H9: =IF($F9="","",$F9*$G9) -> 50867.798 | I9: =IF($E9="","",INDEX(MARKA_PARA,MATCH($J9,MARKA_AD,0))) -> EUR | J9: ABB | K9: =IF($E9="","",INDEX(MARKA_KAT,MATCH($J9,MARKA_AD,0))) -> 0.405 | L9: adet | M9: 260602 ABB Elektrifikasyon Fiyat Listesi Kasım-2025 | N9: OK | O9: SPD yedek koruması | P9: =IF(COUNTIF(BOM!$P$3:$P$42,$R9)>0,"COSTA-LSP","") -> COSTA-LSP | Q9: 6 | R9: ABB-2CSM277502R1801
A10: 9 | B10: sigorta | C10: 2CSM258343R1801 | D10: ABB E9F22 GG125 — gG 125A sigorta 22x58mm | E10: 15.62 | F10: =IF($E10="","",IF(INDEX(MARKA_TIP,MATCH($J10,MARKA_AD,0))="NET",$E10,$E10*INDEX(MARKA_KAT,MATCH($J10,MARKA_AD,0))*INDEX(KUR_DEG,MATCH($I10,KUR_AD,0)))) -> 3700.7685 | G10: =SUMIF(BOM!$P:$P,$R10,BOM!$I:$I) -> 3 | H10: =IF($F10="","",$F10*$G10) -> 11102.306 | I10: =IF($E10="","",INDEX(MARKA_PARA,MATCH($J10,MARKA_AD,0))) -> EUR | J10: ABB | K10: =IF($E10="","",INDEX(MARKA_KAT,MATCH($J10,MARKA_AD,0))) -> 0.405 | L10: adet | M10: 260602 ABB Elektrifikasyon Fiyat Listesi Kasım-2025 | N10: OK | O10: Şema: 3(125)A | P10: =IF(COUNTIF(BOM!$P$3:$P$42,$R10)>0,"COSTA-LSP","") -> COSTA-LSP | Q10: 0 | R10: ABB-2CSM258343R1801
A11: 10 | B11: opn | C11: 59A382 | D11: PROTEC T1 3+1 LH TIP1+2 | E11: 69000 | F11: =IF($E11="","",IF(INDEX(MARKA_TIP,MATCH($J11,MARKA_AD,0))="NET",$E11,$E11*INDEX(MARKA_KAT,MATCH($J11,MARKA_AD,0))*INDEX(KUR_DEG,MATCH($I11,KUR_AD,0)))) -> 69000 | G11: =SUMIF(BOM!$P:$P,$R11,BOM!$I:$I) -> 1 | H11: =IF($F11="","",$F11*$G11) -> 69000 | I11: =IF($E11="","",INDEX(MARKA_PARA,MATCH($J11,MARKA_AD,0))) -> KZT | J11: ekt | K11: =IF($E11="","",INDEX(MARKA_KAT,MATCH($J11,MARKA_AD,0))) -> 1 | L11: adet | M11: 260602 ABB Elektrifikasyon Fiyat Listesi Kasım-2025, sf.36 | N11: FIYAT_YOK | O11: Kod doğrulandı, satış fiyatı bu liste ekstresinde yok. TNS/TT 3P+N kabul edildi. | P11: =IF(COUNTIF(BOM!$P$3:$P$42,$R11)>0,"COSTA-LSP","") -> COSTA-LSP | Q11: 4 | R11: SPD-2CTB815101R4500-YOK
A12: 11 | B12: oto | C12: 2CDS253001R0164 | D12: ABB S203-C16 — 3P, C16A, 6kA | E12: 48.51 | F12: =IF($E12="","",IF(INDEX(MARKA_TIP,MATCH($J12,MARKA_AD,0))="NET",$E12,$E12*INDEX(MARKA_KAT,MATCH($J12,MARKA_AD,0))*INDEX(KUR_DEG,MATCH($I12,KUR_AD,0)))) -> 11493.232 | G12: =SUMIF(BOM!$P:$P,$R12,BOM!$I:$I) -> 2 | H12: =IF($F12="","",$F12*$G12) -> 22986.464 | I12: =IF($E12="","",INDEX(MARKA_PARA,MATCH($J12,MARKA_AD,0))) -> EUR | J12: ABB | K12: =IF($E12="","",INDEX(MARKA_KAT,MATCH($J12,MARKA_AD,0))) -> 0.405 | L12: adet | M12: 260602 ABB Elektrifikasyon Fiyat Listesi Kasım-2025 | N12: OK | O12: 1 adet aydınlatma grubu beslemesi + 1 adet 3 fazlı ekipman (kahve makinesi) devresi | P12: =IF(COUNTIF(BOM!$P$3:$P$42,$R12)>0,"COSTA-LSP","") -> COSTA-LSP | Q12: 3 | R12: ABB-2CDS253001R0164
A13: 12 | B13: oto | C13: 2CDS251001R0105 | D13: ABB S201-B10 — 1P, B10A, 6kA (aydınlatma çıkışları) | E13: 9.78 | F13: =IF($E13="","",IF(INDEX(MARKA_TIP,MATCH($J13,MARKA_AD,0))="NET",$E13,$E13*INDEX(MARKA_KAT,MATCH($J13,MARKA_AD,0))*INDEX(KUR_DEG,MATCH($I13,KUR_AD,0)))) -> 2317.1265 | G13: =SUMIF(BOM!$P:$P,$R13,BOM!$I:$I) -> 6 | H13: =IF($F13="","",$F13*$G13) -> 13902.759 | I13: =IF($E13="","",INDEX(MARKA_PARA,MATCH($J13,MARKA_AD,0))) -> EUR | J13: ABB | K13: =IF($E13="","",INDEX(MARKA_KAT,MATCH($J13,MARKA_AD,0))) -> 0.405 | L13: adet | M13: 260602 ABB Elektrifikasyon Fiyat Listesi Kasım-2025 | N13: OK | O13: Şema: B/1x10A x6 (L1-L6) | P13: =IF(COUNTIF(BOM!$P$3:$P$42,$R13)>0,"COSTA-LSP","") -> COSTA-LSP | Q13: 1 | R13: ABB-2CDS251001R0105
... A15: 14 | B15: oto | C15: 2CDS251001R0204 | D15: ABB S201-C20 — 1P, C20A, 6kA (ekipman çıkışları) | E15: 10.77 | F15: =IF($E15="","",IF(INDEX(MARKA_TIP,MATCH($J15,MARKA_AD,0))="NET",$E15,$E15*INDEX(MARKA_KAT,MATCH($J15,MARKA_AD,0))*INDEX(KUR_DEG,MATCH($I15,KUR_AD,0)))) -> 2551.6823 | G15: =SUMIF(BOM!$P:$P,$R15,BOM!$I:$I) -> 3 | H15: =IF($F15="","",$F15*$G15) -> 7655.0468 | I15: =IF($E15="","",INDEX(MARKA_PARA,MATCH($J15,MARKA_AD,0))) -> EUR | J15: ABB | K15: =IF($E15="","",INDEX(MARKA_KAT,MATCH($J15,MARKA_AD,0))) -> 0.405 | L15: adet | M15: 260602 ABB Elektrifikasyon Fiyat Listesi Kasım-2025 | N15: OK | O15: Bulaşık makinesi / filtre kahve makinesi / su ısıtıcı çıkışları | P15: =IF(COUNTIF(BOM!$P$3:$P$42,$R15)>0,"COSTA-LSP","") -> COSTA-LSP | Q15: 1 | R15: ABB-2CDS251001R0204
A16: 15 | B16: oto | C16: 2CDS251001R0254 | D16: ABB S201-C25 — 1P, C25A, 6kA (mercyhet soket çıkışları) | E16: 10.77 | F16: =IF($E16="","",IF(INDEX(MARKA_TIP,MATCH($J16,MARKA_AD,0))="NET",$E16,$E16*INDEX(MARKA_KAT,MATCH($J16,MARKA_AD,0))*INDEX(KUR_DEG,MATCH($I16,KUR_AD,0)))) -> 2551.6823 | G16: =SUMIF(BOM!$P:$P,$R16,BOM!$I:$I) -> 2 | H16: =IF($F16="","",$F16*$G16) -> 5103.3645 | I16: =IF($E16="","",INDEX(MARKA_PARA,MATCH($J16,MARKA_AD,0))) -> EUR | J16: ABB | K16: =IF($E16="","",INDEX(MARKA_KAT,MATCH($J16,MARKA_AD,0))) -> 0.405 | L16: adet | M16: 260602 ABB Elektrifikasyon Fiyat Listesi Kasım-2025 | N16: OK | P16: =IF(COUNTIF(BOM!$P$3:$P$42,$R16)>0,"COSTA-LSP","") -> COSTA-LSP | Q16: 1 | R16: ABB-2CDS251001R0254
A17: 16 | B17: oto | C17: 2CDS251001R0324 | D17: ABB S201-C32 — 1P, C32A, 6kA (UPS giriş + by-pass) | E17: 13.46 | F17: =IF($E17="","",IF(INDEX(MARKA_TIP,MATCH($J17,MARKA_AD,0))="NET",$E17,$E17*INDEX(MARKA_KAT,MATCH($J17,MARKA_AD,0))*INDEX(KUR_DEG,MATCH($I17,KUR_AD,0)))) -> 3189.0105 | G17: =SUMIF(BOM!$P:$P,$R17,BOM!$I:$I) -> 2 | H17: =IF($F17="","",$F17*$G17) -> 6378.021 | I17: =IF($E17="","",INDEX(MARKA_PARA,MATCH($J17,MARKA_AD,0))) -> EUR | J17: ABB | K17: =IF($E17="","",INDEX(MARKA_KAT,MATCH($J17,MARKA_AD,0))) -> 0.405 | L17: adet | M17: 260602 ABB Elektrifikasyon Fiyat Listesi Kasım-2025 | N17: OK | P17: =IF(COUNTIF(BOM!$P$3:$P$42,$R17)>0,"COSTA-LSP","") -> COSTA-LSP | Q17: 1 | R17: ABB-2CDS251001R0324
A18: 17 | B18: УЗО | C18: 2CSF202102R1250 | D18: ABB FH202 A-25/0.03 — 2P, 25A, 30mA, Tip A (F202 A-25/0.03 muadili) | E18: 63.22 | F18: =IF($E18="","",IF(INDEX(MARKA_TIP,MATCH($J18,MARKA_AD,0))="NET",$E18,$E18*INDEX(MARKA_KAT,MATCH($J18,MARKA_AD,0))*INDEX(KUR_DEG,MATCH($I18,KUR_AD,0)))) -> 14978.399 | G18: =SUMIF(BOM!$P:$P,$R18,BOM!$I:$I) -> 32 | H18: =IF($F18="","",$F18*$G18) -> 479308.75 | I18: =IF($E18="","",INDEX(MARKA_PARA,MATCH($J18,MARKA_AD,0))) -> EUR | J18: ABB | K18: =IF($E18="","",INDEX(MARKA_KAT,MATCH($J18,MARKA_AD,0))) -> 0.405 | L18: adet | M18: 260602 ABB Elektrifikasyon Fiyat Listesi Kasım-2025 | N18: MUADIL_ONAY | O18: İstenen 2CSF202101R1250 listede yok; FH gövde serisi aynı marka/anma değer/koruma tipi ama farklı kutu ölçüsü — MÜHENDİS ONAYI GEREKLİ | P18: =IF(COUNTIF(BOM!$P$3:$P$42,$R18)>0,"COSTA-LSP","") -> COSTA-LSP | Q18: 2 | R18: ABB-FH202A25-MUADIL
A19: 18 | B19: УЗО | C19: 2CSF204102R1250 | D19: ABB FH204 A-25/0.03 — 4P, 25A, 30mA, Tip A (F204 A-25/0.03 muadili) | E19: 82.14 | F19: =IF($E19="","",IF(INDEX(MARKA_TIP,MATCH($J19,MARKA_AD,0))="NET",$E19,$E19*INDEX(MARKA_KAT,MATCH($J19,MARKA_AD,0))*INDEX(KUR_DEG,MATCH($I19,KUR_AD,0)))) -> 19461.019 | G19: =SUMIF(BOM!$P:$P,$R19,BOM!$I:$I) -> 2 | H19: =IF($F19="","",$F19*$G19) -> 38922.039 | I19: =IF($E19="","",INDEX(MARKA_PARA,MATCH($J19,MARKA_AD,0))) -> EUR | J19: ABB | K19: =IF($E19="","",INDEX(MARKA_KAT,MATCH($J19,MARKA_AD,0))) -> 0.405 | L19: adet | M19: 260602 ABB Elektrifikasyon Fiyat Listesi Kasım-2025 | N19: MUADIL_ONAY | O19: İstenen 2CSF204101R1250 listede yok; FH gövde serisi — MÜHENDİS ONAYI GEREKLİ | P19: =IF(COUNTIF(BOM!$P$3:$P$42,$R19)>0,"COSTA-LSP","") -> COSTA-LSP | Q19: 4 | R19: ABB-FH204A25-MUADIL
A20: 19 | B20: selector | C20: 1SFA619200R1016 | D20: ABB C2SS1-10B-10 — 2 konum sabit seçici, siyah, 1NA, 22mm | E20: 9.02 | F20: =IF($E20="","",IF(INDEX(MARKA_TIP,MATCH($J20,MARKA_AD,0))="NET",$E20,$E20*INDEX(MARKA_KAT,MATCH($J20,MARKA_AD,0))*INDEX(KUR_DEG,MATCH($I20,KUR_AD,0)))) -> 2137.0635 | G20: =SUMIF(BOM!$P:$P,$R20,BOM!$I:$I) -> 4 | H20: =IF($F20="","",$F20*$G20) -> 8548.254 | I20: =IF($E20="","",INDEX(MARKA_PARA,MATCH($J20,MARKA_AD,0))) -> EUR | J20: ABB | K20: =IF($E20="","",INDEX(MARKA_KAT,MATCH($J20,MARKA_AD,0))) -> 0.405 | L20: adet | M20: 260602 ABB Elektrifikasyon Fiyat Listesi Kasım-2025 | N20: OK | O20: Kapı üzeri aydınlatma grubu kumandası x4 | P20: =IF(COUNTIF(BOM!$P$3:$P$42,$R20)>0,"COSTA-LSP","") -> COSTA-LSP | Q20: 0 | R20: ABB-1SFA619200R1016
A21: 20 | B21: UPS | D21: UPS 5 kVA, 1F/1F, 220V (harici ekipman) | F21: =IF($E21="","",IF(INDEX(MARKA_TIP,MATCH($J21,MARKA_AD,0))="NET",$E21,$E21*INDEX(MARKA_KAT,MATCH($J21,MARKA_AD,0))*INDEX(KUR_DEG,MATCH($I21,KUR_AD,0)))) | G21: =SUMIF(BOM!$P:$P,$R21,BOM!$I:$I) -> 1 | H21: =IF($F21="","",$F21*$G21) | I21: =IF($E21="","",INDEX(MARKA_PARA,MATCH($J21,MARKA_AD,0))) | J21: MUADIL-NET | K21: =IF($E21="","",INDEX(MARKA_KAT,MATCH($J21,MARKA_AD,0))) | L21: adet | M21: — | N21: KAPSAM_DISI | O21: Şemada gösterilmiş, marka/model verilmemiş; müşteri/ayrı tedarik, pano fiyatına dahil edilmedi | P21: =IF(COUNTIF(BOM!$P$3:$P$42,$R21)>0,"COSTA-LSP","") -> COSTA-LSP | Q21: 0 | R21: UPS-5KVA-HARIC
A22: 21 | B22: DIN | C22: 570003 | D22: DIN rayı TS35x7.5mm delikli (1m) | E22: 869 | F22: =IF($E22="","",IF(INDEX(MARKA_TIP,MATCH($J22,MARKA_AD,0))="NET",$E22,$E22*INDEX(MARKA_KAT,MATCH($J22,MARKA_AD,0))*INDEX(KUR_DEG,MATCH($I22,KUR_AD,0)))) -> 521.4 | G22: =SUMIF(BOM!$P:$P,$R22,BOM!$I:$I) -> 2.87 | H22: =IF($F22="","",$F22*$G22) -> 1496.418 | I22: =IF($E22="","",INDEX(MARKA_PARA,MATCH($J22,MARKA_AD,0))) -> KZT | J22: CHINT | K22: =IF($E22="","",INDEX(MARKA_KAT,MATCH($J22,MARKA_AD,0))) -> 0.6 | L22: m | M22: 260827_chint_price.xlsx | N22: OK | P22: =IF(COUNTIF(BOM!$P$3:$P$42,$R22)>0,"COSTA-LSP","") -> COSTA-LSP | Q22: 0 | R22: CHINT-570003
A23: 22 | B23: кабельный канал | C23: 270300200_ | D23: Кабель-канал перф. 60х40 ИМПАКТ IEK (24) | E23: 1980 | F23: =IF($E23="","",IF(INDEX(MARKA_TIP,MATCH($J23,MARKA_AD,0))="NET",$E23,$E23*INDEX(MARKA_KAT,MATCH($J23,MARKA_AD,0))*INDEX(KUR_DEG,MATCH($I23,KUR_AD,0)))) -> 1980 | G23: =SUMIF(BOM!$P:$P,$R23,BOM!$I:$I) -> 16 | H23: =IF($F23="","",$F23*$G23) -> 31680 | I23: =IF($E23="","",INDEX(MARKA_PARA,MATCH($J23,MARKA_AD,0))) -> KZT | J23: EKT | K23: =IF($E23="","",INDEX(MARKA_KAT,MATCH($J23,MARKA_AD,0))) -> 1 | L23: m | M23: birlesik.csv (EKT 250612) | N23: OK | P23: =IF(COUNTIF(BOM!$P$3:$P$42,$R23)>0,"COSTA-LSP","") -> COSTA-LSP | Q23: 0 | R23: EKT-280100335
A24: 23 | B24: klemens | C24: 32421DEK | D24: Geçiş klemensi 2.5-4mm² (ЗН101-2-24A-08) | E24: 117 | F24: =IF($E24="","",IF(INDEX(MARKA_TIP,MATCH($J24,MARKA_AD,0))="NET",$E24,$E24*INDEX(MARKA_KAT,MATCH($J24,MARKA_AD,0))*INDEX(KUR_DEG,MATCH($I24,KUR_AD,0)))) -> 117 | G24: =SUMIF(BOM!$P:$P,$R24,BOM!$I:$I) -> 188 | H24: =IF($F24="","",$F24*$G24) -> 21996 | I24: =IF($E24="","",INDEX(MARKA_PARA,MATCH($J24,MARKA_AD,0))) -> KZT | J24: EKT | K24: =IF($E24="","",INDEX(MARKA_KAT,MATCH($J24,MARKA_AD,0))) -> 1 | L24: adet | M24: birlesik.csv (EKT 250612) | N24: OK | O24: Faz/N/PE hepsi için aynı gövde — renk kodu montajda ayrılır | P24: =IF(COUNTIF(BOM!$P$3:$P$42,$R24)>0,"COSTA-LSP","") -> COSTA-LSP | Q24: 0 | R24: EKT-32421DEK
A25: 24 | B25: klemens aksesuar | C25: YZN11DF-003-K03 | D25: DIN ray uç plakası + stoper seti | E25: 106 | F25: =IF($E25="","",IF(INDEX(MARKA_TIP,MATCH($J25,MARKA_AD,0))="NET",$E25,$E25*INDEX(MARKA_KAT,MATCH($J25,MARKA_AD,0))*INDEX(KUR_DEG,MATCH($I25,KUR_AD,0)))) -> 106 | G25: =SUMIF(BOM!$P:$P,$R25,BOM!$I:$I) -> 10 | H25: =IF($F25="","",$F25*$G25) -> 1060 | I25: =IF($E25="","",INDEX(MARKA_PARA,MATCH($J25,MARKA_AD,0))) -> KZT | J25: EKT | K25: =IF($E25="","",INDEX(MARKA_KAT,MATCH($J25,MARKA_AD,0))) -> 1 | L25: adet | M25: birlesik.csv (EKT 250612) | N25: OK | P25: =IF(COUNTIF(BOM!$P$3:$P$42,$R25)>0,"COSTA-LSP","") -> COSTA-LSP | Q25: 0 | R25: EKT-YZN11DF-003-K03
A26: 25 | B26: iç kablo | C26: PV1(LS)-2.5 | D26: H07V-K / ПВ1(LS) Cu 1x2.5mm² — pano içi kablo | E26: 176 | F26: =IF($E26="","",IF(INDEX(MARKA_TIP,MATCH($J26,MARKA_AD,0))="NET",$E26,$E26*INDEX(MARKA_KAT,MATCH($J26,MARKA_AD,0))*INDEX(KUR_DEG,MATCH($I26,KUR_AD,0)))) -> 176 | G26: =SUMIF(BOM!$P:$P,$R26,BOM!$I:$I) -> 110.9 | H26: =IF($F26="","",$F26*$G26) -> 19518.4 | I26: =IF($E26="","",INDEX(MARKA_PARA,MATCH($J26,MARKA_AD,0))) -> KZT | J26: HARMONY | K26: =IF($E26="","",INDEX(MARKA_KAT,MATCH($J26,MARKA_AD,0))) -> 1 | L26: m | M26: Harmony_Кабель_Прайс_лист.pdf | N26: OK | O26: Liste tarihi bilinmiyor — TEYİT ET | P26: =IF(COUNTIF(BOM!$P$3:$P$42,$R26)>0,"COSTA-LSP","") -> COSTA-LSP | Q26: 0 | R26: HARMONY-PV1LS025
A27: 26 | B27: iç kablo | C27: PV1(LS)-6 | D27: H07V-K / ПВ1(LS) Cu 1x6mm² — pano içi kablo (C32 devreleri) | E27: 423 | F27: =IF($E27="","",IF(INDEX(MARKA_TIP,MATCH($J27,MARKA_AD,0))="NET",$E27,$E27*INDEX(MARKA_KAT,MATCH($J27,MARKA_AD,0))*INDEX(KUR_DEG,MATCH($I27,KUR_AD,0)))) -> 423 | G27: =SUMIF(BOM!$P:$P,$R27,BOM!$I:$I) -> 5.3 | H27: =IF($F27="","",$F27*$G27) -> 2241.9 | I27: =IF($E27="","",INDEX(MARKA_PARA,MATCH($J27,MARKA_AD,0))) -> KZT | J27: HARMONY | K27: =IF($E27="","",INDEX(MARKA_KAT,MATCH($J27,MARKA_AD,0))) -> 1 | L27: m | M27: Harmony_Кабель_Прайс_лист.pdf | N27: OK | O27: Liste tarihi bilinmiyor — TEYİT ET | P27: =IF(COUNTIF(BOM!$P$3:$P$42,$R27)>0,"COSTA-LSP","") -> COSTA-LSP | Q27: 0 | R27: HARMONY-PV1LS06
A28: 27 | B28: iç kablo | C28: PV2(LS)-25 | D28: H07V-K / ПВ2(LS) Cu 1x25mm² — kablo köprü (ana giriş bağlantısı) | E28: 1765 | F28: =IF($E28="","",IF(INDEX(MARKA_TIP,MATCH($J28,MARKA_AD,0))="NET",$E28,$E28*INDEX(MARKA_KAT,MATCH($J28,MARKA_AD,0))*INDEX(KUR_DEG,MATCH($I28,KUR_AD,0)))) -> 1765 | G28: =SUMIF(BOM!$P:$P,$R28,BOM!$I:$I) -> 1.65 | H28: =IF($F28="","",$F28*$G28) -> 2912.25 | I28: =IF($E28="","",INDEX(MARKA_PARA,MATCH($J28,MARKA_AD,0))) -> KZT | J28: HARMONY | K28: =IF($E28="","",INDEX(MARKA_KAT,MATCH($J28,MARKA_AD,0))) -> 1 | L28: m | M28: Harmony_Кабель_Прайс_лист.pdf | N28: OK | O28: ≤125A ana şalter — bara yerine kablo köprü (proje kuralı) | P28: =IF(COUNTIF(BOM!$P$3:$P$42,$R28)>0,"COSTA-LSP","") -> COSTA-LSP | Q28: 0 | R28: HARMONY-PV2LS25
A29: 28 | B29: pabuc | C29: 260100142 | D29: Kablo pabucu 16mm² (МЛ 16-6-6) | E29: 180 | F29: =IF($E29="","",IF(INDEX(MARKA_TIP,MATCH($J29,MARKA_AD,0))="NET",$E29,$E29*INDEX(MARKA_KAT,MATCH($J29,MARKA_AD,0))*INDEX(KUR_DEG,MATCH($I29,KUR_AD,0)))) -> 180 | G29: =SUMIF(BOM!$P:$P,$R29,BOM!$I:$I) -> 8 | H29: =IF($F29="","",$F29*$G29) -> 1440 | I29: =IF($E29="","",INDEX(MARKA_PARA,MATCH($J29,MARKA_AD,0))) -> KZT | J29: EKT | K29: =IF($E29="","",INDEX(MARKA_KAT,MATCH($J29,MARKA_AD,0))) -> 1 | L29: adet | M29: birlesik.csv (EKT 250612) | N29: OK | O29: Ana giriş kablo köprü uçları | P29: =IF(COUNTIF(BOM!$P$3:$P$42,$R29)>0,"COSTA-LSP","") -> COSTA-LSP | Q29: 0 | R29: EKT-260100142
A30: 29 | B30: etiket | C30: 311100733 | D30: Etiket seti — metal marka bandı (100 adet/paket) | E30: 6910 | F30: =IF($E30="","",IF(INDEX(MARKA_TIP,MATCH($J30,MARKA_AD,0))="NET",$E30,$E30*INDEX(MARKA_KAT,MATCH($J30,MARKA_AD,0))*INDEX(KUR_DEG,MATCH($I30,KUR_AD,0)))) -> 6910 | G30: =SUMIF(BOM!$P:$P,$R30,BOM!$I:$I) -> 1 | H30: =IF($F30="","",$F30*$G30) -> 6910 | I30: =IF($E30="","",INDEX(MARKA_PARA,MATCH($J30,MARKA_AD,0))) -> KZT | J30: EKT | K30: =IF($E30="","",INDEX(MARKA_KAT,MATCH($J30,MARKA_AD,0))) -> 1 | L30: набор | M30: birlesik.csv (EKT 250612) | N30: OK | P30: =IF(COUNTIF(BOM!$P$3:$P$42,$R30)>0,"COSTA-LSP","") -> COSTA-LSP | Q30: 0 | R30: EKT-311100733-ETIKET
A31: 30 | B31: toroid | C31: 635-03004 | D31: Трансформатор тока нулевой последовательности CT-80 (TEKLED ELECTRIC) | E31: 12950 | F31: =IF($E31="","",IF(INDEX(MARKA_TIP,MATCH($J31,MARKA_AD,0))="NET",$E31,$E31*INDEX(MARKA_KAT,MATCH($J31,MARKA_AD,0))*INDEX(KUR_DEG,MATCH($I31,KUR_AD,0)))) -> 7770 | G31: =SUMIF(BOM!$P:$P,$R31,BOM!$I:$I) -> 1 | H31: =IF($F31="","",$F31*$G31) -> 7770 | I31: =IF($E31="","",INDEX(MARKA_PARA,MATCH($J31,MARKA_AD,0))) -> KZT | J31: CHINT | K31: =IF($E31="","",INDEX(MARKA_KAT,MATCH($J31,MARKA_AD,0))) -> 0.6 | L31: adet | M31: — | N31: FIYAT_YOK | O31: KAZTEK/EKT kataloğunda özel kod bulunamadı, saha tedarikçisinden fiyat alınmalı | P31: =IF(COUNTIF(BOM!$P$3:$P$42,$R31)>0,"COSTA-LSP","") -> COSTA-LSP | Q31: 0 | R31: TERM-N-BARA
A32: 31 | B32: PE bara | C32: 720-03100 | D32: Реле тока утечки ELR 110V/240V (TEKLED ELECTRIC) | E32: 25900 | F32: =IF($E32="","",IF(INDEX(MARKA_TIP,MATCH($J32,MARKA_AD,0))="NET",$E32,$E32*INDEX(MARKA_KAT,MATCH($J32,MARKA_AD,0))*INDEX(KUR_DEG,MATCH($I32,KUR_AD,0)))) -> 15540 | G32: =SUMIF(BOM!$P:$P,$R32,BOM!$I:$I) -> 1 | H32: =IF($F32="","",$F32*$G32) -> 15540 | I32: =IF($E32="","",INDEX(MARKA_PARA,MATCH($J32,MARKA_AD,0))) -> KZT | J32: CHINT | K32: =IF($E32="","",INDEX(MARKA_KAT,MATCH($J32,MARKA_AD,0))) -> 0.6 | L32: adet | M32: — | N32: FIYAT_YOK | O32: KAZTEK/EKT kataloğunda özel kod bulunamadı, saha tedarikçisinden fiyat alınmalı | P32: =IF(COUNTIF(BOM!$P$3:$P$42,$R32)>0,"COSTA-LSP","") -> COSTA-LSP | Q32: 0 | R32: TERM-PE-BARA
A33: 32 | B33: монтажный материал | D33: Montaj sarf malzemesi (vida, kablo bağı, spiral, destek, dübel-homut) | F33: =IF($E33="","",IF(INDEX(MARKA_TIP,MATCH($J33,MARKA_AD,0))="NET",$E33,$E33*INDEX(MARKA_KAT,MATCH($J33,MARKA_AD,0))*INDEX(KUR_DEG,MATCH($I33,KUR_AD,0)))) | G33: =SUMIF(BOM!$P:$P,$R33,BOM!$I:$I) -> 1 | H33: =IF($F33="","",$F33*$G33) | I33: =IF($E33="","",INDEX(MARKA_PARA,MATCH($J33,MARKA_AD,0))) | J33: MUADIL-NET | K33: =IF($E33="","",INDEX(MARKA_KAT,MATCH($J33,MARKA_AD,0))) | L33: набор | M33: — | N33: FIYAT_YOK | O33: Granüler kalemler mevcut (ör. EKT 240100089 dübel-homut) ama toplu set fiyatı saha teklifine göre girilmeli | P33: =IF(COUNTIF(BOM!$P$3:$P$42,$R33)>0,"COSTA-LSP","") -> COSTA-LSP | Q33: 0 | R33: MONTAJ-MALZEME
A34: 33 | B34: Iscilik | D34: Montaj/kablaj/etiketleme/test işçiliği (dakika bazlı) | E34: =KURALLAR!$B$35 -> 58.333333 | F34: =IF($E34="","",IF(INDEX(MARKA_TIP,MATCH($J34,MARKA_AD,0))="NET",$E34,$E34*INDEX(MARKA_KAT,MATCH($J34,MARKA_AD,0))*INDEX(KUR_DEG,MATCH($I34,KUR_AD,0)))) -> 58.333333 | G34: =SUMIF(BOM!$P:$P,$R34,BOM!$I:$I) -> 2640.6 | H34: =IF($F34="","",$F34*$G34) -> 154035 | I34: =IF($E34="","",INDEX(MARKA_PARA,MATCH($J34,MARKA_AD,0))) -> KZT | J34: ISCILIK | K34: =IF($E34="","",INDEX(MARKA_KAT,MATCH($J34,MARKA_AD,0))) -> 1 | L34: dk | M34: KURALLAR BLOK3 | N34: OK | O34: Dakika ücreti KURALLAR BLOK3'ten okunur; toplam dakika BOM işçilik satırından SUMIF ile gelir | P34: =IF(COUNTIF(BOM!$P$3:$P$42,$R34)>0,"COSTA-LSP","") | Q34: 0 | R34: ISCILIK-DK

Sheet BOM
A1: ROW | B1: Наименование1 | C1: Тип | D1: Артикул | E1: Номенклатура | F1: Цена | G1: net | H1: H(G×I) | I1: Qty | J1: Ед.изм | K1: Завод | L1: tutar | M1: DURUM | N1: NOT | O1: KAYNAK | P1: ANAHTAR (sistem - dokunma) | Q1: NORM_ANAHTAR (sistem) | R1: ISCILIK_DK (satır, hesap) | S1: MODUL (hesap)
A2: 1 | B2: COSTA-LSP | E2: COSTA-LSP | I2: 1 | J2: компл. | M2: OK | N2: COSTA-LSP — Lighting distribution board + UPS dağıtım bölümü (aynı korpus içinde); ABB şaltlı; 3F+N+PE, 400/230V; In=80A; sayaç+SPD+aydınlatma/priz/UPS çıkışları. Kaynak: 10 E D 01 CCA PANEL SINGLE LINE DIAGRAM.dwfx (Drawing No: E D 01, 07.07.2026, Domestic-Ground Floor, SISTEMA). | O2: DWFX şema + devre cetveli
A3: 2 | B3: =E3 -> Shit 2000x800x450+100mm | C3: korpus | D3: =IF($P3="","",INDEX(FIYAT_KOD,MATCH($P3,FIYAT_ART,0))) -> 719-15696 | E3: =IF($P3="","",INDEX(FIYAT_ACK,MATCH($P3,FIYAT_ART,0))) -> Shit 2000x800x450+100mm | F3: =IF($P3="","",INDEX(FIYAT_LISTE,MATCH($P3,FIYAT_ART,0))) -> 172785 | G3: =IF($P3="","",INDEX(FIYAT_NET,MATCH($P3,FIYAT_ART,0))) -> 103671 | H3: =IF(OR($G3="",$I3=""),"",$G3*$I3) -> 103671 | I3: 1 | J3: шт | K3: =IF($P3="","",INDEX(FIYAT_MARKA,MATCH($P3,FIYAT_ART,0))) -> KAZTEK | L3: =IF($H3="","",$H3) -> 103671 | M3: VARSAYIM | N3: Korpus 2 bölüm x (2000x800x400mm+10cm baza) IP31 — DWFX pano görünüşünden H=2000, toplam W=1600(2x800), D=400 okundu; KAZTEK kataloğunda tam ölçü eşleşmesi bulunamadı, en yakın 719-15684 (2000x800x400) x2 seçildi. | O3: DWFX pano görünüşü + KAZTEK katalog | P3: KAZTEK-719-15684 | Q3: KORPUS_AYAKLI | R3: =IF(OR($Q3="",$I3=""),"",$I3*IFERROR(INDEX(NORM_DK,MATCH($Q3,NORM_AD,0)),0)) -> 90 | S3: =IF($P3="",0,$I3*IFERROR(INDEX(FIYAT_MODUL,MATCH($P3,FIYAT_ART,0)),0)) -> 0
A4: 3 | B4: =E4 -> ABB Tmax XT1N 160 TMD — 3P In=80A 36kA (ana giriş şalteri, ayar sahalı) | C4: TMŞ | D4: =IF($P4="","",INDEX(FIYAT_KOD,MATCH($P4,FIYAT_ART,0))) -> 1SDA067415R1 | E4: =IF($P4="","",INDEX(FIYAT_ACK,MATCH($P4,FIYAT_ART,0))) -> ABB Tmax XT1N 160 TMD — 3P In=80A 36kA (ana giriş şalteri, ayar sahalı) | F4: =IF($P4="","",INDEX(FIYAT_LISTE,MATCH($P4,FIYAT_ART,0))) -> 246.1 | G4: =IF($P4="","",INDEX(FIYAT_NET,MATCH($P4,FIYAT_ART,0))) -> 44702.219 | H4: =IF(OR($G4="",$I4=""),"",$G4*$I4) -> 44702.219 | I4: 1 | J4: шт | K4: =IF($P4="","",INDEX(FIYAT_MARKA,MATCH($P4,FIYAT_ART,0))) -> ABB-ACIK | L4: =IF($H4="","",$H4) -> 44702.219 | M4: OK | N4: Şema: 3x80A ana giriş şalteri. | O4: DWFX şema | P4: ABB-1SDA067415R1 | Q4: MCCB_ANA | R4: =IF(OR($Q4="",$I4=""),"",$I4*IFERROR(INDEX(NORM_DK,MATCH($Q4,NORM_AD,0)),0)) -> 90 | S4: =IF($P4="",0,$I4*IFERROR(INDEX(FIYAT_MODUL,MATCH($P4,FIYAT_ART,0)),0)) -> 3
A5: 4 | B5: =E5 -> ABB E93/32 — 3P sigorta yuvası 10.3x38mm | C5: sigorta yuvası | D5: =IF($P5="","",INDEX(FIYAT_KOD,MATCH($P5,FIYAT_ART,0))) -> 2CSM204753R1801 | E5: =IF($P5="","",INDEX(FIYAT_ACK,MATCH($P5,FIYAT_ART,0))) -> ABB E93/32 — 3P sigorta yuvası 10.3x38mm | F5: =IF($P5="","",INDEX(FIYAT_LISTE,MATCH($P5,FIYAT_ART,0))) -> 24.89 | G5: =IF($P5="","",INDEX(FIYAT_NET,MATCH($P5,FIYAT_ART,0))) -> 5897.0633 | H5: =IF(OR($G5="",$I5=""),"",$G5*$I5) -> 5897.0633 | I5: 1 | J5: шт | K5: =IF($P5="","",INDEX(FIYAT_MARKA,MATCH($P5,FIYAT_ART,0))) -> ABB | L5: =IF($H5="","",$H5) -> 5897.0633 | M5: OK | N5: Sayaç gerilim ölçü devresi 3(6)A koruması. | O5: DWFX şema | P5: ABB-2CSM204753R1801 | Q5: SIGORTA_YUVASI | R5: =IF(OR($Q5="",$I5=""),"",$I5*IFERROR(INDEX(NORM_DK,MATCH($Q5,NORM_AD,0)),0)) -> 20 | S5: =IF($P5="",0,$I5*IFERROR(INDEX(FIYAT_MODUL,MATCH($P5,FIYAT_ART,0)),0)) -> 3
A6: 5 | B6: =E6 -> ABB E9F10 GG6 — gG 6A sigorta 10.3x38mm | C6: sigorta | D6: =IF($P6="","",INDEX(FIYAT_KOD,MATCH($P6,FIYAT_ART,0))) -> 2CSM256363R1801 | E6: =IF($P6="","",INDEX(FIYAT_ACK,MATCH($P6,FIYAT_ART,0))) -> ABB E9F10 GG6 — gG 6A sigorta 10.3x38mm | F6: =IF($P6="","",INDEX(FIYAT_LISTE,MATCH($P6,FIYAT_ART,0))) -> 3.81 | G6: =IF($P6="","",INDEX(FIYAT_NET,MATCH($P6,FIYAT_ART,0))) -> 902.68425 | H6: =IF(OR($G6="",$I6=""),"",$G6*$I6) -> 2708.0527 | I6: 3 | J6: шт | K6: =IF($P6="","",INDEX(FIYAT_MARKA,MATCH($P6,FIYAT_ART,0))) -> ABB | L6: =IF($H6="","",$H6) -> 2708.0527 | M6: OK | N6: 3 faz gerilim ölçü sigortası. | O6: DWFX şema | P6: ABB-2CSM256363R1801 | S6: =IF($P6="",0,$I6*IFERROR(INDEX(FIYAT_MODUL,MATCH($P6,FIYAT_ART,0)),0)) -> 0
A7: 6 | B7: =E7 -> ABB E93/32 — 3P sigorta yuvası 10.3x38mm | C7: sigorta yuvası | D7: =IF($P7="","",INDEX(FIYAT_KOD,MATCH($P7,FIYAT_ART,0))) -> 2CSM204753R1801 | E7: =IF($P7="","",INDEX(FIYAT_ACK,MATCH($P7,FIYAT_ART,0))) -> ABB E93/32 — 3P sigorta yuvası 10.3x38mm | F7: =IF($P7="","",INDEX(FIYAT_LISTE,MATCH($P7,FIYAT_ART,0))) -> 24.89 | G7: =IF($P7="","",INDEX(FIYAT_NET,MATCH($P7,FIYAT_ART,0))) -> 5897.0633 | H7: =IF(OR($G7="",$I7=""),"",$G7*$I7) -> 5897.0633 | I7: 1 | J7: шт | K7: =IF($P7="","",INDEX(FIYAT_MARKA,MATCH($P7,FIYAT_ART,0))) -> ABB | L7: =IF($H7="","",$H7) -> 5897.0633 | M7: OK | N7: Faz gösterge lambası devresi 3(6)A koruması. | O7: DWFX şema | P7: ABB-2CSM204753R1801 | Q7: SIGORTA_YUVASI | R7: =IF(OR($Q7="",$I7=""),"",$I7*IFERROR(INDEX(NORM_DK,MATCH($Q7,NORM_AD,0)),0)) -> 20 | S7: =IF($P7="",0,$I7*IFERROR(INDEX(FIYAT_MODUL,MATCH($P7,FIYAT_ART,0)),0)) -> 3
A8: 7 | B8: =E8 -> ABB E9F10 GG6 — gG 6A sigorta 10.3x38mm | C8: sigorta | D8: =IF($P8="","",INDEX(FIYAT_KOD,MATCH($P8,FIYAT_ART,0))) -> 2CSM256363R1801 | E8: =IF($P8="","",INDEX(FIYAT_ACK,MATCH($P8,FIYAT_ART,0))) -> ABB E9F10 GG6 — gG 6A sigorta 10.3x38mm | F8: =IF($P8="","",INDEX(FIYAT_LISTE,MATCH($P8,FIYAT_ART,0))) -> 3.81 | G8: =IF($P8="","",INDEX(FIYAT_NET,MATCH($P8,FIYAT_ART,0))) -> 902.68425 | H8: =IF(OR($G8="",$I8=""),"",$G8*$I8) -> 2708.0527 | I8: 3 | J8: шт | K8: =IF($P8="","",INDEX(FIYAT_MARKA,MATCH($P8,FIYAT_ART,0))) -> ABB | L8: =IF($H8="","",$H8) -> 2708.0527 | M8: OK | N8: 3 faz gösterge sigortası. | O8: DWFX şema | P8: ABB-2CSM256363R1801 | S8: =IF($P8="",0,$I8*IFERROR(INDEX(FIYAT_MODUL,MATCH($P8,FIYAT_ART,0)),0)) -> 0
A9: 8 | B9: =E9 -> Трансформатор тока ТТИ-А 100/5А 5ВА класс 0,5 IEK | C9: tt | D9: =IF($P9="","",INDEX(FIYAT_KOD,MATCH($P9,FIYAT_ART,0))) -> 270300099_ | E9: =IF($P9="","",INDEX(FIYAT_ACK,MATCH($P9,FIYAT_ART,0))) -> Трансформатор тока ТТИ-А 100/5А 5ВА класс 0,5 IEK | F9: =IF($P9="","",INDEX(FIYAT_LISTE,MATCH($P9,FIYAT_ART,0))) -> 5300 | G9: =IF($P9="","",INDEX(FIYAT_NET,MATCH($P9,FIYAT_ART,0))) -> 5300 | H9: =IF(OR($G9="",$I9=""),"",$G9*$I9) -> 15900 | I9: 3 | J9: шт | K9: =IF($P9="","",INDEX(FIYAT_MARKA,MATCH($P9,FIYAT_ART,0))) -> ekt | L9: =IF($H9="","",$H9) -> 15900 | M9: FIYAT_YOK | N9: Sayaç ölçü akım trafosu, şema: 80/5A x3 faz. ABB'de bu ölçüde ürün yok — bkz. FIYAT notu. | O9: DWFX şema | P9: TT-ABB-80-5-YOK | S9: =IF($P9="",0,$I9*IFERROR(INDEX(FIYAT_MODUL,MATCH($P9,FIYAT_ART,0)),0)) -> 0
A10: 9 | B10: =E10 -> ДАЛА СА4-Э720 R TX OP P П RS1 Д W (3x220/380V 5-100A) | C10: sayac | D10: IB | E10: ДАЛА СА4-Э720 R TX OP P П RS1 Д W (3x220/380V 5-100A) | F10: =IF($P10="","",INDEX(FIYAT_LISTE,MATCH($P10,FIYAT_ART,0))) -> 98000 | G10: =IF($P10="","",INDEX(FIYAT_NET,MATCH($P10,FIYAT_ART,0))) -> 98000 | H10: =IF(OR($G10="",$I10=""),"",$G10*$I10) -> 98000 | I10: 1 | J10: шт | K10: =IF($P10="","",INDEX(FIYAT_MARKA,MATCH($P10,FIYAT_ART,0))) -> SAIMAN | L10: =IF($H10="","",$H10) -> 98000 | M10: OK | N10: 3 faz CT bağlı enerji sayacı, PLC | O10: DWFX şema | P10: ABB-2CMA100178R1000 | Q10: SAYAC_AT | R10: =IF(OR($Q10="",$I10=""),"",$I10*IFERROR(INDEX(NORM_DK,MATCH($Q10,NORM_AD,0)),0)) -> 90 | S10: =IF($P10="",0,$I10*IFERROR(INDEX(FIYAT_MODUL,MATCH($P10,FIYAT_ART,0)),0)) -> 8
A11: 10 | B11: =E11 -> ABB E219-D — yeşil LED faz var lambası 115-250VAC, 22mm | C11: sinyal lambası | D11: =IF($P11="","",INDEX(FIYAT_KOD,MATCH($P11,FIYAT_ART,0))) -> 2CCA703402R0001 | E11: =IF($P11="","",INDEX(FIYAT_ACK,MATCH($P11,FIYAT_ART,0))) -> ABB E219-D — yeşil LED faz var lambası 115-250VAC, 22mm | F11: =IF($P11="","",INDEX(FIYAT_LISTE,MATCH($P11,FIYAT_ART,0))) -> 20.81 | G11: =IF($P11="","",INDEX(FIYAT_NET,MATCH($P11,FIYAT_ART,0))) -> 4930.4093 | H11: =IF(OR($G11="",$I11=""),"",$G11*$I11) -> 14791.228 | I11: 3 | J11: шт | K11: =IF($P11="","",INDEX(FIYAT_MARKA,MATCH($P11,FIYAT_ART,0))) -> ABB | L11: =IF($H11="","",$H11) -> 14791.228 | M11: OK | N11: 3 faz var göstergesi. | O11: DWFX şema | P11: ABB-2CCA703402R0001 | Q11: LAMBA_BUTON | R11: =IF(OR($Q11="",$I11=""),"",$I11*IFERROR(INDEX(NORM_DK,MATCH($Q11,NORM_AD,0)),0)) -> 24 | S11: =IF($P11="",0,$I11*IFERROR(INDEX(FIYAT_MODUL,MATCH($P11,FIYAT_ART,0)),0)) -> 0
A12: 11 | B12: =E12 -> ABB E93/125 — 3P sigorta yuvası 22x58mm | C12: sigorta yuvası | D12: =IF($P12="","",INDEX(FIYAT_KOD,MATCH($P12,FIYAT_ART,0))) -> 2CSM277502R1801 | E12: =IF($P12="","",INDEX(FIYAT_ACK,MATCH($P12,FIYAT_ART,0))) -> ABB E93/125 — 3P sigorta yuvası 22x58mm | F12: =IF($P12="","",INDEX(FIYAT_LISTE,MATCH($P12,FIYAT_ART,0))) -> 214.7 | G12: =IF($P12="","",INDEX(FIYAT_NET,MATCH($P12,FIYAT_ART,0))) -> 50867.798 | H12: =IF(OR($G12="",$I12=""),"",$G12*$I12) -> 50867.798 | I12: 1 | J12: шт | K12: =IF($P12="","",INDEX(FIYAT_MARKA,MATCH($P12,FIYAT_ART,0))) -> ABB | L12: =IF($H12="","",$H12) -> 50867.798 | M12: OK | N12: SPD yedek koruması 3(125)A. | O12: DWFX şema | P12: ABB-2CSM277502R1801 | Q12: SIGORTA_YUVASI | R12: =IF(OR($Q12="",$I12=""),"",$I12*IFERROR(INDEX(NORM_DK,MATCH($Q12,NORM_AD,0)),0)) -> 20 | S12: =IF($P12="",0,$I12*IFERROR(INDEX(FIYAT_MODUL,MATCH($P12,FIYAT_ART,0)),0)) -> 6
A13: 12 | B13: =E13 -> ABB E9F22 GG125 — gG 125A sigorta 22x58mm | C13: sigorta | D13: =IF($P13="","",INDEX(FIYAT_KOD,MATCH($P13,FIYAT_ART,0))) -> 2CSM258343R1801 | E13: =IF($P13="","",INDEX(FIYAT_ACK,MATCH($P13,FIYAT_ART,0))) -> ABB E9F22 GG125 — gG 125A sigorta 22x58mm | F13: =IF($P13="","",INDEX(FIYAT_LISTE,MATCH($P13,FIYAT_ART,0))) -> 15.62 | G13: =IF($P13="","",INDEX(FIYAT_NET,MATCH($P13,FIYAT_ART,0))) -> 3700.7685 | H13: =IF(OR($G13="",$I13=""),"",$G13*$I13) -> 11102.306 | I13: 3 | J13: шт | K13: =IF($P13="","",INDEX(FIYAT_MARKA,MATCH($P13,FIYAT_ART,0))) -> ABB | L13: =IF($H13="","",$H13) -> 11102.306 | M13: OK | N13: SPD yedek koruma sigortası. | O13: DWFX şema | P13: ABB-2CSM258343R1801 | S13: =IF($P13="",0,$I13*IFERROR(INDEX(FIYAT_MODUL,MATCH($P13,FIYAT_ART,0)),0)) -> 0
A14: 13 | B14: =E14 -> PROTEC T1 3+1 LH TIP1+2 | C14: UZİP | D14: =IF($P14="","",INDEX(FIYAT_KOD,MATCH($P14,FIYAT_ART,0))) -> 59A382 | E14: =IF($P14="","",INDEX(FIYAT_ACK,MATCH($P14,FIYAT_ART,0))) -> PROTEC T1 3+1 LH TIP1+2 | F14: =IF($P14="","",INDEX(FIYAT_LISTE,MATCH($P14,FIYAT_ART,0))) -> 69000 | G14: =IF($P14="","",INDEX(FIYAT_NET,MATCH($P14,FIYAT_ART,0))) -> 69000 | H14: =IF(OR($G14="",$I14=""),"",$G14*$I14) -> 69000 | I14: 1 | J14: шт | K14: =IF($P14="","",INDEX(FIYAT_MARKA,MATCH($P14,FIYAT_ART,0))) -> ekt | L14: =IF($H14="","",$H14) -> 69000 | M14: FIYAT_YOK | N14: Şema: PF 50kA (B+C) Tip1+2 SPD. Kod doğrulandı, fiyat listede yok — bkz. FIYAT notu. TNS/TT 3P+N kabul edildi, saha topraklama sistemi teyit edilmeli. | O14: DWFX şema | P14: SPD-2CTB815101R4500-YOK | Q14: OPN_SPD | R14: =IF(OR($Q14="",$I14=""),"",$I14*IFERROR(INDEX(NORM_DK,MATCH($Q14,NORM_AD,0)),0)) -> 15 | S14: =IF($P14="",0,$I14*IFERROR(INDEX(FIYAT_MODUL,MATCH($P14,FIYAT_ART,0)),0)) -> 4
A15: 14 | B15: =E15 -> ABB S203-C16 — 3P, C16A, 6kA | C15: oto | D15: =IF($P15="","",INDEX(FIYAT_KOD,MATCH($P15,FIYAT_ART,0))) -> 2CDS253001R0164 | E15: =IF($P15="","",INDEX(FIYAT_ACK,MATCH($P15,FIYAT_ART,0))) -> ABB S203-C16 — 3P, C16A, 6kA | F15: =IF($P15="","",INDEX(FIYAT_LISTE,MATCH($P15,FIYAT_ART,0))) -> 48.51 | G15: =IF($P15="","",INDEX(FIYAT_NET,MATCH($P15,FIYAT_ART,0))) -> 11493.232 | H15: =IF(OR($G15="",$I15=""),"",$G15*$I15) -> 22986.464 | I15: 2 | J15: шт | K15: =IF($P15="","",INDEX(FIYAT_MARKA,MATCH($P15,FIYAT_ART,0))) -> ABB | L15: =IF($H15="","",$H15) -> 22986.464 | M15: OK | N15: 1 adet aydınlatma grubu beslemesi (L1-L6 önü) + 1 adet 3 fazlı ekipman (kahve makinesi P16) devresi. | O15: DWFX şema + devre cetveli | P15: ABB-2CDS253001R0164 | Q15: MCB_3P | R15: =IF(OR($Q15="",$I15=""),"",$I15*IFERROR(INDEX(NORM_DK,MATCH($Q15,NORM_AD,0)),0)) -> 36 | S15: =IF($P15="",0,$I15*IFERROR(INDEX(FIYAT_MODUL,MATCH($P15,FIYAT_ART,0)),0)) -> 6
A16: 15 | B16: =E16 -> ABB FH204 A-25/0.03 — 4P, 25A, 30mA, Tip A (F204 A-25/0.03 muadili) | C16: УЗО | D16: =IF($P16="","",INDEX(FIYAT_KOD,MATCH($P16,FIYAT_ART,0))) -> 2CSF204102R1250 | E16: =IF($P16="","",INDEX(FIYAT_ACK,MATCH($P16,FIYAT_ART,0))) -> ABB FH204 A-25/0.03 — 4P, 25A, 30mA, Tip A (F204 A-25/0.03 muadili) | F16: =IF($P16="","",INDEX(FIYAT_LISTE,MATCH($P16,FIYAT_ART,0))) -> 82.14 | G16: =IF($P16="","",INDEX(FIYAT_NET,MATCH($P16,FIYAT_ART,0))) -> 19461.019 | H16: =IF(OR($G16="",$I16=""),"",$G16*$I16) -> 38922.039 | I16: 2 | J16: шт | K16: =IF($P16="","",INDEX(FIYAT_MARKA,MATCH($P16,FIYAT_ART,0))) -> ABB | L16: =IF($H16="","",$H16) -> 38922.039 | M16: MUADIL_ONAY | N16: 4P 25A/30mA grup RCD x2 (aydınlatma grubu + 3 fazlı ekipman grubu). MUADIL: istenen F204 A-25/0.03 (2CSF204101R1250) listede yok, FH204 A-25/0.03 (2CSF204102R1250) kullanıldı — MÜHENDİS ONAYI GEREKLİ. | O16: DWFX şema + devre cetveli | P16: ABB-FH204A25-MUADIL | Q16: UZO_4P | R16: =IF(OR($Q16="",$I16=""),"",$I16*IFERROR(INDEX(NORM_DK,MATCH($Q16,NORM_AD,0)),0)) -> 40 | S16: =IF($P16="",0,$I16*IFERROR(INDEX(FIYAT_MODUL,MATCH($P16,FIYAT_ART,0)),0)) -> 8
A17: 16 | B17: =E17 -> ABB S201-B10 — 1P, B10A, 6kA (aydınlatma çıkışları) | C17: oto | D17: =IF($P17="","",INDEX(FIYAT_KOD,MATCH($P17,FIYAT_ART,0))) -> 2CDS251001R0105 | E17: =IF($P17="","",INDEX(FIYAT_ACK,MATCH($P17,FIYAT_ART,0))) -> ABB S201-B10 — 1P, B10A, 6kA (aydınlatma çıkışları) | F17: =IF($P17="","",INDEX(FIYAT_LISTE,MATCH($P17,FIYAT_ART,0))) -> 9.78 | G17: =IF($P17="","",INDEX(FIYAT_NET,MATCH($P17,FIYAT_ART,0))) -> 2317.1265 | H17: =IF(OR($G17="",$I17=""),"",$G17*$I17) -> 13902.759 | I17: 6 | J17: шт | K17: =IF($P17="","",INDEX(FIYAT_MARKA,MATCH($P17,FIYAT_ART,0))) -> ABB | L17: =IF($H17="","",$H17) -> 13902.759 | M17: OK | N17: Aydınlatma çıkışları L1-L6 (Spot Light x2, Costa Linear Logo, Sigboard, Spare x2), B/1x10A. | O17: DWFX şema + devre cetveli | P17: ABB-2CDS251001R0105 | Q17: MCB_1P | R17: =IF(OR($Q17="",$I17=""),"",$I17*IFERROR(INDEX(NORM_DK,MATCH($Q17,NORM_AD,0)),0)) -> 60 | S17: =IF($P17="",0,$I17*IFERROR(INDEX(FIYAT_MODUL,MATCH($P17,FIYAT_ART,0)),0)) -> 6
A18: 17 | B18: =E18 -> ABB C2SS1-10B-10 — 2 konum sabit seçici, siyah, 1NA, 22mm | C18: selector | D18: =IF($P18="","",INDEX(FIYAT_KOD,MATCH($P18,FIYAT_ART,0))) -> 1SFA619200R1016 | E18: =IF($P18="","",INDEX(FIYAT_ACK,MATCH($P18,FIYAT_ART,0))) -> ABB C2SS1-10B-10 — 2 konum sabit seçici, siyah, 1NA, 22mm | F18: =IF($P18="","",INDEX(FIYAT_LISTE,MATCH($P18,FIYAT_ART,0))) -> 9.02 | G18: =IF($P18="","",INDEX(FIYAT_NET,MATCH($P18,FIYAT_ART,0))) -> 2137.0635 | H18: =IF(OR($G18="",$I18=""),"",$G18*$I18) -> 8548.254 | I18: 4 | J18: шт | K18: =IF($P18="","",INDEX(FIYAT_MARKA,MATCH($P18,FIYAT_ART,0))) -> ABB | L18: =IF($H18="","",$H18) -> 8548.254 | M18: VARSAYIM | N18: Kapı üzeri aydınlatma grubu kumanda seçicisi x4 (L1-L4). Panel kapı görünüşünden okundu, etiket/fonksiyon sahada teyit edilmeli. | O18: DWFX pano görünüşü | P18: ABB-1SFA619200R1016 | Q18: LAMBA_BUTON | R18: =IF(OR($Q18="",$I18=""),"",$I18*IFERROR(INDEX(NORM_DK,MATCH($Q18,NORM_AD,0)),0)) -> 32 | S18: =IF($P18="",0,$I18*IFERROR(INDEX(FIYAT_MODUL,MATCH($P18,FIYAT_ART,0)),0)) -> 0
A19: 18 | B19: =E19 -> ABB S201-C16 — 1P, C16A, 6kA (priz/ekipman çıkışları) | C19: oto | D19: =IF($P19="","",INDEX(FIYAT_KOD,MATCH($P19,FIYAT_ART,0))) -> 2CDS251001R0164 | E19: =IF($P19="","",INDEX(FIYAT_ACK,MATCH($P19,FIYAT_ART,0))) -> ABB S201-C16 — 1P, C16A, 6kA (priz/ekipman çıkışları) | F19: =IF($P19="","",INDEX(FIYAT_LISTE,MATCH($P19,FIYAT_ART,0))) -> 10.77 | G19: =IF($P19="","",INDEX(FIYAT_NET,MATCH($P19,FIYAT_ART,0))) -> 2551.6823 | H19: =IF(OR($G19="",$I19=""),"",$G19*$I19) -> 68895.421 | I19: 27 | J19: шт | K19: =IF($P19="","",INDEX(FIYAT_MARKA,MATCH($P19,FIYAT_ART,0))) -> ABB | L19: =IF($H19="","",$H19) -> 68895.421 | M19: OK | N19: Priz/ekipman çıkışları C16A — devre cetveli P serisi (spare/led screen/blender/grinder/fridge/bar refrigerator/service socket vb.) 23 adet + UPS çıkış dağıtımı (UP) 4 adet = 27. | O19: DWFX devre cetveli | P19: ABB-2CDS251001R0164 | Q19: MCB_1P | R19: =IF(OR($Q19="",$I19=""),"",$I19*IFERROR(INDEX(NORM_DK,MATCH($Q19,NORM_AD,0)),0)) -> 270 | S19: =IF($P19="",0,$I19*IFERROR(INDEX(FIYAT_MODUL,MATCH($P19,FIYAT_ART,0)),0)) -> 27
A20: 19 | B20: =E20 -> ABB S201-C20 — 1P, C20A, 6kA (ekipman çıkışları) | C20: oto | D20: =IF($P20="","",INDEX(FIYAT_KOD,MATCH($P20,FIYAT_ART,0))) -> 2CDS251001R0204 | E20: =IF($P20="","",INDEX(FIYAT_ACK,MATCH($P20,FIYAT_ART,0))) -> ABB S201-C20 — 1P, C20A, 6kA (ekipman çıkışları) | F20: =IF($P20="","",INDEX(FIYAT_LISTE,MATCH($P20,FIYAT_ART,0))) -> 10.77 | G20: =IF($P20="","",INDEX(FIYAT_NET,MATCH($P20,FIYAT_ART,0))) -> 2551.6823 | H20: =IF(OR($G20="",$I20=""),"",$G20*$I20) -> 7655.0468 | I20: 3 | J20: шт | K20: =IF($P20="","",INDEX(FIYAT_MARKA,MATCH($P20,FIYAT_ART,0))) -> ABB | L20: =IF($H20="","",$H20) -> 7655.0468 | M20: OK | N20: Dishwasher / Filter coffee machine / Water heater soket çıkışları C20A. | O20: DWFX devre cetveli | P20: ABB-2CDS251001R0204 | Q20: MCB_1P | R20: =IF(OR($Q20="",$I20=""),"",$I20*IFERROR(INDEX(NORM_DK,MATCH($Q20,NORM_AD,0)),0)) -> 30 | S20: =IF($P20="",0,$I20*IFERROR(INDEX(FIYAT_MODUL,MATCH($P20,FIYAT_ART,0)),0)) -> 3
A21: 20 | B21: =E21 -> ABB S201-C25 — 1P, C25A, 6kA (mercyhet soket çıkışları) | C21: oto | D21: =IF($P21="","",INDEX(FIYAT_KOD,MATCH($P21,FIYAT_ART,0))) -> 2CDS251001R0254 | E21: =IF($P21="","",INDEX(FIYAT_ACK,MATCH($P21,FIYAT_ART,0))) -> ABB S201-C25 — 1P, C25A, 6kA (mercyhet soket çıkışları) | F21: =IF($P21="","",INDEX(FIYAT_LISTE,MATCH($P21,FIYAT_ART,0))) -> 10.77 | G21: =IF($P21="","",INDEX(FIYAT_NET,MATCH($P21,FIYAT_ART,0))) -> 2551.6823 | H21: =IF(OR($G21="",$I21=""),"",$G21*$I21) -> 5103.3645 | I21: 2 | J21: шт | K21: =IF($P21="","",INDEX(FIYAT_MARKA,MATCH($P21,FIYAT_ART,0))) -> ABB | L21: =IF($H21="","",$H21) -> 5103.3645 | M21: OK | N21: Merchyet soket çıkışları x2 (P1, P11) C25A. | O21: DWFX devre cetveli | P21: ABB-2CDS251001R0254 | Q21: MCB_1P | R21: =IF(OR($Q21="",$I21=""),"",$I21*IFERROR(INDEX(NORM_DK,MATCH($Q21,NORM_AD,0)),0)) -> 20 | S21: =IF($P21="",0,$I21*IFERROR(INDEX(FIYAT_MODUL,MATCH($P21,FIYAT_ART,0)),0)) -> 2
A22: 21 | B22: =E22 -> ABB S201-C32 — 1P, C32A, 6kA (UPS giriş + by-pass) | C22: oto | D22: =IF($P22="","",INDEX(FIYAT_KOD,MATCH($P22,FIYAT_ART,0))) -> 2CDS251001R0324 | E22: =IF($P22="","",INDEX(FIYAT_ACK,MATCH($P22,FIYAT_ART,0))) -> ABB S201-C32 — 1P, C32A, 6kA (UPS giriş + by-pass) | F22: =IF($P22="","",INDEX(FIYAT_LISTE,MATCH($P22,FIYAT_ART,0))) -> 13.46 | G22: =IF($P22="","",INDEX(FIYAT_NET,MATCH($P22,FIYAT_ART,0))) -> 3189.0105 | H22: =IF(OR($G22="",$I22=""),"",$G22*$I22) -> 6378.021 | I22: 2 | J22: шт | K22: =IF($P22="","",INDEX(FIYAT_MARKA,MATCH($P22,FIYAT_ART,0))) -> ABB | L22: =IF($H22="","",$H22) -> 6378.021 | M22: OK | N22: UPS giriş + by-pass hatları C32A. Ayrı bir change-over/ATS cihazı şemada çizilmemiş. | O22: DWFX devre cetveli | P22: ABB-2CDS251001R0324 | Q22: MCB_1P | R22: =IF(OR($Q22="",$I22=""),"",$I22*IFERROR(INDEX(NORM_DK,MATCH($Q22,NORM_AD,0)),0)) -> 20 | S22: =IF($P22="",0,$I22*IFERROR(INDEX(FIYAT_MODUL,MATCH($P22,FIYAT_ART,0)),0)) -> 2
A23: 22 | B23: =E23 -> ABB FH202 A-25/0.03 — 2P, 25A, 30mA, Tip A (F202 A-25/0.03 muadili) | C23: УЗО | D23: =IF($P23="","",INDEX(FIYAT_KOD,MATCH($P23,FIYAT_ART,0))) -> 2CSF202102R1250 | E23: =IF($P23="","",INDEX(FIYAT_ACK,MATCH($P23,FIYAT_ART,0))) -> ABB FH202 A-25/0.03 — 2P, 25A, 30mA, Tip A (F202 A-25/0.03 muadili) | F23: =IF($P23="","",INDEX(FIYAT_LISTE,MATCH($P23,FIYAT_ART,0))) -> 63.22 | G23: =IF($P23="","",INDEX(FIYAT_NET,MATCH($P23,FIYAT_ART,0))) -> 14978.399 | H23: =IF(OR($G23="",$I23=""),"",$G23*$I23) -> 479308.75 | I23: 32 | J23: шт | K23: =IF($P23="","",INDEX(FIYAT_MARKA,MATCH($P23,FIYAT_ART,0))) -> ABB | L23: =IF($H23="","",$H23) -> 479308.75 | M23: MUADIL_ONAY | N23: 2P 25A/30mA grup RCD x32 (priz/ekipman çıkışları 28 adet + UPS dağıtımı UP 4 adet). MUADIL: istenen F202 A-25/0.03 (2CSF202101R1250) listede yok, FH202 A-25/0.03 (2CSF202102R1250) kullanıldı — MÜHENDİS ONAYI GEREKLİ. | O23: DWFX devre cetveli | P23: ABB-FH202A25-MUADIL | Q23: UZO_2P | R23: =IF(OR($Q23="",$I23=""),"",$I23*IFERROR(INDEX(NORM_DK,MATCH($Q23,NORM_AD,0)),0)) -> 384 | S23: =IF($P23="",0,$I23*IFERROR(INDEX(FIYAT_MODUL,MATCH($P23,FIYAT_ART,0)),0)) -> 64
A24: 23 | B24: =E24 -> UPS 5 kVA, 1F/1F, 220V (harici ekipman) | C24: UPS | D24: =IF($P24="","",INDEX(FIYAT_KOD,MATCH($P24,FIYAT_ART,0))) -> 0 | E24: =IF($P24="","",INDEX(FIYAT_ACK,MATCH($P24,FIYAT_ART,0))) -> UPS 5 kVA, 1F/1F, 220V (harici ekipman) | F24: =IF($P24="","",INDEX(FIYAT_LISTE,MATCH($P24,FIYAT_ART,0))) -> 0 | G24: =IF($P24="","",INDEX(FIYAT_NET,MATCH($P24,FIYAT_ART,0))) | H24: =IF(OR($G24="",$I24=""),"",$G24*$I24) | I24: 1 | J24: шт | K24: =IF($P24="","",INDEX(FIYAT_MARKA,MATCH($P24,FIYAT_ART,0))) -> MUADIL-NET | L24: =IF($H24="","",$H24) | M24: KAPSAM_DISI | N24: UPS 5kVA 1F/1F 220V — şemada gösterilmiş, marka/model verilmemiş; müşteri/ayrı tedarik, pano fiyatına dahil edilmedi. | O24: DWFX şema | P24: UPS-5KVA-HARIC | S24: =IF($P24="",0,$I24*IFERROR(INDEX(FIYAT_MODUL,MATCH($P24,FIYAT_ART,0)),0)) -> 0
A25: 24 | B25: =E25 -> H07V-K / ПВ2(LS) Cu 1x25mm² — kablo köprü (ana giriş bağlantısı) | C25: kablo köprü | D25: =IF($P25="","",INDEX(FIYAT_KOD,MATCH($P25,FIYAT_ART,0))) -> PV2(LS)-25 | E25: =IF($P25="","",INDEX(FIYAT_ACK,MATCH($P25,FIYAT_ART,0))) -> H07V-K / ПВ2(LS) Cu 1x25mm² — kablo köprü (ana giriş bağlantısı) | F25: =IF($P25="","",INDEX(FIYAT_LISTE,MATCH($P25,FIYAT_ART,0))) -> 1765 | G25: =IF($P25="","",INDEX(FIYAT_NET,MATCH($P25,FIYAT_ART,0))) -> 1765 | H25: =IF(OR($G25="",$I25=""),"",$G25*$I25) -> 2329.8 | I25: =ROUND(KURALLAR!$B$92*4*KURALLAR!$B$94,2) -> 1.32 | J25: м | K25: =IF($P25="","",INDEX(FIYAT_MARKA,MATCH($P25,FIYAT_ART,0))) -> HARMONY | L25: =IF($H25="","",$H25) -> 2329.8 | M25: VARSAYIM | N25: otomatik hesap: ana şalter In=80A ≤125A → bara yerine kablo köprü (proje kuralı). Metraj = BARA_KOPRU_M(0,30m)×4 kutup(L1,L2,L3,N)×KABLO_FIRE(1,10). | O25: otomatik hesap | P25: HARMONY-PV2LS25 | S25: =IF($P25="",0,$I25*IFERROR(INDEX(FIYAT_MODUL,MATCH($P25,FIYAT_ART,0)),0)) -> 0
A26: 25 | B26: =E26 -> H07V-K / ПВ2(LS) Cu 1x25mm² — kablo köprü (ana giriş bağlantısı) | C26: kablo köprü PE | D26: =IF($P26="","",INDEX(FIYAT_KOD,MATCH($P26,FIYAT_ART,0))) -> PV2(LS)-25 | E26: =IF($P26="","",INDEX(FIYAT_ACK,MATCH($P26,FIYAT_ART,0))) -> H07V-K / ПВ2(LS) Cu 1x25mm² — kablo köprü (ana giriş bağlantısı) | F26: =IF($P26="","",INDEX(FIYAT_LISTE,MATCH($P26,FIYAT_ART,0))) -> 1765 | G26: =IF($P26="","",INDEX(FIYAT_NET,MATCH($P26,FIYAT_ART,0))) -> 1765 | H26: =IF(OR($G26="",$I26=""),"",$G26*$I26) -> 582.45 | I26: =ROUND(KURALLAR!$B$92*1*KURALLAR!$B$94,2) -> 0.33 | J26: м | K26: =IF($P26="","",INDEX(FIYAT_MARKA,MATCH($P26,FIYAT_ART,0))) -> HARMONY | L26: =IF($H26="","",$H26) -> 582.45 | M26: VARSAYIM | N26: otomatik hesap: PE köprü metrajı = BARA_KOPRU_M(0,30m)×1×KABLO_FIRE(1,10). | O26: otomatik hesap | P26: HARMONY-PV2LS25 | S26: =IF($P26="",0,$I26*IFERROR(INDEX(FIYAT_MODUL,MATCH($P26,FIYAT_ART,0)),0)) -> 0
A27: 26 | B27: =E27 -> Kablo pabucu 16mm² (МЛ 16-6-6) | C27: pabuc | D27: =IF($P27="","",INDEX(FIYAT_KOD,MATCH($P27,FIYAT_ART,0))) -> 260100142 | E27: =IF($P27="","",INDEX(FIYAT_ACK,MATCH($P27,FIYAT_ART,0))) -> Kablo pabucu 16mm² (МЛ 16-6-6) | F27: =IF($P27="","",INDEX(FIYAT_LISTE,MATCH($P27,FIYAT_ART,0))) -> 180 | G27: =IF($P27="","",INDEX(FIYAT_NET,MATCH($P27,FIYAT_ART,0))) -> 180 | H27: =IF(OR($G27="",$I27=""),"",$G27*$I27) -> 1440 | I27: 8 | J27: шт | K27: =IF($P27="","",INDEX(FIYAT_MARKA,MATCH($P27,FIYAT_ART,0))) -> EKT | L27: =IF($H27="","",$H27) -> 1440 | M27: VARSAYIM | N27: otomatik hesap: kablo köprü uçları — 4 iletken x 2 uç = 8 adet pabuç. | O27: otomatik hesap | P27: EKT-260100142 | Q27: PABUC_YUKSUK | R27: =IF(OR($Q27="",$I27=""),"",$I27*IFERROR(INDEX(NORM_DK,MATCH($Q27,NORM_AD,0)),0)) -> 24 | S27: =IF($P27="",0,$I27*IFERROR(INDEX(FIYAT_MODUL,MATCH($P27,FIYAT_ART,0)),0)) -> 0
A28: 27 | B28: =E28 -> Трансформатор тока нулевой последовательности CT-80 (TEKLED ELECTRIC) | C28: N bara | D28: =IF($P28="","",INDEX(FIYAT_KOD,MATCH($P28,FIYAT_ART,0))) -> 635-03004 | E28: =IF($P28="","",INDEX(FIYAT_ACK,MATCH($P28,FIYAT_ART,0))) -> Трансформатор тока нулевой последовательности CT-80 (TEKLED ELECTRIC) | F28: =IF($P28="","",INDEX(FIYAT_LISTE,MATCH($P28,FIYAT_ART,0))) -> 12950 | G28: =IF($P28="","",INDEX(FIYAT_NET,MATCH($P28,FIYAT_ART,0))) -> 7770 | H28: =IF(OR($G28="",$I28=""),"",$G28*$I28) -> 7770 | I28: 1 | J28: шт | K28: =IF($P28="","",INDEX(FIYAT_MARKA,MATCH($P28,FIYAT_ART,0))) -> CHINT | L28: =IF($H28="","",$H28) -> 7770 | M28: FIYAT_YOK | N28: İzoleli nötr barası, min. 12 bağlantı (her panoda zorunlu). | O28: otomatik hesap | P28: TERM-N-BARA | S28: =IF($P28="",0,$I28*IFERROR(INDEX(FIYAT_MODUL,MATCH($P28,FIYAT_ART,0)),0)) -> 0
A29: 28 | B29: =E29 -> Реле тока утечки ELR 110V/240V (TEKLED ELECTRIC) | C29: PE bara | D29: =IF($P29="","",INDEX(FIYAT_KOD,MATCH($P29,FIYAT_ART,0))) -> 720-03100 | E29: =IF($P29="","",INDEX(FIYAT_ACK,MATCH($P29,FIYAT_ART,0))) -> Реле тока утечки ELR 110V/240V (TEKLED ELECTRIC) | F29: =IF($P29="","",INDEX(FIYAT_LISTE,MATCH($P29,FIYAT_ART,0))) -> 25900 | G29: =IF($P29="","",INDEX(FIYAT_NET,MATCH($P29,FIYAT_ART,0))) -> 15540 | H29: =IF(OR($G29="",$I29=""),"",$G29*$I29) -> 15540 | I29: 1 | J29: шт | K29: =IF($P29="","",INDEX(FIYAT_MARKA,MATCH($P29,FIYAT_ART,0))) -> CHINT | L29: =IF($H29="","",$H29) -> 15540 | M29: FIYAT_YOK | N29: Topraklama barası (ГЗШ) + izolatör, min. 12 bağlantı (her panoda zorunlu). | O29: otomatik hesap | P29: TERM-PE-BARA | S29: =IF($P29="",0,$I29*IFERROR(INDEX(FIYAT_MODUL,MATCH($P29,FIYAT_ART,0)),0)) -> 0
A30: 29 | B30: =E30 -> Geçiş klemensi 2.5-4mm² (ЗН101-2-24A-08) | C30: klemens | D30: =IF($P30="","",INDEX(FIYAT_KOD,MATCH($P30,FIYAT_ART,0))) -> 32421DEK | E30: =IF($P30="","",INDEX(FIYAT_ACK,MATCH($P30,FIYAT_ART,0))) -> Geçiş klemensi 2.5-4mm² (ЗН101-2-24A-08) | F30: =IF($P30="","",INDEX(FIYAT_LISTE,MATCH($P30,FIYAT_ART,0))) -> 117 | G30: =IF($P30="","",INDEX(FIYAT_NET,MATCH($P30,FIYAT_ART,0))) -> 117 | H30: =IF(OR($G30="",$I30=""),"",$G30*$I30) -> 11349 | I30: =ROUNDUP((($I$17+$I$19+$I$20+$I$21+$I$22)*2+$I$15*4)*KURALLAR!$B$99,0) -> 97 | J30: шт | K30: =IF($P30="","",INDEX(FIYAT_MARKA,MATCH($P30,FIYAT_ART,0))) -> EKT | L30: =IF($H30="","",$H30) -> 11349 | M30: VARSAYIM | N30: otomatik hesap: 1P devre 2 klemens + 3P devre 4 klemens, toplam devre sayısına göre, ×KLEMENS_YEDEK(1,10). | O30: otomatik hesap | P30: EKT-32421DEK | Q30: KLEMENS | R30: =IF(OR($Q30="",$I30=""),"",$I30*IFERROR(INDEX(NORM_DK,MATCH($Q30,NORM_AD,0)),0)) -> 388 | S30: =IF($P30="",0,$I30*IFERROR(INDEX(FIYAT_MODUL,MATCH($P30,FIYAT_ART,0)),0)) -> 0
A31: 30 | B31: =E31 -> Geçiş klemensi 2.5-4mm² (ЗН101-2-24A-08) | C31: klemens N | D31: =IF($P31="","",INDEX(FIYAT_KOD,MATCH($P31,FIYAT_ART,0))) -> 32421DEK | E31: =IF($P31="","",INDEX(FIYAT_ACK,MATCH($P31,FIYAT_ART,0))) -> Geçiş klemensi 2.5-4mm² (ЗН101-2-24A-08) | F31: =IF($P31="","",INDEX(FIYAT_LISTE,MATCH($P31,FIYAT_ART,0))) -> 117 | G31: =IF($P31="","",INDEX(FIYAT_NET,MATCH($P31,FIYAT_ART,0))) -> 117 | H31: =IF(OR($G31="",$I31=""),"",$G31*$I31) -> 5148 | I31: =ROUNDUP(($I$17+$I$19+$I$20+$I$21+$I$22)*1*KURALLAR!$B$99,0) -> 44 | J31: шт | K31: =IF($P31="","",INDEX(FIYAT_MARKA,MATCH($P31,FIYAT_ART,0))) -> EKT | L31: =IF($H31="","",$H31) -> 5148 | M31: VARSAYIM | N31: otomatik hesap: 1P+N devre başına 1 nötr klemens (mavi) ×KLEMENS_YEDEK. | O31: otomatik hesap | P31: EKT-32421DEK | Q31: KLEMENS | R31: =IF(OR($Q31="",$I31=""),"",$I31*IFERROR(INDEX(NORM_DK,MATCH($Q31,NORM_AD,0)),0)) -> 176 | S31: =IF($P31="",0,$I31*IFERROR(INDEX(FIYAT_MODUL,MATCH($P31,FIYAT_ART,0)),0)) -> 0
A32: 31 | B32: =E32 -> Geçiş klemensi 2.5-4mm² (ЗН101-2-24A-08) | C32: klemens PE | D32: =IF($P32="","",INDEX(FIYAT_KOD,MATCH($P32,FIYAT_ART,0))) -> 32421DEK | E32: =IF($P32="","",INDEX(FIYAT_ACK,MATCH($P32,FIYAT_ART,0))) -> Geçiş klemensi 2.5-4mm² (ЗН101-2-24A-08) | F32: =IF($P32="","",INDEX(FIYAT_LISTE,MATCH($P32,FIYAT_ART,0))) -> 117 | G32: =IF($P32="","",INDEX(FIYAT_NET,MATCH($P32,FIYAT_ART,0))) -> 117 | H32: =IF(OR($G32="",$I32=""),"",$G32*$I32) -> 5499 | I32: =ROUNDUP((($I$17+$I$19+$I$20+$I$21+$I$22)+$I$15)*1*KURALLAR!$B$99,0) -> 47 | J32: шт | K32: =IF($P32="","",INDEX(FIYAT_MARKA,MATCH($P32,FIYAT_ART,0))) -> EKT | L32: =IF($H32="","",$H32) -> 5499 | M32: VARSAYIM | N32: otomatik hesap: devre başına 1 PE klemensi (sarı-yeşil) ×KLEMENS_YEDEK. | O32: otomatik hesap | P32: EKT-32421DEK | Q32: KLEMENS | R32: =IF(OR($Q32="",$I32=""),"",$I32*IFERROR(INDEX(NORM_DK,MATCH($Q32,NORM_AD,0)),0)) -> 188 | S32: =IF($P32="",0,$I32*IFERROR(INDEX(FIYAT_MODUL,MATCH($P32,FIYAT_ART,0)),0)) -> 0
A33: 32 | B33: =E33 -> DIN ray uç plakası + stoper seti | C33: klemens aksesuar | D33: =IF($P33="","",INDEX(FIYAT_KOD,MATCH($P33,FIYAT_ART,0))) -> YZN11DF-003-K03 | E33: =IF($P33="","",INDEX(FIYAT_ACK,MATCH($P33,FIYAT_ART,0))) -> DIN ray uç plakası + stoper seti | F33: =IF($P33="","",INDEX(FIYAT_LISTE,MATCH($P33,FIYAT_ART,0))) -> 106 | G33: =IF($P33="","",INDEX(FIYAT_NET,MATCH($P33,FIYAT_ART,0))) -> 106 | H33: =IF(OR($G33="",$I33=""),"",$G33*$I33) -> 1060 | I33: =ROUNDUP(($I$30+$I$31+$I$32)/20,0) -> 10 | J33: шт | K33: =IF($P33="","",INDEX(FIYAT_MARKA,MATCH($P33,FIYAT_ART,0))) -> EKT | L33: =IF($H33="","",$H33) -> 1060 | M33: VARSAYIM | N33: otomatik hesap: uç plakası+stoper, her ~20 klemens için 1 set. | O33: otomatik hesap | P33: EKT-YZN11DF-003-K03 | S33: =IF($P33="",0,$I33*IFERROR(INDEX(FIYAT_MODUL,MATCH($P33,FIYAT_ART,0)),0)) -> 0
A34: 33 | B34: =E34 -> DIN rayı TS35x7.5mm delikli (1m) | C34: DIN рейка | D34: =IF($P34="","",INDEX(FIYAT_KOD,MATCH($P34,FIYAT_ART,0))) -> 570003 | E34: =IF($P34="","",INDEX(FIYAT_ACK,MATCH($P34,FIYAT_ART,0))) -> DIN rayı TS35x7.5mm delikli (1m) | F34: =IF($P34="","",INDEX(FIYAT_LISTE,MATCH($P34,FIYAT_ART,0))) -> 869 | G34: =IF($P34="","",INDEX(FIYAT_NET,MATCH($P34,FIYAT_ART,0))) -> 521.4 | H34: =IF(OR($G34="",$I34=""),"",$G34*$I34) -> 1496.418 | I34: =ROUND((SUM($S$3:$S$32)*18/1000)*KURALLAR!$B$97,2) -> 2.87 | J34: м | K34: =IF($P34="","",INDEX(FIYAT_MARKA,MATCH($P34,FIYAT_ART,0))) -> CHINT | L34: =IF($H34="","",$H34) -> 1496.418 | M34: VARSAYIM | N34: otomatik hesap: toplam modül genişliği (FIYAT!MODUL × BOM adedi, SUM) × 18mm/modül, ×DINRAY_FIRE(1,10, klemens rayı payı dahil). | O34: otomatik hesap | P34: CHINT-570003 | S34: =IF($P34="",0,$I34*IFERROR(INDEX(FIYAT_MODUL,MATCH($P34,FIYAT_ART,0)),0)) -> 0
