Workbook
Name ANA_SALTER_BARA_ESIK_A: KURALLAR!$B$83
Name DINRAY_FIRE: KURALLAR!$B$79
Name DURUM_LIST: KURALLAR!$T$3:$T$12
Name FIYAT_ACK: FIYAT!$C$2:$C$28
Name FIYAT_ART: FIYAT!$B$2:$B$28
Name FIYAT_NET: FIYAT!$I$2:$I$28
Name GARANTI: KURALLAR!$B$94
Name ISCILIK_DK_UCRETI: KURALLAR!$B$32
Name ISCILIK_SAAT_UCRETI: KURALLAR!$B$31
Name ISKONTO: KURALLAR!$B$88
Name KANAL_FIRE: KURALLAR!$B$80
Name KAR_ORANI: KURALLAR!$B$87
Name KLEMENS_YEDEK: KURALLAR!$B$78
Name KORPUS_YEDEK_ORANI: KURALLAR!$B$82
Name KUR_AD: KURALLAR!$A$5:$A$8
Name KUR_DEG: KURALLAR!$B$5:$B$8
Name MARKA_AD: KURALLAR!$A$13:$A$27
Name MARKA_KAT: KURALLAR!$E$13:$E$27
Name MARKA_PARA: KURALLAR!$B$13:$B$27
Name MARKA_TIP: KURALLAR!$F$13:$F$27
Name MODUL_GENISLIK_MM: KURALLAR!$B$81
Name NDS_ORANI: KURALLAR!$B$89
Name NORM_AD: KURALLAR!$A$37:$A$47
Name NORM_DK: KURALLAR!$B$37:$B$47
Name ODEME_SARTI: KURALLAR!$B$93
Name TEKLIF_GECERLILIK: KURALLAR!$B$90
Name TEST_ETIKET_CARPANI: KURALLAR!$B$33
Name URETIM_SURESI: KURALLAR!$B$91

Sheet KURALLAR
A1: KURALLAR — TEK GERÇEK KAYNAK (260914 Aktau Beket)
A3: BLOK 1 — KUR TABLOSU | T3: OK
A4: PARA | B4: KZT | C4: TARIH | T4: FIYAT_YOK
A5: KZT | B5: 1 | T5: MUADIL
A6: USD | B6: 548 | C6: VARSAYIM-son bilinen | T6: MUADIL_ONAY
A7: EUR | B7: 595 | C7: VARSAYIM-son bilinen | T7: CIHAZ_BELIRSIZ
A8: TRY | B8: 13.5 | C8: VARSAYIM-son bilinen | T8: VARSAYIM
T9: KAPSAM_DISI
T10: KONTROL
A11: BLOK 2 — MARKA KURAL TABLOSU | T11: OKUNAMADI
A12: MARKA | B12: PARA | C12: KATSAYI1 | D12: KATSAYI2 | E12: TOPLAM | F12: GIRDI_TIPI | G12: NOT | T12: FIYAT_ESKI
A13: ABB | B13: EUR | C13: 1.35 | D13: 0.3 | E13: =C13*D13 -> 0.405 | F13: LISTE | G13: standart (motorlu/modüler); açık tip değil
A14: ABB-ACIK | B14: EUR | C14: 1.35 | D14: 0.23 | E14: =C14*D14 -> 0.3105 | F14: LISTE | G14: ayar sahalı / açık tip
A15: SCHNEIDER | B15: EUR | C15: 0.6 | D15: 1 | E15: =C15*D15 -> 0.6 | F15: LISTE
A16: CHINT | B16: KZT | C16: 0.6 | D16: 1 | E16: =C16*D16 -> 0.6 | F16: LISTE | G16: birlesik.csv gerçek katsayı
A17: CNC | B17: KZT | C17: 0.55 | D17: 1 | E17: =C17*D17 -> 0.55 | F17: LISTE | G17: liste 2025-02-04, güvenilmez
A18: LEGRAND | B18: TRY | C18: 0.5 | D18: 1 | E18: =C18*D18 -> 0.5 | F18: LISTE | G18: teyitsiz
A19: IEK | B19: KZT | C19: 1 | D19: 1 | E19: =C19*D19 -> 1 | F19: LISTE
A20: EKF | B20: KZT | C20: 1 | D20: 1 | E20: =C20*D20 -> 1 | F20: LISTE | G20: referans, fiyat yasak
A21: EKT | B21: KZT | C21: 1 | D21: 1 | E21: =C21*D21 -> 1 | F21: LISTE | G21: birlesik.csv gerçek katsayı
A22: SAIMAN | B22: KZT | C22: 1 | D22: 1 | E22: =C22*D22 -> 1 | F22: LISTE
A23: KAZTEK | B23: KZT | C23: 0.6 | D23: 1 | E23: =C23*D23 -> 0.6 | F23: LISTE | G23: korpus — birlesik.csv gerçek katsayı (0.60 değil, liste zaten net)
A24: BAKIR-BARA | B24: KZT | C24: 1 | D24: 1 | E24: =C24*D24 -> 1 | F24: NET | G24: kg fiyatından hesaplanır
A25: ALUM-BARA | B25: KZT | C25: 1 | D25: 1 | E25: =C25*D25 -> 1 | F25: NET | G25: kg fiyatından hesaplanır
A26: MUADIL-NET | B26: KZT | C26: 1 | D26: 1 | E26: =C26*D26 -> 1 | F26: NET
A27: ISCILIK | B27: KZT | C27: 1 | D27: 1 | E27: =C27*D27 -> 1 | F27: NET
A30: BLOK 3 — İŞÇİLİK
A31: ISCILIK_SAAT_UCRETI | B31: 3500 | C31: KZT/saat — VARSAYIM (proje bazlı teyit edilmedi)
A32: ISCILIK_DK_UCRETI | B32: =B31/60 -> 58.333333
A33: TEST_ETIKET_CARPANI | B33: 1.15
A35: NORM TABLOSU (dk/birim, sarı=değiştirilebilir)
A36: NORM_ANAHTAR | B36: dk/birim | C36: NOT
A37: KORPUS_AYAKLI | B37: 90 | C37: napolnyy/ayaklı korpus montaj
A38: MCCB_ANA | B38: 60 | C38: ana giriş MCCB/ATS ≤250A
A39: MCCB_BUYUK | B39: 60 | C39: MCCB 80-250A
A40: MCCB_KUCUK | B40: 45 | C40: kompakt/modüler koruma şalteri (S200/S800S serisi)
A41: MCB_1P | B41: 10 | C41: 1P mini otomat
A42: SAYAC_AT | B42: 90 | C42: sayaç/ölçüm cihazı + AT komple
A43: YUMUSAK_YOLVERICI | B43: 45 | C43: PSR tipi yumuşak yolverici
A44: KLEMENS | B44: 4 | C44: adet başına
...

Sheet FIYAT
A1: SIRA | B1: ARTIKUL | C1: ACIKLAMA | D1: TIP | E1: MARKA | F1: LISTE_FIYAT | G1: PARA | H1: KATSAYI | I1: NET_KZT | J1: BIRIM | K1: TOPLAM_ADET | L1: TOPLAM_TUTAR | M1: KAYNAK | N1: DURUM | O1: NOT
A2: 1 | B2: KAZTEK-719-15923 | C2: Мет. Щит ВРУ (2000x800x600)+10 база — TEOS 2000x800x600 IP65 muadili | D2: Korpus | E2: KAZTEK | F2: 148675 | G2: =IF($E2="","",INDEX(MARKA_PARA,MATCH($E2,MARKA_AD,0))) -> KZT | H2: =IF($E2="","",INDEX(MARKA_KAT,MATCH($E2,MARKA_AD,0))) -> 0.6 | I2: =IF($F2="","",IF(INDEX(MARKA_TIP,MATCH($E2,MARKA_AD,0))="NET",$F2,$F2*INDEX(MARKA_KAT,MATCH($E2,MARKA_AD,0))*INDEX(KUR_DEG,MATCH($G2,KUR_AD,0)))) -> 89205 | J2: компл. | K2: =SUMIF(BOM!$D:$D,$B2,BOM!$I:$I) -> 1 | L2: =IF($I2="","",$I2*$K2) -> 89205 | M2: KAZTEK2607 (2026-07-15) | N2: MUADIL_ONAY | O2: TEOS marka değil, IP65 teyidi gerekli
A3: 2 | B3: 2CDS253001R0824 | C3: S 203-C 100 | D3: ОТО | E3: ABB | F3: 242.2 | G3: =IF($E3="","",INDEX(MARKA_PARA,MATCH($E3,MARKA_AD,0))) -> EUR | H3: =IF($E3="","",INDEX(MARKA_KAT,MATCH($E3,MARKA_AD,0))) -> 0.405 | I3: =IF($F3="","",IF(INDEX(MARKA_TIP,MATCH($E3,MARKA_AD,0))="NET",$F3,$F3*INDEX(MARKA_KAT,MATCH($E3,MARKA_AD,0))*INDEX(KUR_DEG,MATCH($G3,KUR_AD,0)))) -> 58364.145 | J3: шт | K3: =SUMIF(BOM!$D:$D,$B3,BOM!$I:$I) -> 0 | L3: =IF($I3="","",$I3*$K3) -> 0 | N3: FIYAT_YOK | O3: ABB Kasım2025 fiyat listesi / birlesik.csv'de S800S yok
A4: 3 | B4: ABB-S800S-3P-80A-D | C4: Автоматический выключатель S800S 3P 80A, х-ка D | D4: ОТО | E4: ABB | G4: =IF($E4="","",INDEX(MARKA_PARA,MATCH($E4,MARKA_AD,0))) -> EUR | H4: =IF($E4="","",INDEX(MARKA_KAT,MATCH($E4,MARKA_AD,0))) -> 0.405 | I4: =IF($F4="","",IF(INDEX(MARKA_TIP,MATCH($E4,MARKA_AD,0))="NET",$F4,$F4*INDEX(MARKA_KAT,MATCH($E4,MARKA_AD,0))*INDEX(KUR_DEG,MATCH($G4,KUR_AD,0)))) | J4: шт | K4: =SUMIF(BOM!$D:$D,$B4,BOM!$I:$I) -> 2 | L4: =IF($I4="","",$I4*$K4) | N4: FIYAT_YOK | O4: ABB Kasım2025 fiyat listesi / birlesik.csv'de S800S yok
A5: 4 | B5: CHINT-256780 | C5: Устройство АВР NXZM-125S/3B 125A | D5: АВР | E5: CHINT | F5: 204604 | G5: =IF($E5="","",INDEX(MARKA_PARA,MATCH($E5,MARKA_AD,0))) -> KZT | H5: =IF($E5="","",INDEX(MARKA_KAT,MATCH($E5,MARKA_AD,0))) -> 0.6 | I5: =IF($F5="","",IF(INDEX(MARKA_TIP,MATCH($E5,MARKA_AD,0))="NET",$F5,$F5*INDEX(MARKA_KAT,MATCH($E5,MARKA_AD,0))*INDEX(KUR_DEG,MATCH($G5,KUR_AD,0)))) -> 122762.4 | J5: шт | K5: =SUMIF(BOM!$D:$D,$B5,BOM!$I:$I) -> 1 | L5: =IF($I5="","",$I5*$K5) -> 122762.4 | M5: CHINT2608 (2026-08-27) | N5: OK | O5: birlesik.csv tam eşleşme
A6: 5 | B6: ABB-2CDS253001R0164 | C6: Автоматический выключатель S203-C 3P 16A (S200S 16A muadili) | D6: ОТО | E6: ABB | F6: 48.51 | G6: =IF($E6="","",INDEX(MARKA_PARA,MATCH($E6,MARKA_AD,0))) -> EUR | H6: =IF($E6="","",INDEX(MARKA_KAT,MATCH($E6,MARKA_AD,0))) -> 0.405 | I6: =IF($F6="","",IF(INDEX(MARKA_TIP,MATCH($E6,MARKA_AD,0))="NET",$F6,$F6*INDEX(MARKA_KAT,MATCH($E6,MARKA_AD,0))*INDEX(KUR_DEG,MATCH($G6,KUR_AD,0)))) -> 11689.697 | J6: шт | K6: =SUMIF(BOM!$D:$D,$B6,BOM!$I:$I) -> 3 | L6: =IF($I6="","",$I6*$K6) -> 35069.092 | M6: ABB Kasım-2025 | N6: MUADIL_ONAY | O6: D eğrisi ABB listesinde yok, C ile muadil
A7: 6 | B7: ABB-2CDS253001R0324 | C7: Автоматический выключатель S203-C 3P 32A (S200S 32A D muadili) | D7: ОТО | E7: ABB | F7: 60.59 | G7: =IF($E7="","",INDEX(MARKA_PARA,MATCH($E7,MARKA_AD,0))) -> EUR | H7: =IF($E7="","",INDEX(MARKA_KAT,MATCH($E7,MARKA_AD,0))) -> 0.405 | I7: =IF($F7="","",IF(INDEX(MARKA_TIP,MATCH($E7,MARKA_AD,0))="NET",$F7,$F7*INDEX(MARKA_KAT,MATCH($E7,MARKA_AD,0))*INDEX(KUR_DEG,MATCH($G7,KUR_AD,0)))) -> 14600.675 | J7: шт | K7: =SUMIF(BOM!$D:$D,$B7,BOM!$I:$I) -> 1 | L7: =IF($I7="","",$I7*$K7) -> 14600.675 | M7: ABB Kasım-2025 | N7: MUADIL_ONAY | O7: D eğrisi ABB listesinde yok, C ile muadil
A8: 7 | B8: ABB-2CDS631031R0104 | C8: Basic M BMS311C10, 1P C10A | D8: ОТО | E8: ABB | F8: 4.95 | G8: =IF($E8="","",INDEX(MARKA_PARA,MATCH($E8,MARKA_AD,0))) -> EUR | H8: =IF($E8="","",INDEX(MARKA_KAT,MATCH($E8,MARKA_AD,0))) -> 0.405 | I8: =IF($F8="","",IF(INDEX(MARKA_TIP,MATCH($E8,MARKA_AD,0))="NET",$F8,$F8*INDEX(MARKA_KAT,MATCH($E8,MARKA_AD,0))*INDEX(KUR_DEG,MATCH($G8,KUR_AD,0)))) -> 1192.8263 | J8: шт | K8: =SUMIF(BOM!$D:$D,$B8,BOM!$I:$I) -> 2 | L8: =IF($I8="","",$I8*$K8) -> 2385.6525 | M8: ABB Kasım-2025 | N8: OK
A9: 8 | B9: ABB-2CDS631031R0064 | C9: Basic M BMS311C06, 1P C6A | D9: ОТО | E9: ABB | F9: 5.94 | G9: =IF($E9="","",INDEX(MARKA_PARA,MATCH($E9,MARKA_AD,0))) -> EUR | H9: =IF($E9="","",INDEX(MARKA_KAT,MATCH($E9,MARKA_AD,0))) -> 0.405 | I9: =IF($F9="","",IF(INDEX(MARKA_TIP,MATCH($E9,MARKA_AD,0))="NET",$F9,$F9*INDEX(MARKA_KAT,MATCH($E9,MARKA_AD,0))*INDEX(KUR_DEG,MATCH($G9,KUR_AD,0)))) -> 1431.3915 | J9: шт | K9: =SUMIF(BOM!$D:$D,$B9,BOM!$I:$I) -> 4 | L9: =IF($I9="","",$I9*$K9) -> 5725.566 | M9: ABB Kasım-2025 | N9: OK
A10: 9 | B10: EKF-SME-MUADIL-YOK | C10: Многофункциональный измерительный прибор SM-E | D10: Прибор | E10: EKF | G10: =IF($E10="","",INDEX(MARKA_PARA,MATCH($E10,MARKA_AD,0))) -> KZT | H10: =IF($E10="","",INDEX(MARKA_KAT,MATCH($E10,MARKA_AD,0))) -> 1 | I10: =IF($F10="","",IF(INDEX(MARKA_TIP,MATCH($E10,MARKA_AD,0))="NET",$F10,$F10*INDEX(MARKA_KAT,MATCH($E10,MARKA_AD,0))*INDEX(KUR_DEG,MATCH($G10,KUR_AD,0)))) | J10: шт | K10: =SUMIF(BOM!$D:$D,$B10,BOM!$I:$I) -> 1 | L10: =IF($I10="","",$I10*$K10) | N10: FIYAT_YOK | O10: EKF fiyatı yasak, panel tipi çok fonksiyonlu ölçüm cihazı için muadil bulunamadı
A11: 10 | B11: ABB-1SFA896113R7000 | C11: Устройство плавного пуска PSR72-600-70 | D11: Плавный пуск | E11: ABB | F11: 859.7 | G11: =IF($E11="","",INDEX(MARKA_PARA,MATCH($E11,MARKA_AD,0))) -> EUR | H11: =IF($E11="","",INDEX(MARKA_KAT,MATCH($E11,MARKA_AD,0))) -> 0.405 | I11: =IF($F11="","",IF(INDEX(MARKA_TIP,MATCH($E11,MARKA_AD,0))="NET",$F11,$F11*INDEX(MARKA_KAT,MATCH($E11,MARKA_AD,0))*INDEX(KUR_DEG,MATCH($G11,KUR_AD,0)))) -> 207166.21 | J11: шт | K11: =SUMIF(BOM!$D:$D,$B11,BOM!$I:$I) -> 2 | L11: =IF($I11="","",$I11*$K11) -> 414332.42 | M11: ABB Kasım-2025 | N11: OK
A12: 11 | B12: ABB-1SFA896106R7000 | C12: Устройство плавного пуска PSR12-600-70 | D12: Плавный пуск | E12: ABB | F12: 248 | G12: =IF($E12="","",INDEX(MARKA_PARA,MATCH($E12,MARKA_AD,0))) -> EUR | H12: =IF($E12="","",INDEX(MARKA_KAT,MATCH($E12,MARKA_AD,0))) -> 0.405 | I12: =IF($F12="","",IF(INDEX(MARKA_TIP,MATCH($E12,MARKA_AD,0))="NET",$F12,$F12*INDEX(MARKA_KAT,MATCH($E12,MARKA_AD,0))*INDEX(KUR_DEG,MATCH($G12,KUR_AD,0)))) -> 59761.8 | J12: шт | K12: =SUMIF(BOM!$D:$D,$B12,BOM!$I:$I) -> 2 | L12: =IF($I12="","",$I12*$K12) -> 119523.6 | M12: ABB Kasım-2025 | N12: OK
A13: 12 | B13: EKT-270300099 | C13: Трансформатор тока ТТИ-А 100/5А 5ВА кл.0,5 (TTE-30-100/5A muadili) | D13: ТТ | E13: EKT | F13: 5047 | G13: =IF($E13="","",INDEX(MARKA_PARA,MATCH($E13,MARKA_AD,0))) -> KZT | H13: =IF($E13="","",INDEX(MARKA_KAT,MATCH($E13,MARKA_AD,0))) -> 1 | I13: =IF($F13="","",IF(INDEX(MARKA_TIP,MATCH($E13,MARKA_AD,0))="NET",$F13,$F13*INDEX(MARKA_KAT,MATCH($E13,MARKA_AD,0))*INDEX(KUR_DEG,MATCH($G13,KUR_AD,0)))) -> 5047 | J13: шт | K13: =SUMIF(BOM!$D:$D,$B13,BOM!$I:$I) -> 3 | L13: =IF($I13="","",$I13*$K13) -> 15141 | M13: EKT2506 (2025-06-12) | N13: MUADIL | O13: EKF fiyatı yasak — EKT eşdeğeri kullanıldı
A14: 13 | B14: EKT-030300442 | C14: Клемма проходная 32A (0,08-4мм, 2х2) | D14: Клеммник | E14: EKT | F14: 210 | G14: =IF($E14="","",INDEX(MARKA_PARA,MATCH($E14,MARKA_AD,0))) -> KZT | H14: =IF($E14="","",INDEX(MARKA_KAT,MATCH($E14,MARKA_AD,0))) -> 1 | I14: =IF($F14="","",IF(INDEX(MARKA_TIP,MATCH($E14,MARKA_AD,0))="NET",$F14,$F14*INDEX(MARKA_KAT,MATCH($E14,MARKA_AD,0))*INDEX(KUR_DEG,MATCH($G14,KUR_AD,0)))) -> 210 | J14: шт | K14: =SUMIF(BOM!$D:$D,$B14,BOM!$I:$I) -> 42 | L14: =IF($I14="","",$I14*$K14) -> 8820 | M14: EKT2506 (2025-06-12) | N14: OK
A15: 14 | B15: EKT-130200088 | C15: Шина N/PE ШНИ-6х9-6-Д-С (изолированная) | D15: Шина | E15: EKT | F15: 307 | G15: =IF($E15="","",INDEX(MARKA_PARA,MATCH($E15,MARKA_AD,0))) -> KZT | H15: =IF($E15="","",INDEX(MARKA_KAT,MATCH($E15,MARKA_AD,0))) -> 1 | I15: =IF($F15="","",IF(INDEX(MARKA_TIP,MATCH($E15,MARKA_AD,0))="NET",$F15,$F15*INDEX(MARKA_KAT,MATCH($E15,MARKA_AD,0))*INDEX(KUR_DEG,MATCH($G15,KUR_AD,0)))) -> 307 | J15: шт | K15: =SUMIF(BOM!$D:$D,$B15,BOM!$I:$I) -> 2 | L15: =IF($I15="","",$I15*$K15) -> 614 | M15: EKT2506 (2025-06-12) | N15: VARSAYIM | O15: Ana şalter ≤125A — kompakt terminal bara, bakır bara yerine
A16: 15 | B16: CHINT-570003 | C16: DIN-рейка оцинкованная TH35-7.5, 200см | D16: DIN | E16: CHINT | F16: 2232 | G16: =IF($E16="","",INDEX(MARKA_PARA,MATCH($E16,MARKA_AD,0))) -> KZT | H16: =IF($E16="","",INDEX(MARKA_KAT,MATCH($E16,MARKA_AD,0))) -> 0.6 | I16: =IF($F16="","",IF(INDEX(MARKA_TIP,MATCH($E16,MARKA_AD,0))="NET",$F16,$F16*INDEX(MARKA_KAT,MATCH($E16,MARKA_AD,0))*INDEX(KUR_DEG,MATCH($G16,KUR_AD,0)))) -> 1339.2 | J16: шт | K16: =SUMIF(BOM!$D:$D,$B16,BOM!$I:$I) -> 1 | L16: =IF($I16="","",$I16*$K16) -> 1339.2 | M16: CHINT2608 (2026-08-27) | N16: OK
A17: 16 | B17: EKT-280300704 | C17: Лоток перфорированный 50х50х3000 (0,7мм) | D17: Канал | E17: EKT | F17: 1022 | G17: =IF($E17="","",INDEX(MARKA_PARA,MATCH($E17,MARKA_AD,0))) -> KZT | H17: =IF($E17="","",INDEX(MARKA_KAT,MATCH($E17,MARKA_AD,0))) -> 1 | I17: =IF($F17="","",IF(INDEX(MARKA_TIP,MATCH($E17,MARKA_AD,0))="NET",$F17,$F17*INDEX(MARKA_KAT,MATCH($E17,MARKA_AD,0))*INDEX(KUR_DEG,MATCH($G17,KUR_AD,0)))) -> 1022 | J17: м | K17: =SUMIF(BOM!$D:$D,$B17,BOM!$I:$I) -> 7 | L17: =IF($I17="","",$I17*$K17) -> 7154 | M17: EKT2506 (2025-06-12) | N17: OK | O17: perforeli tercih kuralı uygulandı
A18: 17 | B18: KAZTEK-444-03054 | C18: Медный заземляющий провод Ø16мм2 | D18: Заземление | E18: KAZTEK | F18: 2000 | G18: =IF($E18="","",INDEX(MARKA_PARA,MATCH($E18,MARKA_AD,0))) -> KZT | H18: =IF($E18="","",INDEX(MARKA_KAT,MATCH($E18,MARKA_AD,0))) -> 0.6 | I18: =IF($F18="","",IF(INDEX(MARKA_TIP,MATCH($E18,MARKA_AD,0))="NET",$F18,$F18*INDEX(MARKA_KAT,MATCH($E18,MARKA_AD,0))*INDEX(KUR_DEG,MATCH($G18,KUR_AD,0)))) -> 1200 | J18: м | K18: =SUMIF(BOM!$D:$D,$B18,BOM!$I:$I) -> 0.3 | L18: =IF($I18="","",$I18*$K18) -> 360 | M18: KAZTEK2607 (2026-07-15) | N18: OK | O18: ГЗШ/kapak-gövde topraklama bağlantısı
A19: 18 | B19: KABLO-PUVNG-1X16 | C19: Провод ПуВнг(А)-LS 1х16 | D19: Кабель | E19: EKT | G19: =IF($E19="","",INDEX(MARKA_PARA,MATCH($E19,MARKA_AD,0))) -> KZT | H19: =IF($E19="","",INDEX(MARKA_KAT,MATCH($E19,MARKA_AD,0))) -> 1 | I19: =IF($F19="","",IF(INDEX(MARKA_TIP,MATCH($E19,MARKA_AD,0))="NET",$F19,$F19*INDEX(MARKA_KAT,MATCH($E19,MARKA_AD,0))*INDEX(KUR_DEG,MATCH($G19,KUR_AD,0)))) | J19: м | K19: =SUMIF(BOM!$D:$D,$B19,BOM!$I:$I) -> 10 | L19: =IF($I19="","",$I19*$K19) | N19: FIYAT_YOK | O19: Tam eşleşen artikül fiyat listesinde yok
A20: 19 | B20: KABLO-PUVNG-1X25 | C20: Провод ПуВнг(А)-LS 1х25 | D20: Кабель | E20: EKT | G20: =IF($E20="","",INDEX(MARKA_PARA,MATCH($E20,MARKA_AD,0))) -> KZT | H20: =IF($E20="","",INDEX(MARKA_KAT,MATCH($E20,MARKA_AD,0))) -> 1 | I20: =IF($F20="","",IF(INDEX(MARKA_TIP,MATCH($E20,MARKA_AD,0))="NET",$F20,$F20*INDEX(MARKA_KAT,MATCH($E20,MARKA_AD,0))*INDEX(KUR_DEG,MATCH($G20,KUR_AD,0)))) | J20: м | K20: =SUMIF(BOM!$D:$D,$B20,BOM!$I:$I) -> 10 | L20: =IF($I20="","",$I20*$K20) | N20: FIYAT_YOK | O20: Tam eşleşen artikül fiyat listesinde yok
A21: 20 | B21: KABLO-PUVNG-1X2.5 | C21: Провод ПуВнг(А)-LS 1х2,5 | D21: Кабель | E21: EKT | G21: =IF($E21="","",INDEX(MARKA_PARA,MATCH($E21,MARKA_AD,0))) -> KZT | H21: =IF($E21="","",INDEX(MARKA_KAT,MATCH($E21,MARKA_AD,0))) -> 1 | I21: =IF($F21="","",IF(INDEX(MARKA_TIP,MATCH($E21,MARKA_AD,0))="NET",$F21,$F21*INDEX(MARKA_KAT,MATCH($E21,MARKA_AD,0))*INDEX(KUR_DEG,MATCH($G21,KUR_AD,0)))) | J21: м | K21: =SUMIF(BOM!$D:$D,$B21,BOM!$I:$I) -> 10 | L21: =IF($I21="","",$I21*$K21) | N21: FIYAT_YOK | O21: Tam eşleşen artikül fiyat listesinde yok
A22: 21 | B22: KABLO-PV3-1X1.5 | C22: Провод ПВ-3 1х1,5 | D22: Кабель | E22: EKT | G22: =IF($E22="","",INDEX(MARKA_PARA,MATCH($E22,MARKA_AD,0))) -> KZT | H22: =IF($E22="","",INDEX(MARKA_KAT,MATCH($E22,MARKA_AD,0))) -> 1 | I22: =IF($F22="","",IF(INDEX(MARKA_TIP,MATCH($E22,MARKA_AD,0))="NET",$F22,$F22*INDEX(MARKA_KAT,MATCH($E22,MARKA_AD,0))*INDEX(KUR_DEG,MATCH($G22,KUR_AD,0)))) | J22: м | K22: =SUMIF(BOM!$D:$D,$B22,BOM!$I:$I) -> 100 | L22: =IF($I22="","",$I22*$K22) | N22: FIYAT_YOK | O22: Tam eşleşen artikül fiyat listesinde yok; miktar kaynakta '???' işaretli
A23: 22 | B23: KABLO-VVGNGFRLS-5X16 | C23: Кабель ВВГнг(А)-FRLS-0,66 5х16 | D23: Кабель | E23: EKT | G23: =IF($E23="","",INDEX(MARKA_PARA,MATCH($E23,MARKA_AD,0))) -> KZT | H23: =IF($E23="","",INDEX(MARKA_KAT,MATCH($E23,MARKA_AD,0))) -> 1 | I23: =IF($F23="","",IF(INDEX(MARKA_TIP,MATCH($E23,MARKA_AD,0))="NET",$F23,$F23*INDEX(MARKA_KAT,MATCH($E23,MARKA_AD,0))*INDEX(KUR_DEG,MATCH($G23,KUR_AD,0)))) | J23: м | K23: =SUMIF(BOM!$D:$D,$B23,BOM!$I:$I) -> 10 | L23: =IF($I23="","",$I23*$K23) | N23: FIYAT_YOK | O23: FRLS sertifikalı kablo fiyat listesinde yok
A24: 23 | B24: KABLO-VVGNGFRLS-5X2.5 | C24: Кабель ВВГнг(А)-FRLS-0,66 5х2,5 | D24: Кабель | E24: EKT | G24: =IF($E24="","",INDEX(MARKA_PARA,MATCH($E24,MARKA_AD,0))) -> KZT | H24: =IF($E24="","",INDEX(MARKA_KAT,MATCH($E24,MARKA_AD,0))) -> 1 | I24: =IF($F24="","",IF(INDEX(MARKA_TIP,MATCH($E24,MARKA_AD,0))="NET",$F24,$F24*INDEX(MARKA_KAT,MATCH($E24,MARKA_AD,0))*INDEX(KUR_DEG,MATCH($G24,KUR_AD,0)))) | J24: м | K24: =SUMIF(BOM!$D:$D,$B24,BOM!$I:$I) -> 10 | L24: =IF($I24="","",$I24*$K24) | N24: FIYAT_YOK | O24: FRLS sertifikalı kablo fiyat listesinde yok
A25: 24 | B25: KABLO-VVGNGFRLS-5X6 | C25: Кабель ВВГнг(А)-FRLS-0,66 5х6 | D25: Кабель | E25: EKT | G25: =IF($E25="","",INDEX(MARKA_PARA,MATCH($E25,MARKA_AD,0))) -> KZT | H25: =IF($E25="","",INDEX(MARKA_KAT,MATCH($E25,MARKA_AD,0))) -> 1 | I25: =IF($F25="","",IF(INDEX(MARKA_TIP,MATCH($E25,MARKA_AD,0))="NET",$F25,$F25*INDEX(MARKA_KAT,MATCH($E25,MARKA_AD,0))*INDEX(KUR_DEG,MATCH($G25,KUR_AD,0)))) | J25: м | K25: =SUMIF(BOM!$D:$D,$B25,BOM!$I:$I) -> 15 | L25: =IF($I25="","",$I25*$K25) | N25: FIYAT_YOK | O25: FRLS sertifikalı kablo fiyat listesinde yok
A26: 25 | B26: EKT-260100142 | C26: Каб. наконечник МЛ 16-6-6 | D26: Расходные материалы | E26: EKT | F26: 180 | G26: =IF($E26="","",INDEX(MARKA_PARA,MATCH($E26,MARKA_AD,0))) -> KZT | H26: =IF($E26="","",INDEX(MARKA_KAT,MATCH($E26,MARKA_AD,0))) -> 1 | I26: =IF($F26="","",IF(INDEX(MARKA_TIP,MATCH($E26,MARKA_AD,0))="NET",$F26,$F26*INDEX(MARKA_KAT,MATCH($E26,MARKA_AD,0))*INDEX(KUR_DEG,MATCH($G26,KUR_AD,0)))) -> 180 | J26: шт | K26: =SUMIF(BOM!$D:$D,$B26,BOM!$I:$I) -> 6 | L26: =IF($I26="","",$I26*$K26) -> 1080 | M26: EKT2506 (2025-06-12) | N26: VARSAYIM | O26: otomatik tamamlama — pabuç
A27: 26 | B27: EKT-311100743 | C27: Бирка кабельная У-134 (100шт/упак) | D27: Расходные материалы | E27: EKT | F27: 1209 | G27: =IF($E27="","",INDEX(MARKA_PARA,MATCH($E27,MARKA_AD,0))) -> KZT | H27: =IF($E27="","",INDEX(MARKA_KAT,MATCH($E27,MARKA_AD,0))) -> 1 | I27: =IF($F27="","",IF(INDEX(MARKA_TIP,MATCH($E27,MARKA_AD,0))="NET",$F27,$F27*INDEX(MARKA_KAT,MATCH($E27,MARKA_AD,0))*INDEX(KUR_DEG,MATCH($G27,KUR_AD,0)))) -> 1209 | J27: упак | K27: =SUMIF(BOM!$D:$D,$B27,BOM!$I:$I) -> 1 | L27: =IF($I27="","",$I27*$K27) -> 1209 | M27: EKT2506 (2025-06-12) | N27: VARSAYIM | O27: otomatik tamamlama — etiketleme
A28: 27 | B28: ISCILIK-MONTAJ | C28: Montaj işçiliği (dakika bazlı) | D28: Işçilik | E28: ISCILIK | F28: =ISCILIK_DK_UCRETI -> 58.333333 | G28: =IF($E28="","",INDEX(MARKA_PARA,MATCH($E28,MARKA_AD,0))) -> KZT | H28: =IF($E28="","",INDEX(MARKA_KAT,MATCH($E28,MARKA_AD,0))) -> 1 | I28: =IF($F28="","",IF(INDEX(MARKA_TIP,MATCH($E28,MARKA_AD,0))="NET",$F28,$F28*INDEX(MARKA_KAT,MATCH($E28,MARKA_AD,0))*INDEX(KUR_DEG,MATCH($G28,KUR_AD,0)))) -> 58.333333 | J28: dk | K28: =SUMIF(BOM!$D:$D,$B28,BOM!$I:$I) -> 1349 | L28: =IF($I28="","",$I28*$K28) -> 78691.667 | N28: OK | O28: F = ISCILIK_DK_UCRETI

Sheet BOM
A1: SIRA | B1: Наименование1 | C1: Тип | D1: Артикул | E1: Номенклатура | F1: Цена | G1: net | H1: H(GxI) | I1: Qty | J1: Ед.изм | K1: Завод | L1: tutar | M1: DURUM | N1: NOT | O1: KAYNAK | P1: NORM_ANAHTAR | Q1: DAKIKA
A2: 1 | B2: ЩН — Щит насосный (напольный, IP65, IP54min), 1 компл. | I2: 1 | J2: компл.
A3: 2 | B3: =IF($D3="","",$E3) -> Мет. Щит ВРУ (2000x800x600)+10 база — TEOS 2000x800x600 IP65 muadili | C3: Корпус | D3: KAZTEK-719-15923 | E3: =IF($D3="","",INDEX(FIYAT_ACK,MATCH($D3,FIYAT_ART,0))) -> Мет. Щит ВРУ (2000x800x600)+10 база — TEOS 2000x800x600 IP65 muadili | F3: =IF($D3="","",INDEX(FIYAT!$F$2:$F$28,MATCH($D3,FIYAT_ART,0))) -> 148675 | G3: =IF($D3="","",INDEX(FIYAT_NET,MATCH($D3,FIYAT_ART,0))) -> 89205 | H3: =IF(OR($G3="",$I3=""),"",$G3*$I3) -> 89205 | I3: 1 | J3: шт | K3: =IF($D3="","",INDEX(FIYAT!$E$2:$E$28,MATCH($D3,FIYAT_ART,0))) -> KAZTEK | L3: =IF($H3="","",$H3) -> 89205 | M3: =IF($D3="","",INDEX(FIYAT!$N$2:$N$28,MATCH($D3,FIYAT_ART,0))) -> MUADIL_ONAY | P3: KORPUS_AYAKLI | Q3: =IF($P3="","",$I3*INDEX(NORM_DK,MATCH($P3,NORM_AD,0))) -> 90
A4: 3 | B4: =IF($D4="","",$E4) -> #N/A | C4: ОТО | D4: ABB-S800S-3P-100A-C | E4: =IF($D4="","",INDEX(FIYAT_ACK,MATCH($D4,FIYAT_ART,0))) -> #N/A | F4: =IF($D4="","",INDEX(FIYAT!$F$2:$F$28,MATCH($D4,FIYAT_ART,0))) -> #N/A | G4: =IF($D4="","",INDEX(FIYAT_NET,MATCH($D4,FIYAT_ART,0))) -> #N/A | H4: =IF(OR($G4="",$I4=""),"",$G4*$I4) -> #N/A | I4: 1 | J4: шт | K4: =IF($D4="","",INDEX(FIYAT!$E$2:$E$28,MATCH($D4,FIYAT_ART,0))) -> #N/A | L4: =IF($H4="","",$H4) -> #N/A | M4: =IF($D4="","",INDEX(FIYAT!$N$2:$N$28,MATCH($D4,FIYAT_ART,0))) -> #N/A | N4: Ana giriş | P4: MCCB_ANA | Q4: =IF($P4="","",$I4*INDEX(NORM_DK,MATCH($P4,NORM_AD,0))) -> 60
A5: 4 | B5: =IF($D5="","",$E5) -> Автоматический выключатель S800S 3P 80A, х-ка D | C5: ОТО | D5: ABB-S800S-3P-80A-D | E5: =IF($D5="","",INDEX(FIYAT_ACK,MATCH($D5,FIYAT_ART,0))) -> Автоматический выключатель S800S 3P 80A, х-ка D | F5: =IF($D5="","",INDEX(FIYAT!$F$2:$F$28,MATCH($D5,FIYAT_ART,0))) -> 0 | G5: =IF($D5="","",INDEX(FIYAT_NET,MATCH($D5,FIYAT_ART,0))) | H5: =IF(OR($G5="",$I5=""),"",$G5*$I5) | I5: 2 | J5: шт | K5: =IF($D5="","",INDEX(FIYAT!$E$2:$E$28,MATCH($D5,FIYAT_ART,0))) -> ABB | L5: =IF($H5="","",$H5) | M5: =IF($D5="","",INDEX(FIYAT!$N$2:$N$28,MATCH($D5,FIYAT_ART,0))) -> FIYAT_YOK | N5: Motor/pompa hattı | P5: MCCB_BUYUK | Q5: =IF($P5="","",$I5*INDEX(NORM_DK,MATCH($P5,NORM_AD,0))) -> 120
A6: 5 | B6: =IF($D6="","",$E6) -> Устройство АВР NXZM-125S/3B 125A | C6: АВР | D6: CHINT-256780 | E6: =IF($D6="","",INDEX(FIYAT_ACK,MATCH($D6,FIYAT_ART,0))) -> Устройство АВР NXZM-125S/3B 125A | F6: =IF($D6="","",INDEX(FIYAT!$F$2:$F$28,MATCH($D6,FIYAT_ART,0))) -> 204604 | G6: =IF($D6="","",INDEX(FIYAT_NET,MATCH($D6,FIYAT_ART,0))) -> 122762.4 | H6: =IF(OR($G6="",$I6=""),"",$G6*$I6) -> 122762.4 | I6: 1 | J6: шт | K6: =IF($D6="","",INDEX(FIYAT!$E$2:$E$28,MATCH($D6,FIYAT_ART,0))) -> CHINT | L6: =IF($H6="","",$H6) -> 122762.4 | M6: =IF($D6="","",INDEX(FIYAT!$N$2:$N$28,MATCH($D6,FIYAT_ART,0))) -> OK | P6: MCCB_ANA | Q6: =IF($P6="","",$I6*INDEX(NORM_DK,MATCH($P6,NORM_AD,0))) -> 60
A7: 6 | B7: =IF($D7="","",$E7) -> Автоматический выключатель S203-C 3P 16A (S200S 16A muadili) | C7: ОТО | D7: ABB-2CDS253001R0164 | E7: =IF($D7="","",INDEX(FIYAT_ACK,MATCH($D7,FIYAT_ART,0))) -> Автоматический выключатель S203-C 3P 16A (S200S 16A muadili) | F7: =IF($D7="","",INDEX(FIYAT!$F$2:$F$28,MATCH($D7,FIYAT_ART,0))) -> 48.51 | G7: =IF($D7="","",INDEX(FIYAT_NET,MATCH($D7,FIYAT_ART,0))) -> 11689.697 | H7: =IF(OR($G7="",$I7=""),"",$G7*$I7) -> 11689.697 | I7: 1 | J7: шт | K7: =IF($D7="","",INDEX(FIYAT!$E$2:$E$28,MATCH($D7,FIYAT_ART,0))) -> ABB | L7: =IF($H7="","",$H7) -> 11689.697 | M7: MUADIL_ONAY | N7: Orijinal: S200S 3P16A (C) | P7: MCCB_KUCUK | Q7: =IF($P7="","",$I7*INDEX(NORM_DK,MATCH($P7,NORM_AD,0))) -> 45
A8: 7 | B8: =IF($D8="","",$E8) -> Автоматический выключатель S203-C 3P 16A (S200S 16A muadili) | C8: ОТО | D8: ABB-2CDS253001R0164 | E8: =IF($D8="","",INDEX(FIYAT_ACK,MATCH($D8,FIYAT_ART,0))) -> Автоматический выключатель S203-C 3P 16A (S200S 16A muadili) | F8: =IF($D8="","",INDEX(FIYAT!$F$2:$F$28,MATCH($D8,FIYAT_ART,0))) -> 48.51 | G8: =IF($D8="","",INDEX(FIYAT_NET,MATCH($D8,FIYAT_ART,0))) -> 11689.697 | H8: =IF(OR($G8="",$I8=""),"",$G8*$I8) -> 23379.395 | I8: 2 | J8: шт | K8: =IF($D8="","",INDEX(FIYAT!$E$2:$E$28,MATCH($D8,FIYAT_ART,0))) -> ABB | L8: =IF($H8="","",$H8) -> 23379.395 | M8: MUADIL_ONAY | N8: Orijinal: S200S 3P16A (D) — D eğrisi yok, C ile MUADIL | P8: MCCB_KUCUK | Q8: =IF($P8="","",$I8*INDEX(NORM_DK,MATCH($P8,NORM_AD,0))) -> 90
A9: 8 | B9: =IF($D9="","",$E9) -> Автоматический выключатель S203-C 3P 32A (S200S 32A D muadili) | C9: ОТО | D9: ABB-2CDS253001R0324 | E9: =IF($D9="","",INDEX(FIYAT_ACK,MATCH($D9,FIYAT_ART,0))) -> Автоматический выключатель S203-C 3P 32A (S200S 32A D muadili) | F9: =IF($D9="","",INDEX(FIYAT!$F$2:$F$28,MATCH($D9,FIYAT_ART,0))) -> 60.59 | G9: =IF($D9="","",INDEX(FIYAT_NET,MATCH($D9,FIYAT_ART,0))) -> 14600.675 | H9: =IF(OR($G9="",$I9=""),"",$G9*$I9) -> 14600.675 | I9: 1 | J9: шт | K9: =IF($D9="","",INDEX(FIYAT!$E$2:$E$28,MATCH($D9,FIYAT_ART,0))) -> ABB | L9: =IF($H9="","",$H9) -> 14600.675 | M9: MUADIL_ONAY | N9: Orijinal: S200S 3P32A (D) — D eğrisi yok, C ile MUADIL | P9: MCCB_KUCUK | Q9: =IF($P9="","",$I9*INDEX(NORM_DK,MATCH($P9,NORM_AD,0))) -> 45
A10: 9 | B10: =IF($D10="","",$E10) -> Basic M BMS311C10, 1P C10A | C10: ОТО | D10: ABB-2CDS631031R0104 | E10: =IF($D10="","",INDEX(FIYAT_ACK,MATCH($D10,FIYAT_ART,0))) -> Basic M BMS311C10, 1P C10A | F10: =IF($D10="","",INDEX(FIYAT!$F$2:$F$28,MATCH($D10,FIYAT_ART,0))) -> 4.95 | G10: =IF($D10="","",INDEX(FIYAT_NET,MATCH($D10,FIYAT_ART,0))) -> 1192.8263 | H10: =IF(OR($G10="",$I10=""),"",$G10*$I10) -> 2385.6525 | I10: 2 | J10: шт | K10: =IF($D10="","",INDEX(FIYAT!$E$2:$E$28,MATCH($D10,FIYAT_ART,0))) -> ABB | L10: =IF($H10="","",$H10) -> 2385.6525 | M10: =IF($D10="","",INDEX(FIYAT!$N$2:$N$28,MATCH($D10,FIYAT_ART,0))) -> OK | P10: MCB_1P | Q10: =IF($P10="","",$I10*INDEX(NORM_DK,MATCH($P10,NORM_AD,0))) -> 20
A11: 10 | B11: =IF($D11="","",$E11) -> Многофункциональный измерительный прибор SM-E | C11: Прибор | D11: EKF-SME-MUADIL-YOK | E11: =IF($D11="","",INDEX(FIYAT_ACK,MATCH($D11,FIYAT_ART,0))) -> Многофункциональный измерительный прибор SM-E | F11: =IF($D11="","",INDEX(FIYAT!$F$2:$F$28,MATCH($D11,FIYAT_ART,0))) -> 0 | G11: =IF($D11="","",INDEX(FIYAT_NET,MATCH($D11,FIYAT_ART,0))) | H11: =IF(OR($G11="",$I11=""),"",$G11*$I11) | I11: 1 | J11: шт | K11: =IF($D11="","",INDEX(FIYAT!$E$2:$E$28,MATCH($D11,FIYAT_ART,0))) -> EKF | L11: =IF($H11="","",$H11) | M11: =IF($D11="","",INDEX(FIYAT!$N$2:$N$28,MATCH($D11,FIYAT_ART,0))) -> FIYAT_YOK | P11: SAYAC_AT | Q11: =IF($P11="","",$I11*INDEX(NORM_DK,MATCH($P11,NORM_AD,0))) -> 90
A12: 11 | B12: =IF($D12="","",$E12) -> Устройство плавного пуска PSR72-600-70 | C12: Плавный пуск | D12: ABB-1SFA896113R7000 | E12: =IF($D12="","",INDEX(FIYAT_ACK,MATCH($D12,FIYAT_ART,0))) -> Устройство плавного пуска PSR72-600-70 | F12: =IF($D12="","",INDEX(FIYAT!$F$2:$F$28,MATCH($D12,FIYAT_ART,0))) -> 859.7 | G12: =IF($D12="","",INDEX(FIYAT_NET,MATCH($D12,FIYAT_ART,0))) -> 207166.21 | H12: =IF(OR($G12="",$I12=""),"",$G12*$I12) -> 414332.42 | I12: 2 | J12: шт | K12: =IF($D12="","",INDEX(FIYAT!$E$2:$E$28,MATCH($D12,FIYAT_ART,0))) -> ABB | L12: =IF($H12="","",$H12) -> 414332.42 | M12: =IF($D12="","",INDEX(FIYAT!$N$2:$N$28,MATCH($D12,FIYAT_ART,0))) -> OK | P12: YUMUSAK_YOLVERICI | Q12: =IF($P12="","",$I12*INDEX(NORM_DK,MATCH($P12,NORM_AD,0))) -> 90
A13: 12 | B13: =IF($D13="","",$E13) -> Устройство плавного пуска PSR12-600-70 | C13: Плавный пуск | D13: ABB-1SFA896106R7000 | E13: =IF($D13="","",INDEX(FIYAT_ACK,MATCH($D13,FIYAT_ART,0))) -> Устройство плавного пуска PSR12-600-70 | F13: =IF($D13="","",INDEX(FIYAT!$F$2:$F$28,MATCH($D13,FIYAT_ART,0))) -> 248 | G13: =IF($D13="","",INDEX(FIYAT_NET,MATCH($D13,FIYAT_ART,0))) -> 59761.8 | H13: =IF(OR($G13="",$I13=""),"",$G13*$I13) -> 119523.6 | I13: 2 | J13: шт | K13: =IF($D13="","",INDEX(FIYAT!$E$2:$E$28,MATCH($D13,FIYAT_ART,0))) -> ABB | L13: =IF($H13="","",$H13) -> 119523.6 | M13: =IF($D13="","",INDEX(FIYAT!$N$2:$N$28,MATCH($D13,FIYAT_ART,0))) -> OK | P13: YUMUSAK_YOLVERICI | Q13: =IF($P13="","",$I13*INDEX(NORM_DK,MATCH($P13,NORM_AD,0))) -> 90
A14: 13 | B14: =IF($D14="","",$E14) -> Трансформатор тока ТТИ-А 100/5А 5ВА кл.0,5 (TTE-30-100/5A muadili) | C14: ТТ | D14: EKT-270300099 | E14: =IF($D14="","",INDEX(FIYAT_ACK,MATCH($D14,FIYAT_ART,0))) -> Трансформатор тока ТТИ-А 100/5А 5ВА кл.0,5 (TTE-30-100/5A muadili) | F14: =IF($D14="","",INDEX(FIYAT!$F$2:$F$28,MATCH($D14,FIYAT_ART,0))) -> 5047 | G14: =IF($D14="","",INDEX(FIYAT_NET,MATCH($D14,FIYAT_ART,0))) -> 5047 | H14: =IF(OR($G14="",$I14=""),"",$G14*$I14) -> 15141 | I14: 3 | J14: шт | K14: =IF($D14="","",INDEX(FIYAT!$E$2:$E$28,MATCH($D14,FIYAT_ART,0))) -> EKT | L14: =IF($H14="","",$H14) -> 15141 | M14: =IF($D14="","",INDEX(FIYAT!$N$2:$N$28,MATCH($D14,FIYAT_ART,0))) -> MUADIL | N14: İşçiliği Прибор (SAYAC_AT) satırına dahil | Q14: =IF($P14="","",$I14*INDEX(NORM_DK,MATCH($P14,NORM_AD,0)))
A15: 14 | B15: =IF($D15="","",$E15) -> Basic M BMS311C06, 1P C6A | C15: ОТО | D15: ABB-2CDS631031R0064 | E15: =IF($D15="","",INDEX(FIYAT_ACK,MATCH($D15,FIYAT_ART,0))) -> Basic M BMS311C06, 1P C6A | F15: =IF($D15="","",INDEX(FIYAT!$F$2:$F$28,MATCH($D15,FIYAT_ART,0))) -> 5.94 | G15: =IF($D15="","",INDEX(FIYAT_NET,MATCH($D15,FIYAT_ART,0))) -> 1431.3915 | H15: =IF(OR($G15="",$I15=""),"",$G15*$I15) -> 5725.566 | I15: 4 | J15: шт | K15: =IF($D15="","",INDEX(FIYAT!$E$2:$E$28,MATCH($D15,FIYAT_ART,0))) -> ABB | L15: =IF($H15="","",$H15) -> 5725.566 | M15: =IF($D15="","",INDEX(FIYAT!$N$2:$N$28,MATCH($D15,FIYAT_ART,0))) -> OK | N15: Kumanda devresi koruması | P15: MCB_1P | Q15: =IF($P15="","",$I15*INDEX(NORM_DK,MATCH($P15,NORM_AD,0))) -> 40
A16: 15 | B16: =IF($D16="","",$E16) -> Клемма проходная 32A (0,08-4мм, 2х2) | C16: Клеммник | D16: EKT-030300442 | E16: =IF($D16="","",INDEX(FIYAT_ACK,MATCH($D16,FIYAT_ART,0))) -> Клемма проходная 32A (0,08-4мм, 2х2) | F16: =IF($D16="","",INDEX(FIYAT!$F$2:$F$28,MATCH($D16,FIYAT_ART,0))) -> 210 | G16: =IF($D16="","",INDEX(FIYAT_NET,MATCH($D16,FIYAT_ART,0))) -> 210 | H16: =IF(OR($G16="",$I16=""),"",$G16*$I16) -> 8820 | I16: 42 | J16: шт | K16: =IF($D16="","",INDEX(FIYAT!$E$2:$E$28,MATCH($D16,FIYAT_ART,0))) -> EKT | L16: =IF($H16="","",$H16) -> 8820 | M16: VARSAYIM | N16: Otomatik hesap: bkz KURALLAR BLOK5 | P16: KLEMENS | Q16: =IF($P16="","",$I16*INDEX(NORM_DK,MATCH($P16,NORM_AD,0))) -> 168
A17: 16 | B17: =IF($D17="","",$E17) -> Шина N/PE ШНИ-6х9-6-Д-С (изолированная) | C17: Шина N | D17: EKT-130200088 | E17: =IF($D17="","",INDEX(FIYAT_ACK,MATCH($D17,FIYAT_ART,0))) -> Шина N/PE ШНИ-6х9-6-Д-С (изолированная) | F17: =IF($D17="","",INDEX(FIYAT!$F$2:$F$28,MATCH($D17,FIYAT_ART,0))) -> 307 | G17: =IF($D17="","",INDEX(FIYAT_NET,MATCH($D17,FIYAT_ART,0))) -> 307 | H17: =IF(OR($G17="",$I17=""),"",$G17*$I17) -> 307 | I17: 1 | J17: шт | K17: =IF($D17="","",INDEX(FIYAT!$E$2:$E$28,MATCH($D17,FIYAT_ART,0))) -> EKT | L17: =IF($H17="","",$H17) -> 307 | M17: VARSAYIM | P17: BARA_KUCUK_N_PE | Q17: =IF($P17="","",$I17*INDEX(NORM_DK,MATCH($P17,NORM_AD,0))) -> 10
A18: 17 | B18: =IF($D18="","",$E18) -> Шина N/PE ШНИ-6х9-6-Д-С (изолированная) | C18: Шина PE | D18: EKT-130200088 | E18: =IF($D18="","",INDEX(FIYAT_ACK,MATCH($D18,FIYAT_ART,0))) -> Шина N/PE ШНИ-6х9-6-Д-С (изолированная) | F18: =IF($D18="","",INDEX(FIYAT!$F$2:$F$28,MATCH($D18,FIYAT_ART,0))) -> 307 | G18: =IF($D18="","",INDEX(FIYAT_NET,MATCH($D18,FIYAT_ART,0))) -> 307 | H18: =IF(OR($G18="",$I18=""),"",$G18*$I18) -> 307 | I18: 1 | J18: шт | K18: =IF($D18="","",INDEX(FIYAT!$E$2:$E$28,MATCH($D18,FIYAT_ART,0))) -> EKT | L18: =IF($H18="","",$H18) -> 307 | M18: VARSAYIM | P18: BARA_KUCUK_N_PE | Q18: =IF($P18="","",$I18*INDEX(NORM_DK,MATCH($P18,NORM_AD,0))) -> 10
A19: 18 | B19: =IF($D19="","",$E19) -> Медный заземляющий провод Ø16мм2 | C19: Заземление | D19: KAZTEK-444-03054 | E19: =IF($D19="","",INDEX(FIYAT_ACK,MATCH($D19,FIYAT_ART,0))) -> Медный заземляющий провод Ø16мм2 | F19: =IF($D19="","",INDEX(FIYAT!$F$2:$F$28,MATCH($D19,FIYAT_ART,0))) -> 2000 | G19: =IF($D19="","",INDEX(FIYAT_NET,MATCH($D19,FIYAT_ART,0))) -> 1200 | H19: =IF(OR($G19="",$I19=""),"",$G19*$I19) -> 360 | I19: 0.3 | J19: м | K19: =IF($D19="","",INDEX(FIYAT!$E$2:$E$28,MATCH($D19,FIYAT_ART,0))) -> KAZTEK | L19: =IF($H19="","",$H19) -> 360 | M19: =IF($D19="","",INDEX(FIYAT!$N$2:$N$28,MATCH($D19,FIYAT_ART,0))) -> OK | N19: Kapak-gövde topraklama bağlantısı | Q19: =IF($P19="","",$I19*INDEX(NORM_DK,MATCH($P19,NORM_AD,0)))
A20: 19 | B20: =IF($D20="","",$E20) -> DIN-рейка оцинкованная TH35-7.5, 200см | C20: DIN рейка | D20: CHINT-570003 | E20: =IF($D20="","",INDEX(FIYAT_ACK,MATCH($D20,FIYAT_ART,0))) -> DIN-рейка оцинкованная TH35-7.5, 200см | F20: =IF($D20="","",INDEX(FIYAT!$F$2:$F$28,MATCH($D20,FIYAT_ART,0))) -> 2232 | G20: =IF($D20="","",INDEX(FIYAT_NET,MATCH($D20,FIYAT_ART,0))) -> 1339.2 | H20: =IF(OR($G20="",$I20=""),"",$G20*$I20) -> 1339.2 | I20: 1 | J20: шт(200см) | K20: =IF($D20="","",INDEX(FIYAT!$E$2:$E$28,MATCH($D20,FIYAT_ART,0))) -> CHINT | L20: =IF($H20="","",$H20) -> 1339.2 | M20: VARSAYIM | N20: ≈2,0 m gerekli (modül hesabı) | Q20: =2*INDEX(NORM_DK,MATCH("DINRAY_KANAL_M",NORM_AD,0)) -> 10
A21: 20 | B21: =IF($D21="","",$E21) -> Лоток перфорированный 50х50х3000 (0,7мм) | C21: Кабельный канал | D21: EKT-280300704 | E21: =IF($D21="","",INDEX(FIYAT_ACK,MATCH($D21,FIYAT_ART,0))) -> Лоток перфорированный 50х50х3000 (0,7мм) | F21: =IF($D21="","",INDEX(FIYAT!$F$2:$F$28,MATCH($D21,FIYAT_ART,0))) -> 1022 | G21: =IF($D21="","",INDEX(FIYAT_NET,MATCH($D21,FIYAT_ART,0))) -> 1022 | H21: =IF(OR($G21="",$I21=""),"",$G21*$I21) -> 7154 | I21: 7 | J21: м | K21: =IF($D21="","",INDEX(FIYAT!$E$2:$E$28,MATCH($D21,FIYAT_ART,0))) -> EKT | L21: =IF($H21="","",$H21) -> 7154 | M21: VARSAYIM | N21: Perforeli tercih kuralı uygulandı | Q21: =7*INDEX(NORM_DK,MATCH("DINRAY_KANAL_M",NORM_AD,0)) -> 35
A22: 21 | B22: =IF($D22="","",$E22) -> Провод ПуВнг(А)-LS 1х16 | C22: Кабель | D22: KABLO-PUVNG-1X16 | E22: =IF($D22="","",INDEX(FIYAT_ACK,MATCH($D22,FIYAT_ART,0))) -> Провод ПуВнг(А)-LS 1х16 | F22: =IF($D22="","",INDEX(FIYAT!$F$2:$F$28,MATCH($D22,FIYAT_ART,0))) -> 0 | G22: =IF($D22="","",INDEX(FIYAT_NET,MATCH($D22,FIYAT_ART,0))) | H22: =IF(OR($G22="",$I22=""),"",$G22*$I22) | I22: 10 | J22: м | K22: =IF($D22="","",INDEX(FIYAT!$E$2:$E$28,MATCH($D22,FIYAT_ART,0))) -> EKT | L22: =IF($H22="","",$H22) | M22: =IF($D22="","",INDEX(FIYAT!$N$2:$N$28,MATCH($D22,FIYAT_ART,0))) -> FIYAT_YOK | N22: силовые цепи | Q22: =IF($P22="","",$I22*INDEX(NORM_DK,MATCH($P22,NORM_AD,0)))
A23: 22 | B23: =IF($D23="","",$E23) -> Провод ПуВнг(А)-LS 1х25 | C23: Кабель | D23: KABLO-PUVNG-1X25 | E23: =IF($D23="","",INDEX(FIYAT_ACK,MATCH($D23,FIYAT_ART,0))) -> Провод ПуВнг(А)-LS 1х25 | F23: =IF($D23="","",INDEX(FIYAT!$F$2:$F$28,MATCH($D23,FIYAT_ART,0))) -> 0 | G23: =IF($D23="","",INDEX(FIYAT_NET,MATCH($D23,FIYAT_ART,0))) | H23: =IF(OR($G23="",$I23=""),"",$G23*$I23) | I23: 10 | J23: м | K23: =IF($D23="","",INDEX(FIYAT!$E$2:$E$28,MATCH($D23,FIYAT_ART,0))) -> EKT | L23: =IF($H23="","",$H23) | M23: =IF($D23="","",INDEX(FIYAT!$N$2:$N$28,MATCH($D23,FIYAT_ART,0))) -> FIYAT_YOK | N23: силовые цепи | Q23: =IF($P23="","",$I23*INDEX(NORM_DK,MATCH($P23,NORM_AD,0)))
A24: 23 | B24: =IF($D24="","",$E24) -> Провод ПуВнг(А)-LS 1х2,5 | C24: Кабель | D24: KABLO-PUVNG-1X2.5 | E24: =IF($D24="","",INDEX(FIYAT_ACK,MATCH($D24,FIYAT_ART,0))) -> Провод ПуВнг(А)-LS 1х2,5 | F24: =IF($D24="","",INDEX(FIYAT!$F$2:$F$28,MATCH($D24,FIYAT_ART,0))) -> 0 | G24: =IF($D24="","",INDEX(FIYAT_NET,MATCH($D24,FIYAT_ART,0))) | H24: =IF(OR($G24="",$I24=""),"",$G24*$I24) | I24: 10 | J24: м | K24: =IF($D24="","",INDEX(FIYAT!$E$2:$E$28,MATCH($D24,FIYAT_ART,0))) -> EKT | L24: =IF($H24="","",$H24) | M24: =IF($D24="","",INDEX(FIYAT!$N$2:$N$28,MATCH($D24,FIYAT_ART,0))) -> FIYAT_YOK | N24: силовые токовые цепи | Q24: =IF($P24="","",$I24*INDEX(NORM_DK,MATCH($P24,NORM_AD,0)))
A25: 24 | B25: =IF($D25="","",$E25) -> Провод ПВ-3 1х1,5 | C25: Кабель | D25: KABLO-PV3-1X1.5 | E25: =IF($D25="","",INDEX(FIYAT_ACK,MATCH($D25,FIYAT_ART,0))) -> Провод ПВ-3 1х1,5 | F25: =IF($D25="","",INDEX(FIYAT!$F$2:$F$28,MATCH($D25,FIYAT_ART,0))) -> 0 | G25: =IF($D25="","",INDEX(FIYAT_NET,MATCH($D25,FIYAT_ART,0))) | H25: =IF(OR($G25="",$I25=""),"",$G25*$I25) | I25: 100 | J25: м | K25: =IF($D25="","",INDEX(FIYAT!$E$2:$E$28,MATCH($D25,FIYAT_ART,0))) -> EKT | L25: =IF($H25="","",$H25) | M25: KONTROL | N25: обвязка цепей управления | Q25: =IF($P25="","",$I25*INDEX(NORM_DK,MATCH($P25,NORM_AD,0)))
A26: 25 | B26: =IF($D26="","",$E26) -> Кабель ВВГнг(А)-FRLS-0,66 5х16 | C26: Кабель | D26: KABLO-VVGNGFRLS-5X16 | E26: =IF($D26="","",INDEX(FIYAT_ACK,MATCH($D26,FIYAT_ART,0))) -> Кабель ВВГнг(А)-FRLS-0,66 5х16 | F26: =IF($D26="","",INDEX(FIYAT!$F$2:$F$28,MATCH($D26,FIYAT_ART,0))) -> 0 | G26: =IF($D26="","",INDEX(FIYAT_NET,MATCH($D26,FIYAT_ART,0))) | H26: =IF(OR($G26="",$I26=""),"",$G26*$I26) | I26: 10 | J26: м | K26: =IF($D26="","",INDEX(FIYAT!$E$2:$E$28,MATCH($D26,FIYAT_ART,0))) -> EKT | L26: =IF($H26="","",$H26) | M26: =IF($D26="","",INDEX(FIYAT!$N$2:$N$28,MATCH($D26,FIYAT_ART,0))) -> FIYAT_YOK | N26: кабели питания насосов | Q26: =IF($P26="","",$I26*INDEX(NORM_DK,MATCH($P26,NORM_AD,0)))
A27: 26 | B27: =IF($D27="","",$E27) -> Кабель ВВГнг(А)-FRLS-0,66 5х2,5 | C27: Кабель | D27: KABLO-VVGNGFRLS-5X2.5 | E27: =IF($D27="","",INDEX(FIYAT_ACK,MATCH($D27,FIYAT_ART,0))) -> Кабель ВВГнг(А)-FRLS-0,66 5х2,5 | F27: =IF($D27="","",INDEX(FIYAT!$F$2:$F$28,MATCH($D27,FIYAT_ART,0))) -> 0 | G27: =IF($D27="","",INDEX(FIYAT_NET,MATCH($D27,FIYAT_ART,0))) | H27: =IF(OR($G27="",$I27=""),"",$G27*$I27) | I27: 10 | J27: м | K27: =IF($D27="","",INDEX(FIYAT!$E$2:$E$28,MATCH($D27,FIYAT_ART,0))) -> EKT | L27: =IF($H27="","",$H27) | M27: =IF($D27="","",INDEX(FIYAT!$N$2:$N$28,MATCH($D27,FIYAT_ART,0))) -> FIYAT_YOK | Q27: =IF($P27="","",$I27*INDEX(NORM_DK,MATCH($P27,NORM_AD,0)))
A28: 27 | B28: =IF($D28="","",$E28) -> Кабель ВВГнг(А)-FRLS-0,66 5х6 | C28: Кабель | D28: KABLO-VVGNGFRLS-5X6 | E28: =IF($D28="","",INDEX(FIYAT_ACK,MATCH($D28,FIYAT_ART,0))) -> Кабель ВВГнг(А)-FRLS-0,66 5х6 | F28: =IF($D28="","",INDEX(FIYAT!$F$2:$F$28,MATCH($D28,FIYAT_ART,0))) -> 0 | G28: =IF($D28="","",INDEX(FIYAT_NET,MATCH($D28,FIYAT_ART,0))) | H28: =IF(OR($G28="",$I28=""),"",$G28*$I28) | I28: 15 | J28: м | K28: =IF($D28="","",INDEX(FIYAT!$E$2:$E$28,MATCH($D28,FIYAT_ART,0))) -> EKT | L28: =IF($H28="","",$H28) | M28: =IF($D28="","",INDEX(FIYAT!$N$2:$N$28,MATCH($D28,FIYAT_ART,0))) -> FIYAT_YOK | Q28: =IF($P28="","",$I28*INDEX(NORM_DK,MATCH($P28,NORM_AD,0)))
A29: 28 | B29: =IF($D29="","",$E29) -> Каб. наконечник МЛ 16-6-6 | C29: Расходные материалы | D29: EKT-260100142 | E29: =IF($D29="","",INDEX(FIYAT_ACK,MATCH($D29,FIYAT_ART,0))) -> Каб. наконечник МЛ 16-6-6 | F29: =IF($D29="","",INDEX(FIYAT!$F$2:$F$28,MATCH($D29,FIYAT_ART,0))) -> 180 | G29: =IF($D29="","",INDEX(FIYAT_NET,MATCH($D29,FIYAT_ART,0))) -> 180 | H29: =IF(OR($G29="",$I29=""),"",$G29*$I29) -> 1080 | I29: 6 | J29: шт | K29: =IF($D29="","",INDEX(FIYAT!$E$2:$E$28,MATCH($D29,FIYAT_ART,0))) -> EKT | L29: =IF($H29="","",$H29) -> 1080 | M29: VARSAYIM | N29: otomatik tamamlama — pabuç | Q29: =IF($P29="","",$I29*INDEX(NORM_DK,MATCH($P29,NORM_AD,0)))
A30: 29 | B30: =IF($D30="","",$E30) -> Бирка кабельная У-134 (100шт/упак) | C30: Расходные материалы | D30: EKT-311100743 | E30: =IF($D30="","",INDEX(FIYAT_ACK,MATCH($D30,FIYAT_ART,0))) -> Бирка кабельная У-134 (100шт/упак) | F30: =IF($D30="","",INDEX(FIYAT!$F$2:$F$28,MATCH($D30,FIYAT_ART,0))) -> 1209 | G30: =IF($D30="","",INDEX(FIYAT_NET,MATCH($D30,FIYAT_ART,0))) -> 1209 | H30: =IF(OR($G30="",$I30=""),"",$G30*$I30) -> 1209 | I30: 1 | J30: упак | K30: =IF($D30="","",INDEX(FIYAT!$E$2:$E$28,MATCH($D30,FIYAT_ART,0))) -> EKT | L30: =IF($H30="","",$H30) -> 1209 | M30: VARSAYIM | N30: otomatik tamamlama — etiketleme | Q30: =IF($P30="","",$I30*INDEX(NORM_DK,MATCH($P30,NORM_AD,0)))
A31: 30 | B31: =IF($D31="","",$E31) -> Montaj işçiliği (dakika bazlı) | C31: Монтажные работы | D31: ISCILIK-MONTAJ | E31: =IF($D31="","",INDEX(FIYAT_ACK,MATCH($D31,FIYAT_ART,0))) -> Montaj işçiliği (dakika bazlı) | F31: =IF($D31="","",INDEX(FIYAT!$F$2:$F$28,MATCH($D31,FIYAT_ART,0))) -> 58.333333 | G31: =IF($D31="","",INDEX(FIYAT_NET,MATCH($D31,FIYAT_ART,0))) -> 58.333333 | H31: =IF(OR($G31="",$I31=""),"",$G31*$I31) -> 78691.667 | I31: =ROUND((SUM($Q2:$Q30)+INDEX(NORM_DK,MATCH("SABIT_HAZIRLIK_TEST_AMBALAJ",NORM_AD,0)))*TEST_ETIKET_CARPANI,1) -> 1349 | J31: dk | K31: ISCILIK | L31: =IF($H31="","",$H31) -> 78691.667 | M31: OK | N31: dakika = Σ satır işçilikleri + sabit hazırlık/test/ambalaj, x TEST_ETIKET_CARPANI
B32: Toplam ЩН | H32: =SUBTOTAL(9,H2:H31) -> #N/A | L32: =SUBTOTAL(9,L2:L31) -> #N/A

Sheet OZET
A1: SIRA | B1: PANO | C1: ADET | D1: MALZEME | E1: IŞÇİLİK | F1: BİRİM | G1: TOPLAM | H1: MODÜL | I1: KAPASİTE | J1: DOLULUK% | K1: YEDEK% | L1: BARA m | M1: BARA kg | N1: BARA TUTARI | O1: FIYAT_YOK adedi | P1: MUADIL adedi | Q1: VARSAYIM adedi
A2: 1 | B2: ЩН | C2: 1 | D2: =SUM(BOM!L2:L30) -> #N/A | E2: =BOM!L31 -> 78691.667 | F2: =D2+E2 -> #N/A | G2: =F2*C2 -> #N/A | H2: 104 | I2: 300 | J2: =H2/I2 -> 0.34666667 | K2: =1-J2 -> 0.65333333 | L2: 0 | M2: 0 | N2: 0 | O2: =COUNTIF(FIYAT!$N:$N,"FIYAT_YOK") -> 10 | P2: =COUNTIF(FIYAT!$N:$N,"MUADIL")+COUNTIF(FIYAT!$N:$N,"MUADIL_ONAY") -> 4 | Q2: =COUNTIF(FIYAT!$N:$N,"VARSAYIM") -> 3
B4: NOT: MODÜL/KAPASİTE değerleri yerleşim planı olmadan VARSAYIM'dır (bkz. KURALLAR BLOK5). Ana şalter ≤125A → BARA satırları 0 (kablo köprü + kompakt N/PE terminal barası kullanıldı).
A6: GENEL TOPLAM (malzeme+işçilik, KZT) | B6: =SUM(G2:G2) -> #N/A
A7: FIYAT_YOK kalem sayısı | B7: =O2 -> 10
A8: DURUM DAMGASI | B8: =IF(SUM(O2:O2)>0,"TEKLİFE HAZIR DEĞİL",IF(SUM(P2:P2)+SUM(Q2:Q2)>0,"ŞARTLI","TEKLİFE HAZIR")) -> TEKLİFE HAZIR DEĞİL

Sheet TEKLIF
A1: TEKLİF
A3: Teklif No: | B3: 260914-AKT-BEKET-01
A4: Tarih: | B4: 2026-09-14
A5: Geçerlilik: | B5: =TEKLIF_GECERLILIK&" gün" -> 0,12 gün
A6: Müşteri: | B6: Aktau — Beket (proje)
A7: Proje: | B7: 260914 Aktau Beket — ЩН
A8: Para birimi: | B8: KZT
A10: =IF(COUNTIF(FIYAT!$N:$N,"FIYAT_YOK")>0,"ТЕКЛИФ ЭКСИК — "&COUNTIF(FIYAT!$N:$N,"FIYAT_YOK")&" KALEM FİYATSIZ","") -> ТЕКЛИФ ЭКСИК — 10 KALEM FİYATSIZ
A12: № | B12: Наименование | C12: Кол-во | D12: Ед.изм | E12: Цена за ед. | F12: Сумма
A13: 1 | B13: ЩН — Щит насосный, напольный IP65 (в комплекте, ABB/CHINT/EKT/KAZTEK) | C13: =OZET!C2 -> 1 | D13: компл. | E13: =OZET!F2*(1+KAR_ORANI) -> #N/A | F13: =E13*C13 -> #N/A
E15: Итого: | F15: =SUM(F13:F13) -> #N/A
E16: Скидка (ISKONTO): | F16: =F15*ISKONTO -> #N/A
E17: Итого со скидкой: | F17: =F15-F16 -> #N/A
E18: НДС (NDS_ORANI): | F18: =F17*NDS_ORANI -> #N/A
E19: Всего с НДС: | F19: =F17+F18 -> #N/A
A21: Срок изготовления: | B21: =URETIM_SURESI&" iş günü" -> 15 iş günü
A22: Условия оплаты: | B22: =ODEME_SARTI -> %50 avans, %50 teslimatta
A23: Гарантия: | B23: =GARANTI -> 12 ay
