Workbook

Sheet KURALLAR
A1: YSF HICH — PANO BOM / MALIYET KURALLARI (APEX CNC listesi -> CHINT donusumu)
A3: BLOK 1 — KUR TABLOSU
A4: PARA | B4: KUR | C4: TARIH
A5: KZT | B5: 1 | C5: 2026-09-08
A6: USD | B6: 548 | C6: 2026-09-08
A7: EUR | B7: 590 | C7: 2026-09-08
A8: TRY | B8: 13.8 | C8: 2026-09-08
A10: BLOK 2 — MARKA KURAL TABLOSU
A11: MARKA | B11: PARA | C11: KATSAYI1 | D11: KATSAYI2 | E11: TOPLAM | F11: GIRDI_TIPI | G11: NOT
A12: ABB | B12: EUR | C12: 1.35 | D12: 0.3 | E12: =C12*D12 -> 0.405 | F12: LISTE | G12: standart
A13: SCHNEIDER | B13: EUR | C13: 0.6 | D13: 1 | E13: =C13*D13 -> 0.6 | F13: LISTE | G13: fiyat listesi bu dosyada yok — FIYAT_YOK
A14: CHINT | B14: KZT | C14: 0.6 | D14: 1 | E14: =C14*D14 -> 0.6 | F14: LISTE | G14: %40 iskonto; liste 27.08.2026 / 02.02.2026
A15: CNC | B15: KZT | C15: 0.55 | D15: 1 | E15: =C15*D15 -> 0.55 | F15: LISTE | G15: kullanilmadi (donusum kaynagi)
A16: IEK | B16: KZT | C16: 1 | D16: 1 | E16: =C16*D16 -> 1 | F16: LISTE
A17: EKF | B17: KZT | C17: 1 | D17: 1 | E17: =C17*D17 -> 1 | F17: LISTE | G17: referans, fiyat yasak
A18: EKT | B18: KZT | C18: 1 | D18: 1 | E18: =C18*D18 -> 1 | F18: LISTE | G18: liste 2025-06-12 — GUNCELLE
A19: KAZTEK | B19: KZT | C19: 0.6 | D19: 1 | E19: =C19*D19 -> 0.6 | F19: LISTE | G19: korpus, liste 2026-07-15
A20: BAKIR-BARA | B20: KZT | C20: 1 | D20: 1 | E20: =C20*D20 -> 1 | F20: NET | G20: kg fiyatindan hesaplanir
A21: ALUM-BARA | B21: KZT | C21: 1 | D21: 1 | E21: =C21*D21 -> 1 | F21: NET | G21: kg fiyatindan hesaplanir
A22: MUADIL-NET | B22: KZT | C22: 1 | D22: 1 | E22: =C22*D22 -> 1 | F22: NET
A23: ISCILIK | B23: KZT | C23: 1 | D23: 1 | E23: =C23*D23 -> 1 | F23: NET
A25: BLOK 3 — ISCILIK VE MONTAJ SARFI (TEKLED normlari — sari hucreler duzenlenebilir)
A26: ISCILIK_DK_UCRETI (KZT/dakika) | B26: 100
A27: TEST_ETIKET_CARPANI | B27: 1.15
A28: MONTAJ_MALZEME_ORANI (malzeme bedelinin %) | B28: 0.07
A30: NORM TABLOSU (dakika / adet)
A31: NORM_KEY | B31: DAKIKA | C31: ACIKLAMA
A32: OTO_1P | B32: 3 | C32: modüler otomat 1P
A33: OTO_2P | B33: 5 | C33: modüler otomat 2P
A34: OTO_3P | B34: 8 | C34: modüler otomat 3P
A35: OTO_4P | B35: 10 | C35: modüler otomat 4P
A36: DIF_2P | B36: 6 | C36: UZO/dif. otomat 1P+N-2P
A37: DIF_4P | B37: 10 | C37: UZO/dif. otomat 4P
A38: DIF_MODUL | B38: 20 | C38: kompakt salter dif. modulu
A39: TMS_125 | B39: 15 | C39: kompakt salter 125 govde
A40: TMS_250 | B40: 25 | C40: kompakt salter 250 govde
A41: TMS_400 | B41: 40 | C41: kompakt salter 400 govde
A42: TMS_630 | B42: 55 | C42: kompakt salter 630 govde
A43: TMS_1600 | B43: 90 | C43: kompakt salter 1600 govde
... A63: KONDANSATOR | B63: 20 | C63: kompanzasyon kondansatoru
...

Sheet FIYAT
A1: SIRA | B1: ARTIKUL | C1: НОМЕНКЛАТУРА | D1: TIP | E1: MARKA | F1: LISTE_FIYAT | G1: PARA | H1: KATSAYI | I1: NET_KZT | J1: BIRIM | K1: TOPLAM_ADET | L1: TOPLAM_TUTAR | M1: KAYNAK | N1: DURUM | O1: NOT | P1: BAZ_DURUM
A2: 1 | B2: 271534 | C2: Авт. выкл. NM8N-125C TM 3P 32А 36кА с рег. термомаг. расцепителем (R) | D2: TMS | E2: CHINT | F2: 64667 | G2: =IFERROR(VLOOKUP($E2,KURALLAR!$A$12:$E$23,2,FALSE()),"KZT") -> KZT | H2: =IFERROR(VLOOKUP($E2,KURALLAR!$A$12:$E$23,5,FALSE()),1) -> 0.6 | I2: =IF($F2="","",$F2*$H2*IFERROR(VLOOKUP($G2,KURALLAR!$A$5:$B$8,2,FALSE()),1)) -> 38800.2 | J2: Шт. | K2: =SUMIF(BOM!$D:$D,$B2,BOM!$I:$I) -> 59 | L2: =SUMIF(BOM!$D:$D,$B2,BOM!$H:$H) -> 2289211.8 | M2: CHINT 27.08.2026 | N2: =IF($P2="ORAN","ORAN (KURALLAR)",IF($I2="","FIYAT_YOK",$P2)) -> MUADIL | O2: CHINT'te 63A govde yok; NM8N-125C 36kA govdesi alindi | P2: MUADIL
A3: 2 | B3: 200231 | C3: УЗО NL1-63 6kA 4P 63A 300mA тип AC (R) | D3: DIF | E3: CHINT | F3: 18106 | G3: =IFERROR(VLOOKUP($E3,KURALLAR!$A$12:$E$23,2,FALSE()),"KZT") -> KZT | H3: =IFERROR(VLOOKUP($E3,KURALLAR!$A$12:$E$23,5,FALSE()),1) -> 0.6 | I3: =IF($F3="","",$F3*$H3*IFERROR(VLOOKUP($G3,KURALLAR!$A$5:$B$8,2,FALSE()),1)) -> 10863.6 | J3: Шт. | K3: =SUMIF(BOM!$D:$D,$B3,BOM!$I:$I) -> 60 | L3: =SUMIF(BOM!$D:$D,$B3,BOM!$H:$H) -> 651816 | M3: CHINT 27.08.2026 | N3: =IF($P3="ORAN","ORAN (KURALLAR)",IF($I3="","FIYAT_YOK",$P3)) -> OK | O3: 4P 63A 300mA AC — birebir | P3: OK
A4: 3 | B4: 521260 | C4: Держатель плавкой вставки RT36-00-160, габарит 00, 160А | D4: FU | E4: CHINT | F4: 2038 | G4: =IFERROR(VLOOKUP($E4,KURALLAR!$A$12:$E$23,2,FALSE()),"KZT") -> KZT | H4: =IFERROR(VLOOKUP($E4,KURALLAR!$A$12:$E$23,5,FALSE()),1) -> 0.6 | I4: =IF($F4="","",$F4*$H4*IFERROR(VLOOKUP($G4,KURALLAR!$A$5:$B$8,2,FALSE()),1)) -> 1222.8 | J4: Шт. | K4: =SUMIF(BOM!$D:$D,$B4,BOM!$I:$I) -> 384 | L4: =SUMIF(BOM!$D:$D,$B4,BOM!$H:$H) -> 469555.2 | M4: CHINT 27.08.2026 | N4: =IF($P4="ORAN","ORAN (KURALLAR)",IF($I4="","FIYAT_YOK",$P4)) -> MUADIL | O4: CHINT'te 14x51 (63A) silindirik yuva yok; NH00 (RT36-00) bicak sigorta yuvasi alindi — montaj/boyut farki KONTROL | P4: MUADIL
A5: 4 | B5: 521347 | C5: Плавкая вставка предохранителя RT36-00-160, габарит 00, 63А | D5: FU | E5: CHINT | F5: 1525 | G5: =IFERROR(VLOOKUP($E5,KURALLAR!$A$12:$E$23,2,FALSE()),"KZT") -> KZT | H5: =IFERROR(VLOOKUP($E5,KURALLAR!$A$12:$E$23,5,FALSE()),1) -> 0.6 | I5: =IF($F5="","",$F5*$H5*IFERROR(VLOOKUP($G5,KURALLAR!$A$5:$B$8,2,FALSE()),1)) -> 915 | J5: Шт. | K5: =SUMIF(BOM!$D:$D,$B5,BOM!$I:$I) -> 408 | L5: =SUMIF(BOM!$D:$D,$B5,BOM!$H:$H) -> 373320 | M5: CHINT 02.02.2026 | N5: =IF($P5="ORAN","ORAN (KURALLAR)",IF($I5="","FIYAT_YOK",$P5)) -> MUADIL | O5: 14x51 63A yerine NH00 63A busonu | P5: MUADIL
A6: 5 | B6: 252578 | C6: Ограничитель имп. перенапр. NU6-IIG 4Р In=25kA Uc=440B Im=65kA (R) | D6: OPN | E6: CHINT | F6: 33208 | G6: =IFERROR(VLOOKUP($E6,KURALLAR!$A$12:$E$23,2,FALSE()),"KZT") -> KZT | H6: =IFERROR(VLOOKUP($E6,KURALLAR!$A$12:$E$23,5,FALSE()),1) -> 0.6 | I6: =IF($F6="","",$F6*$H6*IFERROR(VLOOKUP($G6,KURALLAR!$A$5:$B$8,2,FALSE()),1)) -> 19924.8 | J6: Шт. | K6: =SUMIF(BOM!$D:$D,$B6,BOM!$I:$I) -> 96 | L6: =SUMIF(BOM!$D:$D,$B6,BOM!$H:$H) -> 1912780.8 | M6: CHINT 02.02.2026 | N6: =IF($P6="ORAN","ORAN (KURALLAR)",IF($I6="","FIYAT_YOK",$P6)) -> MUADIL_ONAY | O6: CNC YCS6-B 4P 60kA 420V -> CHINT NU6-IIG 4P Uc=440V In=25kA Imax=65kA. Class I (Iimp) isteniyorsa 308602 NXU-I+II 4P KONTROL | P6: MUADIL_ONAY
A7: 6 | B7: 814172 | C7: Авт. выкл. NXB-63 3P 25A 6кА х-ка C (R) | D7: OTO | E7: CHINT | F7: 5334 | G7: =IFERROR(VLOOKUP($E7,KURALLAR!$A$12:$E$23,2,FALSE()),"KZT") -> KZT | H7: =IFERROR(VLOOKUP($E7,KURALLAR!$A$12:$E$23,5,FALSE()),1) -> 0.6 | I7: =IF($F7="","",$F7*$H7*IFERROR(VLOOKUP($G7,KURALLAR!$A$5:$B$8,2,FALSE()),1)) -> 3200.4 | J7: Шт. | K7: =SUMIF(BOM!$D:$D,$B7,BOM!$I:$I) -> 46 | L7: =SUMIF(BOM!$D:$D,$B7,BOM!$H:$H) -> 147218.4 | M7: CHINT 27.08.2026 | N7: =IF($P7="ORAN","ORAN (KURALLAR)",IF($I7="","FIYAT_YOK",$P7)) -> OK | O7: 3P 25A 6kA C — birebir | P7: OK
A8: 7 | B8: 814014 | C8: Авт. выкл. NXB-63 1P 16A 6кА х-ка C (R) | D8: OTO | E8: CHINT | F8: 1389 | G8: =IFERROR(VLOOKUP($E8,KURALLAR!$A$12:$E$23,2,FALSE()),"KZT") -> KZT | H8: =IFERROR(VLOOKUP($E8,KURALLAR!$A$12:$E$23,5,FALSE()),1) -> 0.6 | I8: =IF($F8="","",$F8*$H8*IFERROR(VLOOKUP($G8,KURALLAR!$A$5:$B$8,2,FALSE()),1)) -> 833.4 | J8: Шт. | K8: =SUMIF(BOM!$D:$D,$B8,BOM!$I:$I) -> 598 | L8: =SUMIF(BOM!$D:$D,$B8,BOM!$H:$H) -> 498373.2 | M8: CHINT 27.08.2026 | N8: =IF($P8="ORAN","ORAN (KURALLAR)",IF($I8="","FIYAT_YOK",$P8)) -> OK | O8: 1P 16A 6kA C — birebir | P8: OK
A9: 8 | B9: 200316 | C9: УЗО NL1-63 6kA 4P 25A 30mA тип AC (R) | D9: DIF | E9: CHINT | F9: 18338 | G9: =IFERROR(VLOOKUP($E9,KURALLAR!$A$12:$E$23,2,FALSE()),"KZT") -> KZT | H9: =IFERROR(VLOOKUP($E9,KURALLAR!$A$12:$E$23,5,FALSE()),1) -> 0.6 | I9: =IF($F9="","",$F9*$H9*IFERROR(VLOOKUP($G9,KURALLAR!$A$5:$B$8,2,FALSE()),1)) -> 11002.8 | J9: Шт. | K9: =SUMIF(BOM!$D:$D,$B9,BOM!$I:$I) -> 16 | L9: =SUMIF(BOM!$D:$D,$B9,BOM!$H:$H) -> 176044.8 | M9: CHINT 27.08.2026 | N9: =IF($P9="ORAN","ORAN (KURALLAR)",IF($I9="","FIYAT_YOK",$P9)) -> OK | O9: 4P 25A 30mA AC — birebir | P9: OK
A10: 9 | B10: 200359 | C10: УЗО NL1-63 6kA 2P 16A 30mA тип AC (R) | D10: DIF | E10: CHINT | F10: 10809 | G10: =IFERROR(VLOOKUP($E10,KURALLAR!$A$12:$E$23,2,FALSE()),"KZT") -> KZT | H10: =IFERROR(VLOOKUP($E10,KURALLAR!$A$12:$E$23,5,FALSE()),1) -> 0.6 | I10: =IF($F10="","",$F10*$H10*IFERROR(VLOOKUP($G10,KURALLAR!$A$5:$B$8,2,FALSE()),1)) -> 6485.4 | J10: Шт. | K10: =SUMIF(BOM!$D:$D,$B10,BOM!$I:$I) -> 51 | L10: =SUMIF(BOM!$D:$D,$B10,BOM!$H:$H) -> 330755.4 | M10: CHINT 27.08.2026 | N10: =IF($P10="ORAN","ORAN (KURALLAR)",IF($I10="","FIYAT_YOK",$P10)) -> OK | O10: 2P 16A 30mA AC — birebir | P10: OK
A11: 10 | B11: 814015 | C11: Авт. выкл. NXB-63 1P 20A 6кА х-ка C (R) | D11: OTO | E11: CHINT | F11: 1434 | G11: =IFERROR(VLOOKUP($E11,KURALLAR!$A$12:$E$23,2,FALSE()),"KZT") -> KZT | H11: =IFERROR(VLOOKUP($E11,KURALLAR!$A$12:$E$23,5,FALSE()),1) -> 0.6 | I11: =IF($F11="","",$F11*$H11*IFERROR(VLOOKUP($G11,KURALLAR!$A$5:$B$8,2,FALSE()),1)) -> 860.4 | J11: Шт. | K11: =SUMIF(BOM!$D:$D,$B11,BOM!$I:$I) -> 4 | L11: =SUMIF(BOM!$D:$D,$B11,BOM!$H:$H) -> 3441.6 | M11: CHINT 27.08.2026 | N11: =IF($P11="ORAN","ORAN (KURALLAR)",IF($I11="","FIYAT_YOK",$P11)) -> OK | O11: 1P 20A 6kA C — birebir | P11: OK
A12: 11 | B12: 814013 | C12: Авт. выкл. NXB-63 1P 10A 6кА х-ка C (R) | D12: OTO | E12: CHINT | F12: 1362 | G12: =IFERROR(VLOOKUP($E12,KURALLAR!$A$12:$E$23,2,FALSE()),"KZT") -> KZT | H12: =IFERROR(VLOOKUP($E12,KURALLAR!$A$12:$E$23,5,FALSE()),1) -> 0.6 | I12: =IF($F12="","",$F12*$H12*IFERROR(VLOOKUP($G12,KURALLAR!$A$5:$B$8,2,FALSE()),1)) -> 817.2 | J12: Шт. | K12: =SUMIF(BOM!$D:$D,$B12,BOM!$I:$I) -> 593 | L12: =SUMIF(BOM!$D:$D,$B12,BOM!$H:$H) -> 484599.6 | M12: CHINT 02.02.2026 | N12: =IF($P12="ORAN","ORAN (KURALLAR)",IF($I12="","FIYAT_YOK",$P12)) -> OK | O12: 1P 10A 6kA C — birebir | P12: OK
A13: 12 | B13: 718-84007 | C13: Шина "N" нулевая 6х9мм на DIN-рейку в корпусном изоляторе ШНИ 12К IEK (10) | D13: BLOK | E13: KAZTEK | F13: 755 | G13: =IFERROR(VLOOKUP($E13,KURALLAR!$A$12:$E$23,2,FALSE()),"KZT") -> KZT | H13: =IFERROR(VLOOKUP($E13,KURALLAR!$A$12:$E$23,5,FALSE()),1) -> 0.6 | I13: =IF($F13="","",$F13*$H13*IFERROR(VLOOKUP($G13,KURALLAR!$A$5:$B$8,2,FALSE()),1)) -> 453 | J13: Шт. | K13: =SUMIF(BOM!$D:$D,$B13,BOM!$I:$I) -> 260 | L13: =SUMIF(BOM!$D:$D,$B13,BOM!$H:$H) -> 117780 | M13: KAZTEK 15.07.2026 | N13: =IF($P13="ORAN","ORAN (KURALLAR)",IF($I13="","FIYAT_YOK",$P13)) -> MUADIL | O13: CHINT listesinde 4x11 dagitim blogu yok; 4 kutup icin 4 ad. izoleli SHNI 12K barasi alindi (adet x4) | P13: MUADIL
A14: 13 | B14: MONTAJ-MALZEME | C14: Монтажный расходный материал (кабель, DIN-рейка, кабель-канал, клеммы, маркировка, крепёж) | D14: MONTAJNYY MATERIAL | E14: MUADIL-NET | G14: =IFERROR(VLOOKUP($E14,KURALLAR!$A$12:$E$23,2,FALSE()),"KZT") -> KZT | H14: =IFERROR(VLOOKUP($E14,KURALLAR!$A$12:$E$23,5,FALSE()),1) -> 1 | I14: =IF($F14="","",$F14*$H14*IFERROR(VLOOKUP($G14,KURALLAR!$A$5:$B$8,2,FALSE()),1)) | J14: компл. | K14: =SUMIF(BOM!$D:$D,$B14,BOM!$I:$I) -> 97 | L14: =SUMIF(BOM!$D:$D,$B14,BOM!$H:$H) -> 5177798 | M14: KURALLAR oran | N14: =IF($P14="ORAN","ORAN (KURALLAR)",IF($I14="","FIYAT_YOK",$P14)) -> ORAN (KURALLAR) | O14: pano ici sarf malzemesi = pano malzeme bedelinin %si (KURALLAR BLOK 3 sari hucre) | P14: ORAN
A15: 14 | B15: 719-15380 | C15: ЩМП (инд.) IP31 (650х500х150мм) | D15: KORPUS | E15: KAZTEK | F15: 27825 | G15: =IFERROR(VLOOKUP($E15,KURALLAR!$A$12:$E$23,2,FALSE()),"KZT") -> KZT | H15: =IFERROR(VLOOKUP($E15,KURALLAR!$A$12:$E$23,5,FALSE()),1) -> 0.6 | I15: =IF($F15="","",$F15*$H15*IFERROR(VLOOKUP($G15,KURALLAR!$A$5:$B$8,2,FALSE()),1)) -> 16695 | J15: Шт. | K15: =SUMIF(BOM!$D:$D,$B15,BOM!$I:$I) -> 36 | L15: =SUMIF(BOM!$D:$D,$B15,BOM!$H:$H) -> 601020 | M15: KAZTEK 15.07.2026 | N15: =IF($P15="ORAN","ORAN (KURALLAR)",IF($I15="","FIYAT_YOK",$P15)) -> VARSAYIM | O15: proje 460x700x200 duvar tipi FORM 2B -> KAZTEK 650x500x150; olcu/FORM sinifi KONTROL | P15: VARSAYIM
A16: 15 | B16: ISCILIK-MONTAJ | C16: Сборка, кабелирование, маркировка, момент затяжки, испытания | D16: MONTAJNAYA RABOTA | E16: ISCILIK | F16: =KURALLAR!$B$26 -> 100 | G16: =IFERROR(VLOOKUP($E16,KURALLAR!$A$12:$E$23,2,FALSE()),"KZT") -> KZT | H16: =IFERROR(VLOOKUP($E16,KURALLAR!$A$12:$E$23,5,FALSE()),1) -> 1 | I16: =IF($F16="","",$F16*$H16*IFERROR(VLOOKUP($G16,KURALLAR!$A$5:$B$8,2,FALSE()),1)) -> 100 | J16: мин | K16: =SUMIF(BOM!$D:$D,$B16,BOM!$I:$I) -> 69554 | L16: =SUMIF(BOM!$D:$D,$B16,BOM!$H:$H) -> 6955400 | M16: TEKLED norm | N16: =IF($P16="ORAN","ORAN (KURALLAR)",IF($I16="","FIYAT_YOK",$P16)) -> OK | O16: montaj+test iscilik — dakika normlari KURALLAR BLOK 3 sari hucrelerinden, x1,15 test/etiket | P16: OK
A17: 16 | B17: 271538 | C17: Авт. выкл. NM8N-125C TM 3P 80А 36кА с рег. термомаг. расцепителем (R) | D17: TMS | E17: CHINT | F17: 64129 | G17: =IFERROR(VLOOKUP($E17,KURALLAR!$A$12:$E$23,2,FALSE()),"KZT") -> KZT | H17: =IFERROR(VLOOKUP($E17,KURALLAR!$A$12:$E$23,5,FALSE()),1) -> 0.6 | I17: =IF($F17="","",$F17*$H17*IFERROR(VLOOKUP($G17,KURALLAR!$A$5:$B$8,2,FALSE()),1)) -> 38477.4 | J17: Шт. | K17: =SUMIF(BOM!$D:$D,$B17,BOM!$I:$I) -> 24 | L17: =SUMIF(BOM!$D:$D,$B17,BOM!$H:$H) -> 923457.6 | M17: CHINT 27.08.2026 | N17: =IF($P17="ORAN","ORAN (KURALLAR)",IF($I17="","FIYAT_YOK",$P17)) -> OK | O17: 125 govde 80A 36kA — birebir | P17: OK
A18: 17 | B18: 449980 | C18: Диф. модуль NM8NL-125 4P RCD1 X рег. ток утечки 0,03-0,05-0,1-0,2-0,3-0,5-1-2 A (R) | D18: DIF | E18: CHINT | F18: 83791 | G18: =IFERROR(VLOOKUP($E18,KURALLAR!$A$12:$E$23,2,FALSE()),"KZT") -> KZT | H18: =IFERROR(VLOOKUP($E18,KURALLAR!$A$12:$E$23,5,FALSE()),1) -> 0.6 | I18: =IF($F18="","",$F18*$H18*IFERROR(VLOOKUP($G18,KURALLAR!$A$5:$B$8,2,FALSE()),1)) -> 50274.6 | J18: Шт. | K18: =SUMIF(BOM!$D:$D,$B18,BOM!$I:$I) -> 7 | L18: =SUMIF(BOM!$D:$D,$B18,BOM!$H:$H) -> 351922.2 | M18: CHINT 02.02.2026 | N18: =IF($P18="ORAN","ORAN (KURALLAR)",IF($I18="","FIYAT_YOK",$P18)) -> CIHAZ_BELIRSIZ | O18: CHINT NL1-63 serisi max 63A — 4P 100A 300mA UZO yok. NM8N-125 4P govde + NM8NL-125 dif modulu teklif edildi; pano giris salteri 4P govdeye cevrilmelidir KONTROL | P18: CIHAZ_BELIRSIZ
A19: 18 | B19: 814012 | C19: Авт. выкл. NXB-63 1P 6A 6кА х-ка C (R) | D19: OTO | E19: CHINT | F19: 1436 | G19: =IFERROR(VLOOKUP($E19,KURALLAR!$A$12:$E$23,2,FALSE()),"KZT") -> KZT | H19: =IFERROR(VLOOKUP($E19,KURALLAR!$A$12:$E$23,5,FALSE()),1) -> 0.6 | I19: =IF($F19="","",$F19*$H19*IFERROR(VLOOKUP($G19,KURALLAR!$A$5:$B$8,2,FALSE()),1)) -> 861.6 | J19: Шт. | K19: =SUMIF(BOM!$D:$D,$B19,BOM!$I:$I) -> 186 | L19: =SUMIF(BOM!$D:$D,$B19,BOM!$H:$H) -> 160257.6 | M19: CHINT 27.08.2026 | N19: =IF($P19="ORAN","ORAN (KURALLAR)",IF($I19="","FIYAT_YOK",$P19)) -> OK | O19: 1P 6A 6kA C — birebir | P19: OK
A20: 19 | B20: 593085 | C20: Индикатор ND16-22DS/4 белый АС230В (R) | D20: LAMB | E20: CHINT | F20: 1047 | G20: =IFERROR(VLOOKUP($E20,KURALLAR!$A$12:$E$23,2,FALSE()),"KZT") -> KZT | H20: =IFERROR(VLOOKUP($E20,KURALLAR!$A$12:$E$23,5,FALSE()),1) -> 0.6 | I20: =IF($F20="","",$F20*$H20*IFERROR(VLOOKUP($G20,KURALLAR!$A$5:$B$8,2,FALSE()),1)) -> 628.2 | J20: Шт. | K20: =SUMIF(BOM!$D:$D,$B20,BOM!$I:$I) -> 102 | L20: =SUMIF(BOM!$D:$D,$B20,BOM!$H:$H) -> 64076.4 | M20: CHINT 02.02.2026 | N20: =IF($P20="ORAN","ORAN (KURALLAR)",IF($I20="","FIYAT_YOK",$P20)) -> OK | O20: beyaz sinyal lambasi 230V | P20: OK
A21: 20 | B21: 814174 | C21: Авт. выкл. NXB-63 3P 40A 6кА х-ка C (R) | D21: OTO | E21: CHINT | F21: 5647 | G21: =IFERROR(VLOOKUP($E21,KURALLAR!$A$12:$E$23,2,FALSE()),"KZT") -> KZT | H21: =IFERROR(VLOOKUP($E21,KURALLAR!$A$12:$E$23,5,FALSE()),1) -> 0.6 | I21: =IF($F21="","",$F21*$H21*IFERROR(VLOOKUP($G21,KURALLAR!$A$5:$B$8,2,FALSE()),1)) -> 3388.2 | J21: Шт. | K21: =SUMIF(BOM!$D:$D,$B21,BOM!$I:$I) -> 46 | L21: =SUMIF(BOM!$D:$D,$B21,BOM!$H:$H) -> 155857.2 | M21: CHINT 27.08.2026 | N21: =IF($P21="ORAN","ORAN (KURALLAR)",IF($I21="","FIYAT_YOK",$P21)) -> OK | O21: 3P 40A 6kA C — birebir | P21: OK
A22: 21 | B22: EX-518U-100A | C22: Трехфазный эл.счетчик EX 518 10(100)А (прям. подкл.) с PLC модулем | D22: SAYAC | E22: MUADIL-NET | G22: =IFERROR(VLOOKUP($E22,KURALLAR!$A$12:$E$23,2,FALSE()),"KZT") -> KZT | H22: =IFERROR(VLOOKUP($E22,KURALLAR!$A$12:$E$23,5,FALSE()),1) -> 1 | I22: =IF($F22="","",$F22*$H22*IFERROR(VLOOKUP($G22,KURALLAR!$A$5:$B$8,2,FALSE()),1)) | J22: Шт. | K22: =SUMIF(BOM!$D:$D,$B22,BOM!$I:$I) -> 29 | L22: =SUMIF(BOM!$D:$D,$B22,BOM!$H:$H) -> 0 | N22: =IF($P22="ORAN","ORAN (KURALLAR)",IF($I22="","FIYAT_YOK",$P22)) -> FIYAT_YOK | O22: Elektron Xisoblagich sayaci — CHINT listesinde yok, fiyat alinacak | P22: KONTROL
A23: 22 | B23: BARA-AL-SAT | C23: Шина алюминиевая твёрдая (ШАТ) | D23: SINA | E23: ALUM-BARA | F23: =KURALLAR!$B$88 -> 4493.6 | G23: =IFERROR(VLOOKUP($E23,KURALLAR!$A$12:$E$23,2,FALSE()),"KZT") -> KZT | H23: =IFERROR(VLOOKUP($E23,KURALLAR!$A$12:$E$23,5,FALSE()),1) -> 1 | I23: =IF($F23="","",$F23*$H23*IFERROR(VLOOKUP($G23,KURALLAR!$A$5:$B$8,2,FALSE()),1)) -> 4493.6 | J23: Кг. | K23: =SUMIF(BOM!$D:$D,$B23,BOM!$I:$I) -> 1392 | L23: =SUMIF(BOM!$D:$D,$B23,BOM!$H:$H) -> 6255091.2 | N23: =IF($P23="ORAN","ORAN (KURALLAR)",IF($I23="","FIYAT_YOK",$P23)) -> VARSAYIM | O23: alu bara — kg fiyati KURALLAR BLOK 8'den hesaplanir | P23: VARSAYIM
A24: 23 | B24: 719-15636 | C24: Щит (moduler) 2000x800x800+100 | D24: KORPUS | E24: KAZTEK | F24: 197400 | G24: =IFERROR(VLOOKUP($E24,KURALLAR!$A$12:$E$23,2,FALSE()),"KZT") -> KZT | H24: =IFERROR(VLOOKUP($E24,KURALLAR!$A$12:$E$23,5,FALSE()),1) -> 0.6 | I24: =IF($F24="","",$F24*$H24*IFERROR(VLOOKUP($G24,KURALLAR!$A$5:$B$8,2,FALSE()),1)) -> 118440 | J24: Шт. | K24: =SUMIF(BOM!$D:$D,$B24,BOM!$I:$I) -> 28 | L24: =SUMIF(BOM!$D:$D,$B24,BOM!$H:$H) -> 3316320 | M24: KAZTEK 15.07.2026 | N24: =IF($P24="ORAN","ORAN (KURALLAR)",IF($I24="","FIYAT_YOK",$P24)) -> VARSAYIM | O24: proje 900x2100x400 -> KAZTEK 2000x800x800+baza (genislik eksik); olcu KONTROL | P24: VARSAYIM
A25: 24 | B25: 271536 | C25: Авт. выкл. NM8N-125C TM 3P 50А 36кА с рег. термомаг. расцепителем (R) | D25: TMS | E25: CHINT | F25: 68025 | G25: =IFERROR(VLOOKUP($E25,KURALLAR!$A$12:$E$23,2,FALSE()),"KZT") -> KZT | H25: =IFERROR(VLOOKUP($E25,KURALLAR!$A$12:$E$23,5,FALSE()),1) -> 0.6 | I25: =IF($F25="","",$F25*$H25*IFERROR(VLOOKUP($G25,KURALLAR!$A$5:$B$8,2,FALSE()),1)) -> 40815 | J25: Шт. | K25: =SUMIF(BOM!$D:$D,$B25,BOM!$I:$I) -> 15 | L25: =SUMIF(BOM!$D:$D,$B25,BOM!$H:$H) -> 612225 | M25: CHINT 27.08.2026 | N25: =IF($P25="ORAN","ORAN (KURALLAR)",IF($I25="","FIYAT_YOK",$P25)) -> MUADIL | O25: CHINT'te 63A govde yok; NM8N-125C 36kA govdesi alindi | P25: MUADIL
A26: 25 | B26: 719-15626 | C26: Мет. Щит (2000x700x500) +10CM BAZA IP54 | D26: KORPUS | E26: KAZTEK | F26: 117250 | G26: =IFERROR(VLOOKUP($E26,KURALLAR!$A$12:$E$23,2,FALSE()),"KZT") -> KZT | H26: =IFERROR(VLOOKUP($E26,KURALLAR!$A$12:$E$23,5,FALSE()),1) -> 0.6 | I26: =IF($F26="","",$F26*$H26*IFERROR(VLOOKUP($G26,KURALLAR!$A$5:$B$8,2,FALSE()),1)) -> 70350 | J26: Шт. | K26: =SUMIF(BOM!$D:$D,$B26,BOM!$I:$I) -> 13 | L26: =SUMIF(BOM!$D:$D,$B26,BOM!$H:$H) -> 914550 | M26: KAZTEK 15.07.2026 | N26: =IF($P26="ORAN","ORAN (KURALLAR)",IF($I26="","FIYAT_YOK",$P26)) -> VARSAYIM | O26: proje 700x2100x400 -> KAZTEK 2000x700x500+baza; FORM sinifi KONTROL | P26: VARSAYIM
A27: 26 | B27: 269252 | C27: Авт. выкл. NM8N-630S TM 3P 500А 50кА с рег. термомаг. расцепителем (R) | D27: TMS | E27: CHINT | F27: 237703 | G27: =IFERROR(VLOOKUP($E27,KURALLAR!$A$12:$E$23,2,FALSE()),"KZT") -> KZT | H27: =IFERROR(VLOOKUP($E27,KURALLAR!$A$12:$E$23,5,FALSE()),1) -> 0.6 | I27: =IF($F27="","",$F27*$H27*IFERROR(VLOOKUP($G27,KURALLAR!$A$5:$B$8,2,FALSE()),1)) -> 142621.8 | J27: Шт. | K27: =SUMIF(BOM!$D:$D,$B27,BOM!$I:$I) -> 4 | L27: =SUMIF(BOM!$D:$D,$B27,BOM!$H:$H) -> 570487.2 | M27: CHINT 27.08.2026 | N27: =IF($P27="ORAN","ORAN (KURALLAR)",IF($I27="","FIYAT_YOK",$P27)) -> MUADIL | O27: 36kA kademesinde 500A yok, 50kA (630S) alindi | P27: MUADIL
A28: 27 | B28: 269604 | C28: Независимый расцепитель SHT22-M8 AC220-240V для NM8N-250/400/630 (R) | D28: BLOK | E28: CHINT | F28: 18552 | G28: =IFERROR(VLOOKUP($E28,KURALLAR!$A$12:$E$23,2,FALSE()),"KZT") -> KZT | H28: =IFERROR(VLOOKUP($E28,KURALLAR!$A$12:$E$23,5,FALSE()),1) -> 0.6 | I28: =IF($F28="","",$F28*$H28*IFERROR(VLOOKUP($G28,KURALLAR!$A$5:$B$8,2,FALSE()),1)) -> 11131.2 | J28: Шт. | K28: =SUMIF(BOM!$D:$D,$B28,BOM!$I:$I) -> 10 | L28: =SUMIF(BOM!$D:$D,$B28,BOM!$H:$H) -> 111312 | M28: CHINT 02.02.2026 | N28: =IF($P28="ORAN","ORAN (KURALLAR)",IF($I28="","FIYAT_YOK",$P28)) -> OK | O28: NM8N-250/400/630 govdesi icin bagimsiz acici | P28: OK
A29: 28 | B29: RELE-KACAK-AYARLI-LCD | C29: Реле защиты от утечки тока с LCD индикацией (регулируемое) — CHINT листинге нет | D29: ROLE | E29: MUADIL-NET | G29: =IFERROR(VLOOKUP($E29,KURALLAR!$A$12:$E$23,2,FALSE()),"KZT") -> KZT | H29: =IFERROR(VLOOKUP($E29,KURALLAR!$A$12:$E$23,5,FALSE()),1) -> 1 | I29: =IF($F29="","",$F29*$H29*IFERROR(VLOOKUP($G29,KURALLAR!$A$5:$B$8,2,FALSE()),1)) | J29: Шт. | K29: =SUMIF(BOM!$D:$D,$B29,BOM!$I:$I) -> 12 | L29: =SUMIF(BOM!$D:$D,$B29,BOM!$H:$H) -> 0 | N29: =IF($P29="ORAN","ORAN (KURALLAR)",IF($I29="","FIYAT_YOK",$P29)) -> FIYAT_YOK | O29: CHINT stok listesinde ayarli kacak akim koruma rolesi (LCD) yok — FIYAT ALINACAK | P29: CIHAZ_BELIRSIZ
A30: 29 | B30: 50442 | C30: Schneider Vigilohm GA300 — тороид тип A, Ø300мм | D30: TT | E30: SCHNEIDER | G30: =IFERROR(VLOOKUP($E30,KURALLAR!$A$12:$E$23,2,FALSE()),"KZT") -> EUR | H30: =IFERROR(VLOOKUP($E30,KURALLAR!$A$12:$E$23,5,FALSE()),1) -> 0.6 | I30: =IF($F30="","",$F30*$H30*IFERROR(VLOOKUP($G30,KURALLAR!$A$5:$B$8,2,FALSE()),1)) | J30: Шт. | K30: =SUMIF(BOM!$D:$D,$B30,BOM!$I:$I) -> 2 | L30: =SUMIF(BOM!$D:$D,$B30,BOM!$H:$H) -> 0 | N30: =IF($P30="ORAN","ORAN (KURALLAR)",IF($I30="","FIYAT_YOK",$P30)) -> FIYAT_YOK | O30: toroid Ø300; CHINT muadili yok KONTROL | P30: KONTROL
A31: 30 | B31: 271535 | C31: Авт. выкл. NM8N-125C TM 3P 40А 36кА с рег. термомаг. расцепителем (R) | D31: TMS | E31: CHINT | F31: 68418 | G31: =IFERROR(VLOOKUP($E31,KURALLAR!$A$12:$E$23,2,FALSE()),"KZT") -> KZT | H31: =IFERROR(VLOOKUP($E31,KURALLAR!$A$12:$E$23,5,FALSE()),1) -> 0.6 | I31: =IF($F31="","",$F31*$H31*IFERROR(VLOOKUP($G31,KURALLAR!$A$5:$B$8,2,FALSE()),1)) -> 41050.8 | J31: Шт. | K31: =SUMIF(BOM!$D:$D,$B31,BOM!$I:$I) -> 57 | L31: =SUMIF(BOM!$D:$D,$B31,BOM!$H:$H) -> 2339895.6 | M31: CHINT 27.08.2026 | N31: =IF($P31="ORAN","ORAN (KURALLAR)",IF($I31="","FIYAT_YOK",$P31)) -> MUADIL | O31: CHINT'te 63A govde yok; NM8N-125C 36kA govdesi alindi | P31: MUADIL
A32: 31 | B32: TT-066-500-5 | C32: Трансформатор тока Т-0.66-1,2 У3 500/5А (для счётчика) | D32: TT | E32: MUADIL-NET | G32: =IFERROR(VLOOKUP($E32,KURALLAR!$A$12:$E$23,2,FALSE()),"KZT") -> KZT | H32: =IFERROR(VLOOKUP($E32,KURALLAR!$A$12:$E$23,5,FALSE()),1) -> 1 | I32: =IF($F32="","",$F32*$H32*IFERROR(VLOOKUP($G32,KURALLAR!$A$5:$B$8,2,FALSE()),1)) | J32: Шт. | K32: =SUMIF(BOM!$D:$D,$B32,BOM!$I:$I) -> 6 | L32: =SUMIF(BOM!$D:$D,$B32,BOM!$H:$H) -> 0 | N32: =IF($P32="ORAN","ORAN (KURALLAR)",IF($I32="","FIYAT_YOK",$P32)) -> FIYAT_YOK | O32: sayac akim trafosu 500/5A — CHINT listesinde uygun oran yok | P32: KONTROL
A33: 32 | B33: KKI1-1 | C33: КОРОБКА КЛЕММНАЯ ИСПЫТАТЕЛЬНАЯ ПЕРЕХОДНАЯ ККИ1-1 EKF PROXIMA | D33: KLEMENS | E33: EKF | G33: =IFERROR(VLOOKUP($E33,KURALLAR!$A$12:$E$23,2,FALSE()),"KZT") -> KZT | H33: =IFERROR(VLOOKUP($E33,KURALLAR!$A$12:$E$23,5,FALSE()),1) -> 1 | I33: =IF($F33="","",$F33*$H33*IFERROR(VLOOKUP($G33,KURALLAR!$A$5:$B$8,2,FALSE()),1)) | J33: Шт. | K33: =SUMIF(BOM!$D:$D,$B33,BOM!$I:$I) -> 28 | L33: =SUMIF(BOM!$D:$D,$B33,BOM!$H:$H) -> 0 | N33: =IF($P33="ORAN","ORAN (KURALLAR)",IF($I33="","FIYAT_YOK",$P33)) -> FIYAT_YOK | O33: EKF referans marka — fiyat kullanilmaz (kural). CHINT/IEK muadili KONTROL | P33: KONTROL
A34: 33 | B34: EX-518U-5A | C34: Трехфазный эл.счетчик EX 518 5А (трансф. подкл.) с PLC модулем | D34: SAYAC | E34: MUADIL-NET | G34: =IFERROR(VLOOKUP($E34,KURALLAR!$A$12:$E$23,2,FALSE()),"KZT") -> KZT | H34: =IFERROR(VLOOKUP($E34,KURALLAR!$A$12:$E$23,5,FALSE()),1) -> 1 | I34: =IF($F34="","",$F34*$H34*IFERROR(VLOOKUP($G34,KURALLAR!$A$5:$B$8,2,FALSE()),1)) | J34: Шт. | K34: =SUMIF(BOM!$D:$D,$B34,BOM!$I:$I) -> 28 | L34: =SUMIF(BOM!$D:$D,$B34,BOM!$H:$H) -> 0 | N34: =IF($P34="ORAN","ORAN (KURALLAR)",IF($I34="","FIYAT_YOK",$P34)) -> FIYAT_YOK | O34: Elektron Xisoblagich sayaci — CHINT listesinde yok, fiyat alinacak | P34: KONTROL
A35: 34 | B35: 268936 | C35: Авт. выкл. NM8N-400C TM 3P 315А 36кА с рег. термомаг. расцепителем (R) | D35: TMS | E35: CHINT | F35: 199091 | G35: =IFERROR(VLOOKUP($E35,KURALLAR!$A$12:$E$23,2,FALSE()),"KZT") -> KZT | H35: =IFERROR(VLOOKUP($E35,KURALLAR!$A$12:$E$23,5,FALSE()),1) -> 0.6 | I35: =IF($F35="","",$F35*$H35*IFERROR(VLOOKUP($G35,KURALLAR!$A$5:$B$8,2,FALSE()),1)) -> 119454.6 | J35: Шт. | K35: =SUMIF(BOM!$D:$D,$B35,BOM!$I:$I) -> 4 | L35: =SUMIF(BOM!$D:$D,$B35,BOM!$H:$H) -> 477818.4 | M35: CHINT 02.02.2026 | N35: =IF($P35="ORAN","ORAN (KURALLAR)",IF($I35="","FIYAT_YOK",$P35)) -> OK | O35: 400 govde 315A 36kA — birebir | P35: OK
A36: 35 | B36: TOROID-100 | C36: Тороидальный трансформатор тока Ø100мм (250-400A) — CHINT листинге нет | D36: TT | E36: MUADIL-NET | G36: =IFERROR(VLOOKUP($E36,KURALLAR!$A$12:$E$23,2,FALSE()),"KZT") -> KZT | H36: =IFERROR(VLOOKUP($E36,KURALLAR!$A$12:$E$23,5,FALSE()),1) -> 1 | I36: =IF($F36="","",$F36*$H36*IFERROR(VLOOKUP($G36,KURALLAR!$A$5:$B$8,2,FALSE()),1)) | J36: Шт. | K36: =SUMIF(BOM!$D:$D,$B36,BOM!$I:$I) -> 7 | L36: =SUMIF(BOM!$D:$D,$B36,BOM!$H:$H) -> 0 | N36: =IF($P36="ORAN","ORAN (KURALLAR)",IF($I36="","FIYAT_YOK",$P36)) -> FIYAT_YOK | O36: toroidal AT Ø100 — CHINT stok listesinde yok | P36: KONTROL
A37: 36 | B37: 271144 | C37: Авт. выкл. NM8N-250C TM 3P 200А 36кА с рег. термомаг. расцепителем (R) | D37: TMS | E37: CHINT | F37: 89663 | G37: =IFERROR(VLOOKUP($E37,KURALLAR!$A$12:$E$23,2,FALSE()),"KZT") -> KZT | H37: =IFERROR(VLOOKUP($E37,KURALLAR!$A$12:$E$23,5,FALSE()),1) -> 0.6 | I37: =IF($F37="","",$F37*$H37*IFERROR(VLOOKUP($G37,KURALLAR!$A$5:$B$8,2,FALSE()),1)) -> 53797.8 | J37: Шт. | K37: =SUMIF(BOM!$D:$D,$B37,BOM!$I:$I) -> 6 | L37: =SUMIF(BOM!$D:$D,$B37,BOM!$H:$H) -> 322786.8 | M37: CHINT 27.08.2026 | N37: =IF($P37="ORAN","ORAN (KURALLAR)",IF($I37="","FIYAT_YOK",$P37)) -> OK | O37: 250 govde 200A 36kA — birebir | P37: OK
A38: 37 | B38: TT-066-200-5 | C38: Трансформатор тока Т-0.66-1,2 У3 200/5А (для счётчика) | D38: TT | E38: MUADIL-NET | G38: =IFERROR(VLOOKUP($E38,KURALLAR!$A$12:$E$23,2,FALSE()),"KZT") -> KZT | H38: =IFERROR(VLOOKUP($E38,KURALLAR!$A$12:$E$23,5,FALSE()),1) -> 1 | I38: =IF($F38="","",$F38*$H38*IFERROR(VLOOKUP($G38,KURALLAR!$A$5:$B$8,2,FALSE()),1)) | J38: Шт. | K38: =SUMIF(BOM!$D:$D,$B38,BOM!$I:$I) -> 18 | L38: =SUMIF(BOM!$D:$D,$B38,BOM!$H:$H) -> 0 | N38: =IF($P38="ORAN","ORAN (KURALLAR)",IF($I38="","FIYAT_YOK",$P38)) -> FIYAT_YOK | O38: sayac akim trafosu 200/5A — CHINT listesinde uygun oran yok | P38: KONTROL
A39: 38 | B39: 271142 | C39: Авт. выкл. NM8N-250C TM 3P 160А 36кА с рег. термомаг. расцепителем (R) | D39: TMS | E39: CHINT | F39: 89083 | G39: =IFERROR(VLOOKUP($E39,KURALLAR!$A$12:$E$23,2,FALSE()),"KZT") -> KZT | H39: =IFERROR(VLOOKUP($E39,KURALLAR!$A$12:$E$23,5,FALSE()),1) -> 0.6 | I39: =IF($F39="","",$F39*$H39*IFERROR(VLOOKUP($G39,KURALLAR!$A$5:$B$8,2,FALSE()),1)) -> 53449.8 | J39: Шт. | K39: =SUMIF(BOM!$D:$D,$B39,BOM!$I:$I) -> 2 | L39: =SUMIF(BOM!$D:$D,$B39,BOM!$H:$H) -> 106899.6 | M39: CHINT 27.08.2026 | N39: =IF($P39="ORAN","ORAN (KURALLAR)",IF($I39="","FIYAT_YOK",$P39)) -> OK | O39: 250 govde 160A 36kA — birebir | P39: OK
A40: 39 | B40: TT-066-150-5 | C40: Трансформатор тока Т-0.66-1,2 У3 150/5А (для счётчика) | D40: TT | E40: MUADIL-NET | G40: =IFERROR(VLOOKUP($E40,KURALLAR!$A$12:$E$23,2,FALSE()),"KZT") -> KZT | H40: =IFERROR(VLOOKUP($E40,KURALLAR!$A$12:$E$23,5,FALSE()),1) -> 1 | I40: =IF($F40="","",$F40*$H40*IFERROR(VLOOKUP($G40,KURALLAR!$A$5:$B$8,2,FALSE()),1)) | J40: Шт. | K40: =SUMIF(BOM!$D:$D,$B40,BOM!$I:$I) -> 6 | L40: =SUMIF(BOM!$D:$D,$B40,BOM!$H:$H) -> 0 | N40: =IF($P40="ORAN","ORAN (KURALLAR)",IF($I40="","FIYAT_YOK",$P40)) -> FIYAT_YOK | O40: sayac akim trafosu 150/5A — CHINT listesinde uygun oran yok | P40: KONTROL
...

Sheet BOM
A1: ROW | B1: Наименование1 | C1: Тип | D1: Артикул | E1: Номенклатура | F1: Цена | G1: net | H1: Сумма | I1: Кол-во | J1: Ед.изм | K1: Завод | L1: Итого | M1: Группа | N1: SRK EUR | O1: Oguzhan | P1: DURUM | Q1: NOT | R1: KAYNAK | S1: PDF | T1: NORM_KEY | U1: NORM_DK
A2: 1 | B2: =E2 -> BLOK A / ЩК-стандарт — НКУ 380/220В 50Гц, FORM 2B, IP31/54 | C2: korpus komplekt | E2: BLOK A / ЩК-стандарт — НКУ 380/220В 50Гц, FORM 2B, IP31/54 | I2: 1 | J2: комплект | P2: OK | Q2: komplekt adedi OZET C sutununda; pano ici malzemeler 1 pano icindir | R2: APEX CNC.xlsx | S2: 170001-ST-EL-CD-BLA-SPD-XX-R02
A3: 2 | C3: TMS | D3: 271534 | E3: =IFERROR(VLOOKUP($D3,FIYAT!$B:$O,2,FALSE()),"") -> Авт. выкл. NM8N-125C TM 3P 32А 36кА с рег. термомаг. расцепителем (R) | F3: =IFERROR(VLOOKUP($D3,FIYAT!$B:$O,5,FALSE()),"") -> 64667 | G3: =IFERROR(VLOOKUP($D3,FIYAT!$B:$O,8,FALSE()),"") -> 38800.2 | H3: =IF(OR($G3="",$I3=""),"",$G3*$I3) -> 38800.2 | I3: 1 | J3: =IFERROR(VLOOKUP($D3,FIYAT!$B:$O,9,FALSE()),"") -> Шт. | K3: =IFERROR(VLOOKUP($D3,FIYAT!$B:$O,4,FALSE()),"") -> CHINT | L3: =IF($H3="","",$H3) -> 38800.2 | P3: =IF($H3="","FIYAT_YOK",IFERROR(VLOOKUP($D3,FIYAT!$B:$P,15,FALSE()),"")) -> MUADIL | Q3: CHINT'te 63A govde yok; NM8N-125C 36kA govdesi alindi | R3: CHINT 27.08.2026 | S3: 170001-ST-EL-CD-BLA-SPD-XX-R02 | T3: TMS_125 | U3: =IFERROR(VLOOKUP($T3,KURALLAR!$A$32:$B$63,2,FALSE()),0)*IF(ISNUMBER($I3),$I3,0) -> 15
A4: 3 | C4: DIF | D4: 200231 | E4: =IFERROR(VLOOKUP($D4,FIYAT!$B:$O,2,FALSE()),"") -> УЗО NL1-63 6kA 4P 63A 300mA тип AC (R) | F4: =IFERROR(VLOOKUP($D4,FIYAT!$B:$O,5,FALSE()),"") -> 18106 | G4: =IFERROR(VLOOKUP($D4,FIYAT!$B:$O,8,FALSE()),"") -> 10863.6 | H4: =IF(OR($G4="",$I4=""),"",$G4*$I4) -> 10863.6 | I4: 1 | J4: =IFERROR(VLOOKUP($D4,FIYAT!$B:$O,9,FALSE()),"") -> Шт. | K4: =IFERROR(VLOOKUP($D4,FIYAT!$B:$O,4,FALSE()),"") -> CHINT | L4: =IF($H4="","",$H4) -> 10863.6 | P4: =IF($H4="","FIYAT_YOK",IFERROR(VLOOKUP($D4,FIYAT!$B:$P,15,FALSE()),"")) -> OK | Q4: 4P 63A 300mA AC — birebir | R4: CHINT 27.08.2026 | S4: 170001-ST-EL-CD-BLA-SPD-XX-R02 | T4: DIF_4P | U4: =IFERROR(VLOOKUP($T4,KURALLAR!$A$32:$B$63,2,FALSE()),0)*IF(ISNUMBER($I4),$I4,0) -> 10
A5: 4 | C5: FU | D5: 521260 | E5: =IFERROR(VLOOKUP($D5,FIYAT!$B:$O,2,FALSE()),"") -> Держатель плавкой вставки RT36-00-160, габарит 00, 160А | F5: =IFERROR(VLOOKUP($D5,FIYAT!$B:$O,5,FALSE()),"") -> 2038 | G5: =IFERROR(VLOOKUP($D5,FIYAT!$B:$O,8,FALSE()),"") -> 1222.8 | H5: =IF(OR($G5="",$I5=""),"",$G5*$I5) -> 4891.2 | I5: 4 | J5: =IFERROR(VLOOKUP($D5,FIYAT!$B:$O,9,FALSE()),"") -> Шт. | K5: =IFERROR(VLOOKUP($D5,FIYAT!$B:$O,4,FALSE()),"") -> CHINT | L5: =IF($H5="","",$H5) -> 4891.2 | P5: =IF($H5="","FIYAT_YOK",IFERROR(VLOOKUP($D5,FIYAT!$B:$P,15,FALSE()),"")) -> MUADIL | Q5: CHINT'te 14x51 (63A) silindirik yuva yok; NH00 (RT36-00) bicak sigorta yuvasi alindi — montaj/boyut farki KONTROL | R5: CHINT 27.08.2026 | S5: 170001-ST-EL-CD-BLA-SPD-XX-R02 | T5: FU_TUTUCU | U5: =IFERROR(VLOOKUP($T5,KURALLAR!$A$32:$B$63,2,FALSE()),0)*IF(ISNUMBER($I5),$I5,0) -> 20
A6: 5 | C6: FU | D6: 521347 | E6: =IFERROR(VLOOKUP($D6,FIYAT!$B:$O,2,FALSE()),"") -> Плавкая вставка предохранителя RT36-00-160, габарит 00, 63А | F6: =IFERROR(VLOOKUP($D6,FIYAT!$B:$O,5,FALSE()),"") -> 1525 | G6: =IFERROR(VLOOKUP($D6,FIYAT!$B:$O,8,FALSE()),"") -> 915 | H6: =IF(OR($G6="",$I6=""),"",$G6*$I6) -> 3660 | I6: 4 | J6: =IFERROR(VLOOKUP($D6,FIYAT!$B:$O,9,FALSE()),"") -> Шт. | K6: =IFERROR(VLOOKUP($D6,FIYAT!$B:$O,4,FALSE()),"") -> CHINT | L6: =IF($H6="","",$H6) -> 3660 | P6: =IF($H6="","FIYAT_YOK",IFERROR(VLOOKUP($D6,FIYAT!$B:$P,15,FALSE()),"")) -> MUADIL | Q6: 14x51 63A yerine NH00 63A busonu | R6: CHINT 02.02.2026 | S6: 170001-ST-EL-CD-BLA-SPD-XX-R02 | T6: FU | U6: =IFERROR(VLOOKUP($T6,KURALLAR!$A$32:$B$63,2,FALSE()),0)*IF(ISNUMBER($I6),$I6,0) -> 12
A7: 6 | C7: OPN | D7: 252578 | E7: =IFERROR(VLOOKUP($D7,FIYAT!$B:$O,2,FALSE()),"") -> Ограничитель имп. перенапр. NU6-IIG 4Р In=25kA Uc=440B Im=65kA (R) | F7: =IFERROR(VLOOKUP($D7,FIYAT!$B:$O,5,FALSE()),"") -> 33208 | G7: =IFERROR(VLOOKUP($D7,FIYAT!$B:$O,8,FALSE()),"") -> 19924.8 | H7: =IF(OR($G7="",$I7=""),"",$G7*$I7) -> 19924.8 | I7: 1 | J7: =IFERROR(VLOOKUP($D7,FIYAT!$B:$O,9,FALSE()),"") -> Шт. | K7: =IFERROR(VLOOKUP($D7,FIYAT!$B:$O,4,FALSE()),"") -> CHINT | L7: =IF($H7="","",$H7) -> 19924.8 | P7: =IF($H7="","FIYAT_YOK",IFERROR(VLOOKUP($D7,FIYAT!$B:$P,15,FALSE()),"")) -> MUADIL_ONAY | Q7: CNC YCS6-B 4P 60kA 420V -> CHINT NU6-IIG 4P Uc=440V In=25kA Imax=65kA. Class I (Iimp) isteniyorsa 308602 NXU-I+II 4P KONTROL | R7: CHINT 02.02.2026 | S7: 170001-ST-EL-CD-BLA-SPD-XX-R02 | T7: OPN | U7: =IFERROR(VLOOKUP($T7,KURALLAR!$A$32:$B$63,2,FALSE()),0)*IF(ISNUMBER($I7),$I7,0) -> 10
A8: 7 | C8: OTO | D8: 814172 | E8: =IFERROR(VLOOKUP($D8,FIYAT!$B:$O,2,FALSE()),"") -> Авт. выкл. NXB-63 3P 25A 6кА х-ка C (R) | F8: =IFERROR(VLOOKUP($D8,FIYAT!$B:$O,5,FALSE()),"") -> 5334 | G8: =IFERROR(VLOOKUP($D8,FIYAT!$B:$O,8,FALSE()),"") -> 3200.4 | H8: =IF(OR($G8="",$I8=""),"",$G8*$I8) -> 3200.4 | I8: 1 | J8: =IFERROR(VLOOKUP($D8,FIYAT!$B:$O,9,FALSE()),"") -> Шт. | K8: =IFERROR(VLOOKUP($D8,FIYAT!$B:$O,4,FALSE()),"") -> CHINT | L8: =IF($H8="","",$H8) -> 3200.4 | P8: =IF($H8="","FIYAT_YOK",IFERROR(VLOOKUP($D8,FIYAT!$B:$P,15,FALSE()),"")) -> OK | Q8: 3P 25A 6kA C — birebir | R8: CHINT 27.08.2026 | S8: 170001-ST-EL-CD-BLA-SPD-XX-R02 | T8: OTO_3P | U8: =IFERROR(VLOOKUP($T8,KURALLAR!$A$32:$B$63,2,FALSE()),0)*IF(ISNUMBER($I8),$I8,0) -> 8
A9: 8 | C9: OTO | D9: 814014 | E9: =IFERROR(VLOOKUP($D9,FIYAT!$B:$O,2,FALSE()),"") -> Авт. выкл. NXB-63 1P 16A 6кА х-ка C (R) | F9: =IFERROR(VLOOKUP($D9,FIYAT!$B:$O,5,FALSE()),"") -> 1389 | G9: =IFERROR(VLOOKUP($D9,FIYAT!$B:$O,8,FALSE()),"") -> 833.4 | H9: =IF(OR($G9="",$I9=""),"",$G9*$I9) -> 14167.8 | I9: 17 | J9: =IFERROR(VLOOKUP($D9,FIYAT!$B:$O,9,FALSE()),"") -> Шт. | K9: =IFERROR(VLOOKUP($D9,FIYAT!$B:$O,4,FALSE()),"") -> CHINT | L9: =IF($H9="","",$H9) -> 14167.8 | P9: =IF($H9="","FIYAT_YOK",IFERROR(VLOOKUP($D9,FIYAT!$B:$P,15,FALSE()),"")) -> OK | Q9: 1P 16A 6kA C — birebir | R9: CHINT 27.08.2026 | S9: 170001-ST-EL-CD-BLA-SPD-XX-R02 | T9: OTO_1P | U9: =IFERROR(VLOOKUP($T9,KURALLAR!$A$32:$B$63,2,FALSE()),0)*IF(ISNUMBER($I9),$I9,0) -> 51
A10: 9 | C10: DIF | D10: 200316 | E10: =IFERROR(VLOOKUP($D10,FIYAT!$B:$O,2,FALSE()),"") -> УЗО NL1-63 6kA 4P 25A 30mA тип AC (R) | F10: =IFERROR(VLOOKUP($D10,FIYAT!$B:$O,5,FALSE()),"") -> 18338 | G10: =IFERROR(VLOOKUP($D10,FIYAT!$B:$O,8,FALSE()),"") -> 11002.8 | H10: =IF(OR($G10="",$I10=""),"",$G10*$I10) -> 11002.8 | I10: 1 | J10: =IFERROR(VLOOKUP($D10,FIYAT!$B:$O,9,FALSE()),"") -> Шт. | K10: =IFERROR(VLOOKUP($D10,FIYAT!$B:$O,4,FALSE()),"") -> CHINT | L10: =IF($H10="","",$H10) -> 11002.8 | P10: =IF($H10="","FIYAT_YOK",IFERROR(VLOOKUP($D10,FIYAT!$B:$P,15,FALSE()),"")) -> OK | Q10: 4P 25A 30mA AC — birebir | R10: CHINT 27.08.2026 | S10: 170001-ST-EL-CD-BLA-SPD-XX-R02 | T10: DIF_4P | U10: =IFERROR(VLOOKUP($T10,KURALLAR!$A$32:$B$63,2,FALSE()),0)*IF(ISNUMBER($I10),$I10,0) -> 10
A11: 10 | C11: DIF | D11: 200359 | E11: =IFERROR(VLOOKUP($D11,FIYAT!$B:$O,2,FALSE()),"") -> УЗО NL1-63 6kA 2P 16A 30mA тип AC (R) | F11: =IFERROR(VLOOKUP($D11,FIYAT!$B:$O,5,FALSE()),"") -> 10809 | G11: =IFERROR(VLOOKUP($D11,FIYAT!$B:$O,8,FALSE()),"") -> 6485.4 | H11: =IF(OR($G11="",$I11=""),"",$G11*$I11) -> 6485.4 | I11: 1 | J11: =IFERROR(VLOOKUP($D11,FIYAT!$B:$O,9,FALSE()),"") -> Шт. | K11: =IFERROR(VLOOKUP($D11,FIYAT!$B:$O,4,FALSE()),"") -> CHINT | L11: =IF($H11="","",$H11) -> 6485.4 | P11: =IF($H11="","FIYAT_YOK",IFERROR(VLOOKUP($D11,FIYAT!$B:$P,15,FALSE()),"")) -> OK | Q11: 2P 16A 30mA AC — birebir | R11: CHINT 27.08.2026 | S11: 170001-ST-EL-CD-BLA-SPD-XX-R02 | T11: DIF_2P | U11: =IFERROR(VLOOKUP($T11,KURALLAR!$A$32:$B$63,2,FALSE()),0)*IF(ISNUMBER($I11),$I11,0) -> 6
A12: 11 | C12: OTO | D12: 814015 | E12: =IFERROR(VLOOKUP($D12,FIYAT!$B:$O,2,FALSE()),"") -> Авт. выкл. NXB-63 1P 20A 6кА х-ка C (R) | F12: =IFERROR(VLOOKUP($D12,FIYAT!$B:$O,5,FALSE()),"") -> 1434 | G12: =IFERROR(VLOOKUP($D12,FIYAT!$B:$O,8,FALSE()),"") -> 860.4 | H12: =IF(OR($G12="",$I12=""),"",$G12*$I12) -> 860.4 | I12: 1 | J12: =IFERROR(VLOOKUP($D12,FIYAT!$B:$O,9,FALSE()),"") -> Шт. | K12: =IFERROR(VLOOKUP($D12,FIYAT!$B:$O,4,FALSE()),"") -> CHINT | L12: =IF($H12="","",$H12) -> 860.4 | P12: =IF($H12="","FIYAT_YOK",IFERROR(VLOOKUP($D12,FIYAT!$B:$P,15,FALSE()),"")) -> OK | Q12: 1P 20A 6kA C — birebir | R12: CHINT 27.08.2026 | S12: 170001-ST-EL-CD-BLA-SPD-XX-R02 | T12: OTO_1P | U12: =IFERROR(VLOOKUP($T12,KURALLAR!$A$32:$B$63,2,FALSE()),0)*IF(ISNUMBER($I12),$I12,0) -> 3
A13: 12 | C13: OTO | D13: 814013 | E13: =IFERROR(VLOOKUP($D13,FIYAT!$B:$O,2,FALSE()),"") -> Авт. выкл. NXB-63 1P 10A 6кА х-ка C (R) | F13: =IFERROR(VLOOKUP($D13,FIYAT!$B:$O,5,FALSE()),"") -> 1362 | G13: =IFERROR(VLOOKUP($D13,FIYAT!$B:$O,8,FALSE()),"") -> 817.2 | H13: =IF(OR($G13="",$I13=""),"",$G13*$I13) -> 3268.8 | I13: 4 | J13: =IFERROR(VLOOKUP($D13,FIYAT!$B:$O,9,FALSE()),"") -> Шт. | K13: =IFERROR(VLOOKUP($D13,FIYAT!$B:$O,4,FALSE()),"") -> CHINT | L13: =IF($H13="","",$H13) -> 3268.8 | P13: =IF($H13="","FIYAT_YOK",IFERROR(VLOOKUP($D13,FIYAT!$B:$P,15,FALSE()),"")) -> OK | Q13: 1P 10A 6kA C — birebir | R13: CHINT 02.02.2026 | S13: 170001-ST-EL-CD-BLA-SPD-XX-R02 | T13: OTO_1P | U13: =IFERROR(VLOOKUP($T13,KURALLAR!$A$32:$B$63,2,FALSE()),0)*IF(ISNUMBER($I13),$I13,0) -> 12
A14: 13 | C14: BLOK | D14: 718-84007 | E14: =IFERROR(VLOOKUP($D14,FIYAT!$B:$O,2,FALSE()),"") -> Шина "N" нулевая 6х9мм на DIN-рейку в корпусном изоляторе ШНИ 12К IEK (10) | F14: =IFERROR(VLOOKUP($D14,FIYAT!$B:$O,5,FALSE()),"") -> 755 | G14: =IFERROR(VLOOKUP($D14,FIYAT!$B:$O,8,FALSE()),"") -> 453 | H14: =IF(OR($G14="",$I14=""),"",$G14*$I14) -> 1812 | I14: 4 | J14: =IFERROR(VLOOKUP($D14,FIYAT!$B:$O,9,FALSE()),"") -> Шт. | K14: =IFERROR(VLOOKUP($D14,FIYAT!$B:$O,4,FALSE()),"") -> KAZTEK | L14: =IF($H14="","",$H14) -> 1812 | P14: =IF($H14="","FIYAT_YOK",IFERROR(VLOOKUP($D14,FIYAT!$B:$P,15,FALSE()),"")) -> MUADIL | Q14: CHINT listesinde 4x11 dagitim blogu yok; 4 kutup icin 4 ad. izoleli SHNI 12K barasi alindi (adet x4) | R14: KAZTEK 15.07.2026 | S14: 170001-ST-EL-CD-BLA-SPD-XX-R02 | T14: BLOK | U14: =IFERROR(VLOOKUP($T14,KURALLAR!$A$32:$B$63,2,FALSE()),0)*IF(ISNUMBER($I14),$I14,0) -> 32
A15: 14 | C15: KORPUS | D15: 719-15380 | E15: =IFERROR(VLOOKUP($D15,FIYAT!$B:$O,2,FALSE()),"") -> ЩМП (инд.) IP31 (650х500х150мм) | F15: =IFERROR(VLOOKUP($D15,FIYAT!$B:$O,5,FALSE()),"") -> 27825 | G15: =IFERROR(VLOOKUP($D15,FIYAT!$B:$O,8,FALSE()),"") -> 16695 | H15: =IF(OR($G15="",$I15=""),"",$G15*$I15) -> 16695 | I15: 1 | J15: =IFERROR(VLOOKUP($D15,FIYAT!$B:$O,9,FALSE()),"") -> Шт. | K15: =IFERROR(VLOOKUP($D15,FIYAT!$B:$O,4,FALSE()),"") -> KAZTEK | L15: =IF($H15="","",$H15) -> 16695 | P15: =IF($H15="","FIYAT_YOK",IFERROR(VLOOKUP($D15,FIYAT!$B:$P,15,FALSE()),"")) -> VARSAYIM | Q15: proje 460x700x200 duvar tipi FORM 2B -> KAZTEK 650x500x150; olcu/FORM sinifi KONTROL | R15: KAZTEK 15.07.2026 | S15: 170001-ST-EL-CD-BLA-SPD-XX-R02 | T15: KORPUS_ORTA | U15: =IFERROR(VLOOKUP($T15,KURALLAR!$A$32:$B$63,2,FALSE()),0)*IF(ISNUMBER($I15),$I15,0) -> 30
A16: 15 | C16: MONTAJNYY MATERIAL | D16: MONTAJ-MALZEME | E16: =IFERROR(VLOOKUP($D16,FIYAT!$B:$O,2,FALSE()),"") -> Монтажный расходный материал (кабель, DIN-рейка, кабель-канал, клеммы, маркировка, крепёж) | F16: =IFERROR(VLOOKUP($D16,FIYAT!$B:$O,5,FALSE()),"") -> 0 | G16: =IFERROR(VLOOKUP($D16,FIYAT!$B:$O,8,FALSE()),"") | H16: =ROUND(SUM($H$3:$H$15)*KURALLAR!$B$28,0) -> 9494 | I16: 1 | J16: =IFERROR(VLOOKUP($D16,FIYAT!$B:$O,9,FALSE()),"") -> компл. | K16: =IFERROR(VLOOKUP($D16,FIYAT!$B:$O,4,FALSE()),"") -> MUADIL-NET | L16: =IF($H16="","",$H16) -> 9494 | P16: =IF($H16="","FIYAT_YOK",IFERROR(VLOOKUP($D16,FIYAT!$B:$P,15,FALSE()),"")) -> ORAN | Q16: pano ici sarf malzemesi = pano malzeme bedelinin %si (KURALLAR BLOK 3 sari hucre) | R16: KURALLAR oran | S16: 170001-ST-EL-CD-BLA-SPD-XX-R02 | U16: 0
A17: 16 | C17: MONTAJNAYA RABOTA | D17: ISCILIK-MONTAJ | E17: =IFERROR(VLOOKUP($D17,FIYAT!$B:$O,2,FALSE()),"") -> Сборка, кабелирование, маркировка, момент затяжки, испытания | F17: =IFERROR(VLOOKUP($D17,FIYAT!$B:$O,5,FALSE()),"") -> 100 | G17: =IFERROR(VLOOKUP($D17,FIYAT!$B:$O,8,FALSE()),"") -> 100 | H17: =IF(OR($G17="",$I17=""),"",$G17*$I17) -> 25200 | I17: =ROUND(SUM($U$3:$U$16)*KURALLAR!$B$27,0) -> 252 | J17: =IFERROR(VLOOKUP($D17,FIYAT!$B:$O,9,FALSE()),"") -> мин | K17: =IFERROR(VLOOKUP($D17,FIYAT!$B:$O,4,FALSE()),"") -> ISCILIK | L17: =IF($H17="","",$H17) -> 25200 | P17: =IF($H17="","FIYAT_YOK",IFERROR(VLOOKUP($D17,FIYAT!$B:$P,15,FALSE()),"")) -> OK | Q17: =CONCATENATE("montaj+test iscilik: ",TEXT($I17,"# ##0")," dk = ",TEXT($I17/60,"0,00")," saat (norm x test/etiket carpani)") -> montaj+test iscilik: 252 dk = 4,20 saat (norm x test/etiket carpani) | R17: TEKLED norm | S17: 170001-ST-EL-CD-BLA-SPD-XX-R02 | U17: 0
A18: 17 | B18: Toplam BLOK A / ЩК-стандарт | H18: =SUBTOTAL(9,H3:H17) -> 170326.4 | L18: =SUBTOTAL(9,L3:L17) -> 170326.4 | U18: =SUBTOTAL(9,U3:U17) -> 219
A19: 18 | B19: =E19 -> BLOK A / ЩЭ-F(4-23).1 — НКУ 380/220В 50Гц, FORM 2B, IP31/54 | C19: korpus komplekt | E19: BLOK A / ЩЭ-F(4-23).1 — НКУ 380/220В 50Гц, FORM 2B, IP31/54 | I19: 1 | J19: комплект | P19: OK | Q19: komplekt adedi OZET C sutununda; pano ici malzemeler 1 pano icindir | R19: APEX CNC.xlsx | S19: 170001-ST-EL-CD-BLA-SPD-XX-R02
A20: 19 | C20: TMS | D20: 271538 | E20: =IFERROR(VLOOKUP($D20,FIYAT!$B:$O,2,FALSE()),"") -> Авт. выкл. NM8N-125C TM 3P 80А 36кА с рег. термомаг. расцепителем (R) | F20: =IFERROR(VLOOKUP($D20,FIYAT!$B:$O,5,FALSE()),"") -> 64129 | G20: =IFERROR(VLOOKUP($D20,FIYAT!$B:$O,8,FALSE()),"") -> 38477.4 | H20: =IF(OR($G20="",$I20=""),"",$G20*$I20) -> 38477.4 | I20: 1 | J20: =IFERROR(VLOOKUP($D20,FIYAT!$B:$O,9,FALSE()),"") -> Шт. | K20: =IFERROR(VLOOKUP($D20,FIYAT!$B:$O,4,FALSE()),"") -> CHINT | L20: =IF($H20="","",$H20) -> 38477.4 | P20: =IF($H20="","FIYAT_YOK",IFERROR(VLOOKUP($D20,FIYAT!$B:$P,15,FALSE()),"")) -> OK | Q20: 125 govde 80A 36kA — birebir | R20: CHINT 27.08.2026 | S20: 170001-ST-EL-CD-BLA-SPD-XX-R02 | T20: TMS_125 | U20: =IFERROR(VLOOKUP($T20,KURALLAR!$A$32:$B$63,2,FALSE()),0)*IF(ISNUMBER($I20),$I20,0) -> 15
A21: 20 | C21: DIF | D21: 449980 | E21: =IFERROR(VLOOKUP($D21,FIYAT!$B:$O,2,FALSE()),"") -> Диф. модуль NM8NL-125 4P RCD1 X рег. ток утечки 0,03-0,05-0,1-0,2-0,3-0,5-1-2 A (R) | F21: =IFERROR(VLOOKUP($D21,FIYAT!$B:$O,5,FALSE()),"") -> 83791 | G21: =IFERROR(VLOOKUP($D21,FIYAT!$B:$O,8,FALSE()),"") -> 50274.6 | H21: =IF(OR($G21="",$I21=""),"",$G21*$I21) -> 50274.6 | I21: 1 | J21: =IFERROR(VLOOKUP($D21,FIYAT!$B:$O,9,FALSE()),"") -> Шт. | K21: =IFERROR(VLOOKUP($D21,FIYAT!$B:$O,4,FALSE()),"") -> CHINT | L21: =IF($H21="","",$H21) -> 50274.6 | P21: =IF($H21="","FIYAT_YOK",IFERROR(VLOOKUP($D21,FIYAT!$B:$P,15,FALSE()),"")) -> CIHAZ_BELIRSIZ | Q21: CHINT NL1-63 serisi max 63A — 4P 100A 300mA UZO yok. NM8N-125 4P govde + NM8NL-125 dif modulu teklif edildi; pano giris salteri 4P govdeye cevrilmelidir KONTROL | R21: CHINT 02.02.2026 | S21: 170001-ST-EL-CD-BLA-SPD-XX-R02 | T21: DIF_MODUL | U21: =IFERROR(VLOOKUP($T21,KURALLAR!$A$32:$B$63,2,FALSE()),0)*IF(ISNUMBER($I21),$I21,0) -> 20
A22: 21 | C22: FU | D22: 521260 | E22: =IFERROR(VLOOKUP($D22,FIYAT!$B:$O,2,FALSE()),"") -> Держатель плавкой вставки RT36-00-160, габарит 00, 160А | F22: =IFERROR(VLOOKUP($D22,FIYAT!$B:$O,5,FALSE()),"") -> 2038 | G22: =IFERROR(VLOOKUP($D22,FIYAT!$B:$O,8,FALSE()),"") -> 1222.8 | H22: =IF(OR($G22="",$I22=""),"",$G22*$I22) -> 4891.2 | I22: 4 | J22: =IFERROR(VLOOKUP($D22,FIYAT!$B:$O,9,FALSE()),"") -> Шт. | K22: =IFERROR(VLOOKUP($D22,FIYAT!$B:$O,4,FALSE()),"") -> CHINT | L22: =IF($H22="","",$H22) -> 4891.2 | P22: =IF($H22="","FIYAT_YOK",IFERROR(VLOOKUP($D22,FIYAT!$B:$P,15,FALSE()),"")) -> MUADIL | Q22: CHINT'te 14x51 (63A) silindirik yuva yok; NH00 (RT36-00) bicak sigorta yuvasi alindi — montaj/boyut farki KONTROL | R22: CHINT 27.08.2026 | S22: 170001-ST-EL-CD-BLA-SPD-XX-R02 | T22: FU_TUTUCU | U22: =IFERROR(VLOOKUP($T22,KURALLAR!$A$32:$B$63,2,FALSE()),0)*IF(ISNUMBER($I22),$I22,0) -> 20
A23: 22 | C23: FU | D23: 521347 | E23: =IFERROR(VLOOKUP($D23,FIYAT!$B:$O,2,FALSE()),"") -> Плавкая вставка предохранителя RT36-00-160, габарит 00, 63А | F23: =IFERROR(VLOOKUP($D23,FIYAT!$B:$O,5,FALSE()),"") -> 1525 | G23: =IFERROR(VLOOKUP($D23,FIYAT!$B:$O,8,FALSE()),"") -> 915 | H23: =IF(OR($G23="",$I23=""),"",$G23*$I23) -> 3660 | I23: 4 | J23: =IFERROR(VLOOKUP($D23,FIYAT!$B:$O,9,FALSE()),"") -> Шт. | K23: =IFERROR(VLOOKUP($D23,FIYAT!$B:$O,4,FALSE()),"") -> CHINT | L23: =IF($H23="","",$H23) -> 3660 | P23: =IF($H23="","FIYAT_YOK",IFERROR(VLOOKUP($D23,FIYAT!$B:$P,15,FALSE()),"")) -> MUADIL | Q23: 14x51 63A yerine NH00 63A busonu | R23: CHINT 02.02.2026 | S23: 170001-ST-EL-CD-BLA-SPD-XX-R02 | T23: FU | U23: =IFERROR(VLOOKUP($T23,KURALLAR!$A$32:$B$63,2,FALSE()),0)*IF(ISNUMBER($I23),$I23,0) -> 12
A24: 23 | C24: OPN | D24: 252578 | E24: =IFERROR(VLOOKUP($D24,FIYAT!$B:$O,2,FALSE()),"") -> Ограничитель имп. перенапр. NU6-IIG 4Р In=25kA Uc=440B Im=65kA (R) | F24: =IFERROR(VLOOKUP($D24,FIYAT!$B:$O,5,FALSE()),"") -> 33208 | G24: =IFERROR(VLOOKUP($D24,FIYAT!$B:$O,8,FALSE()),"") -> 19924.8 | H24: =IF(OR($G24="",$I24=""),"",$G24*$I24) -> 19924.8 | I24: 1 | J24: =IFERROR(VLOOKUP($D24,FIYAT!$B:$O,9,FALSE()),"") -> Шт. | K24: =IFERROR(VLOOKUP($D24,FIYAT!$B:$O,4,FALSE()),"") -> CHINT | L24: =IF($H24="","",$H24) -> 19924.8 | P24: =IF($H24="","FIYAT_YOK",IFERROR(VLOOKUP($D24,FIYAT!$B:$P,15,FALSE()),"")) -> MUADIL_ONAY | Q24: CNC YCS6-B 4P 60kA 420V -> CHINT NU6-IIG 4P Uc=440V In=25kA Imax=65kA. Class I (Iimp) isteniyorsa 308602 NXU-I+II 4P KONTROL | R24: CHINT 02.02.2026 | S24: 170001-ST-EL-CD-BLA-SPD-XX-R02 | T24: OPN | U24: =IFERROR(VLOOKUP($T24,KURALLAR!$A$32:$B$63,2,FALSE()),0)*IF(ISNUMBER($I24),$I24,0) -> 10
A25: 24 | C25: OTO | D25: 814012 | E25: =IFERROR(VLOOKUP($D25,FIYAT!$B:$O,2,FALSE()),"") -> Авт. выкл. NXB-63 1P 6A 6кА х-ка C (R) | F25: =IFERROR(VLOOKUP($D25,FIYAT!$B:$O,5,FALSE()),"") -> 1436 | G25: =IFERROR(VLOOKUP($D25,FIYAT!$B:$O,8,FALSE()),"") -> 861.6 | H25: =IF(OR($G25="",$I25=""),"",$G25*$I25) -> 3446.4 | I25: 4 | J25: =IFERROR(VLOOKUP($D25,FIYAT!$B:$O,9,FALSE()),"") -> Шт. | K25: =IFERROR(VLOOKUP($D25,FIYAT!$B:$O,4,FALSE()),"") -> CHINT | L25: =IF($H25="","",$H25) -> 3446.4 | P25: =IF($H25="","FIYAT_YOK",IFERROR(VLOOKUP($D25,FIYAT!$B:$P,15,FALSE()),"")) -> OK | Q25: 1P 6A 6kA C — birebir | R25: CHINT 27.08.2026 | S25: 170001-ST-EL-CD-BLA-SPD-XX-R02 | T25: OTO_1P | U25: =IFERROR(VLOOKUP($T25,KURALLAR!$A$32:$B$63,2,FALSE()),0)*IF(ISNUMBER($I25),$I25,0) -> 12
A26: 25 | C26: LAMB | D26: 593085 | E26: =IFERROR(VLOOKUP($D26,FIYAT!$B:$O,2,FALSE()),"") -> Индикатор ND16-22DS/4 белый АС230В (R) | F26: =IFERROR(VLOOKUP($D26,FIYAT!$B:$O,5,FALSE()),"") -> 1047 | G26: =IFERROR(VLOOKUP($D26,FIYAT!$B:$O,8,FALSE()),"") -> 628.2 | H26: =IF(OR($G26="",$I26=""),"",$G26*$I26) -> 1884.6 | I26: 3 | J26: =IFERROR(VLOOKUP($D26,FIYAT!$B:$O,9,FALSE()),"") -> Шт. | K26: =IFERROR(VLOOKUP($D26,FIYAT!$B:$O,4,FALSE()),"") -> CHINT | L26: =IF($H26="","",$H26) -> 1884.6 | P26: =IF($H26="","FIYAT_YOK",IFERROR(VLOOKUP($D26,FIYAT!$B:$P,15,FALSE()),"")) -> OK | Q26: beyaz sinyal lambasi 230V | R26: CHINT 02.02.2026 | S26: 170001-ST-EL-CD-BLA-SPD-XX-R02 | T26: LAMB | U26: =IFERROR(VLOOKUP($T26,KURALLAR!$A$32:$B$63,2,FALSE()),0)*IF(ISNUMBER($I26),$I26,0) -> 12
A27: 26 | C27: OTO | D27: 814174 | E27: =IFERROR(VLOOKUP($D27,FIYAT!$B:$O,2,FALSE()),"") -> Авт. выкл. NXB-63 3P 40A 6кА х-ка C (R) | F27: =IFERROR(VLOOKUP($D27,FIYAT!$B:$O,5,FALSE()),"") -> 5647 | G27: =IFERROR(VLOOKUP($D27,FIYAT!$B:$O,8,FALSE()),"") -> 3388.2 | H27: =IF(OR($G27="",$I27=""),"",$G27*$I27) -> 23717.4 | I27: 7 | J27: =IFERROR(VLOOKUP($D27,FIYAT!$B:$O,9,FALSE()),"") -> Шт. | K27: =IFERROR(VLOOKUP($D27,FIYAT!$B:$O,4,FALSE()),"") -> CHINT | L27: =IF($H27="","",$H27) -> 23717.4 | P27: =IF($H27="","FIYAT_YOK",IFERROR(VLOOKUP($D27,FIYAT!$B:$P,15,FALSE()),"")) -> OK | Q27: 3P 40A 6kA C — birebir | R27: CHINT 27.08.2026 | S27: 170001-ST-EL-CD-BLA-SPD-XX-R02 | T27: OTO_3P | U27: =IFERROR(VLOOKUP($T27,KURALLAR!$A$32:$B$63,2,FALSE()),0)*IF(ISNUMBER($I27),$I27,0) -> 56
A28: 27 | C28: SAYAC | D28: EX-518U-100A | E28: =IFERROR(VLOOKUP($D28,FIYAT!$B:$O,2,FALSE()),"") -> Трехфазный эл.счетчик EX 518 10(100)А (прям. подкл.) с PLC модулем | F28: =IFERROR(VLOOKUP($D28,FIYAT!$B:$O,5,FALSE()),"") -> 0 | G28: =IFERROR(VLOOKUP($D28,FIYAT!$B:$O,8,FALSE()),"") | H28: =IF(OR($G28="",$I28=""),"",$G28*$I28) | I28: 5 | J28: =IFERROR(VLOOKUP($D28,FIYAT!$B:$O,9,FALSE()),"") -> Шт. | K28: =IFERROR(VLOOKUP($D28,FIYAT!$B:$O,4,FALSE()),"") -> MUADIL-NET | L28: =IF($H28="","",$H28) | P28: =IF($H28="","FIYAT_YOK",IFERROR(VLOOKUP($D28,FIYAT!$B:$P,15,FALSE()),"")) -> FIYAT_YOK | Q28: Elektron Xisoblagich sayaci — CHINT listesinde yok, fiyat alinacak | S28: 170001-ST-EL-CD-BLA-SPD-XX-R02 | T28: SAYAC | U28: =IFERROR(VLOOKUP($T28,KURALLAR!$A$32:$B$63,2,FALSE()),0)*IF(ISNUMBER($I28),$I28,0) -> 150
A29: 28 | C29: SINA | D29: BARA-AL-SAT | E29: =IFERROR(VLOOKUP($D29,FIYAT!$B:$O,2,FALSE()),"") -> Шина алюминиевая твёрдая (ШАТ) | F29: =IFERROR(VLOOKUP($D29,FIYAT!$B:$O,5,FALSE()),"") -> 4493.6 | G29: =IFERROR(VLOOKUP($D29,FIYAT!$B:$O,8,FALSE()),"") -> 4493.6 | H29: =IF(OR($G29="",$I29=""),"",$G29*$I29) -> 89872 | I29: 20 | J29: =IFERROR(VLOOKUP($D29,FIYAT!$B:$O,9,FALSE()),"") -> Кг. | K29: =IFERROR(VLOOKUP($D29,FIYAT!$B:$O,4,FALSE()),"") -> ALUM-BARA | L29: =IF($H29="","",$H29) -> 89872 | P29: =IF($H29="","FIYAT_YOK",IFERROR(VLOOKUP($D29,FIYAT!$B:$P,15,FALSE()),"")) -> VARSAYIM | Q29: alu bara — kg fiyati KURALLAR BLOK 8'den hesaplanir | S29: 170001-ST-EL-CD-BLA-SPD-XX-R02 | T29: BARA_KG | U29: =IFERROR(VLOOKUP($T29,KURALLAR!$A$32:$B$63,2,FALSE()),0)*IF(ISNUMBER($I29),$I29,0) -> 120
A30: 29 | C30: KORPUS | D30: 719-15636 | E30: =IFERROR(VLOOKUP($D30,FIYAT!$B:$O,2,FALSE()),"") -> Щит (moduler) 2000x800x800+100 | F30: =IFERROR(VLOOKUP($D30,FIYAT!$B:$O,5,FALSE()),"") -> 197400 | G30: =IFERROR(VLOOKUP($D30,FIYAT!$B:$O,8,FALSE()),"") -> 118440 | H30: =IF(OR($G30="",$I30=""),"",$G30*$I30) -> 118440 | I30: 1 | J30: =IFERROR(VLOOKUP($D30,FIYAT!$B:$O,9,FALSE()),"") -> Шт. | K30: =IFERROR(VLOOKUP($D30,FIYAT!$B:$O,4,FALSE()),"") -> KAZTEK | L30: =IF($H30="","",$H30) -> 118440 | P30: =IF($H30="","FIYAT_YOK",IFERROR(VLOOKUP($D30,FIYAT!$B:$P,15,FALSE()),"")) -> VARSAYIM | Q30: proje 900x2100x400 -> KAZTEK 2000x800x800+baza (genislik eksik); olcu KONTROL | R30: KAZTEK 15.07.2026 | S30: 170001-ST-EL-CD-BLA-SPD-XX-R02 | T30: KORPUS_DIKILI | U30: =IFERROR(VLOOKUP($T30,KURALLAR!$A$32:$B$63,2,FALSE()),0)*IF(ISNUMBER($I30),$I30,0) -> 90
A31: 30 | C31: MONTAJNYY MATERIAL | D31: MONTAJ-MALZEME | E31: =IFERROR(VLOOKUP($D31,FIYAT!$B:$O,2,FALSE()),"") -> Монтажный расходный материал (кабель, DIN-рейка, кабель-канал, клеммы, маркировка, крепёж) | F31: =IFERROR(VLOOKUP($D31,FIYAT!$B:$O,5,FALSE()),"") -> 0 | G31: =IFERROR(VLOOKUP($D31,FIYAT!$B:$O,8,FALSE()),"") | H31: =ROUND(SUM($H$20:$H$30)*KURALLAR!$B$28,0) -> 24821 | I31: 1 | J31: =IFERROR(VLOOKUP($D31,FIYAT!$B:$O,9,FALSE()),"") -> компл. | K31: =IFERROR(VLOOKUP($D31,FIYAT!$B:$O,4,FALSE()),"") -> MUADIL-NET | L31: =IF($H31="","",$H31) -> 24821 | P31: =IF($H31="","FIYAT_YOK",IFERROR(VLOOKUP($D31,FIYAT!$B:$P,15,FALSE()),"")) -> ORAN | Q31: pano ici sarf malzemesi = pano malzeme bedelinin %si (KURALLAR BLOK 3 sari hucre) | R31: KURALLAR oran | S31: 170001-ST-EL-CD-BLA-SPD-XX-R02 | U31: 0
A32: 31 | C32: MONTAJNAYA RABOTA | D32: ISCILIK-MONTAJ | E32: =IFERROR(VLOOKUP($D32,FIYAT!$B:$O,2,FALSE()),"") -> Сборка, кабелирование, маркировка, момент затяжки, испытания | F32: =IFERROR(VLOOKUP($D32,FIYAT!$B:$O,5,FALSE()),"") -> 100 | G32: =IFERROR(VLOOKUP($D32,FIYAT!$B:$O,8,FALSE()),"") -> 100 | H32: =IF(OR($G32="",$I32=""),"",$G32*$I32) -> 59500 | I32: =ROUND(SUM($U$20:$U$31)*KURALLAR!$B$27,0) -> 595 | J32: =IFERROR(VLOOKUP($D32,FIYAT!$B:$O,9,FALSE()),"") -> мин | K32: =IFERROR(VLOOKUP($D32,FIYAT!$B:$O,4,FALSE()),"") -> ISCILIK | L32: =IF($H32="","",$H32) -> 59500 | P32: =IF($H32="","FIYAT_YOK",IFERROR(VLOOKUP($D32,FIYAT!$B:$P,15,FALSE()),"")) -> OK | Q32: =CONCATENATE("montaj+test iscilik: ",TEXT($I32,"# ##0")," dk = ",TEXT($I32/60,"0,00")," saat (norm x test/etiket carpani)") -> montaj+test iscilik: 595 dk = 9,92 saat (norm x test/etiket carpani) | R32: TEKLED norm | S32: 170001-ST-EL-CD-BLA-SPD-XX-R02 | U32: 0
A33: 32 | B33: Toplam BLOK A / ЩЭ-F(4-23).1 | H33: =SUBTOTAL(9,H20:H32) -> 438909.4 | L33: =SUBTOTAL(9,L20:L32) -> 438909.4 | U33: =SUBTOTAL(9,U20:U32) -> 517
A34: 33 | B34: =E34 -> BLOK A / ЩЭ-F(4-23).2 — НКУ 380/220В 50Гц, FORM 2B, IP31/54 | C34: korpus komplekt | E34: BLOK A / ЩЭ-F(4-23).2 — НКУ 380/220В 50Гц, FORM 2B, IP31/54 | I34: 1 | J34: комплект | P34: OK | Q34: komplekt adedi OZET C sutununda; pano ici malzemeler 1 pano icindir | R34: APEX CNC.xlsx | S34: 170001-ST-EL-CD-BLA-SPD-XX-R02
A35: 34 | C35: TMS | D35: 271538 | E35: =IFERROR(VLOOKUP($D35,FIYAT!$B:$O,2,FALSE()),"") -> Авт. выкл. NM8N-125C TM 3P 80А 36кА с рег. термомаг. расцепителем (R) | F35: =IFERROR(VLOOKUP($D35,FIYAT!$B:$O,5,FALSE()),"") -> 64129 | G35: =IFERROR(VLOOKUP($D35,FIYAT!$B:$O,8,FALSE()),"") -> 38477.4 | H35: =IF(OR($G35="",$I35=""),"",$G35*$I35) -> 38477.4 | I35: 1 | J35: =IFERROR(VLOOKUP($D35,FIYAT!$B:$O,9,FALSE()),"") -> Шт. | K35: =IFERROR(VLOOKUP($D35,FIYAT!$B:$O,4,FALSE()),"") -> CHINT | L35: =IF($H35="","",$H35) -> 38477.4 | P35: =IF($H35="","FIYAT_YOK",IFERROR(VLOOKUP($D35,FIYAT!$B:$P,15,FALSE()),"")) -> OK | Q35: 125 govde 80A 36kA — birebir | R35: CHINT 27.08.2026 | S35: 170001-ST-EL-CD-BLA-SPD-XX-R02 | T35: TMS_125 | U35: =IFERROR(VLOOKUP($T35,KURALLAR!$A$32:$B$63,2,FALSE()),0)*IF(ISNUMBER($I35),$I35,0) -> 15
A36: 35 | C36: DIF | D36: 449980 | E36: =IFERROR(VLOOKUP($D36,FIYAT!$B:$O,2,FALSE()),"") -> Диф. модуль NM8NL-125 4P RCD1 X рег. ток утечки 0,03-0,05-0,1-0,2-0,3-0,5-1-2 A (R) | F36: =IFERROR(VLOOKUP($D36,FIYAT!$B:$O,5,FALSE()),"") -> 83791 | G36: =IFERROR(VLOOKUP($D36,FIYAT!$B:$O,8,FALSE()),"") -> 50274.6 | H36: =IF(OR($G36="",$I36=""),"",$G36*$I36) -> 50274.6 | I36: 1 | J36: =IFERROR(VLOOKUP($D36,FIYAT!$B:$O,9,FALSE()),"") -> Шт. | K36: =IFERROR(VLOOKUP($D36,FIYAT!$B:$O,4,FALSE()),"") -> CHINT | L36: =IF($H36="","",$H36) -> 50274.6 | P36: =IF($H36="","FIYAT_YOK",IFERROR(VLOOKUP($D36,FIYAT!$B:$P,15,FALSE()),"")) -> CIHAZ_BELIRSIZ | Q36: CHINT NL1-63 serisi max 63A — 4P 100A 300mA UZO yok. NM8N-125 4P govde + NM8NL-125 dif modulu teklif edildi; pano giris salteri 4P govdeye cevrilmelidir KONTROL | R36: CHINT 02.02.2026 | S36: 170001-ST-EL-CD-BLA-SPD-XX-R02 | T36: DIF_MODUL | U36: =IFERROR(VLOOKUP($T36,KURALLAR!$A$32:$B$63,2,FALSE()),0)*IF(ISNUMBER($I36),$I36,0) -> 20
A37: 36 | C37: FU | D37: 521260 | E37: =IFERROR(VLOOKUP($D37,FIYAT!$B:$O,2,FALSE()),"") -> Держатель плавкой вставки RT36-00-160, габарит 00, 160А | F37: =IFERROR(VLOOKUP($D37,FIYAT!$B:$O,5,FALSE()),"") -> 2038 | G37: =IFERROR(VLOOKUP($D37,FIYAT!$B:$O,8,FALSE()),"") -> 1222.8 | H37: =IF(OR($G37="",$I37=""),"",$G37*$I37) -> 4891.2 | I37: 4 | J37: =IFERROR(VLOOKUP($D37,FIYAT!$B:$O,9,FALSE()),"") -> Шт. | K37: =IFERROR(VLOOKUP($D37,FIYAT!$B:$O,4,FALSE()),"") -> CHINT | L37: =IF($H37="","",$H37) -> 4891.2 | P37: =IF($H37="","FIYAT_YOK",IFERROR(VLOOKUP($D37,FIYAT!$B:$P,15,FALSE()),"")) -> MUADIL | Q37: CHINT'te 14x51 (63A) silindirik yuva yok; NH00 (RT36-00) bicak sigorta yuvasi alindi — montaj/boyut farki KONTROL | R37: CHINT 27.08.2026 | S37: 170001-ST-EL-CD-BLA-SPD-XX-R02 | T37: FU_TUTUCU | U37: =IFERROR(VLOOKUP($T37,KURALLAR!$A$32:$B$63,2,FALSE()),0)*IF(ISNUMBER($I37),$I37,0) -> 20
A38: 37 | C38: FU | D38: 521347 | E38: =IFERROR(VLOOKUP($D38,FIYAT!$B:$O,2,FALSE()),"") -> Плавкая вставка предохранителя RT36-00-160, габарит 00, 63А | F38: =IFERROR(VLOOKUP($D38,FIYAT!$B:$O,5,FALSE()),"") -> 1525 | G38: =IFERROR(VLOOKUP($D38,FIYAT!$B:$O,8,FALSE()),"") -> 915 | H38: =IF(OR($G38="",$I38=""),"",$G38*$I38) -> 3660 | I38: 4 | J38: =IFERROR(VLOOKUP($D38,FIYAT!$B:$O,9,FALSE()),"") -> Шт. | K38: =IFERROR(VLOOKUP($D38,FIYAT!$B:$O,4,FALSE()),"") -> CHINT | L38: =IF($H38="","",$H38) -> 3660 | P38: =IF($H38="","FIYAT_YOK",IFERROR(VLOOKUP($D38,FIYAT!$B:$P,15,FALSE()),"")) -> MUADIL | Q38: 14x51 63A yerine NH00 63A busonu | R38: CHINT 02.02.2026 | S38: 170001-ST-EL-CD-BLA-SPD-XX-R02 | T38: FU | U38: =IFERROR(VLOOKUP($T38,KURALLAR!$A$32:$B$63,2,FALSE()),0)*IF(ISNUMBER($I38),$I38,0) -> 12
A39: 38 | C39: OPN | D39: 252578 | E39: =IFERROR(VLOOKUP($D39,FIYAT!$B:$O,2,FALSE()),"") -> Ограничитель имп. перенапр. NU6-IIG 4Р In=25kA Uc=440B Im=65kA (R) | F39: =IFERROR(VLOOKUP($D39,FIYAT!$B:$O,5,FALSE()),"") -> 33208 | G39: =IFERROR(VLOOKUP($D39,FIYAT!$B:$O,8,FALSE()),"") -> 19924.8 | H39: =IF(OR($G39="",$I39=""),"",$G39*$I39) -> 19924.8 | I39: 1 | J39: =IFERROR(VLOOKUP($D39,FIYAT!$B:$O,9,FALSE()),"") -> Шт. | K39: =IFERROR(VLOOKUP($D39,FIYAT!$B:$O,4,FALSE()),"") -> CHINT | L39: =IF($H39="","",$H39) -> 19924.8 | P39: =IF($H39="","FIYAT_YOK",IFERROR(VLOOKUP($D39,FIYAT!$B:$P,15,FALSE()),"")) -> MUADIL_ONAY | Q39: CNC YCS6-B 4P 60kA 420V -> CHINT NU6-IIG 4P Uc=440V In=25kA Imax=65kA. Class I (Iimp) isteniyorsa 308602 NXU-I+II 4P KONTROL | R39: CHINT 02.02.2026 | S39: 170001-ST-EL-CD-BLA-SPD-XX-R02 | T39: OPN | U39: =IFERROR(VLOOKUP($T39,KURALLAR!$A$32:$B$63,2,FALSE()),0)*IF(ISNUMBER($I39),$I39,0) -> 10
A40: 39 | C40: OTO | D40: 814012 | E40: =IFERROR(VLOOKUP($D40,FIYAT!$B:$O,2,FALSE()),"") -> Авт. выкл. NXB-63 1P 6A 6кА х-ка C (R) | F40: =IFERROR(VLOOKUP($D40,FIYAT!$B:$O,5,FALSE()),"") -> 1436 | G40: =IFERROR(VLOOKUP($D40,FIYAT!$B:$O,8,FALSE()),"") -> 861.6 | H40: =IF(OR($G40="",$I40=""),"",$G40*$I40) -> 3446.4 | I40: 4 | J40: =IFERROR(VLOOKUP($D40,FIYAT!$B:$O,9,FALSE()),"") -> Шт. | K40: =IFERROR(VLOOKUP($D40,FIYAT!$B:$O,4,FALSE()),"") -> CHINT | L40: =IF($H40="","",$H40) -> 3446.4 | P40: =IF($H40="","FIYAT_YOK",IFERROR(VLOOKUP($D40,FIYAT!$B:$P,15,FALSE()),"")) -> OK | Q40: 1P 6A 6kA C — birebir | R40: CHINT 27.08.2026 | S40: 170001-ST-EL-CD-BLA-SPD-XX-R02 | T40: OTO_1P | U40: =IFERROR(VLOOKUP($T40,KURALLAR!$A$32:$B$63,2,FALSE()),0)*IF(ISNUMBER($I40),$I40,0) -> 12
...

Sheet OZET
A1: № | B1: BLOK | C1: PANO | D1: KOMPLEKT ADET | E1: 1 PANO TOPLAM (KZT) | F1: TOPLAM (KZT) | G1: 1 PANO ISCILIK (dk) | H1: 1 PANO ISCILIK (saat) | I1: PDF
A2: 1 | B2: BLOK A | C2: ЩК-стандарт | D2: 1 | E2: =BOM!$H$18 -> 170326.4 | F2: =IF($E2="","",$E2*$D2) -> 170326.4 | G2: =BOM!$I$17 -> 252 | H2: =ROUND($G2/60,2) -> 4.2 | I2: 170001-ST-EL-CD-BLA-SPD-XX-R02
A3: 2 | B3: BLOK A | C3: ЩЭ-F(4-23).1 | D3: 20 | E3: =BOM!$H$33 -> 438909.4 | F3: =IF($E3="","",$E3*$D3) -> 8778188 | G3: =BOM!$I$32 -> 595 | H3: =ROUND($G3/60,2) -> 9.92 | I3: 170001-ST-EL-CD-BLA-SPD-XX-R02
A4: 3 | B4: BLOK A | C4: ЩЭ-F(4-23).2 | D4: 20 | E4: =BOM!$H$48 -> 438909.4 | F4: =IF($E4="","",$E4*$D4) -> 8778188 | G4: =BOM!$I$47 -> 595 | H4: =ROUND($G4/60,2) -> 9.92 | I4: 170001-ST-EL-CD-BLA-SPD-XX-R02
A5: 4 | B5: BLOK A | C5: ЩЭ-F24.1 | D5: 1 | E5: =BOM!$H$63 -> 278643.6 | F5: =IF($E5="","",$E5*$D5) -> 278643.6 | G5: =BOM!$I$62 -> 397 | H5: =ROUND($G5/60,2) -> 6.62 | I5: 170001-ST-EL-CD-BLA-SPD-XX-R02
A6: 5 | B6: BLOK A | C6: ЩЭ-F24.2 | D6: 1 | E6: =BOM!$H$78 -> 278643.6 | F6: =IF($E6="","",$E6*$D6) -> 278643.6 | G6: =BOM!$I$77 -> 397 | H6: =ROUND($G6/60,2) -> 6.62 | I6: 170001-ST-EL-CD-BLA-SPD-XX-R02
A7: 6 | B7: BLOK A | C7: 24F-ЩК(1-4) | D7: 1 | E7: =BOM!$H$97 -> 224887.6 | F7: =IF($E7="","",$E7*$D7) -> 224887.6 | G7: =BOM!$I$96 -> 297 | H7: =ROUND($G7/60,2) -> 4.95 | I7: 170001-ST-EL-CD-BLA-SPD-XX-R02
A8: 7 | B8: BLOK A | C8: ЩЭ-F3 | D8: 1 | E8: =BOM!$H$116 -> 736978.6 | F8: =IF($E8="","",$E8*$D8) -> 736978.6 | G8: =BOM!$I$115 -> 667 | H8: =ROUND($G8/60,2) -> 11.12 | I8: 170001-ST-EL-CD-BLA-SPD-XX-R02
A9: 8 | B9: BLOK A | C9: ЩЭ-F2 | D9: 1 | E9: =BOM!$H$136 -> 635746.4 | F9: =IF($E9="","",$E9*$D9) -> 635746.4 | G9: =BOM!$I$135 -> 662 | H9: =ROUND($G9/60,2) -> 11.03 | I9: 170001-ST-EL-CD-BLA-SPD-XX-R02
A10: 9 | B10: BLOK A | C10: ЩЭ-F1 | D10: 1 | E10: =BOM!$H$158 -> 635374.4 | F10: =IF($E10="","",$E10*$D10) -> 635374.4 | G10: =BOM!$I$157 -> 662 | H10: =ROUND($G10/60,2) -> 11.03 | I10: 170001-ST-EL-CD-BLA-SPD-XX-R02
