Workbook

Sheet BOM
A1: YSF HICH — 260827 AKTAU DUMAN — ВРУ-0,4кВ / АВР — CHINT PANO BOM v1
A2: Fiyat: CHINT ×0.60 | KAZTEK ×1.00 | EKT/UNIT/IEK ×1.00 | SAIMAN ×1.00 | Katsayilar: Kurallar sayfasi (sari hucreler)
A4: ROW | B4: Наименование1 | C4: Тип | D4: Артикул | E4: Номенклатура | F4: Цена | G4: Нетто KZT | H4: Сумма KZT (1 щит) | I4: Кол-во | J4: Ед.изм. | K4: Завод | L4: Сумма KZT (проект) | M4: Группа | N4: — | O4: —
A5: 4 | B5: ШАВР-3-400-2(У) IP54 УХЛ3 — шкаф АВР 400А | C5: щит | E5: ШАВР-3-400-2(У) IP54 УХЛ3 — шкаф АВР 400А | I5: 1 | J5: компл.
A6: 4 | C6: korpus | D6: 719-15085 | E6: Мет.Корпус ВРУ (1700X700X450+10X700 База) IP31 | F6: 154595 | G6: =0.6*F6 -> 92757 | H6: =G6*I6 -> 92757 | I6: 1 | J6: шт. | K6: KAZTEK | L6: =H6*$I$5 -> 92757 | M6: korpus
A7: 4 | C7: TMŞ | D7: 131373 | E7: Авт. выкл. NXM-400S/3Р 400A 50кА (R) | F7: 74241 | G7: =F7*Kurallar!$B$2 -> 44544.6 | H7: =G7*I7 -> 89089.2 | I7: 2 | J7: шт. | K7: CHINT | L7: =H7*$I$5 -> 89089.2 | M7: TMŞ
A8: 4 | C8: blok ats | D8: 256811 | E8: Устройство автоматического ввода резерва NXZM-400S/3B 400A (R) | F8: 579699 | G8: =F8*Kurallar!$B$2 -> 347819.4 | H8: =G8*I8 -> 347819.4 | I8: 1 | J8: шт. | K8: CHINT | L8: =H8*$I$5 -> 347819.4 | M8: blok
A9: 4 | C9: OTO | D9: 814014 | E9: Авт. выкл. NXB-63 1P 16A 6кА х-ка C, 220В — доп. автомат цепей управления | F9: 1389 | G9: =F9*Kurallar!$B$2 -> 833.4 | H9: =G9*I9 -> 833.4 | I9: 1 | J9: шт. | K9: CHINT | L9: =H9*$I$5 -> 833.4 | M9: OTO
A10: 4 | C10: lamb | D10: 593077 | E10: Индикатор ND16-22D/2 зеленый AC/DC230В — EL1 / EL2 | F10: 589 | G10: =F10*Kurallar!$B$2 -> 353.4 | H10: =G10*I10 -> 706.8 | I10: 2 | J10: шт. | K10: CHINT | L10: =H10*$I$5 -> 706.8 | M10: lamb
A11: 4 | C11: lamb | D11: 592865 | E11: Индикатор ND16-22D/2 зеленый AC/DC380В — контроль фаз ввод 1/2 | F11: 836 | G11: =F11*Kurallar!$B$2 -> 501.6 | H11: =G11*I11 -> 3009.6 | I11: 6 | J11: шт. | K11: CHINT | L11: =H11*$I$5 -> 3009.6 | M11: lamb
A12: 4 | C12: busbar | D12: 130300324_ | E12: Шина медн.4х50х4000 | F12: 18357 | G12: =F12*Kurallar!$B$4 -> 18357 | H12: =G12*I12 -> 183570 | I12: 10 | J12: м | K12: ekt | L12: =H12*$I$5 -> 183570 | M12: bara
A13: 4 | C13: din | D13: 570003 | E13: DIN-рейка оцинкованная TH35-7.5 100см | F13: 869 | G13: =F13*Kurallar!$B$2 -> 521.4 | H13: =G13*I13 -> 1042.8 | I13: 2 | J13: шт. | K13: CHINT | L13: =H13*$I$5 -> 1042.8 | M13: din
A14: 4 | C14: Klemens | D14: 130301153 | E14: Зажим наборный ЗНИ 4мм² (35А) серый UNIT | F14: 90 | G14: =F14*Kurallar!$B$4 -> 90 | H14: =G14*I14 -> 1800 | I14: 20 | J14: шт. | K14: EKT | L14: =H14*$I$5 -> 1800 | M14: Klemens
A15: 4 | C15: kablo | D15: 100300025 | E15: Провод ПВ3-2,5 белый ГОСТ — цепи управления | F15: 144 | G15: =F15*Kurallar!$B$4 -> 144 | H15: =G15*I15 -> 8640 | I15: 60 | J15: м | K15: EKT | L15: =H15*$I$5 -> 8640 | M15: kablo
A16: 4 | C16: pabuc | D16: UNP41-035-10-10 | E16: Наконечник медный луженый ТМЛ 35–10–10 | F16: 398 | G16: =F16*Kurallar!$B$4 -> 398 | H16: =G16*I16 -> 4776 | I16: 12 | J16: шт. | K16: EKT | L16: =H16*$I$5 -> 4776 | M16: pabuc
A17: 4 | C17: монтажный материал | E17: Монтажный материал / montaj sarf malzemesi (%3) | G17: =SUM(H6:H16)*Kurallar!$B$6 -> 22021.326 | H17: =G17*I17 -> 22021.326 | I17: 1 | J17: компл. | K17: TEKLED | L17: =H17*$I$5 -> 22021.326 | M17: монтажный материал
A18: 4 | C18: монтажная работа | E18: Монтажные работы / pano montaj-kablaj iscilligi (690 dk) | F18: =I18/60 -> 11.5 | G18: =Kurallar!$B$7 -> 100 | H18: =G18*I18 -> 69000 | I18: 690 | J18: мин | K18: TEKLED | L18: =H18*$I$5 -> 69000 | M18: монтажная работа
B19: Toplam ШАВР-3-400-2(У) IP54 УХЛ3 — шкаф АВР 400 | E19: Toplam — 1 щит / проект 1 шт | H19: =SUBTOTAL(9,H6:H18) -> 825065.53 | I19: 1 | J19: компл. | L19: =SUBTOTAL(9,L6:L18) -> 825065.53
A20: 1 | B20: ВРУ1-11-10 УХЛ4 IP31 — вводная — распределительная панель | C20: щит | E20: ВРУ1-11-10 УХЛ4 IP31 — вводная — распределительная панель | I20: 1 | J20: компл.
A21: 1 | C21: korpus | D21: 719-15085 | E21: Мет.Корпус ВРУ (1700X700X450+10X700 База) IP31 | F21: 154595 | G21: =0.6*F21 -> 92757 | H21: =G21*I21 -> 278271 | I21: 3 | J21: шт. | K21: KAZTEK | L21: =H21*$I$20 -> 278271 | M21: korpus
A22: 1 | C22: TMŞ | D22: 131373 | E22: Авт. выкл. NXM-400S/3Р 400A 50кА (R) | F22: 74241 | G22: =F22*Kurallar!$B$2 -> 44544.6 | H22: =G22*I22 -> 133633.8 | I22: 3 | J22: шт. | K22: CHINT | L22: =H22*$I$20 -> 133633.8 | M22: TMŞ
A23: 1 | C23: TMŞ | D23: 844363 | E23: Авт. выкл. NXM-400S/3Р 320A 50кА (R) | F23: 73736 | G23: =F23*Kurallar!$B$2 -> 44241.6 | H23: =G23*I23 -> 132724.8 | I23: 3 | J23: шт. | K23: CHINT | L23: =H23*$I$20 -> 132724.8 | M23: TMŞ
A24: 1 | C24: TMŞ | D24: 131369 | E24: Авт. выкл. NXM-250S/3Р 250A 36кА (R) | F24: 36869 | G24: =F24*Kurallar!$B$2 -> 22121.4 | H24: =G24*I24 -> 66364.2 | I24: 3 | J24: шт. | K24: CHINT | L24: =H24*$I$20 -> 66364.2 | M24: TMŞ
A25: 2 | C25: TMŞ | D25: 131361 | E25: Авт. выкл. NXM-125S/3Р 80A 25кА (R) | F25: 19418 | G25: =F25*Kurallar!$B$2 -> 11650.8 | H25: =G25*I25 -> 34952.4 | I25: 3 | J25: шт. | K25: CHINT | L25: =H25*$I$20 -> 34952.4 | M25: TMŞ
A26: 2 | C26: TMŞ | D26: 844300 | E26: Авт. выкл. NXM-125S/3Р 32A 25кА (R) | F26: 19700 | G26: =F26*Kurallar!$B$2 -> 11820 | H26: =G26*I26 -> 35460 | I26: 3 | J26: шт. | K26: CHINT | L26: =H26*$I$20 -> 35460 | M26: TMŞ
A27: 2 | C27: TMŞ | D27: 844299 | E27: Авт. выкл. NXM-125S/3Р 25A 25кА (R) | F27: 18139 | G27: =F27*Kurallar!$B$2 -> 10883.4 | H27: =G27*I27 -> 43533.6 | I27: 4 | J27: шт. | K27: CHINT | L27: =H27*$I$20 -> 43533.6 | M27: TMŞ
A28: 1 | C28: sayac | D28: IA | E28: ДАЛА СА4У-Э720 R TX OP П RS1 Д W (3x220/380V 5-7,5A) | F28: 88000 | G28: =F28*Kurallar!$B$5 -> 88000 | H28: =G28*I28 -> 264000 | I28: 3 | J28: шт. | K28: SAIMAN | L28: =H28*$I$20 -> 264000 | M28: sayac
A29: 1 | C29: tt | D29: VJ | E29: Трансформатор тока ТШП-0,66 У3 кл.точн. 0,5, 250/5А (1ТАа...1ТАс) | F29: 5350 | G29: =F29*Kurallar!$B$5 -> 5350 | H29: =G29*I29 -> 48150 | I29: 9 | J29: шт. | K29: ekt | L29: =H29*$I$20 -> 48150 | M29: tt
A30: 1 | C30: opn | D30: 252559 | E30: Ограничитель имп. перенапр. NU6-IIG 3Р+N In=25kA Uc=275В Im=65kA (FV1) | F30: 36941 | G30: =F30*Kurallar!$B$2 -> 22164.6 | H30: =G30*I30 -> 66493.8 | I30: 3 | J30: шт. | K30: CHINT | L30: =H30*$I$20 -> 66493.8 | M30: opn
A31: 1 | C31: kondensator | E31: Конденсатор связи КЗ 0,5 мкФ 0,66кВ (1Са...1Сс) | F31: 4500 | G31: =F31*Kurallar!$B$4 -> 4500 | H31: =G31*I31 -> 40500 | I31: 9 | J31: шт. | K31: ekt | L31: =H31*$I$20 -> 40500 | M31: fu
A32: 1 | C32: busbar | D32: 130300324_ | E32: Шина медн.4х50х4000 | F32: 18357 | G32: =F32*Kurallar!$B$4 -> 18357 | H32: =G32*I32 -> 770994 | I32: 42 | J32: м | K32: ekt | L32: =H32*$I$20 -> 770994 | M32: bara
A33: 1 | C33: bara | D33: 718-42016 | E33: Шина нулевая 8х12мм, 1м (N и PE) | F33: 1000 | G33: =F33*Kurallar!$B$3 -> 1000 | H33: =G33*I33 -> 4000 | I33: 4 | J33: шт. | K33: KAZTEK | L33: =H33*$I$20 -> 4000 | M33: bara
A34: 1 | C34: Klemens | D34: 130301157 | E34: Зажим наборный ЗНИ 16мм² (100А) серый UNIT | F34: 261 | G34: =F34*Kurallar!$B$4 -> 261 | H34: =G34*I34 -> 3915 | I34: 15 | J34: шт. | K34: EKT | L34: =H34*$I$20 -> 3915 | M34: Klemens
A35: 1 | C35: Klemens | D35: 130301153 | E35: Зажим наборный ЗНИ 4мм² (35А) серый UNIT — цепи учёта | F35: 90 | G35: =F35*Kurallar!$B$4 -> 90 | H35: =G35*I35 -> 3600 | I35: 40 | J35: шт. | K35: EKT | L35: =H35*$I$20 -> 3600 | M35: Klemens
A36: 1 | C36: kablo | D36: 100300016 | E36: Провод ПВ3-25 белый ГОСТ | F36: 1560 | G36: =F36*Kurallar!$B$4 -> 1560 | H36: =G36*I36 -> 46800 | I36: 30 | J36: м | K36: EKT | L36: =H36*$I$20 -> 46800 | M36: kablo
A37: 1 | C37: kablo | D37: 100300031 | E37: Провод ПВ3-6 белый ГОСТ | F37: 361 | G37: =F37*Kurallar!$B$4 -> 361 | H37: =G37*I37 -> 21660 | I37: 60 | J37: м | K37: EKT | L37: =H37*$I$20 -> 21660 | M37: kablo
A38: 1 | C38: kablo | D38: 100300025 | E38: Провод ПВ3-2,5 белый ГОСТ — вторичные цепи | F38: 144 | G38: =F38*Kurallar!$B$4 -> 144 | H38: =G38*I38 -> 11520 | I38: 80 | J38: м | K38: EKT | L38: =H38*$I$20 -> 11520 | M38: kablo
A39: 1 | C39: pabuc | D39: UNP41-025-08-08 | E39: Наконечник медный луженый ТМЛ 25–8–8 | F39: 264 | G39: =F39*Kurallar!$B$4 -> 264 | H39: =G39*I39 -> 10560 | I39: 40 | J39: шт. | K39: EKT | L39: =H39*$I$20 -> 10560 | M39: pabuc
A40: 1 | C40: монтажный материал | E40: Монтажный материал / montaj sarf malzemesi (%3) | G40: =SUM(H21:H39)*Kurallar!$B$6 -> 60513.978 | H40: =G40*I40 -> 60513.978 | I40: 1 | J40: компл. | K40: TEKLED | L40: =H40*$I$20 -> 60513.978 | M40: монтажный материал
A41: 1 | C41: монтажная работа | E41: Монтажные работы / pano montaj-kablaj iscilligi (1330 dk) | F41: =I41/60*2.5 -> 55.416667 | G41: =Kurallar!$B$7 -> 100 | H41: =G41*I41*2 -> 266000 | I41: 1330 | J41: мин | K41: TEKLED | L41: =H41*$I$20 -> 266000 | M41: монтажная работа
...

Sheet СВОД
A1: СВОД — 260827 Aktau Duman — ВРУ-0,4кВ / АВР
A3: № | B3: Щит | C3: Кол-во, шт | D3: Цена за 1 щит, ₸ | E3: Сумма, ₸ | F3: Монтаж, мин
A4: 1 | B4: ВРУ1-11-10 УХЛ4 IP31 — вводная панель | C4: 1 | D4: =BOM!H42 -> 2343646.6 | E4: =BOM!L42 -> 2343646.6 | F4: 1330 | G4: =2.3*D4 -> 5390387.1
A5: 3 | B5: БУО — блок автоматического управления освещением 14х16А с фотореле | C5: 1 | D5: =BOM!H59 -> 146844.36 | E5: =BOM!L59 -> 146844.36 | F5: 480 | G5: =2.3*D5 -> 337742.03
A6: 4 | B6: ШАВР-3-400-2(У) IP54 УХЛ3 — шкаф АВР 400А | C6: 1 | D6: =BOM!H19 -> 825065.53 | E6: =BOM!L19 -> 825065.53 | F6: 690 | G6: =2.3*D6 -> 1897650.7
A7: 5 | B7: Ящик с понижающим трансформатором 220/36В, 250Вт | C7: 1 | D7: 25000 | E7: =D7*C7 -> 25000 | F7: 30 | G7: =2.3*D7 -> 57500
B8: ИТОГО | E8: =SUM(E4:E7) -> 3340556.5 | F8: =SUM(F4:F7) -> 2530

Sheet Kurallar
A1: KURALLAR / KATSAYILAR — sari hucreler duzenlenebilir
A2: CHINT net katsayi (liste ×) | B2: 0.6
A3: KAZTEK / TEKSAN net katsayi | B3: 1
A4: EKT / UNIT / IEK net katsayi | B4: 1
A5: SAIMAN net katsayi | B5: 1
A6: Montaj malzemesi (malzeme ×) | B6: 0.03
A7: Iscilik birim, KZT/dk | B7: 100
A8: Iscilik test/etiket carpani | B8: 1.15
A9: Genel gider % | B9: 0.08
A10: Kar % | B10: 0.15
A11: KDV % | B11: 0.12
A13: 1) FIYAT YOK — satir BOM'da kaldi, F/G/H/L bos, C sutunu "FIYAT YOK"
A14: Мет. Щит ВРУ 1-11-10 УХЛ4 (1700х800х450) | KAZTEK 719-15010 | artikul var, fiyat listesinde BOS. Fiyatli en yakin: 719-15085 Мет.Корпус ВРУ (1700x700x450+10 baza) IP31 = 154.595 KZT (genislik 700 vs 800).
A15: Мет. Щит ВРУ 1-50-03 АУХЛ4 (1700х800х450) IP31 | KAZTEK | ВРУ1-50-03 tipi fiyat listesinde YOK. Fiyatli en yakin: 719-15085 = 154.595 KZT.
A16: Конденсатор связи КЗ 0,5 мкФ 0,66кВ (1Са...1Сс), 9 adet | hicbir fiyat listesinde YOK. PLC sayac baglanti kondansatoru — tedarikciden teklif alinmali.
A17: Медная сборная шина A/B/C/N/PE 40х5мм + izolator, 3 panoda 3 komplekt | fiyat listelerinde bakir bara YOK. Kesit kisa devre ve termik hesapla netlesecek.
A19: 2) CIHAZ BELIRSIZ
A20: Semada "ВА 88-32 320 А" ve "ВА 88-33 400/320 А" yazilmis. ВА88-32 gercekte 125А govdedir; 320А bu govdede YOKTUR. Amper esas alindi: 320А -> NM8N-400C TM 3P 400А (ayar 0,8x400=320А), 250А -> NM8N-250C TM 3P 250А. Alternatif NM8N-400S (50kA) secilirse fark +8.843 KZT/adet.
A21: 1QF secmeli kesme kapasitesi semada belirtilmemis. 36kA (C serisi) varsayildi. Trafo gucu/Ik hesabi 36kA'yi asarsa S (50kA) veya Q (70kA) serisine gecilmeli — 400А icin fark: C=208.671, S=223.410, Q=253.271 (liste).
A22: БУО ic yapisi semada detaylandirilmamis; 14x16А grup + 4 modüler kontaktor + fotorole + Р-0-А secici varsayildi.
A23: Sayac tipi: siparis "САР 4 У-Э720 TX P PLC IP П RS". SAIMAN listesinde PLC varyanti YOK. Kullanilan: LE / Дала СА4У-Э720 R TX IP П RS Д = 39.100 KZT. PLC haberlesme sart ise SaiCom P1 3-faz PLC modem (YJ, 14.500 KZT) x3 EKLENMELI. MUHENDIS ONAYI GEREKLI.
A25: 3) MUADIL KULLANILDI
A26: ВА88-32 / ВА88-33 (IEK) -> CHINT NM8N serisi | onayli | musteri CHINT istedi, amper/kutup birebir.
... A54: Toplam EKSIKTIR — 4 kalem fiyatsiz (2 korpus, kondansator, bakir bara).
