Workbook
Name ADRES: KURALLAR!$B$169
Name AL_YOGUNLUK: KURALLAR!$B$193
Name ALAN_TIP_LIST: KURALLAR!$A$458:$A$463
Name ALUM_KG_KZT: KURALLAR!$B$195
Name ALUM_KG_USD: KURALLAR!$B$189
Name AMBALAJ_KZT_PANO: KURALLAR!$B$180
Name BAKIR_KG_KZT: KURALLAR!$B$194
Name BAKIR_KG_USD: KURALLAR!$B$188
Name BARA_AL_A: KURALLAR!$J$242:$J$260
Name BARA_AL_KGM: KURALLAR!$G$242:$G$260
Name BARA_AL_S_A: KURALLAR!$D$295:$D$324
Name BARA_AL_S_KOD: KURALLAR!$A$295:$A$324
Name BARA_AL_S_MAX: KURALLAR!$E$295:$E$324
Name BARA_AL_S_MM2T: KURALLAR!$C$295:$C$324
Name BARA_AL_S_SERIT: KURALLAR!$B$295:$B$324
Name BARA_AL2_A: KURALLAR!$K$242:$K$260
Name BARA_BOY_M: KURALLAR!$B$114
Name BARA_CU_A: KURALLAR!$H$242:$H$260
Name BARA_CU_KGM: KURALLAR!$F$242:$F$260
Name BARA_CU_S_A: KURALLAR!$D$263:$D$292
Name BARA_CU_S_KOD: KURALLAR!$A$263:$A$292
Name BARA_CU_S_MAX: KURALLAR!$E$263:$E$292
Name BARA_CU_S_MM2T: KURALLAR!$C$263:$C$292
Name BARA_CU_S_SERIT: KURALLAR!$B$263:$B$292
Name BARA_CU2_A: KURALLAR!$I$242:$I$260
Name BARA_DERATING: KURALLAR!$B$164
Name BARA_DIKEY_PAY_M: KURALLAR!$B$116
Name BARA_FIRE: KURALLAR!$B$109
Name BARA_ISLEM_KAT: KURALLAR!$B$191
Name BARA_IZOLATOR_ARALIK_M: KURALLAR!$B$117
Name BARA_KENAR_PAY_M: KURALLAR!$B$115
Name BARA_KOD_AL: KURALLAR!$B$242:$B$260
Name BARA_KOD_CU: KURALLAR!$A$242:$A$260
Name BARA_KOPRU_M: KURALLAR!$B$113
Name BARA_MM2: KURALLAR!$E$242:$E$260
Name BARA_N_ORANI: KURALLAR!$B$110
Name BARA_PE_MIN_MM2: KURALLAR!$B$112
Name BARA_PE_ORANI: KURALLAR!$B$111
Name BARA_T_ILETKEN: KURALLAR!$B$107
Name BARA_T_NORM: KURALLAR!$B$108
Name BARA_T_ORTAM: KURALLAR!$B$106
Name BOM_I: BOM!$I$2:$I$640
Name BOM_P: BOM!$M$2:$M$640
Name BOM_S: BOM!$P$2:$P$640
Name BOM_T: BOM!$Q$2:$Q$640
Name BOM_U: BOM!$R$2:$R$640
Name CU_YOGUNLUK: KURALLAR!$B$192
Name DEVRE_A: DEVRE!$A$2:$A$586
Name DEVRE_C: DEVRE!$C$2:$C$586
Name DEVRE_H: DEVRE!$H$2:$H$586
Name DEVRE_TIPI_LIST: KURALLAR!$A$466:$A$470
Name DEVRE_U: DEVRE!$U$2:$U$586
Name DINRAY_FIRE: KURALLAR!$B$148
Name DINRAY_KOD: KURALLAR!$B$158
Name DK_SAAT: KURALLAR!$B$22
Name DOKUMAN_KZT: KURALLAR!$B$184
Name DOLULUK_MAX: KURALLAR!$B$129
Name DOLULUK_UYARI: KURALLAR!$B$128
Name DURUM_LIST: KURALLAR!$A$399:$A$409
Name DURUM_SEV: KURALLAR!$B$399:$B$409

Sheet BOM
A1: ROW | B1: Наименование1 | C1: Тип | D1: Артикул | E1: Номенклатура | F1: Цена | G1: net | H1: сумма | I1: Qty | J1: Ед.изм | K1: Завод | L1: tutar | M1: DURUM | N1: NOT | O1: KAYNAK | P1: ANAHTAR | Q1: PANO_ID | R1: NORM_ANAHTAR | S1: ETIKET_ELLE | T1: ISCILIK_DK | U1: ALAN_MODUL | V1: BARA_KG | W1: MALZ_TABAN | X1: SARF_KESIT | Y1: NEDEN | Z1: DEVRE_SEV | AA1: TOPLAM_QTY | AB1: ALAN_EKSIK | AC1: BOBIN_EKSIK
A2: =ROW()-1 -> 1 | B2: =$E2 -> Вводно-распределительное устройство ВРУ-1 (с АВР) | E2: =INDEX(PANO_TAMAD,MATCH($Q2,PANO_ID,0)) -> Вводно-распределительное устройство ВРУ-1 (с АВР) | I2: 1 | J2: компл. | Q2: P01
A3: =ROW()-1 -> 2 | B3: =$E3 -> Shit 2000x800x450+100mm | C3: korpus | D3: =IF($P3="","",IF(INDEX(FIYAT_ARTIKUL,MATCH($P3,FIYAT_KOD,0))="","",INDEX(FIYAT_ARTIKUL,MATCH($P3,FIYAT_KOD,0)))) -> 719-15696 | E3: =IF($P3="","",INDEX(FIYAT_ACK,MATCH($P3,FIYAT_KOD,0))) -> Shit 2000x800x450+100mm | F3: =IF($P3="","",IF(INDEX(FIYAT_LISTE,MATCH($P3,FIYAT_KOD,0))="","",INDEX(FIYAT_LISTE,MATCH($P3,FIYAT_KOD,0)))) -> 172785 | G3: =IF($P3="","",IF(INDEX(FIYAT_NET,MATCH($P3,FIYAT_KOD,0))="","",INDEX(FIYAT_NET,MATCH($P3,FIYAT_KOD,0)))) -> 103671 | H3: =IF(OR($G3="",$I3="",$M3="KONTROL",$M3="KAPSAM_DISI"),"",$G3*$I3) | I3: 1 | J3: =IF($P3="","",INDEX(FIYAT_BIRIM,MATCH($P3,FIYAT_KOD,0))) -> шт | K3: =IF($P3="","",INDEX(FIYAT_MARKA,MATCH($P3,FIYAT_KOD,0))) -> KAZTEK | L3: =IF($H3="","",$H3) | M3: =IF($P3="","",INDEX(DURUM_LIST,MATCH(MAX(INDEX(DURUM_SEV,MATCH(INDEX(FIYAT_DURUM,MATCH($P3,FIYAT_KOD,0)),DURUM_LIST,0)),IF($S3="",0,INDEX(DURUM_SEV,MATCH($S3,DURUM_LIST,0))),$Z3),DURUM_SEV,0))) -> KONTROL | N3: ОЛ: ВРУ-2 20.80.45 IP31 2000х800х450 → KAZTEK 2000x800x450 (IP açıklamada yok) | O3: =IF($P3="","",INDEX(FIYAT_KAYNAK,MATCH($P3,FIYAT_KOD,0))) -> KAZTEK2607 | P3: =INDEX(PANO_KORPUS,MATCH($Q3,PANO_ID,0)) -> KAZTEK-719-15696 | Q3: =$Q2 -> P01 | R3: KORPUS_AYAKLI | T3: =IF(OR($R3="",$I3=""),"",$I3*INDEX(NORM_DK,MATCH($R3,NORM_AD,0))) -> 90 | U3: =IF(OR($P3="",$I3=""),"",IF(IF(INDEX(FIYAT_ALAN,MATCH($P3,FIYAT_KOD,0))="","",INDEX(FIYAT_ALAN,MATCH($P3,FIYAT_KOD,0)))<>"",$I3*IF(INDEX(FIYAT_ALAN,MATCH($P3,FIYAT_KOD,0))="","",INDEX(FIYAT_ALAN,MATCH($P3,FIYAT_KOD,0))),IF(IF(INDEX(FIYAT_MODUL,MATCH($P3,FIYAT_KOD,0))="","",INDEX(FIYAT_MODUL,MATCH($P3,FIYAT_KOD,0)))<>"",$I3*IF(INDEX(FIYAT_MODUL,MATCH($P3,FIYAT_KOD,0))="","",INDEX(FIYAT_MODUL,MATCH($P3,FIYAT_KOD,0))),IF(IF(INDEX(FIYAT_GENISLIK,MATCH($P3,FIYAT_KOD,0))="","",INDEX(FIYAT_GENISLIK,MATCH($P3,FIYAT_KOD,0)))<>"",$I3*IF(INDEX(FIYAT_GENISLIK,MATCH($P3,FIYAT_KOD,0))="","",INDEX(FIYAT_GENISLIK,MATCH($P3,FIYAT_KOD,0)))/MODUL_GENISLIK_MM,"")))) | V3: =IF(OR($C3<>"шина",$I3=""),"",$I3*INDEX(FIYAT_KGM,MATCH($P3,FIYAT_KOD,0))) | W3: =IF($H3="","",$H3) | Y3: KORPUS | Z3: =IF($P3="","",MAX(_xlfn.MAXIFS(DEVRE!$AM:$AM,DEVRE!$A:$A,$Q3,DEVRE!$C:$C,$P3),_xlfn.MAXIFS(DEVRE!$AM:$AM,DEVRE!$A:$A,$Q3,DEVRE!$H:$H,$P3))) -> 0 | AA3: =IF(OR($I3="",$Q3="",$P3=""),"",$I3*INDEX(PANO_ADET,MATCH($Q3,PANO_ID,0))) -> 1 | AB3: =IF($P3="",0,IF(AND($U3="",COUNTIF(ALAN_TIP_LIST,$C3)>0),1,0)) -> 0 | AC3: =IF(OR($P3="",$C3<>"kontaktör"),0,IF(IF(INDEX(FIYAT_BOBIN,MATCH($P3,FIYAT_KOD,0))="","",INDEX(FIYAT_BOBIN,MATCH($P3,FIYAT_KOD,0)))="",1,0)) -> 0
A4: =ROW()-1 -> 3 | B4: =$E4 -> Авт. выкл. NXM-160S/3Р 125A 36кА | C4: TMŞ | D4: =IF($P4="","",IF(INDEX(FIYAT_ARTIKUL,MATCH($P4,FIYAT_KOD,0))="","",INDEX(FIYAT_ARTIKUL,MATCH($P4,FIYAT_KOD,0)))) -> 844326 | E4: =IF($P4="","",INDEX(FIYAT_ACK,MATCH($P4,FIYAT_KOD,0))) -> Авт. выкл. NXM-160S/3Р 125A 36кА | F4: =IF($P4="","",IF(INDEX(FIYAT_LISTE,MATCH($P4,FIYAT_KOD,0))="","",INDEX(FIYAT_LISTE,MATCH($P4,FIYAT_KOD,0)))) -> 27656 | G4: =IF($P4="","",IF(INDEX(FIYAT_NET,MATCH($P4,FIYAT_KOD,0))="","",INDEX(FIYAT_NET,MATCH($P4,FIYAT_KOD,0)))) -> 16593.6 | H4: =IF(OR($G4="",$I4="",$M4="KONTROL",$M4="KAPSAM_DISI"),"",$G4*$I4) -> 33187.2 | I4: =SUMIFS(DEVRE!$T:$T,DEVRE!$A:$A,$Q4,DEVRE!$C:$C,$P4)+SUMIFS(DEVRE!$U:$U,DEVRE!$A:$A,$Q4,DEVRE!$H:$H,$P4) -> 2 | J4: =IF($P4="","",INDEX(FIYAT_BIRIM,MATCH($P4,FIYAT_KOD,0))) -> шт | K4: =IF($P4="","",INDEX(FIYAT_MARKA,MATCH($P4,FIYAT_KOD,0))) -> CHINT | L4: =IF($H4="","",$H4) -> 33187.2 | M4: =IF($P4="","",INDEX(DURUM_LIST,MATCH(MAX(INDEX(DURUM_SEV,MATCH(INDEX(FIYAT_DURUM,MATCH($P4,FIYAT_KOD,0)),DURUM_LIST,0)),IF($S4="",0,INDEX(DURUM_SEV,MATCH($S4,DURUM_LIST,0))),$Z4),DURUM_SEV,0))) -> OK | N4: DEVRE: QF1, QF2 · şema 2 | O4: =IF($P4="","",INDEX(FIYAT_KAYNAK,MATCH($P4,FIYAT_KOD,0))) -> CHINT2608 | P4: CHINT-844326 | Q4: =$Q3 -> P01 | R4: MCCB_3P_250 | T4: =IF(OR($R4="",$I4=""),"",$I4*INDEX(NORM_DK,MATCH($R4,NORM_AD,0))) -> 120 | U4: =IF(OR($P4="",$I4=""),"",IF(IF(INDEX(FIYAT_ALAN,MATCH($P4,FIYAT_KOD,0))="","",INDEX(FIYAT_ALAN,MATCH($P4,FIYAT_KOD,0)))<>"",$I4*IF(INDEX(FIYAT_ALAN,MATCH($P4,FIYAT_KOD,0))="","",INDEX(FIYAT_ALAN,MATCH($P4,FIYAT_KOD,0))),IF(IF(INDEX(FIYAT_MODUL,MATCH($P4,FIYAT_KOD,0))="","",INDEX(FIYAT_MODUL,MATCH($P4,FIYAT_KOD,0)))<>"",$I4*IF(INDEX(FIYAT_MODUL,MATCH($P4,FIYAT_KOD,0))="","",INDEX(FIYAT_MODUL,MATCH($P4,FIYAT_KOD,0))),IF(IF(INDEX(FIYAT_GENISLIK,MATCH($P4,FIYAT_KOD,0))="","",INDEX(FIYAT_GENISLIK,MATCH($P4,FIYAT_KOD,0)))<>"",$I4*IF(INDEX(FIYAT_GENISLIK,MATCH($P4,FIYAT_KOD,0))="","",INDEX(FIYAT_GENISLIK,MATCH($P4,FIYAT_KOD,0)))/MODUL_GENISLIK_MM,"")))) | V4: =IF(OR($C4<>"шина",$I4=""),"",$I4*INDEX(FIYAT_KGM,MATCH($P4,FIYAT_KOD,0))) | W4: =IF($H4="","",$H4) -> 33187.2 | Y4: DEVRE | Z4: =IF($P4="","",MAX(_xlfn.MAXIFS(DEVRE!$AM:$AM,DEVRE!$A:$A,$Q4,DEVRE!$C:$C,$P4),_xlfn.MAXIFS(DEVRE!$AM:$AM,DEVRE!$A:$A,$Q4,DEVRE!$H:$H,$P4))) -> 0 | AA4: =IF(OR($I4="",$Q4="",$P4=""),"",$I4*INDEX(PANO_ADET,MATCH($Q4,PANO_ID,0))) -> 2 | AB4: =IF($P4="",0,IF(AND($U4="",COUNTIF(ALAN_TIP_LIST,$C4)>0),1,0)) -> 1 | AC4: =IF(OR($P4="",$C4<>"kontaktör"),0,IF(IF(INDEX(FIYAT_BOBIN,MATCH($P4,FIYAT_KOD,0))="","",INDEX(FIYAT_BOBIN,MATCH($P4,FIYAT_KOD,0)))="",1,0)) -> 0
A5: =ROW()-1 -> 4 | B5: =$E5 -> Счет.элек Меркурий 3ф 5 (7,5)A 230 ART-03 PQRSIDN многотариф/трансф | C5: sayac | D5: =IF($P5="","",IF(INDEX(FIYAT_ARTIKUL,MATCH($P5,FIYAT_KOD,0))="","",INDEX(FIYAT_ARTIKUL,MATCH($P5,FIYAT_KOD,0)))) -> 989-190-0114 | E5: =IF($P5="","",INDEX(FIYAT_ACK,MATCH($P5,FIYAT_KOD,0))) -> Счет.элек Меркурий 3ф 5 (7,5)A 230 ART-03 PQRSIDN многотариф/трансф | F5: =IF($P5="","",IF(INDEX(FIYAT_LISTE,MATCH($P5,FIYAT_KOD,0))="","",INDEX(FIYAT_LISTE,MATCH($P5,FIYAT_KOD,0)))) -> 35380 | G5: =IF($P5="","",IF(INDEX(FIYAT_NET,MATCH($P5,FIYAT_KOD,0))="","",INDEX(FIYAT_NET,MATCH($P5,FIYAT_KOD,0)))) -> 21228 | H5: =IF(OR($G5="",$I5="",$M5="KONTROL",$M5="KAPSAM_DISI"),"",$G5*$I5) -> 21228 | I5: =SUMIFS(DEVRE!$T:$T,DEVRE!$A:$A,$Q5,DEVRE!$C:$C,$P5)+SUMIFS(DEVRE!$U:$U,DEVRE!$A:$A,$Q5,DEVRE!$H:$H,$P5) -> 1 | J5: =IF($P5="","",INDEX(FIYAT_BIRIM,MATCH($P5,FIYAT_KOD,0))) -> шт | K5: =IF($P5="","",INDEX(FIYAT_MARKA,MATCH($P5,FIYAT_KOD,0))) -> KAZTEK | L5: =IF($H5="","",$H5) -> 21228 | M5: =IF($P5="","",INDEX(DURUM_LIST,MATCH(MAX(INDEX(DURUM_SEV,MATCH(INDEX(FIYAT_DURUM,MATCH($P5,FIYAT_KOD,0)),DURUM_LIST,0)),IF($S5="",0,INDEX(DURUM_SEV,MATCH($S5,DURUM_LIST,0))),$Z5),DURUM_SEV,0))) -> OK | N5: DEVRE: PI1 · şema 1 | O5: =IF($P5="","",INDEX(FIYAT_KAYNAK,MATCH($P5,FIYAT_KOD,0))) -> KAZTEK2607 | P5: KAZTEK-989-190-0114 | Q5: =$Q4 -> P01 | R5: SAYAC_AT | T5: =IF(OR($R5="",$I5=""),"",$I5*INDEX(NORM_DK,MATCH($R5,NORM_AD,0))) -> 90 | U5: =IF(OR($P5="",$I5=""),"",IF(IF(INDEX(FIYAT_ALAN,MATCH($P5,FIYAT_KOD,0))="","",INDEX(FIYAT_ALAN,MATCH($P5,FIYAT_KOD,0)))<>"",$I5*IF(INDEX(FIYAT_ALAN,MATCH($P5,FIYAT_KOD,0))="","",INDEX(FIYAT_ALAN,MATCH($P5,FIYAT_KOD,0))),IF(IF(INDEX(FIYAT_MODUL,MATCH($P5,FIYAT_KOD,0))="","",INDEX(FIYAT_MODUL,MATCH($P5,FIYAT_KOD,0)))<>"",$I5*IF(INDEX(FIYAT_MODUL,MATCH($P5,FIYAT_KOD,0))="","",INDEX(FIYAT_MODUL,MATCH($P5,FIYAT_KOD,0))),IF(IF(INDEX(FIYAT_GENISLIK,MATCH($P5,FIYAT_KOD,0))="","",INDEX(FIYAT_GENISLIK,MATCH($P5,FIYAT_KOD,0)))<>"",$I5*IF(INDEX(FIYAT_GENISLIK,MATCH($P5,FIYAT_KOD,0))="","",INDEX(FIYAT_GENISLIK,MATCH($P5,FIYAT_KOD,0)))/MODUL_GENISLIK_MM,"")))) | V5: =IF(OR($C5<>"шина",$I5=""),"",$I5*INDEX(FIYAT_KGM,MATCH($P5,FIYAT_KOD,0))) | W5: =IF($H5="","",$H5) -> 21228 | Y5: DEVRE | Z5: =IF($P5="","",MAX(_xlfn.MAXIFS(DEVRE!$AM:$AM,DEVRE!$A:$A,$Q5,DEVRE!$C:$C,$P5),_xlfn.MAXIFS(DEVRE!$AM:$AM,DEVRE!$A:$A,$Q5,DEVRE!$H:$H,$P5))) -> 0 | AA5: =IF(OR($I5="",$Q5="",$P5=""),"",$I5*INDEX(PANO_ADET,MATCH($Q5,PANO_ID,0))) -> 1 | AB5: =IF($P5="",0,IF(AND($U5="",COUNTIF(ALAN_TIP_LIST,$C5)>0),1,0)) -> 1 | AC5: =IF(OR($P5="",$C5<>"kontaktör"),0,IF(IF(INDEX(FIYAT_BOBIN,MATCH($P5,FIYAT_KOD,0))="","",INDEX(FIYAT_BOBIN,MATCH($P5,FIYAT_KOD,0)))="",1,0)) -> 0
A6: =ROW()-1 -> 5 | B6: =$E6 -> Трансформатор тока ТТИ-А 125\5А 5ВА кл.т.0,5 IEK | C6: tt | D6: =IF($P6="","",IF(INDEX(FIYAT_ARTIKUL,MATCH($P6,FIYAT_KOD,0))="","",INDEX(FIYAT_ARTIKUL,MATCH($P6,FIYAT_KOD,0)))) -> ст-9951729 | E6: =IF($P6="","",INDEX(FIYAT_ACK,MATCH($P6,FIYAT_KOD,0))) -> Трансформатор тока ТТИ-А 125\5А 5ВА кл.т.0,5 IEK | F6: =IF($P6="","",IF(INDEX(FIYAT_LISTE,MATCH($P6,FIYAT_KOD,0))="","",INDEX(FIYAT_LISTE,MATCH($P6,FIYAT_KOD,0)))) -> 4701 | G6: =IF($P6="","",IF(INDEX(FIYAT_NET,MATCH($P6,FIYAT_KOD,0))="","",INDEX(FIYAT_NET,MATCH($P6,FIYAT_KOD,0)))) -> 4701 | H6: =IF(OR($G6="",$I6="",$M6="KONTROL",$M6="KAPSAM_DISI"),"",$G6*$I6) -> 14103 | I6: =SUMIFS(DEVRE!$T:$T,DEVRE!$A:$A,$Q6,DEVRE!$C:$C,$P6)+SUMIFS(DEVRE!$U:$U,DEVRE!$A:$A,$Q6,DEVRE!$H:$H,$P6) -> 3 | J6: =IF($P6="","",INDEX(FIYAT_BIRIM,MATCH($P6,FIYAT_KOD,0))) -> шт | K6: =IF($P6="","",INDEX(FIYAT_MARKA,MATCH($P6,FIYAT_KOD,0))) -> EKT | L6: =IF($H6="","",$H6) -> 14103 | M6: =IF($P6="","",INDEX(DURUM_LIST,MATCH(MAX(INDEX(DURUM_SEV,MATCH(INDEX(FIYAT_DURUM,MATCH($P6,FIYAT_KOD,0)),DURUM_LIST,0)),IF($S6="",0,INDEX(DURUM_SEV,MATCH($S6,DURUM_LIST,0))),$Z6),DURUM_SEV,0))) -> FIYAT_ESKI | N6: DEVRE: PI1 · şema 3 | O6: =IF($P6="","",INDEX(FIYAT_KAYNAK,MATCH($P6,FIYAT_KOD,0))) -> EKT2506 | P6: EKT-ст-9951729 | Q6: =$Q5 -> P01 | T6: =IF(OR($R6="",$I6=""),"",$I6*INDEX(NORM_DK,MATCH($R6,NORM_AD,0))) | U6: =IF(OR($P6="",$I6=""),"",IF(IF(INDEX(FIYAT_ALAN,MATCH($P6,FIYAT_KOD,0))="","",INDEX(FIYAT_ALAN,MATCH($P6,FIYAT_KOD,0)))<>"",$I6*IF(INDEX(FIYAT_ALAN,MATCH($P6,FIYAT_KOD,0))="","",INDEX(FIYAT_ALAN,MATCH($P6,FIYAT_KOD,0))),IF(IF(INDEX(FIYAT_MODUL,MATCH($P6,FIYAT_KOD,0))="","",INDEX(FIYAT_MODUL,MATCH($P6,FIYAT_KOD,0)))<>"",$I6*IF(INDEX(FIYAT_MODUL,MATCH($P6,FIYAT_KOD,0))="","",INDEX(FIYAT_MODUL,MATCH($P6,FIYAT_KOD,0))),IF(IF(INDEX(FIYAT_GENISLIK,MATCH($P6,FIYAT_KOD,0))="","",INDEX(FIYAT_GENISLIK,MATCH($P6,FIYAT_KOD,0)))<>"",$I6*IF(INDEX(FIYAT_GENISLIK,MATCH($P6,FIYAT_KOD,0))="","",INDEX(FIYAT_GENISLIK,MATCH($P6,FIYAT_KOD,0)))/MODUL_GENISLIK_MM,"")))) | V6: =IF(OR($C6<>"шина",$I6=""),"",$I6*INDEX(FIYAT_KGM,MATCH($P6,FIYAT_KOD,0))) | W6: =IF($H6="","",$H6) -> 14103 | Y6: DEVRE | Z6: =IF($P6="","",MAX(_xlfn.MAXIFS(DEVRE!$AM:$AM,DEVRE!$A:$A,$Q6,DEVRE!$C:$C,$P6),_xlfn.MAXIFS(DEVRE!$AM:$AM,DEVRE!$A:$A,$Q6,DEVRE!$H:$H,$P6))) -> 0 | AA6: =IF(OR($I6="",$Q6="",$P6=""),"",$I6*INDEX(PANO_ADET,MATCH($Q6,PANO_ID,0))) -> 3 | AB6: =IF($P6="",0,IF(AND($U6="",COUNTIF(ALAN_TIP_LIST,$C6)>0),1,0)) -> 1 | AC6: =IF(OR($P6="",$C6<>"kontaktör"),0,IF(IF(INDEX(FIYAT_BOBIN,MATCH($P6,FIYAT_KOD,0))="","",INDEX(FIYAT_BOBIN,MATCH($P6,FIYAT_KOD,0)))="",1,0)) -> 0
A7: =ROW()-1 -> 6 | B7: =$E7 -> Авт. выкл. NXB-125 3P 100A 10кА х-ка C | C7: OTO | D7: =IF($P7="","",IF(INDEX(FIYAT_ARTIKUL,MATCH($P7,FIYAT_KOD,0))="","",INDEX(FIYAT_ARTIKUL,MATCH($P7,FIYAT_KOD,0)))) -> 816141 | E7: =IF($P7="","",INDEX(FIYAT_ACK,MATCH($P7,FIYAT_KOD,0))) -> Авт. выкл. NXB-125 3P 100A 10кА х-ка C | F7: =IF($P7="","",IF(INDEX(FIYAT_LISTE,MATCH($P7,FIYAT_KOD,0))="","",INDEX(FIYAT_LISTE,MATCH($P7,FIYAT_KOD,0)))) -> 11015 | G7: =IF($P7="","",IF(INDEX(FIYAT_NET,MATCH($P7,FIYAT_KOD,0))="","",INDEX(FIYAT_NET,MATCH($P7,FIYAT_KOD,0)))) -> 6609 | H7: =IF(OR($G7="",$I7="",$M7="KONTROL",$M7="KAPSAM_DISI"),"",$G7*$I7) -> 6609 | I7: =SUMIFS(DEVRE!$T:$T,DEVRE!$A:$A,$Q7,DEVRE!$C:$C,$P7)+SUMIFS(DEVRE!$U:$U,DEVRE!$A:$A,$Q7,DEVRE!$H:$H,$P7) -> 1 | J7: =IF($P7="","",INDEX(FIYAT_BIRIM,MATCH($P7,FIYAT_KOD,0))) -> шт | K7: =IF($P7="","",INDEX(FIYAT_MARKA,MATCH($P7,FIYAT_KOD,0))) -> CHINT | L7: =IF($H7="","",$H7) -> 6609 | M7: =IF($P7="","",INDEX(DURUM_LIST,MATCH(MAX(INDEX(DURUM_SEV,MATCH(INDEX(FIYAT_DURUM,MATCH($P7,FIYAT_KOD,0)),DURUM_LIST,0)),IF($S7="",0,INDEX(DURUM_SEV,MATCH($S7,DURUM_LIST,0))),$Z7),DURUM_SEV,0))) -> OK | N7: DEVRE: МС-1 · şema 1 | O7: =IF($P7="","",INDEX(FIYAT_KAYNAK,MATCH($P7,FIYAT_KOD,0))) -> CHINT2608 | P7: CHINT-816141 | Q7: =$Q6 -> P01 | R7: MCB_3P | T7: =IF(OR($R7="",$I7=""),"",$I7*INDEX(NORM_DK,MATCH($R7,NORM_AD,0))) -> 8 | U7: =IF(OR($P7="",$I7=""),"",IF(IF(INDEX(FIYAT_ALAN,MATCH($P7,FIYAT_KOD,0))="","",INDEX(FIYAT_ALAN,MATCH($P7,FIYAT_KOD,0)))<>"",$I7*IF(INDEX(FIYAT_ALAN,MATCH($P7,FIYAT_KOD,0))="","",INDEX(FIYAT_ALAN,MATCH($P7,FIYAT_KOD,0))),IF(IF(INDEX(FIYAT_MODUL,MATCH($P7,FIYAT_KOD,0))="","",INDEX(FIYAT_MODUL,MATCH($P7,FIYAT_KOD,0)))<>"",$I7*IF(INDEX(FIYAT_MODUL,MATCH($P7,FIYAT_KOD,0))="","",INDEX(FIYAT_MODUL,MATCH($P7,FIYAT_KOD,0))),IF(IF(INDEX(FIYAT_GENISLIK,MATCH($P7,FIYAT_KOD,0))="","",INDEX(FIYAT_GENISLIK,MATCH($P7,FIYAT_KOD,0)))<>"",$I7*IF(INDEX(FIYAT_GENISLIK,MATCH($P7,FIYAT_KOD,0))="","",INDEX(FIYAT_GENISLIK,MATCH($P7,FIYAT_KOD,0)))/MODUL_GENISLIK_MM,"")))) -> 3 | V7: =IF(OR($C7<>"шина",$I7=""),"",$I7*INDEX(FIYAT_KGM,MATCH($P7,FIYAT_KOD,0))) | W7: =IF($H7="","",$H7) -> 6609 | Y7: DEVRE | Z7: =IF($P7="","",MAX(_xlfn.MAXIFS(DEVRE!$AM:$AM,DEVRE!$A:$A,$Q7,DEVRE!$C:$C,$P7),_xlfn.MAXIFS(DEVRE!$AM:$AM,DEVRE!$A:$A,$Q7,DEVRE!$H:$H,$P7))) -> 0 | AA7: =IF(OR($I7="",$Q7="",$P7=""),"",$I7*INDEX(PANO_ADET,MATCH($Q7,PANO_ID,0))) -> 1 | AB7: =IF($P7="",0,IF(AND($U7="",COUNTIF(ALAN_TIP_LIST,$C7)>0),1,0)) -> 0 | AC7: =IF(OR($P7="",$C7<>"kontaktör"),0,IF(IF(INDEX(FIYAT_BOBIN,MATCH($P7,FIYAT_KOD,0))="","",INDEX(FIYAT_BOBIN,MATCH($P7,FIYAT_KOD,0)))="",1,0)) -> 0
A8: =ROW()-1 -> 7 | B8: =$E8 -> Механическая блокировка MI-9 для NXC-120-225 | C8: аксессуар | D8: =IF($P8="","",IF(INDEX(FIYAT_ARTIKUL,MATCH($P8,FIYAT_KOD,0))="","",INDEX(FIYAT_ARTIKUL,MATCH($P8,FIYAT_KOD,0)))) -> 263761 | E8: =IF($P8="","",INDEX(FIYAT_ACK,MATCH($P8,FIYAT_KOD,0))) -> Механическая блокировка MI-9 для NXC-120-225 | F8: =IF($P8="","",IF(INDEX(FIYAT_LISTE,MATCH($P8,FIYAT_KOD,0))="","",INDEX(FIYAT_LISTE,MATCH($P8,FIYAT_KOD,0)))) -> 3506 | G8: =IF($P8="","",IF(INDEX(FIYAT_NET,MATCH($P8,FIYAT_KOD,0))="","",INDEX(FIYAT_NET,MATCH($P8,FIYAT_KOD,0)))) -> 2103.6 | H8: =IF(OR($G8="",$I8="",$M8="KONTROL",$M8="KAPSAM_DISI"),"",$G8*$I8) -> 2103.6 | I8: 1 | J8: =IF($P8="","",INDEX(FIYAT_BIRIM,MATCH($P8,FIYAT_KOD,0))) -> шт | K8: =IF($P8="","",INDEX(FIYAT_MARKA,MATCH($P8,FIYAT_KOD,0))) -> CHINT | L8: =IF($H8="","",$H8) -> 2103.6 | M8: =IF($P8="","",INDEX(DURUM_LIST,MATCH(MAX(INDEX(DURUM_SEV,MATCH(INDEX(FIYAT_DURUM,MATCH($P8,FIYAT_KOD,0)),DURUM_LIST,0)),IF($S8="",0,INDEX(DURUM_SEV,MATCH($S8,DURUM_LIST,0))),$Z8),DURUM_SEV,0))) -> VARSAYIM | N8: реверс (ОЛ s.11) → mekanik kilit MI-9 NXC-120..225 | O8: =IF($P8="","",INDEX(FIYAT_KAYNAK,MATCH($P8,FIYAT_KOD,0))) -> CHINT2608 | P8: CHINT-263761 | Q8: =$Q7 -> P01 | S8: VARSAYIM | T8: =IF(OR($R8="",$I8=""),"",$I8*INDEX(NORM_DK,MATCH($R8,NORM_AD,0))) | U8: =IF(OR($P8="",$I8=""),"",IF(IF(INDEX(FIYAT_ALAN,MATCH($P8,FIYAT_KOD,0))="","",INDEX(FIYAT_ALAN,MATCH($P8,FIYAT_KOD,0)))<>"",$I8*IF(INDEX(FIYAT_ALAN,MATCH($P8,FIYAT_KOD,0))="","",INDEX(FIYAT_ALAN,MATCH($P8,FIYAT_KOD,0))),IF(IF(INDEX(FIYAT_MODUL,MATCH($P8,FIYAT_KOD,0))="","",INDEX(FIYAT_MODUL,MATCH($P8,FIYAT_KOD,0)))<>"",$I8*IF(INDEX(FIYAT_MODUL,MATCH($P8,FIYAT_KOD,0))="","",INDEX(FIYAT_MODUL,MATCH($P8,FIYAT_KOD,0))),IF(IF(INDEX(FIYAT_GENISLIK,MATCH($P8,FIYAT_KOD,0))="","",INDEX(FIYAT_GENISLIK,MATCH($P8,FIYAT_KOD,0)))<>"",$I8*IF(INDEX(FIYAT_GENISLIK,MATCH($P8,FIYAT_KOD,0))="","",INDEX(FIYAT_GENISLIK,MATCH($P8,FIYAT_KOD,0)))/MODUL_GENISLIK_MM,"")))) | V8: =IF(OR($C8<>"шина",$I8=""),"",$I8*INDEX(FIYAT_KGM,MATCH($P8,FIYAT_KOD,0))) | W8: =IF($H8="","",$H8) -> 2103.6 | Y8: SEMA_DISI | Z8: =IF($P8="","",MAX(_xlfn.MAXIFS(DEVRE!$AM:$AM,DEVRE!$A:$A,$Q8,DEVRE!$C:$C,$P8),_xlfn.MAXIFS(DEVRE!$AM:$AM,DEVRE!$A:$A,$Q8,DEVRE!$H:$H,$P8))) -> 0 | AA8: =IF(OR($I8="",$Q8="",$P8=""),"",$I8*INDEX(PANO_ADET,MATCH($Q8,PANO_ID,0))) -> 1 | AB8: =IF($P8="",0,IF(AND($U8="",COUNTIF(ALAN_TIP_LIST,$C8)>0),1,0)) -> 0 | AC8: =IF(OR($P8="",$C8<>"kontaktör"),0,IF(IF(INDEX(FIYAT_BOBIN,MATCH($P8,FIYAT_KOD,0))="","",INDEX(FIYAT_BOBIN,MATCH($P8,FIYAT_KOD,0)))="",1,0)) -> 0
A9: =ROW()-1 -> 8 | B9: =$E9 -> Контактор 3P 125A AC-3 230V | C9: kontaktör | D9: =IF($P9="","",IF(INDEX(FIYAT_ARTIKUL,MATCH($P9,FIYAT_KOD,0))="","",INDEX(FIYAT_ARTIKUL,MATCH($P9,FIYAT_KOD,0)))) | E9: =IF($P9="","",INDEX(FIYAT_ACK,MATCH($P9,FIYAT_KOD,0))) -> Контактор 3P 125A AC-3 230V | F9: =IF($P9="","",IF(INDEX(FIYAT_LISTE,MATCH($P9,FIYAT_KOD,0))="","",INDEX(FIYAT_LISTE,MATCH($P9,FIYAT_KOD,0)))) | G9: =IF($P9="","",IF(INDEX(FIYAT_NET,MATCH($P9,FIYAT_KOD,0))="","",INDEX(FIYAT_NET,MATCH($P9,FIYAT_KOD,0)))) | H9: =IF(OR($G9="",$I9="",$M9="KONTROL",$M9="KAPSAM_DISI"),"",$G9*$I9) | I9: 2 | J9: =IF($P9="","",INDEX(FIYAT_BIRIM,MATCH($P9,FIYAT_KOD,0))) -> шт | K9: =IF($P9="","",INDEX(FIYAT_MARKA,MATCH($P9,FIYAT_KOD,0))) -> CHINT | L9: =IF($H9="","",$H9) | M9: =IF($P9="","",INDEX(DURUM_LIST,MATCH(MAX(INDEX(DURUM_SEV,MATCH(INDEX(FIYAT_DURUM,MATCH($P9,FIYAT_KOD,0)),DURUM_LIST,0)),IF($S9="",0,INDEX(DURUM_SEV,MATCH($S9,DURUM_LIST,0))),$Z9),DURUM_SEV,0))) -> FIYAT_YOK | N9: KM1.1, KM1.2 КМИ-49512 125А 230В (ОЛ s.11); CHINT 125A AC-3 yok | O9: =IF($P9="","",INDEX(FIYAT_KAYNAK,MATCH($P9,FIYAT_KOD,0))) -> CHINT2608 | P9: YOK-KONTAKTOR-3P-125-230V | Q9: =$Q8 -> P01 | R9: KONTAKTOR | T9: =IF(OR($R9="",$I9=""),"",$I9*INDEX(NORM_DK,MATCH($R9,NORM_AD,0))) -> 0 | U9: =IF(OR($P9="",$I9=""),"",IF(IF(INDEX(FIYAT_ALAN,MATCH($P9,FIYAT_KOD,0))="","",INDEX(FIYAT_ALAN,MATCH($P9,FIYAT_KOD,0)))<>"",$I9*IF(INDEX(FIYAT_ALAN,MATCH($P9,FIYAT_KOD,0))="","",INDEX(FIYAT_ALAN,MATCH($P9,FIYAT_KOD,0))),IF(IF(INDEX(FIYAT_MODUL,MATCH($P9,FIYAT_KOD,0))="","",INDEX(FIYAT_MODUL,MATCH($P9,FIYAT_KOD,0)))<>"",$I9*IF(INDEX(FIYAT_MODUL,MATCH($P9,FIYAT_KOD,0))="","",INDEX(FIYAT_MODUL,MATCH($P9,FIYAT_KOD,0))),IF(IF(INDEX(FIYAT_GENISLIK,MATCH($P9,FIYAT_KOD,0))="","",INDEX(FIYAT_GENISLIK,MATCH($P9,FIYAT_KOD,0)))<>"",$I9*IF(INDEX(FIYAT_GENISLIK,MATCH($P9,FIYAT_KOD,0))="","",INDEX(FIYAT_GENISLIK,MATCH($P9,FIYAT_KOD,0)))/MODUL_GENISLIK_MM,"")))) | V9: =IF(OR($C9<>"шина",$I9=""),"",$I9*INDEX(FIYAT_KGM,MATCH($P9,FIYAT_KOD,0))) | W9: =IF($H9="","",$H9) | Y9: SEMA_DISI | Z9: =IF($P9="","",MAX(_xlfn.MAXIFS(DEVRE!$AM:$AM,DEVRE!$A:$A,$Q9,DEVRE!$C:$C,$P9),_xlfn.MAXIFS(DEVRE!$AM:$AM,DEVRE!$A:$A,$Q9,DEVRE!$H:$H,$P9))) -> 0 | AA9: =IF(OR($I9="",$Q9="",$P9=""),"",$I9*INDEX(PANO_ADET,MATCH($Q9,PANO_ID,0))) -> 2 | AB9: =IF($P9="",0,IF(AND($U9="",COUNTIF(ALAN_TIP_LIST,$C9)>0),1,0)) -> 1 | AC9: =IF(OR($P9="",$C9<>"kontaktör"),0,IF(IF(INDEX(FIYAT_BOBIN,MATCH($P9,FIYAT_KOD,0))="","",INDEX(FIYAT_BOBIN,MATCH($P9,FIYAT_KOD,0)))="",1,0)) -> 0
A10: =ROW()-1 -> 9 | B10: =$E10 -> Авт. выкл. NXB-63 1P 6A 6кА х-ка C | C10: OTO | D10: =IF($P10="","",IF(INDEX(FIYAT_ARTIKUL,MATCH($P10,FIYAT_KOD,0))="","",INDEX(FIYAT_ARTIKUL,MATCH($P10,FIYAT_KOD,0)))) -> 814012 | E10: =IF($P10="","",INDEX(FIYAT_ACK,MATCH($P10,FIYAT_KOD,0))) -> Авт. выкл. NXB-63 1P 6A 6кА х-ка C | F10: =IF($P10="","",IF(INDEX(FIYAT_LISTE,MATCH($P10,FIYAT_KOD,0))="","",INDEX(FIYAT_LISTE,MATCH($P10,FIYAT_KOD,0)))) -> 1436 | G10: =IF($P10="","",IF(INDEX(FIYAT_NET,MATCH($P10,FIYAT_KOD,0))="","",INDEX(FIYAT_NET,MATCH($P10,FIYAT_KOD,0)))) -> 861.6 | H10: =IF(OR($G10="",$I10="",$M10="KONTROL",$M10="KAPSAM_DISI"),"",$G10*$I10) -> 4308 | I10: =SUMIFS(DEVRE!$T:$T,DEVRE!$A:$A,$Q10,DEVRE!$C:$C,$P10)+SUMIFS(DEVRE!$U:$U,DEVRE!$A:$A,$Q10,DEVRE!$H:$H,$P10) -> 5 | J10: =IF($P10="","",INDEX(FIYAT_BIRIM,MATCH($P10,FIYAT_KOD,0))) -> шт | K10: =IF($P10="","",INDEX(FIYAT_MARKA,MATCH($P10,FIYAT_KOD,0))) -> CHINT | L10: =IF($H10="","",$H10) -> 4308 | M10: =IF($P10="","",INDEX(DURUM_LIST,MATCH(MAX(INDEX(DURUM_SEV,MATCH(INDEX(FIYAT_DURUM,MATCH($P10,FIYAT_KOD,0)),DURUM_LIST,0)),IF($S10="",0,INDEX(DURUM_SEV,MATCH($S10,DURUM_LIST,0))),$Z10),DURUM_SEV,0))) -> OTO | N10: DEVRE: QF3, QF4, QF-OTO1, QF-OTO2, QF-OTO3 · şema 2 · OTO 3 | O10: =IF($P10="","",INDEX(FIYAT_KAYNAK,MATCH($P10,FIYAT_KOD,0))) -> CHINT2608 | P10: CHINT-814012 | Q10: =$Q9 -> P01 | R10: KUMANDA_MCB | T10: =IF(OR($R10="",$I10=""),"",$I10*INDEX(NORM_DK,MATCH($R10,NORM_AD,0))) -> 0 | U10: =IF(OR($P10="",$I10=""),"",IF(IF(INDEX(FIYAT_ALAN,MATCH($P10,FIYAT_KOD,0))="","",INDEX(FIYAT_ALAN,MATCH($P10,FIYAT_KOD,0)))<>"",$I10*IF(INDEX(FIYAT_ALAN,MATCH($P10,FIYAT_KOD,0))="","",INDEX(FIYAT_ALAN,MATCH($P10,FIYAT_KOD,0))),IF(IF(INDEX(FIYAT_MODUL,MATCH($P10,FIYAT_KOD,0))="","",INDEX(FIYAT_MODUL,MATCH($P10,FIYAT_KOD,0)))<>"",$I10*IF(INDEX(FIYAT_MODUL,MATCH($P10,FIYAT_KOD,0))="","",INDEX(FIYAT_MODUL,MATCH($P10,FIYAT_KOD,0))),IF(IF(INDEX(FIYAT_GENISLIK,MATCH($P10,FIYAT_KOD,0))="","",INDEX(FIYAT_GENISLIK,MATCH($P10,FIYAT_KOD,0)))<>"",$I10*IF(INDEX(FIYAT_GENISLIK,MATCH($P10,FIYAT_KOD,0))="","",INDEX(FIYAT_GENISLIK,MATCH($P10,FIYAT_KOD,0)))/MODUL_GENISLIK_MM,"")))) -> 5 | V10: =IF(OR($C10<>"шина",$I10=""),"",$I10*INDEX(FIYAT_KGM,MATCH($P10,FIYAT_KOD,0))) | W10: =IF($H10="","",$H10) -> 4308 | Y10: DEVRE | Z10: =IF($P10="","",MAX(_xlfn.MAXIFS(DEVRE!$AM:$AM,DEVRE!$A:$A,$Q10,DEVRE!$C:$C,$P10),_xlfn.MAXIFS(DEVRE!$AM:$AM,DEVRE!$A:$A,$Q10,DEVRE!$H:$H,$P10))) -> 1 | AA10: =IF(OR($I10="",$Q10="",$P10=""),"",$I10*INDEX(PANO_ADET,MATCH($Q10,PANO_ID,0))) -> 5 | AB10: =IF($P10="",0,IF(AND($U10="",COUNTIF(ALAN_TIP_LIST,$C10)>0),1,0)) -> 0 | AC10: =IF(OR($P10="",$C10<>"kontaktör"),0,IF(IF(INDEX(FIYAT_BOBIN,MATCH($P10,FIYAT_KOD,0))="","",INDEX(FIYAT_BOBIN,MATCH($P10,FIYAT_KOD,0)))="",1,0)) -> 0
A11: =ROW()-1 -> 10 | B11: =$E11 -> Реле контроля фаз NJB1-X AC380V | C11: Röle | D11: =IF($P11="","",IF(INDEX(FIYAT_ARTIKUL,MATCH($P11,FIYAT_KOD,0))="","",INDEX(FIYAT_ARTIKUL,MATCH($P11,FIYAT_KOD,0)))) -> 310008 | E11: =IF($P11="","",INDEX(FIYAT_ACK,MATCH($P11,FIYAT_KOD,0))) -> Реле контроля фаз NJB1-X AC380V | F11: =IF($P11="","",IF(INDEX(FIYAT_LISTE,MATCH($P11,FIYAT_KOD,0))="","",INDEX(FIYAT_LISTE,MATCH($P11,FIYAT_KOD,0)))) -> 16808 | G11: =IF($P11="","",IF(INDEX(FIYAT_NET,MATCH($P11,FIYAT_KOD,0))="","",INDEX(FIYAT_NET,MATCH($P11,FIYAT_KOD,0)))) -> 10084.8 | H11: =IF(OR($G11="",$I11="",$M11="KONTROL",$M11="KAPSAM_DISI"),"",$G11*$I11) -> 20169.6 | I11: 2 | J11: =IF($P11="","",INDEX(FIYAT_BIRIM,MATCH($P11,FIYAT_KOD,0))) -> шт | K11: =IF($P11="","",INDEX(FIYAT_MARKA,MATCH($P11,FIYAT_KOD,0))) -> CHINT | L11: =IF($H11="","",$H11) -> 20169.6 | M11: =IF($P11="","",INDEX(DURUM_LIST,MATCH(MAX(INDEX(DURUM_SEV,MATCH(INDEX(FIYAT_DURUM,MATCH($P11,FIYAT_KOD,0)),DURUM_LIST,0)),IF($S11="",0,INDEX(DURUM_SEV,MATCH($S11,DURUM_LIST,0))),$Z11),DURUM_SEV,0))) -> VARSAYIM | N11: Реле фаз ORF ×2 (ОЛ s.11) → NJB1-X AC380V | O11: =IF($P11="","",INDEX(FIYAT_KAYNAK,MATCH($P11,FIYAT_KOD,0))) -> CHINT2608 | P11: CHINT-310008 | Q11: =$Q10 -> P01 | R11: AVR_KONTROL | S11: VARSAYIM | T11: =IF(OR($R11="",$I11=""),"",$I11*INDEX(NORM_DK,MATCH($R11,NORM_AD,0))) -> 0 | U11: =IF(OR($P11="",$I11=""),"",IF(IF(INDEX(FIYAT_ALAN,MATCH($P11,FIYAT_KOD,0))="","",INDEX(FIYAT_ALAN,MATCH($P11,FIYAT_KOD,0)))<>"",$I11*IF(INDEX(FIYAT_ALAN,MATCH($P11,FIYAT_KOD,0))="","",INDEX(FIYAT_ALAN,MATCH($P11,FIYAT_KOD,0))),IF(IF(INDEX(FIYAT_MODUL,MATCH($P11,FIYAT_KOD,0))="","",INDEX(FIYAT_MODUL,MATCH($P11,FIYAT_KOD,0)))<>"",$I11*IF(INDEX(FIYAT_MODUL,MATCH($P11,FIYAT_KOD,0))="","",INDEX(FIYAT_MODUL,MATCH($P11,FIYAT_KOD,0))),IF(IF(INDEX(FIYAT_GENISLIK,MATCH($P11,FIYAT_KOD,0))="","",INDEX(FIYAT_GENISLIK,MATCH($P11,FIYAT_KOD,0)))<>"",$I11*IF(INDEX(FIYAT_GENISLIK,MATCH($P11,FIYAT_KOD,0))="","",INDEX(FIYAT_GENISLIK,MATCH($P11,FIYAT_KOD,0)))/MODUL_GENISLIK_MM,"")))) | V11: =IF(OR($C11<>"шина",$I11=""),"",$I11*INDEX(FIYAT_KGM,MATCH($P11,FIYAT_KOD,0))) | W11: =IF($H11="","",$H11) -> 20169.6 | Y11: SEMA_DISI | Z11: =IF($P11="","",MAX(_xlfn.MAXIFS(DEVRE!$AM:$AM,DEVRE!$A:$A,$Q11,DEVRE!$C:$C,$P11),_xlfn.MAXIFS(DEVRE!$AM:$AM,DEVRE!$A:$A,$Q11,DEVRE!$H:$H,$P11))) -> 0 | AA11: =IF(OR($I11="",$Q11="",$P11=""),"",$I11*INDEX(PANO_ADET,MATCH($Q11,PANO_ID,0))) -> 2 | AB11: =IF($P11="",0,IF(AND($U11="",COUNTIF(ALAN_TIP_LIST,$C11)>0),1,0)) -> 0 | AC11: =IF(OR($P11="",$C11<>"kontaktör"),0,IF(IF(INDEX(FIYAT_BOBIN,MATCH($P11,FIYAT_KOD,0))="","",INDEX(FIYAT_BOBIN,MATCH($P11,FIYAT_KOD,0)))="",1,0)) -> 0
A12: =ROW()-1 -> 11 | B12: =$E12 -> Светильник ЛПО 2001 8Вт | C12: lamb | D12: =IF($P12="","",IF(INDEX(FIYAT_ARTIKUL,MATCH($P12,FIYAT_KOD,0))="","",INDEX(FIYAT_ARTIKUL,MATCH($P12,FIYAT_KOD,0)))) | E12: =IF($P12="","",INDEX(FIYAT_ACK,MATCH($P12,FIYAT_KOD,0))) -> Светильник ЛПО 2001 8Вт | F12: =IF($P12="","",IF(INDEX(FIYAT_LISTE,MATCH($P12,FIYAT_KOD,0))="","",INDEX(FIYAT_LISTE,MATCH($P12,FIYAT_KOD,0)))) | G12: =IF($P12="","",IF(INDEX(FIYAT_NET,MATCH($P12,FIYAT_KOD,0))="","",INDEX(FIYAT_NET,MATCH($P12,FIYAT_KOD,0)))) | H12: =IF(OR($G12="",$I12="",$M12="KONTROL",$M12="KAPSAM_DISI"),"",$G12*$I12) | I12: 2 | J12: =IF($P12="","",INDEX(FIYAT_BIRIM,MATCH($P12,FIYAT_KOD,0))) -> шт | K12: =IF($P12="","",INDEX(FIYAT_MARKA,MATCH($P12,FIYAT_KOD,0))) -> CHINT | L12: =IF($H12="","",$H12) | M12: =IF($P12="","",INDEX(DURUM_LIST,MATCH(MAX(INDEX(DURUM_SEV,MATCH(INDEX(FIYAT_DURUM,MATCH($P12,FIYAT_KOD,0)),DURUM_LIST,0)),IF($S12="",0,INDEX(DURUM_SEV,MATCH($S12,DURUM_LIST,0))),$Z12),DURUM_SEV,0))) -> FIYAT_YOK | N12: HL1, HL2 ЛПО 2001 8Вт (ОЛ s.11) | O12: =IF($P12="","",INDEX(FIYAT_KAYNAK,MATCH($P12,FIYAT_KOD,0))) -> CHINT2608 | P12: YOK-LAMB-LPO2001-8W | Q12: =$Q11 -> P01 | R12: PRIZ_AYD | T12: =IF(OR($R12="",$I12=""),"",$I12*INDEX(NORM_DK,MATCH($R12,NORM_AD,0))) -> 0 | U12: =IF(OR($P12="",$I12=""),"",IF(IF(INDEX(FIYAT_ALAN,MATCH($P12,FIYAT_KOD,0))="","",INDEX(FIYAT_ALAN,MATCH($P12,FIYAT_KOD,0)))<>"",$I12*IF(INDEX(FIYAT_ALAN,MATCH($P12,FIYAT_KOD,0))="","",INDEX(FIYAT_ALAN,MATCH($P12,FIYAT_KOD,0))),IF(IF(INDEX(FIYAT_MODUL,MATCH($P12,FIYAT_KOD,0))="","",INDEX(FIYAT_MODUL,MATCH($P12,FIYAT_KOD,0)))<>"",$I12*IF(INDEX(FIYAT_MODUL,MATCH($P12,FIYAT_KOD,0))="","",INDEX(FIYAT_MODUL,MATCH($P12,FIYAT_KOD,0))),IF(IF(INDEX(FIYAT_GENISLIK,MATCH($P12,FIYAT_KOD,0))="","",INDEX(FIYAT_GENISLIK,MATCH($P12,FIYAT_KOD,0)))<>"",$I12*IF(INDEX(FIYAT_GENISLIK,MATCH($P12,FIYAT_KOD,0))="","",INDEX(FIYAT_GENISLIK,MATCH($P12,FIYAT_KOD,0)))/MODUL_GENISLIK_MM,"")))) | V12: =IF(OR($C12<>"шина",$I12=""),"",$I12*INDEX(FIYAT_KGM,MATCH($P12,FIYAT_KOD,0))) | W12: =IF($H12="","",$H12) | Y12: SEMA_DISI | Z12: =IF($P12="","",MAX(_xlfn.MAXIFS(DEVRE!$AM:$AM,DEVRE!$A:$A,$Q12,DEVRE!$C:$C,$P12),_xlfn.MAXIFS(DEVRE!$AM:$AM,DEVRE!$A:$A,$Q12,DEVRE!$H:$H,$P12))) -> 0 | AA12: =IF(OR($I12="",$Q12="",$P12=""),"",$I12*INDEX(PANO_ADET,MATCH($Q12,PANO_ID,0))) -> 2 | AB12: =IF($P12="",0,IF(AND($U12="",COUNTIF(ALAN_TIP_LIST,$C12)>0),1,0)) -> 0 | AC12: =IF(OR($P12="",$C12<>"kontaktör"),0,IF(IF(INDEX(FIYAT_BOBIN,MATCH($P12,FIYAT_KOD,0))="","",INDEX(FIYAT_BOBIN,MATCH($P12,FIYAT_KOD,0)))="",1,0)) -> 0
A13: =ROW()-1 -> 12 | B13: =$E13 | C13: аксессуар | D13: =IF($P13="","",IF(INDEX(FIYAT_ARTIKUL,MATCH($P13,FIYAT_KOD,0))="","",INDEX(FIYAT_ARTIKUL,MATCH($P13,FIYAT_KOD,0)))) | E13: =IF($P13="","",INDEX(FIYAT_ACK,MATCH($P13,FIYAT_KOD,0))) | F13: =IF($P13="","",IF(INDEX(FIYAT_LISTE,MATCH($P13,FIYAT_KOD,0))="","",INDEX(FIYAT_LISTE,MATCH($P13,FIYAT_KOD,0)))) | G13: =IF($P13="","",IF(INDEX(FIYAT_NET,MATCH($P13,FIYAT_KOD,0))="","",INDEX(FIYAT_NET,MATCH($P13,FIYAT_KOD,0)))) | H13: =IF(OR($G13="",$I13="",$M13="KONTROL",$M13="KAPSAM_DISI"),"",$G13*$I13) | I13: =IF(INDEX(PANO_GIRIS,MATCH($Q13,PANO_ID,0))="EVET",1,"") -> 1 | J13: =IF($P13="","",INDEX(FIYAT_BIRIM,MATCH($P13,FIYAT_KOD,0))) | K13: =IF($P13="","",INDEX(FIYAT_MARKA,MATCH($P13,FIYAT_KOD,0))) | L13: =IF($H13="","",$H13) | M13: =IF($P13="","",INDEX(DURUM_LIST,MATCH(MAX(INDEX(DURUM_SEV,MATCH(INDEX(FIYAT_DURUM,MATCH($P13,FIYAT_KOD,0)),DURUM_LIST,0)),IF($S13="",0,INDEX(DURUM_SEV,MATCH($S13,DURUM_LIST,0))),$Z13),DURUM_SEV,0))) | N13: ГЗШ · GZS_KOD boş | O13: =IF($P13="","",INDEX(FIYAT_KAYNAK,MATCH($P13,FIYAT_KOD,0))) | P13: =IF(GZS_KOD="","",GZS_KOD) | Q13: =$Q12 -> P01 | S13: OTO | T13: =IF(OR($R13="",$I13=""),"",$I13*INDEX(NORM_DK,MATCH($R13,NORM_AD,0))) | U13: =IF(OR($P13="",$I13=""),"",IF(IF(INDEX(FIYAT_ALAN,MATCH($P13,FIYAT_KOD,0))="","",INDEX(FIYAT_ALAN,MATCH($P13,FIYAT_KOD,0)))<>"",$I13*IF(INDEX(FIYAT_ALAN,MATCH($P13,FIYAT_KOD,0))="","",INDEX(FIYAT_ALAN,MATCH($P13,FIYAT_KOD,0))),IF(IF(INDEX(FIYAT_MODUL,MATCH($P13,FIYAT_KOD,0))="","",INDEX(FIYAT_MODUL,MATCH($P13,FIYAT_KOD,0)))<>"",$I13*IF(INDEX(FIYAT_MODUL,MATCH($P13,FIYAT_KOD,0))="","",INDEX(FIYAT_MODUL,MATCH($P13,FIYAT_KOD,0))),IF(IF(INDEX(FIYAT_GENISLIK,MATCH($P13,FIYAT_KOD,0))="","",INDEX(FIYAT_GENISLIK,MATCH($P13,FIYAT_KOD,0)))<>"",$I13*IF(INDEX(FIYAT_GENISLIK,MATCH($P13,FIYAT_KOD,0))="","",INDEX(FIYAT_GENISLIK,MATCH($P13,FIYAT_KOD,0)))/MODUL_GENISLIK_MM,"")))) | V13: =IF(OR($C13<>"шина",$I13=""),"",$I13*INDEX(FIYAT_KGM,MATCH($P13,FIYAT_KOD,0))) | W13: =IF($H13="","",$H13) | Y13: OTO:GZS | Z13: =IF($P13="","",MAX(_xlfn.MAXIFS(DEVRE!$AM:$AM,DEVRE!$A:$A,$Q13,DEVRE!$C:$C,$P13),_xlfn.MAXIFS(DEVRE!$AM:$AM,DEVRE!$A:$A,$Q13,DEVRE!$H:$H,$P13))) | AA13: =IF(OR($I13="",$Q13="",$P13=""),"",$I13*INDEX(PANO_ADET,MATCH($Q13,PANO_ID,0))) | AB13: =IF($P13="",0,IF(AND($U13="",COUNTIF(ALAN_TIP_LIST,$C13)>0),1,0)) -> 0 | AC13: =IF(OR($P13="",$C13<>"kontaktör"),0,IF(IF(INDEX(FIYAT_BOBIN,MATCH($P13,FIYAT_KOD,0))="","",INDEX(FIYAT_BOBIN,MATCH($P13,FIYAT_KOD,0)))="",1,0)) -> 0
A14: =ROW()-1 -> 13 | B14: =$E14 | C14: аксессуар | D14: =IF($P14="","",IF(INDEX(FIYAT_ARTIKUL,MATCH($P14,FIYAT_KOD,0))="","",INDEX(FIYAT_ARTIKUL,MATCH($P14,FIYAT_KOD,0)))) | E14: =IF($P14="","",INDEX(FIYAT_ACK,MATCH($P14,FIYAT_KOD,0))) | F14: =IF($P14="","",IF(INDEX(FIYAT_LISTE,MATCH($P14,FIYAT_KOD,0))="","",INDEX(FIYAT_LISTE,MATCH($P14,FIYAT_KOD,0)))) | G14: =IF($P14="","",IF(INDEX(FIYAT_NET,MATCH($P14,FIYAT_KOD,0))="","",INDEX(FIYAT_NET,MATCH($P14,FIYAT_KOD,0)))) | H14: =IF(OR($G14="",$I14="",$M14="KONTROL",$M14="KAPSAM_DISI"),"",$G14*$I14) | I14: =IF(INDEX(PANO_PEN,MATCH($Q14,PANO_ID,0))=0,"",1) | J14: =IF($P14="","",INDEX(FIYAT_BIRIM,MATCH($P14,FIYAT_KOD,0))) | K14: =IF($P14="","",INDEX(FIYAT_MARKA,MATCH($P14,FIYAT_KOD,0))) | L14: =IF($H14="","",$H14) | M14: =IF($P14="","",INDEX(DURUM_LIST,MATCH(MAX(INDEX(DURUM_SEV,MATCH(INDEX(FIYAT_DURUM,MATCH($P14,FIYAT_KOD,0)),DURUM_LIST,0)),IF($S14="",0,INDEX(DURUM_SEV,MATCH($S14,DURUM_LIST,0))),$Z14),DURUM_SEV,0))) | N14: PEN köprüsü (TN-C-S ise) | O14: =IF($P14="","",INDEX(FIYAT_KAYNAK,MATCH($P14,FIYAT_KOD,0))) | P14: =IF(PEN_KOPRU_KOD="","",PEN_KOPRU_KOD) | Q14: =$Q13 -> P01 | S14: OTO | T14: =IF(OR($R14="",$I14=""),"",$I14*INDEX(NORM_DK,MATCH($R14,NORM_AD,0))) | U14: =IF(OR($P14="",$I14=""),"",IF(IF(INDEX(FIYAT_ALAN,MATCH($P14,FIYAT_KOD,0))="","",INDEX(FIYAT_ALAN,MATCH($P14,FIYAT_KOD,0)))<>"",$I14*IF(INDEX(FIYAT_ALAN,MATCH($P14,FIYAT_KOD,0))="","",INDEX(FIYAT_ALAN,MATCH($P14,FIYAT_KOD,0))),IF(IF(INDEX(FIYAT_MODUL,MATCH($P14,FIYAT_KOD,0))="","",INDEX(FIYAT_MODUL,MATCH($P14,FIYAT_KOD,0)))<>"",$I14*IF(INDEX(FIYAT_MODUL,MATCH($P14,FIYAT_KOD,0))="","",INDEX(FIYAT_MODUL,MATCH($P14,FIYAT_KOD,0))),IF(IF(INDEX(FIYAT_GENISLIK,MATCH($P14,FIYAT_KOD,0))="","",INDEX(FIYAT_GENISLIK,MATCH($P14,FIYAT_KOD,0)))<>"",$I14*IF(INDEX(FIYAT_GENISLIK,MATCH($P14,FIYAT_KOD,0))="","",INDEX(FIYAT_GENISLIK,MATCH($P14,FIYAT_KOD,0)))/MODUL_GENISLIK_MM,"")))) | V14: =IF(OR($C14<>"шина",$I14=""),"",$I14*INDEX(FIYAT_KGM,MATCH($P14,FIYAT_KOD,0))) | W14: =IF($H14="","",$H14) | Y14: OTO:PEN | Z14: =IF($P14="","",MAX(_xlfn.MAXIFS(DEVRE!$AM:$AM,DEVRE!$A:$A,$Q14,DEVRE!$C:$C,$P14),_xlfn.MAXIFS(DEVRE!$AM:$AM,DEVRE!$A:$A,$Q14,DEVRE!$H:$H,$P14))) | AA14: =IF(OR($I14="",$Q14="",$P14=""),"",$I14*INDEX(PANO_ADET,MATCH($Q14,PANO_ID,0))) | AB14: =IF($P14="",0,IF(AND($U14="",COUNTIF(ALAN_TIP_LIST,$C14)>0),1,0)) -> 0 | AC14: =IF(OR($P14="",$C14<>"kontaktör"),0,IF(IF(INDEX(FIYAT_BOBIN,MATCH($P14,FIYAT_KOD,0))="","",INDEX(FIYAT_BOBIN,MATCH($P14,FIYAT_KOD,0)))="",1,0)) -> 0
A15: =ROW()-1 -> 14 | B15: =$E15 | C15: аксессуар | D15: =IF($P15="","",IF(INDEX(FIYAT_ARTIKUL,MATCH($P15,FIYAT_KOD,0))="","",INDEX(FIYAT_ARTIKUL,MATCH($P15,FIYAT_KOD,0)))) | E15: =IF($P15="","",INDEX(FIYAT_ACK,MATCH($P15,FIYAT_KOD,0))) | F15: =IF($P15="","",IF(INDEX(FIYAT_LISTE,MATCH($P15,FIYAT_KOD,0))="","",INDEX(FIYAT_LISTE,MATCH($P15,FIYAT_KOD,0)))) | G15: =IF($P15="","",IF(INDEX(FIYAT_NET,MATCH($P15,FIYAT_KOD,0))="","",INDEX(FIYAT_NET,MATCH($P15,FIYAT_KOD,0)))) | H15: =IF(OR($G15="",$I15="",$M15="KONTROL",$M15="KAPSAM_DISI"),"",$G15*$I15) | I15: =IF(INDEX(PANO_BARA_GEREK,MATCH($Q15,PANO_ID,0))="HAYIR",2,"") -> 2 | J15: =IF($P15="","",INDEX(FIYAT_BIRIM,MATCH($P15,FIYAT_KOD,0))) | K15: =IF($P15="","",INDEX(FIYAT_MARKA,MATCH($P15,FIYAT_KOD,0))) | L15: =IF($H15="","",$H15) | M15: =IF($P15="","",INDEX(DURUM_LIST,MATCH(MAX(INDEX(DURUM_SEV,MATCH(INDEX(FIYAT_DURUM,MATCH($P15,FIYAT_KOD,0)),DURUM_LIST,0)),IF($S15="",0,INDEX(DURUM_SEV,MATCH($S15,DURUM_LIST,0))),$Z15),DURUM_SEV,0))) | N15: N/PE barası · NOTR_BARA_KOD boş | O15: =IF($P15="","",INDEX(FIYAT_KAYNAK,MATCH($P15,FIYAT_KOD,0))) | P15: =IF(NOTR_BARA_KOD="","",NOTR_BARA_KOD) | Q15: =$Q14 -> P01 | S15: OTO | T15: =IF(OR($R15="",$I15=""),"",$I15*INDEX(NORM_DK,MATCH($R15,NORM_AD,0))) | U15: =IF(OR($P15="",$I15=""),"",IF(IF(INDEX(FIYAT_ALAN,MATCH($P15,FIYAT_KOD,0))="","",INDEX(FIYAT_ALAN,MATCH($P15,FIYAT_KOD,0)))<>"",$I15*IF(INDEX(FIYAT_ALAN,MATCH($P15,FIYAT_KOD,0))="","",INDEX(FIYAT_ALAN,MATCH($P15,FIYAT_KOD,0))),IF(IF(INDEX(FIYAT_MODUL,MATCH($P15,FIYAT_KOD,0))="","",INDEX(FIYAT_MODUL,MATCH($P15,FIYAT_KOD,0)))<>"",$I15*IF(INDEX(FIYAT_MODUL,MATCH($P15,FIYAT_KOD,0))="","",INDEX(FIYAT_MODUL,MATCH($P15,FIYAT_KOD,0))),IF(IF(INDEX(FIYAT_GENISLIK,MATCH($P15,FIYAT_KOD,0))="","",INDEX(FIYAT_GENISLIK,MATCH($P15,FIYAT_KOD,0)))<>"",$I15*IF(INDEX(FIYAT_GENISLIK,MATCH($P15,FIYAT_KOD,0))="","",INDEX(FIYAT_GENISLIK,MATCH($P15,FIYAT_KOD,0)))/MODUL_GENISLIK_MM,"")))) | V15: =IF(OR($C15<>"шина",$I15=""),"",$I15*INDEX(FIYAT_KGM,MATCH($P15,FIYAT_KOD,0))) | W15: =IF($H15="","",$H15) | Y15: OTO:NPE | Z15: =IF($P15="","",MAX(_xlfn.MAXIFS(DEVRE!$AM:$AM,DEVRE!$A:$A,$Q15,DEVRE!$C:$C,$P15),_xlfn.MAXIFS(DEVRE!$AM:$AM,DEVRE!$A:$A,$Q15,DEVRE!$H:$H,$P15))) | AA15: =IF(OR($I15="",$Q15="",$P15=""),"",$I15*INDEX(PANO_ADET,MATCH($Q15,PANO_ID,0))) | AB15: =IF($P15="",0,IF(AND($U15="",COUNTIF(ALAN_TIP_LIST,$C15)>0),1,0)) -> 0 | AC15: =IF(OR($P15="",$C15<>"kontaktör"),0,IF(IF(INDEX(FIYAT_BOBIN,MATCH($P15,FIYAT_KOD,0))="","",INDEX(FIYAT_BOBIN,MATCH($P15,FIYAT_KOD,0)))="",1,0)) -> 0
A16: =ROW()-1 -> 15 | B16: =$E16 | C16: DIN | D16: =IF($P16="","",IF(INDEX(FIYAT_ARTIKUL,MATCH($P16,FIYAT_KOD,0))="","",INDEX(FIYAT_ARTIKUL,MATCH($P16,FIYAT_KOD,0)))) | E16: =IF($P16="","",INDEX(FIYAT_ACK,MATCH($P16,FIYAT_KOD,0))) | F16: =IF($P16="","",IF(INDEX(FIYAT_LISTE,MATCH($P16,FIYAT_KOD,0))="","",INDEX(FIYAT_LISTE,MATCH($P16,FIYAT_KOD,0)))) | G16: =IF($P16="","",IF(INDEX(FIYAT_NET,MATCH($P16,FIYAT_KOD,0))="","",INDEX(FIYAT_NET,MATCH($P16,FIYAT_KOD,0)))) | H16: =IF(OR($G16="",$I16="",$M16="KONTROL",$M16="KAPSAM_DISI"),"",$G16*$I16) | I16: =INDEX(PANO_DIN_M,MATCH($Q16,PANO_ID,0)) | J16: =IF($P16="","",INDEX(FIYAT_BIRIM,MATCH($P16,FIYAT_KOD,0))) | K16: =IF($P16="","",INDEX(FIYAT_MARKA,MATCH($P16,FIYAT_KOD,0))) | L16: =IF($H16="","",$H16) | M16: =IF($P16="","",INDEX(DURUM_LIST,MATCH(MAX(INDEX(DURUM_SEV,MATCH(INDEX(FIYAT_DURUM,MATCH($P16,FIYAT_KOD,0)),DURUM_LIST,0)),IF($S16="",0,INDEX(DURUM_SEV,MATCH($S16,DURUM_LIST,0))),$Z16),DURUM_SEV,0))) | N16: DIN ray · DINRAY_KOD / SIRA_ARALIK_MM / KORPUS_IC_PAY_M boş | O16: =IF($P16="","",INDEX(FIYAT_KAYNAK,MATCH($P16,FIYAT_KOD,0))) | P16: =IF(DINRAY_KOD="","",DINRAY_KOD) | Q16: =$Q15 -> P01 | R16: DINRAY_M | S16: OTO | T16: =IF(OR($R16="",$I16=""),"",$I16*INDEX(NORM_DK,MATCH($R16,NORM_AD,0))) | U16: =IF(OR($P16="",$I16=""),"",IF(IF(INDEX(FIYAT_ALAN,MATCH($P16,FIYAT_KOD,0))="","",INDEX(FIYAT_ALAN,MATCH($P16,FIYAT_KOD,0)))<>"",$I16*IF(INDEX(FIYAT_ALAN,MATCH($P16,FIYAT_KOD,0))="","",INDEX(FIYAT_ALAN,MATCH($P16,FIYAT_KOD,0))),IF(IF(INDEX(FIYAT_MODUL,MATCH($P16,FIYAT_KOD,0))="","",INDEX(FIYAT_MODUL,MATCH($P16,FIYAT_KOD,0)))<>"",$I16*IF(INDEX(FIYAT_MODUL,MATCH($P16,FIYAT_KOD,0))="","",INDEX(FIYAT_MODUL,MATCH($P16,FIYAT_KOD,0))),IF(IF(INDEX(FIYAT_GENISLIK,MATCH($P16,FIYAT_KOD,0))="","",INDEX(FIYAT_GENISLIK,MATCH($P16,FIYAT_KOD,0)))<>"",$I16*IF(INDEX(FIYAT_GENISLIK,MATCH($P16,FIYAT_KOD,0))="","",INDEX(FIYAT_GENISLIK,MATCH($P16,FIYAT_KOD,0)))/MODUL_GENISLIK_MM,"")))) | V16: =IF(OR($C16<>"шина",$I16=""),"",$I16*INDEX(FIYAT_KGM,MATCH($P16,FIYAT_KOD,0))) | W16: =IF($H16="","",$H16) | Y16: OTO:DIN | Z16: =IF($P16="","",MAX(_xlfn.MAXIFS(DEVRE!$AM:$AM,DEVRE!$A:$A,$Q16,DEVRE!$C:$C,$P16),_xlfn.MAXIFS(DEVRE!$AM:$AM,DEVRE!$A:$A,$Q16,DEVRE!$H:$H,$P16))) | AA16: =IF(OR($I16="",$Q16="",$P16=""),"",$I16*INDEX(PANO_ADET,MATCH($Q16,PANO_ID,0))) | AB16: =IF($P16="",0,IF(AND($U16="",COUNTIF(ALAN_TIP_LIST,$C16)>0),1,0)) -> 0 | AC16: =IF(OR($P16="",$C16<>"kontaktör"),0,IF(IF(INDEX(FIYAT_BOBIN,MATCH($P16,FIYAT_KOD,0))="","",INDEX(FIYAT_BOBIN,MATCH($P16,FIYAT_KOD,0)))="",1,0)) -> 0
A17: =ROW()-1 -> 16 | B17: =$E17 | C17: кабель-канал | D17: =IF($P17="","",IF(INDEX(FIYAT_ARTIKUL,MATCH($P17,FIYAT_KOD,0))="","",INDEX(FIYAT_ARTIKUL,MATCH($P17,FIYAT_KOD,0)))) | E17: =IF($P17="","",INDEX(FIYAT_ACK,MATCH($P17,FIYAT_KOD,0))) | F17: =IF($P17="","",IF(INDEX(FIYAT_LISTE,MATCH($P17,FIYAT_KOD,0))="","",INDEX(FIYAT_LISTE,MATCH($P17,FIYAT_KOD,0)))) | G17: =IF($P17="","",IF(INDEX(FIYAT_NET,MATCH($P17,FIYAT_KOD,0))="","",INDEX(FIYAT_NET,MATCH($P17,FIYAT_KOD,0)))) | H17: =IF(OR($G17="",$I17="",$M17="KONTROL",$M17="KAPSAM_DISI"),"",$G17*$I17) | I17: =INDEX(PANO_KANAL_M,MATCH($Q17,PANO_ID,0)) | J17: =IF($P17="","",INDEX(FIYAT_BIRIM,MATCH($P17,FIYAT_KOD,0))) | K17: =IF($P17="","",INDEX(FIYAT_MARKA,MATCH($P17,FIYAT_KOD,0))) | L17: =IF($H17="","",$H17) | M17: =IF($P17="","",INDEX(DURUM_LIST,MATCH(MAX(INDEX(DURUM_SEV,MATCH(INDEX(FIYAT_DURUM,MATCH($P17,FIYAT_KOD,0)),DURUM_LIST,0)),IF($S17="",0,INDEX(DURUM_SEV,MATCH($S17,DURUM_LIST,0))),$Z17),DURUM_SEV,0))) | N17: perforeli lоток EKT 280300704 (kalıcı kural) · MÜHENDİS ONAYI GEREKLİ | O17: =IF($P17="","",INDEX(FIYAT_KAYNAK,MATCH($P17,FIYAT_KOD,0))) | P17: =INDEX(PANO_KANAL_KOD,MATCH($Q17,PANO_ID,0)) | Q17: =$Q16 -> P01 | R17: KANAL_M | S17: MUADIL_ONAY | T17: =IF(OR($R17="",$I17=""),"",$I17*INDEX(NORM_DK,MATCH($R17,NORM_AD,0))) | U17: =IF(OR($P17="",$I17=""),"",IF(IF(INDEX(FIYAT_ALAN,MATCH($P17,FIYAT_KOD,0))="","",INDEX(FIYAT_ALAN,MATCH($P17,FIYAT_KOD,0)))<>"",$I17*IF(INDEX(FIYAT_ALAN,MATCH($P17,FIYAT_KOD,0))="","",INDEX(FIYAT_ALAN,MATCH($P17,FIYAT_KOD,0))),IF(IF(INDEX(FIYAT_MODUL,MATCH($P17,FIYAT_KOD,0))="","",INDEX(FIYAT_MODUL,MATCH($P17,FIYAT_KOD,0)))<>"",$I17*IF(INDEX(FIYAT_MODUL,MATCH($P17,FIYAT_KOD,0))="","",INDEX(FIYAT_MODUL,MATCH($P17,FIYAT_KOD,0))),IF(IF(INDEX(FIYAT_GENISLIK,MATCH($P17,FIYAT_KOD,0))="","",INDEX(FIYAT_GENISLIK,MATCH($P17,FIYAT_KOD,0)))<>"",$I17*IF(INDEX(FIYAT_GENISLIK,MATCH($P17,FIYAT_KOD,0))="","",INDEX(FIYAT_GENISLIK,MATCH($P17,FIYAT_KOD,0)))/MODUL_GENISLIK_MM,"")))) | V17: =IF(OR($C17<>"шина",$I17=""),"",$I17*INDEX(FIYAT_KGM,MATCH($P17,FIYAT_KOD,0))) | W17: =IF($H17="","",$H17) | Y17: OTO:KANAL | Z17: =IF($P17="","",MAX(_xlfn.MAXIFS(DEVRE!$AM:$AM,DEVRE!$A:$A,$Q17,DEVRE!$C:$C,$P17),_xlfn.MAXIFS(DEVRE!$AM:$AM,DEVRE!$A:$A,$Q17,DEVRE!$H:$H,$P17))) | AA17: =IF(OR($I17="",$Q17="",$P17=""),"",$I17*INDEX(PANO_ADET,MATCH($Q17,PANO_ID,0))) | AB17: =IF($P17="",0,IF(AND($U17="",COUNTIF(ALAN_TIP_LIST,$C17)>0),1,0)) -> 0 | AC17: =IF(OR($P17="",$C17<>"kontaktör"),0,IF(IF(INDEX(FIYAT_BOBIN,MATCH($P17,FIYAT_KOD,0))="","",INDEX(FIYAT_BOBIN,MATCH($P17,FIYAT_KOD,0)))="",1,0)) -> 0
A18: =ROW()-1 -> 17 | B18: =$E18 | C18: кабель-канал | D18: =IF($P18="","",IF(INDEX(FIYAT_ARTIKUL,MATCH($P18,FIYAT_KOD,0))="","",INDEX(FIYAT_ARTIKUL,MATCH($P18,FIYAT_KOD,0)))) | E18: =IF($P18="","",INDEX(FIYAT_ACK,MATCH($P18,FIYAT_KOD,0))) | F18: =IF($P18="","",IF(INDEX(FIYAT_LISTE,MATCH($P18,FIYAT_KOD,0))="","",INDEX(FIYAT_LISTE,MATCH($P18,FIYAT_KOD,0)))) | G18: =IF($P18="","",IF(INDEX(FIYAT_NET,MATCH($P18,FIYAT_KOD,0))="","",INDEX(FIYAT_NET,MATCH($P18,FIYAT_KOD,0)))) | H18: =IF(OR($G18="",$I18="",$M18="KONTROL",$M18="KAPSAM_DISI"),"",$G18*$I18) | I18: =INDEX(PANO_KANAL_M,MATCH($Q18,PANO_ID,0)) | J18: =IF($P18="","",INDEX(FIYAT_BIRIM,MATCH($P18,FIYAT_KOD,0))) | K18: =IF($P18="","",INDEX(FIYAT_MARKA,MATCH($P18,FIYAT_KOD,0))) | L18: =IF($H18="","",$H18) | M18: =IF($P18="","",INDEX(DURUM_LIST,MATCH(MAX(INDEX(DURUM_SEV,MATCH(INDEX(FIYAT_DURUM,MATCH($P18,FIYAT_KOD,0)),DURUM_LIST,0)),IF($S18="",0,INDEX(DURUM_SEV,MATCH($S18,DURUM_LIST,0))),$Z18),DURUM_SEV,0))) | N18: lоток kapağı EKT 280300718 · MÜHENDİS ONAYI GEREKLİ | O18: =IF($P18="","",INDEX(FIYAT_KAYNAK,MATCH($P18,FIYAT_KOD,0))) | P18: =INDEX(PANO_KAPAK_KOD,MATCH($Q18,PANO_ID,0)) | Q18: =$Q17 -> P01 | S18: MUADIL_ONAY | T18: =IF(OR($R18="",$I18=""),"",$I18*INDEX(NORM_DK,MATCH($R18,NORM_AD,0))) | U18: =IF(OR($P18="",$I18=""),"",IF(IF(INDEX(FIYAT_ALAN,MATCH($P18,FIYAT_KOD,0))="","",INDEX(FIYAT_ALAN,MATCH($P18,FIYAT_KOD,0)))<>"",$I18*IF(INDEX(FIYAT_ALAN,MATCH($P18,FIYAT_KOD,0))="","",INDEX(FIYAT_ALAN,MATCH($P18,FIYAT_KOD,0))),IF(IF(INDEX(FIYAT_MODUL,MATCH($P18,FIYAT_KOD,0))="","",INDEX(FIYAT_MODUL,MATCH($P18,FIYAT_KOD,0)))<>"",$I18*IF(INDEX(FIYAT_MODUL,MATCH($P18,FIYAT_KOD,0))="","",INDEX(FIYAT_MODUL,MATCH($P18,FIYAT_KOD,0))),IF(IF(INDEX(FIYAT_GENISLIK,MATCH($P18,FIYAT_KOD,0))="","",INDEX(FIYAT_GENISLIK,MATCH($P18,FIYAT_KOD,0)))<>"",$I18*IF(INDEX(FIYAT_GENISLIK,MATCH($P18,FIYAT_KOD,0))="","",INDEX(FIYAT_GENISLIK,MATCH($P18,FIYAT_KOD,0)))/MODUL_GENISLIK_MM,"")))) | V18: =IF(OR($C18<>"шина",$I18=""),"",$I18*INDEX(FIYAT_KGM,MATCH($P18,FIYAT_KOD,0))) | W18: =IF($H18="","",$H18) | Y18: OTO:KANAL | Z18: =IF($P18="","",MAX(_xlfn.MAXIFS(DEVRE!$AM:$AM,DEVRE!$A:$A,$Q18,DEVRE!$C:$C,$P18),_xlfn.MAXIFS(DEVRE!$AM:$AM,DEVRE!$A:$A,$Q18,DEVRE!$H:$H,$P18))) | AA18: =IF(OR($I18="",$Q18="",$P18=""),"",$I18*INDEX(PANO_ADET,MATCH($Q18,PANO_ID,0))) | AB18: =IF($P18="",0,IF(AND($U18="",COUNTIF(ALAN_TIP_LIST,$C18)>0),1,0)) -> 0 | AC18: =IF(OR($P18="",$C18<>"kontaktör"),0,IF(IF(INDEX(FIYAT_BOBIN,MATCH($P18,FIYAT_KOD,0))="","",INDEX(FIYAT_BOBIN,MATCH($P18,FIYAT_KOD,0)))="",1,0)) -> 0
A19: =ROW()-1 -> 18 | B19: =$E19 -> HARMONY ПВ3 1 1,5 | C19: кабель | D19: =IF($P19="","",IF(INDEX(FIYAT_ARTIKUL,MATCH($P19,FIYAT_KOD,0))="","",INDEX(FIYAT_ARTIKUL,MATCH($P19,FIYAT_KOD,0)))) -> 151.01.PV3.01,5 | E19: =IF($P19="","",INDEX(FIYAT_ACK,MATCH($P19,FIYAT_KOD,0))) -> HARMONY ПВ3 1 1,5 | F19: =IF($P19="","",IF(INDEX(FIYAT_LISTE,MATCH($P19,FIYAT_KOD,0))="","",INDEX(FIYAT_LISTE,MATCH($P19,FIYAT_KOD,0)))) -> 105 | G19: =IF($P19="","",IF(INDEX(FIYAT_NET,MATCH($P19,FIYAT_KOD,0))="","",INDEX(FIYAT_NET,MATCH($P19,FIYAT_KOD,0)))) -> 105 | H19: =IF(OR($G19="",$I19="",$M19="KONTROL",$M19="KAPSAM_DISI"),"",$G19*$I19) -> 1449 | I19: =ROUND((SUMIFS(DEVRE!$Z:$Z,DEVRE!$A:$A,$Q19,DEVRE!$V:$V,$X19)+IF($X19=GRUP_BESLEME_KESIT,INDEX(PANO_GRUP_KABLO_M,MATCH($Q19,PANO_ID,0)),0))*KABLO_FIRE,1) -> 13.8 | J19: =IF($P19="","",INDEX(FIYAT_BIRIM,MATCH($P19,FIYAT_KOD,0))) -> м | K19: =IF($P19="","",INDEX(FIYAT_MARKA,MATCH($P19,FIYAT_KOD,0))) -> HARMONY | L19: =IF($H19="","",$H19) -> 1449 | M19: =IF($P19="","",INDEX(DURUM_LIST,MATCH(MAX(INDEX(DURUM_SEV,MATCH(INDEX(FIYAT_DURUM,MATCH($P19,FIYAT_KOD,0)),DURUM_LIST,0)),IF($S19="",0,INDEX(DURUM_SEV,MATCH($S19,DURUM_LIST,0))),$Z19),DURUM_SEV,0))) -> FIYAT_ESKI | N19: ПВ3 1.5 mm² · DEVRE KABLO_M × KABLO_FIRE | O19: =IF($P19="","",INDEX(FIYAT_KAYNAK,MATCH($P19,FIYAT_KOD,0))) -> HARMONY | P19: HARMONY-151.01.PV3.01,5 | Q19: =$Q18 -> P01 | R19: KABLO_IC_M | S19: OTO | T19: =IF(OR($R19="",$I19=""),"",$I19*INDEX(NORM_DK,MATCH($R19,NORM_AD,0))) -> 0 | U19: =IF(OR($P19="",$I19=""),"",IF(IF(INDEX(FIYAT_ALAN,MATCH($P19,FIYAT_KOD,0))="","",INDEX(FIYAT_ALAN,MATCH($P19,FIYAT_KOD,0)))<>"",$I19*IF(INDEX(FIYAT_ALAN,MATCH($P19,FIYAT_KOD,0))="","",INDEX(FIYAT_ALAN,MATCH($P19,FIYAT_KOD,0))),IF(IF(INDEX(FIYAT_MODUL,MATCH($P19,FIYAT_KOD,0))="","",INDEX(FIYAT_MODUL,MATCH($P19,FIYAT_KOD,0)))<>"",$I19*IF(INDEX(FIYAT_MODUL,MATCH($P19,FIYAT_KOD,0))="","",INDEX(FIYAT_MODUL,MATCH($P19,FIYAT_KOD,0))),IF(IF(INDEX(FIYAT_GENISLIK,MATCH($P19,FIYAT_KOD,0))="","",INDEX(FIYAT_GENISLIK,MATCH($P19,FIYAT_KOD,0)))<>"",$I19*IF(INDEX(FIYAT_GENISLIK,MATCH($P19,FIYAT_KOD,0))="","",INDEX(FIYAT_GENISLIK,MATCH($P19,FIYAT_KOD,0)))/MODUL_GENISLIK_MM,"")))) | V19: =IF(OR($C19<>"шина",$I19=""),"",$I19*INDEX(FIYAT_KGM,MATCH($P19,FIYAT_KOD,0))) | W19: =IF($H19="","",$H19) -> 1449 | X19: 1.5 | Y19: OTO:KABLO | Z19: =IF($P19="","",MAX(_xlfn.MAXIFS(DEVRE!$AM:$AM,DEVRE!$A:$A,$Q19,DEVRE!$C:$C,$P19),_xlfn.MAXIFS(DEVRE!$AM:$AM,DEVRE!$A:$A,$Q19,DEVRE!$H:$H,$P19))) -> 0 | AA19: =IF(OR($I19="",$Q19="",$P19=""),"",$I19*INDEX(PANO_ADET,MATCH($Q19,PANO_ID,0))) -> 13.8 | AB19: =IF($P19="",0,IF(AND($U19="",COUNTIF(ALAN_TIP_LIST,$C19)>0),1,0)) -> 0 | AC19: =IF(OR($P19="",$C19<>"kontaktör"),0,IF(IF(INDEX(FIYAT_BOBIN,MATCH($P19,FIYAT_KOD,0))="","",INDEX(FIYAT_BOBIN,MATCH($P19,FIYAT_KOD,0)))="",1,0)) -> 0
A20: =ROW()-1 -> 19 | B20: =$E20 -> HARMONY ПВ3 1 2,5 | C20: кабель | D20: =IF($P20="","",IF(INDEX(FIYAT_ARTIKUL,MATCH($P20,FIYAT_KOD,0))="","",INDEX(FIYAT_ARTIKUL,MATCH($P20,FIYAT_KOD,0)))) -> 151.01.PV3.02,5 | E20: =IF($P20="","",INDEX(FIYAT_ACK,MATCH($P20,FIYAT_KOD,0))) -> HARMONY ПВ3 1 2,5 | F20: =IF($P20="","",IF(INDEX(FIYAT_LISTE,MATCH($P20,FIYAT_KOD,0))="","",INDEX(FIYAT_LISTE,MATCH($P20,FIYAT_KOD,0)))) -> 174 | G20: =IF($P20="","",IF(INDEX(FIYAT_NET,MATCH($P20,FIYAT_KOD,0))="","",INDEX(FIYAT_NET,MATCH($P20,FIYAT_KOD,0)))) -> 174 | H20: =IF(OR($G20="",$I20="",$M20="KONTROL",$M20="KAPSAM_DISI"),"",$G20*$I20) -> 2871 | I20: =ROUND((SUMIFS(DEVRE!$Z:$Z,DEVRE!$A:$A,$Q20,DEVRE!$V:$V,$X20)+IF($X20=GRUP_BESLEME_KESIT,INDEX(PANO_GRUP_KABLO_M,MATCH($Q20,PANO_ID,0)),0))*KABLO_FIRE,1) -> 16.5 | J20: =IF($P20="","",INDEX(FIYAT_BIRIM,MATCH($P20,FIYAT_KOD,0))) -> м | K20: =IF($P20="","",INDEX(FIYAT_MARKA,MATCH($P20,FIYAT_KOD,0))) -> HARMONY | L20: =IF($H20="","",$H20) -> 2871 | M20: =IF($P20="","",INDEX(DURUM_LIST,MATCH(MAX(INDEX(DURUM_SEV,MATCH(INDEX(FIYAT_DURUM,MATCH($P20,FIYAT_KOD,0)),DURUM_LIST,0)),IF($S20="",0,INDEX(DURUM_SEV,MATCH($S20,DURUM_LIST,0))),$Z20),DURUM_SEV,0))) -> FIYAT_ESKI | N20: ПВ3 2.5 mm² · DEVRE KABLO_M × KABLO_FIRE | O20: =IF($P20="","",INDEX(FIYAT_KAYNAK,MATCH($P20,FIYAT_KOD,0))) -> HARMONY | P20: HARMONY-151.01.PV3.02,5 | Q20: =$Q19 -> P01 | R20: KABLO_IC_M | S20: OTO | T20: =IF(OR($R20="",$I20=""),"",$I20*INDEX(NORM_DK,MATCH($R20,NORM_AD,0))) -> 0 | U20: =IF(OR($P20="",$I20=""),"",IF(IF(INDEX(FIYAT_ALAN,MATCH($P20,FIYAT_KOD,0))="","",INDEX(FIYAT_ALAN,MATCH($P20,FIYAT_KOD,0)))<>"",$I20*IF(INDEX(FIYAT_ALAN,MATCH($P20,FIYAT_KOD,0))="","",INDEX(FIYAT_ALAN,MATCH($P20,FIYAT_KOD,0))),IF(IF(INDEX(FIYAT_MODUL,MATCH($P20,FIYAT_KOD,0))="","",INDEX(FIYAT_MODUL,MATCH($P20,FIYAT_KOD,0)))<>"",$I20*IF(INDEX(FIYAT_MODUL,MATCH($P20,FIYAT_KOD,0))="","",INDEX(FIYAT_MODUL,MATCH($P20,FIYAT_KOD,0))),IF(IF(INDEX(FIYAT_GENISLIK,MATCH($P20,FIYAT_KOD,0))="","",INDEX(FIYAT_GENISLIK,MATCH($P20,FIYAT_KOD,0)))<>"",$I20*IF(INDEX(FIYAT_GENISLIK,MATCH($P20,FIYAT_KOD,0))="","",INDEX(FIYAT_GENISLIK,MATCH($P20,FIYAT_KOD,0)))/MODUL_GENISLIK_MM,"")))) | V20: =IF(OR($C20<>"шина",$I20=""),"",$I20*INDEX(FIYAT_KGM,MATCH($P20,FIYAT_KOD,0))) | W20: =IF($H20="","",$H20) -> 2871 | X20: 2.5 | Y20: OTO:KABLO | Z20: =IF($P20="","",MAX(_xlfn.MAXIFS(DEVRE!$AM:$AM,DEVRE!$A:$A,$Q20,DEVRE!$C:$C,$P20),_xlfn.MAXIFS(DEVRE!$AM:$AM,DEVRE!$A:$A,$Q20,DEVRE!$H:$H,$P20))) -> 0 | AA20: =IF(OR($I20="",$Q20="",$P20=""),"",$I20*INDEX(PANO_ADET,MATCH($Q20,PANO_ID,0))) -> 16.5 | AB20: =IF($P20="",0,IF(AND($U20="",COUNTIF(ALAN_TIP_LIST,$C20)>0),1,0)) -> 0 | AC20: =IF(OR($P20="",$C20<>"kontaktör"),0,IF(IF(INDEX(FIYAT_BOBIN,MATCH($P20,FIYAT_KOD,0))="","",INDEX(FIYAT_BOBIN,MATCH($P20,FIYAT_KOD,0)))="",1,0)) -> 0
A21: =ROW()-1 -> 20 | B21: =$E21 -> HARMONY ПВ3 1 25 | C21: кабель | D21: =IF($P21="","",IF(INDEX(FIYAT_ARTIKUL,MATCH($P21,FIYAT_KOD,0))="","",INDEX(FIYAT_ARTIKUL,MATCH($P21,FIYAT_KOD,0)))) -> 151.01.PV3.25 | E21: =IF($P21="","",INDEX(FIYAT_ACK,MATCH($P21,FIYAT_KOD,0))) -> HARMONY ПВ3 1 25 | F21: =IF($P21="","",IF(INDEX(FIYAT_LISTE,MATCH($P21,FIYAT_KOD,0))="","",INDEX(FIYAT_LISTE,MATCH($P21,FIYAT_KOD,0)))) -> 1688 | G21: =IF($P21="","",IF(INDEX(FIYAT_NET,MATCH($P21,FIYAT_KOD,0))="","",INDEX(FIYAT_NET,MATCH($P21,FIYAT_KOD,0)))) -> 1688 | H21: =IF(OR($G21="",$I21="",$M21="KONTROL",$M21="KAPSAM_DISI"),"",$G21*$I21) -> 11140.8 | I21: =ROUND((SUMIFS(DEVRE!$Z:$Z,DEVRE!$A:$A,$Q21,DEVRE!$V:$V,$X21)+IF($X21=GRUP_BESLEME_KESIT,INDEX(PANO_GRUP_KABLO_M,MATCH($Q21,PANO_ID,0)),0))*KABLO_FIRE,1) -> 6.6 | J21: =IF($P21="","",INDEX(FIYAT_BIRIM,MATCH($P21,FIYAT_KOD,0))) -> м | K21: =IF($P21="","",INDEX(FIYAT_MARKA,MATCH($P21,FIYAT_KOD,0))) -> HARMONY | L21: =IF($H21="","",$H21) -> 11140.8 | M21: =IF($P21="","",INDEX(DURUM_LIST,MATCH(MAX(INDEX(DURUM_SEV,MATCH(INDEX(FIYAT_DURUM,MATCH($P21,FIYAT_KOD,0)),DURUM_LIST,0)),IF($S21="",0,INDEX(DURUM_SEV,MATCH($S21,DURUM_LIST,0))),$Z21),DURUM_SEV,0))) -> FIYAT_ESKI | N21: ПВ3 25 mm² · DEVRE KABLO_M × KABLO_FIRE | O21: =IF($P21="","",INDEX(FIYAT_KAYNAK,MATCH($P21,FIYAT_KOD,0))) -> HARMONY | P21: HARMONY-151.01.PV3.25 | Q21: =$Q20 -> P01 | R21: KABLO_IC_M | S21: OTO | T21: =IF(OR($R21="",$I21=""),"",$I21*INDEX(NORM_DK,MATCH($R21,NORM_AD,0))) -> 0 | U21: =IF(OR($P21="",$I21=""),"",IF(IF(INDEX(FIYAT_ALAN,MATCH($P21,FIYAT_KOD,0))="","",INDEX(FIYAT_ALAN,MATCH($P21,FIYAT_KOD,0)))<>"",$I21*IF(INDEX(FIYAT_ALAN,MATCH($P21,FIYAT_KOD,0))="","",INDEX(FIYAT_ALAN,MATCH($P21,FIYAT_KOD,0))),IF(IF(INDEX(FIYAT_MODUL,MATCH($P21,FIYAT_KOD,0))="","",INDEX(FIYAT_MODUL,MATCH($P21,FIYAT_KOD,0)))<>"",$I21*IF(INDEX(FIYAT_MODUL,MATCH($P21,FIYAT_KOD,0))="","",INDEX(FIYAT_MODUL,MATCH($P21,FIYAT_KOD,0))),IF(IF(INDEX(FIYAT_GENISLIK,MATCH($P21,FIYAT_KOD,0))="","",INDEX(FIYAT_GENISLIK,MATCH($P21,FIYAT_KOD,0)))<>"",$I21*IF(INDEX(FIYAT_GENISLIK,MATCH($P21,FIYAT_KOD,0))="","",INDEX(FIYAT_GENISLIK,MATCH($P21,FIYAT_KOD,0)))/MODUL_GENISLIK_MM,"")))) | V21: =IF(OR($C21<>"шина",$I21=""),"",$I21*INDEX(FIYAT_KGM,MATCH($P21,FIYAT_KOD,0))) | W21: =IF($H21="","",$H21) -> 11140.8 | X21: 25 | Y21: OTO:KABLO | Z21: =IF($P21="","",MAX(_xlfn.MAXIFS(DEVRE!$AM:$AM,DEVRE!$A:$A,$Q21,DEVRE!$C:$C,$P21),_xlfn.MAXIFS(DEVRE!$AM:$AM,DEVRE!$A:$A,$Q21,DEVRE!$H:$H,$P21))) -> 0 | AA21: =IF(OR($I21="",$Q21="",$P21=""),"",$I21*INDEX(PANO_ADET,MATCH($Q21,PANO_ID,0))) -> 6.6 | AB21: =IF($P21="",0,IF(AND($U21="",COUNTIF(ALAN_TIP_LIST,$C21)>0),1,0)) -> 0 | AC21: =IF(OR($P21="",$C21<>"kontaktör"),0,IF(IF(INDEX(FIYAT_BOBIN,MATCH($P21,FIYAT_KOD,0))="","",INDEX(FIYAT_BOBIN,MATCH($P21,FIYAT_KOD,0)))="",1,0)) -> 0
A22: =ROW()-1 -> 21 | B22: =$E22 -> HARMONY ПВ3 1 35 | C22: кабель | D22: =IF($P22="","",IF(INDEX(FIYAT_ARTIKUL,MATCH($P22,FIYAT_KOD,0))="","",INDEX(FIYAT_ARTIKUL,MATCH($P22,FIYAT_KOD,0)))) -> 151.01.PV3.35 | E22: =IF($P22="","",INDEX(FIYAT_ACK,MATCH($P22,FIYAT_KOD,0))) -> HARMONY ПВ3 1 35 | F22: =IF($P22="","",IF(INDEX(FIYAT_LISTE,MATCH($P22,FIYAT_KOD,0))="","",INDEX(FIYAT_LISTE,MATCH($P22,FIYAT_KOD,0)))) -> 2399 | G22: =IF($P22="","",IF(INDEX(FIYAT_NET,MATCH($P22,FIYAT_KOD,0))="","",INDEX(FIYAT_NET,MATCH($P22,FIYAT_KOD,0)))) -> 2399 | H22: =IF(OR($G22="",$I22="",$M22="KONTROL",$M22="KAPSAM_DISI"),"",$G22*$I22) -> 12714.7 | I22: =ROUND((SUMIFS(DEVRE!$Z:$Z,DEVRE!$A:$A,$Q22,DEVRE!$V:$V,$X22)+IF($X22=GRUP_BESLEME_KESIT,INDEX(PANO_GRUP_KABLO_M,MATCH($Q22,PANO_ID,0)),0))*KABLO_FIRE,1) -> 5.3 | J22: =IF($P22="","",INDEX(FIYAT_BIRIM,MATCH($P22,FIYAT_KOD,0))) -> м | K22: =IF($P22="","",INDEX(FIYAT_MARKA,MATCH($P22,FIYAT_KOD,0))) -> HARMONY | L22: =IF($H22="","",$H22) -> 12714.7 | M22: =IF($P22="","",INDEX(DURUM_LIST,MATCH(MAX(INDEX(DURUM_SEV,MATCH(INDEX(FIYAT_DURUM,MATCH($P22,FIYAT_KOD,0)),DURUM_LIST,0)),IF($S22="",0,INDEX(DURUM_SEV,MATCH($S22,DURUM_LIST,0))),$Z22),DURUM_SEV,0))) -> FIYAT_ESKI | N22: ПВ3 35 mm² · DEVRE KABLO_M × KABLO_FIRE | O22: =IF($P22="","",INDEX(FIYAT_KAYNAK,MATCH($P22,FIYAT_KOD,0))) -> HARMONY | P22: HARMONY-151.01.PV3.35 | Q22: =$Q21 -> P01 | R22: KABLO_IC_M | S22: OTO | T22: =IF(OR($R22="",$I22=""),"",$I22*INDEX(NORM_DK,MATCH($R22,NORM_AD,0))) -> 0 | U22: =IF(OR($P22="",$I22=""),"",IF(IF(INDEX(FIYAT_ALAN,MATCH($P22,FIYAT_KOD,0))="","",INDEX(FIYAT_ALAN,MATCH($P22,FIYAT_KOD,0)))<>"",$I22*IF(INDEX(FIYAT_ALAN,MATCH($P22,FIYAT_KOD,0))="","",INDEX(FIYAT_ALAN,MATCH($P22,FIYAT_KOD,0))),IF(IF(INDEX(FIYAT_MODUL,MATCH($P22,FIYAT_KOD,0))="","",INDEX(FIYAT_MODUL,MATCH($P22,FIYAT_KOD,0)))<>"",$I22*IF(INDEX(FIYAT_MODUL,MATCH($P22,FIYAT_KOD,0))="","",INDEX(FIYAT_MODUL,MATCH($P22,FIYAT_KOD,0))),IF(IF(INDEX(FIYAT_GENISLIK,MATCH($P22,FIYAT_KOD,0))="","",INDEX(FIYAT_GENISLIK,MATCH($P22,FIYAT_KOD,0)))<>"",$I22*IF(INDEX(FIYAT_GENISLIK,MATCH($P22,FIYAT_KOD,0))="","",INDEX(FIYAT_GENISLIK,MATCH($P22,FIYAT_KOD,0)))/MODUL_GENISLIK_MM,"")))) | V22: =IF(OR($C22<>"шина",$I22=""),"",$I22*INDEX(FIYAT_KGM,MATCH($P22,FIYAT_KOD,0))) | W22: =IF($H22="","",$H22) -> 12714.7 | X22: 35 | Y22: OTO:KABLO | Z22: =IF($P22="","",MAX(_xlfn.MAXIFS(DEVRE!$AM:$AM,DEVRE!$A:$A,$Q22,DEVRE!$C:$C,$P22),_xlfn.MAXIFS(DEVRE!$AM:$AM,DEVRE!$A:$A,$Q22,DEVRE!$H:$H,$P22))) -> 0 | AA22: =IF(OR($I22="",$Q22="",$P22=""),"",$I22*INDEX(PANO_ADET,MATCH($Q22,PANO_ID,0))) -> 5.3 | AB22: =IF($P22="",0,IF(AND($U22="",COUNTIF(ALAN_TIP_LIST,$C22)>0),1,0)) -> 0 | AC22: =IF(OR($P22="",$C22<>"kontaktör"),0,IF(IF(INDEX(FIYAT_BOBIN,MATCH($P22,FIYAT_KOD,0))="","",INDEX(FIYAT_BOBIN,MATCH($P22,FIYAT_KOD,0)))="",1,0)) -> 0
A23: =ROW()-1 -> 22 | B23: =$E23 -> Монтажный материал | C23: монтажный материал | D23: =IF($P23="","",IF(INDEX(FIYAT_ARTIKUL,MATCH($P23,FIYAT_KOD,0))="","",INDEX(FIYAT_ARTIKUL,MATCH($P23,FIYAT_KOD,0)))) -> MONTAJ-MALZ | E23: =IF($P23="","",INDEX(FIYAT_ACK,MATCH($P23,FIYAT_KOD,0))) -> Монтажный материал | F23: =IF($P23="","",IF(INDEX(FIYAT_LISTE,MATCH($P23,FIYAT_KOD,0))="","",INDEX(FIYAT_LISTE,MATCH($P23,FIYAT_KOD,0)))) -> 1 | G23: =IF($P23="","",IF(INDEX(FIYAT_NET,MATCH($P23,FIYAT_KOD,0))="","",INDEX(FIYAT_NET,MATCH($P23,FIYAT_KOD,0)))) -> 1 | H23: =IF(OR($G23="",$I23="",$M23="KONTROL",$M23="KAPSAM_DISI"),"",$G23*$I23) | I23: =IF(MONTAJ_MALZ_ORANI="","",ROUND(SUMIFS($W:$W,$Q:$Q,$Q23)*MONTAJ_MALZ_ORANI,0)) | J23: =IF($P23="","",INDEX(FIYAT_BIRIM,MATCH($P23,FIYAT_KOD,0))) -> тг | K23: =IF($P23="","",INDEX(FIYAT_MARKA,MATCH($P23,FIYAT_KOD,0))) -> HESAP | L23: =IF($H23="","",$H23) | M23: =IF($P23="","",INDEX(DURUM_LIST,MATCH(MAX(INDEX(DURUM_SEV,MATCH(INDEX(FIYAT_DURUM,MATCH($P23,FIYAT_KOD,0)),DURUM_LIST,0)),IF($S23="",0,INDEX(DURUM_SEV,MATCH($S23,DURUM_LIST,0))),$Z23),DURUM_SEV,0))) -> OK | N23: MONTAJ_MALZ_ORANI × malzeme tabanı · oran boş | O23: =IF($P23="","",INDEX(FIYAT_KAYNAK,MATCH($P23,FIYAT_KOD,0))) -> HESAP | P23: MONTAJ-MALZ | Q23: =$Q22 -> P01 | V23: =IF(OR($C23<>"шина",$I23=""),"",$I23*INDEX(FIYAT_KGM,MATCH($P23,FIYAT_KOD,0))) | Y23: HESAP | Z23: =IF($P23="","",MAX(_xlfn.MAXIFS(DEVRE!$AM:$AM,DEVRE!$A:$A,$Q23,DEVRE!$C:$C,$P23),_xlfn.MAXIFS(DEVRE!$AM:$AM,DEVRE!$A:$A,$Q23,DEVRE!$H:$H,$P23))) -> 0 | AA23: =IF(OR($I23="",$Q23="",$P23=""),"",$I23*INDEX(PANO_ADET,MATCH($Q23,PANO_ID,0))) | AB23: =IF($P23="",0,IF(AND($U23="",COUNTIF(ALAN_TIP_LIST,$C23)>0),1,0)) -> 0 | AC23: =IF(OR($P23="",$C23<>"kontaktör"),0,IF(IF(INDEX(FIYAT_BOBIN,MATCH($P23,FIYAT_KOD,0))="","",INDEX(FIYAT_BOBIN,MATCH($P23,FIYAT_KOD,0)))="",1,0)) -> 0
A24: =ROW()-1 -> 23 | B24: =$E24 -> Монтажная работа | C24: монтажная работа | D24: =IF($P24="","",IF(INDEX(FIYAT_ARTIKUL,MATCH($P24,FIYAT_KOD,0))="","",INDEX(FIYAT_ARTIKUL,MATCH($P24,FIYAT_KOD,0)))) -> ISCILIK-MONTAJ | E24: =IF($P24="","",INDEX(FIYAT_ACK,MATCH($P24,FIYAT_KOD,0))) -> Монтажная работа | F24: =IF($I24="","",ROUND($I24/DK_SAAT,2)) -> 5.9 | G24: =IF($P24="","",IF(INDEX(FIYAT_NET,MATCH($P24,FIYAT_KOD,0))="","",INDEX(FIYAT_NET,MATCH($P24,FIYAT_KOD,0)))) -> 100 | H24: =IF(OR($G24="",$I24="",$M24="KONTROL",$M24="KAPSAM_DISI"),"",$G24*$I24) -> 35400 | I24: =ROUND((SUMIFS($T:$T,$Q:$Q,$Q24)+INDEX(NORM_DK,MATCH("PABUC_YUKSUK",NORM_AD,0))*(SUMIFS(DEVRE!$AI:$AI,DEVRE!$A:$A,$Q24)+SUMIFS(DEVRE!$AJ:$AJ,DEVRE!$A:$A,$Q24)))*ISCILIK_CARPANI+INDEX(NORM_DK,MATCH("SABIT_AMBALAJ",NORM_AD,0)),0) -> 354 | J24: =IF($P24="","",INDEX(FIYAT_BIRIM,MATCH($P24,FIYAT_KOD,0))) -> мин | K24: =IF($P24="","",INDEX(FIYAT_MARKA,MATCH($P24,FIYAT_KOD,0))) -> HESAP | L24: =IF($H24="","",$H24) -> 35400 | M24: =IF($P24="","",INDEX(DURUM_LIST,MATCH(MAX(INDEX(DURUM_SEV,MATCH(INDEX(FIYAT_DURUM,MATCH($P24,FIYAT_KOD,0)),DURUM_LIST,0)),IF($S24="",0,INDEX(DURUM_SEV,MATCH($S24,DURUM_LIST,0))),$Z24),DURUM_SEV,0))) -> OK | N24: Σ norm dk × ISCILIK_CARPANI (F = saat) | O24: =IF($P24="","",INDEX(FIYAT_KAYNAK,MATCH($P24,FIYAT_KOD,0))) -> HESAP | P24: ISCILIK-MONTAJ | Q24: =$Q23 -> P01 | V24: =IF(OR($C24<>"шина",$I24=""),"",$I24*INDEX(FIYAT_KGM,MATCH($P24,FIYAT_KOD,0))) | Y24: HESAP | Z24: =IF($P24="","",MAX(_xlfn.MAXIFS(DEVRE!$AM:$AM,DEVRE!$A:$A,$Q24,DEVRE!$C:$C,$P24),_xlfn.MAXIFS(DEVRE!$AM:$AM,DEVRE!$A:$A,$Q24,DEVRE!$H:$H,$P24))) -> 0 | AA24: =IF(OR($I24="",$Q24="",$P24=""),"",$I24*INDEX(PANO_ADET,MATCH($Q24,PANO_ID,0))) -> 354 | AB24: =IF($P24="",0,IF(AND($U24="",COUNTIF(ALAN_TIP_LIST,$C24)>0),1,0)) -> 0 | AC24: =IF(OR($P24="",$C24<>"kontaktör"),0,IF(IF(INDEX(FIYAT_BOBIN,MATCH($P24,FIYAT_KOD,0))="","",INDEX(FIYAT_BOBIN,MATCH($P24,FIYAT_KOD,0)))="",1,0)) -> 0
A25: =ROW()-1 -> 24 | B25: ="Toplam "&$E2 -> Toplam Вводно-распределительное устройство ВРУ-1 (с АВР) | H25: =SUBTOTAL(9,H3:H24) -> 165283.9 | L25: =SUBTOTAL(9,L3:L24) -> 165283.9
A26: =ROW()-1 -> 25 | B26: =$E26 -> Щит распределительный ЩР-1 | E26: =INDEX(PANO_TAMAD,MATCH($Q26,PANO_ID,0)) -> Щит распределительный ЩР-1 | I26: 1 | J26: компл. | Q26: P02
