Workbook

Sheet Kurallar
A1: TAGAM AEROPORT — 001-26-ЭОМ — BOM PARAMETRELERİ (03.08.2026)
A2: Parametre | B2: Değer | C2: Birim | D2: Açıklama / Kaynak
A3: TL/KZT kuru | B3: 10.1 | C3: KZT | D3: 03.08.2026 yaklaşık. Legrand TR fiyat listesi TL bazlıdır.
A4: LEGRAND net katsayısı | B4: 0.5 | C4: - | D4: ⚠ TEYİT EDİLMEDİ. Proje talimatlarında Legrand iskonto oranı tanımlı değil.
A5: CHINT net katsayısı | B5: 0.6 | C5: - | D5: Liste × 0,60 (%40 iskonto) — proje talimatı.
A6: EKT / IEK / UNIT / SAİMAN katsayısı | B6: 1 | C6: - | D6: Liste fiyatı = net.
A7: Montaj malzemesi oranı | B7: 0.03 | C7: - | D7: Pano malzeme ara toplamının %3'ü.
A8: İşçilik birim fiyatı | B8: 100 | C8: KZT/dk | D8: Proje standardı.
A9: İŞÇİLİK NORMLARI (dakika) | D9: Tüm normlar bu sayfadan değiştirilir.
A10: OTO 1P | B10: 10 | C10: dk/adet
A11: OTO 2P | B11: 14 | C11: dk/adet
A12: OTO 3P | B12: 18 | C12: dk/adet
A13: OTO 4P | B13: 22 | C13: dk/adet
A14: DİF 2P | B14: 16 | C14: dk/adet
A15: DİF 4P | B15: 24 | C15: dk/adet
A16: TMŞ ≤250A | B16: 60 | C16: dk/adet
A17: TMŞ 315–630A | B17: 90 | C17: dk/adet
A18: Sayaç + akım trafosu seti | B18: 90 | C18: dk/set
A19: Röle / modüler cihaz | B19: 10 | C19: dk/adet
A20: Klemens | B20: 4 | C20: dk/adet
A21: Bakır bara | B21: 45 | C21: dk/metre
... A26: Korpus hazırlık — küçük | B26: 30 | C26: dk/adet
A27: ЩС üstten kablo girişi dizayn ilavesi | B27: 120 | C27: dk/pano | D27: Klemens üstte / ana şalter altta düzeni — ilave dikey kablolama.
A28: Test / etiketleme / kontrol çarpanı | B28: 1.15 | C28: -
A30: FİYAT LİSTESİ YAŞ DENETİMİ
A31: Marka | B31: Liste tarihi | C31: Yaş (ay) | D31: YAS_DURUM
A32: CHINT | B32: 46231 | C32: =ROUND((DATE(2026,8,3)-B32)/30.44,1) -> 0.2 | D32: =IF(C32<=12,"KULLANILABİLİR",IF(C32<=18,"UYARI - ESKİ","YASAK - FİYATLANDIRMADA KULLANILAMAZ")) -> KULLANILABİLİR
A33: SAİMAN | B33: 46037 | C33: =ROUND((DATE(2026,8,3)-B33)/30.44,1) -> 6.6 | D33: =IF(C33<=12,"KULLANILABİLİR",IF(C33<=18,"UYARI - ESKİ","YASAK - FİYATLANDIRMADA KULLANILAMAZ")) -> KULLANILABİLİR
A34: LEGRAND | B34: 45931 | C34: =ROUND((DATE(2026,8,3)-B34)/30.44,1) -> 10.1 | D34: =IF(C34<=12,"KULLANILABİLİR",IF(C34<=18,"UYARI - ESKİ","YASAK - FİYATLANDIRMADA KULLANILAMAZ")) -> KULLANILABİLİR
A35: ABB | B35: 45962 | C35: =ROUND((DATE(2026,8,3)-B35)/30.44,1) -> 9 | D35: =IF(C35<=12,"KULLANILABİLİR",IF(C35<=18,"UYARI - ESKİ","YASAK - FİYATLANDIRMADA KULLANILAMAZ")) -> KULLANILABİLİR
A36: SCHNEIDER | B36: 45839 | C36: =ROUND((DATE(2026,8,3)-B36)/30.44,1) -> 13.1 | D36: =IF(C36<=12,"KULLANILABİLİR",IF(C36<=18,"UYARI - ESKİ","YASAK - FİYATLANDIRMADA KULLANILAMAZ")) -> UYARI - ESKİ
A37: EKT | B37: 45827 | C37: =ROUND((DATE(2026,8,3)-B37)/30.44,1) -> 13.5 | D37: =IF(C37<=12,"KULLANILABİLİR",IF(C37<=18,"UYARI - ESKİ","YASAK - FİYATLANDIRMADA KULLANILAMAZ")) -> UYARI - ESKİ
A38: CNC | B38: 45692 | C38: =ROUND((DATE(2026,8,3)-B38)/30.44,1) -> 17.9 | D38: =IF(C38<=12,"KULLANILABİLİR",IF(C38<=18,"UYARI - ESKİ","YASAK - FİYATLANDIRMADA KULLANILAMAZ")) -> UYARI - ESKİ
A39: TEKSAN | B39: 45748 | C39: =ROUND((DATE(2026,8,3)-B39)/30.44,1) -> 16.1 | D39: =IF(C39<=12,"KULLANILABİLİR",IF(C39<=18,"UYARI - ESKİ","YASAK - FİYATLANDIRMADA KULLANILAMAZ")) -> UYARI - ESKİ
A40: KLEMSAN | B40: 44866 | C40: =ROUND((DATE(2026,8,3)-B40)/30.44,1) -> 45 | D40: =IF(C40<=12,"KULLANILABİLİR",IF(C40<=18,"UYARI - ESKİ","YASAK - FİYATLANDIRMADA KULLANILAMAZ")) -> YASAK - FİYATLANDIRMADA KULLANILAMAZ
A41: ONKA | B41: 44743 | C41: =ROUND((DATE(2026,8,3)-B41)/30.44,1) -> 49.1 | D41: =IF(C41<=12,"KULLANILABİLİR",IF(C41<=18,"UYARI - ESKİ","YASAK - FİYATLANDIRMADA KULLANILAMAZ")) -> YASAK - FİYATLANDIRMADA KULLANILAMAZ
A42: EKF | B42: 44614 | C42: =ROUND((DATE(2026,8,3)-B42)/30.44,1) -> 53.3 | D42: =IF(C42<=12,"KULLANILABİLİR",IF(C42<=18,"UYARI - ESKİ","YASAK - FİYATLANDIRMADA KULLANILAMAZ")) -> YASAK - FİYATLANDIRMADA KULLANILAMAZ
A44: KURALLAR / UYARILAR / TESPİT EDİLEN HATALAR
A45: 1 | B45: SAYAÇ TİPİ — STAJYER BOM'UNDAKİ HATA DÜZELTİLDİ. Şemada ТА1-ТА3 Т-0,66 400/5 akım trafosu var, yani sayaç TRANSFORMATÖR bağlantılıdır. Stajyer BOM'unda direkt bağlantılı ДАЛА СА4-Э720 (5-60А) seçilmiş — YANLIŞ. Doğrusu 'У' tipi: ДАЛА СА4У-Э720 (5-7,5А). Sayaç modeli ЭнергоСбыт/АЖК ile teyit edilmeli.
A46: 2 | B46: AKIM TRAFOSU — Şemada Т-0,66 400/5. SAİMAN listesinde 400А için ТШП-0,66 kl.0,5 mevcut (art. VI). Ticari ölçüm için kl.0,5 zorunludur. 3 adet (üç fazlı ölçüm).
...

Sheet fiyat calismasi burda
B1: Наименование | C1: malzeme | D1: Артикул | E1: Номенклатура | F1: Цена,тг | H1: СУММ. | I1: Кол- во | J1: Ед.изм | K1: завод изготовитель
B2: =E2 -> ЩУР — Щит учетно-распределительный (л.2), 1800×800×450, напольный | E2: ЩУР — Щит учетно-распределительный (л.2), 1800×800×450, напольный | I2: 1 | J2: комплект | K2: TEKLED
A3: 1 | B3: =$E$2 -> ЩУР — Щит учетно-распределительный (л.2), 1800×800×450, напольный | C3: korpus | D3: щт-0001641 | E3: Корпус ВРУ сборный 1800х800х450 IP31, металл (по чертежу 2000х800х450 — см. Kurallar п.5) | F3: 97028 | G3: =F3*Kurallar!$B$6 -> 97028 | H3: =G3*I3 -> 97028 | I3: 1 | J3: шт | K3: EKT
A4: 2 | B4: =$E$2 -> ЩУР — Щит учетно-распределительный (л.2), 1800×800×450, напольный | C4: TMŞ | D4: 4 220 02 | E4: DPX³ 630 автомат. выключатель 3P, TM, In=400A, Icu=36кА (ввод, QF) | F4: 56900 | G4: =F4*Kurallar!$B$4*Kurallar!$B$3 -> 287345 | H4: =G4*I4 -> 287345 | I4: 1 | J4: шт | K4: LEGRAND
A5: 3 | B5: =$E$2 -> ЩУР — Щит учетно-распределительный (л.2), 1800×800×450, напольный | C5: tt | D5: 4 121 25 | E5: Трансформатор тока однофазный 400/5, 8ВА, кл. 0,5 (ТА1-ТА3) | F5: 2810 | G5: =F5*Kurallar!$B$4*Kurallar!$B$3 -> 14190.5 | H5: =G5*I5 -> 42571.5 | I5: 3 | J5: шт | K5: LEGRAND
A6: 4 | B6: =$E$2 -> ЩУР — Щит учетно-распределительный (л.2), 1800×800×450, напольный | C6: sayac | D6: LQ | E6: Счётчик ДАЛА СА4У-Э720 R TX IP П RS1 Д W, 3х220/380В, 5-7,5А (трансформаторного включения) | F6: 90500 | G6: =F6*Kurallar!$B$6 -> 90500 | H6: =G6*I6 -> 90500 | I6: 1 | J6: шт | K6: SAİMAN
A7: 5 | B7: =$E$2 -> ЩУР — Щит учетно-распределительный (л.2), 1800×800×450, напольный | C7: TMŞ | D7: 4 200 45 | E7: DPX³ 160 автомат. выключатель 3P, TM, In=100A, Icu=25кА (QF1 → ЩС) | F7: 9890 | G7: =F7*Kurallar!$B$4*Kurallar!$B$3 -> 49944.5 | H7: =G7*I7 -> 49944.5 | I7: 1 | J7: шт | K7: LEGRAND
A8: 6 | B8: =$E$2 -> ЩУР — Щит учетно-распределительный (л.2), 1800×800×450, напольный | C8: DİF | D8: 4 111 86 | E8: DX³ дифавтомат 4P, C16, 30мА, тип AC (QF2 / Р22-Б1, водонагреватель) | F8: 14100 | G8: =F8*Kurallar!$B$4*Kurallar!$B$3 -> 71205 | H8: =G8*I8 -> 71205 | I8: 1 | J8: шт | K8: LEGRAND
A9: 7 | B9: =$E$2 -> ЩУР — Щит учетно-распределительный (л.2), 1800×800×450, напольный | C9: DİF | D9: 4 111 88 | E9: DX³ дифавтомат 4P, C25, 30мА, тип AC (QF3 / ТХ1, мойка) | F9: 14100 | G9: =F9*Kurallar!$B$4*Kurallar!$B$3 -> 71205 | H9: =G9*I9 -> 71205 | I9: 1 | J9: шт | K9: LEGRAND
A10: 8 | B10: =$E$2 -> ЩУР — Щит учетно-распределительный (л.2), 1800×800×450, напольный | C10: DİF | D10: 4 111 87 | E10: DX³ дифавтомат 4P, C20, 30мА, тип AC (QF4 / ТХ2, пароварка) | F10: 14100 | G10: =F10*Kurallar!$B$4*Kurallar!$B$3 -> 71205 | H10: =G10*I10 -> 71205 | I10: 1 | J10: шт | K10: LEGRAND
A11: 9 | B11: =$E$2 -> ЩУР — Щит учетно-распределительный (л.2), 1800×800×450, напольный | C11: DİF | D11: 4 111 89 | E11: DX³ дифавтомат 4P, C32, 30мА, тип AC (QF5-QF8 / ТХ3-ТХ6) | F11: 14300 | G11: =F11*Kurallar!$B$4*Kurallar!$B$3 -> 72215 | H11: =G11*I11 -> 288860 | I11: 4 | J11: шт | K11: LEGRAND
A12: 10 | B12: =$E$2 -> ЩУР — Щит учетно-распределительный (л.2), 1800×800×450, напольный | C12: DİF | D12: 4 111 59 | E12: DX³ дифавтомат 2P, C20, 30мА, тип AC (QF9, QF13-QF22) | F12: 7760 | G12: =F12*Kurallar!$B$4*Kurallar!$B$3 -> 39188 | H12: =G12*I12 -> 431068 | I12: 11 | J12: шт | K12: LEGRAND
A13: 11 | B13: =$E$2 -> ЩУР — Щит учетно-распределительный (л.2), 1800×800×450, напольный | C13: OTO | D13: 4 336 91 | E13: XG6 автоматический выключатель 3P, C16, 6кА (QF10-QF12 / К5-К7, кондиционеры) | F13: 1470 | G13: =F13*Kurallar!$B$4*Kurallar!$B$3 -> 7423.5 | H13: =G13*I13 -> 22270.5 | I13: 3 | J13: шт | K13: LEGRAND
A14: 12 | B14: =$E$2 -> ЩУР — Щит учетно-распределительный (л.2), 1800×800×450, напольный | C14: Röle | D14: 296662 | E14: Реле напряжения OUVR-1 63A, 3P+N (для QF10-QF12, взамен РН-47) | F14: 19215 | G14: =F14*Kurallar!$B$5 -> 11529 | H14: =G14*I14 -> 34587 | I14: 3 | J14: шт | K14: CHINT
A15: 13 | B15: =$E$2 -> ЩУР — Щит учетно-распределительный (л.2), 1800×800×450, напольный | C15: Röle | D15: 448784 | E15: Реле напряжения с дисплеем OUVR-3 63A, 1P+N (для QF13, взамен РН-47) | F15: 10236 | G15: =F15*Kurallar!$B$5 -> 6141.6 | H15: =G15*I15 -> 6141.6 | I15: 1 | J15: шт | K15: CHINT
A16: 14 | B16: =$E$2 -> ЩУР — Щит учетно-распределительный (л.2), 1800×800×450, напольный | C16: Klemens | D16: 0 371 60 | E16: Viking³ клемма винтовая 2,5мм², серая (фазные проводники) | F16: 73.5 | G16: =F16*Kurallar!$B$4*Kurallar!$B$3 -> 371.175 | H16: =G16*I16 -> 9650.55 | I16: 26 | J16: шт | K16: LEGRAND
A17: 15 | B17: =$E$2 -> ЩУР — Щит учетно-распределительный (л.2), 1800×800×450, напольный | C17: Klemens | D17: 0 371 00 | E17: Viking³ клемма винтовая 2,5мм², синяя (нейтраль N) | F17: 74.7 | G17: =F17*Kurallar!$B$4*Kurallar!$B$3 -> 377.235 | H17: =G17*I17 -> 6035.76 | I17: 16 | J17: шт | K17: LEGRAND
A18: 16 | B18: =$E$2 -> ЩУР — Щит учетно-распределительный (л.2), 1800×800×450, напольный | C18: Klemens | D18: 0 371 61 | E18: Viking³ клемма винтовая 4мм², серая (ТХ1, кабель 5х4) | F18: 78.4 | G18: =F18*Kurallar!$B$4*Kurallar!$B$3 -> 395.92 | H18: =G18*I18 -> 1187.76 | I18: 3 | J18: шт | K18: LEGRAND
A19: 17 | B19: =$E$2 -> ЩУР — Щит учетно-распределительный (л.2), 1800×800×450, напольный | C19: Klemens | D19: 0 371 01 | E19: Viking³ клемма винтовая 4мм², синяя (N) | F19: 82.1 | G19: =F19*Kurallar!$B$4*Kurallar!$B$3 -> 414.605 | H19: =G19*I19 -> 414.605 | I19: 1 | J19: шт | K19: LEGRAND
A20: 18 | B20: =$E$2 -> ЩУР — Щит учетно-распределительный (л.2), 1800×800×450, напольный | C20: Klemens | D20: 0 371 62 | E20: Viking³ клемма винтовая 6мм², серая (ТХ3-ТХ6, кабель 5х6) | F20: 117 | G20: =F20*Kurallar!$B$4*Kurallar!$B$3 -> 590.85 | H20: =G20*I20 -> 7090.2 | I20: 12 | J20: шт | K20: LEGRAND
A21: 19 | B21: =$E$2 -> ЩУР — Щит учетно-распределительный (л.2), 1800×800×450, напольный | C21: Klemens | D21: 0 371 02 | E21: Viking³ клемма винтовая 6мм², синяя (N) | F21: 117 | G21: =F21*Kurallar!$B$4*Kurallar!$B$3 -> 590.85 | H21: =G21*I21 -> 2363.4 | I21: 4 | J21: шт | K21: LEGRAND
A22: 20 | B22: =$E$2 -> ЩУР — Щит учетно-распределительный (л.2), 1800×800×450, напольный | C22: Klemens | D22: 0 371 70 | E22: Viking³ клемма заземления PE 2,5мм², жёлто-зелёная | F22: 323 | G22: =F22*Kurallar!$B$4*Kurallar!$B$3 -> 1631.15 | H22: =G22*I22 -> 26098.4 | I22: 16 | J22: шт | K22: LEGRAND
A23: 21 | B23: =$E$2 -> ЩУР — Щит учетно-распределительный (л.2), 1800×800×450, напольный | C23: Klemens | D23: 0 371 71 | E23: Viking³ клемма заземления PE 4мм², жёлто-зелёная | F23: 331 | G23: =F23*Kurallar!$B$4*Kurallar!$B$3 -> 1671.55 | H23: =G23*I23 -> 1671.55 | I23: 1 | J23: шт | K23: LEGRAND
A24: 22 | B24: =$E$2 -> ЩУР — Щит учетно-распределительный (л.2), 1800×800×450, напольный | C24: Klemens | D24: 0 371 72 | E24: Viking³ клемма заземления PE 6мм², жёлто-зелёная | F24: 408 | G24: =F24*Kurallar!$B$4*Kurallar!$B$3 -> 2060.4 | H24: =G24*I24 -> 8241.6 | I24: 4 | J24: шт | K24: LEGRAND
A25: 23 | B25: =$E$2 -> ЩУР — Щит учетно-распределительный (л.2), 1800×800×450, напольный | C25: LOOBAR | D25: 0 373 00 | E25: Шина бронзовая распределительная 416 мм (N) | F25: 2780 | G25: =F25*Kurallar!$B$4*Kurallar!$B$3 -> 14039 | H25: =G25*I25 -> 28078 | I25: 2 | J25: шт | K25: LEGRAND
A26: 24 | B26: =$E$2 -> ЩУР — Щит учетно-распределительный (л.2), 1800×800×450, напольный | C26: LOOBAR | D26: 130300323_ | E26: Шина медная 4х40х4000 (L1, L2, L3, N, PE — главные шины) | F26: 11131 | G26: =F26*Kurallar!$B$6 -> 11131 | H26: =G26*I26 -> 22262 | I26: 2 | J26: шт | K26: EKT
A27: 25 | B27: =$E$2 -> ЩУР — Щит учетно-распределительный (л.2), 1800×800×450, напольный | C27: DIN ray | D27: 570003 | E27: DIN-рейка оцинкованная TH35-7.5, 100 см | F27: 869 | G27: =F27*Kurallar!$B$5 -> 521.4 | H27: =G27*I27 -> 2607 | I27: 5 | J27: шт | K27: CHINT
A28: 26 | B28: =$E$2 -> ЩУР — Щит учетно-распределительный (л.2), 1800×800×450, напольный | C28: kablo kanalı | D28: 0 362 07 | E28: Lina 25 кабель-канал перфорированный 40х60 мм | F28: 1040 | G28: =F28*Kurallar!$B$4*Kurallar!$B$3 -> 5252 | H28: =G28*I28 -> 52520 | I28: 10 | J28: м | K28: LEGRAND
A29: 27 | B29: =$E$2 -> ЩУР — Щит учетно-распределительный (л.2), 1800×800×450, напольный | C29: монтажный материал | D29: — | E29: Монтажный материал (наконечники, маркировка, крепёж, кабельные вводы) | F29: =SUM(H3:H28) -> 1732151.9 | G29: =F29*Kurallar!$B$7 -> 51964.558 | H29: =G29*I29 -> 51964.558 | I29: 1 | J29: компл. | K29: —
A30: 28 | B30: =$E$2 -> ЩУР — Щит учетно-распределительный (л.2), 1800×800×450, напольный | C30: монтажная работа | D30: — | E30: Сборка, монтаж, маркировка, испытания (норма-минуты) | F30: =I30/60 -> 27.025 | G30: =Kurallar!$B$8 -> 100 | H30: =G30*I30 -> 162150 | I30: =(Kurallar!$B$24+Kurallar!$B$17+Kurallar!$B$16+Kurallar!$B$18+7*Kurallar!$B$15+11*Kurallar!$B$14+3*Kurallar!$B$12+4*Kurallar!$B$19+83*Kurallar!$B$20+5*Kurallar!$B$21+2*Kurallar!$B$22+15*Kurallar!$B$23)*Kurallar!$B$28 -> 1621.5 | J30: мин | K30: TEKLED
B31: Итого ЩУР | E31: ИТОГО ЩУР | H31: =SUBTOTAL(9,H3:H30) -> 1946266.5
B32: =E32 -> ЩС — Щит силовой (л.3), 1800×800×450, напольный — ввод кабелей СВЕРХУ, клеммы вверху, вводной аппарат внизу | E32: ЩС — Щит силовой (л.3), 1800×800×450, напольный — ввод кабелей СВЕРХУ, клеммы вверху, вводной аппарат внизу | I32: 1 | J32: комплект | K32: TEKLED
A33: 1 | B33: =$E$32 -> ЩС — Щит силовой (л.3), 1800×800×450, напольный — ввод кабелей СВЕРХУ, клеммы вверху, вводной аппарат внизу | C33: korpus | D33: щт-0001641 | E33: Корпус ВРУ сборный 1800х800х450 IP31, металл — верхний кабельный ввод, клеммный ряд вверху, вводной аппарат внизу | F33: 97028 | G33: =F33*Kurallar!$B$6 -> 97028 | H33: =G33*I33 -> 97028 | I33: 1 | J33: шт | K33: EKT
A34: 2 | B34: =$E$32 -> ЩС — Щит силовой (л.3), 1800×800×450, напольный — ввод кабелей СВЕРХУ, клеммы вверху, вводной аппарат внизу | C34: TMŞ | D34: 4 200 45 | E34: DPX³ 160 автомат. выключатель 3P, TM, In=100A, Icu=25кА (ввод, внизу панели) | F34: 9890 | G34: =F34*Kurallar!$B$4*Kurallar!$B$3 -> 49944.5 | H34: =G34*I34 -> 49944.5 | I34: 1 | J34: шт | K34: LEGRAND
A35: 3 | B35: =$E$32 -> ЩС — Щит силовой (л.3), 1800×800×450, напольный — ввод кабелей СВЕРХУ, клеммы вверху, вводной аппарат внизу | C35: OTO | D35: 4 336 38 | E35: XG6 автоматический выключатель 1P, C10, 6кА (QF1-QF20 / ГР.1-ГР.21, освещение) | F35: 350 | G35: =F35*Kurallar!$B$4*Kurallar!$B$3 -> 1767.5 | H35: =G35*I35 -> 35350 | I35: 20 | J35: шт | K35: LEGRAND
A36: 4 | B36: =$E$32 -> ЩС — Щит силовой (л.3), 1800×800×450, напольный — ввод кабелей СВЕРХУ, клеммы вверху, вводной аппарат внизу | C36: DİF | D36: 4 111 59 | E36: DX³ дифавтомат 2P, C20, 30мА, тип AC (QF21, QF23-QF43, QF45-QF47) | F36: 7760 | G36: =F36*Kurallar!$B$4*Kurallar!$B$3 -> 39188 | H36: =G36*I36 -> 979700 | I36: 25 | J36: шт | K36: LEGRAND
A37: 5 | B37: =$E$32 -> ЩС — Щит силовой (л.3), 1800×800×450, напольный — ввод кабелей СВЕРХУ, клеммы вверху, вводной аппарат внизу | C37: DİF | D37: 4 111 60 | E37: DX³ дифавтомат 2P, C25, 30мА, тип AC (QF22 / Р2, QF44 / Р25 — фритюрницы) | F37: 7760 | G37: =F37*Kurallar!$B$4*Kurallar!$B$3 -> 39188 | H37: =G37*I37 -> 78376 | I37: 2 | J37: шт | K37: LEGRAND
A38: 6 | B38: =$E$32 -> ЩС — Щит силовой (л.3), 1800×800×450, напольный — ввод кабелей СВЕРХУ, клеммы вверху, вводной аппарат внизу | C38: Röle | D38: 448784 | E38: Реле напряжения с дисплеем OUVR-3 63A, 1P+N (QF45-QF47 / К1-К3, взамен РН-47) | F38: 10236 | G38: =F38*Kurallar!$B$5 -> 6141.6 | H38: =G38*I38 -> 18424.8 | I38: 3 | J38: шт | K38: CHINT
A39: 7 | B39: =$E$32 -> ЩС — Щит силовой (л.3), 1800×800×450, напольный — ввод кабелей СВЕРХУ, клеммы вверху, вводной аппарат внизу | C39: Klemens | D39: 0 371 60 | E39: Viking³ клемма винтовая 2,5мм², серая (фазные проводники) | F39: 73.5 | G39: =F39*Kurallar!$B$4*Kurallar!$B$3 -> 371.175 | H39: =G39*I39 -> 16702.875 | I39: 45 | J39: шт | K39: LEGRAND
A40: 8 | B40: =$E$32 -> ЩС — Щит силовой (л.3), 1800×800×450, напольный — ввод кабелей СВЕРХУ, клеммы вверху, вводной аппарат внизу | C40: Klemens | D40: 0 371 00 | E40: Viking³ клемма винтовая 2,5мм², синяя (нейтраль N) | F40: 74.7 | G40: =F40*Kurallar!$B$4*Kurallar!$B$3 -> 377.235 | H40: =G40*I40 -> 16975.575 | I40: 45 | J40: шт | K40: LEGRAND
...

Sheet СВОД
A1: № | B1: Обозначение | C1: Наименование щита | D1: Габарит, мм | E1: Кол-во | F1: Ед.изм | G1: Сумма, KZT
A2: 1 | B2: ЩУР | C2: Щит учетно-распределительный (л.2) | D2: 1800×800×450 | E2: 1 | F2: компл. | G2: ='fiyat calismasi burda'!H31 -> 1946266.5
A3: 2 | B3: ЩС | C3: Щит силовой (л.3) — верхний кабельный ввод | D3: 1800×800×450 | E3: 1 | F3: компл. | G3: ='fiyat calismasi burda'!H51 -> 1758193.5
A4: 3 | B4: ЩЛ-1…ЩЛ-5 | C4: Локальные боксы 4 мод. IP65 (спец. л.1) | D4: 128×200×116 | E4: 5 | F4: шт | G4: ='fiyat calismasi burda'!H60 -> 464334.95
C5: ВСЕГО | G5: =SUM(G2:G4) -> 4168794.9
A7: Все параметры, коэффициенты и нормы — на листе Kurallar (жёлтые ячейки).
A8: Разделы KONTROL и KAPSAM DIŞI на листе "fiyat calismasi burda" в итоги НЕ входят.
