Workbook

Sheet BOM
A1: Наименование | B1: malzeme | C1: Артикул | D1: Номенклатура | E1: Цена,тг | F1: Цена,тг | G1: СУММ. | H1: Кол- во | I1: Ед.изм | J1: завод изготовитель | K1: Источник | L1: Примечание (листы DXF) | M1: норма, мин/шт | N1: мин. итого
A2: MKA-MCC-1 (MCC-01-DT1-04 (VIP)) — MCC, 8 моторных фидеров (ABB) | D2: MKA-MCC-1 (MCC-01-DT1-04 (VIP)) — MCC, 8 моторных фидеров (ABB) | H2: 1 | I2: комплект | J2: ABB (комплектующие) | K2: MKA-MCC
A3: MKA-MCC-1 (MCC-01-DT1-04 (VIP)) — MCC, 8 моторных фидеров (ABB) | B3: korpus | C3: 719-15698 | D3: Мет.Корпус (2000X800X400+10 CM База) IP31 | E3: 175000 | F3: =E3*0.6 -> 105000 | G3: =IF(OR(F3="",H3=""),"",H3*F3) -> 105000 | H3: 1 | I3: =IFERROR(INDEX(FIYAT!$K$2:$K$32,MATCH($C3,FIYAT!$C$2:$C$32,0)),"") | J3: teksan f | K3: MKA-MCC | L3: хвост. листы: QF 3x40A 6кА (х-ка C принята) | M3: =IFERROR(INDEX(KURALLAR!$B$13:$B$23,MATCH($B3,KURALLAR!$A$13:$A$23,0)),0) -> 0 | N3: =H3*M3 -> 0
A4: MKA-MCC-1 (MCC-01-DT1-04 (VIP)) — MCC, 8 моторных фидеров (ABB) | B4: mccb | C4: 1SDA068059R1 | D4: =IFERROR(INDEX(FIYAT!$D$2:$D$32,MATCH($C4,FIYAT!$C$2:$C$32,0)),"АРТИКУЛ НЕ В FIYAT") -> Авт. выкл. Tmax XT3N 250, TMD, In=250A, 3P, Icu 36кА | E4: =IFERROR(INDEX(FIYAT!$I$2:$I$32,MATCH($C4,FIYAT!$C$2:$C$32,0)),"") -> 234187.41 | F4: =IFERROR(INDEX(FIYAT!$J$2:$J$32,MATCH($C4,FIYAT!$C$2:$C$32,0)),"") -> 234187.41 | G4: =IF(OR(F4="",H4=""),"",H4*F4) -> 234187.41 | H4: 1 | I4: =IFERROR(INDEX(FIYAT!$K$2:$K$32,MATCH($C4,FIYAT!$C$2:$C$32,0)),"") -> шт | J4: =IFERROR(INDEX(FIYAT!$L$2:$L$32,MATCH($C4,FIYAT!$C$2:$C$32,0)),"") -> abb | K4: MKA-MCC | L4: лист 1 (ввод): QF1 MAIN BREAKER; на схеме «XT1N 250A»; ПОДМЕНА XT1N→XT3N (XT1 макс. 160А) | M4: =IFERROR(INDEX(KURALLAR!$B$13:$B$23,MATCH($B4,KURALLAR!$A$13:$A$23,0)),0) -> 15.3 | N4: =H4*M4 -> 15.3
A5: MKA-MCC-1 (MCC-01-DT1-04 (VIP)) — MCC, 8 моторных фидеров (ABB) | B5: oto | C5: 2CDS211001R0065 | D5: =IFERROR(INDEX(FIYAT!$D$2:$D$32,MATCH($C5,FIYAT!$C$2:$C$32,0)),"АРТИКУЛ НЕ В FIYAT") -> Авт. выкл. SH 201-B 6, 1P, 6А, х-ка B, 6кА | E5: =IFERROR(INDEX(FIYAT!$I$2:$I$32,MATCH($C5,FIYAT!$C$2:$C$32,0)),"") -> 4503.2117 | F5: =IFERROR(INDEX(FIYAT!$J$2:$J$32,MATCH($C5,FIYAT!$C$2:$C$32,0)),"") -> 4503.2117 | G5: =IF(OR(F5="",H5=""),"",H5*F5) -> 49535.329 | H5: 11 | I5: =IFERROR(INDEX(FIYAT!$K$2:$K$32,MATCH($C5,FIYAT!$C$2:$C$32,0)),"") -> шт | J5: =IFERROR(INDEX(FIYAT!$L$2:$L$32,MATCH($C5,FIYAT!$C$2:$C$32,0)),"") -> abb | K5: MKA-MCC | L5: лист 1 (ввод): FH1-FH3, защита ламп фаз; фидеры: 1F1 защита цепи управления | M5: =IFERROR(INDEX(KURALLAR!$B$13:$B$23,MATCH($B5,KURALLAR!$A$13:$A$23,0)),0) -> 4 | N5: =H5*M5 -> 44
A6: MKA-MCC-1 (MCC-01-DT1-04 (VIP)) — MCC, 8 моторных фидеров (ABB) | B6: lamb | C6: 1SFA619403R5231 | D6: =IFERROR(INDEX(FIYAT!$D$2:$D$32,MATCH($C6,FIYAT!$C$2:$C$32,0)),"АРТИКУЛ НЕ В FIYAT") -> Лампа сигнальная LED CL2-523R, 230В AC, красная | E6: =IFERROR(INDEX(FIYAT!$I$2:$I$32,MATCH($C6,FIYAT!$C$2:$C$32,0)),"") -> 4906.1038 | F6: =IFERROR(INDEX(FIYAT!$J$2:$J$32,MATCH($C6,FIYAT!$C$2:$C$32,0)),"") -> 4906.1038 | G6: =IF(OR(F6="",H6=""),"",H6*F6) -> 44154.934 | H6: 9 | I6: =IFERROR(INDEX(FIYAT!$K$2:$K$32,MATCH($C6,FIYAT!$C$2:$C$32,0)),"") -> шт | J6: =IFERROR(INDEX(FIYAT!$L$2:$L$32,MATCH($C6,FIYAT!$C$2:$C$32,0)),"") -> abb | K6: MKA-MCC | L6: лист 1 (ввод): H1 лампа фазы; фидеры: 1H2 FAULT (тип не указан, принят CL2-523R) | M6: =IFERROR(INDEX(KURALLAR!$B$13:$B$23,MATCH($B6,KURALLAR!$A$13:$A$23,0)),0) -> 8 | N6: =H6*M6 -> 72
A7: MKA-MCC-1 (MCC-01-DT1-04 (VIP)) — MCC, 8 моторных фидеров (ABB) | B7: lamb | C7: 1SFA619403R5233 | D7: =IFERROR(INDEX(FIYAT!$D$2:$D$32,MATCH($C7,FIYAT!$C$2:$C$32,0)),"АРТИКУЛ НЕ В FIYAT") -> Лампа сигнальная LED CL2-523Y, 230В AC, жёлтая | E7: =IFERROR(INDEX(FIYAT!$I$2:$I$32,MATCH($C7,FIYAT!$C$2:$C$32,0)),"") -> 4906.1038 | F7: =IFERROR(INDEX(FIYAT!$J$2:$J$32,MATCH($C7,FIYAT!$C$2:$C$32,0)),"") -> 4906.1038 | G7: =IF(OR(F7="",H7=""),"",H7*F7) -> 4906.1038 | H7: 1 | I7: =IFERROR(INDEX(FIYAT!$K$2:$K$32,MATCH($C7,FIYAT!$C$2:$C$32,0)),"") -> шт | J7: =IFERROR(INDEX(FIYAT!$L$2:$L$32,MATCH($C7,FIYAT!$C$2:$C$32,0)),"") -> abb | K7: MKA-MCC | L7: лист 1 (ввод): H2 лампа фазы | M7: =IFERROR(INDEX(KURALLAR!$B$13:$B$23,MATCH($B7,KURALLAR!$A$13:$A$23,0)),0) -> 8 | N7: =H7*M7 -> 8
A8: MKA-MCC-1 (MCC-01-DT1-04 (VIP)) — MCC, 8 моторных фидеров (ABB) | B8: lamb | C8: 1SFA619403R5232 | D8: =IFERROR(INDEX(FIYAT!$D$2:$D$32,MATCH($C8,FIYAT!$C$2:$C$32,0)),"АРТИКУЛ НЕ В FIYAT") -> Лампа сигнальная LED CL2-523G, 230В AC, зелёная | E8: =IFERROR(INDEX(FIYAT!$I$2:$I$32,MATCH($C8,FIYAT!$C$2:$C$32,0)),"") -> 4906.1038 | F8: =IFERROR(INDEX(FIYAT!$J$2:$J$32,MATCH($C8,FIYAT!$C$2:$C$32,0)),"") -> 4906.1038 | G8: =IF(OR(F8="",H8=""),"",H8*F8) -> 44154.934 | H8: 9 | I8: =IFERROR(INDEX(FIYAT!$K$2:$K$32,MATCH($C8,FIYAT!$C$2:$C$32,0)),"") -> шт | J8: =IFERROR(INDEX(FIYAT!$L$2:$L$32,MATCH($C8,FIYAT!$C$2:$C$32,0)),"") -> abb | K8: MKA-MCC | L8: лист 1 (ввод): H3 лампа фазы; фидеры: 1H1 ON (тип не указан, принят CL2-523G) | M8: =IFERROR(INDEX(KURALLAR!$B$13:$B$23,MATCH($B8,KURALLAR!$A$13:$A$23,0)),0) -> 8 | N8: =H8*M8 -> 72
A9: MKA-MCC-1 (MCC-01-DT1-04 (VIP)) — MCC, 8 моторных фидеров (ABB) | B9: rele | C9: 1SVR550824R9100 | D9: =IFERROR(INDEX(FIYAT!$D$2:$D$32,MATCH($C9,FIYAT!$C$2:$C$32,0)),"АРТИКУЛ НЕ В FIYAT") -> Реле контроля фаз CM-PFE, 3x208-440В AC, 1 перекл. контакт | E9: =IFERROR(INDEX(FIYAT!$I$2:$I$32,MATCH($C9,FIYAT!$C$2:$C$32,0)),"") -> 73132.566 | F9: =IFERROR(INDEX(FIYAT!$J$2:$J$32,MATCH($C9,FIYAT!$C$2:$C$32,0)),"") -> 73132.566 | G9: =IF(OR(F9="",H9=""),"",H9*F9) -> 73132.566 | H9: 1 | I9: =IFERROR(INDEX(FIYAT!$K$2:$K$32,MATCH($C9,FIYAT!$C$2:$C$32,0)),"") -> шт | J9: =IFERROR(INDEX(FIYAT!$L$2:$L$32,MATCH($C9,FIYAT!$C$2:$C$32,0)),"") -> abb | K9: MKA-MCC | L9: лист 1 (ввод): -FKR реле контроля фаз | M9: =IFERROR(INDEX(KURALLAR!$B$13:$B$23,MATCH($B9,KURALLAR!$A$13:$A$23,0)),0) -> 21.8 | N9: =H9*M9 -> 21.8
A10: MKA-MCC-1 (MCC-01-DT1-04 (VIP)) — MCC, 8 моторных фидеров (ABB) | B10: bh | C10: 2CSM204753R1801 | D10: =IFERROR(INDEX(FIYAT!$D$2:$D$32,MATCH($C10,FIYAT!$C$2:$C$32,0)),"АРТИКУЛ НЕ В FIYAT") -> Держатель плавких вставок E 93/32, 3P, 10.3x38 | E10: =IFERROR(INDEX(FIYAT!$I$2:$I$32,MATCH($C10,FIYAT!$C$2:$C$32,0)),"") -> 12693.651 | F10: =IFERROR(INDEX(FIYAT!$J$2:$J$32,MATCH($C10,FIYAT!$C$2:$C$32,0)),"") -> 12693.651 | G10: =IF(OR(F10="",H10=""),"",H10*F10) -> 12693.651 | H10: 1 | I10: =IFERROR(INDEX(FIYAT!$K$2:$K$32,MATCH($C10,FIYAT!$C$2:$C$32,0)),"") -> шт | J10: =IFERROR(INDEX(FIYAT!$L$2:$L$32,MATCH($C10,FIYAT!$C$2:$C$32,0)),"") -> abb | K10: MKA-MCC | L10: лист 1 (ввод): -FFKR | M10: =IFERROR(INDEX(KURALLAR!$B$13:$B$23,MATCH($B10,KURALLAR!$A$13:$A$23,0)),0) -> 4 | N10: =H10*M10 -> 4
A11: MKA-MCC-1 (MCC-01-DT1-04 (VIP)) — MCC, 8 моторных фидеров (ABB) | B11: aksesuar | C11: 2CSM256363R1801 | D11: =IFERROR(INDEX(FIYAT!$D$2:$D$32,MATCH($C11,FIYAT!$C$2:$C$32,0)),"АРТИКУЛ НЕ В FIYAT") -> Плавкая вставка E 9F10 GG6, 10.3x38, 6А gG | E11: =IFERROR(INDEX(FIYAT!$I$2:$I$32,MATCH($C11,FIYAT!$C$2:$C$32,0)),"") -> 1943.0619 | F11: =IFERROR(INDEX(FIYAT!$J$2:$J$32,MATCH($C11,FIYAT!$C$2:$C$32,0)),"") -> 1943.0619 | G11: =IF(OR(F11="",H11=""),"",H11*F11) -> 5829.1857 | H11: 3 | I11: =IFERROR(INDEX(FIYAT!$K$2:$K$32,MATCH($C11,FIYAT!$C$2:$C$32,0)),"") -> шт | J11: =IFERROR(INDEX(FIYAT!$L$2:$L$32,MATCH($C11,FIYAT!$C$2:$C$32,0)),"") -> abb | K11: MKA-MCC | L11: лист 1 (ввод): -FFKR, по 1 на полюс (принято) | M11: =IFERROR(INDEX(KURALLAR!$B$13:$B$23,MATCH($B11,KURALLAR!$A$13:$A$23,0)),0) -> 0 | N11: =H11*M11 -> 0
A12: MKA-MCC-1 (MCC-01-DT1-04 (VIP)) — MCC, 8 моторных фидеров (ABB) | B12: rele | C12: 1SVR405613R3000 | D12: =IFERROR(INDEX(FIYAT!$D$2:$D$32,MATCH($C12,FIYAT!$C$2:$C$32,0)),"АРТИКУЛ НЕ В FIYAT") -> Реле CR-M230AC4, 4 перекл., катушка 230В AC | E12: =IFERROR(INDEX(FIYAT!$I$2:$I$32,MATCH($C12,FIYAT!$C$2:$C$32,0)),"") -> 6543.1717 | F12: =IFERROR(INDEX(FIYAT!$J$2:$J$32,MATCH($C12,FIYAT!$C$2:$C$32,0)),"") -> 6543.1717 | G12: =IF(OR(F12="",H12=""),"",H12*F12) -> 111233.92 | H12: 17 | I12: =IFERROR(INDEX(FIYAT!$K$2:$K$32,MATCH($C12,FIYAT!$C$2:$C$32,0)),"") -> шт | J12: =IFERROR(INDEX(FIYAT!$L$2:$L$32,MATCH($C12,FIYAT!$C$2:$C$32,0)),"") -> abb | K12: MKA-MCC | L12: лист 1 (ввод): -R0 выходное реле реле фаз; фидеры: 1R1 (ARIZA) + реле LAMP TEST на листе 2 | M12: =IFERROR(INDEX(KURALLAR!$B$13:$B$23,MATCH($B12,KURALLAR!$A$13:$A$23,0)),0) -> 21.8 | N12: =H12*M12 -> 370.6
A13: MKA-MCC-1 (MCC-01-DT1-04 (VIP)) — MCC, 8 моторных фидеров (ABB) | B13: kolodka | C13: 1SVR405651R3000 | D13: CR-M4SS колодка для реле | E13: 4334.915 | F13: 4334.915 | G13: =IF(OR(F13="",H13=""),"",H13*F13) -> 73693.555 | H13: 17 | I13: шт | J13: abb | K13: MKA-MCC | L13: лист 1 (ввод): -R0 выходное реле реле фаз; фидеры: 1R1 (ARIZA) + реле LAMP TEST на листе 2 | M13: =IFERROR(INDEX(KURALLAR!$B$13:$B$23,MATCH($B13,KURALLAR!$A$13:$A$23,0)),0) -> 0 | N13: =H13*M13 -> 0
A14: MKA-MCC-1 (MCC-01-DT1-04 (VIP)) — MCC, 8 моторных фидеров (ABB) | B14: oto | C14: 2CDS252001R0104 | D14: =IFERROR(INDEX(FIYAT!$D$2:$D$32,MATCH($C14,FIYAT!$C$2:$C$32,0)),"АРТИКУЛ НЕ В FIYAT") -> Авт. выкл. S 202-C 10, 2P, 10А, х-ка C | E14: =IFERROR(INDEX(FIYAT!$I$2:$I$32,MATCH($C14,FIYAT!$C$2:$C$32,0)),"") -> 19241.923 | F14: =IFERROR(INDEX(FIYAT!$J$2:$J$32,MATCH($C14,FIYAT!$C$2:$C$32,0)),"") -> 19241.923 | G14: =IF(OR(F14="",H14=""),"",H14*F14) -> 38483.845 | H14: 2 | I14: =IFERROR(INDEX(FIYAT!$K$2:$K$32,MATCH($C14,FIYAT!$C$2:$C$32,0)),"") -> шт | J14: =IFERROR(INDEX(FIYAT!$L$2:$L$32,MATCH($C14,FIYAT!$C$2:$C$32,0)),"") -> abb | K14: MKA-MCC | L14: лист 2: -FT1, -FT2 (питание T1/T2) | M14: =IFERROR(INDEX(KURALLAR!$B$13:$B$23,MATCH($B14,KURALLAR!$A$13:$A$23,0)),0) -> 4 | N14: =H14*M14 -> 8
A15: MKA-MCC-1 (MCC-01-DT1-04 (VIP)) — MCC, 8 моторных фидеров (ABB) | B15: button | C15: 1SFA619100R1016 | D15: =IFERROR(INDEX(FIYAT!$D$2:$D$32,MATCH($C15,FIYAT!$C$2:$C$32,0)),"АРТИКУЛ НЕ В FIYAT") -> Кнопка CP1-10B-10, чёрная, 1НО, без фиксации | E15: =IFERROR(INDEX(FIYAT!$I$2:$I$32,MATCH($C15,FIYAT!$C$2:$C$32,0)),"") -> 3187.4375 | F15: =IFERROR(INDEX(FIYAT!$J$2:$J$32,MATCH($C15,FIYAT!$C$2:$C$32,0)),"") -> 3187.4375 | G15: =IF(OR(F15="",H15=""),"",H15*F15) -> 3187.4375 | H15: 1 | I15: =IFERROR(INDEX(FIYAT!$K$2:$K$32,MATCH($C15,FIYAT!$C$2:$C$32,0)),"") -> шт | J15: =IFERROR(INDEX(FIYAT!$L$2:$L$32,MATCH($C15,FIYAT!$C$2:$C$32,0)),"") -> abb | K15: MKA-MCC | L15: лист 2: LAMP TEST | M15: =IFERROR(INDEX(KURALLAR!$B$13:$B$23,MATCH($B15,KURALLAR!$A$13:$A$23,0)),0) -> 8 | N15: =H15*M15 -> 8
A16: MKA-MCC-1 (MCC-01-DT1-04 (VIP)) — MCC, 8 моторных фидеров (ABB) | B16: motor | C16: 1SAM250000R1007 | D16: =IFERROR(INDEX(FIYAT!$D$2:$D$32,MATCH($C16,FIYAT!$C$2:$C$32,0)),"АРТИКУЛ НЕ В FIYAT") -> Автомат защиты двигателя MS116-2.5 (1.6-2.5А) | E16: =IFERROR(INDEX(FIYAT!$I$2:$I$32,MATCH($C16,FIYAT!$C$2:$C$32,0)),"") -> 31889.675 | F16: =IFERROR(INDEX(FIYAT!$J$2:$J$32,MATCH($C16,FIYAT!$C$2:$C$32,0)),"") -> 31889.675 | G16: =IF(OR(F16="",H16=""),"",H16*F16) -> 191338.05 | H16: 6 | I16: =IFERROR(INDEX(FIYAT!$K$2:$K$32,MATCH($C16,FIYAT!$C$2:$C$32,0)),"") -> шт | J16: =IFERROR(INDEX(FIYAT!$L$2:$L$32,MATCH($C16,FIYAT!$C$2:$C$32,0)),"") -> abb | K16: MKA-MCC | L16: фидеры: MS116-2.5 (поз. Q1) | M16: =IFERROR(INDEX(KURALLAR!$B$13:$B$23,MATCH($B16,KURALLAR!$A$13:$A$23,0)),0) -> 2 | N16: =H16*M16 -> 12
A17: MKA-MCC-1 (MCC-01-DT1-04 (VIP)) — MCC, 8 моторных фидеров (ABB) | B17: motor | C17: 1SAM250000R1009 | D17: =IFERROR(INDEX(FIYAT!$D$2:$D$32,MATCH($C17,FIYAT!$C$2:$C$32,0)),"АРТИКУЛ НЕ В FIYAT") -> Автомат защиты двигателя MS116-6.3 (4-6.3А) | E17: =IFERROR(INDEX(FIYAT!$I$2:$I$32,MATCH($C17,FIYAT!$C$2:$C$32,0)),"") -> 31889.675 | F17: =IFERROR(INDEX(FIYAT!$J$2:$J$32,MATCH($C17,FIYAT!$C$2:$C$32,0)),"") -> 31889.675 | G17: =IF(OR(F17="",H17=""),"",H17*F17) -> 63779.349 | H17: 2 | I17: =IFERROR(INDEX(FIYAT!$K$2:$K$32,MATCH($C17,FIYAT!$C$2:$C$32,0)),"") -> шт | J17: =IFERROR(INDEX(FIYAT!$L$2:$L$32,MATCH($C17,FIYAT!$C$2:$C$32,0)),"") -> abb | K17: MKA-MCC | L17: фидеры: MS116-6.3 (поз. Q1) | M17: =IFERROR(INDEX(KURALLAR!$B$13:$B$23,MATCH($B17,KURALLAR!$A$13:$A$23,0)),0) -> 2 | N17: =H17*M17 -> 4
A18: MKA-MCC-1 (MCC-01-DT1-04 (VIP)) — MCC, 8 моторных фидеров (ABB) | B18: contactor | C18: 1SBL137001R1310 | D18: =IFERROR(INDEX(FIYAT!$D$2:$D$32,MATCH($C18,FIYAT!$C$2:$C$32,0)),"АРТИКУЛ НЕ В FIYAT") -> Контактор AF09-30-10, 3P, 9А AC3, 1НО, катушка 100-250В AC/DC | E18: =IFERROR(INDEX(FIYAT!$I$2:$I$32,MATCH($C18,FIYAT!$C$2:$C$32,0)),"") -> 19333.721 | F18: =IFERROR(INDEX(FIYAT!$J$2:$J$32,MATCH($C18,FIYAT!$C$2:$C$32,0)),"") -> 19333.721 | G18: =IF(OR(F18="",H18=""),"",H18*F18) -> 154669.77 | H18: 8 | I18: =IFERROR(INDEX(FIYAT!$K$2:$K$32,MATCH($C18,FIYAT!$C$2:$C$32,0)),"") -> шт | J18: =IFERROR(INDEX(FIYAT!$L$2:$L$32,MATCH($C18,FIYAT!$C$2:$C$32,0)),"") -> abb | K18: MKA-MCC | L18: фидеры: AF09-30-10 (поз. K1) | M18: =IFERROR(INDEX(KURALLAR!$B$13:$B$23,MATCH($B18,KURALLAR!$A$13:$A$23,0)),0) -> 5.9 | N18: =H18*M18 -> 47.2
A19: MKA-MCC-1 (MCC-01-DT1-04 (VIP)) — MCC, 8 моторных фидеров (ABB) | B19: kontak | C19: 1SBN010120R1011 | D19: =IFERROR(INDEX(FIYAT!$D$2:$D$32,MATCH($C19,FIYAT!$C$2:$C$32,0)),"АРТИКУЛ НЕ В FIYAT") -> Блок доп. контактов боковой CAL4-11 (1НО+1НЗ) для AF09...AF96 | E19: =IFERROR(INDEX(FIYAT!$I$2:$I$32,MATCH($C19,FIYAT!$C$2:$C$32,0)),"") -> 6201.4784 | F19: =IFERROR(INDEX(FIYAT!$J$2:$J$32,MATCH($C19,FIYAT!$C$2:$C$32,0)),"") -> 6201.4784 | G19: =IF(OR(F19="",H19=""),"",H19*F19) -> 49611.827 | H19: 8 | I19: =IFERROR(INDEX(FIYAT!$K$2:$K$32,MATCH($C19,FIYAT!$C$2:$C$32,0)),"") -> шт | J19: =IFERROR(INDEX(FIYAT!$L$2:$L$32,MATCH($C19,FIYAT!$C$2:$C$32,0)),"") -> abb | K19: MKA-MCC | L19: фидеры: 1 на контактор | M19: =IFERROR(INDEX(KURALLAR!$B$13:$B$23,MATCH($B19,KURALLAR!$A$13:$A$23,0)),0) -> 2 | N19: =H19*M19 -> 16
A20: MKA-MCC-1 (MCC-01-DT1-04 (VIP)) — MCC, 8 моторных фидеров (ABB) | B20: kontak | C20: 1SAM201901R1001 | D20: =IFERROR(INDEX(FIYAT!$D$2:$D$32,MATCH($C20,FIYAT!$C$2:$C$32,0)),"АРТИКУЛ НЕ В FIYAT") -> Блок доп. контактов HKF1-11 (1НО+1НЗ), верхний, для MS116 | E20: =IFERROR(INDEX(FIYAT!$I$2:$I$32,MATCH($C20,FIYAT!$C$2:$C$32,0)),"") -> 4793.906 | F20: =IFERROR(INDEX(FIYAT!$J$2:$J$32,MATCH($C20,FIYAT!$C$2:$C$32,0)),"") -> 4793.906 | G20: =IF(OR(F20="",H20=""),"",H20*F20) -> 38351.248 | H20: 8 | I20: =IFERROR(INDEX(FIYAT!$K$2:$K$32,MATCH($C20,FIYAT!$C$2:$C$32,0)),"") -> шт | J20: =IFERROR(INDEX(FIYAT!$L$2:$L$32,MATCH($C20,FIYAT!$C$2:$C$32,0)),"") -> abb | K20: MKA-MCC | L20: фидеры: 1 на MS116 (метка дублируется в силовой и управл. частях) | M20: =IFERROR(INDEX(KURALLAR!$B$13:$B$23,MATCH($B20,KURALLAR!$A$13:$A$23,0)),0) -> 2 | N20: =H20*M20 -> 16
A21: MKA-MCC-1 (MCC-01-DT1-04 (VIP)) — MCC, 8 моторных фидеров (ABB) | B21: kontak | C21: 1SAM201903R1001 | D21: =IFERROR(INDEX(FIYAT!$D$2:$D$32,MATCH($C21,FIYAT!$C$2:$C$32,0)),"АРТИКУЛ НЕ В FIYAT") -> Контакт сигнализации SK1-11 (1НО+1НЗ), боковой, для MS116 | E21: =IFERROR(INDEX(FIYAT!$I$2:$I$32,MATCH($C21,FIYAT!$C$2:$C$32,0)),"") -> 9766.3085 | F21: =IFERROR(INDEX(FIYAT!$J$2:$J$32,MATCH($C21,FIYAT!$C$2:$C$32,0)),"") -> 9766.3085 | G21: =IF(OR(F21="",H21=""),"",H21*F21) -> 78130.468 | H21: 8 | I21: =IFERROR(INDEX(FIYAT!$K$2:$K$32,MATCH($C21,FIYAT!$C$2:$C$32,0)),"") -> шт | J21: =IFERROR(INDEX(FIYAT!$L$2:$L$32,MATCH($C21,FIYAT!$C$2:$C$32,0)),"") -> abb | K21: MKA-MCC | L21: фидеры: 1 на MS116 (метка дублируется в силовой и управл. частях) | M21: =IFERROR(INDEX(KURALLAR!$B$13:$B$23,MATCH($B21,KURALLAR!$A$13:$A$23,0)),0) -> 2 | N21: =H21*M21 -> 16
A22: MKA-MCC-1 (MCC-01-DT1-04 (VIP)) — MCC, 8 моторных фидеров (ABB) | B22: perekluchatel | C22: 1SFA611210R1006 | D22: M3SS1-10B mandal buton kafalari | E22: 5431.3935 | F22: 5431.3935 | G22: =IF(OR(F22="",H22=""),"",H22*F22) -> 43451.148 | H22: 8 | I22: шт | J22: abb | K22: MKA-MCC | L22: фидеры: 1S1 селектор MAN-0-AUTO (корпус) | M22: =IFERROR(INDEX(KURALLAR!$B$13:$B$23,MATCH($B22,KURALLAR!$A$13:$A$23,0)),0) -> 21.8 | N22: =H22*M22 -> 174.4
A23: MKA-MCC-1 (MCC-01-DT1-04 (VIP)) — MCC, 8 моторных фидеров (ABB) | B23: perekluchatel | C23: 1SFA611601R1100 | D23: =IFERROR(INDEX(FIYAT!$D$2:$D$32,MATCH($C23,FIYAT!$C$2:$C$32,0)),"АРТИКУЛ НЕ В FIYAT") -> Корпус MCBH5-00 для головок и блоков (5 блоков в ряд) | E23: =IFERROR(INDEX(FIYAT!$I$2:$I$32,MATCH($C23,FIYAT!$C$2:$C$32,0)),"") -> 647.6873 | F23: =IFERROR(INDEX(FIYAT!$J$2:$J$32,MATCH($C23,FIYAT!$C$2:$C$32,0)),"") -> 647.6873 | G23: =IF(OR(F23="",H23=""),"",H23*F23) -> 5181.4984 | H23: 8 | I23: =IFERROR(INDEX(FIYAT!$K$2:$K$32,MATCH($C23,FIYAT!$C$2:$C$32,0)),"") -> шт | J23: =IFERROR(INDEX(FIYAT!$L$2:$L$32,MATCH($C23,FIYAT!$C$2:$C$32,0)),"") -> abb | K23: MKA-MCC | L23: фидеры: 1S1 селектор MAN-0-AUTO (корпус) | M23: =IFERROR(INDEX(KURALLAR!$B$13:$B$23,MATCH($B23,KURALLAR!$A$13:$A$23,0)),0) -> 21.8 | N23: =H23*M23 -> 174.4
A24: MKA-MCC-1 (MCC-01-DT1-04 (VIP)) — MCC, 8 моторных фидеров (ABB) | B24: kontak | C24: 1SFA611610R1001 | D24: =IFERROR(INDEX(FIYAT!$D$2:$D$32,MATCH($C24,FIYAT!$C$2:$C$32,0)),"АРТИКУЛ НЕ В FIYAT") -> Блок контактов MCB-10, 1НО | E24: =IFERROR(INDEX(FIYAT!$I$2:$I$32,MATCH($C24,FIYAT!$C$2:$C$32,0)),"") -> 2345.954 | F24: =IFERROR(INDEX(FIYAT!$J$2:$J$32,MATCH($C24,FIYAT!$C$2:$C$32,0)),"") -> 2345.954 | G24: =IF(OR(F24="",H24=""),"",H24*F24) -> 18767.632 | H24: 8 | I24: =IFERROR(INDEX(FIYAT!$K$2:$K$32,MATCH($C24,FIYAT!$C$2:$C$32,0)),"") -> шт | J24: =IFERROR(INDEX(FIYAT!$L$2:$L$32,MATCH($C24,FIYAT!$C$2:$C$32,0)),"") -> abb | K24: MKA-MCC | L24: фидеры: 1S1 контактные блоки, 2 на селектор (принято; на схеме MCB-20/A, MCB-10/A) | M24: =IFERROR(INDEX(KURALLAR!$B$13:$B$23,MATCH($B24,KURALLAR!$A$13:$A$23,0)),0) -> 2 | N24: =H24*M24 -> 16
A25: MKA-MCC-1 (MCC-01-DT1-04 (VIP)) — MCC, 8 моторных фидеров (ABB) | B25: kontak | C25: 1SFA611610R1002 | D25: MCB--20 Блок контактов | E25: 3059 | F25: 3059 | G25: =IF(OR(F25="",H25=""),"",H25*F25) -> 24472 | H25: 8 | I25: шт | J25: abb | K25: MKA-MCC | L25: фидеры: 1S1 контактные блоки, 2 на селектор (принято; на схеме MCB-20/A, MCB-10/A) | M25: =IFERROR(INDEX(KURALLAR!$B$13:$B$23,MATCH($B25,KURALLAR!$A$13:$A$23,0)),0) -> 2 | N25: =H25*M25 -> 16
A26: MKA-MCC-1 (MCC-01-DT1-04 (VIP)) — MCC, 8 моторных фидеров (ABB) | B26: rele | C26: 1SVR405601R0000 | D26: =IFERROR(INDEX(FIYAT!$D$2:$D$32,MATCH($C26,FIYAT!$C$2:$C$32,0)),"АРТИКУЛ НЕ В FIYAT") -> Реле CR-P024AC2, 2 перекл., 8А, катушка 24В AC | E26: =IFERROR(INDEX(FIYAT!$I$2:$I$32,MATCH($C26,FIYAT!$C$2:$C$32,0)),"") -> 4334.915 | F26: =IFERROR(INDEX(FIYAT!$J$2:$J$32,MATCH($C26,FIYAT!$C$2:$C$32,0)),"") -> 4334.915 | G26: =IF(OR(F26="",H26=""),"",H26*F26) -> 69358.64 | H26: 16 | I26: =IFERROR(INDEX(FIYAT!$K$2:$K$32,MATCH($C26,FIYAT!$C$2:$C$32,0)),"") -> шт | J26: =IFERROR(INDEX(FIYAT!$L$2:$L$32,MATCH($C26,FIYAT!$C$2:$C$32,0)),"") -> abb | K26: MKA-MCC | L26: фидеры: 1R2 REMOTE START/STOP, 1R3 FIRE START | M26: =IFERROR(INDEX(KURALLAR!$B$13:$B$23,MATCH($B26,KURALLAR!$A$13:$A$23,0)),0) -> 21.8 | N26: =H26*M26 -> 348.8
A27: MKA-MCC-1 (MCC-01-DT1-04 (VIP)) — MCC, 8 моторных фидеров (ABB) | B27: kolodka | C27: 1SVR405650R1000 | D27: CR-PSS колодка для реле | E27: 4666.4085 | F27: 4666.4085 | G27: =IF(OR(F27="",H27=""),"",H27*F27) -> 74662.536 | H27: 16 | I27: шт | J27: abb | K27: MKA-MCC | L27: лист 1 (ввод): -R0 выходное реле реле фаз; фидеры: 1R1 (ARIZA) + реле LAMP TEST на листе 2 | M27: =IFERROR(INDEX(KURALLAR!$B$13:$B$23,MATCH($B27,KURALLAR!$A$13:$A$23,0)),0) -> 0 | N27: =H27*M27 -> 0
A28: MKA-MCC-1 (MCC-01-DT1-04 (VIP)) — MCC, 8 моторных фидеров (ABB) | B28: tt | D28: Понижающий трансформатор ОСМ1-0,25кВА 380-220/220-110-42-36-24-12-5 | E28: 30000 | F28: 30000 | G28: =IF(OR(F28="",H28=""),"",H28*F28) -> 30000 | H28: 1 | I28: =IFERROR(INDEX(FIYAT!$K$2:$K$32,MATCH($C28,FIYAT!$C$2:$C$32,0)),"") | J28: pys | K28: MKA-MCC | L28: хвост. листы: QF 3x40A 6кА (х-ка C принята) | M28: =IFERROR(INDEX(KURALLAR!$B$13:$B$23,MATCH($B28,KURALLAR!$A$13:$A$23,0)),0) -> 0 | N28: =H28*M28 -> 0
A29: MKA-MCC-1 (MCC-01-DT1-04 (VIP)) — MCC, 8 моторных фидеров (ABB) | B29: tt | D29: Понижающий трансформатор ОСМ1 0,1кВА 380-220/220-110-42-36-24-12-6 | E29: 20000 | F29: 20000 | G29: =IF(OR(F29="",H29=""),"",H29*F29) -> 20000 | H29: 1 | I29: =IFERROR(INDEX(FIYAT!$K$2:$K$32,MATCH($C29,FIYAT!$C$2:$C$32,0)),"") | J29: pys | K29: MKA-MCC | L29: хвост. листы: QF 3x40A 6кА (х-ка C принята) | M29: =IFERROR(INDEX(KURALLAR!$B$13:$B$23,MATCH($B29,KURALLAR!$A$13:$A$23,0)),0) -> 0 | N29: =H29*M29 -> 0
A30: MKA-MCC-1 (MCC-01-DT1-04 (VIP)) — MCC, 8 моторных фидеров (ABB) | B30: oto | C30: 2CDS213001R0404 | D30: =IFERROR(INDEX(FIYAT!$D$2:$D$32,MATCH($C30,FIYAT!$C$2:$C$32,0)),"АРТИКУЛ НЕ В FIYAT") -> Авт. выкл. SH 203-C 40, 3P, 40А, х-ка C, 6кА | E30: =IFERROR(INDEX(FIYAT!$I$2:$I$32,MATCH($C30,FIYAT!$C$2:$C$32,0)),"") -> 24163.326 | F30: =IFERROR(INDEX(FIYAT!$J$2:$J$32,MATCH($C30,FIYAT!$C$2:$C$32,0)),"") -> 24163.326 | G30: =IF(OR(F30="",H30=""),"",H30*F30) -> 241633.26 | H30: 10 | I30: =IFERROR(INDEX(FIYAT!$K$2:$K$32,MATCH($C30,FIYAT!$C$2:$C$32,0)),"") -> шт | J30: =IFERROR(INDEX(FIYAT!$L$2:$L$32,MATCH($C30,FIYAT!$C$2:$C$32,0)),"") -> abb | K30: MKA-MCC | L30: хвост. листы: QF 3x40A 6кА (х-ка C принята) | M30: =IFERROR(INDEX(KURALLAR!$B$13:$B$23,MATCH($B30,KURALLAR!$A$13:$A$23,0)),0) -> 4 | N30: =H30*M30 -> 40
A31: MKA-MCC-1 (MCC-01-DT1-04 (VIP)) — MCC, 8 моторных фидеров (ABB) | B31: oto | C31: 2CDS211001R0164 | D31: =IFERROR(INDEX(FIYAT!$D$2:$D$32,MATCH($C31,FIYAT!$C$2:$C$32,0)),"АРТИКУЛ НЕ В FIYAT") -> Авт. выкл. SH 201-C 16, 1P, 16А, х-ка C, 6кА | E31: =IFERROR(INDEX(FIYAT!$I$2:$I$32,MATCH($C31,FIYAT!$C$2:$C$32,0)),"") -> 4125.8191 | F31: =IFERROR(INDEX(FIYAT!$J$2:$J$32,MATCH($C31,FIYAT!$C$2:$C$32,0)),"") -> 4125.8191 | G31: =IF(OR(F31="",H31=""),"",H31*F31) -> 61887.286 | H31: 15 | I31: =IFERROR(INDEX(FIYAT!$K$2:$K$32,MATCH($C31,FIYAT!$C$2:$C$32,0)),"") -> шт | J31: =IFERROR(INDEX(FIYAT!$L$2:$L$32,MATCH($C31,FIYAT!$C$2:$C$32,0)),"") -> abb | K31: MKA-MCC | L31: хвост. листы: QF 1x16A 6кА (х-ка C принята) | M31: =IFERROR(INDEX(KURALLAR!$B$13:$B$23,MATCH($B31,KURALLAR!$A$13:$A$23,0)),0) -> 4 | N31: =H31*M31 -> 60
A32: MKA-MCC-1 (MCC-01-DT1-04 (VIP)) — MCC, 8 моторных фидеров (ABB) | B32: монтажный материал | C32: монтажный материал | D32: монтажный материал | E32: =G33*KURALLAR!$C$8 -> 62580 | F32: =E32 -> 62580 | G32: =H32*F32 -> 62580 | H32: 1 | I32: шт | J32: монтажный материал | K32: MKA-MCC
A33: MKA-MCC-1 (MCC-01-DT1-04 (VIP)) — MCC, 8 моторных фидеров (ABB) | B33: монтажная работа | C33: монтажная работа | D33: монтажная работа | E33: =KURALLAR!$C$6 -> 100 | F33: =E33 -> 100 | G33: =H33*F33 -> 156450 | H33: =SUM(N4:N31)*KURALLAR!$C$7 -> 1564.5 | I33: мин | J33: монтажная работа | K33: MKA-MCC
A34: MKA-MCC-1 (MCC-01-DT1-04 (VIP)) — MCC, 8 моторных фидеров (ABB) | D34: ИТОГО по щиту, тг | G34: =SUM(G4:G33) -> 2079517.6 | K34: MKA-MCC
A35: MKA-MCC-2 (MCC-01-DT1-05 (6 GATE)) — MCC, 4 моторных фидеров (ABB) | D35: MKA-MCC-2 (MCC-01-DT1-05 (6 GATE)) — MCC, 4 моторных фидеров (ABB) | H35: 1 | I35: комплект | J35: ABB (комплектующие) | K35: MKA-MCC
A36: MKA-MCC-2 (MCC-01-DT1-05 (6 GATE)) — MCC, 4 моторных фидеров (ABB) | B36: korpus | C36: 719-15568 | D36: Мет. Щит ЩМП- 6 (1200х750х300) IP31 | E36: 65000 | F36: =E36*0.6 -> 39000 | G36: =IF(OR(F36="",H36=""),"",H36*F36) -> 39000 | H36: 1 | I36: =IFERROR(INDEX(FIYAT!$K$2:$K$32,MATCH($C36,FIYAT!$C$2:$C$32,0)),"") | J36: teksan f | K36: MKA-MCC | L36: хвост. листы: QF 3x40A 6кА (х-ка C принята) | M36: =IFERROR(INDEX(KURALLAR!$B$13:$B$23,MATCH($B36,KURALLAR!$A$13:$A$23,0)),0) -> 0 | N36: =H36*M36 -> 0
A37: MKA-MCC-2 (MCC-01-DT1-05 (6 GATE)) — MCC, 4 моторных фидеров (ABB) | B37: mccb | C37: 1SDA068059R1 | D37: =IFERROR(INDEX(FIYAT!$D$2:$D$32,MATCH($C37,FIYAT!$C$2:$C$32,0)),"АРТИКУЛ НЕ В FIYAT") -> Авт. выкл. Tmax XT3N 250, TMD, In=250A, 3P, Icu 36кА | E37: =IFERROR(INDEX(FIYAT!$I$2:$I$32,MATCH($C37,FIYAT!$C$2:$C$32,0)),"") -> 234187.41 | F37: =IFERROR(INDEX(FIYAT!$J$2:$J$32,MATCH($C37,FIYAT!$C$2:$C$32,0)),"") -> 234187.41 | G37: =IF(OR(F37="",H37=""),"",H37*F37) -> 234187.41 | H37: 1 | I37: =IFERROR(INDEX(FIYAT!$K$2:$K$32,MATCH($C37,FIYAT!$C$2:$C$32,0)),"") -> шт | J37: =IFERROR(INDEX(FIYAT!$L$2:$L$32,MATCH($C37,FIYAT!$C$2:$C$32,0)),"") -> abb | K37: MKA-MCC | L37: лист 1 (ввод): QF1 MAIN BREAKER; на схеме «XT1N 250A»; ПОДМЕНА XT1N→XT3N (XT1 макс. 160А) | M37: =IFERROR(INDEX(KURALLAR!$B$13:$B$23,MATCH($B37,KURALLAR!$A$13:$A$23,0)),0) -> 15.3 | N37: =H37*M37 -> 15.3
A38: MKA-MCC-2 (MCC-01-DT1-05 (6 GATE)) — MCC, 4 моторных фидеров (ABB) | B38: oto | C38: 2CDS211001R0065 | D38: =IFERROR(INDEX(FIYAT!$D$2:$D$32,MATCH($C38,FIYAT!$C$2:$C$32,0)),"АРТИКУЛ НЕ В FIYAT") -> Авт. выкл. SH 201-B 6, 1P, 6А, х-ка B, 6кА | E38: =IFERROR(INDEX(FIYAT!$I$2:$I$32,MATCH($C38,FIYAT!$C$2:$C$32,0)),"") -> 4503.2117 | F38: =IFERROR(INDEX(FIYAT!$J$2:$J$32,MATCH($C38,FIYAT!$C$2:$C$32,0)),"") -> 4503.2117 | G38: =IF(OR(F38="",H38=""),"",H38*F38) -> 31522.482 | H38: 7 | I38: =IFERROR(INDEX(FIYAT!$K$2:$K$32,MATCH($C38,FIYAT!$C$2:$C$32,0)),"") -> шт | J38: =IFERROR(INDEX(FIYAT!$L$2:$L$32,MATCH($C38,FIYAT!$C$2:$C$32,0)),"") -> abb | K38: MKA-MCC | L38: лист 1 (ввод): FH1-FH3, защита ламп фаз; фидеры: 1F1 защита цепи управления | M38: =IFERROR(INDEX(KURALLAR!$B$13:$B$23,MATCH($B38,KURALLAR!$A$13:$A$23,0)),0) -> 4 | N38: =H38*M38 -> 28
A39: MKA-MCC-2 (MCC-01-DT1-05 (6 GATE)) — MCC, 4 моторных фидеров (ABB) | B39: lamb | C39: 1SFA619403R5231 | D39: =IFERROR(INDEX(FIYAT!$D$2:$D$32,MATCH($C39,FIYAT!$C$2:$C$32,0)),"АРТИКУЛ НЕ В FIYAT") -> Лампа сигнальная LED CL2-523R, 230В AC, красная | E39: =IFERROR(INDEX(FIYAT!$I$2:$I$32,MATCH($C39,FIYAT!$C$2:$C$32,0)),"") -> 4906.1038 | F39: =IFERROR(INDEX(FIYAT!$J$2:$J$32,MATCH($C39,FIYAT!$C$2:$C$32,0)),"") -> 4906.1038 | G39: =IF(OR(F39="",H39=""),"",H39*F39) -> 24530.519 | H39: 5 | I39: =IFERROR(INDEX(FIYAT!$K$2:$K$32,MATCH($C39,FIYAT!$C$2:$C$32,0)),"") -> шт | J39: =IFERROR(INDEX(FIYAT!$L$2:$L$32,MATCH($C39,FIYAT!$C$2:$C$32,0)),"") -> abb | K39: MKA-MCC | L39: лист 1 (ввод): H1 лампа фазы; фидеры: 1H2 FAULT (тип не указан, принят CL2-523R) | M39: =IFERROR(INDEX(KURALLAR!$B$13:$B$23,MATCH($B39,KURALLAR!$A$13:$A$23,0)),0) -> 8 | N39: =H39*M39 -> 40
A40: MKA-MCC-2 (MCC-01-DT1-05 (6 GATE)) — MCC, 4 моторных фидеров (ABB) | B40: lamb | C40: 1SFA619403R5233 | D40: =IFERROR(INDEX(FIYAT!$D$2:$D$32,MATCH($C40,FIYAT!$C$2:$C$32,0)),"АРТИКУЛ НЕ В FIYAT") -> Лампа сигнальная LED CL2-523Y, 230В AC, жёлтая | E40: =IFERROR(INDEX(FIYAT!$I$2:$I$32,MATCH($C40,FIYAT!$C$2:$C$32,0)),"") -> 4906.1038 | F40: =IFERROR(INDEX(FIYAT!$J$2:$J$32,MATCH($C40,FIYAT!$C$2:$C$32,0)),"") -> 4906.1038 | G40: =IF(OR(F40="",H40=""),"",H40*F40) -> 4906.1038 | H40: 1 | I40: =IFERROR(INDEX(FIYAT!$K$2:$K$32,MATCH($C40,FIYAT!$C$2:$C$32,0)),"") -> шт | J40: =IFERROR(INDEX(FIYAT!$L$2:$L$32,MATCH($C40,FIYAT!$C$2:$C$32,0)),"") -> abb | K40: MKA-MCC | L40: лист 1 (ввод): H2 лампа фазы | M40: =IFERROR(INDEX(KURALLAR!$B$13:$B$23,MATCH($B40,KURALLAR!$A$13:$A$23,0)),0) -> 8 | N40: =H40*M40 -> 8
...

Sheet FIYAT
A1: ID | B1: tip | C1: Артикул | D1: Номенклатура | E1: Тип (модель) | F1: Цена по прайсу, EUR | G1: Группа скидки | H1: Скидка | I1: Прайс,тг | J1: Нетто,тг | K1: Ед.изм | L1: marka | M1: Источник (стр. PDF)
A2: F001 | B2: mccb | C2: 1SDA067415R1 | D2: Авт. выкл. Tmax XT1N 160, TMD, In=80A, 3P, Icu 36кА | E2: XT1N 160 TMD In=80A 3P | F2: 246.1 | G2: MCCB | H2: 0 | I2: =F2*KURALLAR!$C$3 -> 125508.54 | J2: =I2*(1-H2) -> 125508.54 | K2: шт | L2: abb | M2: ABB KASIM2025, PDF стр. 102
A3: F002 | B3: mccb | C3: 1SDA067418R1 | D3: Авт. выкл. Tmax XT1N 160, TMD, In=160A, 3P, Icu 36кА | E3: XT1N 160 TMD In=160A 3P | F3: 317.9 | G3: MCCB | H3: 0 | I3: =F3*KURALLAR!$C$3 -> 162125.82 | J3: =I3*(1-H3) -> 162125.82 | K3: шт | L3: abb | M3: ABB KASIM2025, PDF стр. 102
A4: F003 | B4: mccb | C4: 1SDA068058R1 | D4: Авт. выкл. Tmax XT3N 250, TMD, In=200A, 3P, Icu 36кА | E4: XT3N 250 TMD In=200A 3P | F4: 459.2 | G4: MCCB | H4: 0 | I4: =F4*KURALLAR!$C$3 -> 234187.41 | J4: =I4*(1-H4) -> 234187.41 | K4: шт | L4: abb | M4: ABB KASIM2025, PDF стр. 102
A5: F004 | B5: mccb | C5: 1SDA068059R1 | D5: Авт. выкл. Tmax XT3N 250, TMD, In=250A, 3P, Icu 36кА | E5: XT3N 250 TMD In=250A 3P | F5: 459.2 | G5: MCCB | H5: 0 | I5: =F5*KURALLAR!$C$3 -> 234187.41 | J5: =I5*(1-H5) -> 234187.41 | K5: шт | L5: abb | M5: ABB KASIM2025, PDF стр. 102
A6: F005 | B6: motor | C6: 1SAM250000R1007 | D6: Автомат защиты двигателя MS116-2.5 (1.6-2.5А) | E6: MS116-2.5 | F6: 62.53 | G6: OTHER | H6: 0 | I6: =F6*KURALLAR!$C$3 -> 31889.675 | J6: =I6*(1-H6) -> 31889.675 | K6: шт | L6: abb | M6: ABB KASIM2025, PDF стр. 232
A7: F006 | B7: motor | C7: 1SAM250000R1009 | D7: Автомат защиты двигателя MS116-6.3 (4-6.3А) | E7: MS116-6.3 | F7: 62.53 | G7: OTHER | H7: 0 | I7: =F7*KURALLAR!$C$3 -> 31889.675 | J7: =I7*(1-H7) -> 31889.675 | K7: шт | L7: abb | M7: ABB KASIM2025, PDF стр. 232
A8: F007 | B8: motor | C8: 1SAM250000R1010 | D8: Автомат защиты двигателя MS116-10 (6.3-10А) | E8: MS116-10 | F8: 67.17 | G8: OTHER | H8: 0 | I8: =F8*KURALLAR!$C$3 -> 34256.028 | J8: =I8*(1-H8) -> 34256.028 | K8: шт | L8: abb | M8: ABB KASIM2025, PDF стр. 232
A9: F008 | B9: contactor | C9: 1SBL137001R1310 | D9: Контактор AF09-30-10, 3P, 9А AC3, 1НО, катушка 100-250В AC/DC | E9: AF09-30-10 | F9: 37.91 | G9: OTHER | H9: 0 | I9: =F9*KURALLAR!$C$3 -> 19333.721 | J9: =I9*(1-H9) -> 19333.721 | K9: шт | L9: abb | M9: ABB KASIM2025, PDF стр. 222
A10: F009 | B10: contactor | C10: 1SBL157001R1310 | D10: Контактор AF12-30-10, 3P, 12А AC3, 1НО, катушка 100-250В AC/DC | E10: AF12-30-10 | F10: 39.64 | G10: OTHER | H10: 0 | I10: =F10*KURALLAR!$C$3 -> 20216.004 | J10: =I10*(1-H10) -> 20216.004 | K10: шт | L10: abb | M10: ABB KASIM2025, PDF стр. 222
A11: F010 | B11: kontak | C11: 1SBN010120R1011 | D11: Блок доп. контактов боковой CAL4-11 (1НО+1НЗ) для AF09...AF96 | E11: CAL4-11 | F11: 12.16 | G11: OTHER | H11: 0 | I11: =F11*KURALLAR!$C$3 -> 6201.4784 | J11: =I11*(1-H11) -> 6201.4784 | K11: шт | L11: abb | M11: ABB KASIM2025, PDF стр. 225
A12: F011 | B12: kontak | C12: 1SAM201901R1001 | D12: Блок доп. контактов HKF1-11 (1НО+1НЗ), верхний, для MS116 | E12: HKF1-11 | F12: 9.4 | G12: OTHER | H12: 0 | I12: =F12*KURALLAR!$C$3 -> 4793.906 | J12: =I12*(1-H12) -> 4793.906 | K12: шт | L12: abb | M12: ABB KASIM2025, PDF стр. 233
A13: F012 | B13: kontak | C13: 1SAM201903R1001 | D13: Контакт сигнализации SK1-11 (1НО+1НЗ), боковой, для MS116 | E13: SK1-11 | F13: 19.15 | G13: OTHER | H13: 0 | I13: =F13*KURALLAR!$C$3 -> 9766.3085 | J13: =I13*(1-H13) -> 9766.3085 | K13: шт | L13: abb | M13: ABB KASIM2025, PDF стр. 233
... A32: F031 | B32: aksesuar | C32: 2CSM256363R1801 | D32: Плавкая вставка E 9F10 GG6, 10.3x38, 6А gG | E32: E 9F10 GG6 | F32: 3.81 | G32: OTHER | H32: 0 | I32: =F32*KURALLAR!$C$3 -> 1943.0619 | J32: =I32*(1-H32) -> 1943.0619 | K32: шт | L32: abb | M32: ABB KASIM2025, PDF стр. 37
B33: kolodka | C33: 1SVR405651R3000 | D33: CR-M4SS колодка для реле | E33: CR-M4SS | F33: 8.5 | G33: OTHER | H33: 0 | I33: =F33*KURALLAR!$C$3 -> 4334.915 | J33: =I33*(1-H33) -> 4334.915 | K33: шт | L33: abb | M33: ABB KASIM2025, PDF стр. 38
C34: 1SFA611210R1006 | D34: M3SS1-10B mandal buton kafalari | E34: M3SS1-10B | F34: 10.65 | G34: OTHER | H34: 0 | I34: =F34*KURALLAR!$C$3 -> 5431.3935 | J34: =I34*(1-H34) -> 5431.3935 | K34: шт | L34: abb
C35: 1SFA611610R1002 | D35: MCB--20 Блок контактов | E35: MCB-20 | F35: 6 | G35: OTHER | H35: 0 | I35: =F35*KURALLAR!$C$3 -> 3059.94 | J35: =I35*(1-H35) -> 3059.94 | K35: шт | L35: abb
B36: kolodka | C36: 1SVR405650R1000 | D36: CR-PSS колодка для реле | E36: CR-PSS | F36: 9.15 | G36: OTHER | H36: 0 | I36: =F36*KURALLAR!$C$3 -> 4666.4085 | J36: =I36*(1-H36) -> 4666.4085 | K36: шт | L36: abb | M36: ABB KASIM2025, PDF стр. 38

Sheet KURALLAR
A1: KURALLAR — жёлтые ячейки меняются вручную; BOM, FIYAT и OZET пересчитываются
A3: EUR_KZT | B3: Курс EUR→KZT (НБ РК, последний найденный на 07.10.2026 — обновить на дату КП) | C3: 509.99
A4: DISC_MCCB | B4: Скидка: компактные и воздушные автоматы (из названия файла прайса: 77%) | C4: 0.77
A5: DISC_OTHER | B5: Скидка: все прочие группы (из названия файла прайса: 70%) | C5: 0.7
A6: DK_UCRET | B6: Стоимость монтажа, KZT/мин (как в образце) | C6: 100
A7: ISCILIK_KAT | B7: Множитель норм времени | C7: 1
A8: MONTAJ_MALZ_KAT | B8: Монтажный материал = стоимость работ × | C8: 0.4
A9: NDS_ORANI | B9: НДС | C9: 0.16
A12: НОРМЫ МОНТАЖА, мин/шт (взяты из таблицы KURALLAR образца ASTANA WB)
A13: mccb | B13: 15.3
A14: oto | B14: 4
A15: contactor | B15: 5.9
A16: kontak | B16: 2
A17: lamb | B17: 8
A18: button | B18: 8
A19: rele | B19: 21.8
A20: perekluchatel | B20: 21.8
A21: motor | B21: 2
A22: bh | B22: 4
A23: aksesuar | B23: 0

Sheet OZET
A1: ЩИТ | B1: ШТ | C1: Оборудование ABB,тг | D1: Монтажный материал,тг | E1: Монтаж (работа),тг | F1: ИТОГО по щиту,тг | G1: Фидеров | H1: Мин. монтажа
A2: MKA-MCC-1 (MCC-01-DT1-04 (VIP)) | B2: 1 | C2: =BOM!G34-BOM!G32-BOM!G33 -> 1860487.6 | D2: =BOM!G32 -> 62580 | E2: =BOM!G33 -> 156450 | F2: =BOM!G34*B2 -> 2079517.6 | G2: 8 | H2: =BOM!H33 -> 1564.5
A3: MKA-MCC-2 (MCC-01-DT1-05 (6 GATE)) | B3: 1 | C3: =BOM!G66-BOM!G64-BOM!G65 -> 1274451.6 | D3: =BOM!G64 -> 31460 | E3: =BOM!G65 -> 78650 | F3: =BOM!G66*B3 -> 1384561.6 | G3: 4 | H3: =BOM!H65 -> 786.5
A4: MKA-MCC-3 (MCC-03-DT1-01 (VK 5)) | B4: 1 | C4: =BOM!G100-BOM!G98-BOM!G99 -> 1556676.3 | D4: =BOM!G98 -> 52884 | E4: =BOM!G99 -> 132210 | F4: =BOM!G100*B4 -> 1741770.3 | G4: 8 | H4: =BOM!H99 -> 1322.1
A5: MKA-MCC-4 (MCC-03-DT1-02 (NEW)) | B5: 1 | C5: =BOM!G135-BOM!G133-BOM!G134 -> 1665600.9 | D5: =BOM!G133 -> 47968 | E5: =BOM!G134 -> 119920 | F5: =BOM!G135*B5 -> 1833488.9 | G5: 7 | H5: =BOM!H134 -> 1199.2
A6: MKA-MCC-5 (MCC-03-DT1-04 (57)) | B6: 1 | C6: =BOM!G170-BOM!G168-BOM!G169 -> 1985142.6 | D6: =BOM!G168 -> 65596 | E6: =BOM!G169 -> 163990 | F6: =BOM!G170*B6 -> 2214728.6 | G6: 10 | H6: =BOM!H169 -> 1639.9
A7: MKA-MCC-6 (MCC-03-DT1-0 (VK 11)) | B7: 1 | C7: =BOM!G204-BOM!G202-BOM!G203 -> 2093386.1 | D7: =BOM!G202 -> 76388 | E7: =BOM!G203 -> 190970 | F7: =BOM!G204*B7 -> 2360744.1 | G7: 12 | H7: =BOM!H203 -> 1909.7
A8: ИТОГО без НДС, тг | C8: =SUM(C2:C7) -> 10435745 | D8: =SUM(D2:D7) -> 336876 | E8: =SUM(E2:E7) -> 842190 | F8: =SUM(F2:F7) -> 11614811 | G8: =SUM(G2:G7) -> 49 | H8: =SUM(H2:H7) -> 8421.9
A9: НДС, тг | F9: =F8*KURALLAR!$C$9 -> 1858369.8
A10: ИТОГО с НДС, тг | F10: =F8+F9 -> 13473181
A12: Нетто-цены: прайс ABB Ноябрь 2025 (EUR) × курс × (1−скидка). Параметры — лист KURALLAR.

Sheet ДОПУЩЕНИЯ
A1: ДОПУЩЕНИЯ И ЗАМЕЧАНИЯ
A2: Источник | B2: DXF «mcc_tek_hat_seması»: 69 листов, 6 щитов MKA-MCC-1…6 (Almaty Airport, MKA STROY LLP), 49 моторных фидеров. Цены — ABB Elektrifikasyon Fiyat Listesi, Kasım 2025 (EUR).
A3: Скидки | B3: Взяты из названия файла прайса: 77% — компактные/воздушные автоматы (XT), 70% — все прочие группы. Проверьте.
A4: Курс | B4: 509,99 ₸/€ — официальный курс НБ РК на 07.10.2026 (последний найденный). Обновить в KURALLAR!C3.
A5: Главные автоматы | B5: Схема: «XT1N 200A» и «XT1N 250A» (MCC-1, 2, 4). У XT1 макс. 160А, поэтому приняты XT3N 250 In=200/250А. Подтвердить с проектировщиком.
A6: Катушка контакторов | B6: Цепи управления 230В → AF..-30-10 с катушкой 100-250В AC/DC (R1310), а не 24-60В.
A7: HKF1-11 / SK1-11 | B7: Метка встречается дважды на фидер (силовая и цепь управления) — принято по 1 шт. на фидер.
A8: Селектор 1S1 | B8: Принято: корпус MCBH5-00 ×1 + 2 блока MCB-10 (1НО) на фидер. На схеме указаны MCB-20/A, MCB-10/A — в прайсе таких артикулов нет. Головка селектора 1-0-2 в прайсе не найдена.
A9: Лампы фидеров | B9: 1H1 (ON) и 1H2 (FAULT) без типа на схеме — приняты CL2-523G / CL2-523R как на листе ввода.
A10: Плавкие вставки | B10: E 9F10 GG6: принято 3 шт. на щит (по полюсу).
A11: Автоматы QF | B11: Тип кривой не указан — принята C. 6кА → серия SH200.
A12: Монтаж | B12: Нормы минут и ставка 100 ₸/мин взяты из образца ASTANA WB; монтажный материал = 40% работ. Обнулите в KURALLAR, если не нужно.
A13: НЕ ВОШЛО (нет в каталоге ABB) | B13: Корпуса щитов, шины, трансформаторы T1 250VA 400/230В и T2 100VA 230/24В (по 1 на щит ×6), головки селекторов 1-0-2 (49), розетки/колодки реле CR-M / CR-P, клеммники X1/X2/X3 и PE, внутренний монтаж, кабели N2XH.
