Workbook

Sheet KURALLAR
A1: YSF HICH — FREEDOM LOUNGE (TAV-FR-E-EAP-009-R000) BOM KURAL TABLOSU
A2: SARI hücreler düzenlenebilir. Değiştirince tüm BOM yeniden hesaplanır. Diğer her şey formüldür.
A4: 1. DÖVİZ KURLARI
A5: ПАРА | B5: KZT KURU | C5: KAYNAK / TARİH
A6: KZT | B6: 1 | C6: Baz para birimi — değiştirmeyin
A7: EUR | B7: 540 | C7: Ağustos 2026 KZT/EUR bandı 537-543 (Investing.com / moneypanda.kz). BOM günü kuruyla güncelleyin.
A8: TL | B8: 13.5 | C8: Bu BOM da Schneider/Legrand kalemi yok — kullanılmıyor.
A9: USD | B9: 505 | C9: Kullanılmıyor.
A11: 2. MARKA KATSAYILARI (нетто = лист × katsayı × kur)
A12: ЗАВОД | B12: KATSAYI | C12: PARA | D12: NOT
A13: ABB | B13: 0.405 | C13: EUR | D13: liste × 1,35 × 0,30 = 0,405 (standart gruplar %70 iskonto)
A14: ABB_ACB | B14: 0.3105 | C14: EUR | D14: liste × 1,35 × 0,23 (ayar sahalı / açık tip şalterler %77). ⚠ XT3N TMD tipleri "ayar sahalı" sayılıyorsa MCCB satırlarında M sütunu ABB_ACB yapılmalı.
A15: CHINT | B15: 0.6 | C15: KZT | D15: %40 iskonto
A16: EKT | B16: 1 | C16: KZT | D16: Net fiyat
A17: KAZTEK | B17: 1 | C17: KZT | D17: Korpus — net fiyat
A18: SAYMAN | B18: 1 | C18: KZT | D18: Net fiyat
A20: 3. MONTAJ MALZEMESİ VE İŞÇİLİK ORANLARI
A21: Montaj malzemesi oranı (pano malzeme ara toplamı üzerinden) | B21: 0.03
A22: İşçilik birim fiyatı (KZT / dakika) | B22: 100
A23: Test / etiketleme / muayene çarpanı | B23: 1.15
A25: 4. İŞÇİLİK ZAMAN NORMLARI (Кол-во sütunu = DAKİKA)
A26: NORM | B26: DK/BİRİM | C26: ADET EMDP1 | D26: ADET UMDP1 | E26: DK EMDP1 | F26: DK UMDP1
A27: Korpus hazırlığı — zemin tipi | B27: 90 | C27: 1 | D27: 0 | E27: =B27*C27 -> 90 | F27: =B27*D27 -> 0
A28: Korpus hazırlığı — orta boy / duvar tipi | B28: 45 | C28: 0 | D28: 1 | E28: =B28*C28 -> 0 | F28: =B28*D28 -> 45
A29: Otomat 1P (MCB) | B29: 10 | C29: 40 | D29: 13 | E29: =B29*C29 -> 400 | F29: =B29*D29 -> 130
A30: Otomat 2P (MCB) | B30: 14 | C30: 2 | D30: 2 | E30: =B30*C30 -> 28 | F30: =B30*D30 -> 28
A31: Otomat 3P (MCB) | B31: 18 | C31: 3 | D31: 0 | E31: =B31*C31 -> 54 | F31: =B31*D31 -> 0
A32: Difavtomat 1P+N (RCBO) | B32: 12 | C32: 47 | D32: 0 | E32: =B32*C32 -> 564 | F32: =B32*D32 -> 0
A33: УЗО 2P (RCCB) | B33: 14 | C33: 2 | D33: 11 | E33: =B33*C33 -> 28 | F33: =B33*D33 -> 154
A34: УЗО 4P (RCCB) | B34: 20 | C34: 6 | D34: 0 | E34: =B34*C34 -> 120 | F34: =B34*D34 -> 0
A35: TMŞ (MCCB) ≤250A | B35: 60 | C35: 2 | D35: 0 | E35: =B35*C35 -> 120 | F35: =B35*D35 -> 0
A36: TMŞ aksesuarı (motor / bobin / RC modül) | B36: 30 | C36: 4 | D36: 0 | E36: =B36*C36 -> 120 | F36: =B36*D36 -> 0
A37: Motor koruma şalteri (MPCB) | B37: 25 | C37: 6 | D37: 0 | E37: =B37*C37 -> 150 | F37: =B37*D37 -> 0
A38: Yardımcı kontak bloğu | B38: 4 | C38: 12 | D38: 0 | E38: =B38*C38 -> 48 | F38: =B38*D38 -> 0
... A52: DIN ray / kablo kanalı (m) | B52: 5 | C52: 52 | D52: 12 | E52: =B52*C52 -> 260 | F52: =B52*D52 -> 60
A53: ARA TOPLAM (dk) | E53: =SUM(E27:E52) -> 4433 | F53: =SUM(F27:F52) -> 807
A54: TOPLAM İŞÇİLİK (dk) — çarpan dahil | E54: =ROUND(E53*KURALLAR!$B$23,0) -> 5098 | F54: =ROUND(F53*KURALLAR!$B$23,0) -> 928
A56: 5. FİYAT LİSTESİ YAŞ DENETİMİ (≤12 ay ✅ · 13-18 ay ⚠ · >18 ay ⛔ teklifte kullanılamaz)
A57: KAYNAK | B57: LİSTE TARİHİ | C57: YAŞ (ay) | D57: DURUM | E57: KULLANIM
A58: ABB Elektrifikasyon Fiyat Listesi | B58: 45962 | C58: =DATEDIF(B58,TODAY(),"m") -> 9 | D58: =IF(C58<=12,"✅ KULLAN",IF(C58<=18,"⚠ UYARILI","⛔ YASAK")) -> ✅ KULLAN | E58: Bu BOM da ana marka
...

Sheet BOM
A1: № | B1: Наименование1 | C1: Тип материала | D1: Артикул | E1: Номенклатура | F1: Цена (лист) | G1: Цена нетто, тг | H1: Сумма, тг | I1: Кол-во | J1: Ед.изм. | K1: Завод | L1: Валюта | M1: Коэф. | N1: Статус | O1: Примечание / KONTROL
A2: 1 | B2: ЩИТ EMDP1 — Freedom Lounge (TAV-FR-E-EAP-009-R000, схема 05.08.2026) | E2: ЩИТ EMDP1 — Freedom Lounge (TAV-FR-E-EAP-009-R000, схема 05.08.2026) | I2: 1 | J2: комплект | K2: TEKLED | N2: — | O2: Şema: Freedom_однолинейная_схема.pdf (05.08.2026), 1 s. — план однолинейной схемы низкого напряжения
A3: 101 | B3: =E2 -> ЩИТ EMDP1 — Freedom Lounge (TAV-FR-E-EAP-009-R000, схема 05.08.2026) | C3: корпус | D3: 710-15926 | E3: Металлический корпус напольный 1900x1200x500 (TEKSAN) | F3: 199245 | G3: =IF(OR($F3="",$M3=""),"",ROUND($F3*INDEX(KURALLAR!$B$13:$B$18,MATCH($M3,KURALLAR!$A$13:$A$18,0))*INDEX(KURALLAR!$B$6:$B$9,MATCH($L3,KURALLAR!$A$6:$A$9,0)),2)) -> 199245 | H3: =IF($G3="","",$G3*$I3) -> 199245 | I3: 1 | J3: шт | K3: KAZTEK | L3: KZT | M3: KAZTEK | N3: UYGUN | O3: Kaztek/TEKSAN onceligi. Modul ihtiyaci ~285 mod; 1900x1200 govde yeterli. Cokel/baza ayrica teyit edilmeli.
A4: 102 | B4: =E2 -> ЩИТ EMDP1 — Freedom Lounge (TAV-FR-E-EAP-009-R000, схема 05.08.2026) | C4: TMŞ | D4: 1SDA068070R1 | E4: XT3N 250, TMD, In=250A, InN=100%, 4p (175-250A, Ir=1) — ввод EMDP1 | F4: 798 | G4: =IF(OR($F4="",$M4=""),"",ROUND($F4*INDEX(KURALLAR!$B$13:$B$18,MATCH($M4,KURALLAR!$A$13:$A$18,0))*INDEX(KURALLAR!$B$6:$B$9,MATCH($L4,KURALLAR!$A$6:$A$9,0)),2)) -> 174522.6 | H4: =IF($G4="","",$G4*$I4) -> 174522.6 | I4: 1 | J4: шт | K4: ABB | L4: EUR | M4: ABB | N4: KONTROL | O4: Semada "ABB XT4N 250 TMD 250" yaziyor. ABB XT4 govdesinde TMD acma unitesi YOK; 175-250A TMD tam olarak XT3N 250 TMD 250 karsiligidir. 4 kutup secildi (ana kacak akim rolesi + TN-S). Teyit gerekli.
A5: 103 | B5: =E2 -> ЩИТ EMDP1 — Freedom Lounge (TAV-FR-E-EAP-009-R000, схема 05.08.2026) | C5: TMŞ aks. | D5: 1SDA067130R1 | E5: XT3, 4 полюса, RC Sel. тип A, 0,03…10A, 0,1…3с — реле дифф. защиты | F5: 1370 | G5: =IF(OR($F5="",$M5=""),"",ROUND($F5*INDEX(KURALLAR!$B$13:$B$18,MATCH($M5,KURALLAR!$A$13:$A$18,0))*INDEX(KURALLAR!$B$6:$B$9,MATCH($L5,KURALLAR!$A$6:$A$9,0)),2)) -> 299619 | H5: =IF($G5="","",$G5*$I5) -> 599238 | I5: 2 | J5: шт | K5: ABB | L5: EUR | M5: ABB | N5: KONTROL | O5: 1 ad. ana giris (semada "0,03-30A 0-5s F TYPE RCD" + toroidal trafo), 1 ad. ПВУ отопление ("SI TYPE RCD"). ABB RC Sel XT3 = tip A, 0,03-10A / 0,1-3s. Semadaki 0,03-30A / 0-5s ve F tipi ABB XT3 gaminda yok — teyit edilmeli.
A6: 104 | B6: =E2 -> ЩИТ EMDP1 — Freedom Lounge (TAV-FR-E-EAP-009-R000, схема 05.08.2026) | C6: TMŞ aks. | D6: 1SDA066460R1 | E6: XT1, XT3 MOD моторный привод 220…250 V AC/DC | F6: 675.1 | G6: =IF(OR($F6="",$M6=""),"",ROUND($F6*INDEX(KURALLAR!$B$13:$B$18,MATCH($M6,KURALLAR!$A$13:$A$18,0))*INDEX(KURALLAR!$B$6:$B$9,MATCH($L6,KURALLAR!$A$6:$A$9,0)),2)) -> 147644.37 | H6: =IF($G6="","",$G6*$I6) -> 147644.37 | I6: 1 | J6: шт | K6: ABB | L6: EUR | M6: ABB | N6: UYGUN | O6: Semada ana salter uzerinde motor sembolu (M).
A7: 105 | B7: =E2 -> ЩИТ EMDP1 — Freedom Lounge (TAV-FR-E-EAP-009-R000, схема 05.08.2026) | C7: TMŞ aks. | D7: 1SDA066325R1 | E7: XT1…XT4 SOR-C 220-240V AC/220-250V DC — независимый расцепитель (TRIP COIL) | F7: 115.1 | G7: =IF(OR($F7="",$M7=""),"",ROUND($F7*INDEX(KURALLAR!$B$13:$B$18,MATCH($M7,KURALLAR!$A$13:$A$18,0))*INDEX(KURALLAR!$B$6:$B$9,MATCH($L7,KURALLAR!$A$6:$A$9,0)),2)) -> 25172.37 | H7: =IF($G7="","",$G7*$I7) -> 25172.37 | I7: 1 | J7: шт | K7: ABB | L7: EUR | M7: ABB | N7: UYGUN | O7: Semada TRIP COIL; E.B. acil kesme butonu ile tetiklenir.
A8: 106 | B8: =E2 -> ЩИТ EMDP1 — Freedom Lounge (TAV-FR-E-EAP-009-R000, схема 05.08.2026) | C8: TMŞ | D8: 1SDA068069R1 | E8: XT3N 250, TMD, In=200A, InN=100%, 4p (140-200A) — ПВУ отопление | F8: 798 | G8: =IF(OR($F8="",$M8=""),"",ROUND($F8*INDEX(KURALLAR!$B$13:$B$18,MATCH($M8,KURALLAR!$A$13:$A$18,0))*INDEX(KURALLAR!$B$6:$B$9,MATCH($L8,KURALLAR!$A$6:$A$9,0)),2)) -> 174522.6 | H8: =IF($G8="","",$G8*$I8) -> 174522.6 | I8: 1 | J8: шт | K8: ABB | L8: EUR | M8: ABB | N8: KONTROL | O8: Semada ayni kolonda hem "(MPCB) 140-200A 100kA" hem "ABB XT3N 200 TMD 200" var; ayni fonksiyon kabul edilip TEK cihaz alindi. XT3N Icu=36kA — semada istenen 100kA saglanmiyor, teyit gerekli.
A9: 107 | B9: =E2 -> ЩИТ EMDP1 — Freedom Lounge (TAV-FR-E-EAP-009-R000, схема 05.08.2026) | C9: ОТО | D9: 2CDS251001R0105 | E9: S201-B10, 1P, 10A, кривая B, 6kA — 1x10A NB | F9: 9.78 | G9: =IF(OR($F9="",$M9=""),"",ROUND($F9*INDEX(KURALLAR!$B$13:$B$18,MATCH($M9,KURALLAR!$A$13:$A$18,0))*INDEX(KURALLAR!$B$6:$B$9,MATCH($L9,KURALLAR!$A$6:$A$9,0)),2)) -> 2138.89 | H9: =IF($G9="","",$G9*$I9) -> 79138.93 | I9: 37 | J9: шт | K9: ABB | L9: EUR | M9: ABB | N9: DÜZELTİLDİ | O9: Sema sayimi: KNX bolumu 8 ad. (gr.01, 02 + 6 numarasiz) + aydinlatma 29 ad. (gr.03-31) = 37. Onceki BOM 31 idi.
A10: 108 | B10: =E2 -> ЩИТ EMDP1 — Freedom Lounge (TAV-FR-E-EAP-009-R000, схема 05.08.2026) | C10: ОТО | D10: 2CDS253001R0254 | E10: S203-C25, 3P, 25A, кривая C, 6kA — 3x25A NC | F10: 48.51 | G10: =IF(OR($F10="",$M10=""),"",ROUND($F10*INDEX(KURALLAR!$B$13:$B$18,MATCH($M10,KURALLAR!$A$13:$A$18,0))*INDEX(KURALLAR!$B$6:$B$9,MATCH($L10,KURALLAR!$A$6:$A$9,0)),2)) -> 10609.14 | H10: =IF($G10="","",$G10*$I10) -> 21218.28 | I10: 2 | J10: шт | K10: ABB | L10: EUR | M10: ABB | N10: UYGUN | O10: 1 ad. aydinlatma sekmesi beslemesi, 1 ad. mekanik bara (gr.81-85) beslemesi.
A11: 109 | B11: =E2 -> ЩИТ EMDP1 — Freedom Lounge (TAV-FR-E-EAP-009-R000, схема 05.08.2026) | C11: ОТО | D11: 2CDS253001R0164 | E11: S203-C16, 3P, 16A, кривая C, 6kA — 3x16A NC (гр.32) | F11: 48.51 | G11: =IF(OR($F11="",$M11=""),"",ROUND($F11*INDEX(KURALLAR!$B$13:$B$18,MATCH($M11,KURALLAR!$A$13:$A$18,0))*INDEX(KURALLAR!$B$6:$B$9,MATCH($L11,KURALLAR!$A$6:$A$9,0)),2)) -> 10609.14 | H11: =IF($G11="","",$G11*$I11) -> 10609.14 | I11: 1 | J11: шт | K11: ABB | L11: EUR | M11: ABB | N11: KONTROL | O11: Gr.32 (Розетка для витрины) kolonunda hem 3x16A NC hem 4xC25A 30mA УЗО типа А etiketi var; diger 47 priz devresi tekil difavtomat. Uc fazli ozel vitrin beslemesi mi, kopyala-yapistir artigi mi — teyit edilmeli.
A12: 110 | B12: =E2 -> ЩИТ EMDP1 — Freedom Lounge (TAV-FR-E-EAP-009-R000, схема 05.08.2026) | C12: ОТО | D12: 2CDS251001R0065 | E12: S201-B6, 1P, 6A, кривая B, 6kA — 3(1x6A) B TYPE, цепь напряжения анализатора | F12: 11.74 | G12: =IF(OR($F12="",$M12=""),"",ROUND($F12*INDEX(KURALLAR!$B$13:$B$18,MATCH($M12,KURALLAR!$A$13:$A$18,0))*INDEX(KURALLAR!$B$6:$B$9,MATCH($L12,KURALLAR!$A$6:$A$9,0)),2)) -> 2567.54 | H12: =IF($G12="","",$G12*$I12) -> 7702.62 | I12: 3 | J12: шт | K12: ABB | L12: EUR | M12: ABB | N12: UYGUN | O12: Semada CVM-C10 gerilim devresi korumasi: 3(1x6A) (B TYPE).
A13: 111 | B13: =E2 -> ЩИТ EMDP1 — Freedom Lounge (TAV-FR-E-EAP-009-R000, схема 05.08.2026) | C13: ДИФ | D13: 2CSR255080R1164 | E13: DS201 C16 AC30, 1P+N, 16A, 30mA — C16A 30mA дифавтомат | F13: 87.63 | G13: =IF(OR($F13="",$M13=""),"",ROUND($F13*INDEX(KURALLAR!$B$13:$B$18,MATCH($M13,KURALLAR!$A$13:$A$18,0))*INDEX(KURALLAR!$B$6:$B$9,MATCH($L13,KURALLAR!$A$6:$A$9,0)),2)) -> 19164.68 | H13: =IF($G13="","",$G13*$I13) -> 824081.24 | I13: 43 | J13: шт | K13: ABB | L13: EUR | M13: ABB | N13: DÜZELTİLDİ | O13: Gr.33-79 arasi C16 difavtomat sayimi = 43 (gr.48,49,50,53 C25; gr.32 ayri). Onceki BOM 44 idi. DIKKAT: ABB TR listesinde DS201 sadece AC tipi var; RK sartlari ve semanin УЗО типа А tercihi ile tip A DS201 teyit edilmeli.
A14: 112 | B14: =E2 -> ЩИТ EMDP1 — Freedom Lounge (TAV-FR-E-EAP-009-R000, схема 05.08.2026) | C14: ДИФ | D14: 2CSR255080R1254 | E14: DS201 C25 AC30, 1P+N, 25A, 30mA — C25A 30mA дифавтомат | F14: 87.63 | G14: =IF(OR($F14="",$M14=""),"",ROUND($F14*INDEX(KURALLAR!$B$13:$B$18,MATCH($M14,KURALLAR!$A$13:$A$18,0))*INDEX(KURALLAR!$B$6:$B$9,MATCH($L14,KURALLAR!$A$6:$A$9,0)),2)) -> 19164.68 | H14: =IF($G14="","",$G14*$I14) -> 76658.72 | I14: 4 | J14: шт | K14: ABB | L14: EUR | M14: ABB | N14: UYGUN | O14: Gr.48 (индукционная плита), гр.49 (микроволновая печь), гр.50 (холодильный шкаф), гр.53 (сервисные розетки). Tip A teyidi gerekli.
A15: 113 | B15: =E2 -> ЩИТ EMDP1 — Freedom Lounge (TAV-FR-E-EAP-009-R000, схема 05.08.2026) | C15: ККР | D15: 2CSF204401R1250 | E15: F204 A-25/0.03 AP-R, 4P, 25A, 30mA, тип A (супериммунный) — 4xC25A 30mA УЗО типа А | F15: 168 | G15: =IF(OR($F15="",$M15=""),"",ROUND($F15*INDEX(KURALLAR!$B$13:$B$18,MATCH($M15,KURALLAR!$A$13:$A$18,0))*INDEX(KURALLAR!$B$6:$B$9,MATCH($L15,KURALLAR!$A$6:$A$9,0)),2)) -> 36741.6 | H15: =IF($G15="","",$G15*$I15) -> 220449.6 | I15: 6 | J15: шт | K15: ABB | L15: EUR | M15: ABB | N15: DÜZELTİLDİ | O15: 3 ad. aydinlatma sekmeleri + 1 ad. gr.32 + 1 ad. mekanik bara (гр.81-85) + 1 ad. гр.80 Оборудование ПВУ ("SI TYPE RCD"). ABB TR listesinde 30mA tip A yalnizca AP-R serisinde var — bu ayni zamanda semanin SI TYPE talebini karsilar.
A16: 114 | B16: =E2 -> ЩИТ EMDP1 — Freedom Lounge (TAV-FR-E-EAP-009-R000, схема 05.08.2026) | C16: ККР | D16: 2CSF202401R1250 | E16: F202 A-25/0.03 AP-R, 2P, 25A, 30mA, тип A — 2xC25A / 2xC16A 30mA УЗО типа А | F16: 129.2 | G16: =IF(OR($F16="",$M16=""),"",ROUND($F16*INDEX(KURALLAR!$B$13:$B$18,MATCH($M16,KURALLAR!$A$13:$A$18,0))*INDEX(KURALLAR!$B$6:$B$9,MATCH($L16,KURALLAR!$A$6:$A$9,0)),2)) -> 28256.04 | H16: =IF($G16="","",$G16*$I16) -> 56512.08 | I16: 2 | J16: шт | K16: ABB | L16: EUR | M16: ABB | N16: KONTROL | O16: KNX bolumu beslemesi: 1 ad. 2xC16A 30mA + 1 ad. 2xC25A 30mA. ABB F202 tip A minimum In=25A oldugu icin 16A devrede de 25A kullanildi.
A17: 115 | B17: =E2 -> ЩИТ EMDP1 — Freedom Lounge (TAV-FR-E-EAP-009-R000, схема 05.08.2026) | C17: МКС | D17: 1SAM350000R1010 | E17: MS132-10 (6,3-10A), Icu 100kA — мотор-автомат | F17: 78.51 | G17: =IF(OR($F17="",$M17=""),"",ROUND($F17*INDEX(KURALLAR!$B$13:$B$18,MATCH($M17,KURALLAR!$A$13:$A$18,0))*INDEX(KURALLAR!$B$6:$B$9,MATCH($L17,KURALLAR!$A$6:$A$9,0)),2)) -> 17170.14 | H17: =IF($G17="","",$G17*$I17) -> 17170.14 | I17: 1 | J17: шт | K17: ABB | L17: EUR | M17: ABB | N17: DÜZELTİLDİ | O17: Гр.80 Оборудование ПВУ (semada 6-10A 100kA). MS116 yerine MS132 secildi: 100kA sarti yalnizca MS132 ile saglanir.
A18: 116 | B18: =E2 -> ЩИТ EMDP1 — Freedom Lounge (TAV-FR-E-EAP-009-R000, схема 05.08.2026) | C18: МКС | D18: 1SAM350000R1012 | E18: MS132-12 (8-12A), Icu 100kA — мотор-автомат | F18: 86.99 | G18: =IF(OR($F18="",$M18=""),"",ROUND($F18*INDEX(KURALLAR!$B$13:$B$18,MATCH($M18,KURALLAR!$A$13:$A$18,0))*INDEX(KURALLAR!$B$6:$B$9,MATCH($L18,KURALLAR!$A$6:$A$9,0)),2)) -> 19024.71 | H18: =IF($G18="","",$G18*$I18) -> 38049.42 | I18: 2 | J18: шт | K18: ABB | L18: EUR | M18: ABB | N18: KONTROL | O18: Гр.81 Эл. водонагреватель + гр.84 Резерв механики-2 (semada 9-13A). MS132 kademeleri 8-12A ve 10-16A; 9-13A tam karsiligi yok.
A19: 117 | B19: =E2 -> ЩИТ EMDP1 — Freedom Lounge (TAV-FR-E-EAP-009-R000, схема 05.08.2026) | C19: МКС | D19: 1SAM350000R1011 | E19: MS132-16 (10-16A), Icu 100kA — мотор-автомат | F19: 86.99 | G19: =IF(OR($F19="",$M19=""),"",ROUND($F19*INDEX(KURALLAR!$B$13:$B$18,MATCH($M19,KURALLAR!$A$13:$A$18,0))*INDEX(KURALLAR!$B$6:$B$9,MATCH($L19,KURALLAR!$A$6:$A$9,0)),2)) -> 19024.71 | H19: =IF($G19="","",$G19*$I19) -> 19024.71 | I19: 1 | J19: шт | K19: ABB | L19: EUR | M19: ABB | N19: UYGUN | O19: Гр.83 Резерв механики-1 (semada 10-16A).
A20: 118 | B20: =E2 -> ЩИТ EMDP1 — Freedom Lounge (TAV-FR-E-EAP-009-R000, схема 05.08.2026) | C20: МКС | D20: 1SAM350000R1004 | E20: MS132-0.63 (0,4-0,63A), Icu 100kA — мотор-автомат | F20: 71.65 | G20: =IF(OR($F20="",$M20=""),"",ROUND($F20*INDEX(KURALLAR!$B$13:$B$18,MATCH($M20,KURALLAR!$A$13:$A$18,0))*INDEX(KURALLAR!$B$6:$B$9,MATCH($L20,KURALLAR!$A$6:$A$9,0)),2)) -> 15669.86 | H20: =IF($G20="","",$G20*$I20) -> 31339.72 | I20: 2 | J20: шт | K20: ABB | L20: EUR | M20: ABB | N20: UYGUN | O20: Гр.82 Выт. вент. с/у + гр.85 Резерв механики-3.
A21: 119 | B21: =E2 -> ЩИТ EMDP1 — Freedom Lounge (TAV-FR-E-EAP-009-R000, схема 05.08.2026) | C21: БЛОК | D21: 1SAM201902R1001 | E21: HK1-11 доп. контакт 1НО+1НЗ для MS132 | F21: 10.89 | G21: =IF(OR($F21="",$M21=""),"",ROUND($F21*INDEX(KURALLAR!$B$13:$B$18,MATCH($M21,KURALLAR!$A$13:$A$18,0))*INDEX(KURALLAR!$B$6:$B$9,MATCH($L21,KURALLAR!$A$6:$A$9,0)),2)) -> 2381.64 | H21: =IF($G21="","",$G21*$I21) -> 14289.84 | I21: 6 | J21: шт | K21: ABB | L21: EUR | M21: ABB | N21: UYGUN | O21: Her mekanik cikis icin 1 ad. (6 ad. MPCB).
A22: 120 | B22: =E2 -> ЩИТ EMDP1 — Freedom Lounge (TAV-FR-E-EAP-009-R000, схема 05.08.2026) | C22: КОНТАКТОР | D22: 1SFL527002R1311 | E22: AF205-30-11, 205A AC-3, 3P, кат. 100-250V AC/DC — 3x200A ПВУ отопление | F22: 906.6 | G22: =IF(OR($F22="",$M22=""),"",ROUND($F22*INDEX(KURALLAR!$B$13:$B$18,MATCH($M22,KURALLAR!$A$13:$A$18,0))*INDEX(KURALLAR!$B$6:$B$9,MATCH($L22,KURALLAR!$A$6:$A$9,0)),2)) -> 198273.42 | H22: =IF($G22="","",$G22*$I22) -> 198273.42 | I22: 1 | J22: шт | K22: ABB | L22: EUR | M22: ABB | N22: KONTROL | O22: Semada -C2 3x200A. AC-3/AC-1 kullanim kategorisi ve gercek yuk akimi (isitici = AC-1) teyit edilirse daha kucuk govde yeterli olabilir.
A23: 121 | B23: =E2 -> ЩИТ EMDP1 — Freedom Lounge (TAV-FR-E-EAP-009-R000, схема 05.08.2026) | C23: КОНТАКТОР | D23: 1SBL237001R1300 | E23: AF26-30-00, 26A AC-3, 3P — 3x25A Оборудование ПВУ | F23: 59.16 | G23: =IF(OR($F23="",$M23=""),"",ROUND($F23*INDEX(KURALLAR!$B$13:$B$18,MATCH($M23,KURALLAR!$A$13:$A$18,0))*INDEX(KURALLAR!$B$6:$B$9,MATCH($L23,KURALLAR!$A$6:$A$9,0)),2)) -> 12938.29 | H23: =IF($G23="","",$G23*$I23) -> 12938.29 | I23: 1 | J23: шт | K23: ABB | L23: EUR | M23: ABB | N23: UYGUN | O23: Semada -C1 3x25A.
A24: 122 | B24: =E2 -> ЩИТ EMDP1 — Freedom Lounge (TAV-FR-E-EAP-009-R000, схема 05.08.2026) | C24: КОНТАКТОР | D24: 1SBL177001R1310 | E24: AF16-30-10, 18A AC-3, 3P — 3x16A | F24: 46.39 | G24: =IF(OR($F24="",$M24=""),"",ROUND($F24*INDEX(KURALLAR!$B$13:$B$18,MATCH($M24,KURALLAR!$A$13:$A$18,0))*INDEX(KURALLAR!$B$6:$B$9,MATCH($L24,KURALLAR!$A$6:$A$9,0)),2)) -> 10145.49 | H24: =IF($G24="","",$G24*$I24) -> 40581.96 | I24: 4 | J24: шт | K24: ABB | L24: EUR | M24: ABB | N24: DÜZELTİLDİ | O24: Эл. водонагреватель, Выт. вент. с/у, Резерв механики-1, Резерв механики-2.
A25: 123 | B25: =E2 -> ЩИТ EMDP1 — Freedom Lounge (TAV-FR-E-EAP-009-R000, схема 05.08.2026) | C25: КОНТАКТОР | D25: 1SBL137001R1310 | E25: AF09-30-10, 9A AC-3, 3P — 3x9A Резерв механики-3 | F25: 37.91 | G25: =IF(OR($F25="",$M25=""),"",ROUND($F25*INDEX(KURALLAR!$B$13:$B$18,MATCH($M25,KURALLAR!$A$13:$A$18,0))*INDEX(KURALLAR!$B$6:$B$9,MATCH($L25,KURALLAR!$A$6:$A$9,0)),2)) -> 8290.92 | H25: =IF($G25="","",$G25*$I25) -> 8290.92 | I25: 1 | J25: шт | K25: ABB | L25: EUR | M25: ABB | N25: UYGUN | O25: Semada -C6 3x9A.
A26: 124 | B26: =E2 -> ЩИТ EMDP1 — Freedom Lounge (TAV-FR-E-EAP-009-R000, схема 05.08.2026) | C26: БЛОК | D26: 1SBN010140R1122 | E26: CA4-22M доп. контактный блок 2НО+2НЗ (AF09…AF16) | F26: 22.58 | G26: =IF(OR($F26="",$M26=""),"",ROUND($F26*INDEX(KURALLAR!$B$13:$B$18,MATCH($M26,KURALLAR!$A$13:$A$18,0))*INDEX(KURALLAR!$B$6:$B$9,MATCH($L26,KURALLAR!$A$6:$A$9,0)),2)) -> 4938.25 | H26: =IF($G26="","",$G26*$I26) -> 29629.5 | I26: 6 | J26: шт | K26: ABB | L26: EUR | M26: ABB | N26: UYGUN | O26: 1-0-2 secici + sinyal lambasi kumanda devresi icin.
A27: 125 | B27: =E2 -> ЩИТ EMDP1 — Freedom Lounge (TAV-FR-E-EAP-009-R000, схема 05.08.2026) | C27: ОТО | D27: 2CDS252001R0404 | E27: S202-C40, 2P, 40A, кривая C, 6kA — 2x40A NC (K01, K02) | F27: 49.01 | G27: =IF(OR($F27="",$M27=""),"",ROUND($F27*INDEX(KURALLAR!$B$13:$B$18,MATCH($M27,KURALLAR!$A$13:$A$18,0))*INDEX(KURALLAR!$B$6:$B$9,MATCH($L27,KURALLAR!$A$6:$A$9,0)),2)) -> 10718.49 | H27: =IF($G27="","",$G27*$I27) -> 21436.98 | I27: 2 | J27: шт | K27: ABB | L27: EUR | M27: ABB | N27: UYGUN | O27: EMDP1 barasindan ИБП beslemesi (EMDP1-K01/UPS-1) ve K02.
A28: 126 | B28: =E2 -> ЩИТ EMDP1 — Freedom Lounge (TAV-FR-E-EAP-009-R000, схема 05.08.2026) | C28: МАНДАЛ БУТОН | D28: 1SFA619210R1026 | E28: C3SS1-10B-20 переключатель 1-0-2, 2НО, чёрный | F28: 13.13 | G28: =IF(OR($F28="",$M28=""),"",ROUND($F28*INDEX(KURALLAR!$B$13:$B$18,MATCH($M28,KURALLAR!$A$13:$A$18,0))*INDEX(KURALLAR!$B$6:$B$9,MATCH($L28,KURALLAR!$A$6:$A$9,0)),2)) -> 2871.53 | H28: =IF($G28="","",$G28*$I28) -> 20100.71 | I28: 7 | J28: шт | K28: ABB | L28: EUR | M28: ABB | N28: DÜZELTİLDİ | O28: Semada 7 ad. 1-0-2 secici (-PC01 iki kez etiketlenmis, -PC02…-PC06). Onceki BOM 6 idi.
A29: 127 | B29: =E2 -> ЩИТ EMDP1 — Freedom Lounge (TAV-FR-E-EAP-009-R000, схема 05.08.2026) | C29: СИГН. ЛАМПА | D29: 1SFA619403R5232 | E29: CL2-523G сигнальная лампа с LED, 230V AC, зелёная — "Автоматика" | F29: 9.62 | G29: =IF(OR($F29="",$M29=""),"",ROUND($F29*INDEX(KURALLAR!$B$13:$B$18,MATCH($M29,KURALLAR!$A$13:$A$18,0))*INDEX(KURALLAR!$B$6:$B$9,MATCH($L29,KURALLAR!$A$6:$A$9,0)),2)) -> 2103.89 | H29: =IF($G29="","",$G29*$I29) -> 14727.23 | I29: 7 | J29: шт | K29: ABB | L29: EUR | M29: ABB | N29: DÜZELTİLDİ | O29: Her mekanik cikista 3 lamba (Выкл/Автоматика/Ручной режим) x 7 cikis.
A30: 128 | B30: =E2 -> ЩИТ EMDP1 — Freedom Lounge (TAV-FR-E-EAP-009-R000, схема 05.08.2026) | C30: СИГН. ЛАМПА | D30: 1SFA619403R5233 | E30: CL2-523Y сигнальная лампа с LED, 230V AC, жёлтая — "Ручной режим" | F30: 9.62 | G30: =IF(OR($F30="",$M30=""),"",ROUND($F30*INDEX(KURALLAR!$B$13:$B$18,MATCH($M30,KURALLAR!$A$13:$A$18,0))*INDEX(KURALLAR!$B$6:$B$9,MATCH($L30,KURALLAR!$A$6:$A$9,0)),2)) -> 2103.89 | H30: =IF($G30="","",$G30*$I30) -> 14727.23 | I30: 7 | J30: шт | K30: ABB | L30: EUR | M30: ABB | N30: DÜZELTİLDİ
A31: 129 | B31: =E2 -> ЩИТ EMDP1 — Freedom Lounge (TAV-FR-E-EAP-009-R000, схема 05.08.2026) | C31: СИГН. ЛАМПА | D31: 1SFA619403R5231 | E31: CL2-523R сигнальная лампа с LED, 230V AC, красная — "Выкл" | F31: 9.62 | G31: =IF(OR($F31="",$M31=""),"",ROUND($F31*INDEX(KURALLAR!$B$13:$B$18,MATCH($M31,KURALLAR!$A$13:$A$18,0))*INDEX(KURALLAR!$B$6:$B$9,MATCH($L31,KURALLAR!$A$6:$A$9,0)),2)) -> 2103.89 | H31: =IF($G31="","",$G31*$I31) -> 14727.23 | I31: 7 | J31: шт | K31: ABB | L31: EUR | M31: ABB | N31: DÜZELTİLDİ
A32: 130 | B32: =E2 -> ЩИТ EMDP1 — Freedom Lounge (TAV-FR-E-EAP-009-R000, схема 05.08.2026) | C32: ОПН | D32: 2CTB812111R2300 | E32: OVR T1-T2 3N 100-255 P TS — ОПН B+C класс, 3F+N+PE | F32: 1197 | G32: =IF(OR($F32="",$M32=""),"",ROUND($F32*INDEX(KURALLAR!$B$13:$B$18,MATCH($M32,KURALLAR!$A$13:$A$18,0))*INDEX(KURALLAR!$B$6:$B$9,MATCH($L32,KURALLAR!$A$6:$A$9,0)),2)) -> 261783.9 | H32: =IF($G32="","",$G32*$I32) -> 261783.9 | I32: 1 | J32: шт | K32: ABB | L32: EUR | M32: ABB | N32: KONTROL | O32: Semada 4x50 kA / 4x100 kA. OVR T1-T2 3N 100-255: Iimp 25kA/kutup, Itotal 100kA. Iimp 50kA/kutup isteniyorsa urun degismelidir.
A33: 131 | B33: =E2 -> ЩИТ EMDP1 — Freedom Lounge (TAV-FR-E-EAP-009-R000, схема 05.08.2026) | C33: РУБИЛЬНИК | D33: 1SEP600116R0002 | E33: XLP1-1P-2BC разъединитель-предохранитель 1P, NH1, 250A | F33: 155.6 | G33: =IF(OR($F33="",$M33=""),"",ROUND($F33*INDEX(KURALLAR!$B$13:$B$18,MATCH($M33,KURALLAR!$A$13:$A$18,0))*INDEX(KURALLAR!$B$6:$B$9,MATCH($L33,KURALLAR!$A$6:$A$9,0)),2)) -> 34029.72 | H33: =IF($G33="","",$G33*$I33) -> 102089.16 | I33: 3 | J33: шт | K33: ABB | L33: EUR | M33: ABB | N33: DÜZELTİLDİ | O33: Semada "3 шт (1x250) A NH" — ОПН on koruma. Onceki BOM XLP00 + 125A idi.
A34: 132 | B34: =E2 -> ЩИТ EMDP1 — Freedom Lounge (TAV-FR-E-EAP-009-R000, схема 05.08.2026) | C34: ФУ | D34: 1SCA022627R4650 | E34: OFAF1H250 предохранитель NH1 250A gG | F34: 18.11 | G34: =IF(OR($F34="",$M34=""),"",ROUND($F34*INDEX(KURALLAR!$B$13:$B$18,MATCH($M34,KURALLAR!$A$13:$A$18,0))*INDEX(KURALLAR!$B$6:$B$9,MATCH($L34,KURALLAR!$A$6:$A$9,0)),2)) -> 3960.66 | H34: =IF($G34="","",$G34*$I34) -> 11881.98 | I34: 3 | J34: шт | K34: ABB | L34: EUR | M34: ABB | N34: DÜZELTİLDİ | O34: Onceki BOM 125A idi; semada 250A.
A35: 133 | B35: =E2 -> ЩИТ EMDP1 — Freedom Lounge (TAV-FR-E-EAP-009-R000, схема 05.08.2026) | C35: САЯЧ | D35: ND | E35: Дала СА4У-Э720 (3x220/380V, 5-7,5A) — трёхфазный счётчик трансформаторного включения x/5A | F35: 19000 | G35: =IF(OR($F35="",$M35=""),"",ROUND($F35*INDEX(KURALLAR!$B$13:$B$18,MATCH($M35,KURALLAR!$A$13:$A$18,0))*INDEX(KURALLAR!$B$6:$B$9,MATCH($L35,KURALLAR!$A$6:$A$9,0)),2)) -> 19000 | H35: =IF($G35="","",$G35*$I35) -> 19000 | I35: 1 | J35: шт | K35: SAYMAN | L35: KZT | M35: SAYMAN | N35: KONTROL | O35: Sema: "Трехфазный счетчик электроэнергии X/5A", muhurlu bolmede, RK normlarina uygun olmali. Kesin model ve АСКУЭ (RS/GPRS) modul talebi elektrik dagitim sirketiyle teyit edilmeli.
A36: 134 | B36: =E2 -> ЩИТ EMDP1 — Freedom Lounge (TAV-FR-E-EAP-009-R000, схема 05.08.2026) | C36: ТТ | D36: VJ | E36: Трансформатор тока ТШП-0,66 У3, кл. точн. 0,5, 250/5A | F36: 4000 | G36: =IF(OR($F36="",$M36=""),"",ROUND($F36*INDEX(KURALLAR!$B$13:$B$18,MATCH($M36,KURALLAR!$A$13:$A$18,0))*INDEX(KURALLAR!$B$6:$B$9,MATCH($L36,KURALLAR!$A$6:$A$9,0)),2)) -> 4000 | H36: =IF($G36="","",$G36*$I36) -> 24000 | I36: 6 | J36: шт | K36: SAYMAN | L36: KZT | M36: SAYMAN | N36: DÜZELTİLDİ | O36: Semada iki ayri 3 faz olcum seti: sayac (muhurlu bolme) + CVM-C10 analizoru; her biri 250/5A CLASS-0,5 5VA. Onceki BOM 75/5A idi.
A37: 135 | B37: =E2 -> ЩИТ EMDP1 — Freedom Lounge (TAV-FR-E-EAP-009-R000, схема 05.08.2026) | C37: АНАЛИЗАТОР | E37: CVM-C10 CIRCUTOR — анализатор качества эл. энергии, x/5A-400/231V | G37: =IF(OR($F37="",$M37=""),"",ROUND($F37*INDEX(KURALLAR!$B$13:$B$18,MATCH($M37,KURALLAR!$A$13:$A$18,0))*INDEX(KURALLAR!$B$6:$B$9,MATCH($L37,KURALLAR!$A$6:$A$9,0)),2)) | H37: =IF($G37="","",$G37*$I37) | I37: 1 | J37: шт | K37: CIRCUTOR | L37: KZT | N37: KONTROL | O37: Semada acikca CVM-C10 CIRCUTOR yaziyor. Bu marka fiyat listelerimizde yok — tedarikci teklifi alinmali. Fiyat bos birakildi, toplama dahil DEGIL.
A38: 136 | B38: =E2 -> ЩИТ EMDP1 — Freedom Lounge (TAV-FR-E-EAP-009-R000, схема 05.08.2026) | C38: БУТОН | D38: 1SFA184071R9001 | E38: P9MER4RN грибовидная кнопка ∅40 мм, красная, фиксируемая (E.B. — EMERGENCY POWER CUT-OFF) | F38: 22.27 | G38: =IF(OR($F38="",$M38=""),"",ROUND($F38*INDEX(KURALLAR!$B$13:$B$18,MATCH($M38,KURALLAR!$A$13:$A$18,0))*INDEX(KURALLAR!$B$6:$B$9,MATCH($L38,KURALLAR!$A$6:$A$9,0)),2)) -> 4870.45 | H38: =IF($G38="","",$G38*$I38) -> 4870.45 | I38: 1 | J38: шт | K38: ABB | L38: EUR | M38: ABB | N38: KONTROL | O38: Semada pano DISINDA, 4mm² 2 damarli kablo ile TRIP COIL devresine bagli. Kapsam (pano ustu mu, saha montaji mi) ve kutu/etiket ihtiyaci teyit edilmeli.
A39: 137 | B39: =E2 -> ЩИТ EMDP1 — Freedom Lounge (TAV-FR-E-EAP-009-R000, схема 05.08.2026) | C39: ГУЧ КАЙНАГЫ | D39: MDR-60-12 | E39: MEAN WELL MDR-60-12, источник питания 12VDC / 5A (PS1) | G39: =IF(OR($F39="",$M39=""),"",ROUND($F39*INDEX(KURALLAR!$B$13:$B$18,MATCH($M39,KURALLAR!$A$13:$A$18,0))*INDEX(KURALLAR!$B$6:$B$9,MATCH($L39,KURALLAR!$A$6:$A$9,0)),2)) | H39: =IF($G39="","",$G39*$I39) | I39: 1 | J39: шт | K39: MEAN WELL | L39: KZT | N39: KONTROL | O39: Semada PS1. KNX degildir — TEKLED kapsamindadir. Fiyat listelerimizde yok, tedarikci fiyati girilmeli.
A40: 138 | B40: =E2 -> ЩИТ EMDP1 — Freedom Lounge (TAV-FR-E-EAP-009-R000, схема 05.08.2026) | C40: KNX | E40: 20-канальный модуль включения/отключения (KNX) | G40: =IF(OR($F40="",$M40=""),"",ROUND($F40*INDEX(KURALLAR!$B$13:$B$18,MATCH($M40,KURALLAR!$A$13:$A$18,0))*INDEX(KURALLAR!$B$6:$B$9,MATCH($L40,KURALLAR!$A$6:$A$9,0)),2)) | H40: =IF($G40="","",$G40*$I40) | I40: 1 | J40: шт | K40: MÜŞTERİ ТЕМИНИ | L40: KZT | N40: MÜŞTERİ TEMİNİ | O40: Semada aydinlatma bolumu ustunde "20-канальный модуль включения/отключения". Malzeme bedeli teklif disi; pano ici yer + montaj bize ait.
...

Sheet СВОД
A1: СВОД — Freedom Lounge, Международный аэропорт г. Алматы, Терминал Т2
A2: ТОО "Germes Limited Company" · TAV-FR-E-EAP-009-R000 · схема 05.08.2026
A4: № | B4: Наименование щита | C4: Кол-во компл. | D4: Цена за компл., тг | E4: Сумма, тг
A5: 1 | B5: ЩИТ EMDP1 — Freedom Lounge (TAV-FR-E-EAP-009-R000, схема 05.08.2026) | C5: 1 | D5: =BOM!$H$61 -> 1537381.6 | E5: =$C5*$D5 -> 1537381.6
A6: 2 | B6: ЩИТ UMDP1 — Freedom Lounge (ИБП 6 kVA) | C6: 1 | D6: =BOM!$H$81 -> 394913.09 | E6: =$C6*$D6 -> 394913.09
B7: ОБЩИЙ ИТОГ | E7: =SUM($E$5:$E$6) -> 1932294.7
A9: ⚠ Fiyatı boş bırakılan kalemler (CVM-C10 analizör, UMDP1 analizörü, ИБП 6 kVA, MEAN WELL MDR-60-12, bakır ana bara) toplama DAHİL DEĞİLDİR.
A10: ⚠ KNX malzemeleri müşteri teminidir — malzeme bedeli teklif dışıdır, montaj işçiliği dahildir.
A11: ⚠ Tüm KONTROL maddeleri KURALLAR sayfası bölüm 7 dedir. Teklif öncesi bu liste kapatılmalıdır.
