Workbook

Sheet BOM
A1: YSF HICH — BOM — Atırau 250 kişilik okul ek bina (24-2024-ЭЛ) — CHINT apparat + TEKSAN korpus
A2: CHINT net kat. (liste ×): | B2: 0.6
A3: Montaj malzeme % (düzenle): | B3: 0.03
A4: Montaj işçilik % (düzenle): | B4: 0.05
A5: TEKSAN net kat. (iskonto teyit): | B5: 1
A6: № | B6: Наименование | C6: Тип | D6: Артикул | E6: Номенклатура | F6: Цена (лист) | G6: Нетто KZT | H6: Сумма KZT | I6: Кол-во | J6: Ед.изм. | K6: Завод
A7: 1 | B7: ВРУ | E7: ВРУ (ВРУ1-11-10 giriş+АВР + ВРУ1-47-00 dağıtım, 2 seksiyon) | I7: 1 | J7: компл. | K7: CHINT+TEKSAN
A8: 2 | C8: korpus | D8: 714-15112 | E8: Щит мет. ЩРн-7-2 PR 1320х750х300 IP54 (TEKSAN) — ВРУ gövde | F8: 71190 | G8: =F8*$B$5 -> 71190 | H8: =G8*I8 -> 71190 | I8: 1 | J8: шт. | K8: TEKSAN
A9: 3 | C9: rubilnik | D9: 420126 | E9: Реверсивный рубильник NH40-125 с блоком АВР, приоритет 1-го ввода, 3P 125А | F9: 444876 | G9: =F9*$B$2 -> 266925.6 | H9: =G9*I9 -> 266925.6 | I9: 1 | J9: шт. | K9: CHINT
A10: 4 | C10: fu | D10: 521260 | E10: Держатель плавк. вставки RT36-00-160 габ.00 160А (1П) | F10: 2038 | G10: =F10*$B$2 -> 1222.8 | H10: =G10*I10 -> 25678.8 | I10: 21 | J10: шт. | K10: CHINT
A11: 5 | C11: fu | D11: 521345 | E11: Плавкая вставка RT36-00-160 габ.00 50А | F11: 1525 | G11: =F11*$B$2 -> 915 | H11: =G11*I11 -> 10980 | I11: 12 | J11: шт. | K11: CHINT
A12: 6 | C12: fu | D12: 521341 | E12: Плавкая вставка RT36-00-160 габ.00 32А | F12: 1510 | G12: =F12*$B$2 -> 906 | H12: =G12*I12 -> 2718 | I12: 3 | J12: шт. | K12: CHINT
A13: 7 | C13: fu | D13: 521340 | E13: Плавкая вставка RT36-00-160 габ.00 25А | F13: 1510 | G13: =F13*$B$2 -> 906 | H13: =G13*I13 -> 5436 | I13: 6 | J13: шт. | K13: CHINT
A14: 8 | C14: fu | D14: 521366 | E14: Держатель плавк. вставки RT36-0-160 габ.0 160А (1П) | F14: 3100 | G14: =F14*$B$2 -> 1860 | H14: =G14*I14 -> 16740 | I14: 9 | J14: шт. | K14: CHINT
A15: 9 | C15: fu | D15: 521223 | E15: Плавкая вставка RT36-0-160 габ.0 40А ⚠stok | F15: 2175 | G15: =F15*$B$2 -> 1305 | H15: =G15*I15 -> 11745 | I15: 9 | J15: шт. | K15: CHINT
A16: 10 | C16: montaj | E16: Монтажный материал | H16: =$B$3*SUM(H8:H15) -> 12342.402 | I16: 1 | J16: компл.
A17: 11 | C17: işçilik | E17: Монтажная работа | H17: =$B$4*SUM(H8:H15) -> 20570.67 | I17: 1 | J17: компл.
B18: Toplam ВРУ | H18: =SUBTOTAL(9,H8:H17) -> 444326.47
A19: 12 | B19: ЩО-1 | E19: Щит осветительный ЩО-1 (ЩРв-24) | I19: 1 | J19: компл. | K19: CHINT+TEKSAN
A20: 13 | C20: korpus | D20: 713-15010 | E20: Щит мет. ЩРв-24 б/о 320х405х120 IP31 (TEKSAN) | F20: 11150 | G20: =F20*$B$5 -> 11150 | H20: =G20*I20 -> 11150 | I20: 1 | J20: шт. | K20: TEKSAN
A21: 14 | C21: OTO | D21: 179703 | E21: Авт. выкл. NB1-63 3P 25А 6кА х-ка C | F21: 7907 | G21: =F21*$B$2 -> 4744.2 | H21: =G21*I21 -> 4744.2 | I21: 1 | J21: шт. | K21: CHINT
A22: 15 | C22: OTO | D22: 179616 | E22: Авт. выкл. NB1-63 1P 16А 6кА х-ка C | F22: 2818 | G22: =F22*$B$2 -> 1690.8 | H22: =G22*I22 -> 20289.6 | I22: 12 | J22: шт. | K22: CHINT
A23: 16 | C23: DİF | D23: 515380 | E23: Диф. авт. NXBLE-63YH 1P+N C16 30mA тип AC 6kA | F23: 5104 | G23: =F23*$B$2 -> 3062.4 | H23: =G23*I23 -> 6124.8 | I23: 2 | J23: шт. | K23: CHINT
A24: 17 | C24: montaj | E24: Монтажный материал | H24: =$B$3*SUM(H20:H23) -> 1269.258 | I24: 1 | J24: компл.
A25: 18 | C25: işçilik | E25: Монтажная работа | H25: =$B$4*SUM(H20:H23) -> 2115.43 | I25: 1 | J25: компл.
B26: Toplam ЩО-1 | H26: =SUBTOTAL(9,H20:H25) -> 45693.288
A27: 19 | B27: ЩО-2 | E27: Щит осветительный ЩО-2 (ЩРв-24) | I27: 1 | J27: компл. | K27: CHINT+TEKSAN
A28: 20 | C28: korpus | D28: 713-15010 | E28: Щит мет. ЩРв-24 б/о 320х405х120 IP31 (TEKSAN) | F28: 11150 | G28: =F28*$B$5 -> 11150 | H28: =G28*I28 -> 11150 | I28: 1 | J28: шт. | K28: TEKSAN
A29: 21 | C29: OTO | D29: 179703 | E29: Авт. выкл. NB1-63 3P 25А 6кА х-ка C | F29: 7907 | G29: =F29*$B$2 -> 4744.2 | H29: =G29*I29 -> 4744.2 | I29: 1 | J29: шт. | K29: CHINT
A30: 22 | C30: OTO | D30: 179616 | E30: Авт. выкл. NB1-63 1P 16А 6кА х-ка C | F30: 2818 | G30: =F30*$B$2 -> 1690.8 | H30: =G30*I30 -> 15217.2 | I30: 9 | J30: шт. | K30: CHINT
A31: 23 | C31: DİF | D31: 515380 | E31: Диф. авт. NXBLE-63YH 1P+N C16 30mA тип AC 6kA | F31: 5104 | G31: =F31*$B$2 -> 3062.4 | H31: =G31*I31 -> 6124.8 | I31: 2 | J31: шт. | K31: CHINT
A32: 24 | C32: montaj | E32: Монтажный материал | H32: =$B$3*SUM(H28:H31) -> 1117.086 | I32: 1 | J32: компл.
A33: 25 | C33: işçilik | E33: Монтажная работа | H33: =$B$4*SUM(H28:H31) -> 1861.81 | I33: 1 | J33: компл.
B34: Toplam ЩО-2 | H34: =SUBTOTAL(9,H28:H33) -> 40215.096
A35: 26 | B35: ЩО-3 | E35: Щит осветительный ЩО-3 (ЩРв-24) | I35: 1 | J35: компл. | K35: CHINT+TEKSAN
A36: 27 | C36: korpus | D36: 713-15010 | E36: Щит мет. ЩРв-24 б/о 320х405х120 IP31 (TEKSAN) | F36: 11150 | G36: =F36*$B$5 -> 11150 | H36: =G36*I36 -> 11150 | I36: 1 | J36: шт. | K36: TEKSAN
A37: 28 | C37: OTO | D37: 179703 | E37: Авт. выкл. NB1-63 3P 25А 6кА х-ка C | F37: 7907 | G37: =F37*$B$2 -> 4744.2 | H37: =G37*I37 -> 4744.2 | I37: 1 | J37: шт. | K37: CHINT
A38: 29 | C38: OTO | D38: 179616 | E38: Авт. выкл. NB1-63 1P 16А 6кА х-ка C | F38: 2818 | G38: =F38*$B$2 -> 1690.8 | H38: =G38*I38 -> 20289.6 | I38: 12 | J38: шт. | K38: CHINT
A39: 30 | C39: DİF | D39: 515380 | E39: Диф. авт. NXBLE-63YH 1P+N C16 30mA тип AC 6kA | F39: 5104 | G39: =F39*$B$2 -> 3062.4 | H39: =G39*I39 -> 6124.8 | I39: 2 | J39: шт. | K39: CHINT
A40: 31 | C40: montaj | E40: Монтажный материал | H40: =$B$3*SUM(H36:H39) -> 1269.258 | I40: 1 | J40: компл.
...

Sheet СВОД
A1: СВОД — Panolar özeti — Atırau 250 kişilik okul (24-2024-ЭЛ) — CHINT apparat + TEKSAN korpus
A3: № | B3: Пано | C3: Пано tipi / gövde | D3: Cihaz özeti | E3: Tutar KZT (netto+montaj)
A4: 1 | B4: ВРУ | C4: ЩРн-7-2 PR (gövde teyit) | D4: АВР NH40-125 ×1; ППН çıkış 10 (50A×4,40A×3,32A×1,25A×2) fuse-switch | E4: =BOM!H18 -> 444326.47
A5: 2 | B5: ЩО-1 | C5: ЩРв-24 | D5: Ввод 3P25A ×1; 1P16A ×12; RCBO16 ×2 | E5: =BOM!H26 -> 45693.288
A6: 3 | B6: ЩО-2 | C6: ЩРв-24 | D6: Ввод 3P25A ×1; 1P16A ×9; RCBO16 ×2 | E6: =BOM!H34 -> 40215.096
A7: 4 | B7: ЩО-3 | C7: ЩРв-24 | D7: Ввод 3P25A ×1; 1P16A ×12; RCBO16 ×2 | E7: =BOM!H42 -> 45693.288
A8: 5 | B8: ЩО-4 | C8: ЩРв-24 | D8: Ввод 3P25A ×1; 1P16A ×13; RCBO16 ×2 | E8: =BOM!H50 -> 47519.352
A9: 6 | B9: ЩАО-1 | C9: ЩРв-9 | D9: Ввод 3P25A ×1; 1P16A ×4 | E9: =BOM!H57 -> 20625.192
A10: 7 | B10: ЩАО-2 | C10: ЩРв-9 | D10: Ввод 3P25A ×1; 1P16A ×3 | E10: =BOM!H64 -> 18799.128
A11: 8 | B11: ЩС-1 | C11: ЩРв-36 | D11: Ввод 3P25A ×1; RCBO16 ×9 | E11: =BOM!H71 -> 45873.864
A12: 9 | B12: ЩС-2 | C12: ЩРв-48 | D12: Ввод 3P25A ×1; RCBO20 ×1; RCBO16 ×11 | E12: =BOM!H79 -> 63158.184
A13: 10 | B13: ЩС-3 | C13: ЩРв-72 (spec 54) | D13: Ввод 3P25A ×1; 3P16A ×2; RCBO20 ×1; RCBO16 ×11 | E13: =BOM!H88 -> 80671.896
A14: 11 | B14: ЩС-4 | C14: ЩРв-36 | D14: Ввод 3P25A ×1; 3P16A ×2; 1P25A ×1; 1P16A ×4; RCBO16 ×5 | E14: =BOM!H98 -> 51782.976
A15: 12 | B15: ЩС-5 | C15: ЩРв-36 | D15: Ввод 3P25A ×1; 3P16A ×5; RCBO16 ×2 | E15: =BOM!H106 -> 47660.4
A16: 13 | B16: ЩС-6 | C16: ЩРв-18 | D16: Ввод 3P25A ×1; 3P16A ×4 | E16: =BOM!H113 -> 41198.76
B17: GENEL TOPLAM | E17: =SUM(E4:E16) -> 993217.9
A19: Metraj notu: 40A gab0 sigorta stok 3 ad. (9 gerekli) — sipariş; ATS stok 1 — rezerve; sayaç+akım trafosu (СА4У 100/5) ayrı metraj (SAİMAN/şebeke)
A21: Cihaz toplamları (dağıtım panoları)
A22: Cihaz | B22: Артикул | C22: Adet | D22: Liste KZT | E22: Netto KZT | F22: Toplam netto KZT
A23: NB1-63 3P C25 (ввод) | B23: 179703 | C23: 12 | D23: 7907 | E23: =D23*BOM!$B$2 -> 4744.2 | F23: =C23*E23 -> 56930.4
A24: NB1-63 1P C16 | B24: 179616 | C24: 57 | D24: 2818 | E24: =D24*BOM!$B$2 -> 1690.8 | F24: =C24*E24 -> 96375.6
A25: NB1-63 1P C25 | B25: 179619 | C25: 1 | D25: 2869 | E25: =D25*BOM!$B$2 -> 1721.4 | F25: =C25*E25 -> 1721.4
A26: NB1-63 3P C16 | B26: 179700 | C26: 13 | D26: 7697 | E26: =D26*BOM!$B$2 -> 4618.2 | F26: =C26*E26 -> 60036.6
A27: NXBLE-63YH 1P+N C16 30mA | B27: 515380 | C27: 46 | D27: 5104 | E27: =D27*BOM!$B$2 -> 3062.4 | F27: =C27*E27 -> 140870.4
A28: NXBLE-63YH 1P+N C20 30mA | B28: 515387 | C28: 2 | D28: 5632 | E28: =D28*BOM!$B$2 -> 3379.2 | F28: =C28*E28 -> 6758.4
A29: Korpuslar (TEKSAN)
A30: Щит мет. ЩРв-24 б/о 320х405х120 IP31 | B30: 713-15010 | C30: 4 | D30: 11150 | E30: =D30*BOM!$B$5 -> 11150 | F30: =C30*E30 -> 44600
A31: Щит мет. ЩРв-9 275х320х120 | B31: 713-15037 | C31: 2 | D31: 7590 | E31: =D31*BOM!$B$5 -> 7590 | F31: =C31*E31 -> 15180
A32: Щит мет. ЩРв-36 550х320х120 | B32: 713-15030 | C32: 3 | D32: 10170 | E32: =D32*BOM!$B$5 -> 10170 | F32: =C32*E32 -> 30510
A33: Щит мет. ЩРв-48з-3 620х310х120 | B33: 719-15925 | C33: 1 | D33: 16670 | E33: =D33*BOM!$B$5 -> 16670 | F33: =C33*E33 -> 16670
A34: Щит мет. ЩРв-72 670х450х125 | B34: 713-15024 | C34: 1 | D34: 23650 | E34: =D34*BOM!$B$5 -> 23650 | F34: =C34*E34 -> 23650
A35: Щит мет. ЩРв-1/18 277х450х120 IP31 | B35: 713-15007 | C35: 1 | D35: 14930 | E35: =D35*BOM!$B$5 -> 14930 | F35: =C35*E35 -> 14930
A36: Щит мет. ЩРн-7-2 PR 1320х750х300 IP54 | B36: 714-15112 | C36: 1 | D36: 71190 | E36: =D36*BOM!$B$5 -> 71190 | F36: =C36*E36 -> 71190
