Workbook

Sheet Özet
A1: MALZEME İCMALİ (BOM) — Futbol Stadyumu Aktobe, I. Etap
A2: KJ Albüm 2 / Bölüm 2 — Monolitik diyaframlar (LŞM) ve asansör kuyuları (ŞLM), pafta 93–190
A3: DİKKAT: Miktarlar her çizimdeki BİR eleman içindir. Bina genelindeki toplam için KJ-62 yerleşim planındaki eleman adetleriyle çarpılmalıdır.
A5: 1) DONATI — Çap ve sınıf bazında
A6: Çap (mm) | B6: Sınıf | C6: Standart | D6: Birim kütle (kg/m) | E6: Toplam boy (m) | F6: Kütle-hesap (kg) | G6: Kütle-proje (kg) | H6: Kütle-proje (ton)
A7: 8 | B7: A240 | C7: ГОСТ 34028-2016 | D7: 0.395 | E7: =ROUND(SUMIFS('Detay-Poz Listesi'!$J$5:$J$487,'Detay-Poz Listesi'!$D$5:$D$487,A7,'Detay-Poz Listesi'!$E$5:$E$487,B7),2) -> 5549.61 | F7: =ROUND(SUMIFS('Detay-Poz Listesi'!$K$5:$K$487,'Detay-Poz Listesi'!$D$5:$D$487,A7,'Detay-Poz Listesi'!$E$5:$E$487,B7),2) -> 2192.05 | G7: =ROUND(SUMIFS('Detay-Poz Listesi'!$L$5:$L$487,'Detay-Poz Listesi'!$D$5:$D$487,A7,'Detay-Poz Listesi'!$E$5:$E$487,B7),2) -> 2192.05 | H7: =ROUND(G7/1000,3) -> 2.192
A8: 14 | B8: A400 | C8: ГОСТ 34028-2016 | D8: 1.208 | E8: =ROUND(SUMIFS('Detay-Poz Listesi'!$J$5:$J$487,'Detay-Poz Listesi'!$D$5:$D$487,A8,'Detay-Poz Listesi'!$E$5:$E$487,B8),2) -> 277.34 | F8: =ROUND(SUMIFS('Detay-Poz Listesi'!$K$5:$K$487,'Detay-Poz Listesi'!$D$5:$D$487,A8,'Detay-Poz Listesi'!$E$5:$E$487,B8),2) -> 335.03 | G8: =ROUND(SUMIFS('Detay-Poz Listesi'!$L$5:$L$487,'Detay-Poz Listesi'!$D$5:$D$487,A8,'Detay-Poz Listesi'!$E$5:$E$487,B8),2) -> 856.57 | H8: =ROUND(G8/1000,3) -> 0.857
A9: 14 | B9: A500 | C9: ГОСТ 34028-2016 | D9: 1.208 | E9: =ROUND(SUMIFS('Detay-Poz Listesi'!$J$5:$J$487,'Detay-Poz Listesi'!$D$5:$D$487,A9,'Detay-Poz Listesi'!$E$5:$E$487,B9),2) -> 26787.69 | F9: =ROUND(SUMIFS('Detay-Poz Listesi'!$K$5:$K$487,'Detay-Poz Listesi'!$D$5:$D$487,A9,'Detay-Poz Listesi'!$E$5:$E$487,B9),2) -> 32359.32 | G9: =ROUND(SUMIFS('Detay-Poz Listesi'!$L$5:$L$487,'Detay-Poz Listesi'!$D$5:$D$487,A9,'Detay-Poz Listesi'!$E$5:$E$487,B9),2) -> 32395.64 | H9: =ROUND(G9/1000,3) -> 32.396
A10: 16 | B10: A500 | C10: ГОСТ 34028-2016 | D10: 1.578 | E10: =ROUND(SUMIFS('Detay-Poz Listesi'!$J$5:$J$487,'Detay-Poz Listesi'!$D$5:$D$487,A10,'Detay-Poz Listesi'!$E$5:$E$487,B10),2) -> 2068.39 | F10: =ROUND(SUMIFS('Detay-Poz Listesi'!$K$5:$K$487,'Detay-Poz Listesi'!$D$5:$D$487,A10,'Detay-Poz Listesi'!$E$5:$E$487,B10),2) -> 3263.9 | G10: =ROUND(SUMIFS('Detay-Poz Listesi'!$L$5:$L$487,'Detay-Poz Listesi'!$D$5:$D$487,A10,'Detay-Poz Listesi'!$E$5:$E$487,B10),2) -> 3263.9 | H10: =ROUND(G10/1000,3) -> 3.264
A11: TOPLAM DONATI | E11: =ROUND(SUM(E7:E10),3) -> 34683.03 | F11: =ROUND(SUM(F7:F10),3) -> 38150.3 | G11: =ROUND(SUM(G7:G10),3) -> 38708.16 | H11: =ROUND(SUM(H7:H10),3) -> 38.709
A13: 2) BETON ve YALITIM
A14: Kalem | B14: Şartname | C14: Birim | D14: Miktar
A15: Beton | B15: C25/30 W10 F150 | C15: m³ | D15: ='Eleman Bazında'!H104 -> 652.44
A16: Su yalıtımı | B16: BN 70/30 (ГОСТ 6617-2021) | C16: m² | D16: ='Eleman Bazında'!I104 -> 329.57
A17: Not: Bitüm miktarı '1 kat için m²' olarak verilmiştir; şartname 2 kat ister → satın almada 2× alın.
A18: Beton: 0.000 kotu altındaki tüm elemanlarda sülfata dayanıklı çimento ile, C25/30 W10 F150 (genel notlar, pafta 92). Yalıtım: toprakla temas eden yüzeylerde sıcak bitümle 2 kat.

Sheet Kesim Listesi
A1: KESİM & BÜKÜM LİSTESİ (üretim için) — çap × sınıf × boy bazında konsolide
A2: Adetler BİR eleman içindir. 'mtül' satırları çizimde boy verilmeden metretül olarak tanımlanmıştır — kesim boyu şantiyede bindirmeye göre belirlenir.
A4: Çap (mm) | B4: Sınıf | C4: Boy (mm) | D4: Şekil / Büküm | E4: Toplam adet | F4: Toplam boy (m) | G4: Kütle (kg) | H4: Geçtiği pafta sayısı
A5: 8 | B5: A240 | C5: 630 | D5: Etriye/fikstur: 460 duz + 2x80 kanca (L=630) | E5: =SUMIFS('Detay-Poz Listesi'!$G$5:$G$487,'Detay-Poz Listesi'!$D$5:$D$487,A5,'Detay-Poz Listesi'!$E$5:$E$487,B5,'Detay-Poz Listesi'!$F$5:$F$487,C5) -> 7083 | F5: =ROUND(SUMIFS('Detay-Poz Listesi'!$J$5:$J$487,'Detay-Poz Listesi'!$D$5:$D$487,A5,'Detay-Poz Listesi'!$E$5:$E$487,B5,'Detay-Poz Listesi'!$F$5:$F$487,C5),2) -> 4462.29 | G5: =ROUND(SUMIFS('Detay-Poz Listesi'!$L$5:$L$487,'Detay-Poz Listesi'!$D$5:$D$487,A5,'Detay-Poz Listesi'!$E$5:$E$487,B5,'Detay-Poz Listesi'!$F$5:$F$487,C5),2) -> 1762.61 | H5: 56
A6: 8 | B6: A240 | C6: 390 | D6: Etriye/fikstur: 220 duz + 2x80 kanca (L=390) | E6: =SUMIFS('Detay-Poz Listesi'!$G$5:$G$487,'Detay-Poz Listesi'!$D$5:$D$487,A6,'Detay-Poz Listesi'!$E$5:$E$487,B6,'Detay-Poz Listesi'!$F$5:$F$487,C6) -> 2788 | F6: =ROUND(SUMIFS('Detay-Poz Listesi'!$J$5:$J$487,'Detay-Poz Listesi'!$D$5:$D$487,A6,'Detay-Poz Listesi'!$E$5:$E$487,B6,'Detay-Poz Listesi'!$F$5:$F$487,C6),2) -> 1087.32 | G6: =ROUND(SUMIFS('Detay-Poz Listesi'!$L$5:$L$487,'Detay-Poz Listesi'!$D$5:$D$487,A6,'Detay-Poz Listesi'!$E$5:$E$487,B6,'Detay-Poz Listesi'!$F$5:$F$487,C6),2) -> 429.44 | H6: 43
A7: 14 | B7: A400 | C7: mtül | D7: Yatay dağıtma donatısı | F7: =ROUND(SUMIFS('Detay-Poz Listesi'!$H$5:$H$487,'Detay-Poz Listesi'!$D$5:$D$487,A7,'Detay-Poz Listesi'!$E$5:$E$487,B7,'Detay-Poz Listesi'!$F$5:$F$487,""),2) -> 277.34 | G7: =ROUND(SUMIFS('Detay-Poz Listesi'!$L$5:$L$487,'Detay-Poz Listesi'!$D$5:$D$487,A7,'Detay-Poz Listesi'!$E$5:$E$487,B7,'Detay-Poz Listesi'!$F$5:$F$487,""),2) -> 856.57 | H7: 2
A8: 14 | B8: A500 | C8: 3350 | D8: Düz çubuk | E8: =SUMIFS('Detay-Poz Listesi'!$G$5:$G$487,'Detay-Poz Listesi'!$D$5:$D$487,A8,'Detay-Poz Listesi'!$E$5:$E$487,B8,'Detay-Poz Listesi'!$F$5:$F$487,C8) -> 1949 | F8: =ROUND(SUMIFS('Detay-Poz Listesi'!$J$5:$J$487,'Detay-Poz Listesi'!$D$5:$D$487,A8,'Detay-Poz Listesi'!$E$5:$E$487,B8,'Detay-Poz Listesi'!$F$5:$F$487,C8),2) -> 6529.15 | G8: =ROUND(SUMIFS('Detay-Poz Listesi'!$L$5:$L$487,'Detay-Poz Listesi'!$D$5:$D$487,A8,'Detay-Poz Listesi'!$E$5:$E$487,B8,'Detay-Poz Listesi'!$F$5:$F$487,C8),2) -> 7887.16 | H8: 96
A9: 14 | B9: A500 | C9: 3280 | D9: Düz çubuk | E9: =SUMIFS('Detay-Poz Listesi'!$G$5:$G$487,'Detay-Poz Listesi'!$D$5:$D$487,A9,'Detay-Poz Listesi'!$E$5:$E$487,B9,'Detay-Poz Listesi'!$F$5:$F$487,C9) -> 40 | F9: =ROUND(SUMIFS('Detay-Poz Listesi'!$J$5:$J$487,'Detay-Poz Listesi'!$D$5:$D$487,A9,'Detay-Poz Listesi'!$E$5:$E$487,B9,'Detay-Poz Listesi'!$F$5:$F$487,C9),2) -> 131.2 | G9: =ROUND(SUMIFS('Detay-Poz Listesi'!$L$5:$L$487,'Detay-Poz Listesi'!$D$5:$D$487,A9,'Detay-Poz Listesi'!$E$5:$E$487,B9,'Detay-Poz Listesi'!$F$5:$F$487,C9),2) -> 158.49 | H9: 1
A10: 14 | B10: A500 | C10: 3260 | D10: Düz çubuk | E10: =SUMIFS('Detay-Poz Listesi'!$G$5:$G$487,'Detay-Poz Listesi'!$D$5:$D$487,A10,'Detay-Poz Listesi'!$E$5:$E$487,B10,'Detay-Poz Listesi'!$F$5:$F$487,C10) -> 38 | F10: =ROUND(SUMIFS('Detay-Poz Listesi'!$J$5:$J$487,'Detay-Poz Listesi'!$D$5:$D$487,A10,'Detay-Poz Listesi'!$E$5:$E$487,B10,'Detay-Poz Listesi'!$F$5:$F$487,C10),2) -> 123.88 | G10: =ROUND(SUMIFS('Detay-Poz Listesi'!$L$5:$L$487,'Detay-Poz Listesi'!$D$5:$D$487,A10,'Detay-Poz Listesi'!$E$5:$E$487,B10,'Detay-Poz Listesi'!$F$5:$F$487,C10),2) -> 149.65 | H10: 1
A11: 14 | B11: A500 | C11: 2930 | D11: Düz çubuk | E11: =SUMIFS('Detay-Poz Listesi'!$G$5:$G$487,'Detay-Poz Listesi'!$D$5:$D$487,A11,'Detay-Poz Listesi'!$E$5:$E$487,B11,'Detay-Poz Listesi'!$F$5:$F$487,C11) -> 1955 | F11: =ROUND(SUMIFS('Detay-Poz Listesi'!$J$5:$J$487,'Detay-Poz Listesi'!$D$5:$D$487,A11,'Detay-Poz Listesi'!$E$5:$E$487,B11,'Detay-Poz Listesi'!$F$5:$F$487,C11),2) -> 5728.15 | G11: =ROUND(SUMIFS('Detay-Poz Listesi'!$L$5:$L$487,'Detay-Poz Listesi'!$D$5:$D$487,A11,'Detay-Poz Listesi'!$E$5:$E$487,B11,'Detay-Poz Listesi'!$F$5:$F$487,C11),2) -> 6919.5 | H11: 96
A12: 14 | B12: A500 | C12: 2780 | D12: Düz çubuk | E12: =SUMIFS('Detay-Poz Listesi'!$G$5:$G$487,'Detay-Poz Listesi'!$D$5:$D$487,A12,'Detay-Poz Listesi'!$E$5:$E$487,B12,'Detay-Poz Listesi'!$F$5:$F$487,C12) -> 36 | F12: =ROUND(SUMIFS('Detay-Poz Listesi'!$J$5:$J$487,'Detay-Poz Listesi'!$D$5:$D$487,A12,'Detay-Poz Listesi'!$E$5:$E$487,B12,'Detay-Poz Listesi'!$F$5:$F$487,C12),2) -> 100.08 | G12: =ROUND(SUMIFS('Detay-Poz Listesi'!$L$5:$L$487,'Detay-Poz Listesi'!$D$5:$D$487,A12,'Detay-Poz Listesi'!$E$5:$E$487,B12,'Detay-Poz Listesi'!$F$5:$F$487,C12),2) -> 120.9 | H12: 1
A13: 14 | B13: A500 | C13: 2600 | D13: Düz çubuk | E13: =SUMIFS('Detay-Poz Listesi'!$G$5:$G$487,'Detay-Poz Listesi'!$D$5:$D$487,A13,'Detay-Poz Listesi'!$E$5:$E$487,B13,'Detay-Poz Listesi'!$F$5:$F$487,C13) -> 62 | F13: =ROUND(SUMIFS('Detay-Poz Listesi'!$J$5:$J$487,'Detay-Poz Listesi'!$D$5:$D$487,A13,'Detay-Poz Listesi'!$E$5:$E$487,B13,'Detay-Poz Listesi'!$F$5:$F$487,C13),2) -> 161.2 | G13: =ROUND(SUMIFS('Detay-Poz Listesi'!$L$5:$L$487,'Detay-Poz Listesi'!$D$5:$D$487,A13,'Detay-Poz Listesi'!$E$5:$E$487,B13,'Detay-Poz Listesi'!$F$5:$F$487,C13),2) -> 194.73 | H13: 4
A14: 14 | B14: A500 | C14: 2480 | D14: Düz çubuk | E14: =SUMIFS('Detay-Poz Listesi'!$G$5:$G$487,'Detay-Poz Listesi'!$D$5:$D$487,A14,'Detay-Poz Listesi'!$E$5:$E$487,B14,'Detay-Poz Listesi'!$F$5:$F$487,C14) -> 618 | F14: =ROUND(SUMIFS('Detay-Poz Listesi'!$J$5:$J$487,'Detay-Poz Listesi'!$D$5:$D$487,A14,'Detay-Poz Listesi'!$E$5:$E$487,B14,'Detay-Poz Listesi'!$F$5:$F$487,C14),2) -> 1532.64 | G14: =ROUND(SUMIFS('Detay-Poz Listesi'!$L$5:$L$487,'Detay-Poz Listesi'!$D$5:$D$487,A14,'Detay-Poz Listesi'!$E$5:$E$487,B14,'Detay-Poz Listesi'!$F$5:$F$487,C14),2) -> 1851.41 | H14: 26
A15: 14 | B15: A500 | C15: 2180 | D15: Düz çubuk | E15: =SUMIFS('Detay-Poz Listesi'!$G$5:$G$487,'Detay-Poz Listesi'!$D$5:$D$487,A15,'Detay-Poz Listesi'!$E$5:$E$487,B15,'Detay-Poz Listesi'!$F$5:$F$487,C15) -> 62 | F15: =ROUND(SUMIFS('Detay-Poz Listesi'!$J$5:$J$487,'Detay-Poz Listesi'!$D$5:$D$487,A15,'Detay-Poz Listesi'!$E$5:$E$487,B15,'Detay-Poz Listesi'!$F$5:$F$487,C15),2) -> 135.16 | G15: =ROUND(SUMIFS('Detay-Poz Listesi'!$L$5:$L$487,'Detay-Poz Listesi'!$D$5:$D$487,A15,'Detay-Poz Listesi'!$E$5:$E$487,B15,'Detay-Poz Listesi'!$F$5:$F$487,C15),2) -> 163.27 | H15: 4
A16: 14 | B16: A500 | C16: 1730 | D16: Düz çubuk | E16: =SUMIFS('Detay-Poz Listesi'!$G$5:$G$487,'Detay-Poz Listesi'!$D$5:$D$487,A16,'Detay-Poz Listesi'!$E$5:$E$487,B16,'Detay-Poz Listesi'!$F$5:$F$487,C16) -> 54 | F16: =ROUND(SUMIFS('Detay-Poz Listesi'!$J$5:$J$487,'Detay-Poz Listesi'!$D$5:$D$487,A16,'Detay-Poz Listesi'!$E$5:$E$487,B16,'Detay-Poz Listesi'!$F$5:$F$487,C16),2) -> 93.42 | G16: =ROUND(SUMIFS('Detay-Poz Listesi'!$L$5:$L$487,'Detay-Poz Listesi'!$D$5:$D$487,A16,'Detay-Poz Listesi'!$E$5:$E$487,B16,'Detay-Poz Listesi'!$F$5:$F$487,C16),2) -> 112.85 | H16: 1
A17: 14 | B17: A500 | C17: 560 | D17: Düz çubuk | E17: =SUMIFS('Detay-Poz Listesi'!$G$5:$G$487,'Detay-Poz Listesi'!$D$5:$D$487,A17,'Detay-Poz Listesi'!$E$5:$E$487,B17,'Detay-Poz Listesi'!$F$5:$F$487,C17) -> 104 | F17: =ROUND(SUMIFS('Detay-Poz Listesi'!$J$5:$J$487,'Detay-Poz Listesi'!$D$5:$D$487,A17,'Detay-Poz Listesi'!$E$5:$E$487,B17,'Detay-Poz Listesi'!$F$5:$F$487,C17),2) -> 58.24 | G17: =ROUND(SUMIFS('Detay-Poz Listesi'!$L$5:$L$487,'Detay-Poz Listesi'!$D$5:$D$487,A17,'Detay-Poz Listesi'!$E$5:$E$487,B17,'Detay-Poz Listesi'!$F$5:$F$487,C17),2) -> 70.35 | H17: 6
A18: 14 | B18: A500 | C18: mtül | D18: Yatay dağıtma donatısı | F18: =ROUND(SUMIFS('Detay-Poz Listesi'!$H$5:$H$487,'Detay-Poz Listesi'!$D$5:$D$487,A18,'Detay-Poz Listesi'!$E$5:$E$487,B18,'Detay-Poz Listesi'!$F$5:$F$487,""),2) -> 12194.57 | G18: =ROUND(SUMIFS('Detay-Poz Listesi'!$L$5:$L$487,'Detay-Poz Listesi'!$D$5:$D$487,A18,'Detay-Poz Listesi'!$E$5:$E$487,B18,'Detay-Poz Listesi'!$F$5:$F$487,""),2) -> 14767.33 | H18: 97
A19: 16 | B19: A500 | C19: 1970 | D19: L-cubuk: 950 x 950 (L=1970) | E19: =SUMIFS('Detay-Poz Listesi'!$G$5:$G$487,'Detay-Poz Listesi'!$D$5:$D$487,A19,'Detay-Poz Listesi'!$E$5:$E$487,B19,'Detay-Poz Listesi'!$F$5:$F$487,C19) -> 830 | F19: =ROUND(SUMIFS('Detay-Poz Listesi'!$J$5:$J$487,'Detay-Poz Listesi'!$D$5:$D$487,A19,'Detay-Poz Listesi'!$E$5:$E$487,B19,'Detay-Poz Listesi'!$F$5:$F$487,C19),2) -> 1635.1 | G19: =ROUND(SUMIFS('Detay-Poz Listesi'!$L$5:$L$487,'Detay-Poz Listesi'!$D$5:$D$487,A19,'Detay-Poz Listesi'!$E$5:$E$487,B19,'Detay-Poz Listesi'!$F$5:$F$487,C19),2) -> 2580.2 | H19: 34
A20: 16 | B20: A500 | C20: 1370 | D20: L-cubuk: 650 x 650 (L=1370) | E20: =SUMIFS('Detay-Poz Listesi'!$G$5:$G$487,'Detay-Poz Listesi'!$D$5:$D$487,A20,'Detay-Poz Listesi'!$E$5:$E$487,B20,'Detay-Poz Listesi'!$F$5:$F$487,C20) -> 187 | F20: =ROUND(SUMIFS('Detay-Poz Listesi'!$J$5:$J$487,'Detay-Poz Listesi'!$D$5:$D$487,A20,'Detay-Poz Listesi'!$E$5:$E$487,B20,'Detay-Poz Listesi'!$F$5:$F$487,C20),2) -> 256.19 | G20: =ROUND(SUMIFS('Detay-Poz Listesi'!$L$5:$L$487,'Detay-Poz Listesi'!$D$5:$D$487,A20,'Detay-Poz Listesi'!$E$5:$E$487,B20,'Detay-Poz Listesi'!$F$5:$F$487,C20),2) -> 404.26 | H20: 8
A21: 16 | B21: A500 | C21: 1150 | D21: L-cubuk: 600 x 600 (L=1150) | E21: =SUMIFS('Detay-Poz Listesi'!$G$5:$G$487,'Detay-Poz Listesi'!$D$5:$D$487,A21,'Detay-Poz Listesi'!$E$5:$E$487,B21,'Detay-Poz Listesi'!$F$5:$F$487,C21) -> 154 | F21: =ROUND(SUMIFS('Detay-Poz Listesi'!$J$5:$J$487,'Detay-Poz Listesi'!$D$5:$D$487,A21,'Detay-Poz Listesi'!$E$5:$E$487,B21,'Detay-Poz Listesi'!$F$5:$F$487,C21),2) -> 177.1 | G21: =ROUND(SUMIFS('Detay-Poz Listesi'!$L$5:$L$487,'Detay-Poz Listesi'!$D$5:$D$487,A21,'Detay-Poz Listesi'!$E$5:$E$487,B21,'Detay-Poz Listesi'!$F$5:$F$487,C21),2) -> 279.44 | H21: 7
A22: TOPLAM | E22: =ROUND(SUM(E5:E21),2) -> 15960 | F22: =ROUND(SUM(F5:F21),2) -> 34683.03 | G22: =ROUND(SUM(G5:G21),2) -> 38708.16

Sheet Eleman Bazında
A1: ELEMAN / GÖRÜNÜŞ BAZINDA İCMAL
A2: Sarı sütun: KJ-62 yerleşim planından eleman adedini girin — toplam metraj otomatik hesaplanır.
A4: Pafta | B4: Eleman | C4: Görünüş | D4: Ø8 A240 (kg) | E4: Ø14 (kg) | F4: Ø16 A500 (kg) | G4: Donatı toplam (kg) | H4: Beton C25/30 (m³) | I4: Bitüm BN70/30 (m²) | J4: Eleman adedi | K4: Toplam donatı (kg) | L4: Toplam beton (m³)
A5: 93 | B5: ЛШМ-1 | C5: Вид А | D5: =ROUND(SUMIFS('Detay-Poz Listesi'!$L$5:$L$487,'Detay-Poz Listesi'!$A$5:$A$487,A5,'Detay-Poz Listesi'!$C$5:$C$487,C5,'Detay-Poz Listesi'!$D$5:$D$487,8),2) -> 23.39 | E5: =ROUND(SUMIFS('Detay-Poz Listesi'!$L$5:$L$487,'Detay-Poz Listesi'!$A$5:$A$487,A5,'Detay-Poz Listesi'!$C$5:$C$487,C5,'Detay-Poz Listesi'!$D$5:$D$487,14),2) -> 318.45 | F5: =ROUND(SUMIFS('Detay-Poz Listesi'!$L$5:$L$487,'Detay-Poz Listesi'!$A$5:$A$487,A5,'Detay-Poz Listesi'!$C$5:$C$487,C5,'Detay-Poz Listesi'!$D$5:$D$487,16),2) -> 0 | G5: =ROUND(SUM(D5:F5),2) -> 341.84 | H5: 7.01 | J5: 1 | K5: =ROUND(G5*J5,2) -> 341.84 | L5: =ROUND(H5*J5,2) -> 7.01
A6: 94 | B6: ЛШМ-1 | C6: Вид Б | D6: =ROUND(SUMIFS('Detay-Poz Listesi'!$L$5:$L$487,'Detay-Poz Listesi'!$A$5:$A$487,A6,'Detay-Poz Listesi'!$C$5:$C$487,C6,'Detay-Poz Listesi'!$D$5:$D$487,8),2) -> 23.39 | E6: =ROUND(SUMIFS('Detay-Poz Listesi'!$L$5:$L$487,'Detay-Poz Listesi'!$A$5:$A$487,A6,'Detay-Poz Listesi'!$C$5:$C$487,C6,'Detay-Poz Listesi'!$D$5:$D$487,14),2) -> 332.36 | F6: =ROUND(SUMIFS('Detay-Poz Listesi'!$L$5:$L$487,'Detay-Poz Listesi'!$A$5:$A$487,A6,'Detay-Poz Listesi'!$C$5:$C$487,C6,'Detay-Poz Listesi'!$D$5:$D$487,16),2) -> 0 | G6: =ROUND(SUM(D6:F6),2) -> 355.75 | H6: 7.01 | J6: 1 | K6: =ROUND(G6*J6,2) -> 355.75 | L6: =ROUND(H6*J6,2) -> 7.01
A7: 95 | B7: ЛШМ-1 | C7: Вид В | D7: =ROUND(SUMIFS('Detay-Poz Listesi'!$L$5:$L$487,'Detay-Poz Listesi'!$A$5:$A$487,A7,'Detay-Poz Listesi'!$C$5:$C$487,C7,'Detay-Poz Listesi'!$D$5:$D$487,8),2) -> 36.08 | E7: =ROUND(SUMIFS('Detay-Poz Listesi'!$L$5:$L$487,'Detay-Poz Listesi'!$A$5:$A$487,A7,'Detay-Poz Listesi'!$C$5:$C$487,C7,'Detay-Poz Listesi'!$D$5:$D$487,14),2) -> 500.14 | F7: =ROUND(SUMIFS('Detay-Poz Listesi'!$L$5:$L$487,'Detay-Poz Listesi'!$A$5:$A$487,A7,'Detay-Poz Listesi'!$C$5:$C$487,C7,'Detay-Poz Listesi'!$D$5:$D$487,16),2) -> 0 | G7: =ROUND(SUM(D7:F7),2) -> 536.22 | H7: 10.88 | I7: 22.75 | J7: 1 | K7: =ROUND(G7*J7,2) -> 536.22 | L7: =ROUND(H7*J7,2) -> 10.88
A8: 96 | B8: ЛШМ-1 | C8: Вид Г | D8: =ROUND(SUMIFS('Detay-Poz Listesi'!$L$5:$L$487,'Detay-Poz Listesi'!$A$5:$A$487,A8,'Detay-Poz Listesi'!$C$5:$C$487,C8,'Detay-Poz Listesi'!$D$5:$D$487,8),2) -> 37.83 | E8: =ROUND(SUMIFS('Detay-Poz Listesi'!$L$5:$L$487,'Detay-Poz Listesi'!$A$5:$A$487,A8,'Detay-Poz Listesi'!$C$5:$C$487,C8,'Detay-Poz Listesi'!$D$5:$D$487,14),2) -> 529.75 | F8: =ROUND(SUMIFS('Detay-Poz Listesi'!$L$5:$L$487,'Detay-Poz Listesi'!$A$5:$A$487,A8,'Detay-Poz Listesi'!$C$5:$C$487,C8,'Detay-Poz Listesi'!$D$5:$D$487,16),2) -> 68.39 | G8: =ROUND(SUM(D8:F8),2) -> 635.97 | H8: 13.13 | J8: 1 | K8: =ROUND(G8*J8,2) -> 635.97 | L8: =ROUND(H8*J8,2) -> 13.13
A9: 97 | B9: ЛШМ-2 | C9: Вид А | D9: =ROUND(SUMIFS('Detay-Poz Listesi'!$L$5:$L$487,'Detay-Poz Listesi'!$A$5:$A$487,A9,'Detay-Poz Listesi'!$C$5:$C$487,C9,'Detay-Poz Listesi'!$D$5:$D$487,8),2) -> 22.65 | E9: =ROUND(SUMIFS('Detay-Poz Listesi'!$L$5:$L$487,'Detay-Poz Listesi'!$A$5:$A$487,A9,'Detay-Poz Listesi'!$C$5:$C$487,C9,'Detay-Poz Listesi'!$D$5:$D$487,14),2) -> 317.98 | F9: =ROUND(SUMIFS('Detay-Poz Listesi'!$L$5:$L$487,'Detay-Poz Listesi'!$A$5:$A$487,A9,'Detay-Poz Listesi'!$C$5:$C$487,C9,'Detay-Poz Listesi'!$D$5:$D$487,16),2) -> 0 | G9: =ROUND(SUM(D9:F9),2) -> 340.63 | H9: 6.73 | J9: 1 | K9: =ROUND(G9*J9,2) -> 340.63 | L9: =ROUND(H9*J9,2) -> 6.73
A10: 98 | B10: ЛШМ-2 | C10: Вид Б | D10: =ROUND(SUMIFS('Detay-Poz Listesi'!$L$5:$L$487,'Detay-Poz Listesi'!$A$5:$A$487,A10,'Detay-Poz Listesi'!$C$5:$C$487,C10,'Detay-Poz Listesi'!$D$5:$D$487,8),2) -> 27.87 | E10: =ROUND(SUMIFS('Detay-Poz Listesi'!$L$5:$L$487,'Detay-Poz Listesi'!$A$5:$A$487,A10,'Detay-Poz Listesi'!$C$5:$C$487,C10,'Detay-Poz Listesi'!$D$5:$D$487,14),2) -> 392.51 | F10: =ROUND(SUMIFS('Detay-Poz Listesi'!$L$5:$L$487,'Detay-Poz Listesi'!$A$5:$A$487,A10,'Detay-Poz Listesi'!$C$5:$C$487,C10,'Detay-Poz Listesi'!$D$5:$D$487,16),2) -> 0 | G10: =ROUND(SUM(D10:F10),2) -> 420.38 | H10: 8.38 | J10: 1 | K10: =ROUND(G10*J10,2) -> 420.38 | L10: =ROUND(H10*J10,2) -> 8.38
A11: 99 | B11: ЛШМ-2 | C11: Вид В | D11: =ROUND(SUMIFS('Detay-Poz Listesi'!$L$5:$L$487,'Detay-Poz Listesi'!$A$5:$A$487,A11,'Detay-Poz Listesi'!$C$5:$C$487,C11,'Detay-Poz Listesi'!$D$5:$D$487,8),2) -> 37.83 | E11: =ROUND(SUMIFS('Detay-Poz Listesi'!$L$5:$L$487,'Detay-Poz Listesi'!$A$5:$A$487,A11,'Detay-Poz Listesi'!$C$5:$C$487,C11,'Detay-Poz Listesi'!$D$5:$D$487,14),2) -> 533.73 | F11: =ROUND(SUMIFS('Detay-Poz Listesi'!$L$5:$L$487,'Detay-Poz Listesi'!$A$5:$A$487,A11,'Detay-Poz Listesi'!$C$5:$C$487,C11,'Detay-Poz Listesi'!$D$5:$D$487,16),2) -> 68.39 | G11: =ROUND(SUM(D11:F11),2) -> 639.95 | H11: 13.13 | J11: 1 | K11: =ROUND(G11*J11,2) -> 639.95 | L11: =ROUND(H11*J11,2) -> 13.13
A12: 100 | B12: ЛШМ-2 | C12: Вид Г | D12: =ROUND(SUMIFS('Detay-Poz Listesi'!$L$5:$L$487,'Detay-Poz Listesi'!$A$5:$A$487,A12,'Detay-Poz Listesi'!$C$5:$C$487,C12,'Detay-Poz Listesi'!$D$5:$D$487,8),2) -> 54 | E12: =ROUND(SUMIFS('Detay-Poz Listesi'!$L$5:$L$487,'Detay-Poz Listesi'!$A$5:$A$487,A12,'Detay-Poz Listesi'!$C$5:$C$487,C12,'Detay-Poz Listesi'!$D$5:$D$487,14),2) -> 689.96 | F12: =ROUND(SUMIFS('Detay-Poz Listesi'!$L$5:$L$487,'Detay-Poz Listesi'!$A$5:$A$487,A12,'Detay-Poz Listesi'!$C$5:$C$487,C12,'Detay-Poz Listesi'!$D$5:$D$487,16),2) -> 136.78 | G12: =ROUND(SUM(D12:F12),2) -> 880.74 | H12: 16.05 | I12: 28.03 | J12: 1 | K12: =ROUND(G12*J12,2) -> 880.74 | L12: =ROUND(H12*J12,2) -> 16.05
A13: 101 | B13: ЛШМ-2* | C13: Вид А | D13: =ROUND(SUMIFS('Detay-Poz Listesi'!$L$5:$L$487,'Detay-Poz Listesi'!$A$5:$A$487,A13,'Detay-Poz Listesi'!$C$5:$C$487,C13,'Detay-Poz Listesi'!$D$5:$D$487,8),2) -> 22.65 | E13: =ROUND(SUMIFS('Detay-Poz Listesi'!$L$5:$L$487,'Detay-Poz Listesi'!$A$5:$A$487,A13,'Detay-Poz Listesi'!$C$5:$C$487,C13,'Detay-Poz Listesi'!$D$5:$D$487,14),2) -> 316.5 | F13: =ROUND(SUMIFS('Detay-Poz Listesi'!$L$5:$L$487,'Detay-Poz Listesi'!$A$5:$A$487,A13,'Detay-Poz Listesi'!$C$5:$C$487,C13,'Detay-Poz Listesi'!$D$5:$D$487,16),2) -> 0 | G13: =ROUND(SUM(D13:F13),2) -> 339.15 | H13: 6.76 | J13: 1 | K13: =ROUND(G13*J13,2) -> 339.15 | L13: =ROUND(H13*J13,2) -> 6.76
A14: 102 | B14: ЛШМ-2* | C14: Вид Б | D14: =ROUND(SUMIFS('Detay-Poz Listesi'!$L$5:$L$487,'Detay-Poz Listesi'!$A$5:$A$487,A14,'Detay-Poz Listesi'!$C$5:$C$487,C14,'Detay-Poz Listesi'!$D$5:$D$487,8),2) -> 28.12 | E14: =ROUND(SUMIFS('Detay-Poz Listesi'!$L$5:$L$487,'Detay-Poz Listesi'!$A$5:$A$487,A14,'Detay-Poz Listesi'!$C$5:$C$487,C14,'Detay-Poz Listesi'!$D$5:$D$487,14),2) -> 391 | F14: =ROUND(SUMIFS('Detay-Poz Listesi'!$L$5:$L$487,'Detay-Poz Listesi'!$A$5:$A$487,A14,'Detay-Poz Listesi'!$C$5:$C$487,C14,'Detay-Poz Listesi'!$D$5:$D$487,16),2) -> 0 | G14: =ROUND(SUM(D14:F14),2) -> 419.12 | H14: 8.4 | J14: 1 | K14: =ROUND(G14*J14,2) -> 419.12 | L14: =ROUND(H14*J14,2) -> 8.4
A15: 103 | B15: ЛШМ-2* | C15: Вид В | D15: =ROUND(SUMIFS('Detay-Poz Listesi'!$L$5:$L$487,'Detay-Poz Listesi'!$A$5:$A$487,A15,'Detay-Poz Listesi'!$C$5:$C$487,C15,'Detay-Poz Listesi'!$D$5:$D$487,8),2) -> 37.83 | E15: =ROUND(SUMIFS('Detay-Poz Listesi'!$L$5:$L$487,'Detay-Poz Listesi'!$A$5:$A$487,A15,'Detay-Poz Listesi'!$C$5:$C$487,C15,'Detay-Poz Listesi'!$D$5:$D$487,14),2) -> 587.3 | F15: =ROUND(SUMIFS('Detay-Poz Listesi'!$L$5:$L$487,'Detay-Poz Listesi'!$A$5:$A$487,A15,'Detay-Poz Listesi'!$C$5:$C$487,C15,'Detay-Poz Listesi'!$D$5:$D$487,16),2) -> 68.39 | G15: =ROUND(SUM(D15:F15),2) -> 693.52 | H15: 13.35 | J15: 1 | K15: =ROUND(G15*J15,2) -> 693.52 | L15: =ROUND(H15*J15,2) -> 13.35
A16: 104 | B16: ЛШМ-2* | C16: Вид Г | D16: =ROUND(SUMIFS('Detay-Poz Listesi'!$L$5:$L$487,'Detay-Poz Listesi'!$A$5:$A$487,A16,'Detay-Poz Listesi'!$C$5:$C$487,C16,'Detay-Poz Listesi'!$D$5:$D$487,8),2) -> 53.75 | E16: =ROUND(SUMIFS('Detay-Poz Listesi'!$L$5:$L$487,'Detay-Poz Listesi'!$A$5:$A$487,A16,'Detay-Poz Listesi'!$C$5:$C$487,C16,'Detay-Poz Listesi'!$D$5:$D$487,14),2) -> 684.11 | F16: =ROUND(SUMIFS('Detay-Poz Listesi'!$L$5:$L$487,'Detay-Poz Listesi'!$A$5:$A$487,A16,'Detay-Poz Listesi'!$C$5:$C$487,C16,'Detay-Poz Listesi'!$D$5:$D$487,16),2) -> 136.78 | G16: =ROUND(SUM(D16:F16),2) -> 874.64 | H16: 16.1 | I16: 28.1 | J16: 1 | K16: =ROUND(G16*J16,2) -> 874.64 | L16: =ROUND(H16*J16,2) -> 16.1
A17: 105 | B17: ЛШМ-2-1 | C17: Вид А | D17: =ROUND(SUMIFS('Detay-Poz Listesi'!$L$5:$L$487,'Detay-Poz Listesi'!$A$5:$A$487,A17,'Detay-Poz Listesi'!$C$5:$C$487,C17,'Detay-Poz Listesi'!$D$5:$D$487,8),2) -> 23.39 | E17: =ROUND(SUMIFS('Detay-Poz Listesi'!$L$5:$L$487,'Detay-Poz Listesi'!$A$5:$A$487,A17,'Detay-Poz Listesi'!$C$5:$C$487,C17,'Detay-Poz Listesi'!$D$5:$D$487,14),2) -> 330.27 | F17: =ROUND(SUMIFS('Detay-Poz Listesi'!$L$5:$L$487,'Detay-Poz Listesi'!$A$5:$A$487,A17,'Detay-Poz Listesi'!$C$5:$C$487,C17,'Detay-Poz Listesi'!$D$5:$D$487,16),2) -> 0 | G17: =ROUND(SUM(D17:F17),2) -> 353.66 | H17: 6.99 | J17: 1 | K17: =ROUND(G17*J17,2) -> 353.66 | L17: =ROUND(H17*J17,2) -> 6.99
A18: 106 | B18: ЛШМ-2-1 | C18: Вид Б | D18: =ROUND(SUMIFS('Detay-Poz Listesi'!$L$5:$L$487,'Detay-Poz Listesi'!$A$5:$A$487,A18,'Detay-Poz Listesi'!$C$5:$C$487,C18,'Detay-Poz Listesi'!$D$5:$D$487,8),2) -> 28.12 | E18: =ROUND(SUMIFS('Detay-Poz Listesi'!$L$5:$L$487,'Detay-Poz Listesi'!$A$5:$A$487,A18,'Detay-Poz Listesi'!$C$5:$C$487,C18,'Detay-Poz Listesi'!$D$5:$D$487,14),2) -> 388.08 | F18: =ROUND(SUMIFS('Detay-Poz Listesi'!$L$5:$L$487,'Detay-Poz Listesi'!$A$5:$A$487,A18,'Detay-Poz Listesi'!$C$5:$C$487,C18,'Detay-Poz Listesi'!$D$5:$D$487,16),2) -> 0 | G18: =ROUND(SUM(D18:F18),2) -> 416.2 | H18: 8.44 | J18: 1 | K18: =ROUND(G18*J18,2) -> 416.2 | L18: =ROUND(H18*J18,2) -> 8.44
A19: 107 | B19: ЛШМ-2-1 | C19: Вид В | D19: =ROUND(SUMIFS('Detay-Poz Listesi'!$L$5:$L$487,'Detay-Poz Listesi'!$A$5:$A$487,A19,'Detay-Poz Listesi'!$C$5:$C$487,C19,'Detay-Poz Listesi'!$D$5:$D$487,8),2) -> 37.83 | E19: =ROUND(SUMIFS('Detay-Poz Listesi'!$L$5:$L$487,'Detay-Poz Listesi'!$A$5:$A$487,A19,'Detay-Poz Listesi'!$C$5:$C$487,C19,'Detay-Poz Listesi'!$D$5:$D$487,14),2) -> 541.32 | F19: =ROUND(SUMIFS('Detay-Poz Listesi'!$L$5:$L$487,'Detay-Poz Listesi'!$A$5:$A$487,A19,'Detay-Poz Listesi'!$C$5:$C$487,C19,'Detay-Poz Listesi'!$D$5:$D$487,16),2) -> 68.39 | G19: =ROUND(SUM(D19:F19),2) -> 647.54 | H19: 13.35 | J19: 1 | K19: =ROUND(G19*J19,2) -> 647.54 | L19: =ROUND(H19*J19,2) -> 13.35
A20: 108 | B20: ЛШМ-2-1 | C20: Вид Г | D20: =ROUND(SUMIFS('Detay-Poz Listesi'!$L$5:$L$487,'Detay-Poz Listesi'!$A$5:$A$487,A20,'Detay-Poz Listesi'!$C$5:$C$487,C20,'Detay-Poz Listesi'!$D$5:$D$487,8),2) -> 53.75 | E20: =ROUND(SUMIFS('Detay-Poz Listesi'!$L$5:$L$487,'Detay-Poz Listesi'!$A$5:$A$487,A20,'Detay-Poz Listesi'!$C$5:$C$487,C20,'Detay-Poz Listesi'!$D$5:$D$487,14),2) -> 669.88 | F20: =ROUND(SUMIFS('Detay-Poz Listesi'!$L$5:$L$487,'Detay-Poz Listesi'!$A$5:$A$487,A20,'Detay-Poz Listesi'!$C$5:$C$487,C20,'Detay-Poz Listesi'!$D$5:$D$487,16),2) -> 68.39 | G20: =ROUND(SUM(D20:F20),2) -> 792.02 | H20: 16.17 | I20: 28.05 | J20: 1 | K20: =ROUND(G20*J20,2) -> 792.02 | L20: =ROUND(H20*J20,2) -> 16.17
A21: 109 | B21: ЛШМ-2*-1 | C21: Вид А | D21: =ROUND(SUMIFS('Detay-Poz Listesi'!$L$5:$L$487,'Detay-Poz Listesi'!$A$5:$A$487,A21,'Detay-Poz Listesi'!$C$5:$C$487,C21,'Detay-Poz Listesi'!$D$5:$D$487,8),2) -> 23.39 | E21: =ROUND(SUMIFS('Detay-Poz Listesi'!$L$5:$L$487,'Detay-Poz Listesi'!$A$5:$A$487,A21,'Detay-Poz Listesi'!$C$5:$C$487,C21,'Detay-Poz Listesi'!$D$5:$D$487,14),2) -> 330.27 | F21: =ROUND(SUMIFS('Detay-Poz Listesi'!$L$5:$L$487,'Detay-Poz Listesi'!$A$5:$A$487,A21,'Detay-Poz Listesi'!$C$5:$C$487,C21,'Detay-Poz Listesi'!$D$5:$D$487,16),2) -> 0 | G21: =ROUND(SUM(D21:F21),2) -> 353.66 | H21: 6.99 | J21: 1 | K21: =ROUND(G21*J21,2) -> 353.66 | L21: =ROUND(H21*J21,2) -> 6.99
A22: 110 | B22: ЛШМ-2*-1 | C22: Вид Б | D22: =ROUND(SUMIFS('Detay-Poz Listesi'!$L$5:$L$487,'Detay-Poz Listesi'!$A$5:$A$487,A22,'Detay-Poz Listesi'!$C$5:$C$487,C22,'Detay-Poz Listesi'!$D$5:$D$487,8),2) -> 28.12 | E22: =ROUND(SUMIFS('Detay-Poz Listesi'!$L$5:$L$487,'Detay-Poz Listesi'!$A$5:$A$487,A22,'Detay-Poz Listesi'!$C$5:$C$487,C22,'Detay-Poz Listesi'!$D$5:$D$487,14),2) -> 388.08 | F22: =ROUND(SUMIFS('Detay-Poz Listesi'!$L$5:$L$487,'Detay-Poz Listesi'!$A$5:$A$487,A22,'Detay-Poz Listesi'!$C$5:$C$487,C22,'Detay-Poz Listesi'!$D$5:$D$487,16),2) -> 0 | G22: =ROUND(SUM(D22:F22),2) -> 416.2 | H22: 8.44 | J22: 1 | K22: =ROUND(G22*J22,2) -> 416.2 | L22: =ROUND(H22*J22,2) -> 8.44
A23: 111 | B23: ЛШМ-2*-1 | C23: Вид В | D23: =ROUND(SUMIFS('Detay-Poz Listesi'!$L$5:$L$487,'Detay-Poz Listesi'!$A$5:$A$487,A23,'Detay-Poz Listesi'!$C$5:$C$487,C23,'Detay-Poz Listesi'!$D$5:$D$487,8),2) -> 37.83 | E23: =ROUND(SUMIFS('Detay-Poz Listesi'!$L$5:$L$487,'Detay-Poz Listesi'!$A$5:$A$487,A23,'Detay-Poz Listesi'!$C$5:$C$487,C23,'Detay-Poz Listesi'!$D$5:$D$487,14),2) -> 541.32 | F23: =ROUND(SUMIFS('Detay-Poz Listesi'!$L$5:$L$487,'Detay-Poz Listesi'!$A$5:$A$487,A23,'Detay-Poz Listesi'!$C$5:$C$487,C23,'Detay-Poz Listesi'!$D$5:$D$487,16),2) -> 68.39 | G23: =ROUND(SUM(D23:F23),2) -> 647.54 | H23: 13.35 | J23: 1 | K23: =ROUND(G23*J23,2) -> 647.54 | L23: =ROUND(H23*J23,2) -> 13.35
A24: 112 | B24: ЛШМ-2*-1 | C24: Вид Г | D24: =ROUND(SUMIFS('Detay-Poz Listesi'!$L$5:$L$487,'Detay-Poz Listesi'!$A$5:$A$487,A24,'Detay-Poz Listesi'!$C$5:$C$487,C24,'Detay-Poz Listesi'!$D$5:$D$487,8),2) -> 53.75 | E24: =ROUND(SUMIFS('Detay-Poz Listesi'!$L$5:$L$487,'Detay-Poz Listesi'!$A$5:$A$487,A24,'Detay-Poz Listesi'!$C$5:$C$487,C24,'Detay-Poz Listesi'!$D$5:$D$487,14),2) -> 669.88 | F24: =ROUND(SUMIFS('Detay-Poz Listesi'!$L$5:$L$487,'Detay-Poz Listesi'!$A$5:$A$487,A24,'Detay-Poz Listesi'!$C$5:$C$487,C24,'Detay-Poz Listesi'!$D$5:$D$487,16),2) -> 68.39 | G24: =ROUND(SUM(D24:F24),2) -> 792.02 | H24: 16.17 | I24: 28.05 | J24: 1 | K24: =ROUND(G24*J24,2) -> 792.02 | L24: =ROUND(H24*J24,2) -> 16.17
A25: 113 | B25: ЛШМ-3 | C25: Вид А | D25: =ROUND(SUMIFS('Detay-Poz Listesi'!$L$5:$L$487,'Detay-Poz Listesi'!$A$5:$A$487,A25,'Detay-Poz Listesi'!$C$5:$C$487,C25,'Detay-Poz Listesi'!$D$5:$D$487,8),2) -> 28.12 | E25: =ROUND(SUMIFS('Detay-Poz Listesi'!$L$5:$L$487,'Detay-Poz Listesi'!$A$5:$A$487,A25,'Detay-Poz Listesi'!$C$5:$C$487,C25,'Detay-Poz Listesi'!$D$5:$D$487,14),2) -> 389.03 | F25: =ROUND(SUMIFS('Detay-Poz Listesi'!$L$5:$L$487,'Detay-Poz Listesi'!$A$5:$A$487,A25,'Detay-Poz Listesi'!$C$5:$C$487,C25,'Detay-Poz Listesi'!$D$5:$D$487,16),2) -> 0 | G25: =ROUND(SUM(D25:F25),2) -> 417.15 | H25: 8.49 | J25: 1 | K25: =ROUND(G25*J25,2) -> 417.15 | L25: =ROUND(H25*J25,2) -> 8.49
A26: 114 | B26: ЛШМ-3 | C26: Вид Б | D26: =ROUND(SUMIFS('Detay-Poz Listesi'!$L$5:$L$487,'Detay-Poz Listesi'!$A$5:$A$487,A26,'Detay-Poz Listesi'!$C$5:$C$487,C26,'Detay-Poz Listesi'!$D$5:$D$487,8),2) -> 23.39 | E26: =ROUND(SUMIFS('Detay-Poz Listesi'!$L$5:$L$487,'Detay-Poz Listesi'!$A$5:$A$487,A26,'Detay-Poz Listesi'!$C$5:$C$487,C26,'Detay-Poz Listesi'!$D$5:$D$487,14),2) -> 331.2 | F26: =ROUND(SUMIFS('Detay-Poz Listesi'!$L$5:$L$487,'Detay-Poz Listesi'!$A$5:$A$487,A26,'Detay-Poz Listesi'!$C$5:$C$487,C26,'Detay-Poz Listesi'!$D$5:$D$487,16),2) -> 0 | G26: =ROUND(SUM(D26:F26),2) -> 354.59 | H26: 7.05 | J26: 1 | K26: =ROUND(G26*J26,2) -> 354.59 | L26: =ROUND(H26*J26,2) -> 7.05
A27: 115 | B27: ЛШМ-3 | C27: Вид В | D27: =ROUND(SUMIFS('Detay-Poz Listesi'!$L$5:$L$487,'Detay-Poz Listesi'!$A$5:$A$487,A27,'Detay-Poz Listesi'!$C$5:$C$487,C27,'Detay-Poz Listesi'!$D$5:$D$487,8),2) -> 37.83 | E27: =ROUND(SUMIFS('Detay-Poz Listesi'!$L$5:$L$487,'Detay-Poz Listesi'!$A$5:$A$487,A27,'Detay-Poz Listesi'!$C$5:$C$487,C27,'Detay-Poz Listesi'!$D$5:$D$487,14),2) -> 504.21 | F27: =ROUND(SUMIFS('Detay-Poz Listesi'!$L$5:$L$487,'Detay-Poz Listesi'!$A$5:$A$487,A27,'Detay-Poz Listesi'!$C$5:$C$487,C27,'Detay-Poz Listesi'!$D$5:$D$487,16),2) -> 74.61 | G27: =ROUND(SUM(D27:F27),2) -> 616.65 | H27: 13.35 | J27: 1 | K27: =ROUND(G27*J27,2) -> 616.65 | L27: =ROUND(H27*J27,2) -> 13.35
A28: 116 | B28: ЛШМ-3 | C28: Вид Г | D28: =ROUND(SUMIFS('Detay-Poz Listesi'!$L$5:$L$487,'Detay-Poz Listesi'!$A$5:$A$487,A28,'Detay-Poz Listesi'!$C$5:$C$487,C28,'Detay-Poz Listesi'!$D$5:$D$487,8),2) -> 53.75 | E28: =ROUND(SUMIFS('Detay-Poz Listesi'!$L$5:$L$487,'Detay-Poz Listesi'!$A$5:$A$487,A28,'Detay-Poz Listesi'!$C$5:$C$487,C28,'Detay-Poz Listesi'!$D$5:$D$487,14),2) -> 669.92 | F28: =ROUND(SUMIFS('Detay-Poz Listesi'!$L$5:$L$487,'Detay-Poz Listesi'!$A$5:$A$487,A28,'Detay-Poz Listesi'!$C$5:$C$487,C28,'Detay-Poz Listesi'!$D$5:$D$487,16),2) -> 68.39 | G28: =ROUND(SUM(D28:F28),2) -> 792.06 | H28: 16.17 | I28: 28.03 | J28: 1 | K28: =ROUND(G28*J28,2) -> 792.06 | L28: =ROUND(H28*J28,2) -> 16.17
A29: 117 | B29: ЛШМ-3* | C29: Вид А | D29: =ROUND(SUMIFS('Detay-Poz Listesi'!$L$5:$L$487,'Detay-Poz Listesi'!$A$5:$A$487,A29,'Detay-Poz Listesi'!$C$5:$C$487,C29,'Detay-Poz Listesi'!$D$5:$D$487,8),2) -> 28.12 | E29: =ROUND(SUMIFS('Detay-Poz Listesi'!$L$5:$L$487,'Detay-Poz Listesi'!$A$5:$A$487,A29,'Detay-Poz Listesi'!$C$5:$C$487,C29,'Detay-Poz Listesi'!$D$5:$D$487,14),2) -> 393.97 | F29: =ROUND(SUMIFS('Detay-Poz Listesi'!$L$5:$L$487,'Detay-Poz Listesi'!$A$5:$A$487,A29,'Detay-Poz Listesi'!$C$5:$C$487,C29,'Detay-Poz Listesi'!$D$5:$D$487,16),2) -> 0 | G29: =ROUND(SUM(D29:F29),2) -> 422.09 | H29: 8.45 | J29: 1 | K29: =ROUND(G29*J29,2) -> 422.09 | L29: =ROUND(H29*J29,2) -> 8.45
A30: 118 | B30: ЛШМ-3* | C30: Вид Б | D30: =ROUND(SUMIFS('Detay-Poz Listesi'!$L$5:$L$487,'Detay-Poz Listesi'!$A$5:$A$487,A30,'Detay-Poz Listesi'!$C$5:$C$487,C30,'Detay-Poz Listesi'!$D$5:$D$487,8),2) -> 22.65 | E30: =ROUND(SUMIFS('Detay-Poz Listesi'!$L$5:$L$487,'Detay-Poz Listesi'!$A$5:$A$487,A30,'Detay-Poz Listesi'!$C$5:$C$487,C30,'Detay-Poz Listesi'!$D$5:$D$487,14),2) -> 327.01 | F30: =ROUND(SUMIFS('Detay-Poz Listesi'!$L$5:$L$487,'Detay-Poz Listesi'!$A$5:$A$487,A30,'Detay-Poz Listesi'!$C$5:$C$487,C30,'Detay-Poz Listesi'!$D$5:$D$487,16),2) -> 0 | G30: =ROUND(SUM(D30:F30),2) -> 349.66 | H30: 6.81 | J30: 1 | K30: =ROUND(G30*J30,2) -> 349.66 | L30: =ROUND(H30*J30,2) -> 6.81
A31: 119 | B31: ЛШМ-3* | C31: Вид В | D31: =ROUND(SUMIFS('Detay-Poz Listesi'!$L$5:$L$487,'Detay-Poz Listesi'!$A$5:$A$487,A31,'Detay-Poz Listesi'!$C$5:$C$487,C31,'Detay-Poz Listesi'!$D$5:$D$487,8),2) -> 37.83 | E31: =ROUND(SUMIFS('Detay-Poz Listesi'!$L$5:$L$487,'Detay-Poz Listesi'!$A$5:$A$487,A31,'Detay-Poz Listesi'!$C$5:$C$487,C31,'Detay-Poz Listesi'!$D$5:$D$487,14),2) -> 504.21 | F31: =ROUND(SUMIFS('Detay-Poz Listesi'!$L$5:$L$487,'Detay-Poz Listesi'!$A$5:$A$487,A31,'Detay-Poz Listesi'!$C$5:$C$487,C31,'Detay-Poz Listesi'!$D$5:$D$487,16),2) -> 74.61 | G31: =ROUND(SUM(D31:F31),2) -> 616.65 | H31: 13.35 | J31: 1 | K31: =ROUND(G31*J31,2) -> 616.65 | L31: =ROUND(H31*J31,2) -> 13.35
A32: 120 | B32: ЛШМ-3* | C32: Вид Г | D32: =ROUND(SUMIFS('Detay-Poz Listesi'!$L$5:$L$487,'Detay-Poz Listesi'!$A$5:$A$487,A32,'Detay-Poz Listesi'!$C$5:$C$487,C32,'Detay-Poz Listesi'!$D$5:$D$487,8),2) -> 53.75 | E32: =ROUND(SUMIFS('Detay-Poz Listesi'!$L$5:$L$487,'Detay-Poz Listesi'!$A$5:$A$487,A32,'Detay-Poz Listesi'!$C$5:$C$487,C32,'Detay-Poz Listesi'!$D$5:$D$487,14),2) -> 689.61 | F32: =ROUND(SUMIFS('Detay-Poz Listesi'!$L$5:$L$487,'Detay-Poz Listesi'!$A$5:$A$487,A32,'Detay-Poz Listesi'!$C$5:$C$487,C32,'Detay-Poz Listesi'!$D$5:$D$487,16),2) -> 136.78 | G32: =ROUND(SUM(D32:F32),2) -> 880.14 | H32: 16.17 | I32: 28.03 | J32: 1 | K32: =ROUND(G32*J32,2) -> 880.14 | L32: =ROUND(H32*J32,2) -> 16.17
A33: 121 | B33: ЛШМ-3-1 | C33: Вид А | D33: =ROUND(SUMIFS('Detay-Poz Listesi'!$L$5:$L$487,'Detay-Poz Listesi'!$A$5:$A$487,A33,'Detay-Poz Listesi'!$C$5:$C$487,C33,'Detay-Poz Listesi'!$D$5:$D$487,8),2) -> 22.65 | E33: =ROUND(SUMIFS('Detay-Poz Listesi'!$L$5:$L$487,'Detay-Poz Listesi'!$A$5:$A$487,A33,'Detay-Poz Listesi'!$C$5:$C$487,C33,'Detay-Poz Listesi'!$D$5:$D$487,14),2) -> 327.39 | F33: =ROUND(SUMIFS('Detay-Poz Listesi'!$L$5:$L$487,'Detay-Poz Listesi'!$A$5:$A$487,A33,'Detay-Poz Listesi'!$C$5:$C$487,C33,'Detay-Poz Listesi'!$D$5:$D$487,16),2) -> 0 | G33: =ROUND(SUM(D33:F33),2) -> 350.04 | H33: 6.83 | J33: 1 | K33: =ROUND(G33*J33,2) -> 350.04 | L33: =ROUND(H33*J33,2) -> 6.83
A34: 122 | B34: ЛШМ-3-1 | C34: Вид Б | D34: =ROUND(SUMIFS('Detay-Poz Listesi'!$L$5:$L$487,'Detay-Poz Listesi'!$A$5:$A$487,A34,'Detay-Poz Listesi'!$C$5:$C$487,C34,'Detay-Poz Listesi'!$D$5:$D$487,8),2) -> 28.12 | E34: =ROUND(SUMIFS('Detay-Poz Listesi'!$L$5:$L$487,'Detay-Poz Listesi'!$A$5:$A$487,A34,'Detay-Poz Listesi'!$C$5:$C$487,C34,'Detay-Poz Listesi'!$D$5:$D$487,14),2) -> 393.28 | F34: =ROUND(SUMIFS('Detay-Poz Listesi'!$L$5:$L$487,'Detay-Poz Listesi'!$A$5:$A$487,A34,'Detay-Poz Listesi'!$C$5:$C$487,C34,'Detay-Poz Listesi'!$D$5:$D$487,16),2) -> 0 | G34: =ROUND(SUM(D34:F34),2) -> 421.4 | H34: 8.47 | J34: 1 | K34: =ROUND(G34*J34,2) -> 421.4 | L34: =ROUND(H34*J34,2) -> 8.47
A35: 123 | B35: ЛШМ-3-1 | C35: Вид В | D35: =ROUND(SUMIFS('Detay-Poz Listesi'!$L$5:$L$487,'Detay-Poz Listesi'!$A$5:$A$487,A35,'Detay-Poz Listesi'!$C$5:$C$487,C35,'Detay-Poz Listesi'!$D$5:$D$487,8),2) -> 37.83 | E35: =ROUND(SUMIFS('Detay-Poz Listesi'!$L$5:$L$487,'Detay-Poz Listesi'!$A$5:$A$487,A35,'Detay-Poz Listesi'!$C$5:$C$487,C35,'Detay-Poz Listesi'!$D$5:$D$487,14),2) -> 488.17 | F35: =ROUND(SUMIFS('Detay-Poz Listesi'!$L$5:$L$487,'Detay-Poz Listesi'!$A$5:$A$487,A35,'Detay-Poz Listesi'!$C$5:$C$487,C35,'Detay-Poz Listesi'!$D$5:$D$487,16),2) -> 74.61 | G35: =ROUND(SUM(D35:F35),2) -> 600.61 | H35: 13.35 | J35: 1 | K35: =ROUND(G35*J35,2) -> 600.61 | L35: =ROUND(H35*J35,2) -> 13.35
A36: 124 | B36: ЛШМ-3-1 | C36: Вид Г | D36: =ROUND(SUMIFS('Detay-Poz Listesi'!$L$5:$L$487,'Detay-Poz Listesi'!$A$5:$A$487,A36,'Detay-Poz Listesi'!$C$5:$C$487,C36,'Detay-Poz Listesi'!$D$5:$D$487,8),2) -> 53.75 | E36: =ROUND(SUMIFS('Detay-Poz Listesi'!$L$5:$L$487,'Detay-Poz Listesi'!$A$5:$A$487,A36,'Detay-Poz Listesi'!$C$5:$C$487,C36,'Detay-Poz Listesi'!$D$5:$D$487,14),2) -> 689.61 | F36: =ROUND(SUMIFS('Detay-Poz Listesi'!$L$5:$L$487,'Detay-Poz Listesi'!$A$5:$A$487,A36,'Detay-Poz Listesi'!$C$5:$C$487,C36,'Detay-Poz Listesi'!$D$5:$D$487,16),2) -> 136.78 | G36: =ROUND(SUM(D36:F36),2) -> 880.14 | H36: 16.17 | I36: 28.03 | J36: 1 | K36: =ROUND(G36*J36,2) -> 880.14 | L36: =ROUND(H36*J36,2) -> 16.17
A37: 125 | B37: ЛШМ-4 | C37: Вид А | D37: =ROUND(SUMIFS('Detay-Poz Listesi'!$L$5:$L$487,'Detay-Poz Listesi'!$A$5:$A$487,A37,'Detay-Poz Listesi'!$C$5:$C$487,C37,'Detay-Poz Listesi'!$D$5:$D$487,8),2) -> 31.85 | E37: =ROUND(SUMIFS('Detay-Poz Listesi'!$L$5:$L$487,'Detay-Poz Listesi'!$A$5:$A$487,A37,'Detay-Poz Listesi'!$C$5:$C$487,C37,'Detay-Poz Listesi'!$D$5:$D$487,14),2) -> 358.85 | F37: =ROUND(SUMIFS('Detay-Poz Listesi'!$L$5:$L$487,'Detay-Poz Listesi'!$A$5:$A$487,A37,'Detay-Poz Listesi'!$C$5:$C$487,C37,'Detay-Poz Listesi'!$D$5:$D$487,16),2) -> 74.61 | G37: =ROUND(SUM(D37:F37),2) -> 465.31 | H37: 10.13 | J37: 1 | K37: =ROUND(G37*J37,2) -> 465.31 | L37: =ROUND(H37*J37,2) -> 10.13
A38: 126 | B38: ЛШМ-4 | C38: Вид Б | D38: =ROUND(SUMIFS('Detay-Poz Listesi'!$L$5:$L$487,'Detay-Poz Listesi'!$A$5:$A$487,A38,'Detay-Poz Listesi'!$C$5:$C$487,C38,'Detay-Poz Listesi'!$D$5:$D$487,8),2) -> 31.85 | E38: =ROUND(SUMIFS('Detay-Poz Listesi'!$L$5:$L$487,'Detay-Poz Listesi'!$A$5:$A$487,A38,'Detay-Poz Listesi'!$C$5:$C$487,C38,'Detay-Poz Listesi'!$D$5:$D$487,14),2) -> 461.17 | F38: =ROUND(SUMIFS('Detay-Poz Listesi'!$L$5:$L$487,'Detay-Poz Listesi'!$A$5:$A$487,A38,'Detay-Poz Listesi'!$C$5:$C$487,C38,'Detay-Poz Listesi'!$D$5:$D$487,16),2) -> 74.61 | G38: =ROUND(SUM(D38:F38),2) -> 567.63 | H38: 10.13 | I38: 17.55 | J38: 1 | K38: =ROUND(G38*J38,2) -> 567.63 | L38: =ROUND(H38*J38,2) -> 10.13
A39: 127 | B39: ЛШМ-4 | C39: Вид В | D39: =ROUND(SUMIFS('Detay-Poz Listesi'!$L$5:$L$487,'Detay-Poz Listesi'!$A$5:$A$487,A39,'Detay-Poz Listesi'!$C$5:$C$487,C39,'Detay-Poz Listesi'!$D$5:$D$487,8),2) -> 43.8 | E39: =ROUND(SUMIFS('Detay-Poz Listesi'!$L$5:$L$487,'Detay-Poz Listesi'!$A$5:$A$487,A39,'Detay-Poz Listesi'!$C$5:$C$487,C39,'Detay-Poz Listesi'!$D$5:$D$487,14),2) -> 579.56 | F39: =ROUND(SUMIFS('Detay-Poz Listesi'!$L$5:$L$487,'Detay-Poz Listesi'!$A$5:$A$487,A39,'Detay-Poz Listesi'!$C$5:$C$487,C39,'Detay-Poz Listesi'!$D$5:$D$487,16),2) -> 0 | G39: =ROUND(SUM(D39:F39),2) -> 623.36 | H39: 12.38 | J39: 1 | K39: =ROUND(G39*J39,2) -> 623.36 | L39: =ROUND(H39*J39,2) -> 12.38
A40: 128 | B40: ЛШМ-4 | C40: Вид Д | D40: =ROUND(SUMIFS('Detay-Poz Listesi'!$L$5:$L$487,'Detay-Poz Listesi'!$A$5:$A$487,A40,'Detay-Poz Listesi'!$C$5:$C$487,C40,'Detay-Poz Listesi'!$D$5:$D$487,8),2) -> 43.8 | E40: =ROUND(SUMIFS('Detay-Poz Listesi'!$L$5:$L$487,'Detay-Poz Listesi'!$A$5:$A$487,A40,'Detay-Poz Listesi'!$C$5:$C$487,C40,'Detay-Poz Listesi'!$D$5:$D$487,14),2) -> 571.97 | F40: =ROUND(SUMIFS('Detay-Poz Listesi'!$L$5:$L$487,'Detay-Poz Listesi'!$A$5:$A$487,A40,'Detay-Poz Listesi'!$C$5:$C$487,C40,'Detay-Poz Listesi'!$D$5:$D$487,16),2) -> 0 | G40: =ROUND(SUM(D40:F40),2) -> 615.77 | H40: 12.38 | J40: 1 | K40: =ROUND(G40*J40,2) -> 615.77 | L40: =ROUND(H40*J40,2) -> 12.38
A41: 128.1 | B41: ЛШМ-4 | C41: Вид Г | D41: =ROUND(SUMIFS('Detay-Poz Listesi'!$L$5:$L$487,'Detay-Poz Listesi'!$A$5:$A$487,A41,'Detay-Poz Listesi'!$C$5:$C$487,C41,'Detay-Poz Listesi'!$D$5:$D$487,8),2) -> 41.06 | E41: =ROUND(SUMIFS('Detay-Poz Listesi'!$L$5:$L$487,'Detay-Poz Listesi'!$A$5:$A$487,A41,'Detay-Poz Listesi'!$C$5:$C$487,C41,'Detay-Poz Listesi'!$D$5:$D$487,14),2) -> 571.97 | F41: =ROUND(SUMIFS('Detay-Poz Listesi'!$L$5:$L$487,'Detay-Poz Listesi'!$A$5:$A$487,A41,'Detay-Poz Listesi'!$C$5:$C$487,C41,'Detay-Poz Listesi'!$D$5:$D$487,16),2) -> 0 | G41: =ROUND(SUM(D41:F41),2) -> 613.03 | H41: 12.38 | J41: 1 | K41: =ROUND(G41*J41,2) -> 613.03 | L41: =ROUND(H41*J41,2) -> 12.38
...

Sheet Detay-Poz Listesi
A1: POZ LİSTESİ — Betonarme Donatı (kaynak: KJ Albüm 2 / Bölüm 2, pafta 93–190)
A2: Mavi hücreler = çizimden okunan girdi. Siyah hücreler = formül. Adetler BİR eleman içindir.
A4: Pafta | B4: Eleman | C4: Görünüş | D4: Çap (mm) | E4: Sınıf | F4: Boy (mm) | G4: Adet | H4: Uzunluk (mtül) | I4: Birim kütle (kg/m) | J4: Toplam boy (m) | K4: Kütle-hesap (kg) | L4: Kütle-proje (kg) | M4: Fark (kg) | N4: Şekil / Büküm
A5: 93 | B5: ЛШМ-1 | C5: Вид А | D5: 14 | E5: A500 | F5: 2930 | G5: 24 | I5: 1.208 | J5: =IF(F5="",H5,F5/1000*G5) -> 70.32 | K5: =ROUND(J5*I5,2) -> 84.95 | L5: 84.95 | M5: =ROUND(K5-L5,2) -> 0 | N5: Düz çubuk
A6: 93 | B6: ЛШМ-1 | C6: Вид А | D6: 14 | E6: A500 | F6: 3350 | G6: 24 | I6: 1.208 | J6: =IF(F6="",H6,F6/1000*G6) -> 80.4 | K6: =ROUND(J6*I6,2) -> 97.12 | L6: 97.12 | M6: =ROUND(K6-L6,2) -> 0 | N6: Düz çubuk
A7: 93 | B7: ЛШМ-1 | C7: Вид А | D7: 14 | E7: A500 | H7: 112.9 | I7: 1.208 | J7: =IF(F7="",H7,F7/1000*G7) -> 112.9 | K7: =ROUND(J7*I7,2) -> 136.38 | L7: 136.38 | M7: =ROUND(K7-L7,2) -> 0 | N7: Yatay dağıtma (mtül)
A8: 93 | B8: ЛШМ-1 | C8: Вид А | D8: 8 | E8: A240 | F8: 630 | G8: 94 | I8: 0.395 | J8: =IF(F8="",H8,F8/1000*G8) -> 59.22 | K8: =ROUND(J8*I8,2) -> 23.39 | L8: 23.39 | M8: =ROUND(K8-L8,2) -> 0 | N8: Etriye/fikstur: 460 duz + 2x80 kanca (L=630)
A9: 94 | B9: ЛШМ-1 | C9: Вид Б | D9: 14 | E9: A500 | F9: 3350 | G9: 24 | I9: 1.208 | J9: =IF(F9="",H9,F9/1000*G9) -> 80.4 | K9: =ROUND(J9*I9,2) -> 97.12 | L9: 97.12 | M9: =ROUND(K9-L9,2) -> 0 | N9: Düz çubuk
A10: 94 | B10: ЛШМ-1 | C10: Вид Б | D10: 14 | E10: A500 | F10: 2930 | G10: 24 | I10: 1.208 | J10: =IF(F10="",H10,F10/1000*G10) -> 70.32 | K10: =ROUND(J10*I10,2) -> 84.95 | L10: 84.95 | M10: =ROUND(K10-L10,2) -> 0 | N10: Düz çubuk
A11: 94 | B11: ЛШМ-1 | C11: Вид Б | D11: 14 | E11: A500 | H11: 124.41 | I11: 1.208 | J11: =IF(F11="",H11,F11/1000*G11) -> 124.41 | K11: =ROUND(J11*I11,2) -> 150.29 | L11: 150.29 | M11: =ROUND(K11-L11,2) -> 0 | N11: Yatay dağıtma (mtül)
A12: 94 | B12: ЛШМ-1 | C12: Вид Б | D12: 8 | E12: A240 | F12: 630 | G12: 94 | I12: 0.395 | J12: =IF(F12="",H12,F12/1000*G12) -> 59.22 | K12: =ROUND(J12*I12,2) -> 23.39 | L12: 23.39 | M12: =ROUND(K12-L12,2) -> 0 | N12: Etriye/fikstur: 460 duz + 2x80 kanca (L=630)
A13: 95 | B13: ЛШМ-1 | C13: Вид В | D13: 14 | E13: A500 | F13: 3350 | G13: 18 | I13: 1.208 | J13: =IF(F13="",H13,F13/1000*G13) -> 60.3 | K13: =ROUND(J13*I13,2) -> 72.84 | L13: 72.84 | M13: =ROUND(K13-L13,2) -> 0 | N13: Düz çubuk
A14: 95 | B14: ЛШМ-1 | C14: Вид В | D14: 14 | E14: A500 | F14: 2930 | G14: 18 | I14: 1.208 | J14: =IF(F14="",H14,F14/1000*G14) -> 52.74 | K14: =ROUND(J14*I14,2) -> 63.71 | L14: 63.71 | M14: =ROUND(K14-L14,2) -> 0 | N14: Düz çubuk
A15: 95 | B15: ЛШМ-1 | C15: Вид В | D15: 14 | E15: A500 | F15: 3260 | G15: 38 | I15: 1.208 | J15: =IF(F15="",H15,F15/1000*G15) -> 123.88 | K15: =ROUND(J15*I15,2) -> 149.65 | L15: 149.65 | M15: =ROUND(K15-L15,2) -> 0 | N15: Düz çubuk
A16: 95 | B16: ЛШМ-1 | C16: Вид В | D16: 14 | E16: A500 | H16: 177.1 | I16: 1.208 | J16: =IF(F16="",H16,F16/1000*G16) -> 177.1 | K16: =ROUND(J16*I16,2) -> 213.94 | L16: 213.94 | M16: =ROUND(K16-L16,2) -> 0 | N16: Yatay dağıtma (mtül)
A17: 95 | B17: ЛШМ-1 | C17: Вид В | D17: 8 | E17: A240 | F17: 630 | G17: 145 | I17: 0.395 | J17: =IF(F17="",H17,F17/1000*G17) -> 91.35 | K17: =ROUND(J17*I17,2) -> 36.08 | L17: 36.08 | M17: =ROUND(K17-L17,2) -> 0 | N17: Etriye/fikstur: 460 duz + 2x80 kanca (L=630)
A18: 96 | B18: ЛШМ-1 | C18: Вид Г | D18: 14 | E18: A500 | F18: 3350 | G18: 33 | I18: 1.208 | J18: =IF(F18="",H18,F18/1000*G18) -> 110.55 | K18: =ROUND(J18*I18,2) -> 133.54 | L18: 133.54 | M18: =ROUND(K18-L18,2) -> 0 | N18: Düz çubuk
A19: 96 | B19: ЛШМ-1 | C19: Вид Г | D19: 14 | E19: A500 | F19: 2930 | G19: 33 | I19: 1.208 | J19: =IF(F19="",H19,F19/1000*G19) -> 96.69 | K19: =ROUND(J19*I19,2) -> 116.8 | L19: 116.8 | M19: =ROUND(K19-L19,2) -> 0 | N19: Düz çubuk
A20: 96 | B20: ЛШМ-1 | C20: Вид Г | D20: 14 | E20: A500 | F20: 2480 | G20: 16 | I20: 1.208 | J20: =IF(F20="",H20,F20/1000*G20) -> 39.68 | K20: =ROUND(J20*I20,2) -> 47.93 | L20: 47.93 | M20: =ROUND(K20-L20,2) -> 0 | N20: Düz çubuk
A21: 96 | B21: ЛШМ-1 | C21: Вид Г | D21: 14 | E21: A500 | H21: 191.62 | I21: 1.208 | J21: =IF(F21="",H21,F21/1000*G21) -> 191.62 | K21: =ROUND(J21*I21,2) -> 231.48 | L21: 231.48 | M21: =ROUND(K21-L21,2) -> 0 | N21: Yatay dağıtma (mtül)
A22: 96 | B22: ЛШМ-1 | C22: Вид Г | D22: 8 | E22: A240 | F22: 630 | G22: 152 | I22: 0.395 | J22: =IF(F22="",H22,F22/1000*G22) -> 95.76 | K22: =ROUND(J22*I22,2) -> 37.83 | L22: 37.83 | M22: =ROUND(K22-L22,2) -> 0 | N22: Etriye/fikstur: 460 duz + 2x80 kanca (L=630)
A23: 96 | B23: ЛШМ-1 | C23: Вид Г | D23: 16 | E23: A500 | F23: 1970 | G23: 22 | I23: 1.578 | J23: =IF(F23="",H23,F23/1000*G23) -> 43.34 | K23: =ROUND(J23*I23,2) -> 68.39 | L23: 68.39 | M23: =ROUND(K23-L23,2) -> 0 | N23: L-cubuk: 950 x 950 (L=1970)
A24: 97 | B24: ЛШМ-2 | C24: Вид А | D24: 14 | E24: A500 | F24: 3350 | G24: 22 | I24: 1.208 | J24: =IF(F24="",H24,F24/1000*G24) -> 73.7 | K24: =ROUND(J24*I24,2) -> 89.03 | L24: 89.03 | M24: =ROUND(K24-L24,2) -> 0 | N24: Düz çubuk
A25: 97 | B25: ЛШМ-2 | C25: Вид А | D25: 14 | E25: A500 | F25: 2930 | G25: 22 | I25: 1.208 | J25: =IF(F25="",H25,F25/1000*G25) -> 64.46 | K25: =ROUND(J25*I25,2) -> 77.87 | L25: 77.87 | M25: =ROUND(K25-L25,2) -> 0 | N25: Düz çubuk
A26: 97 | B26: ЛШМ-2 | C26: Вид А | D26: 14 | E26: A500 | H26: 125.07 | I26: 1.208 | J26: =IF(F26="",H26,F26/1000*G26) -> 125.07 | K26: =ROUND(J26*I26,2) -> 151.08 | L26: 151.08 | M26: =ROUND(K26-L26,2) -> 0 | N26: Yatay dağıtma (mtül)
A27: 97 | B27: ЛШМ-2 | C27: Вид А | D27: 8 | E27: A240 | F27: 630 | G27: 91 | I27: 0.395 | J27: =IF(F27="",H27,F27/1000*G27) -> 57.33 | K27: =ROUND(J27*I27,2) -> 22.65 | L27: 22.65 | M27: =ROUND(K27-L27,2) -> 0 | N27: Etriye/fikstur: 460 duz + 2x80 kanca (L=630)
A28: 98 | B28: ЛШМ-2 | C28: Вид Б | D28: 14 | E28: A500 | F28: 3350 | G28: 28 | I28: 1.208 | J28: =IF(F28="",H28,F28/1000*G28) -> 93.8 | K28: =ROUND(J28*I28,2) -> 113.31 | L28: 113.31 | M28: =ROUND(K28-L28,2) -> 0 | N28: Düz çubuk
A29: 98 | B29: ЛШМ-2 | C29: Вид Б | D29: 14 | E29: A500 | F29: 2930 | G29: 28 | I29: 1.208 | J29: =IF(F29="",H29,F29/1000*G29) -> 82.04 | K29: =ROUND(J29*I29,2) -> 99.1 | L29: 99.1 | M29: =ROUND(K29-L29,2) -> 0 | N29: Düz çubuk
A30: 98 | B30: ЛШМ-2 | C30: Вид Б | D30: 14 | E30: A500 | H30: 149.09 | I30: 1.208 | J30: =IF(F30="",H30,F30/1000*G30) -> 149.09 | K30: =ROUND(J30*I30,2) -> 180.1 | L30: 180.1 | M30: =ROUND(K30-L30,2) -> 0 | N30: Yatay dağıtma (mtül)
A31: 98 | B31: ЛШМ-2 | C31: Вид Б | D31: 8 | E31: A240 | F31: 630 | G31: 112 | I31: 0.395 | J31: =IF(F31="",H31,F31/1000*G31) -> 70.56 | K31: =ROUND(J31*I31,2) -> 27.87 | L31: 27.87 | M31: =ROUND(K31-L31,2) -> 0 | N31: Etriye/fikstur: 460 duz + 2x80 kanca (L=630)
A32: 99 | B32: ЛШМ-2 | C32: Вид В | D32: 14 | E32: A500 | F32: 3350 | G32: 33 | I32: 1.208 | J32: =IF(F32="",H32,F32/1000*G32) -> 110.55 | K32: =ROUND(J32*I32,2) -> 133.54 | L32: 133.54 | M32: =ROUND(K32-L32,2) -> 0 | N32: Düz çubuk
A33: 99 | B33: ЛШМ-2 | C33: Вид В | D33: 14 | E33: A500 | F33: 2930 | G33: 33 | I33: 1.208 | J33: =IF(F33="",H33,F33/1000*G33) -> 96.69 | K33: =ROUND(J33*I33,2) -> 116.8 | L33: 116.8 | M33: =ROUND(K33-L33,2) -> 0 | N33: Düz çubuk
A34: 99 | B34: ЛШМ-2 | C34: Вид В | D34: 14 | E34: A500 | F34: 2480 | G34: 16 | I34: 1.208 | J34: =IF(F34="",H34,F34/1000*G34) -> 39.68 | K34: =ROUND(J34*I34,2) -> 47.93 | L34: 47.93 | M34: =ROUND(K34-L34,2) -> 0 | N34: Düz çubuk
A35: 99 | B35: ЛШМ-2 | C35: Вид В | D35: 14 | E35: A500 | H35: 194.92 | I35: 1.208 | J35: =IF(F35="",H35,F35/1000*G35) -> 194.92 | K35: =ROUND(J35*I35,2) -> 235.46 | L35: 235.46 | M35: =ROUND(K35-L35,2) -> 0 | N35: Yatay dağıtma (mtül)
A36: 99 | B36: ЛШМ-2 | C36: Вид В | D36: 8 | E36: A240 | F36: 630 | G36: 152 | I36: 0.395 | J36: =IF(F36="",H36,F36/1000*G36) -> 95.76 | K36: =ROUND(J36*I36,2) -> 37.83 | L36: 37.83 | M36: =ROUND(K36-L36,2) -> 0 | N36: Etriye/fikstur: 460 duz + 2x80 kanca (L=630)
A37: 99 | B37: ЛШМ-2 | C37: Вид В | D37: 16 | E37: A500 | F37: 1970 | G37: 22 | I37: 1.578 | J37: =IF(F37="",H37,F37/1000*G37) -> 43.34 | K37: =ROUND(J37*I37,2) -> 68.39 | L37: 68.39 | M37: =ROUND(K37-L37,2) -> 0 | N37: L-cubuk: 950 x 950 (L=1970)
A38: 100 | B38: ЛШМ-2 | C38: Вид Г | D38: 14 | E38: A500 | F38: 3350 | G38: 33 | I38: 1.208 | J38: =IF(F38="",H38,F38/1000*G38) -> 110.55 | K38: =ROUND(J38*I38,2) -> 133.54 | L38: 133.54 | M38: =ROUND(K38-L38,2) -> 0 | N38: Düz çubuk
A39: 100 | B39: ЛШМ-2 | C39: Вид Г | D39: 14 | E39: A500 | F39: 2930 | G39: 33 | I39: 1.208 | J39: =IF(F39="",H39,F39/1000*G39) -> 96.69 | K39: =ROUND(J39*I39,2) -> 116.8 | L39: 116.8 | M39: =ROUND(K39-L39,2) -> 0 | N39: Düz çubuk
A40: 100 | B40: ЛШМ-2 | C40: Вид Г | D40: 14 | E40: A500 | F40: 2480 | G40: 44 | I40: 1.208 | J40: =IF(F40="",H40,F40/1000*G40) -> 109.12 | K40: =ROUND(J40*I40,2) -> 131.82 | L40: 131.82 | M40: =ROUND(K40-L40,2) -> 0 | N40: Düz çubuk
A41: 100 | B41: ЛШМ-2 | C41: Вид Г | D41: 14 | E41: A500 | H41: 254.8 | I41: 1.208 | J41: =IF(F41="",H41,F41/1000*G41) -> 254.8 | K41: =ROUND(J41*I41,2) -> 307.8 | L41: 307.8 | M41: =ROUND(K41-L41,2) -> 0 | N41: Yatay dağıtma (mtül)
...

Sheet Kontrol Notları
A1: PROJE İLE TESPİT EDİLEN TUTARSIZLIKLAR — üretim öncesi proje müellifine sorulmalı
A3: Konum | B3: Tespit | C3: Yapılacak
A4: Genel | B4: Bu albümde haddelenmiş çelik profil (kanal/köşebent/IPE/kutu) YOKTUR. GOST 8240/8509/26020/30245 yalnızca referans doküman listesindedir; profil çizimleri KM albümündedir. | C4: Profil üretimi için KM albümü talep edilmeli.
A5: Genel | B5: Adetler bir eleman içindir; her markanın binada kaç kez tekrarlandığı bu albümde yok. | C5: KJ-62 'monolitik şaft yerleşim planı' alınmalı.
A6: Genel | B6: Yatay dağıtma donatısı metretül (м.п.) olarak verilmiş, kesim boyu yok. | C6: Bindirme boyları ile kesim planı yapılmalı.
A7: Pafta 113, 114 | B7: Spesifikasyonda Ø8 = 28.12 / 23.39 kg, çelik sarfiyat tablosunda 21.40 kg. | C7: Ø8 miktarı doğrulanmalı.
A8: Pafta 103 | B8: Poz 4 (Ø14, 194.92 mtül): 194.92 × 1.208 = 235.46 kg, tabloda 281.44 kg. | C8: Kütle doğrulanmalı.
A9: Pafta 123 | B9: Spesifikasyonda Ø8 = 37.83 kg, sarfiyat tablosunda 62.22 kg. | C9: Ø8 miktarı doğrulanmalı.
A10: Pafta 125 | B10: Poz toplamı Ø14 = 358.85 kg, tabloda 302.19 kg; Ø16 poz 74.61 kg, tabloda 201.67 kg. | C10: Ciddi sapma — tablo yeniden hesaplanmalı.
A11: Pafta 128 | B11: Spesifikasyon ara toplamı 571.96 kg, sarfiyat tablosu 579.55 kg. | C11: Doğrulanmalı.
A12: Pafta 128.1 | B12: Ø8: poz 41.06 kg, tablo 43.80 kg. | C12: Doğrulanmalı.
A13: Pafta 130 | B13: Poz toplamı Ø14 = 476.82 kg, tabloda 545.58 kg. | C13: Doğrulanmalı.
A14: Pafta 133 | B14: Ø16 poz 74.61 kg, tabloda 158.11 kg; Ø8 poz 20.95 kg, tabloda 42.06 kg. | C14: Ciddi sapma.
... A20: Beton | B20: Bazı paftalarda beton 'C25/30' (212-101-1101), bazılarında 'C25/30 W10 F150' (212-101-1104) yazılmış. Genel notlar 0.000 kotu altı için W10 C25/30 F150 + sülfata dayanıklı çimento şartı koyuyor. | C20: Tüm elemanlar için W10 F150 kabul edilmeli.
