Workbook

Sheet BOM
B1: Наименование | C1: malzeme | D1: Артикул | E1: Номенклатура | F1: Цена,тг1 | G1: Цена,тг | H1: СУММ. | I1: Кол- во | J1: Ед.изм | K1: завод изготовитель | L1: MALZ
B2: MAIN PANEL | E2: MAIN PANEL | H2: =SUM(H3:H22) -> 413312.8 | I2: 1 | J2: комплект | K2: TEKSAN | L2: =SUM(L3:L22) -> 413312.8
B3: MAIN PANEL | C3: korpus | D3: 719-15085 | E3: Мет. корпус ВРУ 1700x700x450 + база 100x700, IP31 | F3: 154595 | G3: 154595 | H3: =G3*I3 -> 154595 | I3: 1 | J3: ШТ. | K3: teksan f | L3: =H3 -> 154595
B4: MAIN PANEL | C4: tms | D4: 131362 | E4: Авт. выкл. NXM-125S/3Р 100A 25кА (R) | F4: 18517 | G4: 11110.2 | H4: =G4*I4 -> 22220.4 | I4: 2 | J4: ШТ. | K4: chint | L4: =H4 -> 22220.4
B5: MAIN PANEL | C5: PH | D5: KONTROL EDİLECEK | E5: Независимый расцепитель SHT для NXM-125 AC230V | F5: 0 | G5: 0 | H5: =G5*I5 -> 0 | I5: 1 | J5: ШТ. | K5: chint | L5: =H5 -> 0
B6: MAIN PANEL | C6: MANTAR BUTON | D6: 574862 | E6: Кнопка управления «Грибок» Φ40 с фиксацией NP2-BS542, красная 1НЗ IP40 | F6: 1799 | G6: 1079.4 | H6: =G6*I6 -> 1079.4 | I6: 1 | J6: ШТ. | K6: chint | L6: =H6 -> 1079.4
B7: MAIN PANEL | C7: pp | D7: 403037 | E7: Откидной выключатель-разъединитель NHR17-125/3, 3P, 125А, с плавкими вставками | F7: 2070 | G7: 1242 | H7: =G7*I7 -> 1242 | I7: 1 | J7: ШТ. | K7: chint | L7: =H7 -> 1242
B8: MAIN PANEL | C8: pp | D8: 521257 | E8: Плавкая вставка предохранителя RT36-00-160, габарит 00, 125А | F8: 1545 | G8: 927 | H8: =G8*I8 -> 2781 | I8: 3 | J8: ШТ. | K8: chint | L8: =H8 -> 2781
B9: MAIN PANEL | C9: opn | D9: 308602 | E9: Ограничитель имп. перенапр. NXU-I+II 4P In=25kA Uc=385В Im=50kA (R) | F9: 56704 | G9: 34022.4 | H9: =G9*I9 -> 34022.4 | I9: 1 | J9: ШТ. | K9: chint | L9: =H9 -> 34022.4
B10: MAIN PANEL | C10: uzo | D10: 280934 | E10: УЗО NXL-63 10kA 3P+N 63A 300mA AC (R) | F10: 15688 | G10: 9412.8 | H10: =G10*I10 -> 9412.8 | I10: 1 | J10: ШТ. | K10: chint | L10: =H10 -> 9412.8
B11: MAIN PANEL | C11: uzo | D11: 200229 | E11: УЗО NL1-63 6kA 4P 25A 300mA тип AC (R) | F11: 14768 | G11: 8860.8 | H11: =G11*I11 -> 8860.8 | I11: 1 | J11: ШТ. | K11: chint | L11: =H11 -> 8860.8
B12: MAIN PANEL | C12: oto | D12: 813875 | E12: Авт. выкл. NXB-63H 3P 40A 10кА х-ка C (R) | F12: 11002 | G12: 6601.2 | H12: =G12*I12 -> 26404.8 | I12: 4 | J12: ШТ. | K12: chint | L12: =H12 -> 26404.8
B13: MAIN PANEL | C13: oto | D13: 813874 | E13: Авт. выкл. NXB-63H 3P 32A 10кА х-ка C (R) | F13: 11771 | G13: 7062.6 | H13: =G13*I13 -> 21187.8 | I13: 3 | J13: ШТ. | K13: chint | L13: =H13 -> 21187.8
B14: MAIN PANEL | C14: oto | D14: 813873 | E14: Авт. выкл. NXB-63H 3P 25A 10кА х-ка C (R) | F14: 10552 | G14: 6331.2 | H14: =G14*I14 -> 6331.2 | I14: 1 | J14: ШТ. | K14: chint | L14: =H14 -> 6331.2
... B22: MAIN PANEL | C22: Монтажные работы | D22: Монтажные работы | E22: Монтажные работы | F22: 10 | G22: 100 | H22: =G22*I22 -> 60000 | I22: 600 | J22: ШТ. | K22: Монтажные работы | L22: =H22 -> 60000
B23: ПОДВАЛ-ELP | E23: ПОДВАЛ-ELP | H23: =SUM(H24:H39) -> 231510 | I23: 1 | J23: комплект | K23: TEKSAN | L23: =SUM(L24:L39) -> 231510
B24: ПОДВАЛ-ELP | C24: korpus | E24: SHRV sıva altı 1400x700x180 mm | F24: 100000 | G24: 100000 | H24: =G24*I24 -> 100000 | I24: 1 | J24: ШТ. | K24: teksan f | L24: =H24 -> 100000
B25: ПОДВАЛ-ELP | C25: oto | D25: 814172 | E25: Авт. выкл. NXB-63 3P 25A 6кА х-ка C (R) | F25: 4761 | G25: 2856.6 | H25: =G25*I25 -> 2856.6 | I25: 1 | J25: ШТ. | K25: chint | L25: =H25 -> 2856.6
B26: ПОДВАЛ-ELP | C26: oto | D26: 296708 | E26: Авт. выкл. NXB-63S 1P 6А 4.5kA х-ка C (R) | F26: 947 | G26: 568.2 | H26: =G26*I26 -> 1704.6 | I26: 3 | J26: ШТ. | K26: chint | L26: =H26 -> 1704.6
B27: ПОДВАЛ-ELP | C27: sinyal lamb | D27: 593076 | E27: Индикатор ND16-22D/2 желтый AC/DC230В (R) | F27: 571 | G27: 342.6 | H27: =G27*I27 -> 342.6 | I27: 1 | J27: ШТ. | K27: chint | L27: =H27 -> 342.6
B28: ПОДВАЛ-ELP | C28: sinyal lamb | D28: 593077 | E28: Индикатор ND16-22D/2 зеленый AC/DC230В (R) | F28: 589 | G28: 353.4 | H28: =G28*I28 -> 353.4 | I28: 1 | J28: ШТ. | K28: chint | L28: =H28 -> 353.4
B29: ПОДВАЛ-ELP | C29: sinyal lamb | D29: 593075 | E29: Индикатор ND16-22D/2 красный AC/DC230В (R) | F29: 571 | G29: 342.6 | H29: =G29*I29 -> 342.6 | I29: 1 | J29: ШТ. | K29: chint | L29: =H29 -> 342.6
B30: ПОДВАЛ-ELP | C30: uzo | D30: 280721 | E30: УЗО NXL-63 6kA 1P+N 25A 30mA AC (R) | F30: 6747 | G30: 4048.2 | H30: =G30*I30 -> 8096.4 | I30: 2 | J30: ШТ. | K30: chint | L30: =H30 -> 8096.4
B31: ПОДВАЛ-ELP | C31: uzo | D31: 280789 | E31: УЗО NXL-63 6kA 3P+N 25A 30mA AC (R) | F31: 12143 | G31: 7285.8 | H31: =G31*I31 -> 14571.6 | I31: 2 | J31: ШТ. | K31: chint | L31: =H31 -> 14571.6
B32: ПОДВАЛ-ELP | C32: uzo | D32: 280791 | E32: УЗО NXL-63 6kA 3P+N 40A 30mA AC (R) | F32: 12143 | G32: 7285.8 | H32: =G32*I32 -> 7285.8 | I32: 1 | J32: ШТ. | K32: chint | L32: =H32 -> 7285.8
B33: ПОДВАЛ-ELP | C33: oto | D33: 296696 | E33: Авт. выкл. NXB-63S 1P 10А 4.5kA х-ка B (R) | F33: 871 | G33: 522.6 | H33: =G33*I33 -> 2090.4 | I33: 4 | J33: ШТ. | K33: chint | L33: =H33 -> 2090.4
B34: ПОДВАЛ-ELP | C34: oto | D34: 296710 | E34: Авт. выкл. NXB-63S 1P 16А 4.5kA х-ка C (R) | F34: 760 | G34: 456 | H34: =G34*I34 -> 3192 | I34: 7 | J34: ШТ. | K34: chint | L34: =H34 -> 3192
B35: ПОДВАЛ-ELP | C35: oto | D35: 814170 | E35: Авт. выкл. NXB-63 3P 16A 6кА х-ка C (R) | F35: 4875 | G35: 2925 | H35: =G35*I35 -> 5850 | I35: 2 | J35: ШТ. | K35: chint | L35: =H35 -> 5850
B36: ПОДВАЛ-ELP | C36: KLEMENS | D36: 130301144_ | E36: ЗВИ 3 ПВХ (1,0-2,5мм² 3А) 12 пар UNIT | F36: 172 | G36: 172 | H36: =G36*I36 -> 3096 | I36: 18 | J36: ШТ. | K36: pys | L36: =H36 -> 3096
... B39: ПОДВАЛ-ELP | C39: Монтажные работы | D39: Монтажные работы | E39: Монтажные работы | F39: 10 | G39: 100 | H39: =G39*I39 -> 36000 | I39: 360 | J39: ШТ. | K39: Монтажные работы | L39: =H39 -> 36000
B40: АДМИНИСТРАЦИЯ-ELP | E40: АДМИНИСТРАЦИЯ-ELP | H40: =SUM(H41:H54) -> 232963.6 | I40: 1 | J40: комплект | K40: TEKSAN | L40: =SUM(L41:L54) -> 232963.6
B41: АДМИНИСТРАЦИЯ-ELP | C41: korpus | E41: SHRV sıva altı 1400x700x180 mm | F41: 100000 | G41: 100000 | H41: =G41*I41 -> 100000 | I41: 1 | J41: ШТ. | K41: teksan f | L41: =H41 -> 100000
B42: АДМИНИСТРАЦИЯ-ELP | C42: oto | D42: 814172 | E42: Авт. выкл. NXB-63 3P 25A 6кА х-ка C (R) | F42: 4761 | G42: 2856.6 | H42: =G42*I42 -> 2856.6 | I42: 1 | J42: ШТ. | K42: chint | L42: =H42 -> 2856.6
B43: АДМИНИСТРАЦИЯ-ELP | C43: oto | D43: 296708 | E43: Авт. выкл. NXB-63S 1P 6А 4.5kA х-ка C (R) | F43: 947 | G43: 568.2 | H43: =G43*I43 -> 1704.6 | I43: 3 | J43: ШТ. | K43: chint | L43: =H43 -> 1704.6
B44: АДМИНИСТРАЦИЯ-ELP | C44: sinyal lamb | D44: 593076 | E44: Индикатор ND16-22D/2 желтый AC/DC230В (R) | F44: 571 | G44: 342.6 | H44: =G44*I44 -> 342.6 | I44: 1 | J44: ШТ. | K44: chint | L44: =H44 -> 342.6
B45: АДМИНИСТРАЦИЯ-ELP | C45: sinyal lamb | D45: 593077 | E45: Индикатор ND16-22D/2 зеленый AC/DC230В (R) | F45: 589 | G45: 353.4 | H45: =G45*I45 -> 353.4 | I45: 1 | J45: ШТ. | K45: chint | L45: =H45 -> 353.4
B46: АДМИНИСТРАЦИЯ-ELP | C46: sinyal lamb | D46: 593075 | E46: Индикатор ND16-22D/2 красный AC/DC230В (R) | F46: 571 | G46: 342.6 | H46: =G46*I46 -> 342.6 | I46: 1 | J46: ШТ. | K46: chint | L46: =H46 -> 342.6
B47: АДМИНИСТРАЦИЯ-ELP | C47: uzo | D47: 280789 | E47: УЗО NXL-63 6kA 3P+N 25A 30mA AC (R) | F47: 12143 | G47: 7285.8 | H47: =G47*I47 -> 7285.8 | I47: 1 | J47: ШТ. | K47: chint | L47: =H47 -> 7285.8
B48: АДМИНИСТРАЦИЯ-ELP | C48: uzo | D48: 280791 | E48: УЗО NXL-63 6kA 3P+N 40A 30mA AC (R) | F48: 12143 | G48: 7285.8 | H48: =G48*I48 -> 21857.4 | I48: 3 | J48: ШТ. | K48: chint | L48: =H48 -> 21857.4
B49: АДМИНИСТРАЦИЯ-ELP | C49: oto | D49: 296696 | E49: Авт. выкл. NXB-63S 1P 10А 4.5kA х-ка B (R) | F49: 871 | G49: 522.6 | H49: =G49*I49 -> 5748.6 | I49: 11 | J49: ШТ. | K49: chint | L49: =H49 -> 5748.6
...

Sheet FIYAT
A1: Наименование | B1: СУММ. | C1: Кол-во | D1: Ед.изм | E1: MALZ
A2: MAIN PANEL | B2: =BOM!H2 -> 413312.8 | C2: 1 | D2: комплект | E2: =BOM!L2 -> 413312.8
A3: ПОДВАЛ-ELP | B3: =BOM!H23 -> 231510 | C3: 1 | D3: комплект | E3: =BOM!L23 -> 231510
A4: АДМИНИСТРАЦИЯ-ELP | B4: =BOM!H40 -> 232963.6 | C4: 1 | D4: комплект | E4: =BOM!L40 -> 232963.6
A5: ZK-ELP | B5: =BOM!H55 -> 376801.2 | C5: 1 | D5: комплект | E5: =BOM!L55 -> 376801.2
A6: 2K-ELP | B6: =BOM!H75 -> 269323.8 | C6: 1 | D6: комплект | E6: =BOM!L75 -> 269323.8
A7: КРЫША-ELP | B7: =BOM!H95 -> 296133.6 | C7: 1 | D7: комплект | E7: =BOM!L95 -> 296133.6
A8: КОТЕЛЬНАЯ-ELP | B8: =BOM!H115 -> 299945.8 | C8: 1 | D8: комплект | E8: =BOM!L115 -> 299945.8
