Workbook
Name AL_A: KURALLAR!$C$191:$C$199
Name AL_KOD: KURALLAR!$A$191:$A$199
Name AL_MM2: KURALLAR!$B$191:$B$199
Name BAG_ADET_M: KURALLAR!$C$130
Name BARA_DERATING: KURALLAR!$C$138
Name BARA_ESIK_A: KURALLAR!$C$137
Name BARA_FIRE: KURALLAR!$C$139
Name CU_A: KURALLAR!$C$180:$C$187
Name CU_KOD: KURALLAR!$A$180:$A$187
Name CU_MM2: KURALLAR!$B$180:$B$187
Name DK_UCRET: KURALLAR!$C$71
Name F_BK: FIYAT!$AC$2:$AC$310
Name F_G: FIYAT!$X$2:$X$310
Name F_IN: FIYAT!$AI$2:$AI$310
Name F_INKOR: FIYAT!$AJ$2:$AJ$310
Name F_KAP: FIYAT!$AA$2:$AA$310
Name F_KK: FIYAT!$AF$2:$AF$310
Name F_KLN: FIYAT!$AG$2:$AG$310
Name F_KPE: FIYAT!$AH$2:$AH$310
Name F_MODUL: FIYAT!$U$2:$U$310
Name F_PAKET: FIYAT!$V$2:$V$310
Name F_TEL: FIYAT!$AD$2:$AD$310
Name F_TELM: FIYAT!$AE$2:$AE$310
Name F_Y: FIYAT!$Y$2:$Y$310
Name FA: FIYAT!$C$2:$C$310
Name FIRMA: KURALLAR!$C$9
Name FIYAT_AD: FIYAT!$D$2:$D$310
Name FIYAT_BIRIM: FIYAT!$I$2:$I$310
Name FIYAT_DURUM: FIYAT!$Q$2:$Q$310
Name FIYAT_LISTE: FIYAT!$E$2:$E$310
Name FIYAT_MARKA: FIYAT!$J$2:$J$310
Name FIYAT_NET: FIYAT!$F$2:$F$310
Name GECERLILIK: KURALLAR!$C$10
Name ISCILIK_KAT: KURALLAR!$C$72
Name ISKONTO: KURALLAR!$C$14
Name IZOLATOR_ARALIK_M: KURALLAR!$C$142
Name KABLO_FIRE: KURALLAR!$C$126
Name KABLO_IN_ALT: KURALLAR!$A$149:$A$159
Name KABLO_KESIT: KURALLAR!$B$149:$B$159
Name KABLO_MAX_IN: KURALLAR!$C$133
Name KANAL_FIRE: KURALLAR!$C$141
Name KAPI_TOPRAK_M: KURALLAR!$C$143
Name KAR_ORANI: KURALLAR!$C$13
Name KAYNAK_KOD: KURALLAR!$A$51:$A$66
Name KAYNAK_TARIH: KURALLAR!$C$51:$C$66
Name KLEMENS_ALT: KURALLAR!$A$163:$A$168
Name KLEMENS_KES: KURALLAR!$B$163:$B$168
Name KLEMENS_MAX_KESIT: KURALLAR!$C$136
Name KLEMENS_YEDEK: KURALLAR!$C$127
Name KORPUS_IC_PAY_MM: KURALLAR!$C$140
Name KORPUS_YEDEK: KURALLAR!$C$145
Name KUMANDA_KESIT: KURALLAR!$C$131
Name KUR_AD: KURALLAR!$A$19:$A$23
Name KUR_DEG: KURALLAR!$B$19:$B$23
Name MARKA_AD: KURALLAR!$A$27:$A$47
Name MARKA_IZIN: KURALLAR!$D$27:$D$47
Name MARKA_KAT: KURALLAR!$C$27:$C$47
Name MARKA_PARA: KURALLAR!$B$27:$B$47
Name MODUL_MM: KURALLAR!$C$144
Name MONTAJ_MALZ_KAT: KURALLAR!$C$73

Sheet BOM
A1: Наименование | B1: malzeme | C1: Артикул | D1: Номенклатура | E1: Цена,тг | F1: Цена,тг | G1: СУММ. | H1: Кол- во | I1: Ед.изм | J1: завод из готовитель | K1: Источник | L1: malz | M1: PANO ADET | N1: ROL | O1: NORM | P1: DURUM | Q1: NOT
A2: =D2 -> ВРУ-1 (260917 fok atr) | D2: ВРУ-1 (260917 fok atr) | H2: 1 | I2: комплект | J2: TEKLED electric | K2: 260917 | M2: =H2 -> 1
A3: =A2 -> ВРУ-1 (260917 fok atr) | B3: korpus | C3: 719-15696 | D3: Shit 2000x800x450+100mm | E3: =IF(ISNA(MATCH($C3,FA,0)),"",IF(INDEX(FIYAT_LISTE,MATCH($C3,FA,0))="","",INDEX(FIYAT_LISTE,MATCH($C3,FA,0)))) -> 172785 | F3: =IF(ISNA(MATCH($C3,FA,0)),"",IF(INDEX(FIYAT_NET,MATCH($C3,FA,0))="","",INDEX(FIYAT_NET,MATCH($C3,FA,0)))) -> 103671 | G3: =IF(OR(F3="",H3=""),"",H3*F3) -> 103671 | H3: 1 | I3: =IF(ISNA(MATCH($C3,FA,0)),"",IF(INDEX(FIYAT_BIRIM,MATCH($C3,FA,0))="","",INDEX(FIYAT_BIRIM,MATCH($C3,FA,0)))) -> шт | J3: kaztek | K3: =K2 -> 260917 | L3: =G3 -> 103671 | M3: =M2 -> 1 | N3: KORPUS | O3: KORPUS_AYAKLI | P3: =IF(ISNA(MATCH($C3,FA,0)),"ARTİKÜL YOK",INDEX(FIYAT_DURUM,MATCH($C3,FA,0))) -> OK | Q3: ОЛ: ВРУ-2 20.80.45 IP31 TITAN (YKM2-C3-2084-31) 2000x800x450 — KAZTEK muadil, taban 100 mm
A4: =A3 -> ВРУ-1 (260917 fok atr) | B4: mccb | C4: 844326 | D4: =IF(ISNA(MATCH($C4,FA,0)),"ARTİKÜL FIYAT SAYFASINDA YOK",INDEX(FIYAT_AD,MATCH($C4,FA,0))) -> Авт. выкл. NXM-160S/3Р 125A 36кА (R) | E4: =IF(ISNA(MATCH($C4,FA,0)),"",IF(INDEX(FIYAT_LISTE,MATCH($C4,FA,0))="","",INDEX(FIYAT_LISTE,MATCH($C4,FA,0)))) -> 27656 | F4: =IF(ISNA(MATCH($C4,FA,0)),"",IF(INDEX(FIYAT_NET,MATCH($C4,FA,0))="","",INDEX(FIYAT_NET,MATCH($C4,FA,0)))) -> 16593.6 | G4: =IF(OR(F4="",H4=""),"",H4*F4) -> 33187.2 | H4: 2 | I4: =IF(ISNA(MATCH($C4,FA,0)),"",IF(INDEX(FIYAT_BIRIM,MATCH($C4,FA,0))="","",INDEX(FIYAT_BIRIM,MATCH($C4,FA,0)))) -> шт | J4: =IF(ISNA(MATCH($C4,FA,0)),"",IF(INDEX(FIYAT_MARKA,MATCH($C4,FA,0))="","",INDEX(FIYAT_MARKA,MATCH($C4,FA,0)))) -> chint | K4: =K3 -> 260917 | L4: =G4 -> 33187.2 | M4: =M3 -> 1 | N4: GIRIS | O4: mccb | P4: =IF(ISNA(MATCH($C4,FA,0)),"ARTİKÜL YOK",INDEX(FIYAT_DURUM,MATCH($C4,FA,0))) -> OK | Q4: ОЛ QF1,QF2 ВА88-32 3P 125A 35kA → NXM-160S 36kA
A5: =A4 -> ВРУ-1 (260917 fok atr) | B5: kilit | C5: 263761 | D5: =IF(ISNA(MATCH($C5,FA,0)),"ARTİKÜL FIYAT SAYFASINDA YOK",INDEX(FIYAT_AD,MATCH($C5,FA,0))) -> Механическая блокировка MI-9 для NXC-120-225 (R) | E5: =IF(ISNA(MATCH($C5,FA,0)),"",IF(INDEX(FIYAT_LISTE,MATCH($C5,FA,0))="","",INDEX(FIYAT_LISTE,MATCH($C5,FA,0)))) -> 3506 | F5: =IF(ISNA(MATCH($C5,FA,0)),"",IF(INDEX(FIYAT_NET,MATCH($C5,FA,0))="","",INDEX(FIYAT_NET,MATCH($C5,FA,0)))) -> 2103.6 | G5: =IF(OR(F5="",H5=""),"",H5*F5) -> 2103.6 | H5: 1 | I5: =IF(ISNA(MATCH($C5,FA,0)),"",IF(INDEX(FIYAT_BIRIM,MATCH($C5,FA,0))="","",INDEX(FIYAT_BIRIM,MATCH($C5,FA,0)))) -> шт | J5: =IF(ISNA(MATCH($C5,FA,0)),"",IF(INDEX(FIYAT_MARKA,MATCH($C5,FA,0))="","",INDEX(FIYAT_MARKA,MATCH($C5,FA,0)))) -> chint | K5: =K4 -> 260917 | L5: =G5 -> 2103.6 | M5: =M4 -> 1 | N5: KUMANDA | O5: kilit | P5: =IF(ISNA(MATCH($C5,FA,0)),"ARTİKÜL YOK",INDEX(FIYAT_DURUM,MATCH($C5,FA,0))) -> OK | Q5: projede yok — АВР kontaktör mekanik kilidi için eklendi
A6: =A5 -> ВРУ-1 (260917 fok atr) | B6: sayac | C6: 989-190-0114 | D6: =IF(ISNA(MATCH($C6,FA,0)),"ARTİKÜL FIYAT SAYFASINDA YOK",INDEX(FIYAT_AD,MATCH($C6,FA,0))) -> Счет.элек Меркурий 3ф 5 (7,5)A 230 ART-03 PQRSIDN многотариф/трансф | E6: =IF(ISNA(MATCH($C6,FA,0)),"",IF(INDEX(FIYAT_LISTE,MATCH($C6,FA,0))="","",INDEX(FIYAT_LISTE,MATCH($C6,FA,0)))) -> 105000 | F6: =IF(ISNA(MATCH($C6,FA,0)),"",IF(INDEX(FIYAT_NET,MATCH($C6,FA,0))="","",INDEX(FIYAT_NET,MATCH($C6,FA,0)))) -> 105000 | G6: =IF(OR(F6="",H6=""),"",H6*F6) -> 105000 | H6: 1 | I6: =IF(ISNA(MATCH($C6,FA,0)),"",IF(INDEX(FIYAT_BIRIM,MATCH($C6,FA,0))="","",INDEX(FIYAT_BIRIM,MATCH($C6,FA,0)))) -> шт | J6: kaztek | K6: =K5 -> 260917 | L6: =G6 -> 105000 | M6: =M5 -> 1 | N6: OLCU | O6: sayac | P6: =IF(ISNA(MATCH($C6,FA,0)),"ARTİKÜL YOK",INDEX(FIYAT_DURUM,MATCH($C6,FA,0))) -> OK | Q6: Меркурий 230 ART-03 трансф.
A7: =A6 -> ВРУ-1 (260917 fok atr) | B7: tt | C7: 256478 | D7: =IF(ISNA(MATCH($C7,FA,0)),"ARTİKÜL FIYAT SAYFASINDA YOK",INDEX(FIYAT_AD,MATCH($C7,FA,0))) -> Трансформатор тока BH-0.66 30 | B 150/5A класс точности 0.5-1 ® | E7: =IF(ISNA(MATCH($C7,FA,0)),"",IF(INDEX(FIYAT_LISTE,MATCH($C7,FA,0))="","",INDEX(FIYAT_LISTE,MATCH($C7,FA,0)))) -> 5682 | F7: =IF(ISNA(MATCH($C7,FA,0)),"",IF(INDEX(FIYAT_NET,MATCH($C7,FA,0))="","",INDEX(FIYAT_NET,MATCH($C7,FA,0)))) -> 3409.2 | G7: =IF(OR(F7="",H7=""),"",H7*F7) -> 10227.6 | H7: 3 | I7: =IF(ISNA(MATCH($C7,FA,0)),"",IF(INDEX(FIYAT_BIRIM,MATCH($C7,FA,0))="","",INDEX(FIYAT_BIRIM,MATCH($C7,FA,0)))) -> шт | J7: =IF(ISNA(MATCH($C7,FA,0)),"",IF(INDEX(FIYAT_MARKA,MATCH($C7,FA,0))="","",INDEX(FIYAT_MARKA,MATCH($C7,FA,0)))) -> chint | K7: =K6 -> 260917 | L7: =G7 -> 10227.6 | M7: =M6 -> 1 | N7: OLCU | O7: tt | P7: =IF(ISNA(MATCH($C7,FA,0)),"ARTİKÜL YOK",INDEX(FIYAT_DURUM,MATCH($C7,FA,0))) -> OK | Q7: ТТИ-А 125/5 → 150/5, bir üst kademe (125/5 listede yok)
A8: =A7 -> ВРУ-1 (260917 fok atr) | B8: oto | C8: 816141 | D8: =IF(ISNA(MATCH($C8,FA,0)),"ARTİKÜL FIYAT SAYFASINDA YOK",INDEX(FIYAT_AD,MATCH($C8,FA,0))) -> Авт. выкл. NXB-125 3P 100A 10кА х-ка C (R) | E8: =IF(ISNA(MATCH($C8,FA,0)),"",IF(INDEX(FIYAT_LISTE,MATCH($C8,FA,0))="","",INDEX(FIYAT_LISTE,MATCH($C8,FA,0)))) -> 11015 | F8: =IF(ISNA(MATCH($C8,FA,0)),"",IF(INDEX(FIYAT_NET,MATCH($C8,FA,0))="","",INDEX(FIYAT_NET,MATCH($C8,FA,0)))) -> 6609 | G8: =IF(OR(F8="",H8=""),"",H8*F8) -> 6609 | H8: 1 | I8: =IF(ISNA(MATCH($C8,FA,0)),"",IF(INDEX(FIYAT_BIRIM,MATCH($C8,FA,0))="","",INDEX(FIYAT_BIRIM,MATCH($C8,FA,0)))) -> шт | J8: =IF(ISNA(MATCH($C8,FA,0)),"",IF(INDEX(FIYAT_MARKA,MATCH($C8,FA,0))="","",INDEX(FIYAT_MARKA,MATCH($C8,FA,0)))) -> chint | K8: =K7 -> 260917 | L8: =G8 -> 6609 | M8: =M7 -> 1 | N8: CIKIS | O8: oto | P8: =IF(ISNA(MATCH($C8,FA,0)),"ARTİKÜL YOK",INDEX(FIYAT_DURUM,MATCH($C8,FA,0))) -> OK | Q8: şema ВА47-100 3П 100А → МС-1 ЩР-1
A9: =A8 -> ВРУ-1 (260917 fok atr) | B9: oto | C9: 296825 | D9: =IF(ISNA(MATCH($C9,FA,0)),"ARTİKÜL FIYAT SAYFASINDA YOK",INDEX(FIYAT_AD,MATCH($C9,FA,0))) -> Авт. выкл. NXB-63S 3P 6А 4.5kA х-ка C (R) | E9: =IF(ISNA(MATCH($C9,FA,0)),"",IF(INDEX(FIYAT_LISTE,MATCH($C9,FA,0))="","",INDEX(FIYAT_LISTE,MATCH($C9,FA,0)))) -> 2873 | F9: =IF(ISNA(MATCH($C9,FA,0)),"",IF(INDEX(FIYAT_NET,MATCH($C9,FA,0))="","",INDEX(FIYAT_NET,MATCH($C9,FA,0)))) -> 1723.8 | G9: =IF(OR(F9="",H9=""),"",H9*F9) -> 3447.6 | H9: 2 | I9: =IF(ISNA(MATCH($C9,FA,0)),"",IF(INDEX(FIYAT_BIRIM,MATCH($C9,FA,0))="","",INDEX(FIYAT_BIRIM,MATCH($C9,FA,0)))) -> шт | J9: =IF(ISNA(MATCH($C9,FA,0)),"",IF(INDEX(FIYAT_MARKA,MATCH($C9,FA,0))="","",INDEX(FIYAT_MARKA,MATCH($C9,FA,0)))) -> chint | K9: =K8 -> 260917 | L9: =G9 -> 3447.6 | M9: =M8 -> 1 | N9: KUMANDA | O9: oto | P9: =IF(ISNA(MATCH($C9,FA,0)),"ARTİKÜL YOK",INDEX(FIYAT_DURUM,MATCH($C9,FA,0))) -> OK | Q9: projede yok — giriş başına faz sinyal lambası grubu koruması için eklendi
A10: =A9 -> ВРУ-1 (260917 fok atr) | B10: oto | C10: 296708 | D10: =IF(ISNA(MATCH($C10,FA,0)),"ARTİKÜL FIYAT SAYFASINDA YOK",INDEX(FIYAT_AD,MATCH($C10,FA,0))) -> Авт. выкл. NXB-63S 1P 6А 4.5kA х-ка C (R) | E10: =IF(ISNA(MATCH($C10,FA,0)),"",IF(INDEX(FIYAT_LISTE,MATCH($C10,FA,0))="","",INDEX(FIYAT_LISTE,MATCH($C10,FA,0)))) -> 975 | F10: =IF(ISNA(MATCH($C10,FA,0)),"",IF(INDEX(FIYAT_NET,MATCH($C10,FA,0))="","",INDEX(FIYAT_NET,MATCH($C10,FA,0)))) -> 585 | G10: =IF(OR(F10="",H10=""),"",H10*F10) -> 1170 | H10: 2 | I10: =IF(ISNA(MATCH($C10,FA,0)),"",IF(INDEX(FIYAT_BIRIM,MATCH($C10,FA,0))="","",INDEX(FIYAT_BIRIM,MATCH($C10,FA,0)))) -> шт | J10: =IF(ISNA(MATCH($C10,FA,0)),"",IF(INDEX(FIYAT_MARKA,MATCH($C10,FA,0))="","",INDEX(FIYAT_MARKA,MATCH($C10,FA,0)))) -> chint | K10: =K9 -> 260917 | L10: =G10 -> 1170 | M10: =M9 -> 1 | N10: KUMANDA | O10: oto | P10: =IF(ISNA(MATCH($C10,FA,0)),"ARTİKÜL YOK",INDEX(FIYAT_DURUM,MATCH($C10,FA,0))) -> OK | Q10: ОЛ QF3,QF4 ВА47-29 1P 6A (HL1,HL2) ×2 + projede yok — АВР kaynak başına kumanda koruması için ×2 eklendi
A11: =A10 -> ВРУ-1 (260917 fok atr) | B11: contactor | C11: 836515 | D11: =IF(ISNA(MATCH($C11,FA,0)),"ARTİKÜL FIYAT SAYFASINDA YOK",INDEX(FIYAT_AD,MATCH($C11,FA,0))) -> Контактор NXC-160 160A 220В/АС3 2НО+2НЗ 50Гц (R) | E11: =IF(ISNA(MATCH($C11,FA,0)),"",IF(INDEX(FIYAT_LISTE,MATCH($C11,FA,0))="","",INDEX(FIYAT_LISTE,MATCH($C11,FA,0)))) -> 100471 | F11: =IF(ISNA(MATCH($C11,FA,0)),"",IF(INDEX(FIYAT_NET,MATCH($C11,FA,0))="","",INDEX(FIYAT_NET,MATCH($C11,FA,0)))) -> 60282.6 | G11: =IF(OR(F11="",H11=""),"",H11*F11) -> 120565.2 | H11: 2 | I11: =IF(ISNA(MATCH($C11,FA,0)),"",IF(INDEX(FIYAT_BIRIM,MATCH($C11,FA,0))="","",INDEX(FIYAT_BIRIM,MATCH($C11,FA,0)))) -> шт | J11: =IF(ISNA(MATCH($C11,FA,0)),"",IF(INDEX(FIYAT_MARKA,MATCH($C11,FA,0))="","",INDEX(FIYAT_MARKA,MATCH($C11,FA,0)))) -> chint | K11: =K10 -> 260917 | L11: =G11 -> 120565.2 | M11: =M10 -> 1 | N11: GIRIS | O11: contactor | P11: =IF(ISNA(MATCH($C11,FA,0)),"ARTİKÜL YOK",INDEX(FIYAT_DURUM,MATCH($C11,FA,0))) -> OK | Q11: ОЛ KM1.1,KM1.2 КМИ-49512 — АВР kuralı: koruma 125 A bir üst kademe
A12: =A11 -> ВРУ-1 (260917 fok atr) | B12: kontak | C12: 938256 | D12: =IF(ISNA(MATCH($C12,FA,0)),"ARTİKÜL FIYAT SAYFASINDA YOK",INDEX(FIYAT_AD,MATCH($C12,FA,0))) -> Приставка доп.контакты AX-3X/11 к контактору NXC-06~630 (R) | E12: =IF(ISNA(MATCH($C12,FA,0)),"",IF(INDEX(FIYAT_LISTE,MATCH($C12,FA,0))="","",INDEX(FIYAT_LISTE,MATCH($C12,FA,0)))) -> 1306 | F12: =IF(ISNA(MATCH($C12,FA,0)),"",IF(INDEX(FIYAT_NET,MATCH($C12,FA,0))="","",INDEX(FIYAT_NET,MATCH($C12,FA,0)))) -> 783.6 | G12: =IF(OR(F12="",H12=""),"",H12*F12) -> 1567.2 | H12: 2 | I12: =IF(ISNA(MATCH($C12,FA,0)),"",IF(INDEX(FIYAT_BIRIM,MATCH($C12,FA,0))="","",INDEX(FIYAT_BIRIM,MATCH($C12,FA,0)))) -> шт | J12: =IF(ISNA(MATCH($C12,FA,0)),"",IF(INDEX(FIYAT_MARKA,MATCH($C12,FA,0))="","",INDEX(FIYAT_MARKA,MATCH($C12,FA,0)))) -> chint | K12: =K11 -> 260917 | L12: =G12 -> 1567.2 | M12: =M11 -> 1 | N12: KUMANDA | O12: kontak | P12: =IF(ISNA(MATCH($C12,FA,0)),"ARTİKÜL YOK",INDEX(FIYAT_DURUM,MATCH($C12,FA,0))) -> OK | Q12: projede yok — АВР kontaktör yardımcı kontağı için eklendi
A13: =A12 -> ВРУ-1 (260917 fok atr) | B13: aksesuar | C13: 200100060 | D13: =IF(ISNA(MATCH($C13,FA,0)),"ARTİKÜL FIYAT SAYFASINDA YOK",INDEX(FIYAT_AD,MATCH($C13,FA,0))) -> Испытательная клеммная коробка(колодка) для счетчиков электроэнергии | E13: =IF(ISNA(MATCH($C13,FA,0)),"",IF(INDEX(FIYAT_LISTE,MATCH($C13,FA,0))="","",INDEX(FIYAT_LISTE,MATCH($C13,FA,0)))) -> 5999 | F13: =IF(ISNA(MATCH($C13,FA,0)),"",IF(INDEX(FIYAT_NET,MATCH($C13,FA,0))="","",INDEX(FIYAT_NET,MATCH($C13,FA,0)))) -> 5999 | G13: =IF(OR(F13="",H13=""),"",H13*F13) -> 5999 | H13: 1 | I13: =IF(ISNA(MATCH($C13,FA,0)),"",IF(INDEX(FIYAT_BIRIM,MATCH($C13,FA,0))="","",INDEX(FIYAT_BIRIM,MATCH($C13,FA,0)))) -> шт | J13: =IF(ISNA(MATCH($C13,FA,0)),"",IF(INDEX(FIYAT_MARKA,MATCH($C13,FA,0))="","",INDEX(FIYAT_MARKA,MATCH($C13,FA,0)))) -> ekt | K13: =K12 -> 260917 | L13: =G13 -> 5999 | M13: =M12 -> 1 | N13: OLCU | O13: aksesuar | P13: =IF(ISNA(MATCH($C13,FA,0)),"ARTİKÜL YOK",INDEX(FIYAT_DURUM,MATCH($C13,FA,0))) -> ESKİ | Q13: projede yok — trafo bağlantılı sayaç için test klemens kutusu eklendi
A14: =A13 -> ВРУ-1 (260917 fok atr) | B14: avr_rele | C14: 311100864 | D14: Устройство управления резервным питанием F&F AVR-02-G NEW | E14: 59554 | F14: =E14 -> 59554 | G14: =IF(OR(F14="",H14=""),"",H14*F14) -> 59554 | H14: 1 | I14: =IF(ISNA(MATCH($C14,FA,0)),"",IF(INDEX(FIYAT_BIRIM,MATCH($C14,FA,0))="","",INDEX(FIYAT_BIRIM,MATCH($C14,FA,0)))) | J14: pys | K14: =K13 -> 260917 | L14: =G14 -> 59554 | M14: =M13 -> 1 | N14: KUMANDA | O14: avr_rele | P14: =IF(ISNA(MATCH($C14,FA,0)),"ARTİKÜL YOK",INDEX(FIYAT_DURUM,MATCH($C14,FA,0))) -> ARTİKÜL YOK | Q14: ОЛ Реле фаз ORF ×2 yerine АВР kuralı: F&F АВР rölesi
A15: =A14 -> ВРУ-1 (260917 fok atr) | B15: lamb | C15: 593076 | D15: =IF(ISNA(MATCH($C15,FA,0)),"ARTİKÜL FIYAT SAYFASINDA YOK",INDEX(FIYAT_AD,MATCH($C15,FA,0))) -> Индикатор ND16-22D/2 желтый AC/DC230В (R) | E15: =IF(ISNA(MATCH($C15,FA,0)),"",IF(INDEX(FIYAT_LISTE,MATCH($C15,FA,0))="","",INDEX(FIYAT_LISTE,MATCH($C15,FA,0)))) -> 571 | F15: =IF(ISNA(MATCH($C15,FA,0)),"",IF(INDEX(FIYAT_NET,MATCH($C15,FA,0))="","",INDEX(FIYAT_NET,MATCH($C15,FA,0)))) -> 342.6 | G15: =IF(OR(F15="",H15=""),"",H15*F15) -> 685.2 | H15: 2 | I15: =IF(ISNA(MATCH($C15,FA,0)),"",IF(INDEX(FIYAT_BIRIM,MATCH($C15,FA,0))="","",INDEX(FIYAT_BIRIM,MATCH($C15,FA,0)))) -> шт | J15: =IF(ISNA(MATCH($C15,FA,0)),"",IF(INDEX(FIYAT_MARKA,MATCH($C15,FA,0))="","",INDEX(FIYAT_MARKA,MATCH($C15,FA,0)))) -> chint | K15: =K14 -> 260917 | L15: =G15 -> 685.2 | M15: =M14 -> 1 | N15: KUMANDA | O15: lamb | P15: =IF(ISNA(MATCH($C15,FA,0)),"ARTİKÜL YOK",INDEX(FIYAT_DURUM,MATCH($C15,FA,0))) -> OK | Q15: projede yok — giriş başına L1 faz sinyal lambası için eklendi
A16: =A15 -> ВРУ-1 (260917 fok atr) | B16: lamb | C16: 593077 | D16: =IF(ISNA(MATCH($C16,FA,0)),"ARTİKÜL FIYAT SAYFASINDA YOK",INDEX(FIYAT_AD,MATCH($C16,FA,0))) -> Индикатор ND16-22D/2 зеленый AC/DC230В (R) | E16: =IF(ISNA(MATCH($C16,FA,0)),"",IF(INDEX(FIYAT_LISTE,MATCH($C16,FA,0))="","",INDEX(FIYAT_LISTE,MATCH($C16,FA,0)))) -> 589 | F16: =IF(ISNA(MATCH($C16,FA,0)),"",IF(INDEX(FIYAT_NET,MATCH($C16,FA,0))="","",INDEX(FIYAT_NET,MATCH($C16,FA,0)))) -> 353.4 | G16: =IF(OR(F16="",H16=""),"",H16*F16) -> 706.8 | H16: 2 | I16: =IF(ISNA(MATCH($C16,FA,0)),"",IF(INDEX(FIYAT_BIRIM,MATCH($C16,FA,0))="","",INDEX(FIYAT_BIRIM,MATCH($C16,FA,0)))) -> шт | J16: =IF(ISNA(MATCH($C16,FA,0)),"",IF(INDEX(FIYAT_MARKA,MATCH($C16,FA,0))="","",INDEX(FIYAT_MARKA,MATCH($C16,FA,0)))) -> chint | K16: =K15 -> 260917 | L16: =G16 -> 706.8 | M16: =M15 -> 1 | N16: KUMANDA | O16: lamb | P16: =IF(ISNA(MATCH($C16,FA,0)),"ARTİKÜL YOK",INDEX(FIYAT_DURUM,MATCH($C16,FA,0))) -> OK | Q16: projede yok — giriş başına L2 faz sinyal lambası için eklendi
A17: =A16 -> ВРУ-1 (260917 fok atr) | B17: lamb | C17: 593075 | D17: =IF(ISNA(MATCH($C17,FA,0)),"ARTİKÜL FIYAT SAYFASINDA YOK",INDEX(FIYAT_AD,MATCH($C17,FA,0))) -> Индикатор ND16-22D/2 красный AC/DC230В (R) | E17: =IF(ISNA(MATCH($C17,FA,0)),"",IF(INDEX(FIYAT_LISTE,MATCH($C17,FA,0))="","",INDEX(FIYAT_LISTE,MATCH($C17,FA,0)))) -> 571 | F17: =IF(ISNA(MATCH($C17,FA,0)),"",IF(INDEX(FIYAT_NET,MATCH($C17,FA,0))="","",INDEX(FIYAT_NET,MATCH($C17,FA,0)))) -> 342.6 | G17: =IF(OR(F17="",H17=""),"",H17*F17) -> 685.2 | H17: 2 | I17: =IF(ISNA(MATCH($C17,FA,0)),"",IF(INDEX(FIYAT_BIRIM,MATCH($C17,FA,0))="","",INDEX(FIYAT_BIRIM,MATCH($C17,FA,0)))) -> шт | J17: =IF(ISNA(MATCH($C17,FA,0)),"",IF(INDEX(FIYAT_MARKA,MATCH($C17,FA,0))="","",INDEX(FIYAT_MARKA,MATCH($C17,FA,0)))) -> chint | K17: =K16 -> 260917 | L17: =G17 -> 685.2 | M17: =M16 -> 1 | N17: KUMANDA | O17: lamb | P17: =IF(ISNA(MATCH($C17,FA,0)),"ARTİKÜL YOK",INDEX(FIYAT_DURUM,MATCH($C17,FA,0))) -> OK | Q17: projede yok — giriş başına L3 faz sinyal lambası için eklendi
A18: =A17 -> ВРУ-1 (260917 fok atr) | B18: lamb | C18: PYS-001 | D18: =IF(ISNA(MATCH($C18,FA,0)),"ARTİKÜL FIYAT SAYFASINDA YOK",INDEX(FIYAT_AD,MATCH($C18,FA,0))) -> Светильник ЛПО 2001 8Вт IEK | E18: 1000 | F18: =E18 -> 1000 | G18: =IF(OR(F18="",H18=""),"",H18*F18) -> 1000 | H18: 1 | I18: =IF(ISNA(MATCH($C18,FA,0)),"",IF(INDEX(FIYAT_BIRIM,MATCH($C18,FA,0))="","",INDEX(FIYAT_BIRIM,MATCH($C18,FA,0)))) -> шт | J18: =IF(ISNA(MATCH($C18,FA,0)),"",IF(INDEX(FIYAT_MARKA,MATCH($C18,FA,0))="","",INDEX(FIYAT_MARKA,MATCH($C18,FA,0)))) -> pys | K18: =K17 -> 260917 | L18: =G18 -> 1000 | M18: =M17 -> 1 | N18: KUMANDA | O18: lamb | P18: =IF(ISNA(MATCH($C18,FA,0)),"ARTİKÜL YOK",INDEX(FIYAT_DURUM,MATCH($C18,FA,0))) -> FİYAT YOK | Q18: ОЛ HL1,HL2 ЛПО 2001 8Вт — listede yok
A19: =A18 -> ВРУ-1 (260917 fok atr) | B19: nbara | C19: =IF((SUMIFS($H$3:$H$18,$N$3:$N$18,"CIKIS")+SUMIFS($H$3:$H$18,$N$3:$N$18,"KUMANDA")+1)>MAX(SNI_DELIK),INDEX(SNI_KOD,ROWS(SNI_KOD)),INDEX(SNI_KOD,COUNTIF(SNI_DELIK,"<"&(SUMIFS($H$3:$H$18,$N$3:$N$18,"CIKIS")+SUMIFS($H$3:$H$18,$N$3:$N$18,"KUMANDA")+1))+1)) -> 130200363 | D19: =IF(ISNA(MATCH($C19,FA,0)),"ARTİKÜL FIYAT SAYFASINDA YOK",INDEX(FIYAT_AD,MATCH($C19,FA,0))) -> Шина "N" нулевая 8х12мм комб с изол "Стойка" ШНИ 14-КС-С UNIT (20/200) | E19: =IF(ISNA(MATCH($C19,FA,0)),"",IF(INDEX(FIYAT_LISTE,MATCH($C19,FA,0))="","",INDEX(FIYAT_LISTE,MATCH($C19,FA,0)))) -> 1049 | F19: =IF(ISNA(MATCH($C19,FA,0)),"",IF(INDEX(FIYAT_NET,MATCH($C19,FA,0))="","",INDEX(FIYAT_NET,MATCH($C19,FA,0)))) -> 1049 | G19: =IF(OR(F19="",H19=""),"",H19*F19) -> 2098 | H19: =IF((SUMIFS($H$3:$H$18,$N$3:$N$18,"CIKIS")+SUMIFS($H$3:$H$18,$N$3:$N$18,"KUMANDA")+1)>MAX(SNI_DELIK),ROUNDUP((SUMIFS($H$3:$H$18,$N$3:$N$18,"CIKIS")+SUMIFS($H$3:$H$18,$N$3:$N$18,"KUMANDA")+1)/MAX(SNI_DELIK),0),1) -> 2 | I19: =IF(ISNA(MATCH($C19,FA,0)),"",IF(INDEX(FIYAT_BIRIM,MATCH($C19,FA,0))="","",INDEX(FIYAT_BIRIM,MATCH($C19,FA,0)))) -> шт | J19: =IF(ISNA(MATCH($C19,FA,0)),"",IF(INDEX(FIYAT_MARKA,MATCH($C19,FA,0))="","",INDEX(FIYAT_MARKA,MATCH($C19,FA,0)))) -> ekt | K19: =K18 -> 260917 | L19: =G19 -> 2098 | M19: =M18 -> 1 | N19: SARF | O19: nbara | P19: =IF(ISNA(MATCH($C19,FA,0)),"ARTİKÜL YOK",INDEX(FIYAT_DURUM,MATCH($C19,FA,0))) -> ESKİ | Q19: N barası (otomatik)
A20: =A19 -> ВРУ-1 (260917 fok atr) | B20: nbara | C20: =IF((SUMIFS($H$3:$H$18,$N$3:$N$18,"CIKIS")+2+N(KURALLAR!$J$203))>MAX(SNI_DELIK),INDEX(SNI_KOD,ROWS(SNI_KOD)),INDEX(SNI_KOD,COUNTIF(SNI_DELIK,"<"&(SUMIFS($H$3:$H$18,$N$3:$N$18,"CIKIS")+2+N(KURALLAR!$J$203)))+1)) -> 130200364 | D20: =IF(ISNA(MATCH($C20,FA,0)),"ARTİKÜL FIYAT SAYFASINDA YOK",INDEX(FIYAT_AD,MATCH($C20,FA,0))) -> Шина "N" нулевая 8х12мм комб с изол "Стойка" ШНИ 6-КС-С UNIT (20/300) | E20: =IF(ISNA(MATCH($C20,FA,0)),"",IF(INDEX(FIYAT_LISTE,MATCH($C20,FA,0))="","",INDEX(FIYAT_LISTE,MATCH($C20,FA,0)))) -> 560 | F20: =IF(ISNA(MATCH($C20,FA,0)),"",IF(INDEX(FIYAT_NET,MATCH($C20,FA,0))="","",INDEX(FIYAT_NET,MATCH($C20,FA,0)))) -> 560 | G20: =IF(OR(F20="",H20=""),"",H20*F20) -> 560 | H20: =IF((SUMIFS($H$3:$H$18,$N$3:$N$18,"CIKIS")+2+N(KURALLAR!$J$203))>MAX(SNI_DELIK),ROUNDUP((SUMIFS($H$3:$H$18,$N$3:$N$18,"CIKIS")+2+N(KURALLAR!$J$203))/MAX(SNI_DELIK),0),1) -> 1 | I20: =IF(ISNA(MATCH($C20,FA,0)),"",IF(INDEX(FIYAT_BIRIM,MATCH($C20,FA,0))="","",INDEX(FIYAT_BIRIM,MATCH($C20,FA,0)))) -> шт | J20: =IF(ISNA(MATCH($C20,FA,0)),"",IF(INDEX(FIYAT_MARKA,MATCH($C20,FA,0))="","",INDEX(FIYAT_MARKA,MATCH($C20,FA,0)))) -> ekt | K20: =K19 -> 260917 | L20: =G20 -> 560 | M20: =M19 -> 1 | N20: SARF | O20: nbara | P20: =IF(ISNA(MATCH($C20,FA,0)),"ARTİKÜL YOK",INDEX(FIYAT_DURUM,MATCH($C20,FA,0))) -> ESKİ | Q20: PE barası (otomatik)
A21: =A20 -> ВРУ-1 (260917 fok atr) | B21: kanal | C21: 280100020 | D21: =IF(ISNA(MATCH($C21,FA,0)),"ARTİKÜL FIYAT SAYFASINDA YOK",INDEX(FIYAT_AD,MATCH($C21,FA,0))) -> Кабель.канал перф. 40х40 ИМПАКТ IEK (36) | E21: =IF(ISNA(MATCH($C21,FA,0)),"",IF(INDEX(FIYAT_LISTE,MATCH($C21,FA,0))="","",INDEX(FIYAT_LISTE,MATCH($C21,FA,0)))) -> 1486 | F21: =IF(ISNA(MATCH($C21,FA,0)),"",IF(INDEX(FIYAT_NET,MATCH($C21,FA,0))="","",INDEX(FIYAT_NET,MATCH($C21,FA,0)))) -> 1486 | G21: =IF(OR(F21="",H21=""),"",H21*F21) -> 13076.8 | H21: =ROUND(((N(KURALLAR!$E$203)+1)*KURALLAR!$M$203/1000+2*KURALLAR!$N$203/1000)*KANAL_FIRE,1) -> 8.8 | I21: =IF(ISNA(MATCH($C21,FA,0)),"",IF(INDEX(FIYAT_BIRIM,MATCH($C21,FA,0))="","",INDEX(FIYAT_BIRIM,MATCH($C21,FA,0)))) -> м | J21: =IF(ISNA(MATCH($C21,FA,0)),"",IF(INDEX(FIYAT_MARKA,MATCH($C21,FA,0))="","",INDEX(FIYAT_MARKA,MATCH($C21,FA,0)))) -> ekt | K21: =K20 -> 260917 | L21: =G21 -> 13076.8 | M21: =M20 -> 1 | N21: SARF | O21: kanal | P21: =IF(ISNA(MATCH($C21,FA,0)),"ARTİKÜL YOK",INDEX(FIYAT_DURUM,MATCH($C21,FA,0))) -> ESKİ | Q21: plastik perforeli kanal
A22: =A21 -> ВРУ-1 (260917 fok atr) | B22: kablo | C22: 151.01.PV3.01,5 | D22: =IF(ISNA(MATCH($C22,FA,0)),"ARTİKÜL FIYAT SAYFASINDA YOK",INDEX(FIYAT_AD,MATCH($C22,FA,0))) -> HARMONY ПВ3 1*1,5 | E22: =IF(ISNA(MATCH($C22,FA,0)),"",IF(INDEX(FIYAT_LISTE,MATCH($C22,FA,0))="","",INDEX(FIYAT_LISTE,MATCH($C22,FA,0)))) -> 105 | F22: =IF(ISNA(MATCH($C22,FA,0)),"",IF(INDEX(FIYAT_NET,MATCH($C22,FA,0))="","",INDEX(FIYAT_NET,MATCH($C22,FA,0)))) -> 105 | G22: =IF(OR(F22="",H22=""),"",H22*F22) -> 1890 | H22: =ROUND(SUMPRODUCT(SUMIFS($H$3:$H$18,$C$3:$C$18,FA,$N$3:$N$18,"<>YEDEK")*(F_BK=1.5)*F_TELM)*KABLO_FIRE,1) -> 18 | I22: =IF(ISNA(MATCH($C22,FA,0)),"",IF(INDEX(FIYAT_BIRIM,MATCH($C22,FA,0))="","",INDEX(FIYAT_BIRIM,MATCH($C22,FA,0)))) -> м | J22: =IF(ISNA(MATCH($C22,FA,0)),"",IF(INDEX(FIYAT_MARKA,MATCH($C22,FA,0))="","",INDEX(FIYAT_MARKA,MATCH($C22,FA,0)))) -> harmony | K22: =K21 -> 260917 | L22: =G22 -> 1890 | M22: =M21 -> 1 | N22: SARF | O22: kablo | P22: =IF(ISNA(MATCH($C22,FA,0)),"ARTİKÜL YOK",INDEX(FIYAT_DURUM,MATCH($C22,FA,0))) -> TARİH YOK | Q22: ПВ3 1.5 mm² pano içi
A23: =A22 -> ВРУ-1 (260917 fok atr) | B23: kablo | C23: 151.01.PV3.02,5 | D23: =IF(ISNA(MATCH($C23,FA,0)),"ARTİKÜL FIYAT SAYFASINDA YOK",INDEX(FIYAT_AD,MATCH($C23,FA,0))) -> HARMONY ПВ3 1*2,5 | E23: =IF(ISNA(MATCH($C23,FA,0)),"",IF(INDEX(FIYAT_LISTE,MATCH($C23,FA,0))="","",INDEX(FIYAT_LISTE,MATCH($C23,FA,0)))) -> 174 | F23: =IF(ISNA(MATCH($C23,FA,0)),"",IF(INDEX(FIYAT_NET,MATCH($C23,FA,0))="","",INDEX(FIYAT_NET,MATCH($C23,FA,0)))) -> 174 | G23: =IF(OR(F23="",H23=""),"",H23*F23) -> 2296.8 | H23: =ROUND(SUMPRODUCT(SUMIFS($H$3:$H$18,$C$3:$C$18,FA,$N$3:$N$18,"<>YEDEK")*(F_BK=2.5)*F_TELM)*KABLO_FIRE,1) -> 13.2 | I23: =IF(ISNA(MATCH($C23,FA,0)),"",IF(INDEX(FIYAT_BIRIM,MATCH($C23,FA,0))="","",INDEX(FIYAT_BIRIM,MATCH($C23,FA,0)))) -> м | J23: =IF(ISNA(MATCH($C23,FA,0)),"",IF(INDEX(FIYAT_MARKA,MATCH($C23,FA,0))="","",INDEX(FIYAT_MARKA,MATCH($C23,FA,0)))) -> harmony | K23: =K22 -> 260917 | L23: =G23 -> 2296.8 | M23: =M22 -> 1 | N23: SARF | O23: kablo | P23: =IF(ISNA(MATCH($C23,FA,0)),"ARTİKÜL YOK",INDEX(FIYAT_DURUM,MATCH($C23,FA,0))) -> TARİH YOK | Q23: ПВ3 2.5 mm² pano içi
A24: =A23 -> ВРУ-1 (260917 fok atr) | B24: kablo | C24: 151.01.PV3.25 | D24: =IF(ISNA(MATCH($C24,FA,0)),"ARTİKÜL FIYAT SAYFASINDA YOK",INDEX(FIYAT_AD,MATCH($C24,FA,0))) -> HARMONY ПВ3 1*25 | E24: =IF(ISNA(MATCH($C24,FA,0)),"",IF(INDEX(FIYAT_LISTE,MATCH($C24,FA,0))="","",INDEX(FIYAT_LISTE,MATCH($C24,FA,0)))) -> 1688 | F24: =IF(ISNA(MATCH($C24,FA,0)),"",IF(INDEX(FIYAT_NET,MATCH($C24,FA,0))="","",INDEX(FIYAT_NET,MATCH($C24,FA,0)))) -> 1688 | G24: =IF(OR(F24="",H24=""),"",H24*F24) -> 1350.4 | H24: =ROUND(SUMPRODUCT(SUMIFS($H$3:$H$18,$C$3:$C$18,FA,$N$3:$N$18,"<>YEDEK")*(F_BK=25)*F_TELM)*KABLO_FIRE,1) -> 0.8 | I24: =IF(ISNA(MATCH($C24,FA,0)),"",IF(INDEX(FIYAT_BIRIM,MATCH($C24,FA,0))="","",INDEX(FIYAT_BIRIM,MATCH($C24,FA,0)))) -> м | J24: =IF(ISNA(MATCH($C24,FA,0)),"",IF(INDEX(FIYAT_MARKA,MATCH($C24,FA,0))="","",INDEX(FIYAT_MARKA,MATCH($C24,FA,0)))) -> harmony | K24: =K23 -> 260917 | L24: =G24 -> 1350.4 | M24: =M23 -> 1 | N24: SARF | O24: kablo | P24: =IF(ISNA(MATCH($C24,FA,0)),"ARTİKÜL YOK",INDEX(FIYAT_DURUM,MATCH($C24,FA,0))) -> TARİH YOK | Q24: ПВ3 25 mm² pano içi
A25: =A24 -> ВРУ-1 (260917 fok atr) | B25: kablo | C25: 151.01.PV3.35 | D25: =IF(ISNA(MATCH($C25,FA,0)),"ARTİKÜL FIYAT SAYFASINDA YOK",INDEX(FIYAT_AD,MATCH($C25,FA,0))) -> HARMONY ПВ3 1*35 | E25: =IF(ISNA(MATCH($C25,FA,0)),"",IF(INDEX(FIYAT_LISTE,MATCH($C25,FA,0))="","",INDEX(FIYAT_LISTE,MATCH($C25,FA,0)))) -> 2399 | F25: =IF(ISNA(MATCH($C25,FA,0)),"",IF(INDEX(FIYAT_NET,MATCH($C25,FA,0))="","",INDEX(FIYAT_NET,MATCH($C25,FA,0)))) -> 2399 | G25: =IF(OR(F25="",H25=""),"",H25*F25) -> 7916.7 | H25: =ROUND(SUMPRODUCT(SUMIFS($H$3:$H$18,$C$3:$C$18,FA,$N$3:$N$18,"<>YEDEK")*(F_BK=35)*F_TELM)*KABLO_FIRE,1) -> 3.3 | I25: =IF(ISNA(MATCH($C25,FA,0)),"",IF(INDEX(FIYAT_BIRIM,MATCH($C25,FA,0))="","",INDEX(FIYAT_BIRIM,MATCH($C25,FA,0)))) -> м | J25: =IF(ISNA(MATCH($C25,FA,0)),"",IF(INDEX(FIYAT_MARKA,MATCH($C25,FA,0))="","",INDEX(FIYAT_MARKA,MATCH($C25,FA,0)))) -> harmony | K25: =K24 -> 260917 | L25: =G25 -> 7916.7 | M25: =M24 -> 1 | N25: SARF | O25: kablo | P25: =IF(ISNA(MATCH($C25,FA,0)),"ARTİKÜL YOK",INDEX(FIYAT_DURUM,MATCH($C25,FA,0))) -> TARİH YOK | Q25: ПВ3 35 mm² pano içi
A26: =A25 -> ВРУ-1 (260917 fok atr) | B26: kablo | C26: 151.01.PV3.50 | D26: =IF(ISNA(MATCH($C26,FA,0)),"ARTİKÜL FIYAT SAYFASINDA YOK",INDEX(FIYAT_AD,MATCH($C26,FA,0))) -> HARMONY ПВ3 1*50 | E26: =IF(ISNA(MATCH($C26,FA,0)),"",IF(INDEX(FIYAT_LISTE,MATCH($C26,FA,0))="","",INDEX(FIYAT_LISTE,MATCH($C26,FA,0)))) -> 3455 | F26: =IF(ISNA(MATCH($C26,FA,0)),"",IF(INDEX(FIYAT_NET,MATCH($C26,FA,0))="","",INDEX(FIYAT_NET,MATCH($C26,FA,0)))) -> 3455 | G26: =IF(OR(F26="",H26=""),"",H26*F26) -> 13820 | H26: =ROUND(SUMPRODUCT(SUMIFS($H$3:$H$18,$C$3:$C$18,FA,$N$3:$N$18,"<>YEDEK")*(F_BK=50)*F_TELM)*KABLO_FIRE,1) -> 4 | I26: =IF(ISNA(MATCH($C26,FA,0)),"",IF(INDEX(FIYAT_BIRIM,MATCH($C26,FA,0))="","",INDEX(FIYAT_BIRIM,MATCH($C26,FA,0)))) -> м | J26: =IF(ISNA(MATCH($C26,FA,0)),"",IF(INDEX(FIYAT_MARKA,MATCH($C26,FA,0))="","",INDEX(FIYAT_MARKA,MATCH($C26,FA,0)))) -> harmony | K26: =K25 -> 260917 | L26: =G26 -> 13820 | M26: =M25 -> 1 | N26: SARF | O26: kablo | P26: =IF(ISNA(MATCH($C26,FA,0)),"ARTİKÜL YOK",INDEX(FIYAT_DURUM,MATCH($C26,FA,0))) -> TARİH YOK | Q26: ПВ3 50 mm² pano içi
A27: =A26 -> ВРУ-1 (260917 fok atr) | B27: kablo | C27: 151.01.PV3.06 | D27: =IF(ISNA(MATCH($C27,FA,0)),"ARTİKÜL FIYAT SAYFASINDA YOK",INDEX(FIYAT_AD,MATCH($C27,FA,0))) -> HARMONY ПВ3 1*6 | E27: =IF(ISNA(MATCH($C27,FA,0)),"",IF(INDEX(FIYAT_LISTE,MATCH($C27,FA,0))="","",INDEX(FIYAT_LISTE,MATCH($C27,FA,0)))) -> 398 | F27: =IF(ISNA(MATCH($C27,FA,0)),"",IF(INDEX(FIYAT_NET,MATCH($C27,FA,0))="","",INDEX(FIYAT_NET,MATCH($C27,FA,0)))) -> 398 | G27: =IF(OR(F27="",H27=""),"",H27*F27) -> 398 | H27: =N(KURALLAR!$J$203)*KAPI_TOPRAK_M -> 1 | I27: =IF(ISNA(MATCH($C27,FA,0)),"",IF(INDEX(FIYAT_BIRIM,MATCH($C27,FA,0))="","",INDEX(FIYAT_BIRIM,MATCH($C27,FA,0)))) -> м | J27: =IF(ISNA(MATCH($C27,FA,0)),"",IF(INDEX(FIYAT_MARKA,MATCH($C27,FA,0))="","",INDEX(FIYAT_MARKA,MATCH($C27,FA,0)))) -> harmony | K27: =K26 -> 260917 | L27: =G27 -> 398 | M27: =M26 -> 1 | N27: SARF | O27: kablo | P27: =IF(ISNA(MATCH($C27,FA,0)),"ARTİKÜL YOK",INDEX(FIYAT_DURUM,MATCH($C27,FA,0))) -> TARİH YOK | Q27: kapak topraklama iletkeni 6 mm²
A28: =A27 -> ВРУ-1 (260917 fok atr) | B28: yuksuk | C28: 311100817 | D28: =IF(ISNA(MATCH($C28,FA,0)),"ARTİKÜL FIYAT SAYFASINDA YOK",INDEX(FIYAT_AD,MATCH($C28,FA,0))) -> Наконечник НШВИ 1,5-8 изолированный 79440 (100шт) КВТ NEW | E28: =IF(ISNA(MATCH($C28,FA,0)),"",IF(INDEX(FIYAT_LISTE,MATCH($C28,FA,0))="","",INDEX(FIYAT_LISTE,MATCH($C28,FA,0)))) -> 428 | F28: =IF(ISNA(MATCH($C28,FA,0)),"",IF(INDEX(FIYAT_NET,MATCH($C28,FA,0))="","",INDEX(FIYAT_NET,MATCH($C28,FA,0)))) -> 428 | G28: =IF(OR(F28="",H28=""),"",H28*F28) -> 428 | H28: =ROUNDUP(SUMPRODUCT(SUMIFS($H$3:$H$18,$C$3:$C$18,FA,$N$3:$N$18,"<>YEDEK")*(F_BK=1.5)*F_TEL)*2*YUKSUK_FIRE/MAX(1,IF(ISNA(MATCH($C28,FA,0)),1,N(INDEX(F_PAKET,MATCH($C28,FA,0))))),0) -> 1 | I28: =IF(ISNA(MATCH($C28,FA,0)),"",IF(INDEX(FIYAT_BIRIM,MATCH($C28,FA,0))="","",INDEX(FIYAT_BIRIM,MATCH($C28,FA,0)))) -> упак | J28: =IF(ISNA(MATCH($C28,FA,0)),"",IF(INDEX(FIYAT_MARKA,MATCH($C28,FA,0))="","",INDEX(FIYAT_MARKA,MATCH($C28,FA,0)))) -> ekt | K28: =K27 -> 260917 | L28: =G28 -> 428 | M28: =M27 -> 1 | N28: SARF | O28: yuksuk | P28: =IF(ISNA(MATCH($C28,FA,0)),"ARTİKÜL YOK",INDEX(FIYAT_DURUM,MATCH($C28,FA,0))) -> ESKİ | Q28: yüksük 1.5 mm² · tel başına 2 uç
A29: =A28 -> ВРУ-1 (260917 fok atr) | B29: yuksuk | C29: 311100820 | D29: =IF(ISNA(MATCH($C29,FA,0)),"ARTİKÜL FIYAT SAYFASINDA YOK",INDEX(FIYAT_AD,MATCH($C29,FA,0))) -> Наконечник НШВИ 2,5-8 изолированный 79443 (100шт) КВТ NEW | E29: =IF(ISNA(MATCH($C29,FA,0)),"",IF(INDEX(FIYAT_LISTE,MATCH($C29,FA,0))="","",INDEX(FIYAT_LISTE,MATCH($C29,FA,0)))) -> 540 | F29: =IF(ISNA(MATCH($C29,FA,0)),"",IF(INDEX(FIYAT_NET,MATCH($C29,FA,0))="","",INDEX(FIYAT_NET,MATCH($C29,FA,0)))) -> 540 | G29: =IF(OR(F29="",H29=""),"",H29*F29) -> 540 | H29: =ROUNDUP(SUMPRODUCT(SUMIFS($H$3:$H$18,$C$3:$C$18,FA,$N$3:$N$18,"<>YEDEK")*(F_BK=2.5)*F_TEL)*2*YUKSUK_FIRE/MAX(1,IF(ISNA(MATCH($C29,FA,0)),1,N(INDEX(F_PAKET,MATCH($C29,FA,0))))),0) -> 1 | I29: =IF(ISNA(MATCH($C29,FA,0)),"",IF(INDEX(FIYAT_BIRIM,MATCH($C29,FA,0))="","",INDEX(FIYAT_BIRIM,MATCH($C29,FA,0)))) -> упак | J29: =IF(ISNA(MATCH($C29,FA,0)),"",IF(INDEX(FIYAT_MARKA,MATCH($C29,FA,0))="","",INDEX(FIYAT_MARKA,MATCH($C29,FA,0)))) -> ekt | K29: =K28 -> 260917 | L29: =G29 -> 540 | M29: =M28 -> 1 | N29: SARF | O29: yuksuk | P29: =IF(ISNA(MATCH($C29,FA,0)),"ARTİKÜL YOK",INDEX(FIYAT_DURUM,MATCH($C29,FA,0))) -> ESKİ | Q29: yüksük 2.5 mm² · tel başına 2 uç
A30: =A29 -> ВРУ-1 (260917 fok atr) | B30: pabuc | C30: 260100167 | D30: =IF(ISNA(MATCH($C30,FA,0)),"ARTİKÜL FIYAT SAYFASINDA YOK",INDEX(FIYAT_AD,MATCH($C30,FA,0))) -> Наконечник медно-луженный JG - 25 IEK (200) | E30: =IF(ISNA(MATCH($C30,FA,0)),"",IF(INDEX(FIYAT_LISTE,MATCH($C30,FA,0))="","",INDEX(FIYAT_LISTE,MATCH($C30,FA,0)))) -> 156 | F30: =IF(ISNA(MATCH($C30,FA,0)),"",IF(INDEX(FIYAT_NET,MATCH($C30,FA,0))="","",INDEX(FIYAT_NET,MATCH($C30,FA,0)))) -> 156 | G30: =IF(OR(F30="",H30=""),"",H30*F30) -> 2184 | H30: =ROUNDUP(SUMPRODUCT(SUMIFS($H$3:$H$18,$C$3:$C$18,FA,$N$3:$N$18,"<>YEDEK")*(F_BK=25)*F_TEL)*2*PABUC_FIRE,0) -> 14 | I30: =IF(ISNA(MATCH($C30,FA,0)),"",IF(INDEX(FIYAT_BIRIM,MATCH($C30,FA,0))="","",INDEX(FIYAT_BIRIM,MATCH($C30,FA,0)))) -> шт | J30: =IF(ISNA(MATCH($C30,FA,0)),"",IF(INDEX(FIYAT_MARKA,MATCH($C30,FA,0))="","",INDEX(FIYAT_MARKA,MATCH($C30,FA,0)))) -> ekt | K30: =K29 -> 260917 | L30: =G30 -> 2184 | M30: =M29 -> 1 | N30: SARF | O30: pabuc | P30: =IF(ISNA(MATCH($C30,FA,0)),"ARTİKÜL YOK",INDEX(FIYAT_DURUM,MATCH($C30,FA,0))) -> ESKİ | Q30: kablo pabucu 25 mm² · tel başına 2 uç
A31: =A30 -> ВРУ-1 (260917 fok atr) | B31: pabuc | C31: 260100158 | D31: =IF(ISNA(MATCH($C31,FA,0)),"ARTİKÜL FIYAT SAYFASINDA YOK",INDEX(FIYAT_AD,MATCH($C31,FA,0))) -> Наконечник медно-луженный JG - 35 IEK (100) | E31: =IF(ISNA(MATCH($C31,FA,0)),"",IF(INDEX(FIYAT_LISTE,MATCH($C31,FA,0))="","",INDEX(FIYAT_LISTE,MATCH($C31,FA,0)))) -> 206 | F31: =IF(ISNA(MATCH($C31,FA,0)),"",IF(INDEX(FIYAT_NET,MATCH($C31,FA,0))="","",INDEX(FIYAT_NET,MATCH($C31,FA,0)))) -> 206 | G31: =IF(OR(F31="",H31=""),"",H31*F31) -> 2472 | H31: =ROUNDUP(SUMPRODUCT(SUMIFS($H$3:$H$18,$C$3:$C$18,FA,$N$3:$N$18,"<>YEDEK")*(F_BK=35)*F_TEL)*2*PABUC_FIRE,0) -> 12 | I31: =IF(ISNA(MATCH($C31,FA,0)),"",IF(INDEX(FIYAT_BIRIM,MATCH($C31,FA,0))="","",INDEX(FIYAT_BIRIM,MATCH($C31,FA,0)))) -> шт | J31: =IF(ISNA(MATCH($C31,FA,0)),"",IF(INDEX(FIYAT_MARKA,MATCH($C31,FA,0))="","",INDEX(FIYAT_MARKA,MATCH($C31,FA,0)))) -> ekt | K31: =K30 -> 260917 | L31: =G31 -> 2472 | M31: =M30 -> 1 | N31: SARF | O31: pabuc | P31: =IF(ISNA(MATCH($C31,FA,0)),"ARTİKÜL YOK",INDEX(FIYAT_DURUM,MATCH($C31,FA,0))) -> ESKİ | Q31: kablo pabucu 35 mm² · tel başına 2 uç
A32: =A31 -> ВРУ-1 (260917 fok atr) | B32: pabuc | C32: 260100168 | D32: =IF(ISNA(MATCH($C32,FA,0)),"ARTİKÜL FIYAT SAYFASINDA YOK",INDEX(FIYAT_AD,MATCH($C32,FA,0))) -> Наконечник медно-луженный JG - 50 IEK (100) | E32: =IF(ISNA(MATCH($C32,FA,0)),"",IF(INDEX(FIYAT_LISTE,MATCH($C32,FA,0))="","",INDEX(FIYAT_LISTE,MATCH($C32,FA,0)))) -> 262 | F32: =IF(ISNA(MATCH($C32,FA,0)),"",IF(INDEX(FIYAT_NET,MATCH($C32,FA,0))="","",INDEX(FIYAT_NET,MATCH($C32,FA,0)))) -> 262 | G32: =IF(OR(F32="",H32=""),"",H32*F32) -> 3144 | H32: =ROUNDUP(SUMPRODUCT(SUMIFS($H$3:$H$18,$C$3:$C$18,FA,$N$3:$N$18,"<>YEDEK")*(F_BK=50)*F_TEL)*2*PABUC_FIRE,0) -> 12 | I32: =IF(ISNA(MATCH($C32,FA,0)),"",IF(INDEX(FIYAT_BIRIM,MATCH($C32,FA,0))="","",INDEX(FIYAT_BIRIM,MATCH($C32,FA,0)))) -> шт | J32: =IF(ISNA(MATCH($C32,FA,0)),"",IF(INDEX(FIYAT_MARKA,MATCH($C32,FA,0))="","",INDEX(FIYAT_MARKA,MATCH($C32,FA,0)))) -> ekt | K32: =K31 -> 260917 | L32: =G32 -> 3144 | M32: =M31 -> 1 | N32: SARF | O32: pabuc | P32: =IF(ISNA(MATCH($C32,FA,0)),"ARTİKÜL YOK",INDEX(FIYAT_DURUM,MATCH($C32,FA,0))) -> ESKİ | Q32: kablo pabucu 50 mm² · tel başına 2 uç
A33: =A32 -> ВРУ-1 (260917 fok atr) | B33: pabuc | C33: 260100138 | D33: =IF(ISNA(MATCH($C33,FA,0)),"ARTİKÜL FIYAT SAYFASINDA YOK",INDEX(FIYAT_AD,MATCH($C33,FA,0))) -> Наконечник медно-луженный JG - 6 IEK (600) | E33: =IF(ISNA(MATCH($C33,FA,0)),"",IF(INDEX(FIYAT_LISTE,MATCH($C33,FA,0))="","",INDEX(FIYAT_LISTE,MATCH($C33,FA,0)))) -> 76 | F33: =IF(ISNA(MATCH($C33,FA,0)),"",IF(INDEX(FIYAT_NET,MATCH($C33,FA,0))="","",INDEX(FIYAT_NET,MATCH($C33,FA,0)))) -> 76 | G33: =IF(OR(F33="",H33=""),"",H33*F33) -> 304 | H33: =2*N(KURALLAR!$J$203) -> 4 | I33: =IF(ISNA(MATCH($C33,FA,0)),"",IF(INDEX(FIYAT_BIRIM,MATCH($C33,FA,0))="","",INDEX(FIYAT_BIRIM,MATCH($C33,FA,0)))) -> шт | J33: =IF(ISNA(MATCH($C33,FA,0)),"",IF(INDEX(FIYAT_MARKA,MATCH($C33,FA,0))="","",INDEX(FIYAT_MARKA,MATCH($C33,FA,0)))) -> ekt | K33: =K32 -> 260917 | L33: =G33 -> 304 | M33: =M32 -> 1 | N33: SARF | O33: pabuc | P33: =IF(ISNA(MATCH($C33,FA,0)),"ARTİKÜL YOK",INDEX(FIYAT_DURUM,MATCH($C33,FA,0))) -> ESKİ | Q33: kapak topraklama pabucu
A34: =A33 -> ВРУ-1 (260917 fok atr) | B34: bag | C34: 240100162 | D34: =IF(ISNA(MATCH($C34,FA,0)),"ARTİKÜL FIYAT SAYFASINDA YOK",INDEX(FIYAT_AD,MATCH($C34,FA,0))) -> Хомут 2,5х100 черный UNIT (100/500) | E34: =IF(ISNA(MATCH($C34,FA,0)),"",IF(INDEX(FIYAT_LISTE,MATCH($C34,FA,0))="","",INDEX(FIYAT_LISTE,MATCH($C34,FA,0)))) -> 182 | F34: =IF(ISNA(MATCH($C34,FA,0)),"",IF(INDEX(FIYAT_NET,MATCH($C34,FA,0))="","",INDEX(FIYAT_NET,MATCH($C34,FA,0)))) -> 182 | G34: =IF(OR(F34="",H34=""),"",H34*F34) -> 182 | H34: =ROUNDUP((N(H22)+N(H23)+N(H24)+N(H25)+N(H26)+N(H27))*BAG_ADET_M/MAX(1,IF(ISNA(MATCH($C34,FA,0)),1,N(INDEX(F_PAKET,MATCH($C34,FA,0))))),0) -> 1 | I34: =IF(ISNA(MATCH($C34,FA,0)),"",IF(INDEX(FIYAT_BIRIM,MATCH($C34,FA,0))="","",INDEX(FIYAT_BIRIM,MATCH($C34,FA,0)))) -> упак | J34: =IF(ISNA(MATCH($C34,FA,0)),"",IF(INDEX(FIYAT_MARKA,MATCH($C34,FA,0))="","",INDEX(FIYAT_MARKA,MATCH($C34,FA,0)))) -> ekt | K34: =K33 -> 260917 | L34: =G34 -> 182 | M34: =M33 -> 1 | N34: SARF | O34: bag | P34: =IF(ISNA(MATCH($C34,FA,0)),"ARTİKÜL YOK",INDEX(FIYAT_DURUM,MATCH($C34,FA,0))) -> ESKİ | Q34: kablo bağı
A35: =A34 -> ВРУ-1 (260917 fok atr) | B35: монтажный материал | C35: монтажный материал | D35: монтажный материал | E35: =G36*MONTAJ_MALZ_KAT -> 27744 | F35: =E35 -> 27744 | G35: =H35*F35 -> 27744 | H35: 1 | I35: шт | J35: монтажный материал | K35: =K34 -> 260917 | L35: =G35 -> 27744 | M35: =M34 -> 1
A36: =A35 -> ВРУ-1 (260917 fok atr) | B36: монтажная работа | C36: монтажная работа | D36: монтажная работа | E36: =ROUND(SUMPRODUCT(SUMIFS(H3:H35,O3:O35,TIP_AD)*NORM_DK)*ISCILIK_KAT/60,2) -> 11.56 | F36: =DK_UCRET -> 100 | G36: =H36*F36 -> 69360 | H36: =60*E36 -> 693.6 | I36: мин | J36: монтажная работа | K36: =K35 -> 260917 | L36: =G36 -> 69360 | M36: =M35 -> 1
A37: =A36 -> ВРУ-1 (260917 fok atr) | G37: =SUM(G3:G36) -> 605943.3 | K37: =K36 -> 260917 | L37: =SUM(L3:L36) -> 605943.3 | M37: =M36 -> 1 | P37: =IF(COUNTIF(P3:P36,"FİYAT YOK")+COUNTIF(P3:P36,"YASAK")+COUNTIF(P3:P36,"MARKA YOK")+COUNTIF(P3:P36,"ARTİKÜL YOK")>0,"EKSİK FİYAT","") -> EKSİK FİYAT | Q37: =IF(KURALLAR!$Q$203="OK","","PANO: "&KURALLAR!$Q$203)
A38: =D38 -> ЩР-1 (260917 fok atr) | D38: ЩР-1 (260917 fok atr) | H38: 1 | I38: комплект | J38: TEKLED electric | K38: 260917 | M38: =H38 -> 1
A39: =A38 -> ЩР-1 (260917 fok atr) | B39: korpus | C39: 714-15040 | D39: Мет. Корпус ЩРН- 48 (660x310x120) IP31 (TS) | E39: =IF(ISNA(MATCH($C39,FA,0)),"",IF(INDEX(FIYAT_LISTE,MATCH($C39,FA,0))="","",INDEX(FIYAT_LISTE,MATCH($C39,FA,0)))) -> 24000 | F39: =IF(ISNA(MATCH($C39,FA,0)),"",IF(INDEX(FIYAT_NET,MATCH($C39,FA,0))="","",INDEX(FIYAT_NET,MATCH($C39,FA,0)))) -> 14400 | G39: =IF(OR(F39="",H39=""),"",H39*F39) -> 14400 | H39: 1 | I39: =IF(ISNA(MATCH($C39,FA,0)),"",IF(INDEX(FIYAT_BIRIM,MATCH($C39,FA,0))="","",INDEX(FIYAT_BIRIM,MATCH($C39,FA,0)))) -> шт | J39: kaztek | K39: =K38 -> 260917 | L39: =G39 -> 14400 | M39: =M38 -> 1 | N39: KORPUS | O39: KORPUS_KUCUK | P39: =IF(ISNA(MATCH($C39,FA,0)),"ARTİKÜL YOK",INDEX(FIYAT_DURUM,MATCH($C39,FA,0))) -> OK | Q39: projede ЩРн-36з — 3 sıra × 150 mm iç yüksekliğe sığmıyor, büyütüldü
A40: =A39 -> ЩР-1 (260917 fok atr) | B40: bh | C40: 193185 | D40: =IF(ISNA(MATCH($C40,FA,0)),"ARTİKÜL FIYAT SAYFASINDA YOK",INDEX(FIYAT_AD,MATCH($C40,FA,0))) -> Выключатель нагрузки NXHB-125 3P 100A (R) | E40: =IF(ISNA(MATCH($C40,FA,0)),"",IF(INDEX(FIYAT_LISTE,MATCH($C40,FA,0))="","",INDEX(FIYAT_LISTE,MATCH($C40,FA,0)))) -> 4334 | F40: =IF(ISNA(MATCH($C40,FA,0)),"",IF(INDEX(FIYAT_NET,MATCH($C40,FA,0))="","",INDEX(FIYAT_NET,MATCH($C40,FA,0)))) -> 2600.4 | G40: =IF(OR(F40="",H40=""),"",H40*F40) -> 2600.4 | H40: 1 | I40: =IF(ISNA(MATCH($C40,FA,0)),"",IF(INDEX(FIYAT_BIRIM,MATCH($C40,FA,0))="","",INDEX(FIYAT_BIRIM,MATCH($C40,FA,0)))) -> шт | J40: =IF(ISNA(MATCH($C40,FA,0)),"",IF(INDEX(FIYAT_MARKA,MATCH($C40,FA,0))="","",INDEX(FIYAT_MARKA,MATCH($C40,FA,0)))) -> chint | K40: =K39 -> 260917 | L40: =G40 -> 2600.4 | M40: =M39 -> 1 | N40: GIRIS | O40: bh | P40: =IF(ISNA(MATCH($C40,FA,0)),"ARTİKÜL YOK",INDEX(FIYAT_DURUM,MATCH($C40,FA,0))) -> OK | Q40: ВН-32 3П 100А
...

Sheet FIYAT
A1: SIRA | B1: malzeme | C1: Артикул | D1: Номенклатура | E1: LİSTE FİYATI | F1: NET, тг | G1: TOPLAM, тг | H1: TOPLAM ADET | I1: Ед.изм | J1: завод | K1: PARA | L1: KATSAYI | M1: KUR | N1: KAYNAK | O1: LİSTE TARİHİ | P1: YAŞ, ay | Q1: DURUM | R1: NOT | S1: KUTUP | T1: IN, A | U1: MODÜL/adet | V1: PAKET adet | W1: KESİT mm² | X1: GENİŞLİK mm | Y1: YÜKSEKLİK mm | Z1: DERİNLİK mm | AA1: KAPASİTE modül | AB1: GRUP | AC1: BAĞLANTI KESİTİ | AD1: TEL/adet | AE1: TEL m/adet | AF1: KLEMENS KESİTİ | AG1: L+N KLEMENS/adet | AH1: PE KLEMENS/adet | AI1: IN sayı | AJ1: KORUMA IN
A2: =ROW()-1 -> 1 | B2: mccb | C2: 844326 | D2: Авт. выкл. NXM-160S/3Р 125A 36кА (R) | E2: 27656 | F2: =IF(OR($E2="",$L2="",$M2="",$Q2="YASAK"),"",$E2*$L2*$M2) -> 16593.6 | G2: =IF($F2="","",$F2*$H2) -> 33187.2 | H2: =SUMPRODUCT((BOM!$C$2:$C$675=$C2)*BOM!$H$2:$H$675*BOM!$M$2:$M$675) -> 2 | I2: шт | J2: chint | K2: =IF(ISNA(MATCH($J2,MARKA_AD,0)),"",INDEX(MARKA_PARA,MATCH($J2,MARKA_AD,0))) -> KZT | L2: =IF(ISNA(MATCH($J2,MARKA_AD,0)),"",INDEX(MARKA_KAT,MATCH($J2,MARKA_AD,0))) -> 0.6 | M2: =IF(OR($K2="",ISNA(MATCH($K2,KUR_AD,0))),"",IF(INDEX(KUR_DEG,MATCH($K2,KUR_AD,0))="","",INDEX(KUR_DEG,MATCH($K2,KUR_AD,0)))) -> 1 | N2: CHINT2608 | O2: =IF(ISNA(MATCH($N2,KAYNAK_KOD,0)),"",IF(INDEX(KAYNAK_TARIH,MATCH($N2,KAYNAK_KOD,0))="","",INDEX(KAYNAK_TARIH,MATCH($N2,KAYNAK_KOD,0)))) -> 46261 | P2: =IF($O2="","",ROUND((TARIH-$O2)/30.4375,1)) -> 0.7 | Q2: =IF(ISNA(MATCH($J2,MARKA_AD,0)),"MARKA YOK",IF(INDEX(MARKA_IZIN,MATCH($J2,MARKA_AD,0))="HAYIR","YASAK",IF($E2="","FİYAT YOK",IF($P2="","TARİH YOK",IF($P2>YAS_YASAK_AY,"YASAK",IF($P2>YAS_ESKI_AY,"ESKİ","OK")))))) -> OK | S2: 3 | T2: 125 | AB2: =IF(ISNA(MATCH($B2,TIP_AD,0)),"",INDEX(TIP_GRUP,MATCH($B2,TIP_AD,0))) -> GUC | AC2: =IF(OR($AB2="GUC"),IF(OR($AI2=0,$AI2>KABLO_MAX_IN),0,LOOKUP($AI2,KABLO_IN_ALT,KABLO_KESIT)),IF($AB2="KUMANDA",KUMANDA_KESIT,IF($AB2="OLCU",OLCU_KESIT,0))) -> 35 | AD2: =IF(OR($AC2=0,ISNA(MATCH($B2,TIP_AD,0))),0,IF(INDEX(TIP_TEL,MATCH($B2,TIP_AD,0))="",2*N($S2)+IF(OR(N($S2)=1,N($S2)=3),1,0),INDEX(TIP_TEL,MATCH($B2,TIP_AD,0)))) -> 3 | AE2: =IF(OR($AD2=0,ISNA(MATCH($B2,TIP_AD,0))),0,$AD2*INDEX(TIP_TELM,MATCH($B2,TIP_AD,0))) -> 1.5 | AF2: =IF(OR($AB2<>"GUC",$AC2=0,$AC2>KLEMENS_MAX_KESIT),0,LOOKUP($AC2,KLEMENS_ALT,KLEMENS_KES)) -> 35 | AG2: =IF($AF2=0,0,N($S2)+IF(OR(N($S2)=1,N($S2)=3),1,0)) -> 4 | AH2: =IF($AF2=0,0,1) -> 1 | AI2: =N($T2) -> 125 | AJ2: =IF(OR($B2="mccb",$B2="oto",$B2="bh",$B2="rubilnik",$B2="ats",$B2="dif",$B2="uzo"),N($T2),0) -> 125
A3: =ROW()-1 -> 2 | B3: contactor | C3: 836515 | D3: Контактор NXC-160 160A 220В/АС3 2НО+2НЗ 50Гц (R) | E3: 100471 | F3: =IF(OR($E3="",$L3="",$M3="",$Q3="YASAK"),"",$E3*$L3*$M3) -> 60282.6 | G3: =IF($F3="","",$F3*$H3) -> 120565.2 | H3: =SUMPRODUCT((BOM!$C$2:$C$675=$C3)*BOM!$H$2:$H$675*BOM!$M$2:$M$675) -> 2 | I3: шт | J3: chint | K3: =IF(ISNA(MATCH($J3,MARKA_AD,0)),"",INDEX(MARKA_PARA,MATCH($J3,MARKA_AD,0))) -> KZT | L3: =IF(ISNA(MATCH($J3,MARKA_AD,0)),"",INDEX(MARKA_KAT,MATCH($J3,MARKA_AD,0))) -> 0.6 | M3: =IF(OR($K3="",ISNA(MATCH($K3,KUR_AD,0))),"",IF(INDEX(KUR_DEG,MATCH($K3,KUR_AD,0))="","",INDEX(KUR_DEG,MATCH($K3,KUR_AD,0)))) -> 1 | N3: CHINT2608 | O3: =IF(ISNA(MATCH($N3,KAYNAK_KOD,0)),"",IF(INDEX(KAYNAK_TARIH,MATCH($N3,KAYNAK_KOD,0))="","",INDEX(KAYNAK_TARIH,MATCH($N3,KAYNAK_KOD,0)))) -> 46261 | P3: =IF($O3="","",ROUND((TARIH-$O3)/30.4375,1)) -> 0.7 | Q3: =IF(ISNA(MATCH($J3,MARKA_AD,0)),"MARKA YOK",IF(INDEX(MARKA_IZIN,MATCH($J3,MARKA_AD,0))="HAYIR","YASAK",IF($E3="","FİYAT YOK",IF($P3="","TARİH YOK",IF($P3>YAS_YASAK_AY,"YASAK",IF($P3>YAS_ESKI_AY,"ESKİ","OK")))))) -> OK | S3: 3 | T3: 160 | AB3: =IF(ISNA(MATCH($B3,TIP_AD,0)),"",INDEX(TIP_GRUP,MATCH($B3,TIP_AD,0))) -> GUC | AC3: =IF(OR($AB3="GUC"),IF(OR($AI3=0,$AI3>KABLO_MAX_IN),0,LOOKUP($AI3,KABLO_IN_ALT,KABLO_KESIT)),IF($AB3="KUMANDA",KUMANDA_KESIT,IF($AB3="OLCU",OLCU_KESIT,0))) -> 50 | AD3: =IF(OR($AC3=0,ISNA(MATCH($B3,TIP_AD,0))),0,IF(INDEX(TIP_TEL,MATCH($B3,TIP_AD,0))="",2*N($S3)+IF(OR(N($S3)=1,N($S3)=3),1,0),INDEX(TIP_TEL,MATCH($B3,TIP_AD,0)))) -> 3 | AE3: =IF(OR($AD3=0,ISNA(MATCH($B3,TIP_AD,0))),0,$AD3*INDEX(TIP_TELM,MATCH($B3,TIP_AD,0))) -> 1.8 | AF3: =IF(OR($AB3<>"GUC",$AC3=0,$AC3>KLEMENS_MAX_KESIT),0,LOOKUP($AC3,KLEMENS_ALT,KLEMENS_KES)) -> 0 | AG3: =IF($AF3=0,0,N($S3)+IF(OR(N($S3)=1,N($S3)=3),1,0)) -> 0 | AH3: =IF($AF3=0,0,1) -> 0 | AI3: =N($T3) -> 160 | AJ3: =IF(OR($B3="mccb",$B3="oto",$B3="bh",$B3="rubilnik",$B3="ats",$B3="dif",$B3="uzo"),N($T3),0) -> 0
A4: =ROW()-1 -> 3 | B4: kontak | C4: 938256 | D4: Приставка доп.контакты AX-3X/11 к контактору NXC-06~630 (R) | E4: 1306 | F4: =IF(OR($E4="",$L4="",$M4="",$Q4="YASAK"),"",$E4*$L4*$M4) -> 783.6 | G4: =IF($F4="","",$F4*$H4) -> 1567.2 | H4: =SUMPRODUCT((BOM!$C$2:$C$675=$C4)*BOM!$H$2:$H$675*BOM!$M$2:$M$675) -> 2 | I4: шт | J4: chint | K4: =IF(ISNA(MATCH($J4,MARKA_AD,0)),"",INDEX(MARKA_PARA,MATCH($J4,MARKA_AD,0))) -> KZT | L4: =IF(ISNA(MATCH($J4,MARKA_AD,0)),"",INDEX(MARKA_KAT,MATCH($J4,MARKA_AD,0))) -> 0.6 | M4: =IF(OR($K4="",ISNA(MATCH($K4,KUR_AD,0))),"",IF(INDEX(KUR_DEG,MATCH($K4,KUR_AD,0))="","",INDEX(KUR_DEG,MATCH($K4,KUR_AD,0)))) -> 1 | N4: CHINT2608 | O4: =IF(ISNA(MATCH($N4,KAYNAK_KOD,0)),"",IF(INDEX(KAYNAK_TARIH,MATCH($N4,KAYNAK_KOD,0))="","",INDEX(KAYNAK_TARIH,MATCH($N4,KAYNAK_KOD,0)))) -> 46261 | P4: =IF($O4="","",ROUND((TARIH-$O4)/30.4375,1)) -> 0.7 | Q4: =IF(ISNA(MATCH($J4,MARKA_AD,0)),"MARKA YOK",IF(INDEX(MARKA_IZIN,MATCH($J4,MARKA_AD,0))="HAYIR","YASAK",IF($E4="","FİYAT YOK",IF($P4="","TARİH YOK",IF($P4>YAS_YASAK_AY,"YASAK",IF($P4>YAS_ESKI_AY,"ESKİ","OK")))))) -> OK | AB4: =IF(ISNA(MATCH($B4,TIP_AD,0)),"",INDEX(TIP_GRUP,MATCH($B4,TIP_AD,0))) -> KUMANDA | AC4: =IF(OR($AB4="GUC"),IF(OR($AI4=0,$AI4>KABLO_MAX_IN),0,LOOKUP($AI4,KABLO_IN_ALT,KABLO_KESIT)),IF($AB4="KUMANDA",KUMANDA_KESIT,IF($AB4="OLCU",OLCU_KESIT,0))) -> 1.5 | AD4: =IF(OR($AC4=0,ISNA(MATCH($B4,TIP_AD,0))),0,IF(INDEX(TIP_TEL,MATCH($B4,TIP_AD,0))="",2*N($S4)+IF(OR(N($S4)=1,N($S4)=3),1,0),INDEX(TIP_TEL,MATCH($B4,TIP_AD,0)))) -> 2 | AE4: =IF(OR($AD4=0,ISNA(MATCH($B4,TIP_AD,0))),0,$AD4*INDEX(TIP_TELM,MATCH($B4,TIP_AD,0))) -> 1.6 | AF4: =IF(OR($AB4<>"GUC",$AC4=0,$AC4>KLEMENS_MAX_KESIT),0,LOOKUP($AC4,KLEMENS_ALT,KLEMENS_KES)) -> 0 | AG4: =IF($AF4=0,0,N($S4)+IF(OR(N($S4)=1,N($S4)=3),1,0)) -> 0 | AH4: =IF($AF4=0,0,1) -> 0 | AI4: =N($T4) -> 0 | AJ4: =IF(OR($B4="mccb",$B4="oto",$B4="bh",$B4="rubilnik",$B4="ats",$B4="dif",$B4="uzo"),N($T4),0) -> 0
A5: =ROW()-1 -> 4 | B5: kilit | C5: 263761 | D5: Механическая блокировка MI-9 для NXC-120-225 (R) | E5: 3506 | F5: =IF(OR($E5="",$L5="",$M5="",$Q5="YASAK"),"",$E5*$L5*$M5) -> 2103.6 | G5: =IF($F5="","",$F5*$H5) -> 2103.6 | H5: =SUMPRODUCT((BOM!$C$2:$C$675=$C5)*BOM!$H$2:$H$675*BOM!$M$2:$M$675) -> 1 | I5: шт | J5: chint | K5: =IF(ISNA(MATCH($J5,MARKA_AD,0)),"",INDEX(MARKA_PARA,MATCH($J5,MARKA_AD,0))) -> KZT | L5: =IF(ISNA(MATCH($J5,MARKA_AD,0)),"",INDEX(MARKA_KAT,MATCH($J5,MARKA_AD,0))) -> 0.6 | M5: =IF(OR($K5="",ISNA(MATCH($K5,KUR_AD,0))),"",IF(INDEX(KUR_DEG,MATCH($K5,KUR_AD,0))="","",INDEX(KUR_DEG,MATCH($K5,KUR_AD,0)))) -> 1 | N5: CHINT2608 | O5: =IF(ISNA(MATCH($N5,KAYNAK_KOD,0)),"",IF(INDEX(KAYNAK_TARIH,MATCH($N5,KAYNAK_KOD,0))="","",INDEX(KAYNAK_TARIH,MATCH($N5,KAYNAK_KOD,0)))) -> 46261 | P5: =IF($O5="","",ROUND((TARIH-$O5)/30.4375,1)) -> 0.7 | Q5: =IF(ISNA(MATCH($J5,MARKA_AD,0)),"MARKA YOK",IF(INDEX(MARKA_IZIN,MATCH($J5,MARKA_AD,0))="HAYIR","YASAK",IF($E5="","FİYAT YOK",IF($P5="","TARİH YOK",IF($P5>YAS_YASAK_AY,"YASAK",IF($P5>YAS_ESKI_AY,"ESKİ","OK")))))) -> OK | AB5: =IF(ISNA(MATCH($B5,TIP_AD,0)),"",INDEX(TIP_GRUP,MATCH($B5,TIP_AD,0))) -> AKSESUAR | AC5: =IF(OR($AB5="GUC"),IF(OR($AI5=0,$AI5>KABLO_MAX_IN),0,LOOKUP($AI5,KABLO_IN_ALT,KABLO_KESIT)),IF($AB5="KUMANDA",KUMANDA_KESIT,IF($AB5="OLCU",OLCU_KESIT,0))) -> 0 | AD5: =IF(OR($AC5=0,ISNA(MATCH($B5,TIP_AD,0))),0,IF(INDEX(TIP_TEL,MATCH($B5,TIP_AD,0))="",2*N($S5)+IF(OR(N($S5)=1,N($S5)=3),1,0),INDEX(TIP_TEL,MATCH($B5,TIP_AD,0)))) -> 0 | AE5: =IF(OR($AD5=0,ISNA(MATCH($B5,TIP_AD,0))),0,$AD5*INDEX(TIP_TELM,MATCH($B5,TIP_AD,0))) -> 0 | AF5: =IF(OR($AB5<>"GUC",$AC5=0,$AC5>KLEMENS_MAX_KESIT),0,LOOKUP($AC5,KLEMENS_ALT,KLEMENS_KES)) -> 0 | AG5: =IF($AF5=0,0,N($S5)+IF(OR(N($S5)=1,N($S5)=3),1,0)) -> 0 | AH5: =IF($AF5=0,0,1) -> 0 | AI5: =N($T5) -> 0 | AJ5: =IF(OR($B5="mccb",$B5="oto",$B5="bh",$B5="rubilnik",$B5="ats",$B5="dif",$B5="uzo"),N($T5),0) -> 0
A6: =ROW()-1 -> 5 | B6: oto | C6: 816141 | D6: Авт. выкл. NXB-125 3P 100A 10кА х-ка C (R) | E6: 11015 | F6: =IF(OR($E6="",$L6="",$M6="",$Q6="YASAK"),"",$E6*$L6*$M6) -> 6609 | G6: =IF($F6="","",$F6*$H6) -> 6609 | H6: =SUMPRODUCT((BOM!$C$2:$C$675=$C6)*BOM!$H$2:$H$675*BOM!$M$2:$M$675) -> 1 | I6: шт | J6: chint | K6: =IF(ISNA(MATCH($J6,MARKA_AD,0)),"",INDEX(MARKA_PARA,MATCH($J6,MARKA_AD,0))) -> KZT | L6: =IF(ISNA(MATCH($J6,MARKA_AD,0)),"",INDEX(MARKA_KAT,MATCH($J6,MARKA_AD,0))) -> 0.6 | M6: =IF(OR($K6="",ISNA(MATCH($K6,KUR_AD,0))),"",IF(INDEX(KUR_DEG,MATCH($K6,KUR_AD,0))="","",INDEX(KUR_DEG,MATCH($K6,KUR_AD,0)))) -> 1 | N6: CHINT2608 | O6: =IF(ISNA(MATCH($N6,KAYNAK_KOD,0)),"",IF(INDEX(KAYNAK_TARIH,MATCH($N6,KAYNAK_KOD,0))="","",INDEX(KAYNAK_TARIH,MATCH($N6,KAYNAK_KOD,0)))) -> 46261 | P6: =IF($O6="","",ROUND((TARIH-$O6)/30.4375,1)) -> 0.7 | Q6: =IF(ISNA(MATCH($J6,MARKA_AD,0)),"MARKA YOK",IF(INDEX(MARKA_IZIN,MATCH($J6,MARKA_AD,0))="HAYIR","YASAK",IF($E6="","FİYAT YOK",IF($P6="","TARİH YOK",IF($P6>YAS_YASAK_AY,"YASAK",IF($P6>YAS_ESKI_AY,"ESKİ","OK")))))) -> OK | S6: 3 | T6: 100 | U6: 4.5 | AB6: =IF(ISNA(MATCH($B6,TIP_AD,0)),"",INDEX(TIP_GRUP,MATCH($B6,TIP_AD,0))) -> GUC | AC6: =IF(OR($AB6="GUC"),IF(OR($AI6=0,$AI6>KABLO_MAX_IN),0,LOOKUP($AI6,KABLO_IN_ALT,KABLO_KESIT)),IF($AB6="KUMANDA",KUMANDA_KESIT,IF($AB6="OLCU",OLCU_KESIT,0))) -> 25 | AD6: =IF(OR($AC6=0,ISNA(MATCH($B6,TIP_AD,0))),0,IF(INDEX(TIP_TEL,MATCH($B6,TIP_AD,0))="",2*N($S6)+IF(OR(N($S6)=1,N($S6)=3),1,0),INDEX(TIP_TEL,MATCH($B6,TIP_AD,0)))) -> 7 | AE6: =IF(OR($AD6=0,ISNA(MATCH($B6,TIP_AD,0))),0,$AD6*INDEX(TIP_TELM,MATCH($B6,TIP_AD,0))) -> 0.7 | AF6: =IF(OR($AB6<>"GUC",$AC6=0,$AC6>KLEMENS_MAX_KESIT),0,LOOKUP($AC6,KLEMENS_ALT,KLEMENS_KES)) -> 35 | AG6: =IF($AF6=0,0,N($S6)+IF(OR(N($S6)=1,N($S6)=3),1,0)) -> 4 | AH6: =IF($AF6=0,0,1) -> 1 | AI6: =N($T6) -> 100 | AJ6: =IF(OR($B6="mccb",$B6="oto",$B6="bh",$B6="rubilnik",$B6="ats",$B6="dif",$B6="uzo"),N($T6),0) -> 100
A7: =ROW()-1 -> 6 | B7: oto | C7: 296825 | D7: Авт. выкл. NXB-63S 3P 6А 4.5kA х-ка C (R) | E7: 2873 | F7: =IF(OR($E7="",$L7="",$M7="",$Q7="YASAK"),"",$E7*$L7*$M7) -> 1723.8 | G7: =IF($F7="","",$F7*$H7) -> 3447.6 | H7: =SUMPRODUCT((BOM!$C$2:$C$675=$C7)*BOM!$H$2:$H$675*BOM!$M$2:$M$675) -> 2 | I7: шт | J7: chint | K7: =IF(ISNA(MATCH($J7,MARKA_AD,0)),"",INDEX(MARKA_PARA,MATCH($J7,MARKA_AD,0))) -> KZT | L7: =IF(ISNA(MATCH($J7,MARKA_AD,0)),"",INDEX(MARKA_KAT,MATCH($J7,MARKA_AD,0))) -> 0.6 | M7: =IF(OR($K7="",ISNA(MATCH($K7,KUR_AD,0))),"",IF(INDEX(KUR_DEG,MATCH($K7,KUR_AD,0))="","",INDEX(KUR_DEG,MATCH($K7,KUR_AD,0)))) -> 1 | N7: CHINT2608 | O7: =IF(ISNA(MATCH($N7,KAYNAK_KOD,0)),"",IF(INDEX(KAYNAK_TARIH,MATCH($N7,KAYNAK_KOD,0))="","",INDEX(KAYNAK_TARIH,MATCH($N7,KAYNAK_KOD,0)))) -> 46261 | P7: =IF($O7="","",ROUND((TARIH-$O7)/30.4375,1)) -> 0.7 | Q7: =IF(ISNA(MATCH($J7,MARKA_AD,0)),"MARKA YOK",IF(INDEX(MARKA_IZIN,MATCH($J7,MARKA_AD,0))="HAYIR","YASAK",IF($E7="","FİYAT YOK",IF($P7="","TARİH YOK",IF($P7>YAS_YASAK_AY,"YASAK",IF($P7>YAS_ESKI_AY,"ESKİ","OK")))))) -> OK | S7: 3 | T7: 6 | U7: 3 | AB7: =IF(ISNA(MATCH($B7,TIP_AD,0)),"",INDEX(TIP_GRUP,MATCH($B7,TIP_AD,0))) -> GUC | AC7: =IF(OR($AB7="GUC"),IF(OR($AI7=0,$AI7>KABLO_MAX_IN),0,LOOKUP($AI7,KABLO_IN_ALT,KABLO_KESIT)),IF($AB7="KUMANDA",KUMANDA_KESIT,IF($AB7="OLCU",OLCU_KESIT,0))) -> 1.5 | AD7: =IF(OR($AC7=0,ISNA(MATCH($B7,TIP_AD,0))),0,IF(INDEX(TIP_TEL,MATCH($B7,TIP_AD,0))="",2*N($S7)+IF(OR(N($S7)=1,N($S7)=3),1,0),INDEX(TIP_TEL,MATCH($B7,TIP_AD,0)))) -> 7 | AE7: =IF(OR($AD7=0,ISNA(MATCH($B7,TIP_AD,0))),0,$AD7*INDEX(TIP_TELM,MATCH($B7,TIP_AD,0))) -> 0.7 | AF7: =IF(OR($AB7<>"GUC",$AC7=0,$AC7>KLEMENS_MAX_KESIT),0,LOOKUP($AC7,KLEMENS_ALT,KLEMENS_KES)) -> 2.5 | AG7: =IF($AF7=0,0,N($S7)+IF(OR(N($S7)=1,N($S7)=3),1,0)) -> 4 | AH7: =IF($AF7=0,0,1) -> 1 | AI7: =N($T7) -> 6 | AJ7: =IF(OR($B7="mccb",$B7="oto",$B7="bh",$B7="rubilnik",$B7="ats",$B7="dif",$B7="uzo"),N($T7),0) -> 6
A8: =ROW()-1 -> 7 | B8: oto | C8: 296708 | D8: Авт. выкл. NXB-63S 1P 6А 4.5kA х-ка C (R) | E8: 975 | F8: =IF(OR($E8="",$L8="",$M8="",$Q8="YASAK"),"",$E8*$L8*$M8) -> 585 | G8: =IF($F8="","",$F8*$H8) -> 1170 | H8: =SUMPRODUCT((BOM!$C$2:$C$675=$C8)*BOM!$H$2:$H$675*BOM!$M$2:$M$675) -> 2 | I8: шт | J8: chint | K8: =IF(ISNA(MATCH($J8,MARKA_AD,0)),"",INDEX(MARKA_PARA,MATCH($J8,MARKA_AD,0))) -> KZT | L8: =IF(ISNA(MATCH($J8,MARKA_AD,0)),"",INDEX(MARKA_KAT,MATCH($J8,MARKA_AD,0))) -> 0.6 | M8: =IF(OR($K8="",ISNA(MATCH($K8,KUR_AD,0))),"",IF(INDEX(KUR_DEG,MATCH($K8,KUR_AD,0))="","",INDEX(KUR_DEG,MATCH($K8,KUR_AD,0)))) -> 1 | N8: CHINT2608 | O8: =IF(ISNA(MATCH($N8,KAYNAK_KOD,0)),"",IF(INDEX(KAYNAK_TARIH,MATCH($N8,KAYNAK_KOD,0))="","",INDEX(KAYNAK_TARIH,MATCH($N8,KAYNAK_KOD,0)))) -> 46261 | P8: =IF($O8="","",ROUND((TARIH-$O8)/30.4375,1)) -> 0.7 | Q8: =IF(ISNA(MATCH($J8,MARKA_AD,0)),"MARKA YOK",IF(INDEX(MARKA_IZIN,MATCH($J8,MARKA_AD,0))="HAYIR","YASAK",IF($E8="","FİYAT YOK",IF($P8="","TARİH YOK",IF($P8>YAS_YASAK_AY,"YASAK",IF($P8>YAS_ESKI_AY,"ESKİ","OK")))))) -> OK | S8: 1 | T8: 6 | U8: 1 | AB8: =IF(ISNA(MATCH($B8,TIP_AD,0)),"",INDEX(TIP_GRUP,MATCH($B8,TIP_AD,0))) -> GUC | AC8: =IF(OR($AB8="GUC"),IF(OR($AI8=0,$AI8>KABLO_MAX_IN),0,LOOKUP($AI8,KABLO_IN_ALT,KABLO_KESIT)),IF($AB8="KUMANDA",KUMANDA_KESIT,IF($AB8="OLCU",OLCU_KESIT,0))) -> 1.5 | AD8: =IF(OR($AC8=0,ISNA(MATCH($B8,TIP_AD,0))),0,IF(INDEX(TIP_TEL,MATCH($B8,TIP_AD,0))="",2*N($S8)+IF(OR(N($S8)=1,N($S8)=3),1,0),INDEX(TIP_TEL,MATCH($B8,TIP_AD,0)))) -> 3 | AE8: =IF(OR($AD8=0,ISNA(MATCH($B8,TIP_AD,0))),0,$AD8*INDEX(TIP_TELM,MATCH($B8,TIP_AD,0))) -> 0.3 | AF8: =IF(OR($AB8<>"GUC",$AC8=0,$AC8>KLEMENS_MAX_KESIT),0,LOOKUP($AC8,KLEMENS_ALT,KLEMENS_KES)) -> 2.5 | AG8: =IF($AF8=0,0,N($S8)+IF(OR(N($S8)=1,N($S8)=3),1,0)) -> 2 | AH8: =IF($AF8=0,0,1) -> 1 | AI8: =N($T8) -> 6 | AJ8: =IF(OR($B8="mccb",$B8="oto",$B8="bh",$B8="rubilnik",$B8="ats",$B8="dif",$B8="uzo"),N($T8),0) -> 6
A9: =ROW()-1 -> 8 | B9: lamb | C9: 593076 | D9: Индикатор ND16-22D/2 желтый AC/DC230В (R) | E9: 571 | F9: =IF(OR($E9="",$L9="",$M9="",$Q9="YASAK"),"",$E9*$L9*$M9) -> 342.6 | G9: =IF($F9="","",$F9*$H9) -> 685.2 | H9: =SUMPRODUCT((BOM!$C$2:$C$675=$C9)*BOM!$H$2:$H$675*BOM!$M$2:$M$675) -> 2 | I9: шт | J9: chint | K9: =IF(ISNA(MATCH($J9,MARKA_AD,0)),"",INDEX(MARKA_PARA,MATCH($J9,MARKA_AD,0))) -> KZT | L9: =IF(ISNA(MATCH($J9,MARKA_AD,0)),"",INDEX(MARKA_KAT,MATCH($J9,MARKA_AD,0))) -> 0.6 | M9: =IF(OR($K9="",ISNA(MATCH($K9,KUR_AD,0))),"",IF(INDEX(KUR_DEG,MATCH($K9,KUR_AD,0))="","",INDEX(KUR_DEG,MATCH($K9,KUR_AD,0)))) -> 1 | N9: CHINT2608 | O9: =IF(ISNA(MATCH($N9,KAYNAK_KOD,0)),"",IF(INDEX(KAYNAK_TARIH,MATCH($N9,KAYNAK_KOD,0))="","",INDEX(KAYNAK_TARIH,MATCH($N9,KAYNAK_KOD,0)))) -> 46261 | P9: =IF($O9="","",ROUND((TARIH-$O9)/30.4375,1)) -> 0.7 | Q9: =IF(ISNA(MATCH($J9,MARKA_AD,0)),"MARKA YOK",IF(INDEX(MARKA_IZIN,MATCH($J9,MARKA_AD,0))="HAYIR","YASAK",IF($E9="","FİYAT YOK",IF($P9="","TARİH YOK",IF($P9>YAS_YASAK_AY,"YASAK",IF($P9>YAS_ESKI_AY,"ESKİ","OK")))))) -> OK | AB9: =IF(ISNA(MATCH($B9,TIP_AD,0)),"",INDEX(TIP_GRUP,MATCH($B9,TIP_AD,0))) -> KUMANDA | AC9: =IF(OR($AB9="GUC"),IF(OR($AI9=0,$AI9>KABLO_MAX_IN),0,LOOKUP($AI9,KABLO_IN_ALT,KABLO_KESIT)),IF($AB9="KUMANDA",KUMANDA_KESIT,IF($AB9="OLCU",OLCU_KESIT,0))) -> 1.5 | AD9: =IF(OR($AC9=0,ISNA(MATCH($B9,TIP_AD,0))),0,IF(INDEX(TIP_TEL,MATCH($B9,TIP_AD,0))="",2*N($S9)+IF(OR(N($S9)=1,N($S9)=3),1,0),INDEX(TIP_TEL,MATCH($B9,TIP_AD,0)))) -> 2 | AE9: =IF(OR($AD9=0,ISNA(MATCH($B9,TIP_AD,0))),0,$AD9*INDEX(TIP_TELM,MATCH($B9,TIP_AD,0))) -> 1.6 | AF9: =IF(OR($AB9<>"GUC",$AC9=0,$AC9>KLEMENS_MAX_KESIT),0,LOOKUP($AC9,KLEMENS_ALT,KLEMENS_KES)) -> 0 | AG9: =IF($AF9=0,0,N($S9)+IF(OR(N($S9)=1,N($S9)=3),1,0)) -> 0 | AH9: =IF($AF9=0,0,1) -> 0 | AI9: =N($T9) -> 0 | AJ9: =IF(OR($B9="mccb",$B9="oto",$B9="bh",$B9="rubilnik",$B9="ats",$B9="dif",$B9="uzo"),N($T9),0) -> 0
A10: =ROW()-1 -> 9 | B10: lamb | C10: 593077 | D10: Индикатор ND16-22D/2 зеленый AC/DC230В (R) | E10: 589 | F10: =IF(OR($E10="",$L10="",$M10="",$Q10="YASAK"),"",$E10*$L10*$M10) -> 353.4 | G10: =IF($F10="","",$F10*$H10) -> 706.8 | H10: =SUMPRODUCT((BOM!$C$2:$C$675=$C10)*BOM!$H$2:$H$675*BOM!$M$2:$M$675) -> 2 | I10: шт | J10: chint | K10: =IF(ISNA(MATCH($J10,MARKA_AD,0)),"",INDEX(MARKA_PARA,MATCH($J10,MARKA_AD,0))) -> KZT | L10: =IF(ISNA(MATCH($J10,MARKA_AD,0)),"",INDEX(MARKA_KAT,MATCH($J10,MARKA_AD,0))) -> 0.6 | M10: =IF(OR($K10="",ISNA(MATCH($K10,KUR_AD,0))),"",IF(INDEX(KUR_DEG,MATCH($K10,KUR_AD,0))="","",INDEX(KUR_DEG,MATCH($K10,KUR_AD,0)))) -> 1 | N10: CHINT2608 | O10: =IF(ISNA(MATCH($N10,KAYNAK_KOD,0)),"",IF(INDEX(KAYNAK_TARIH,MATCH($N10,KAYNAK_KOD,0))="","",INDEX(KAYNAK_TARIH,MATCH($N10,KAYNAK_KOD,0)))) -> 46261 | P10: =IF($O10="","",ROUND((TARIH-$O10)/30.4375,1)) -> 0.7 | Q10: =IF(ISNA(MATCH($J10,MARKA_AD,0)),"MARKA YOK",IF(INDEX(MARKA_IZIN,MATCH($J10,MARKA_AD,0))="HAYIR","YASAK",IF($E10="","FİYAT YOK",IF($P10="","TARİH YOK",IF($P10>YAS_YASAK_AY,"YASAK",IF($P10>YAS_ESKI_AY,"ESKİ","OK")))))) -> OK | AB10: =IF(ISNA(MATCH($B10,TIP_AD,0)),"",INDEX(TIP_GRUP,MATCH($B10,TIP_AD,0))) -> KUMANDA | AC10: =IF(OR($AB10="GUC"),IF(OR($AI10=0,$AI10>KABLO_MAX_IN),0,LOOKUP($AI10,KABLO_IN_ALT,KABLO_KESIT)),IF($AB10="KUMANDA",KUMANDA_KESIT,IF($AB10="OLCU",OLCU_KESIT,0))) -> 1.5 | AD10: =IF(OR($AC10=0,ISNA(MATCH($B10,TIP_AD,0))),0,IF(INDEX(TIP_TEL,MATCH($B10,TIP_AD,0))="",2*N($S10)+IF(OR(N($S10)=1,N($S10)=3),1,0),INDEX(TIP_TEL,MATCH($B10,TIP_AD,0)))) -> 2 | AE10: =IF(OR($AD10=0,ISNA(MATCH($B10,TIP_AD,0))),0,$AD10*INDEX(TIP_TELM,MATCH($B10,TIP_AD,0))) -> 1.6 | AF10: =IF(OR($AB10<>"GUC",$AC10=0,$AC10>KLEMENS_MAX_KESIT),0,LOOKUP($AC10,KLEMENS_ALT,KLEMENS_KES)) -> 0 | AG10: =IF($AF10=0,0,N($S10)+IF(OR(N($S10)=1,N($S10)=3),1,0)) -> 0 | AH10: =IF($AF10=0,0,1) -> 0 | AI10: =N($T10) -> 0 | AJ10: =IF(OR($B10="mccb",$B10="oto",$B10="bh",$B10="rubilnik",$B10="ats",$B10="dif",$B10="uzo"),N($T10),0) -> 0
A11: =ROW()-1 -> 10 | B11: lamb | C11: 593075 | D11: Индикатор ND16-22D/2 красный AC/DC230В (R) | E11: 571 | F11: =IF(OR($E11="",$L11="",$M11="",$Q11="YASAK"),"",$E11*$L11*$M11) -> 342.6 | G11: =IF($F11="","",$F11*$H11) -> 1027.8 | H11: =SUMPRODUCT((BOM!$C$2:$C$675=$C11)*BOM!$H$2:$H$675*BOM!$M$2:$M$675) -> 3 | I11: шт | J11: chint | K11: =IF(ISNA(MATCH($J11,MARKA_AD,0)),"",INDEX(MARKA_PARA,MATCH($J11,MARKA_AD,0))) -> KZT | L11: =IF(ISNA(MATCH($J11,MARKA_AD,0)),"",INDEX(MARKA_KAT,MATCH($J11,MARKA_AD,0))) -> 0.6 | M11: =IF(OR($K11="",ISNA(MATCH($K11,KUR_AD,0))),"",IF(INDEX(KUR_DEG,MATCH($K11,KUR_AD,0))="","",INDEX(KUR_DEG,MATCH($K11,KUR_AD,0)))) -> 1 | N11: CHINT2608 | O11: =IF(ISNA(MATCH($N11,KAYNAK_KOD,0)),"",IF(INDEX(KAYNAK_TARIH,MATCH($N11,KAYNAK_KOD,0))="","",INDEX(KAYNAK_TARIH,MATCH($N11,KAYNAK_KOD,0)))) -> 46261 | P11: =IF($O11="","",ROUND((TARIH-$O11)/30.4375,1)) -> 0.7 | Q11: =IF(ISNA(MATCH($J11,MARKA_AD,0)),"MARKA YOK",IF(INDEX(MARKA_IZIN,MATCH($J11,MARKA_AD,0))="HAYIR","YASAK",IF($E11="","FİYAT YOK",IF($P11="","TARİH YOK",IF($P11>YAS_YASAK_AY,"YASAK",IF($P11>YAS_ESKI_AY,"ESKİ","OK")))))) -> OK | AB11: =IF(ISNA(MATCH($B11,TIP_AD,0)),"",INDEX(TIP_GRUP,MATCH($B11,TIP_AD,0))) -> KUMANDA | AC11: =IF(OR($AB11="GUC"),IF(OR($AI11=0,$AI11>KABLO_MAX_IN),0,LOOKUP($AI11,KABLO_IN_ALT,KABLO_KESIT)),IF($AB11="KUMANDA",KUMANDA_KESIT,IF($AB11="OLCU",OLCU_KESIT,0))) -> 1.5 | AD11: =IF(OR($AC11=0,ISNA(MATCH($B11,TIP_AD,0))),0,IF(INDEX(TIP_TEL,MATCH($B11,TIP_AD,0))="",2*N($S11)+IF(OR(N($S11)=1,N($S11)=3),1,0),INDEX(TIP_TEL,MATCH($B11,TIP_AD,0)))) -> 2 | AE11: =IF(OR($AD11=0,ISNA(MATCH($B11,TIP_AD,0))),0,$AD11*INDEX(TIP_TELM,MATCH($B11,TIP_AD,0))) -> 1.6 | AF11: =IF(OR($AB11<>"GUC",$AC11=0,$AC11>KLEMENS_MAX_KESIT),0,LOOKUP($AC11,KLEMENS_ALT,KLEMENS_KES)) -> 0 | AG11: =IF($AF11=0,0,N($S11)+IF(OR(N($S11)=1,N($S11)=3),1,0)) -> 0 | AH11: =IF($AF11=0,0,1) -> 0 | AI11: =N($T11) -> 0 | AJ11: =IF(OR($B11="mccb",$B11="oto",$B11="bh",$B11="rubilnik",$B11="ats",$B11="dif",$B11="uzo"),N($T11),0) -> 0
