Workbook

Sheet Kurallar
A1: TEKLED / YSF HICH — BOM KURALLARI VE PARAMETRELERİ
A2: Проект | B2: 260729 Sensata — «Строительство футбольной академии в г.Талгар», SA-25ДП-192-ЭМ, Альбом 8
A3: BOM tarihi | B3: 46232
A4: Para birimi | B4: KZT (₸), KDV hariç
A5: Marka | B5: CHINT (ana aparat) + EKT/IEK/UNIT (korpus, bara, klemens) + Сайман (sayaç, akım trafosu)
A7: 1. FİYAT VE İŞÇİLİK PARAMETRELERİ (sarı hücreler düzenlenebilir)
A8: Parametre | B8: Değer | C8: Birim | D8: Açıklama
A9: Montaj malzemesi oranı | B9: 0.03 | C9: — | D9: Pano malzeme ara toplamının oranı
A10: İşçilik birim fiyat | B10: 100 | C10: ₸/dk | D10: Kol. G = bu hücre, Kol. I = dakika
A11: Test / etiket / kontrol çarpanı | B11: 1.15 | C11: × | D11: Tüm işçilik normlarına uygulanır
A12: Fiyat yaşı — kullanılabilir sınır | B12: 12 | C12: ay | D12: ≤ bu değer → KULLANILABİLİR
A13: Fiyat yaşı — uyarı sınırı | B13: 18 | C13: ay | D13: > bu değer → YASAK
A15: 2. MARKA KATSAYILARI VE FİYAT LİSTESİ YAŞI
A16: Marka | B16: Katsayı (net = liste × kat.) | C16: Liste tarihi | D16: Yaş, ay | E16: YAŞ_DURUM (formül) | F16: Kaynak dosya
A17: CHINT | B17: 0.6 | C17: 46231 | D17: =ROUND(($B$3-C17)/30.44,1) -> 0 | E17: =IF(D17<=$B$12,"KULLANILABİLİR",IF(D17<=$B$13,"UYARI — teyit et","YASAK — fiyat güncellenmeli")) -> KULLANILABİLİR | F17: 260728_chint_fiyatli_stok_listesi.xlsx
A18: Сайман | B18: 1 | C18: 46023 | D18: =ROUND(($B$3-C18)/30.44,1) -> 6.9 | E18: =IF(D18<=$B$12,"KULLANILABİLİR",IF(D18<=$B$13,"UYARI — teyit et","YASAK — fiyat güncellenmeli")) -> KULLANILABİLİR | F18: САЙМАН_2026_прайс_askardan.xlsx
A19: EKT | B19: 1 | C19: 45827 | D19: =ROUND(($B$3-C19)/30.44,1) -> 13.3 | E19: =IF(D19<=$B$12,"KULLANILABİLİR",IF(D19<=$B$13,"UYARI — teyit et","YASAK — fiyat güncellenmeli")) -> UYARI — teyit et | F19: 19062025_EKT_PRICE.xlsx
A20: IEK | B20: 1 | C20: 45827 | D20: =ROUND(($B$3-C20)/30.44,1) -> 13.3 | E20: =IF(D20<=$B$12,"KULLANILABİLİR",IF(D20<=$B$13,"UYARI — teyit et","YASAK — fiyat güncellenmeli")) -> UYARI — teyit et | F20: 19062025_EKT_PRICE.xlsx
A21: UNIT | B21: 1 | C21: 45827 | D21: =ROUND(($B$3-C21)/30.44,1) -> 13.3 | E21: =IF(D21<=$B$12,"KULLANILABİLİR",IF(D21<=$B$13,"UYARI — teyit et","YASAK — fiyat güncellenmeli")) -> UYARI — teyit et | F21: 19062025_EKT_PRICE.xlsx
A22: Generica | B22: 1 | C22: 45827 | D22: =ROUND(($B$3-C22)/30.44,1) -> 13.3 | E22: =IF(D22<=$B$12,"KULLANILABİLİR",IF(D22<=$B$13,"UYARI — teyit et","YASAK — fiyat güncellenmeli")) -> UYARI — teyit et | F22: 19062025_EKT_PRICE.xlsx
A25: 3. İŞÇİLİK NORMLARI (dk — sarı hücreler düzenlenebilir)
A26: Norm kodu | B26: Açıklama | C26: dk | D26: Birim
A27: OTO1 | B27: Otomatik sigorta 1P | C27: 10 | D27: adet
A28: OTO3 | B28: Otomatik sigorta 3P | C28: 18 | D28: adet
A29: DIF2 | B29: Diferansiyel otomat 1P+N (2 modül) | C29: 14 | D29: adet
A30: DIF4 | B30: Diferansiyel otomat 3P+N (4 modül) | C30: 22 | D30: adet
A31: TMS | B31: Kompakt şalter (MCCB) ≤250A | C31: 60 | D31: adet
A32: RUB | B32: Modüler yük ayırıcı (rubilnik) | C32: 45 | D32: adet
A33: RUBP | B33: Perekidnoy rubilnik 400A (I-0-II) | C33: 90 | D33: adet
A34: SAYAC | B34: Sayaç + akım trafosu grubu | C34: 90 | D34: adet
A35: OLCU | B35: Multimetre / ölçü cihazı (pano kapağı) | C35: 30 | D35: adet
A36: KONT | B36: Kontaktör | C36: 20 | D36: adet
A37: ROLE | B37: Röle / termostat | C37: 10 | D37: adet
A38: BLOK | B38: Yardımcı blok / açtırma bobini | C38: 10 | D38: adet
... A46: KORPUS_F | B46: Korpus hazırlığı — dikili tip (ВРУ) | C46: 90 | D46: adet
A49: 4. ÇAPRAZ DOĞRULAMA — ŞEMA / SPESİFİKASYON UYUŞMAZLIKLARI (⚠ KONTROL)
A50: No | B50: Pano | C50: Konu | D50: Şemada (лист) | E50: Spesifikasyonda (СО) | F50: Alınan karar
A51: 1 | B51: 1-ВРУ | C51: Çıkış Ir=32A adedi | D51: 4 ad. (1QF3, 1QF4, 1QF6, 2QF3) — лист 2 | E51: 3 ad. | F51: ŞEMA esas → 4 adet
A52: 2 | B52: 2-ВРУ | C52: 2QF1 ayar akımı | D52: In=160A, Ir=100A — лист 3 | E52: 3P 160A Ir=125A ×2 | F52: ŞEMA esas → 125A ×1 + 100A ×1
A53: 3 | B53: ЩПС | C53: Çıkış 1P C10 adedi | D53: 4 ad. (QF4, QF5, QF6, QF10) — лист 5 | E53: 3 ad. | F53: ŞEMA esas → 4 adet
...

Sheet BOM
A1: № | B1: Наименование1 | C1: Тип | D1: Артикул | E1: Номенклатура | F1: Цена лист., ₸ | G1: Цена нетто, ₸ | H1: Сумма, ₸ | I1: Кол-во | J1: Ед.изм. | K1: Завод | L1: Примечание
A2: 1 | B2: =E2 -> 1-ВРУ (Блок 1, напольное, 2 секции) | C2: пано | E2: 1-ВРУ (Блок 1, напольное, 2 секции) | I2: 1 | J2: компл.
A3: 2 | C3: korpus | D3: 250200158_ | E3: Корпус ВРУ-1-22 (1700x800x440) пустой щит EKT | F3: 96220 | G3: =F3*VLOOKUP(K3,Kurallar!$A$17:$B$22,2,0) -> 96220 | H3: =G3*I3 -> 192440 | I3: 2 | J3: шт | K3: EKT
A4: 3 | C4: korpus | D4: ст-9951059 | E4: Подставка (цоколь) под ВРУ EKT | F4: 24090 | G4: =F4*VLOOKUP(K4,Kurallar!$A$17:$B$22,2,0) -> 24090 | H4: =G4*I4 -> 48180 | I4: 2 | J4: шт | K4: EKT
A5: 4 | C5: rubilnik | D5: 393375 | E5: Перекидной рубильник NH40-400/3CS, 3P, 400А, 3 положения I-0-II | F5: 215150 | G5: =F5*VLOOKUP(K5,Kurallar!$A$17:$B$22,2,0) -> 129090 | H5: =G5*I5 -> 258180 | I5: 2 | J5: шт | K5: CHINT
A6: 5 | C6: TMŞ | D6: 271174 | E6: Авт. выкл. NM8N-250S TM 3P 200А 50кА с рег. термомаг. расцепителем | F6: 95515 | G6: =F6*VLOOKUP(K6,Kurallar!$A$17:$B$22,2,0) -> 57309 | H6: =G6*I6 -> 114618 | I6: 2 | J6: шт | K6: CHINT
A7: 6 | C7: blok | D7: 269604 | E7: Независимый расцепитель SHT22-M8 AC220-240V для NM8N-250 | F7: 18552 | G7: =F7*VLOOKUP(K7,Kurallar!$A$17:$B$22,2,0) -> 11131.2 | H7: =G7*I7 -> 22262.4 | I7: 2 | J7: шт | K7: CHINT
A8: 7 | C8: tt | D8: TJ | E8: Трансформатор тока ТОП-0,66 У3 кл.точ. 0,5 200/5А | F8: 5100 | G8: =F8*VLOOKUP(K8,Kurallar!$A$17:$B$22,2,0) -> 5100 | H8: =G8*I8 -> 61200 | I8: 12 | J8: шт | K8: Сайман
A9: 8 | C9: sayac | D9: ND | E9: Счетчик Дала СА4У-Э720 (3x220/380V 5-7,5A), акт.+реакт. | F9: 19000 | G9: =F9*VLOOKUP(K9,Kurallar!$A$17:$B$22,2,0) -> 19000 | H9: =G9*I9 -> 38000 | I9: 2 | J9: шт | K9: Сайман
A10: 9 | C10: olcu | D10: 313309 | E10: Многофунк. изм. прибор PD666-3S4 380V 5A 3ф 96x96 RS485 | F10: 70343 | G10: =F10*VLOOKUP(K10,Kurallar!$A$17:$B$22,2,0) -> 42205.8 | H10: =G10*I10 -> 84411.6 | I10: 2 | J10: шт | K10: CHINT
A11: 10 | C11: TMŞ | D11: 146337 | E11: Авт. выкл. NXM-160S/3Р 80A 36кА | F11: 24075 | G11: =F11*VLOOKUP(K11,Kurallar!$A$17:$B$22,2,0) -> 14445 | H11: =G11*I11 -> 14445 | I11: 1 | J11: шт | K11: CHINT
A12: 11 | C12: TMŞ | D12: 146335 | E12: Авт. выкл. NXM-160S/3Р 50A 36кА | F12: 24075 | G12: =F12*VLOOKUP(K12,Kurallar!$A$17:$B$22,2,0) -> 14445 | H12: =G12*I12 -> 101115 | I12: 7 | J12: шт | K12: CHINT
A13: 12 | C13: TMŞ | D13: 146333 | E13: Авт. выкл. NXM-160S/3Р 32A 36кА | F13: 24075 | G13: =F13*VLOOKUP(K13,Kurallar!$A$17:$B$22,2,0) -> 14445 | H13: =G13*I13 -> 57780 | I13: 4 | J13: шт | K13: CHINT
A14: 13 | C14: TMŞ | D14: 146332 | E14: Авт. выкл. NXM-160S/3Р 25A 36кА | F14: 24075 | G14: =F14*VLOOKUP(K14,Kurallar!$A$17:$B$22,2,0) -> 14445 | H14: =G14*I14 -> 86670 | I14: 6 | J14: шт | K14: CHINT
... A24: 23 | C24: montaj | D24: 100300023_ | E24: Провод ПВ3-50 (ПуГВ) | F24: 2935 | G24: =F24*VLOOKUP(K24,Kurallar!$A$17:$B$22,2,0) -> 2935 | H24: =G24*I24 -> 88050 | I24: 30 | J24: м | K24: EKT
A25: 24 | C25: montajный материал | D25: — | E25: Монтажные материалы (наконечники, маркировка, крепёж, метизы) | G25: =SUM(H3:H24)*Kurallar!$B$9 -> 38116.608 | H25: =G25*I25 -> 38116.608 | I25: 1 | J25: компл. | K25: — | L25: Kurallar!B9 = %
A26: 25 | C26: montajная работа | D26: — | E26: Сборка, монтаж, маркировка, испытание щита | F26: =I26/60 -> 47.033333 | G26: =Kurallar!$B$10 -> 100 | H26: =G26*I26 -> 282200 | I26: =ROUND((Kurallar!$C$41*8+Kurallar!$C$38*2+Kurallar!$C$42*6+Kurallar!$C$43*16+Kurallar!$C$39*36+Kurallar!$C$46*2+Kurallar!$C$35*2+Kurallar!$C$37*2+Kurallar!$C$33*2+Kurallar!$C$34*2+Kurallar!$C$31*20)*Kurallar!$B$11,0) -> 2822 | J26: мин. | K26: — | L26: Кол-во = минуты; F = н/час
B27: Toplam: 1-ВРУ (Блок 1, напольное, 2 секции) | H27: =SUBTOTAL(9,H3:H26) -> 1590870.2 | L27: на 1 щит
A28: 27 | B28: =E28 -> 2-ВРУ (Блок 2, напольное, 2 секции) | C28: пано | E28: 2-ВРУ (Блок 2, напольное, 2 секции) | I28: 1 | J28: компл.
A29: 28 | C29: korpus | D29: 250200158_ | E29: Корпус ВРУ-1-22 (1700x800x440) пустой щит EKT | F29: 96220 | G29: =F29*VLOOKUP(K29,Kurallar!$A$17:$B$22,2,0) -> 96220 | H29: =G29*I29 -> 192440 | I29: 2 | J29: шт | K29: EKT
A30: 29 | C30: korpus | D30: ст-9951059 | E30: Подставка (цоколь) под ВРУ EKT | F30: 24090 | G30: =F30*VLOOKUP(K30,Kurallar!$A$17:$B$22,2,0) -> 24090 | H30: =G30*I30 -> 48180 | I30: 2 | J30: шт | K30: EKT
A31: 30 | C31: rubilnik | D31: 393375 | E31: Перекидной рубильник NH40-400/3CS, 3P, 400А, 3 положения I-0-II | F31: 215150 | G31: =F31*VLOOKUP(K31,Kurallar!$A$17:$B$22,2,0) -> 129090 | H31: =G31*I31 -> 258180 | I31: 2 | J31: шт | K31: CHINT
A32: 31 | C32: TMŞ | D32: 271174 | E32: Авт. выкл. NM8N-250S TM 3P 200А 50кА с рег. термомаг. расцепителем | F32: 95515 | G32: =F32*VLOOKUP(K32,Kurallar!$A$17:$B$22,2,0) -> 57309 | H32: =G32*I32 -> 114618 | I32: 2 | J32: шт | K32: CHINT
A33: 32 | C33: blok | D33: 269604 | E33: Независимый расцепитель SHT22-M8 AC220-240V для NM8N-250 | F33: 18552 | G33: =F33*VLOOKUP(K33,Kurallar!$A$17:$B$22,2,0) -> 11131.2 | H33: =G33*I33 -> 22262.4 | I33: 2 | J33: шт | K33: CHINT
A34: 33 | C34: tt | D34: TJ | E34: Трансформатор тока ТОП-0,66 У3 кл.точ. 0,5 200/5А | F34: 5100 | G34: =F34*VLOOKUP(K34,Kurallar!$A$17:$B$22,2,0) -> 5100 | H34: =G34*I34 -> 61200 | I34: 12 | J34: шт | K34: Сайман
A35: 34 | C35: sayac | D35: ND | E35: Счетчик Дала СА4У-Э720 (3x220/380V 5-7,5A), акт.+реакт. | F35: 19000 | G35: =F35*VLOOKUP(K35,Kurallar!$A$17:$B$22,2,0) -> 19000 | H35: =G35*I35 -> 38000 | I35: 2 | J35: шт | K35: Сайман
A36: 35 | C36: olcu | D36: 313309 | E36: Многофунк. изм. прибор PD666-3S4 380V 5A 3ф 96x96 RS485 | F36: 70343 | G36: =F36*VLOOKUP(K36,Kurallar!$A$17:$B$22,2,0) -> 42205.8 | H36: =G36*I36 -> 84411.6 | I36: 2 | J36: шт | K36: CHINT
A37: 36 | C37: TMŞ | D37: 844326 | E37: Авт. выкл. NXM-160S/3Р 125A 36кА | F37: 27656 | G37: =F37*VLOOKUP(K37,Kurallar!$A$17:$B$22,2,0) -> 16593.6 | H37: =G37*I37 -> 16593.6 | I37: 1 | J37: шт | K37: CHINT
A38: 37 | C38: TMŞ | D38: 146338 | E38: Авт. выкл. NXM-160S/3Р 100A 36кА | F38: 24075 | G38: =F38*VLOOKUP(K38,Kurallar!$A$17:$B$22,2,0) -> 14445 | H38: =G38*I38 -> 14445 | I38: 1 | J38: шт | K38: CHINT
A39: 38 | C39: TMŞ | D39: 146337 | E39: Авт. выкл. NXM-160S/3Р 80A 36кА | F39: 24075 | G39: =F39*VLOOKUP(K39,Kurallar!$A$17:$B$22,2,0) -> 14445 | H39: =G39*I39 -> 14445 | I39: 1 | J39: шт | K39: CHINT
A40: 39 | C40: TMŞ | D40: 146335 | E40: Авт. выкл. NXM-160S/3Р 50A 36кА | F40: 24075 | G40: =F40*VLOOKUP(K40,Kurallar!$A$17:$B$22,2,0) -> 14445 | H40: =G40*I40 -> 43335 | I40: 3 | J40: шт | K40: CHINT
... A54: 53 | C54: montaj | D54: 100300023_ | E54: Провод ПВ3-50 (ПуГВ) | F54: 2935 | G54: =F54*VLOOKUP(K54,Kurallar!$A$17:$B$22,2,0) -> 2935 | H54: =G54*I54 -> 88050 | I54: 30 | J54: м | K54: EKT
A55: 54 | C55: montajный материал | D55: — | E55: Монтажные материалы (наконечники, маркировка, крепёж, метизы) | G55: =SUM(H29:H54)*Kurallar!$B$9 -> 38918.058 | H55: =G55*I55 -> 38918.058 | I55: 1 | J55: компл. | K55: — | L55: Kurallar!B9 = %
A56: 55 | C56: montajная работа | D56: — | E56: Сборка, монтаж, маркировка, испытание щита | F56: =I56/60 -> 47.033333 | G56: =Kurallar!$B$10 -> 100 | H56: =G56*I56 -> 282200 | I56: =ROUND((Kurallar!$C$41*8+Kurallar!$C$38*2+Kurallar!$C$42*6+Kurallar!$C$43*16+Kurallar!$C$39*36+Kurallar!$C$46*2+Kurallar!$C$35*2+Kurallar!$C$37*2+Kurallar!$C$33*2+Kurallar!$C$34*2+Kurallar!$C$31*20)*Kurallar!$B$11,0) -> 2822 | J56: мин. | K56: — | L56: Кол-во = минуты; F = н/час
B57: Toplam: 2-ВРУ (Блок 2, напольное, 2 секции) | H57: =SUBTOTAL(9,H29:H56) -> 1618386.7 | L57: на 1 щит
A58: 57 | B58: =E58 -> 3-ВРУ (Блок 3, напольное, 2 секции) | C58: пано | E58: 3-ВРУ (Блок 3, напольное, 2 секции) | I58: 1 | J58: компл.
A59: 58 | C59: korpus | D59: 250200158_ | E59: Корпус ВРУ-1-22 (1700x800x440) пустой щит EKT | F59: 96220 | G59: =F59*VLOOKUP(K59,Kurallar!$A$17:$B$22,2,0) -> 96220 | H59: =G59*I59 -> 192440 | I59: 2 | J59: шт | K59: EKT
A60: 59 | C60: korpus | D60: ст-9951059 | E60: Подставка (цоколь) под ВРУ EKT | F60: 24090 | G60: =F60*VLOOKUP(K60,Kurallar!$A$17:$B$22,2,0) -> 24090 | H60: =G60*I60 -> 48180 | I60: 2 | J60: шт | K60: EKT
A61: 60 | C61: rubilnik | D61: 393375 | E61: Перекидной рубильник NH40-400/3CS, 3P, 400А, 3 положения I-0-II | F61: 215150 | G61: =F61*VLOOKUP(K61,Kurallar!$A$17:$B$22,2,0) -> 129090 | H61: =G61*I61 -> 258180 | I61: 2 | J61: шт | K61: CHINT
A62: 61 | C62: TMŞ | D62: 271172 | E62: Авт. выкл. NM8N-250S TM 3P 160А 50кА с рег. термомаг. расцепителем | F62: 94890 | G62: =F62*VLOOKUP(K62,Kurallar!$A$17:$B$22,2,0) -> 56934 | H62: =G62*I62 -> 113868 | I62: 2 | J62: шт | K62: CHINT
...

Sheet СВОД
A1: № | B1: Наименование щита | C1: Кол-во компл. | D1: Сумма за 1 компл., ₸ | E1: Итого, ₸
A2: 1 | B2: 1-ВРУ (Блок 1, напольное, 2 секции) | C2: 1 | D2: =BOM!H27 -> 1590870.2 | E2: =C2*D2 -> 1590870.2
A3: 2 | B3: 2-ВРУ (Блок 2, напольное, 2 секции) | C3: 1 | D3: =BOM!H57 -> 1618386.7 | E3: =C3*D3 -> 1618386.7
A4: 3 | B4: 3-ВРУ (Блок 3, напольное, 2 секции) | C4: 1 | D4: =BOM!H84 -> 1695737.4 | E4: =C4*D4 -> 1695737.4
A5: 4 | B5: ЩПС — щит противопожарных систем | C5: 1 | D5: =BOM!H98 -> 77464.872 | E5: =C5*D5 -> 77464.872
A6: 5 | B6: ЩГП — щит гарантированного питания | C6: 1 | D6: =BOM!H114 -> 79228.076 | E6: =C6*D6 -> 79228.076
A7: 6 | B7: ЩСоб — щит силовой обогрева | C7: 1 | D7: =BOM!H129 -> 78145.792 | E7: =C7*D7 -> 78145.792
A8: 7 | B8: 1.2-ЩРв — щит силовой вентиляции | C8: 1 | D8: =BOM!H144 -> 72258.996 | E8: =C8*D8 -> 72258.996
A9: 8 | B9: 2.0-ЩРв — щит силовой вентиляции | C9: 1 | D9: =BOM!H160 -> 109466.37 | E9: =C9*D9 -> 109466.37
A10: 9 | B10: 3.0-ЩРв — щит силовой вентиляции | C10: 1 | D10: =BOM!H173 -> 62193.788 | E10: =C10*D10 -> 62193.788
A11: 10 | B11: 1.0-ЩРк — щит силовой кондиционеров | C11: 1 | D11: =BOM!H188 -> 91052.916 | E11: =C11*D11 -> 91052.916
A12: 11 | B12: 2.0-ЩРк — щит силовой кондиционеров | C12: 1 | D12: =BOM!H203 -> 97685.302 | E12: =C12*D12 -> 97685.302
A13: 12 | B13: 3.0-ЩРк — щит силовой кондиционеров | C13: 1 | D13: =BOM!H218 -> 152164.7 | E13: =C13*D13 -> 152164.7
A14: 13 | B14: 1.0-ЩР-1 / 2.0-ЩР-1 — щит силовой | C14: 2 | D14: =BOM!H230 -> 76658.306 | E14: =C14*D14 -> 153316.61
A15: 14 | B15: 1.1-ЩР-1 — щит силовой | C15: 1 | D15: =BOM!H243 -> 141554.83 | E15: =C15*D15 -> 141554.83
A16: 15 | B16: 1.2-ЩР-1 — щит силовой | C16: 1 | D16: =BOM!H255 -> 84362.498 | E16: =C16*D16 -> 84362.498
A17: 16 | B17: 2.1-ЩР-1 — щит силовой (пищеблок) | C17: 1 | D17: =BOM!H269 -> 125850.78 | E17: =C17*D17 -> 125850.78
A18: 17 | B18: 2.1-ЩР-2 — щит силовой | C18: 1 | D18: =BOM!H284 -> 142483.69 | E18: =C18*D18 -> 142483.69
A19: 18 | B19: 2.1-ЩР-3 — щит силовой | C19: 1 | D19: =BOM!H300 -> 121156.3 | E19: =C19*D19 -> 121156.3
A20: 19 | B20: 2.1-ЩР-4(хол) — щит силовой | C20: 1 | D20: =BOM!H314 -> 90017.378 | E20: =C20*D20 -> 90017.378
A21: 20 | B21: 2.1-ЩР-5 — щит силовой | C21: 1 | D21: =BOM!H326 -> 62582.152 | E21: =C21*D21 -> 62582.152
A22: 21 | B22: 2.2-ЩР-1 — щит силовой | C22: 1 | D22: =BOM!H338 -> 130986.03 | E22: =C22*D22 -> 130986.03
A23: 22 | B23: 3.0-ЩР-1 — щит силовой | C23: 1 | D23: =BOM!H350 -> 62582.152 | E23: =C23*D23 -> 62582.152
A24: 23 | B24: 3.1-ЩР-1 — щит силовой (прачечная) | C24: 1 | D24: =BOM!H365 -> 90783.336 | E24: =C24*D24 -> 90783.336
A25: 24 | B25: 3.1-ЩР-2/3, 3.2-ЩР-2/3, 3.3-ЩР-1/2, 3.4-ЩР-1/2 — щит силовой | C25: 8 | D25: =BOM!H377 -> 64786.418 | E25: =C25*D25 -> 518291.34
A26: 25 | B26: 3.2-ЩР-1 — щит силовой | C26: 1 | D26: =BOM!H389 -> 86468.848 | E26: =C26*D26 -> 86468.848
A27: 26 | B27: 1.0-ЩО-1, 2.0-ЩО-1, 3.0-ЩО-1 — щит освещения | C27: 3 | D27: =BOM!H401 -> 40483.254 | E27: =C27*D27 -> 121449.76
A28: 27 | B28: 3.1-ЩО-2, 1.2-ЩО-1, 2.2-ЩО-1, 3.2-ЩО-2, 3.3-ЩО-1/2, 3.4-ЩО-1/2 — щит освещения | C28: 8 | D28: =BOM!H413 -> 40483.254 | E28: =C28*D28 -> 323866.03
A29: 28 | B29: 3.1-ЩО-1, 3.2-ЩО-1 — щит освещения | C29: 2 | D29: =BOM!H425 -> 42917.4 | E29: =C29*D29 -> 85834.8
A30: 29 | B30: 1.1-ЩО-1, 2.1-ЩО-1 — щит освещения | C30: 2 | D30: =BOM!H437 -> 45120.736 | E30: =C30*D30 -> 90241.472
A31: 30 | B31: 1.0-ЩАО-1, 2.0-ЩАО-1 — щит аварийного освещения | C31: 2 | D31: =BOM!H449 -> 42917.4 | E31: =C31*D31 -> 85834.8
A32: 31 | B32: 3.0-ЩАО-1 — щит аварийного освещения | C32: 1 | D32: =BOM!H461 -> 49758.218 | E32: =C32*D32 -> 49758.218
A33: 32 | B33: Щиток лифта (в корпусе в лифтовой шахте) | C33: 1 | D33: =BOM!H470 -> 16542.624 | E33: =C33*D33 -> 16542.624
A34: 33 | B34: ЩУ(бассейн) — щит управления IP65, 24 мод. | C34: 1 | D34: =BOM!H485 -> 112337.16 | E34: =C34*D34 -> 112337.16
A35: 34 | B35: КВ — контакторы вентиляторов (россыпью) | C35: 1 | D35: =BOM!H490 -> 121489.54 | E35: =C35*D35 -> 121489.54
A36: 35 | B36: ЯТП — ящик с понижающим трансформатором 220/36В | C36: 2 | D36: =BOM!H496 -> 30360.34 | E36: =C36*D36 -> 60720.68
B37: ИТОГО по щитам (без НДС) | E37: =SUM(E2:E36) -> 8603166.1
B39: Примечание: позиции блока «KONTROL / KAPSAM DIŞI» в листе BOM в итог не входят — см. лист Kurallar, разделы 4–7.
