Workbook

Sheet BOM
A1: № | B1: Наименование1 | C1: Тип мат. | D1: Артикул | E1: Номенклатура | F1: Цена прайс, KZT | G1: Цена нетто, KZT | H1: Сумма, KZT | I1: Кол-во | J1: Ед.изм. | K1: Завод
B2: =E2 -> ВРУ-1 — Вводно-распределительное устройство ВРУ1-13-20 УХЛ4 (аналог, сборка YSF HICH) | C2: пано | D2: ВРУ-1 | E2: ВРУ-1 — Вводно-распределительное устройство ВРУ1-13-20 УХЛ4 (аналог, сборка YSF HICH) | I2: 1 | J2: комплект | K2: TEKLED ELECTRIC
A3: 1 | B3: =E2 -> ВРУ-1 — Вводно-распределительное устройство ВРУ1-13-20 УХЛ4 (аналог, сборка YSF HICH) | C3: korpus | D3: 719-15043 | E3: Мет. Щит ВРУ 1700х800х450+10CM База | F3: 155000 | G3: =ROUND(F3*Kurallar!$B$6,0) -> 93000 | H3: =G3*I3 -> 93000 | I3: 1 | J3: шт. | K3: Kaztek/TEKSAN
A4: 2 | B4: =E2 -> ВРУ-1 — Вводно-распределительное устройство ВРУ1-13-20 УХЛ4 (аналог, сборка YSF HICH) | C4: TMŞ | D4: 131364 | E4: Авт. выкл. NXM-160S/3Р 160A 36кА (R) | F4: 27169 | G4: =ROUND(F4*Kurallar!$B$4,0) -> 16301 | H4: =G4*I4 -> 16301 | I4: 1 | J4: шт. | K4: CHINT
A5: 3 | B5: =E2 -> ВРУ-1 — Вводно-распределительное устройство ВРУ1-13-20 УХЛ4 (аналог, сборка YSF HICH) | C5: TMŞ | D5: 131363 | E5: Авт. выкл. NXM-125S/3Р 125A 25кА (R) | F5: 19760 | G5: =ROUND(F5*Kurallar!$B$4,0) -> 11856 | H5: =G5*I5 -> 11856 | I5: 1 | J5: шт. | K5: CHINT
A6: 4 | B6: =E2 -> ВРУ-1 — Вводно-распределительное устройство ВРУ1-13-20 УХЛ4 (аналог, сборка YSF HICH) | C6: rubilnik | D6: 270100160_ | E6: Рубильник ВР-32-35 В71250-250А на 2 направления (+6камер) UNIT (1/8) | F6: 16414 | G6: =F6 -> 16414 | H6: =G6*I6 -> 32828 | I6: 2 | J6: шт. | K6: pys
A7: 5 | B7: =E2 -> ВРУ-1 — Вводно-распределительное устройство ВРУ1-13-20 УХЛ4 (аналог, сборка YSF HICH) | C7: tt | D7: 256478 | E7: Трансформатор тока BH-0.66 30 B 150/5А, кл. точн. 0,5 (аналог ТТИ-А 150/5А 5ВА) | F7: 5682 | G7: =ROUND(F7*Kurallar!$B$4,0) -> 3409 | H7: =G7*I7 -> 20454 | I7: 6 | J7: шт. | K7: CHINT
A8: 6 | B8: =E2 -> ВРУ-1 — Вводно-распределительное устройство ВРУ1-13-20 УХЛ4 (аналог, сборка YSF HICH) | C8: sayac | D8: ЦЭ 6850М | E8: Счётчик электроэнергии ЦЭ 6850М 380В 5А, электронный, АСКУЭ (Энергомера) — см. K02 | F8: 125000 | G8: =F8 -> 125000 | H8: =G8*I8 -> 0 | I8: 0 | J8: шт. | K8: Энергомера / прочее
A9: 8 | B9: =E2 -> ВРУ-1 — Вводно-распределительное устройство ВРУ1-13-20 УХЛ4 (аналог, сборка YSF HICH) | C9: LOOBAR | D9: 130200152_ | E9: Шина алюм АД31Т 3х30х4000 | F9: 724 | G9: =ROUND(F9*Kurallar!$B$5,0) -> 724 | H9: =G9*I9 -> 7240 | I9: 10 | J9: м | K9: pys
A10: 9 | B10: =E2 -> ВРУ-1 — Вводно-распределительное устройство ВРУ1-13-20 УХЛ4 (аналог, сборка YSF HICH) | C10: blok | D10: 130500106_ | E10: Изолятор SM40 с болтом (М8) 475А 12кВ UNIT | F10: 324 | G10: =ROUND(F10*Kurallar!$B$5,0) -> 324 | H10: =G10*I10 -> 1944 | I10: 6 | J10: шт. | K10: pys
A11: 10 | B11: =E2 -> ВРУ-1 — Вводно-распределительное устройство ВРУ1-13-20 УХЛ4 (аналог, сборка YSF HICH) | C11: montajный материал | D11: 570003 | E11: DIN-рейка оцинкованная TH35-7.5 100 см | F11: 869 | G11: =ROUND(F11*Kurallar!$B$4,0) -> 521 | H11: =G11*I11 -> 2084 | I11: 4 | J11: шт. | K11: CHINT
A12: 11 | B12: =E2 -> ВРУ-1 — Вводно-распределительное устройство ВРУ1-13-20 УХЛ4 (аналог, сборка YSF HICH) | C12: montajный материал | D12: 270300200_ | E12: Кабель-канал перфорированный 60х40 ИМПАКТ IEK (2 м) | F12: 1801 | G12: =ROUND(F12*Kurallar!$B$5,0) -> 1801 | H12: =G12*I12 -> 10806 | I12: 6 | J12: шт. | K12: pys
A13: 12 | B13: =E2 -> ВРУ-1 — Вводно-распределительное устройство ВРУ1-13-20 УХЛ4 (аналог, сборка YSF HICH) | C13: Klemens | D13: 701-03250-1 | E13: Клемма проходная JHUK2.5B (TEKLED ELECTRIC)2000/100 | F13: 120 | G13: =0.6*F13 -> 72 | H13: =G13*I13 -> 2880 | I13: 40 | J13: шт. | K13: tekled
A14: 13 | B14: =E2 -> ВРУ-1 — Вводно-распределительное устройство ВРУ1-13-20 УХЛ4 (аналог, сборка YSF HICH) | C14: kablo | D14: 100300025_ | E14: Провод ПВ3-2,5 белый ГОСТ | F14: 127 | G14: =ROUND(F14*Kurallar!$B$5,0) -> 127 | H14: =G14*I14 -> 7620 | I14: 60 | J14: м | K14: pys
A15: 14 | B15: =E2 -> ВРУ-1 — Вводно-распределительное устройство ВРУ1-13-20 УХЛ4 (аналог, сборка YSF HICH) | C15: kablo | D15: 100300100_ | E15: Провод ПВ3-2,5 жёлто-зелёный ГОСТ | F15: 127 | G15: =ROUND(F15*Kurallar!$B$5,0) -> 127 | H15: =G15*I15 -> 2540 | I15: 20 | J15: м | K15: pys
A16: 15 | B16: =E2 -> ВРУ-1 — Вводно-распределительное устройство ВРУ1-13-20 УХЛ4 (аналог, сборка YSF HICH) | C16: nakonechnik | D16: 260100016_ | E16: Наконечник медный М 70-10-13 | F16: 329 | G16: =ROUND(F16*Kurallar!$B$5,0) -> 329 | H16: =G16*I16 -> 9870 | I16: 30 | J16: шт. | K16: pys
A17: 16 | B17: =E2 -> ВРУ-1 — Вводно-распределительное устройство ВРУ1-13-20 УХЛ4 (аналог, сборка YSF HICH) | C17: nakonechnik | D17: 260100058_ | E17: Наконечник медно-лужёный Мл 2,5-4-2,6 | F17: 37 | G17: =ROUND(F17*Kurallar!$B$5,0) -> 37 | H17: =G17*I17 -> 3700 | I17: 100 | J17: шт. | K17: pys
A18: 17 | B18: =E2 -> ВРУ-1 — Вводно-распределительное устройство ВРУ1-13-20 УХЛ4 (аналог, сборка YSF HICH) | C18: montajный материал | D18: MONT-3% | E18: Монтажный материал (крепёж, маркировка, кабельные стяжки, наконечники НШВИ) — % от суммы материалов панели | G18: =ROUND(SUM(H3:H17)*Kurallar!$B$9,0) -> 6694 | H18: =G18*I18 -> 6694 | I18: 1 | J18: компл. | K18: montajный материал
A19: 18 | B19: =E2 -> ВРУ-1 — Вводно-распределительное устройство ВРУ1-13-20 УХЛ4 (аналог, сборка YSF HICH) | C19: montajная работа | D19: ISC | E19: Монтажные работы по сборке панели (норма времени, мин) — расчёт в листе Kurallar | F19: =I19/60 -> 10.2 | G19: =Kurallar!$B$10 -> 100 | H19: =G19*I19 -> 61200 | I19: =Kurallar!G62 -> 612 | J19: мин | K19: montajная работа
B20: Итого ВРУ-1 (1 шт.) | H20: =SUBTOTAL(9,H3:H19) -> 291017
B21: =E21 -> ВРУ-2 — Распределительная панель ВРУ1-50-00 УХЛ4 (аналог, сборка YSF HICH) | C21: пано | D21: ВРУ-2 | E21: ВРУ-2 — Распределительная панель ВРУ1-50-00 УХЛ4 (аналог, сборка YSF HICH) | I21: 1 | J21: комплект | K21: TEKLED ELECTRIC
A22: 19 | B22: =E21 -> ВРУ-2 — Распределительная панель ВРУ1-50-00 УХЛ4 (аналог, сборка YSF HICH) | C22: korpus | D22: 719-15043 | E22: Мет. Щит ВРУ 1700х800х450+10CM База | F22: 155000 | G22: =ROUND(F22*Kurallar!$B$6,0) -> 93000 | H22: =G22*I22 -> 93000 | I22: 1 | J22: шт. | K22: Kaztek/TEKSAN
A23: 20 | B23: =E21 -> ВРУ-2 — Распределительная панель ВРУ1-50-00 УХЛ4 (аналог, сборка YSF HICH) | C23: fu | D23: 521260 | E23: Держатель плавкой вставки RT36-00-160, габарит 00, 160А | F23: 2038 | G23: =ROUND(F23*Kurallar!$B$4,0) -> 1223 | H23: =G23*I23 -> 7338 | I23: 6 | J23: шт. | K23: CHINT
A24: 21 | B24: =E21 -> ВРУ-2 — Распределительная панель ВРУ1-50-00 УХЛ4 (аналог, сборка YSF HICH) | C24: fu | D24: 521349 | E24: Плавкая вставка предохранителя RT36-00-160, габарит 00, 100А | F24: 1545 | G24: =ROUND(F24*Kurallar!$B$4,0) -> 927 | H24: =G24*I24 -> 5562 | I24: 6 | J24: шт. | K24: CHINT
A25: 22 | B25: =E21 -> ВРУ-2 — Распределительная панель ВРУ1-50-00 УХЛ4 (аналог, сборка YSF HICH) | C25: fu | D25: 521260 | E25: Держатель плавкой вставки RT36-00-160, габарит 00, 160А | F25: 2038 | G25: =ROUND(F25*Kurallar!$B$4,0) -> 1223 | H25: =G25*I25 -> 22014 | I25: 18 | J25: шт. | K25: CHINT
A26: 23 | B26: =E21 -> ВРУ-2 — Распределительная панель ВРУ1-50-00 УХЛ4 (аналог, сборка YSF HICH) | C26: fu | D26: 521345 | E26: Плавкая вставка предохранителя RT36-00-160, габарит 00, 50А | F26: 1525 | G26: =ROUND(F26*Kurallar!$B$4,0) -> 915 | H26: =G26*I26 -> 2745 | I26: 3 | J26: шт. | K26: CHINT
A27: 24 | B27: =E21 -> ВРУ-2 — Распределительная панель ВРУ1-50-00 УХЛ4 (аналог, сборка YSF HICH) | C27: fu | D27: 521344 | E27: Плавкая вставка предохранителя RT36-00-160, габарит 00, 40А | F27: 1525 | G27: =ROUND(F27*Kurallar!$B$4,0) -> 915 | H27: =G27*I27 -> 13725 | I27: 15 | J27: шт. | K27: CHINT
A28: 25 | B28: =E21 -> ВРУ-2 — Распределительная панель ВРУ1-50-00 УХЛ4 (аналог, сборка YSF HICH) | C28: LOOBAR | D28: 130200152_ | E28: Шина алюм АД31Т 3х30х4000 | F28: 724 | G28: =ROUND(F28*Kurallar!$B$5,0) -> 724 | H28: =G28*I28 -> 7240 | I28: 10 | J28: м | K28: pys
A29: 26 | B29: =E21 -> ВРУ-2 — Распределительная панель ВРУ1-50-00 УХЛ4 (аналог, сборка YSF HICH) | C29: blok | D29: 130500106_ | E29: Изолятор SM40 с болтом (М8) 475А 12кВ UNIT | F29: 324 | G29: =ROUND(F29*Kurallar!$B$5,0) -> 324 | H29: =G29*I29 -> 1296 | I29: 4 | J29: шт. | K29: pys
A30: 31 | B30: =E21 -> ВРУ-2 — Распределительная панель ВРУ1-50-00 УХЛ4 (аналог, сборка YSF HICH) | C30: kablo | D30: 100300100_ | E30: Провод ПВ3-2,5 жёлто-зелёный ГОСТ | F30: 127 | G30: =ROUND(F30*Kurallar!$B$5,0) -> 127 | H30: =G30*I30 -> 1270 | I30: 10 | J30: м | K30: pys
A31: 32 | B31: =E21 -> ВРУ-2 — Распределительная панель ВРУ1-50-00 УХЛ4 (аналог, сборка YSF HICH) | C31: montajный материал | D31: MONT-3% | E31: Монтажный материал (крепёж, маркировка, кабельные стяжки, наконечники НШВИ) — % от суммы материалов панели | G31: =ROUND(SUM(H22:H30)*Kurallar!$B$9,0) -> 4626 | H31: =G31*I31 -> 4626 | I31: 1 | J31: компл. | K31: montajный материал
A32: 33 | B32: =E21 -> ВРУ-2 — Распределительная панель ВРУ1-50-00 УХЛ4 (аналог, сборка YSF HICH) | C32: montajная работа | D32: ISC | E32: Монтажные работы по сборке панели (норма времени, мин) — расчёт в листе Kurallar | F32: =I32/60 -> 7.1 | G32: =Kurallar!$B$10 -> 100 | H32: =G32*I32 -> 42600 | I32: =Kurallar!H62 -> 426 | J32: мин | K32: montajная работа
B33: Итого ВРУ-2 (1 шт.) | H33: =SUBTOTAL(9,H22:H32) -> 201416
B34: =E34 -> АВР-101-100А | E34: АВР-101-100А | F34: =2.3*H51 -> 528954 | G34: =0.65*F34 -> 343820.1 | I34: 1 | J34: комплект | K34: TEKSAN
B35: =B34 -> АВР-101-100А | C35: korpus | D35: 719-15450 | E35: Корпус ЩМП5 (1000x650x300) IP54 | F35: 40030 | G35: =F35*0.6 -> 24018 | H35: =I35*G35 -> 24018 | I35: 1 | J35: ШТ. | K35: teksan f
B36: =B35 -> АВР-101-100А | C36: oto | D36: 131362 | E36: Авт. выкл. NXM-125S/3Р 100A 25кА (R) | F36: 19443 | G36: =F36*0.6 -> 11665.8 | H36: =G36*I36 -> 23331.6 | I36: 2 | J36: ШТ. | K36: chint
B37: =B36 -> АВР-101-100А | C37: contactor | D37: 235643 | E37: Контактор NC2-115 115A 220-240В/АС3 50Гц (старый артикул) | F37: 84983 | G37: =F37*0.6 -> 50989.8 | H37: =G37*I37 -> 101979.6 | I37: 2 | J37: ШТ. | K37: chint
B38: =B37 -> АВР-101-100А | C38: rele | D38: 285448 | E38: Промежуточное реле JZX-22F(D) 4 конт. с инд. LED 3А 220В AC (R) | F38: 1565 | G38: =F38*0.6 -> 939 | H38: =G38*I38 -> 1878 | I38: 2 | J38: ШТ. | K38: chint
B39: =B38 -> АВР-101-100А | C39: rozetka | D39: 285976 | E39: Розетка CZY14A для JZX-22F(D) 4 контакта | F39: 682 | G39: =F39*0.6 -> 409.2 | H39: =G39*I39 -> 818.4 | I39: 2 | J39: ШТ. | K39: chint
B40: =B39 -> АВР-101-100А | C40: rele | D40: 296829 | E40: CKF-318-1 | F40: 15000 | G40: =F40 -> 15000 | H40: =G40*I40 -> 30000 | I40: 2 | J40: ШТ. | K40: pys
...

Sheet СВОД
A1: СВОД — 260818 Laura Chimkent VRU / Заявка ТМЦ №36995
A2: № | B2: Панель | C2: Наименование | D2: Цена за 1 шт., KZT | E2: Кол-во, шт. | F2: Сумма, KZT
A3: 1 | B3: ВРУ-1 | C3: ВРУ1-13-20 УХЛ4 (аналог) — вводная панель | D3: =BOM!H20 -> 291017 | E3: 1 | F3: =D3*E3 -> 291017
A4: 2 | B4: ВРУ-2 | C4: ВРУ1-50-00 УХЛ4 (аналог) — распределительная панель | D4: =BOM!H33 -> 201416 | E4: 1 | F4: =D4*E4 -> 201416
A5: 3 | B5: ЩС-1 | C5: ЩУРн-3/48 (проект ЩУРн-3/36зо) | D5: =BOM!H71 -> 85827.6 | E5: 1 | F5: =D5*E5 -> 85827.6
A6: 4 | B6: ЩС-2 | C6: ЩУРн-3/30 (проект ЩУРн-3/24зо) | D6: =BOM!H91 -> 78871.6 | E6: 1 | F6: =D6*E6 -> 78871.6
C7: ИТОГО по заявке №36995 | F7: =SUM(F3:F6) -> 657132.2
C8: ВНИМАНИЕ: цены счётчиков (ЦЭ 6850М, СЕ 301 S31) и АВР-101-100 отсутствуют в прайс-листах — итог НЕПОЛНЫЙ (см. Kurallar K02, K03).

Sheet Kurallar
A1: KURALLAR / KATSAYILAR — 260818 Laura Chimkent VRU (Заявка ТМЦ №36995)
A2: 1. MARKA KATSAYILARI (sarı hücreler düzenlenebilir)
A3: Marka | B3: Katsayı | C3: Açıklama
A4: CHINT | B4: 0.6 | C4: liste × 0,60 (%40 iskonto)
A5: EKT / IEK / UNIT | B5: 1 | C5: EKT liste fiyatı, net
A6: Kaztek / TEKSAN | B6: 0.6 | C6: Kaztek liste fiyatı, net
A7: 2. GENEL PARAMETRELER
A8: Parametre | B8: Değer | C8: Açıklama
A9: Montaj malzemesi oranı | B9: 0.03 | C9: pano malzeme ara toplamının %3'ü
A10: İşçilik birim fiyat (KZT/dk) | B10: 100 | C10: BOM sütun G
A11: İşçilik çarpanı | B11: 1.15 | C11: test, etiketleme, kontrol
A12: Pano seti adedi | B12: 15 | C12: Заявка №36995: 1-15 blok
A13: BOM tarihi | B13: 46252 | C13: yaş hesabı bu tarihe göre
A14: 3. FİYAT LİSTESİ YAŞI (YAS_DURUM formülle hesaplanır)
A15: Marka / liste | B15: Liste tarihi | C15: Yaş (ay) | D15: YAS_DURUM | E15: Bu BOM'da kullanım
A16: CHINT (260728 stok+fiyat) | B16: 46231 | C16: =ROUND((YEAR($B$13)-YEAR(B16))*12+(MONTH($B$13)-MONTH(B16))+(DAY($B$13)-DAY(B16))/30.44,1) -> 0.7 | D16: =IF(C16>18,"YASAK",IF(C16>12,"UYARI","OK")) -> OK | E16: Ana cihaz markası — kullanıldı
A17: Kaztek pano (2607_15) | B17: 46218 | C17: =ROUND((YEAR($B$13)-YEAR(B17))*12+(MONTH($B$13)-MONTH(B17))+(DAY($B$13)-DAY(B17))/30.44,1) -> 1.1 | D17: =IF(C17>18,"YASAK",IF(C17>12,"UYARI","OK")) -> OK | E17: Korpuslar — kullanıldı
A18: EKT (19062025) | B18: 45827 | C18: =ROUND((YEAR($B$13)-YEAR(B18))*12+(MONTH($B$13)-MONTH(B18))+(DAY($B$13)-DAY(B18))/30.44,1) -> 14 | D18: =IF(C18>18,"YASAK",IF(C18>12,"UYARI","OK")) -> UYARI | E18: Pano içi malzeme — UYARI ile kullanıldı
A19: Schneider (2025 Temmuz) | B19: 45839 | C19: =ROUND((YEAR($B$13)-YEAR(B19))*12+(MONTH($B$13)-MONTH(B19))+(DAY($B$13)-DAY(B19))/30.44,1) -> 13.6 | D19: =IF(C19>18,"YASAK",IF(C19>12,"UYARI","OK")) -> UYARI | E19: Kullanılmadı
A20: ABB (2025 Kasım) | B20: 45962 | C20: =ROUND((YEAR($B$13)-YEAR(B20))*12+(MONTH($B$13)-MONTH(B20))+(DAY($B$13)-DAY(B20))/30.44,1) -> 9.6 | D20: =IF(C20>18,"YASAK",IF(C20>12,"UYARI","OK")) -> OK | E20: Kullanılmadı
A21: Legrand (2025 Ekim) | B21: 45931 | C21: =ROUND((YEAR($B$13)-YEAR(B21))*12+(MONTH($B$13)-MONTH(B21))+(DAY($B$13)-DAY(B21))/30.44,1) -> 10.6 | D21: =IF(C21>18,"YASAK",IF(C21>12,"UYARI","OK")) -> OK | E21: Kullanılmadı (×0,50 katsayı teyitsiz)
A22: CNC (250204) | B22: 45692 | C22: =ROUND((YEAR($B$13)-YEAR(B22))*12+(MONTH($B$13)-MONTH(B22))+(DAY($B$13)-DAY(B22))/30.44,1) -> 18.5 | D22: =IF(C22>18,"YASAK",IF(C22>12,"UYARI","OK")) -> YASAK | E22: YASAK — 18 ay eşiği aşıldı, yenilenmeli
A23: EKF (22.02.2022) | B23: 44614 | C23: =ROUND((YEAR($B$13)-YEAR(B23))*12+(MONTH($B$13)-MONTH(B23))+(DAY($B$13)-DAY(B23))/30.44,1) -> 53.9 | D23: =IF(C23>18,"YASAK",IF(C23>12,"UYARI","OK")) -> YASAK | E23: Fiyatlama yasak — sadece artikül referansı
A24: Klemsan (Kasım 2022) | B24: 44866 | C24: =ROUND((YEAR($B$13)-YEAR(B24))*12+(MONTH($B$13)-MONTH(B24))+(DAY($B$13)-DAY(B24))/30.44,1) -> 45.6 | D24: =IF(C24>18,"YASAK",IF(C24>12,"UYARI","OK")) -> YASAK | E24: Fiyatlama yasak
A25: ONKA (Temmuz 2022) | B25: 44743 | C25: =ROUND((YEAR($B$13)-YEAR(B25))*12+(MONTH($B$13)-MONTH(B25))+(DAY($B$13)-DAY(B25))/30.44,1) -> 49.6 | D25: =IF(C25>18,"YASAK",IF(C25>12,"UYARI","OK")) -> YASAK | E25: Fiyatlama yasak
A26: Harmony kablo prays-listi | B26: TARİH YOK | E26: Tarih belirsiz — kablo fiyatlaması yapılmadı
A27: 4. İŞÇİLİK ZAMAN NORMLARI (dk/birim) — sarı hücreler düzenlenebilir
A28: Norm kalemi | B28: dk
A29: MCB 1P (otomat) | B29: 10
A30: MCB 3P (otomat) | B30: 18
A31: Diferansiyel 2P (RCBO) | B31: 14
A32: MCCB ≤250A (TMŞ) | B32: 60
A33: Perekidnoy rubilnik / переключатель 250A | B33: 60
A34: Rubilnik modüler (выкл. нагрузки) | B34: 45
A35: Sigorta yuvası (RT36 держатель) | B35: 20
A36: Sayaç + akım trafosu seti | B36: 90
A37: AVR cihazı | B37: 60
A38: Klemens (adet) | B38: 4
A39: Tarak bara (adet) | B39: 10
A40: Bakır bara (m) | B40: 45
...
