Workbook

Sheet 01_BOM_DUZELTILDI
A1: № | B1: Pano | C1: Kategori | D1: Ürün Kodu | E1: Ürün İsmi / Açıklama | F1: Birim Fiyat | G1: Birim Net Fiyat2 | H1: Toplam Net (1 pano) | I1: Miktar | J1: Birim | K1: Marka/Tedarikçi | L1: Teknik Özellik | M1: Projedeki Korpus Ölçüsü | N1: Önerilen / Seçilen Korpus | O1: Kaynak | P1: Not | Q1: Tahmini modül | R1: Para | S1: İndirim %
A2: 1 | B2: ВРУ | C2: PANO | E2: ВРУ | G2: ='01_BOM_DUZELTILDI'!$F2 -> 0 | I2: 1 | J2: компл. | K2: TEKLED/TEKSAN | L2: ВРУ / индивидуального изготовления — IP30 / IP30 | M2: индивидуальное изготовление; глубина 450 мм по проекту | N2: ВРУ инд. изг.; глубина 450 мм; габариты уточнить при изготовлении | O2: PDF/Claude BOM | P2: Toplanmış pano satırı; iç malzemeler 1 pano içindir
A3: 2 | B3: ВРУ | C3: korpus | D3: 719-15075 | E3: Met.Korpus Pustoi 1800x800x450 10sm | F3: 165000 | G3: =0.6*F3 -> 99000 | H3: ='01_BOM_DUZELTILDI'!$G3*'01_BOM_DUZELTILDI'!$I3 -> 198000 | I3: 2 | J3: шт | K3: TEKSAN f | L3: индивидуальное изготовление; глубина 450 мм по проекту; IP30 | M3: индивидуальное изготовление; глубина 450 мм по проекту | N3: ВРУ инд. изг.; глубина 450 мм; габариты уточнить при изготовлении | O3: PDF + Claude BOM | P3: Birim düzeltildi: iç malzemede "компл." kullanılmadı | R3: KZT
A4: 3 | B4: ВРУ | C4: rubilnik | D4: 270100161_ | E4: Рубильник ВР-32-37 В71250-400А на 2 направления (+6камер) UNIT (1/6) | F4: 24000 | G4: ='01_BOM_DUZELTILDI'!$F4 -> 24000 | H4: ='01_BOM_DUZELTILDI'!$G4*'01_BOM_DUZELTILDI'!$I4 -> 48000 | I4: 2 | J4: шт | K4: PYS | L4: 3P, 400A | O4: CHINT muadil; fiyat kontrol | P4: Ввод 1 и Ввод 2; аналог вместо BP32И-37B71250; Fiyat IEK kaynaklı olabilir; CHINT fiyat listesi ile kontrol et | R4: KZT
A5: 4 | B5: ВРУ | C5: MCCB | D5: 131369 | E5: Авт. выкл. NXM-250S/3Р 250A 36кА (R) | F5: 36869 | G5: =0.6*F5 -> 22121.4 | H5: ='01_BOM_DUZELTILDI'!$G5*'01_BOM_DUZELTILDI'!$I5 -> 44242.8 | I5: 2 | J5: шт | K5: CHINT | L5: 3P, 250A | O5: CHINT muadil; fiyat kontrol | P5: Секции I+II; аналог вместо ВА88-35; Fiyat IEK kaynaklı olabilir; CHINT fiyat listesi ile kontrol et | R5: KZT
A6: 5 | B6: ВРУ | C6: MCCB | D6: 131364 | E6: Авт. выкл. NXM-160S/3Р 160A 36кА (R) | F6: 27169 | G6: =0.6*F6 -> 16301.4 | H6: ='01_BOM_DUZELTILDI'!$G6*'01_BOM_DUZELTILDI'!$I6 -> 48904.2 | I6: 3 | J6: шт | K6: CHINT | L6: 3P, 160A | O6: CHINT muadil; fiyat kontrol | P6: 4 шт распределение; аналог вместо ВА88-32; Fiyat IEK kaynaklı olabilir; CHINT fiyat listesi ile kontrol et | R6: KZT
A7: 6 | B7: ВРУ | C7: MCB | D7: 296708 | E7: Авт. выкл. NXB-63S 1P 6А 4.5kA х-ка C (R) | F7: 975 | G7: =0.6*F7 -> 585 | H7: ='01_BOM_DUZELTILDI'!$G7*'01_BOM_DUZELTILDI'!$I7 -> 1170 | I7: 2 | J7: шт | K7: CHINT | L7: 1P 6A | O7: CHINT muadil; fiyat kontrol | P7: Отходящие линии; аналог вместо ВА47-100-3Р25А; Fiyat IEK kaynaklı olabilir; CHINT fiyat listesi ile kontrol et | Q7: 30 | R7: KZT
A8: 6 | B8: ВРУ | C8: MCB | D8: 296829 | E8: Авт. выкл. NXB-63S 3P 25А 4.5kA х-ка C (R) | F8: 2429 | G8: =0.6*F8 -> 1457.4 | H8: ='01_BOM_DUZELTILDI'!$G8*'01_BOM_DUZELTILDI'!$I8 -> 8744.4 | I8: 6 | J8: шт | K8: CHINT | L8: 3P, C25A | O8: CHINT muadil; fiyat kontrol | P8: Отходящие линии; аналог вместо ВА47-100-3Р25А; Fiyat IEK kaynaklı olabilir; CHINT fiyat listesi ile kontrol et | Q8: 30 | R8: KZT
A9: 7 | B9: ВРУ | C9: RCBO | D9: 515381 | E9: Диф. авт. выкл. NXBLE-63YH 1P+N C16 30mA тип A, 6kA (R) | F9: 5104 | G9: =0.6*F9 -> 3062.4 | H9: ='01_BOM_DUZELTILDI'!$G9*'01_BOM_DUZELTILDI'!$I9 -> 3062.4 | I9: 1 | J9: шт | K9: CHINT | L9: 1P+N, C16A, 30mA, 30мА | O9: CHINT muadil; fiyat kontrol | P9: ЩАО сигнализация; аналог вместо АВДТ32М; Fiyat IEK kaynaklı olabilir; CHINT fiyat listesi ile kontrol et | Q9: 2 | R9: KZT
A10: 8 | B10: ВРУ | C10: MTR | D10: 270300182_ | E10: Трансформатор Т-0,66 250\5 (9) | F10: 6350 | G10: ='01_BOM_DUZELTILDI'!$F10 -> 6350 | H10: ='01_BOM_DUZELTILDI'!$G10*'01_BOM_DUZELTILDI'!$I10 -> 38100 | I10: 6 | J10: шт | K10: pys | L10: 5A | O10: PDF + Claude BOM | P10: 3 шт секция I + 3 шт секция II | R10: KZT
A11: 9 | B11: ВРУ | C11: WH | D11: LQ | E11: ДАЛА СА4У-Э720 R TX IP П RS1 Д W (3x220/380V 5-7,5A) | F11: 99000 | G11: ='01_BOM_DUZELTILDI'!$F11 -> 99000 | H11: ='01_BOM_DUZELTILDI'!$G11*'01_BOM_DUZELTILDI'!$I11 -> 198000 | I11: 2 | J11: шт | K11: SAIMAN | L11: 5A | O11: PDF + Claude BOM | P11: ПЛК учёт, 2 ввода | R11: KZT
A12: 20 | B12: ВРУ | C12: WH | D12: LP | E12: ДАЛА СА4-Э720 R TX IP P П RS1 Д W (3x220/380V 5-60A) | F12: 105000 | G12: ='01_BOM_DUZELTILDI'!$F12 -> 105000 | H12: ='01_BOM_DUZELTILDI'!$G12*'01_BOM_DUZELTILDI'!$I12 -> 315000 | I12: 3 | J12: шт | K12: SAIMAN | O12: PDF + Claude BOM | R12: KZT
A13: 6 | B13: ВРУ | C13: SPD | D13: 252578 | E13: Ограничитель имп. перенапр. NU6-IIG 4Р In=25kA Uc=440B Im=65kA (R) | F13: 33208 | G13: =0.6*F13 -> 19924.8 | H13: ='01_BOM_DUZELTILDI'!$G13*'01_BOM_DUZELTILDI'!$I13 -> 39849.6 | I13: 2 | J13: шт | K13: CHINT | O13: CHINT muadil; fiyat kontrol | P13: Отходящие линии; аналог вместо ВА47-100-3Р25А; Fiyat IEK kaynaklı olabilir; CHINT fiyat listesi ile kontrol et | Q13: 30 | R13: KZT
A14: 10 | B14: ВРУ | C14: bara | D14: 130200152_ | E14: Шина алюм АД31Т 3х30х4000 | F14: 675 | G14: ='01_BOM_DUZELTILDI'!$F14 -> 675 | H14: ='01_BOM_DUZELTILDI'!$G14*'01_BOM_DUZELTILDI'!$I14 -> 4050 | I14: 6 | J14: м | K14: pys | L14: 100A | O14: PDF + Claude BOM | P14: Секции I+II+общая PE | R14: KZT
A15: 12 | B15: ВРУ | C15: kablo kanalı | D15: KK-60x40 | E15: Кабельный канал 60×40мм | F15: 2530 | G15: ='01_BOM_DUZELTILDI'!$F15 -> 2530 | H15: ='01_BOM_DUZELTILDI'!$G15*'01_BOM_DUZELTILDI'!$I15 -> 15180 | I15: 6 | J15: м | K15: EKT | O15: PDF + Claude BOM | R15: KZT
A16: 13 | B16: ВРУ | C16: montaj malzeme | E16: Монтажный материал | F16: =OFFSET('01_BOM_DUZELTILDI'!$F16,1,2) -> 96000 | G16: ='01_BOM_DUZELTILDI'!$F16 -> 96000 | H16: ='01_BOM_DUZELTILDI'!$G16*'01_BOM_DUZELTILDI'!$I16 -> 96000 | I16: 1 | J16: шт | K16: pys | O16: PDF + Claude BOM | P16: Birim düzeltildi: iç malzemede "компл." kullanılmadı | R16: KZT
A17: 14 | B17: ВРУ | C17: montaj işçilik | E17: Монтажные работы ВРУ | F17: 16 | G17: 100 | H17: ='01_BOM_DUZELTILDI'!$G17*'01_BOM_DUZELTILDI'!$I17 -> 96000 | I17: =60*'01_BOM_DUZELTILDI'!$F17 -> 960 | J17: сағат | K17: Manual | O17: PDF + Claude BOM | P17: Birim düzeltildi: iç malzemede "компл." kullanılmadı | R17: KZT
A18: 15 | B18: ЩГП | C18: PANO | E18: ЩГП | G18: ='01_BOM_DUZELTILDI'!$F18 -> 0 | I18: 1 | J18: компл. | K18: TEKLED/TEKSAN | L18: ЩГП / ЩМП-6.6.1-0 600×600×150 — IP30 / IP30 | M18: 600×600×150 | N18: 600×600×150 | O18: PDF/Claude BOM | P18: Toplanmış pano satırı; iç malzemeler 1 pano içindir
A19: 16 | B19: ЩГП | C19: korpus | D19: 719-15075 | E19: Met.Korpus Pustoi 1800x800x450 10sm | F19: 165000 | G19: =0.6*F19 -> 99000 | H19: ='01_BOM_DUZELTILDI'!$G19*'01_BOM_DUZELTILDI'!$I19 -> 99000 | I19: 1 | J19: шт | K19: TEKSAN f | L19: 600×600×150; IP30 | M19: 600×600×150 | N19: 600×600×150 | O19: PDF + Claude BOM | R19: KZT
A20: 17 | B20: ЩГП | C20: ATS | D20: 256780 | E20: Устройство автоматического ввода резерва NXZM-125S/3B 125A (R) | F20: 204604 | G20: =0.6*F20 -> 122762.4 | H20: ='01_BOM_DUZELTILDI'!$G20*'01_BOM_DUZELTILDI'!$I20 -> 122762.4 | I20: 1 | J20: шт | K20: CHINT | L20: 3P, C125A 10kA, MCCB YAZDIM | O20: CHINT muadil; fiyat kontrol | P20: Главный ввод ЩГП; аналог вместо ВА47-100-3Р125А; Fiyat IEK kaynaklı olabilir; CHINT fiyat listesi ile kontrol et | Q20: 3 | R20: KZT
A21: 17 | B21: ЩГП | C21: mccb | D21: 131363 | E21: Авт. выкл. NXM-125S/3Р 125A 25кА (R) | F21: 19760 | G21: =0.6*F21 -> 11856 | H21: ='01_BOM_DUZELTILDI'!$G21*'01_BOM_DUZELTILDI'!$I21 -> 11856 | I21: 1 | J21: шт | K21: CHINT | L21: 3P, C125A 10kA, MCCB YAZDIM | O21: CHINT muadil; fiyat kontrol | P21: Главный ввод ЩГП; аналог вместо ВА47-100-3Р125А; Fiyat IEK kaynaklı olabilir; CHINT fiyat listesi ile kontrol et | Q21: 3 | R21: KZT
A22: 19 | B22: ЩГП | C22: MTR | D22: 270300100_ | E22: Трансформатор тока ТТИ-А 150/5А 5ВА класс 0,5 IEK | F22: 6350 | G22: ='01_BOM_DUZELTILDI'!$F22 -> 6350 | H22: ='01_BOM_DUZELTILDI'!$G22*'01_BOM_DUZELTILDI'!$I22 -> 19050 | I22: 3 | J22: шт | K22: pys | L22: 5A | O22: PDF + Claude BOM | R22: KZT
A23: 9 | B23: ЩГП | C23: WH | D23: LQ | E23: ДАЛА СА4У-Э720 R TX IP П RS1 Д W (3x220/380V 5-7,5A) | F23: 99000 | G23: ='01_BOM_DUZELTILDI'!$F23 -> 99000 | H23: ='01_BOM_DUZELTILDI'!$G23*'01_BOM_DUZELTILDI'!$I23 -> 99000 | I23: 1 | J23: шт | K23: SAIMAN | L23: 5A | O23: PDF + Claude BOM | P23: ПЛК учёт, 2 ввода | R23: KZT
A24: 20 | B24: ЩГП | C24: WH | D24: LP | E24: ДАЛА СА4-Э720 R TX IP P П RS1 Д W (3x220/380V 5-60A) | F24: 105000 | G24: ='01_BOM_DUZELTILDI'!$F24 -> 105000 | H24: ='01_BOM_DUZELTILDI'!$G24*'01_BOM_DUZELTILDI'!$I24 -> 210000 | I24: 2 | J24: шт | K24: SAIMAN | O24: PDF + Claude BOM | R24: KZT
A25: 21 | B25: ЩГП | C25: MCB | D25: 296830 | E25: Авт. выкл. NXB-63S 3P 32А 4.5kA х-ка C (R) | F25: 2606 | G25: =0.6*F25 -> 1563.6 | H25: ='01_BOM_DUZELTILDI'!$G25*'01_BOM_DUZELTILDI'!$I25 -> 6254.4 | I25: 4 | J25: шт | K25: CHINT | L25: 3P, C32A 1 tanesi 3*40 oldu | O25: CHINT muadil; fiyat kontrol | P25: Отходящие гл.линии; аналог вместо ВА47-29-3Р32А; Fiyat IEK kaynaklı olabilir; CHINT fiyat listesi ile kontrol et | Q25: 15 | R25: KZT
A26: 22 | B26: ЩГП | C26: MCB | D26: 296829 | E26: Авт. выкл. NXB-63S 3P 25А 4.5kA х-ка C (R) | F26: 2429 | G26: =0.6*F26 -> 1457.4 | H26: ='01_BOM_DUZELTILDI'!$G26*'01_BOM_DUZELTILDI'!$I26 -> 1457.4 | I26: 1 | J26: шт | K26: CHINT | L26: 3P, C25A | O26: CHINT muadil; fiyat kontrol | P26: аналог вместо ВА47-29-3Р25А; Fiyat IEK kaynaklı olabilir; CHINT fiyat listesi ile kontrol et | Q26: 3 | R26: KZT
A27: 25 | B27: ЩГП | C27: MCB | D27: 296831 | E27: Авт. выкл. NXB-63S 3P 40А 4.5kA х-ка C (R) | F27: 2807 | G27: =0.6*F27 -> 1684.2 | H27: ='01_BOM_DUZELTILDI'!$G27*'01_BOM_DUZELTILDI'!$I27 -> 1684.2 | I27: 1 | J27: шт | K27: CHINT | L27: 3P, C40A 1. etaptan eklenen | O27: CHINT muadil; fiyat kontrol | P27: аналог вместо ВА47-29-1Р10А; Fiyat IEK kaynaklı olabilir; CHINT fiyat listesi ile kontrol et | Q27: 1 | R27: KZT
A28: 25 | B28: ЩГП | C28: MCB | D28: 296788 | E28: Авт. выкл. NXB-63S 2P 16А 4.5kA х-ка C (R) | F28: 1589 | G28: =0.6*F28 -> 953.4 | H28: ='01_BOM_DUZELTILDI'!$G28*'01_BOM_DUZELTILDI'!$I28 -> 953.4 | I28: 1 | J28: шт | K28: CHINT | L28: 2P, C16A 1. . etaptan eklenen | O28: CHINT muadil; fiyat kontrol | P28: аналог вместо ВА47-29-1Р10А; Fiyat IEK kaynaklı olabilir; CHINT fiyat listesi ile kontrol et | Q28: 1 | R28: KZT
A29: 23 | B29: ЩГП | C29: MCB | D29: 296827 | E29: Авт. выкл. NXB-63S 3P 16А 4.5kA х-ка C (R) | F29: 2337 | G29: =0.6*F29 -> 1402.2 | H29: ='01_BOM_DUZELTILDI'!$G29*'01_BOM_DUZELTILDI'!$I29 -> 4206.6 | I29: 3 | J29: шт | K29: CHINT | L29: 3P, C16A | O29: CHINT muadil; fiyat kontrol | P29: аналог вместо ВА47-29-3Р16А; Fiyat IEK kaynaklı olabilir; CHINT fiyat listesi ile kontrol et | Q29: 9 | R29: KZT
A30: 24 | B30: ЩГП | C30: MCB | D30: 296710 | E30: Авт. выкл. NXB-63S 1P 16А 4.5kA х-ка C (R) | F30: 783 | G30: =0.6*F30 -> 469.8 | H30: ='01_BOM_DUZELTILDI'!$G30*'01_BOM_DUZELTILDI'!$I30 -> 939.6 | I30: 2 | J30: шт | K30: CHINT | L30: 1P, C16A | O30: CHINT muadil; fiyat kontrol | P30: аналог вместо ВА47-29-1Р16А; Fiyat IEK kaynaklı olabilir; CHINT fiyat listesi ile kontrol et | Q30: 2 | R30: KZT
A31: 25 | B31: ЩГП | C31: MCB | D31: 296696 | E31: Авт. выкл. NXB-63S 1P 10А 4.5kA х-ка B (R) | F31: 897 | G31: =0.6*F31 -> 538.2 | H31: ='01_BOM_DUZELTILDI'!$G31*'01_BOM_DUZELTILDI'!$I31 -> 538.2 | I31: 1 | J31: шт | K31: CHINT | L31: 1P, C10A | O31: CHINT muadil; fiyat kontrol | P31: аналог вместо ВА47-29-1Р10А; Fiyat IEK kaynaklı olabilir; CHINT fiyat listesi ile kontrol et | Q31: 1 | R31: KZT
A32: 28 | B32: ЩГП | C32: kablo kanalı | D32: KK-40x40 | E32: Кабельный канал 40×40 | F32: 2200 | G32: ='01_BOM_DUZELTILDI'!$F32 -> 2200 | H32: ='01_BOM_DUZELTILDI'!$G32*'01_BOM_DUZELTILDI'!$I32 -> 6600 | I32: 3 | J32: м | K32: EKT | O32: PDF + Claude BOM | R32: KZT
A33: 29 | B33: ЩГП | C33: montaj malzeme | E33: Монтажный материал | F33: =OFFSET('01_BOM_DUZELTILDI'!$F33,1,2) -> 78000 | G33: ='01_BOM_DUZELTILDI'!$F33 -> 78000 | H33: ='01_BOM_DUZELTILDI'!$G33*'01_BOM_DUZELTILDI'!$I33 -> 78000 | I33: 1 | J33: шт | K33: pys | O33: PDF + Claude BOM | P33: Birim düzeltildi: iç malzemede "компл." kullanılmadı | R33: KZT
A34: 30 | B34: ЩГП | C34: montaj işçilik | E34: Монтажные работы | F34: 13 | G34: 100 | H34: ='01_BOM_DUZELTILDI'!$G34*'01_BOM_DUZELTILDI'!$I34 -> 78000 | I34: =60*'01_BOM_DUZELTILDI'!$F34 -> 780 | J34: сағат | K34: Manual | O34: PDF + Claude BOM | R34: KZT
A35: 31 | B35: ЩРоб | C35: PANO | E35: ЩРоб | G35: ='01_BOM_DUZELTILDI'!$F35 -> 0 | I35: 1 | J35: компл. | K35: TEKLED/TEKSAN | L35: ЩРоб / навесной — IP54 / IP54 | M35: 400×300×150 | N35: 400×300×150 | O35: PDF/Claude BOM | P35: Toplanmış pano satırı; iç malzemeler 1 pano içindir
A36: 32 | B36: ЩРоб | C36: korpus | D36: 714-15128 | E36: Щит мет. ЩРн-1-1 PR (395x310x150) IP31 (TS) | F36: 13500 | G36: =0.6*F36 -> 8100 | H36: ='01_BOM_DUZELTILDI'!$G36*'01_BOM_DUZELTILDI'!$I36 -> 8100 | I36: 1 | J36: шт | K36: TEKSAN f | L36: 400×300×150; IP54 | M36: 400×300×150 | N36: 400×300×150 | O36: PDF + Claude BOM | R36: KZT
A37: 33 | B37: ЩРоб | C37: MCB | D37: 296831 | E37: Авт. выкл. NXB-63S 3P 40А 4.5kA х-ка C (R) | F37: 2807 | G37: =0.6*F37 -> 1684.2 | H37: ='01_BOM_DUZELTILDI'!$G37*'01_BOM_DUZELTILDI'!$I37 -> 1684.2 | I37: 1 | J37: шт | K37: CHINT | L37: 3P, 40A | O37: CHINT muadil; fiyat kontrol | P37: Главный ввод; аналог вместо ВН-32-3Р40А; Fiyat IEK kaynaklı olabilir; CHINT fiyat listesi ile kontrol et | R37: KZT
A38: 36 | B38: ЩРоб | C38: RCBO | D38: 515381 | E38: Диф. авт. выкл. NXBLE-63YH 1P+N C16 30mA тип A, 6kA (R) | F38: 5104 | G38: =0.6*F38 -> 3062.4 | H38: ='01_BOM_DUZELTILDI'!$G38*'01_BOM_DUZELTILDI'!$I38 -> 18374.4 | I38: 6 | J38: шт | K38: CHINT | L38: 1P+N, C16A, 30mA, 30мА projede 5 adet | O38: CHINT muadil; fiyat kontrol | P38: Линии к обогреву ×5; аналог вместо АВДТ32; Fiyat IEK kaynaklı olabilir; CHINT fiyat listesi ile kontrol et | Q38: 10 | R38: KZT
A39: 37 | B39: ЩРоб | C39: contactor | D39: 256054 | E39: Контактор модульный NCH8-20/20 20A 2НО AC220/230В 50Гц (R) | F39: 6145 | G39: =0.6*F39 -> 3687 | H39: ='01_BOM_DUZELTILDI'!$G39*'01_BOM_DUZELTILDI'!$I39 -> 14748 | I39: 4 | J39: шт | K39: CHINT | L39: 20A projede 3 adet | O39: CHINT muadil; fiyat kontrol | P39: Управление нагревом; аналог вместо КМ20-11М-20A; Fiyat IEK kaynaklı olabilir; CHINT fiyat listesi ile kontrol et | Q39: 3 | R39: KZT
A40: 38 | B40: ЩРоб | C40: other | D40: 03-Б2-T1 | E40: Терморегулятор ECOTHERM-03-Б2-T1 | F40: 37000 | G40: ='01_BOM_DUZELTILDI'!$F40 -> 37000 | H40: ='01_BOM_DUZELTILDI'!$G40*'01_BOM_DUZELTILDI'!$I40 -> 37000 | I40: 1 | J40: шт | K40: DEVI | O40: PDF + Claude BOM | P40: Датчик температуры DEVisnow | R40: KZT
...

Sheet Sayfa1
A1: № | B1: Щит | C1: Категория | D1: Код товара | E1: Наименование / Описание | F1: Цена за единицу | G1: Чистая цена за единицу | H1: Итого чистая цена (1 щит) | I1: Количество | J1: Ед. изм. | K1: Марка / Поставщик | L1: malzeme
A2: 1 | B2: ВРУ | C2: PANO | E2: ВРУ | J2: компл. | K2: TEKLED electric
A3: 2 | B3: ВРУ | C3: korpus | D3: 719-15075 | E3: Met.Korpus Pustoi 1800x800x450 10sm | F3: 165000 | G3: =0.6*F3 -> 99000 | H3: ='01_BOM_DUZELTILDI'!$G3*'01_BOM_DUZELTILDI'!$I3 -> 198000 | I3: 2 | J3: шт | K3: TEKSAN f | L3: 198000
A4: 3 | B4: ВРУ | C4: rubilnik | D4: 270100161_ | E4: Рубильник ВР-32-37 В71250-400А на 2 направления (+6камер) UNIT (1/6) | F4: 24000 | G4: ='01_BOM_DUZELTILDI'!$F4 -> 24000 | H4: ='01_BOM_DUZELTILDI'!$G4*'01_BOM_DUZELTILDI'!$I4 -> 48000 | I4: 2 | J4: шт | K4: PYS | L4: 48000
A5: 4 | B5: ВРУ | C5: MCCB | D5: 131369 | E5: Авт. выкл. NXM-250S/3Р 250A 36кА (R) | F5: 36869 | G5: =0.6*F5 -> 22121.4 | H5: ='01_BOM_DUZELTILDI'!$G5*'01_BOM_DUZELTILDI'!$I5 -> 44242.8 | I5: 2 | J5: шт | K5: CHINT | L5: 44242.8
A6: 5 | B6: ВРУ | C6: MCCB | D6: 131364 | E6: Авт. выкл. NXM-160S/3Р 160A 36кА (R) | F6: 27169 | G6: =0.6*F6 -> 16301.4 | H6: ='01_BOM_DUZELTILDI'!$G6*'01_BOM_DUZELTILDI'!$I6 -> 48904.2 | I6: 3 | J6: шт | K6: CHINT | L6: 48904.2
A7: 6 | B7: ВРУ | C7: MCB | D7: 296708 | E7: Авт. выкл. NXB-63S 1P 6А 4.5kA х-ка C (R) | F7: 975 | G7: =0.6*F7 -> 585 | H7: ='01_BOM_DUZELTILDI'!$G7*'01_BOM_DUZELTILDI'!$I7 -> 1170 | I7: 2 | J7: шт | K7: CHINT | L7: 1170
A8: 6 | B8: ВРУ | C8: MCB | D8: 296829 | E8: Авт. выкл. NXB-63S 3P 25А 4.5kA х-ка C (R) | F8: 2429 | G8: =0.6*F8 -> 1457.4 | H8: ='01_BOM_DUZELTILDI'!$G8*'01_BOM_DUZELTILDI'!$I8 -> 8744.4 | I8: 6 | J8: шт | K8: CHINT | L8: 8744.4
A9: 7 | B9: ВРУ | C9: RCBO | D9: 515381 | E9: Диф. авт. выкл. NXBLE-63YH 1P+N C16 30mA тип A, 6kA (R) | F9: 5104 | G9: =0.6*F9 -> 3062.4 | H9: ='01_BOM_DUZELTILDI'!$G9*'01_BOM_DUZELTILDI'!$I9 -> 3062.4 | I9: 1 | J9: шт | K9: CHINT | L9: 3062.4
A10: 8 | B10: ВРУ | C10: MTR | D10: 270300182_ | E10: Трансформатор Т-0,66 250\5 (9) | F10: 6350 | G10: ='01_BOM_DUZELTILDI'!$F10 -> 6350 | H10: ='01_BOM_DUZELTILDI'!$G10*'01_BOM_DUZELTILDI'!$I10 -> 38100 | I10: 6 | J10: шт | K10: pys | L10: 38100
A11: 9 | B11: ВРУ | C11: WH | D11: LQ | E11: ДАЛА СА4У-Э720 R TX IP П RS1 Д W (3x220/380V 5-7,5A) | F11: 99000 | G11: ='01_BOM_DUZELTILDI'!$F11 -> 99000 | H11: ='01_BOM_DUZELTILDI'!$G11*'01_BOM_DUZELTILDI'!$I11 -> 198000 | I11: 2 | J11: шт | K11: SAIMAN | L11: 198000
A12: 20 | B12: ВРУ | C12: WH | D12: LP | E12: ДАЛА СА4-Э720 R TX IP P П RS1 Д W (3x220/380V 5-60A) | F12: 105000 | G12: ='01_BOM_DUZELTILDI'!$F12 -> 105000 | H12: ='01_BOM_DUZELTILDI'!$G12*'01_BOM_DUZELTILDI'!$I12 -> 315000 | I12: 3 | J12: шт | K12: SAIMAN | L12: 315000
A13: 6 | B13: ВРУ | C13: SPD | D13: 252578 | E13: Ограничитель имп. перенапр. NU6-IIG 4Р In=25kA Uc=440B Im=65kA (R) | F13: 33208 | G13: =0.6*F13 -> 19924.8 | H13: ='01_BOM_DUZELTILDI'!$G13*'01_BOM_DUZELTILDI'!$I13 -> 39849.6 | I13: 2 | J13: шт | K13: CHINT | L13: 39849.6
A14: 10 | B14: ВРУ | C14: bara | D14: 130200152_ | E14: Шина алюм АД31Т 3х30х4000 | F14: 675 | G14: ='01_BOM_DUZELTILDI'!$F14 -> 675 | H14: ='01_BOM_DUZELTILDI'!$G14*'01_BOM_DUZELTILDI'!$I14 -> 4050 | I14: 6 | J14: м | K14: pys | L14: 4050
A15: 12 | B15: ВРУ | C15: kablo kanalı | D15: KK-60x40 | E15: Кабельный канал 60×40мм | F15: 2530 | G15: ='01_BOM_DUZELTILDI'!$F15 -> 2530 | H15: ='01_BOM_DUZELTILDI'!$G15*'01_BOM_DUZELTILDI'!$I15 -> 15180 | I15: 6 | J15: м | K15: EKT | L15: 15180
A16: 13 | B16: ВРУ | C16: montaj malzeme | E16: Монтажный материал | F16: =OFFSET('01_BOM_DUZELTILDI'!$F16,1,2) -> 96000 | G16: ='01_BOM_DUZELTILDI'!$F16 -> 96000 | H16: ='01_BOM_DUZELTILDI'!$G16*'01_BOM_DUZELTILDI'!$I16 -> 96000 | I16: 1 | J16: шт | K16: pys | L16: 96000
A17: 14 | B17: ВРУ | C17: montaj işçilik | E17: Монтажные работы | F17: 16 | G17: 100 | H17: ='01_BOM_DUZELTILDI'!$G17*'01_BOM_DUZELTILDI'!$I17 -> 96000 | I17: =60*'01_BOM_DUZELTILDI'!$F17 -> 960 | J17: сағат | K17: Manual | L17: 96000
B18: Toplam ВРУ | H18: =SUBTOTAL(9,H2:H17) -> 1154303.4 | L18: 1154303.4
A19: 15 | B19: ЩГП | C19: PANO | E19: ЩГП | J19: компл. | K19: TEKLED electric
A20: 16 | B20: ЩГП | C20: korpus | D20: 719-15075 | E20: Met.Korpus Pustoi 1800x800x450 10sm | F20: 165000 | G20: =0.6*F20 -> 99000 | H20: ='01_BOM_DUZELTILDI'!$G19*'01_BOM_DUZELTILDI'!$I19 -> 99000 | I20: 1 | J20: шт | K20: TEKSAN f | L20: 99000
A21: 17 | B21: ЩГП | C21: ATS | D21: 256780 | E21: Устройство автоматического ввода резерва NXZM-125S/3B 125A (R) | F21: 204604 | G21: =0.6*F21 -> 122762.4 | H21: ='01_BOM_DUZELTILDI'!$G20*'01_BOM_DUZELTILDI'!$I20 -> 122762.4 | I21: 1 | J21: шт | K21: CHINT | L21: 122762.4
A22: 17 | B22: ЩГП | C22: mccb | D22: 131363 | E22: Авт. выкл. NXM-125S/3Р 125A 25кА (R) | F22: 19760 | G22: =0.6*F22 -> 11856 | H22: ='01_BOM_DUZELTILDI'!$G21*'01_BOM_DUZELTILDI'!$I21 -> 11856 | I22: 1 | J22: шт | K22: CHINT | L22: 11856
A23: 19 | B23: ЩГП | C23: MTR | D23: 270300100_ | E23: Трансформатор тока ТТИ-А 150/5А 5ВА класс 0,5 IEK | F23: 6350 | G23: ='01_BOM_DUZELTILDI'!$F22 -> 6350 | H23: ='01_BOM_DUZELTILDI'!$G22*'01_BOM_DUZELTILDI'!$I22 -> 19050 | I23: 3 | J23: шт | K23: pys | L23: 19050
A24: 9 | B24: ЩГП | C24: WH | D24: LQ | E24: ДАЛА СА4У-Э720 R TX IP П RS1 Д W (3x220/380V 5-7,5A) | F24: 99000 | G24: ='01_BOM_DUZELTILDI'!$F23 -> 99000 | H24: ='01_BOM_DUZELTILDI'!$G23*'01_BOM_DUZELTILDI'!$I23 -> 99000 | I24: 1 | J24: шт | K24: SAIMAN | L24: 99000
A25: 20 | B25: ЩГП | C25: WH | D25: LP | E25: ДАЛА СА4-Э720 R TX IP P П RS1 Д W (3x220/380V 5-60A) | F25: 105000 | G25: ='01_BOM_DUZELTILDI'!$F24 -> 105000 | H25: ='01_BOM_DUZELTILDI'!$G24*'01_BOM_DUZELTILDI'!$I24 -> 210000 | I25: 2 | J25: шт | K25: SAIMAN | L25: 210000
A26: 21 | B26: ЩГП | C26: MCB | D26: 296830 | E26: Авт. выкл. NXB-63S 3P 32А 4.5kA х-ка C (R) | F26: 2606 | G26: =0.6*F26 -> 1563.6 | H26: ='01_BOM_DUZELTILDI'!$G25*'01_BOM_DUZELTILDI'!$I25 -> 6254.4 | I26: 4 | J26: шт | K26: CHINT | L26: 6254.4
A27: 22 | B27: ЩГП | C27: MCB | D27: 296829 | E27: Авт. выкл. NXB-63S 3P 25А 4.5kA х-ка C (R) | F27: 2429 | G27: =0.6*F27 -> 1457.4 | H27: ='01_BOM_DUZELTILDI'!$G26*'01_BOM_DUZELTILDI'!$I26 -> 1457.4 | I27: 1 | J27: шт | K27: CHINT | L27: 1457.4
A28: 25 | B28: ЩГП | C28: MCB | D28: 296831 | E28: Авт. выкл. NXB-63S 3P 40А 4.5kA х-ка C (R) | F28: 2807 | G28: =0.6*F28 -> 1684.2 | H28: ='01_BOM_DUZELTILDI'!$G27*'01_BOM_DUZELTILDI'!$I27 -> 1684.2 | I28: 1 | J28: шт | K28: CHINT | L28: 1684.2
A29: 25 | B29: ЩГП | C29: MCB | D29: 296788 | E29: Авт. выкл. NXB-63S 2P 16А 4.5kA х-ка C (R) | F29: 1589 | G29: =0.6*F29 -> 953.4 | H29: ='01_BOM_DUZELTILDI'!$G28*'01_BOM_DUZELTILDI'!$I28 -> 953.4 | I29: 1 | J29: шт | K29: CHINT | L29: 953.4
A30: 23 | B30: ЩГП | C30: MCB | D30: 296827 | E30: Авт. выкл. NXB-63S 3P 16А 4.5kA х-ка C (R) | F30: 2337 | G30: =0.6*F30 -> 1402.2 | H30: ='01_BOM_DUZELTILDI'!$G29*'01_BOM_DUZELTILDI'!$I29 -> 4206.6 | I30: 3 | J30: шт | K30: CHINT | L30: 4206.6
A31: 24 | B31: ЩГП | C31: MCB | D31: 296710 | E31: Авт. выкл. NXB-63S 1P 16А 4.5kA х-ка C (R) | F31: 783 | G31: =0.6*F31 -> 469.8 | H31: ='01_BOM_DUZELTILDI'!$G30*'01_BOM_DUZELTILDI'!$I30 -> 939.6 | I31: 2 | J31: шт | K31: CHINT | L31: 939.6
A32: 25 | B32: ЩГП | C32: MCB | D32: 296696 | E32: Авт. выкл. NXB-63S 1P 10А 4.5kA х-ка B (R) | F32: 897 | G32: =0.6*F32 -> 538.2 | H32: ='01_BOM_DUZELTILDI'!$G31*'01_BOM_DUZELTILDI'!$I31 -> 538.2 | I32: 1 | J32: шт | K32: CHINT | L32: 538.2
A33: 28 | B33: ЩГП | C33: kablo kanalı | D33: KK-40x40 | E33: Кабельный канал 40×40 | F33: 2200 | G33: ='01_BOM_DUZELTILDI'!$F32 -> 2200 | H33: ='01_BOM_DUZELTILDI'!$G32*'01_BOM_DUZELTILDI'!$I32 -> 6600 | I33: 3 | J33: м | K33: EKT | L33: 6600
A34: 29 | B34: ЩГП | C34: montaj malzeme | E34: Монтажный материал | F34: =OFFSET('01_BOM_DUZELTILDI'!$F33,1,2) -> 78000 | G34: ='01_BOM_DUZELTILDI'!$F33 -> 78000 | H34: ='01_BOM_DUZELTILDI'!$G33*'01_BOM_DUZELTILDI'!$I33 -> 78000 | I34: 1 | J34: шт | K34: pys | L34: 78000
A35: 30 | B35: ЩГП | C35: montaj işçilik | E35: Монтажные работы | F35: 13 | G35: 100 | H35: ='01_BOM_DUZELTILDI'!$G34*'01_BOM_DUZELTILDI'!$I34 -> 78000 | I35: =60*'01_BOM_DUZELTILDI'!$F34 -> 780 | J35: сағат | K35: Manual | L35: 78000
B36: Toplam ЩГП | H36: =SUBTOTAL(9,H19:H35) -> 740302.2 | L36: 740302.2
A37: 31 | B37: ЩРоб | C37: PANO | E37: ЩРоб | J37: компл. | K37: TEKLED electric
A38: 32 | B38: ЩРоб | C38: korpus | D38: 714-15128 | E38: Щит мет. ЩРн-1-1 PR (395x310x150) IP31 (TS) | F38: 13500 | G38: =0.6*F38 -> 8100 | H38: ='01_BOM_DUZELTILDI'!$G36*'01_BOM_DUZELTILDI'!$I36 -> 8100 | I38: 1 | J38: шт | K38: TEKSAN f | L38: 8100
A39: 33 | B39: ЩРоб | C39: MCB | D39: 296831 | E39: Авт. выкл. NXB-63S 3P 40А 4.5kA х-ка C (R) | F39: 2807 | G39: =0.6*F39 -> 1684.2 | H39: ='01_BOM_DUZELTILDI'!$G37*'01_BOM_DUZELTILDI'!$I37 -> 1684.2 | I39: 1 | J39: шт | K39: CHINT | L39: 1684.2
A40: 36 | B40: ЩРоб | C40: RCBO | D40: 515381 | E40: Диф. авт. выкл. NXBLE-63YH 1P+N C16 30mA тип A, 6kA (R) | F40: 5104 | G40: =0.6*F40 -> 3062.4 | H40: ='01_BOM_DUZELTILDI'!$G38*'01_BOM_DUZELTILDI'!$I38 -> 18374.4 | I40: 6 | J40: шт | K40: CHINT | L40: 18374.4
...

Sheet Sayfa2
A1: Код товара | B1: Наименование / Описание | C1: Цена за единицу | D1: 0.65 | F1: Чистая цена за единицу | G1: сумм. | H1: Количество | I1: Ед. изм. | J1: Марка / Поставщик | K1: malzeme | L1: 2.145
B2: ВРУ | C2: =ROUNDUP(L2,-3) -> 2476000 | D2: =C2*0.65 -> 1609400 | E2: =D2*H2 -> 1609400 | F2: =0.7*C2 -> 1733200 | G2: =F2*H2 -> 1733200 | H2: 1 | I2: компл. | J2: TEKLED electric | K2: 1154303.4 | L2: =2.145*K2 -> 2475980.8 | M2: =K2*H2 -> 1154303.4
B3: ЩГП | C3: =ROUNDUP(L3,-3) -> 1588000 | D3: =C3*0.65 -> 1032200 | E3: =D3*H3 -> 1032200 | F3: =0.7*C3 -> 1111600 | G3: =F3*H3 -> 1111600 | H3: 1 | I3: компл. | J3: TEKLED electric | K3: 740302.2 | L3: =2.145*K3 -> 1587948.2 | M3: =K3*H3 -> 740302.2
B4: ЩРоб | C4: =ROUNDUP(L4,-3) -> 236000 | D4: =C4*0.65 -> 153400 | E4: =D4*H4 -> 153400 | F4: =0.7*C4 -> 165200 | G4: =F4*H4 -> 165200 | H4: 1 | I4: компл. | J4: TEKLED electric | K4: 109906.6 | L4: =2.145*K4 -> 235749.66 | M4: =K4*H4 -> 109906.6
B5: ЩРк-1, ЩРк-2 | C5: =ROUNDUP(L5,-3) -> 309000 | D5: =C5*0.65 -> 200850 | E5: =D5*H5 -> 401700 | F5: =0.7*C5 -> 216300 | G5: =F5*H5 -> 432600 | H5: 2 | I5: компл. | J5: TEKLED electric | K5: 143676.6 | L5: =2.145*K5 -> 308186.31 | M5: =K5*H5 -> 287353.2
B6: ЩО | C6: =ROUNDUP(L6,-3) -> 64000 | D6: =C6*0.65 -> 41600 | E6: =D6*H6 -> 41600 | F6: =0.7*C6 -> 44800 | G6: =F6*H6 -> 44800 | H6: 1 | I6: компл. | J6: TEKLED electric | K6: 29807.8 | L6: =2.145*K6 -> 63937.731 | M6: =K6*H6 -> 29807.8
B7: ЩАО | C7: =ROUNDUP(L7,-3) -> 101000 | D7: =C7*0.65 -> 65650 | E7: =D7*H7 -> 65650 | F7: =0.7*C7 -> 70700 | G7: =F7*H7 -> 70700 | H7: 1 | I7: компл. | J7: TEKLED electric | K7: 47071.2 | L7: =2.145*K7 -> 100967.72 | M7: =K7*H7 -> 47071.2
B8: ЩЗ1 | C8: =ROUNDUP(L8,-3) -> 873000 | D8: =C8*0.65 -> 567450 | E8: =D8*H8 -> 567450 | F8: =0.7*C8 -> 611100 | G8: =F8*H8 -> 611100 | H8: 1 | I8: компл. | J8: TEKLED electric | K8: 406657.8 | L8: =2.145*K8 -> 872280.98 | M8: =K8*H8 -> 406657.8
B9: ЩЗ2-12 | C9: =ROUNDUP(L9,-3) -> 1072000 | D9: =C9*0.65 -> 696800 | E9: =D9*H9 -> 7664800 | F9: =0.7*C9 -> 750400 | G9: =F9*H9 -> 8254400 | H9: 11 | I9: компл. | J9: TEKLED electric | K9: 499351.8 | L9: =2.145*K9 -> 1071109.6 | M9: =K9*H9 -> 5492869.8
B10: ЩК Тип A | C10: =ROUNDUP(L10,-3) -> 70000 | D10: =C10*0.65 -> 45500 | E10: =D10*H10 -> 1638000 | F10: =0.7*C10 -> 49000 | G10: =F10*H10 -> 1764000 | H10: 36 | I10: компл. | J10: TEKLED electric | K10: 32526 | L10: =2.145*K10 -> 69768.27 | M10: =K10*H10 -> 1170936
B11: ЩК Тип B | C11: =ROUNDUP(L11,-3) -> 70000 | D11: =C11*0.65 -> 45500 | E11: =D11*H11 -> 2138500 | F11: =0.7*C11 -> 49000 | G11: =F11*H11 -> 2303000 | H11: 47 | I11: компл. | J11: TEKLED electric | K11: 32526 | L11: =2.145*K11 -> 69768.27 | M11: =K11*H11 -> 1528722
B12: ЩК Тип C | C12: =ROUNDUP(L12,-3) -> 77000 | D12: =C12*0.65 -> 50050 | E12: =D12*H12 -> 550550 | F12: =0.7*C12 -> 53900 | G12: =F12*H12 -> 592900 | H12: 11 | I12: компл. | J12: TEKLED electric | K12: 35588.4 | L12: =2.145*K12 -> 76337.118 | M12: =K12*H12 -> 391472.4
B13: ШУЗ | C13: =ROUNDUP(L13,-3) -> 139000 | D13: =C13*0.65 -> 90350 | E13: =D13*H13 -> 90350 | F13: =0.7*C13 -> 97300 | G13: =F13*H13 -> 97300 | H13: 1 | I13: компл. | J13: TEKLED electric | K13: 64551.6 | L13: =2.145*K13 -> 138463.18 | M13: =K13*H13 -> 64551.6
... B17: ЩПСС | C17: =ROUNDUP(L17,-3) -> 42000 | D17: =C17*0.65 -> 27300 | E17: =D17*H17 -> 27300 | F17: =0.7*C17 -> 29400 | G17: =F17*H17 -> 29400 | H17: 1 | I17: компл. | J17: TEKLED electric | K17: 19359 | L17: =2.145*K17 -> 41525.055 | M17: =K17*H17 -> 19359

Sheet 02_Satin_Alma
A1: № | B1: Kategori | C1: Ürün Kodu | D1: Ürün İsmi / Açıklama | E1: Toplam Alım Miktarı | F1: Birim | G1: Marka/Tedarikçi | H1: Birim Net Fiyat | I1: Para | J1: Toplam Net | K1: Panolar | L1: Not
A2: 1 | B2: korpus | C2: ВРУ-01 | D2: Корпус ВРУ индивидуального изготовления | E2: 1 | F2: шт | G2: TEKSAN | H2: 350000 | I2: KZT | J2: =IF(OR(E2="",H2=""),"",E2*H2) -> 350000 | K2: ВРУ | L2: Birim düzeltildi: iç malzemede "компл." kullanılmadı
A3: 2 | B3: MCCB | C3: NH40-400/3 | D3: Выключатель-разъединитель CHINT NH40 3P 400A | E3: 2 | F3: шт | G3: CHINT | H3: 480000 | I3: KZT | J3: =IF(OR(E3="",H3=""),"",E3*H3) -> 960000 | K3: ВРУ | L3: Ввод 1 и Ввод 2; аналог вместо BP32И-37B71250; Fiyat IEK kaynaklı olabilir; CHINT fiyat listesi ile kontrol et
A4: 3 | B4: MCCB | C4: NXM-250S/3300 250A | D4: Автоматический выключатель литой корпус CHINT NXM 3P 250A | E4: 2 | F4: шт | G4: CHINT | H4: 320000 | I4: KZT | J4: =IF(OR(E4="",H4=""),"",E4*H4) -> 640000 | K4: ВРУ | L4: Секции I+II; аналог вместо ВА88-35; Fiyat IEK kaynaklı olabilir; CHINT fiyat listesi ile kontrol et
A5: 4 | B5: MCCB | C5: NXM-160S/3300 160A | D5: Автоматический выключатель литой корпус CHINT NXM 3P 160A | E5: 4 | F5: шт | G5: CHINT | H5: 220000 | I5: KZT | J5: =IF(OR(E5="",H5=""),"",E5*H5) -> 880000 | K5: ВРУ | L5: 4 шт распределение; аналог вместо ВА88-32; Fiyat IEK kaynaklı olabilir; CHINT fiyat listesi ile kontrol et
A6: 5 | B6: MCB | C6: NB1-63 3P C25 | D6: Автоматический выключатель CHINT NB1-63 3P C25A | E6: 11 | F6: шт | G6: CHINT | H6: 18000 | I6: KZT | J6: =IF(OR(E6="",H6=""),"",E6*H6) -> 198000 | K6: ВРУ, ЩГП | L6: Отходящие линии; аналог вместо ВА47-100-3Р25А; Fiyat IEK kaynaklı olabilir; CHINT fiyat listesi ile kontrol et; аналог вместо ВА47-29-3Р25А; Fiyat IEK kaynaklı olabilir; CHINT fiyat listesi ile kontrol et
A7: 6 | B7: RCBO | C7: NXBLE-32 1P+N C16 30mA | D7: Дифф. автомат CHINT NXBLE-32 1P+N C16A 30mA | E7: 7 | F7: шт | G7: CHINT | H7: 13500 | I7: KZT | J7: =IF(OR(E7="",H7=""),"",E7*H7) -> 94500 | K7: ВРУ, ЩР, ЩРоб | L7: Линии к обогреву ×5; аналог вместо АВДТ32; Fiyat IEK kaynaklı olabilir; CHINT fiyat listesi ile kontrol et; аналог вместо АВДТ32; Fiyat IEK kaynaklı olabilir; CHINT fiyat listesi ile kontrol et
A8: 7 | B8: MTR | C8: ТОП-0.66-250/5 | D8: Трансформатор тока ТОП-0.66 У3 250/5A кл.0.5S | E8: 6 | F8: шт | G8: SAIMAN | H8: 22000 | I8: KZT | J8: =IF(OR(E8="",H8=""),"",E8*H8) -> 132000 | K8: ВРУ | L8: 3 шт секция I + 3 шт секция II
A9: 8 | B9: MTR | C9: ДАЛА-CA4Y-3720 | D9: Счётчик ДАЛА CA4Y-3720 R TX PLC IP П 3×220/380В 5|7.5A | E9: 2 | F9: шт | G9: SAIMAN | H9: 39100 | I9: KZT | J9: =IF(OR(E9="",H9=""),"",E9*H9) -> 78200 | K9: ВРУ | L9: ПЛК учёт, 2 ввода
A10: 9 | B10: bara | C10: BB-N-PE | D10: Шина медная N+PE 3L×100A | E10: 3 | F10: м | G10: EKT | H10: 4197 | I10: KZT | J10: =IF(OR(E10="",H10=""),"",E10*H10) -> 12591 | K10: ВРУ | L10: Секции I+II+общая PE
A11: 10 | B11: DIN | C11: DIN-35-2000 | D11: DIN рейка TH35 2м | E11: 4 | F11: шт | G11: EKT | H11: 1200 | I11: KZT | J11: =IF(OR(E11="",H11=""),"",E11*H11) -> 4800 | K11: ВРУ
A12: 11 | B12: kablo kanalı | C12: KK-60x40 | D12: Кабельный канал 60×40мм | E12: 6 | F12: м | G12: EKT | H12: 1800 | I12: KZT | J12: =IF(OR(E12="",H12=""),"",E12*H12) -> 10800 | K12: ВРУ
A13: 12 | B13: montaj malzeme | D13: Монтажный материал (крепёж, DIN, маркировка) | E13: 1 | F13: шт | G13: EKT | H13: 45000 | I13: KZT | J13: =IF(OR(E13="",H13=""),"",E13*H13) -> 45000 | K13: ВРУ | L13: Birim düzeltildi: iç malzemede "компл." kullanılmadı
A14: 13 | B14: montaj işçilik | D14: Монтажные работы ВРУ | E14: 1 | F14: шт | G14: Manual | H14: 280000 | I14: KZT | J14: =IF(OR(E14="",H14=""),"",E14*H14) -> 280000 | K14: ВРУ | L14: Birim düzeltildi: iç malzemede "компл." kullanılmadı
A15: 14 | B15: korpus | C15: ЩМП-6.6.1-0 | D15: Корпус ЩМП-6.6.1-0 600×600×150мм IP30 | E15: 1 | F15: шт | G15: TEKSAN | H15: 55000 | I15: KZT | J15: =IF(OR(E15="",H15=""),"",E15*H15) -> 55000 | K15: ЩГП
A16: 15 | B16: MCB | C16: NB1-125 3P C125 | D16: Автоматический выключатель CHINT NB1-125 3P C125A | E16: 1 | F16: шт | G16: CHINT | H16: 75000 | I16: KZT | J16: =IF(OR(E16="",H16=""),"",E16*H16) -> 75000 | K16: ЩГП | L16: Главный ввод ЩГП; аналог вместо ВА47-100-3Р125А; Fiyat IEK kaynaklı olabilir; CHINT fiyat listesi ile kontrol et
A17: 16 | B17: MCB | C17: NB1-63 3P C32 | D17: Автоматический выключатель CHINT NB1-63 3P C32A | E17: 7 | F17: шт | G17: CHINT | H17: 22000 | I17: KZT | J17: =IF(OR(E17="",H17=""),"",E17*H17) -> 154000 | K17: ЩГП | L17: Вводы от ВРУ ×2; аналог вместо ВА47-100-3Р32А; Fiyat IEK kaynaklı olabilir; CHINT fiyat listesi ile kontrol et; Отходящие гл.линии; аналог вместо ВА47-29-3Р32А; Fiyat IEK kaynaklı olabilir; CHINT fiyat listesi ile kontrol et
A18: 17 | B18: MTR | C18: ТОП-0.66-150/5 | D18: Трансформатор тока ТОП-0.66 У3 150/5A | E18: 3 | F18: шт | G18: SAIMAN | H18: 20000 | I18: KZT | J18: =IF(OR(E18="",H18=""),"",E18*H18) -> 60000 | K18: ЩГП
A19: 18 | B19: MTR | C19: ДАЛА-CA4Y-3720 | D19: Счётчик ДАЛА CA4Y-3720 R TX PLC IP П | E19: 1 | F19: шт | G19: SAIMAN | H19: 39100 | I19: KZT | J19: =IF(OR(E19="",H19=""),"",E19*H19) -> 39100 | K19: ЩГП
A20: 19 | B20: MCB | C20: NB1-63 3P C16 | D20: Автоматический выключатель CHINT NB1-63 3P C16A | E20: 9 | F20: шт | G20: CHINT | H20: 9500 | I20: KZT | J20: =IF(OR(E20="",H20=""),"",E20*H20) -> 85500 | K20: ЩАО, ЩГП, ЩО, ЩР, ЩРоб | L20: Ввод 3P; аналог вместо ВА47-29-3Р16А; Fiyat IEK kaynaklı olabilir; CHINT fiyat listesi ile kontrol et; аналог вместо ВА47-29-3Р16А; Fiyat IEK kaynaklı olabilir; CHINT fiyat listesi ile kontrol et
A21: 20 | B21: MCB | C21: NB1-63 1P C16 | D21: Автоматический выключатель CHINT NB1-63 1P C16A | E21: 6 | F21: шт | G21: CHINT | H21: 3800 | I21: KZT | J21: =IF(OR(E21="",H21=""),"",E21*H21) -> 22800 | K21: ЩГП, ЩР, ЩРоб | L21: аналог вместо ВА47-29-1Р16А; Fiyat IEK kaynaklı olabilir; CHINT fiyat listesi ile kontrol et
A22: 21 | B22: MCB | C22: NB1-63 1P C10 | D22: Автоматический выключатель CHINT NB1-63 1P C10A | E22: 1 | F22: шт | G22: CHINT | H22: 3500 | I22: KZT | J22: =IF(OR(E22="",H22=""),"",E22*H22) -> 3500 | K22: ЩГП | L22: аналог вместо ВА47-29-1Р10А; Fiyat IEK kaynaklı olabilir; CHINT fiyat listesi ile kontrol et
A23: 22 | B23: bara | C23: BB-N-PE | D23: Шина медная N+PE | E23: 1 | F23: м | G23: EKT | H23: 4197 | I23: KZT | J23: =IF(OR(E23="",H23=""),"",E23*H23) -> 4197 | K23: ЩГП
A24: 23 | B24: DIN | C24: DIN-35 | D24: DIN рейка TH35 | E24: 129 | F24: шт | G24: EKT | H24: 870 | I24: KZT | J24: =IF(OR(E24="",H24=""),"",E24*H24) -> 112230 | K24: ЩАО, ЩГП, ЩЗ1, ЩЗ2-12, ЩК Тип A, ЩК Тип B, ЩК Тип C, ЩО, ЩР, ЩРоб | L24: 2 шт на щит; Miktar 1 pano içindir; pano adedi üst satırda: 11 компл.; Miktar 1 pano içindir; pano adedi üst satırda: 47 компл.
A25: 24 | B25: kablo kanalı | C25: KK-40x40 | D25: Кабельный канал 40×40 | E25: 3 | F25: м | G25: EKT | H25: 1200 | I25: KZT | J25: =IF(OR(E25="",H25=""),"",E25*H25) -> 3600 | K25: ЩГП
A26: 25 | B26: montaj malzeme | D26: Монтажный материал | E26: 111 | F26: шт | G26: EKT | H26: 18000 | I26: KZT | J26: =IF(OR(E26="",H26=""),"",E26*H26) -> 1998000 | K26: ЩАО, ЩГП, ЩЗ1, ЩЗ2-12, ЩК Тип A, ЩК Тип B, ЩК Тип C, ЩО, ЩР, ЩРоб | L26: Miktar 1 pano içindir; pano adedi üst satırda: 47 компл.; Birim düzeltildi: iç malzemede "компл." kullanılmadı; Birim düzeltildi: iç malzemede "компл." kullanılmadı
A27: 26 | B27: montaj işçilik | D27: Монтажные работы ЩГП | E27: 40 | F27: сағат | G27: Manual | H27: 3500 | I27: KZT | J27: =IF(OR(E27="",H27=""),"",E27*H27) -> 140000 | K27: ЩГП
A28: 27 | B28: korpus | C28: TF-4030-15 | D28: Корпус навесной 400×300×150 IP54 | E28: 1 | F28: шт | G28: TEKSAN | H28: 28000 | I28: KZT | J28: =IF(OR(E28="",H28=""),"",E28*H28) -> 28000 | K28: ЩРоб
A29: 28 | B29: MCCB | C29: NH40-40/3 | D29: Выключатель нагрузки CHINT NH40 3P 40A | E29: 2 | F29: шт | G29: CHINT | H29: 25000 | I29: KZT | J29: =IF(OR(E29="",H29=""),"",E29*H29) -> 50000 | K29: ЩР, ЩРоб | L29: Главный ввод; аналог вместо ВН-32-3Р40А; Fiyat IEK kaynaklı olabilir; CHINT fiyat listesi ile kontrol et; Ввод QS; аналог вместо ВН-32-3Р40А; Fiyat IEK kaynaklı olabilir; CHINT fiyat listesi ile kontrol et
A30: 29 | B30: contactor | C30: NC1-20 230V AC | D30: Контактор CHINT NC1 20A, катушка 230V AC | E30: 3 | F30: шт | G30: CHINT | H30: 9500 | I30: KZT | J30: =IF(OR(E30="",H30=""),"",E30*H30) -> 28500 | K30: ЩРоб | L30: Управление нагревом; аналог вместо КМ20-11М-20A; Fiyat IEK kaynaklı olabilir; CHINT fiyat listesi ile kontrol et
A31: 30 | B31: other | C31: DEVIreg-316 | D31: Терморегулятор DEVIreg 316 | E31: 1 | F31: шт | G31: DEVI | H31: 45000 | I31: KZT | J31: =IF(OR(E31="",H31=""),"",E31*H31) -> 45000 | K31: ЩРоб | L31: Датчик температуры DEVisnow
A32: 31 | B32: klemens | C32: X1-4 | D32: Клемма 4мм² КВТ | E32: 20 | F32: шт | G32: Klemsan | H32: 380 | I32: KZT | J32: =IF(OR(E32="",H32=""),"",E32*H32) -> 7600 | K32: ЩРоб
A33: 32 | B33: montaj işçilik | D33: Монтажные работы ЩРоб | E33: 24 | F33: сағат | G33: Manual | H33: 3500 | I33: KZT | J33: =IF(OR(E33="",H33=""),"",E33*H33) -> 84000 | K33: ЩРоб
A34: 33 | B34: korpus | C34: TF-3040-15 | D34: Корпус навесной 300×400×150 IP54 | E34: 1 | F34: шт | G34: TEKSAN | H34: 22000 | I34: KZT | J34: =IF(OR(E34="",H34=""),"",E34*H34) -> 22000 | K34: ЩР
A35: 34 | B35: klemens | C35: X1-4 | D35: Клемма 4мм² | E35: 56 | F35: шт | G35: Klemsan | H35: 380 | I35: KZT | J35: =IF(OR(E35="",H35=""),"",E35*H35) -> 21280 | K35: ЩАО, ЩО, ЩР
A36: 35 | B36: montaj işçilik | D36: Монтажные работы | E36: 330 | F36: сағат | G36: Manual | H36: 3500 | I36: KZT | J36: =IF(OR(E36="",H36=""),"",E36*H36) -> 1155000 | K36: ЩАО, ЩК Тип B, ЩК Тип C, ЩО, ЩР | L36: 5 ч × 47; Miktar 1 pano içindir; pano adedi üst satırda: 47 компл.; Miktar 1 pano içindir; pano adedi üst satırda: 11 компл.
A37: 36 | B37: korpus | C37: TF-4030-15 | D37: Корпус навесной 400×300×150 IP31 | E37: 2 | F37: шт | G37: TEKSAN | H37: 22000 | I37: KZT | J37: =IF(OR(E37="",H37=""),"",E37*H37) -> 44000 | K37: ЩАО, ЩО
A38: 37 | B38: MCB | C38: NB1-63 1P B10 | D38: Автоматический выключатель CHINT NB1-63 1P B10A | E38: 112 | F38: шт | G38: CHINT | H38: 3500 | I38: KZT | J38: =IF(OR(E38="",H38=""),"",E38*H38) -> 392000 | K38: ЩАО, ЩК Тип A, ЩК Тип B, ЩК Тип C, ЩО | L38: Выходы ×10; аналог вместо ВА47-29-1Р-В10А; Fiyat IEK kaynaklı olabilir; CHINT fiyat listesi ile kontrol et; Выходы ×8; аналог вместо ВА47-29-1Р-В10А; Fiyat IEK kaynaklı olabilir; CHINT fiyat listesi ile kontrol et
A39: 38 | B39: contactor | C39: NC1-0910 230V AC | D39: Контактор CHINT NC1-0910, катушка 230V AC | E39: 1 | F39: шт | G39: CHINT | H39: 8000 | I39: KZT | J39: =IF(OR(E39="",H39=""),"",E39*H39) -> 8000 | K39: ЩАО | L39: Дистанционное управление; аналог вместо КМИ-10910; Fiyat IEK kaynaklı olabilir; CHINT fiyat listesi ile kontrol et
A40: 39 | B40: korpus | C40: ЩЗ1-ИЗГ | D40: Корпус этажный ЩЗ1 IP20 индивидуального изготовления | E40: 1 | F40: шт | G40: TEKSAN | H40: 65000 | I40: KZT | J40: =IF(OR(E40="",H40=""),"",E40*H40) -> 65000 | K40: ЩЗ1
...

Sheet 03_Kontrol_Notlari
A1: Kural | B1: Sonuç
A2: Boş satır bırakma | B2: Uygulandı: ana BOM’da boş satır yok.
A3: Sıra No’dan sonra pano adı sütunu | B3: Uygulandı: B sütunu her satırda panel adını içerir.
A4: Toplanmış pano satırı | B4: Uygulandı: her pano için Kategori=PANO, adet üst satırda, birim sadece "компл."
A5: İç malzemelerde компл. kullanılmaması | B5: Uygulandı: iç satırlarda "компл." yerine шт/м/сағат kullanıldı.
A6: Pano isminden sonraki satır korpus | B6: Uygulandı: her PANO satırından sonra korpus satırı var.
A7: Projedeki korpus ölçüsü ayrı sütun | B7: Uygulandı: Projedeki Korpus Ölçüsü ve Önerilen/Seçilen Korpus sütunları eklendi.
A8: Satır kopyala-ekle kullanılabilirliği | B8: Uygulandı: birleştirilmiş hücre kullanılmadı, her satır bağımsız.
A9: Her pano BOM’u 1 pano için | B9: Uygulandı: çok adetli panolarda iç malzeme miktarları 1 pano bazına indirildi; toplam alım 02_Satin_Alma’da hesaplandı.
A10: CHINT dönüşümü | B10: IEK şalt satırları CHINT muadiline çevrildi; kesin ürün kodu/fiyat kontrol notu bırakıldı.
