Workbook

Sheet BOM
A1: ROW | B1: Наименование1 | C1: Tip | D1: Артикул | E1: Номенклатура | F1: Цена (liste, KZT) | G1: Net KZT | H1: Сумма KZT | I1: Qty | J1: Ед.изм. | K1: Завод
A2: 1 | B2: =E2 -> ГРЩ | E2: ГРЩ | I2: 1 | J2: комплект
A3: 2 | C3: korpus | D3: 719-15614 | E3: Мет. Корпус (Пустой) (1700x600x450)+10CM База IP31 | F3: 145000 | G3: =F3*Kurallar!$B$3 -> 145000 | H3: =G3*I3 -> 145000 | I3: 1 | J3: шт | K3: EKT
A4: 3 | C4: TMŞ | D4: Мет. Корпус (Пустой) (1700x600x450)+10CM База IP31 | E4: Авт. выкл. NXM-250S/3Р 250A 36кА — ввод QF0 | F4: 36869 | G4: =F4*Kurallar!$B$2 -> 22121.4 | H4: =G4*I4 -> 22121.4 | I4: 1 | J4: шт | K4: CHINT
A5: 4 | C5: OTO | D5: 816143 | E5: Авт. выкл. NXB-125 3P 125A 10кА х-ка C — ЩСО-1 | F5: 11788 | G5: =F5*Kurallar!$B$2 -> 7072.8 | H5: =G5*I5 -> 7072.8 | I5: 1 | J5: шт | K5: CHINT
A6: 5 | C6: OTO | D6: 813876 | E6: Авт. выкл. NXB-63H 3P 50A 10кА х-ка C — ЩСО-2/ЩСО-3/П1В1/ЩЛ | F6: 11254 | G6: =F6*Kurallar!$B$2 -> 6752.4 | H6: =G6*I6 -> 27009.6 | I6: 4 | J6: шт | K6: CHINT
A7: 6 | C7: OTO | D7: 813875 | E7: Авт. выкл. NXB-63H 3P 40A 10кА х-ка C — ЩСО-0 | F7: 11002 | G7: =F7*Kurallar!$B$2 -> 6601.2 | H7: =G7*I7 -> 6601.2 | I7: 1 | J7: шт | K7: CHINT
A8: 7 | C8: OTO | D8: 813874 | E8: Авт. выкл. NXB-63H 3P 32A 10кА х-ка C — серверная/ЩАО | F8: 11771 | G8: =F8*Kurallar!$B$2 -> 7062.6 | H8: =G8*I8 -> 14125.2 | I8: 2 | J8: шт | K8: CHINT
A9: 8 | C9: OTO | D9: 813873 | E9: Авт. выкл. NXB-63H 3P 25A 10кА х-ка C — ЩУН | F9: 10552 | G9: =F9*Kurallar!$B$2 -> 6331.2 | H9: =G9*I9 -> 6331.2 | I9: 1 | J9: шт | K9: CHINT
A10: 9 | C10: OTO | D10: 814019 | E10: Авт. выкл. NXB-63 1P 50A 6кА х-ка C — МГН подъемник (⚠ проектная ошибка кабеля) | F10: 1550 | G10: =F10*Kurallar!$B$2 -> 930 | H10: =G10*I10 -> 930 | I10: 1 | J10: шт | K10: CHINT
A11: 10 | C11: DİF | D11: 515381 | E11: Диф. авт. выкл. NXBLE-63YH 1P+N C16 30mA тип A, 6kA (R) | F11: 5104 | G11: =F11*Kurallar!$B$2 -> 3062.4 | H11: =G11*I11 -> 3062.4 | I11: 1 | J11: шт | K11: CHINT
A12: 11 | C12: OTO | D12: 814013 | E12: Авт. выкл. NXB-63 1P 10A 6кА х-ка C — обогрев воронок (комб. с УЗО) | F12: 1362 | G12: =F12*Kurallar!$B$2 -> 817.2 | H12: =G12*I12 -> 817.2 | I12: 1 | J12: шт | K12: CHINT
A13: 12 | C13: sayac | D13: IA | E13: ДАЛА СА4У-Э720 R TX OP П RS1 Д W (3x220/380V 5-7,5A) | F13: 95000 | G13: =F13*Kurallar!$B$4 -> 95000 | H13: =G13*I13 -> 95000 | I13: 1 | J13: шт | K13: Saiman
A14: 13 | C14: tt | D14: TJ | E14: Трансформатор тока ТОП-0,66 кл.0,5 200/5A (⚠ на схеме 400/5, ПУЭ→200/5) | F14: 6500 | G14: =F14*Kurallar!$B$4 -> 6500 | H14: =G14*I14 -> 39000 | I14: 6 | J14: шт | K14: ekf
A15: 14 | C15: ampermetr | D15: 130300999_ | E15: Амперметр Э47 400/5А кл. точн. 1,5 96х96мм IEK !!! | F15: 4800 | G15: =F15*Kurallar!$B$3 -> 4800 | H15: =G15*I15 -> 14400 | I15: 3 | J15: шт | K15: IEK
A16: 15 | C16: voltmetr | D16: 130301016_ | E16: Вольтметр Э47 500В кл. точн. 1,5 72х72 IEK (1/100) | F16: 4806 | G16: =F16*Kurallar!$B$3 -> 4806 | H16: =G16*I16 -> 4806 | I16: 1 | J16: шт | K16: IEK
A17: 16 | C17: LOOBAR | D17: 130300554_ | E17: Шина медн. 4х30х4000 — ана бара Cu (ПУЭ 1.3.31, 250А) | F17: 8329 | G17: =F17*Kurallar!$B$3 -> 8329 | H17: =G17*I17 -> 8329 | I17: 1 | J17: шт | K17: EKT
A18: 17 | C18: Klemens | D18: 130301154_ | E18: ЗНИ 6мм² серый UNIT — ölçü/kumanda | F18: 111 | G18: =F18*Kurallar!$B$3 -> 111 | H18: =G18*I18 -> 1332 | I18: 12 | J18: шт | K18: UNIT
A19: 18 | C19: bara | D19: 130300473_ | E19: Шина медн.3х20х4000 | F19: 5538 | G19: =F19*Kurallar!$B$3 -> 5538 | H19: =G19*I19 -> 44304 | I19: 8 | J19: M. | K19: pys
A20: 21 | C20: montajный материал | D20: montajный материал | E20: Монтажный материал (наконечники, маркировка, провод, крепёж) | G20: 30000 | H20: =G20*I20 -> 30000 | I20: 1 | J20: компл. | K20: montajный материал
A21: 22 | C21: montajная работа | D21: montajная работа | E21: Монтажная работа (сборка, маркировка, тест) — Qty=dakika | F21: =I21/60 -> 7.1 | G21: =Kurallar!$B$6 -> 100 | H21: =G21*I21 -> 42600 | I21: =ROUND((33*Kurallar!$B$8+1*Kurallar!$B$9+1*Kurallar!$B$10+3*Kurallar!$B$11+4*Kurallar!$B$12+12*Kurallar!$B$14+2*Kurallar!$B$15+3*Kurallar!$B$17+10*Kurallar!$B$18+1.5*Kurallar!$B$19+1*Kurallar!$B$20)*Kurallar!$B$21,0) -> 426 | J21: дк | K21: montajная работа
A22: 23 | B22: Toplam ГРЩ | H22: =SUBTOTAL(9,H3:H21) -> 512842
A23: 24 | B23: =E23 -> ЩСО-0 | E23: ЩСО-0 | I23: 1 | J23: комплект
A24: 25 | C24: korpus | D24: 713-15010 | E24: Pano met.ShRv-24b/o(320х405х120)S/A36IP31(TS) | F24: 16500 | G24: =F24*Kurallar!$B$3 -> 16500 | H24: =G24*I24 -> 16500 | I24: 1 | J24: шт | K24: EKT
A25: 26 | C25: OTO | D25: 813874 | E25: Авт. выкл. NXB-63H 3P 32A 10кА х-ка C — ввод QF0 | F25: 11771 | G25: =F25*Kurallar!$B$2 -> 7062.6 | H25: =G25*I25 -> 7062.6 | I25: 1 | J25: шт | K25: CHINT
A26: 27 | C26: OTO | D26: 814040 | E26: Авт. выкл. NXB-63 1P 16A 6кА х-ка B — освещение Гр.0.1–0.2 | F26: 1419 | G26: =F26*Kurallar!$B$2 -> 851.4 | H26: =G26*I26 -> 1702.8 | I26: 2 | J26: шт | K26: CHINT
A27: 28 | C27: OTO | D27: 814038 | E27: Авт. выкл. NXB-63 1P 6A 6кА х-ка B — ЯТП | F27: 1419 | G27: =F27*Kurallar!$B$2 -> 851.4 | H27: =G27*I27 -> 851.4 | I27: 1 | J27: шт | K27: CHINT
A28: 29 | C28: DİF | D28: 515395 | E28: Диф. авт. выкл. NXBLE-63YH 1P+N C25 30mA тип A, 6kA (R) — розет. Гр.0.1–0.4 (комб.) | F28: 5069 | G28: =F28*Kurallar!$B$2 -> 3041.4 | H28: =G28*I28 -> 12165.6 | I28: 4 | J28: шт | K28: CHINT
A29: 30 | C29: OTO | D29: 814016 | E29: Авт. выкл. NXB-63 1P 25A 6кА х-ка C (комб. с УЗО) | F29: 1330 | G29: =F29*Kurallar!$B$2 -> 798 | H29: =G29*I29 -> 3192 | I29: 4 | J29: шт | K29: CHINT
A30: 36 | C30: montajный материал | E30: Монтажный материал (наконечники, маркировка, провод, крепёж) | G30: =ROUND(Kurallar!$B$5*SUM(H24:H29),0) -> 1244 | H30: =G30*I30 -> 1244 | I30: 1 | J30: компл. | K30: —
A31: 37 | C31: montajная работа | E31: Монтажная работа (сборка, маркировка, тест) — Qty=dakika | F31: =I31/60 -> 3.2666667 | G31: =Kurallar!$B$6 -> 100 | H31: =G31*I31 -> 19600 | I31: =ROUND((18*Kurallar!$B$8+21*Kurallar!$B$14+2*Kurallar!$B$15+1*Kurallar!$B$16+2*Kurallar!$B$17+4*Kurallar!$B$18+1*Kurallar!$B$19)*Kurallar!$B$21,0) -> 196 | J31: дк | K31: —
A32: 38 | B32: Toplam ЩСО-0 | H32: =SUBTOTAL(9,H24:H31) -> 62318.4
A33: 39 | B33: =E33 -> ЩСО-1 | E33: ЩСО-1 | I33: 1 | J33: комплект
A34: 40 | C34: korpus | D34: 713-15024 | E34: ЩРВ- 72 (670x450x125) (TS) | F34: 24490 | G34: =F34*Kurallar!$B$3 -> 24490 | H34: =G34*I34 -> 24490 | I34: 1 | J34: шт | K34: EKT
A35: 41 | C35: OTO | D35: 816143 | E35: Авт. выкл. NXB-125 3P 125A 10кА х-ка C — ввод QF0 | F35: 11788 | G35: =F35*Kurallar!$B$2 -> 7072.8 | H35: =G35*I35 -> 7072.8 | I35: 1 | J35: шт | K35: CHINT
A36: 42 | C36: OTO | D36: 814040 | E36: Авт. выкл. NXB-63 1P 16A 6кА х-ка B — QF1/QF2/QF16 освещение | F36: 1419 | G36: =F36*Kurallar!$B$2 -> 851.4 | H36: =G36*I36 -> 2554.2 | I36: 3 | J36: шт | K36: CHINT
A37: 43 | C37: OTO | D37: 814039 | E37: Авт. выкл. NXB-63 1P 10A 6кА х-ка B — QF10 | F37: 1419 | G37: =F37*Kurallar!$B$2 -> 851.4 | H37: =G37*I37 -> 851.4 | I37: 1 | J37: шт | K37: CHINT
A38: 44 | C38: DİF | D38: 515395 | E38: Диф. авт. выкл. NXBLE-63YH 1P+N C25 30mA тип A, 6kA (R)C — розет. группы (комб.) | F38: 5069 | G38: =F38*Kurallar!$B$2 -> 3041.4 | H38: =G38*I38 -> 18248.4 | I38: 6 | J38: шт | K38: CHINT
A39: 45 | C39: OTO | D39: 814016 | E39: Авт. выкл. NXB-63 1P 25A 6кА х-ка C (комб. с УЗО) | F39: 1330 | G39: =F39*Kurallar!$B$2 -> 798 | H39: =G39*I39 -> 4788 | I39: 6 | J39: шт | K39: CHINT
A40: 46 | C40: OTO | D40: 814170 | E40: Авт. выкл. NXB-63 3P 16A 6кА х-ка C — QF7 (К1) | F40: 5462 | G40: =F40*Kurallar!$B$2 -> 3277.2 | H40: =G40*I40 -> 3277.2 | I40: 1 | J40: шт | K40: CHINT
...

Sheet СВОД
A1: № | B1: Пано | C1: Компл. | D1: 1 компл. maliyeti (KZT) | E1: Toplam (KZT) | F1: 2.3
A2: 1 | B2: ГРЩ | C2: 1 | D2: =BOM!H22 -> 512842 | E2: =C2*D2 -> 512842 | F2: =2.3*D2 -> 1179536.6
A3: 2 | B3: ЩСО-0 | C3: 1 | D3: =BOM!H32 -> 62318.4 | E3: =C3*D3 -> 62318.4 | F3: =2.3*D3 -> 143332.32
A4: 3 | B4: ЩСО-1 | C4: 1 | D4: =BOM!H50 -> 131280.4 | E4: =C4*D4 -> 131280.4 | F4: =2.3*D4 -> 301944.92
A5: 4 | B5: ЩСО-2 | C5: 1 | D5: =BOM!H63 -> 102172.4 | E5: =C5*D5 -> 102172.4 | F5: =2.3*D5 -> 234996.52
A6: 5 | B6: ЩСО-3 | C6: 1 | D6: =BOM!H77 -> 106381.8 | E6: =C6*D6 -> 106381.8 | F6: =2.3*D6 -> 244678.14
A7: 6 | B7: ЩАО | C7: 1 | D7: =BOM!H88 -> 51213.6 | E7: =C7*D7 -> 51213.6 | F7: =2.3*D7 -> 117791.28
A8: 7 | B8: ЩЛ | C8: 1 | D8: =BOM!H102 -> 38896.6 | E8: =C8*D8 -> 38896.6 | F8: =2.3*D8 -> 89462.18
A9: 8 | B9: ЯТП-12/250 | C9: 2 | D9: =BOM!H105 -> 21863 | E9: =C9*D9 -> 43726 | F9: =2.3*D9 -> 50284.9
B10: GENEL TOPLAM | E10: =SUM(E2:E9) -> 1048831.2

Sheet Kurallar
A1: Katsayı / Norm | B1: Değer | C1: Açıklama
A2: CHINT net katsayı | B2: 0.6 | C2: Liste KZT × 0.60 (%40 isk.) — 260613 CHINT listesi (13.06.2026)
A3: EKT/IEK/UNIT net katsayı | B3: 1 | C3: EKT 19.06.2025 (~13 ay) ⚠ ikaz: fiyatlar güncellenmeli
A4: Saiman net katsayı | B4: 1 | C4: Saiman 2026 listesi
A5: Montaj malzeme % | B5: 0.03 | C5: Pano malzeme toplamının %3ü
A6: İşçilik KZT/dk | B6: 100 | C6: G sütunu işçilik satırında
A7: --- İşçilik zaman normları --- | C7: Dakika; I sütunu = toplam dk
A8: Modüler cihaz dk/modül | B8: 2.5 | C8: OTO/DİF(UZO+OTO)/NXB-125
A9: TMŞ (MCCB) dk/adet | B9: 30 | C9: NXM
A10: Sayaç dk/adet | B10: 20
A11: TT dk/adet | B11: 10
A12: PA/PV dk/adet | B12: 10
A13: SHT bobin dk/adet | B13: 7 | C13: РН47 muadili
A14: Klemens dk/adet | B14: 2
A15: N/PE şina dk/adet | B15: 7
A16: Tarak bara dk/adet | B16: 5 | C16: PIN
A17: DIN ray dk/metre | B17: 5
A18: Kanal dk/metre | B18: 5
A19: Korpus hazırlık dk | B19: 60 | C19: ГРЩ ×1.5
A20: Cu bara işleme dk/çubuk | B20: 30
A21: Test/etiket katsayısı | B21: 1
A24: FİYAT KAYNAKLARI:
A25: CHINT: 260613_chint_Остатки...xlsx (13.06.2026, KZT) — GÜNCEL ✅
A26: EKT: 19062025_EKT_PRICE.xlsx (19.06.2025, KZT) — ~13 AY ⚠ ikaz ile kullanıldı
A27: Saiman: САЙМАН_2026_прайс (2026, KZT) — GÜNCEL ✅
A28: Tüm fiyatlar KZT — kur hücresi gerekmez.
A30: NOT: CHINT stok listesinde АВДТ (difavtomat) yok → DİF = УЗО NXL-63 1P+N 30mA + OTO NXB-63 1P kombinasyonu (3 modül).
A31: NOT: ЩЛ ввод 40A D 10kA stokta yok → NXB-63 3P D40 6kA kullanıldı (alternatif: NXM-125S/3P 40A).
A32: NOT: TT 200/5 (ПУЭ 1.5.17 hesabı); şema sembolü 400/5 — çelişki, hesap 200/5 doğruluyor.
