Workbook

Sheet BOM
A1: ROW | B1: Наименование1 | C1: Тип | D1: Артикул | E1: Номенклатура | F1: Цена (лист) | G1: Цена нетто KZT | H1: Сумма KZT | I1: Кол-во | J1: Ед.изм. | K1: Завод
A2: 1 | B2: =E2 -> ЩАВР De-icing (AVR POWER PANEL) | E2: ЩАВР De-icing (AVR POWER PANEL) | I2: 1 | J2: комплект
A3: 2 | C3: korpus | D3: 719-15923 | E3: Мет. Щит ВРУ (2000x800x600)+10 база (TS) | F3: =IFERROR(INDEX(FIYAT_KAYNAK!$F$3:$F$47,MATCH("KAZTEK|719-15923",FIYAT_KAYNAK!$A$3:$A$47,0)),"") -> 148675 | G3: =IFERROR(INDEX(FIYAT_KAYNAK!$J$3:$J$47,MATCH("KAZTEK|719-15923",FIYAT_KAYNAK!$A$3:$A$47,0)),"") -> 148675 | H3: =IF(OR(G3="",I3=""),"",G3*I3) -> 148675 | I3: 1 | J3: шт | K3: KAZTEK
A4: 3 | C4: TMŞ | D4: 1SDA100385R1 | E4: Выключатель автоматический XT5N 400 TMA In=400A InN=100% 4P, Icu 36кА | F4: =IFERROR(INDEX(FIYAT_KAYNAK!$F$3:$F$47,MATCH("ABB|1SDA100385R1",FIYAT_KAYNAK!$A$3:$A$47,0)),"") -> 1810 | G4: =IFERROR(INDEX(FIYAT_KAYNAK!$J$3:$J$47,MATCH("ABB|1SDA100385R1",FIYAT_KAYNAK!$A$3:$A$47,0)),"") -> 393317.98 | H4: =IF(OR(G4="",I4=""),"",G4*I4) -> 786635.95 | I4: 2 | J4: шт | K4: ABB
A5: 4 | C5: rubilnik | D5: 1SCA022847R3250 | E5: Переключатель нагрузки автоматический (АВР) OTM400E4CM230C 400А 4P | F5: =IFERROR(INDEX(FIYAT_KAYNAK!$F$3:$F$47,MATCH("ABB|1SCA022847R3250",FIYAT_KAYNAK!$A$3:$A$47,0)),"") -> 3945 | G5: =IFERROR(INDEX(FIYAT_KAYNAK!$J$3:$J$47,MATCH("ABB|1SCA022847R3250",FIYAT_KAYNAK!$A$3:$A$47,0)),"") -> 857259.35 | H5: =IF(OR(G5="",I5=""),"",G5*I5) -> 857259.35 | I5: 1 | J5: шт | K5: ABB
A6: 5 | C6: TMŞ | D6: 1SDA067418R1 | E6: Выключатель автоматический XT1N 160 TMD In=160A 3P, Icu 36кА — AFL Mast | F6: =IFERROR(INDEX(FIYAT_KAYNAK!$F$3:$F$47,MATCH("ABB|1SDA067418R1",FIYAT_KAYNAK!$A$3:$A$47,0)),"") -> 317.9 | G6: =IFERROR(INDEX(FIYAT_KAYNAK!$J$3:$J$47,MATCH("ABB|1SDA067418R1",FIYAT_KAYNAK!$A$3:$A$47,0)),"") -> 69080.544 | H6: =IF(OR(G6="",I6=""),"",G6*I6) -> 69080.544 | I6: 1 | J6: шт | K6: ABB
A7: 6 | C7: OTO | D7: 2CDS273001R0634 | E7: Выключатель автоматический S203M-C63 3P 63А, 10кА, хар. C — Резерв | F7: =IFERROR(INDEX(FIYAT_KAYNAK!$F$3:$F$47,MATCH("ABB|2CDS273001R0634",FIYAT_KAYNAK!$A$3:$A$47,0)),"") -> 107.1 | G7: =IFERROR(INDEX(FIYAT_KAYNAK!$J$3:$J$47,MATCH("ABB|2CDS273001R0634",FIYAT_KAYNAK!$A$3:$A$47,0)),"") -> 23273.125 | H7: =IF(OR(G7="",I7=""),"",G7*I7) -> 23273.125 | I7: 1 | J7: шт | K7: ABB
A8: 7 | C8: TMŞ | D8: 1SDA067416R1 | E8: Выключатель автоматический XT1N 160 TMD In=100A 3P, Icu 36кА — Резерв / Пункт управления | F8: =IFERROR(INDEX(FIYAT_KAYNAK!$F$3:$F$47,MATCH("ABB|1SDA067416R1",FIYAT_KAYNAK!$A$3:$A$47,0)),"") -> 246.1 | G8: =IFERROR(INDEX(FIYAT_KAYNAK!$J$3:$J$47,MATCH("ABB|1SDA067416R1",FIYAT_KAYNAK!$A$3:$A$47,0)),"") -> 53478.207 | H8: =IF(OR(G8="",I8=""),"",G8*I8) -> 106956.41 | I8: 2 | J8: шт | K8: ABB
A9: 8 | C9: OTO | D9: 2CDS273001R0164 | E9: Выключатель автоматический S203M-C16 3P 16А, 10кА, хар. C — Резервуар De-icing | F9: =IFERROR(INDEX(FIYAT_KAYNAK!$F$3:$F$47,MATCH("ABB|2CDS273001R0164",FIYAT_KAYNAK!$A$3:$A$47,0)),"") -> 63.02 | G9: =IFERROR(INDEX(FIYAT_KAYNAK!$J$3:$J$47,MATCH("ABB|2CDS273001R0164",FIYAT_KAYNAK!$A$3:$A$47,0)),"") -> 13694.419 | H9: =IF(OR(G9="",I9=""),"",G9*I9) -> 13694.419 | I9: 1 | J9: шт | K9: ABB
A10: 9 | C10: OTO | D10: 2CDS273001R0404 | E10: Выключатель автоматический S203M-C40 3P 40А, 10кА, хар. C — Резерв | F10: =IFERROR(INDEX(FIYAT_KAYNAK!$F$3:$F$47,MATCH("ABB|2CDS273001R0404",FIYAT_KAYNAK!$A$3:$A$47,0)),"") -> 81.89 | G10: =IFERROR(INDEX(FIYAT_KAYNAK!$J$3:$J$47,MATCH("ABB|2CDS273001R0404",FIYAT_KAYNAK!$A$3:$A$47,0)),"") -> 17794.922 | H10: =IF(OR(G10="",I10=""),"",G10*I10) -> 17794.922 | I10: 1 | J10: шт | K10: ABB
A11: 10 | C11: OTO | D11: 2CDS271001R0254 | E11: Выключатель автоматический S201M-C25 1P 25А, 10кА, хар. C — Камера / Резерв ×2 | F11: =IFERROR(INDEX(FIYAT_KAYNAK!$F$3:$F$47,MATCH("ABB|2CDS271001R0254",FIYAT_KAYNAK!$A$3:$A$47,0)),"") -> 13.99 | G11: =IFERROR(INDEX(FIYAT_KAYNAK!$J$3:$J$47,MATCH("ABB|2CDS271001R0254",FIYAT_KAYNAK!$A$3:$A$47,0)),"") -> 3040.0655 | H11: =IF(OR(G11="",I11=""),"",G11*I11) -> 9120.1964 | I11: 3 | J11: шт | K11: ABB
A12: 11 | C12: LOOBAR | D12: 130200208_ | E12: Шина медная 5х50х4000 мм (сборные шины 400А, L1/L2/L3/N) | F12: =IFERROR(INDEX(FIYAT_KAYNAK!$F$3:$F$47,MATCH("EKT|130200208_",FIYAT_KAYNAK!$A$3:$A$47,0)),"") -> 17515 | G12: =IFERROR(INDEX(FIYAT_KAYNAK!$J$3:$J$47,MATCH("EKT|130200208_",FIYAT_KAYNAK!$A$3:$A$47,0)),"") -> 17515 | H12: =IF(OR(G12="",I12=""),"",G12*I12) -> 35030 | I12: 2 | J12: шт | K12: EKT
A13: 12 | C13: Klemens | D13: 130301155_ | E13: Зажим наборный ЗНИ 10мм² (70А), серый | F13: =IFERROR(INDEX(FIYAT_KAYNAK!$F$3:$F$47,MATCH("EKT|130301155_",FIYAT_KAYNAK!$A$3:$A$47,0)),"") -> 151 | G13: =IFERROR(INDEX(FIYAT_KAYNAK!$J$3:$J$47,MATCH("EKT|130301155_",FIYAT_KAYNAK!$A$3:$A$47,0)),"") -> 151 | H13: =IF(OR(G13="",I13=""),"",G13*I13) -> 3624 | I13: 24 | J13: шт | K13: EKT
A14: 13 | C14: montajный материал | D14: 570003 | E14: DIN-рейка оцинкованная TH35-7.5, 1000 мм | F14: =IFERROR(INDEX(FIYAT_KAYNAK!$F$3:$F$47,MATCH("CHINT|570003",FIYAT_KAYNAK!$A$3:$A$47,0)),"") -> 869 | G14: =IFERROR(INDEX(FIYAT_KAYNAK!$J$3:$J$47,MATCH("CHINT|570003",FIYAT_KAYNAK!$A$3:$A$47,0)),"") -> 521.4 | H14: =IF(OR(G14="",I14=""),"",G14*I14) -> 4171.2 | I14: 8 | J14: шт | K14: CHINT
A15: 14 | C15: montajный материал | D15: 270300105_ | E15: Кабель-канал перфорированный 40х60, ИМПАКТ | F15: =IFERROR(INDEX(FIYAT_KAYNAK!$F$3:$F$47,MATCH("EKT|270300105_",FIYAT_KAYNAK!$A$3:$A$47,0)),"") -> 1808 | G15: =IFERROR(INDEX(FIYAT_KAYNAK!$J$3:$J$47,MATCH("EKT|270300105_",FIYAT_KAYNAK!$A$3:$A$47,0)),"") -> 1808 | H15: =IF(OR(G15="",I15=""),"",G15*I15) -> 14464 | I15: 8 | J15: шт | K15: EKT
A16: 15 | C16: montajный материал | E16: Монтажные материалы (крепёж, маркировка, наконечники) | G16: =SUM(H3:H15)*Kurallar!$B$13 -> 62693.374 | H16: =G16*I16 -> 62693.374 | I16: 1 | J16: компл. | K16: —
A17: 16 | C17: montajная работа | E17: Сборка щита (норма времени, см. лист «Kurallar») | F17: =I17/60 -> 6.3058333 | G17: =Kurallar!$B$11 -> 100 | H17: =G17*I17 -> 37835 | I17: =Kurallar!$D$39 -> 378.35 | J17: мин | K17: YSF
B18: Toplam ЩАВР De-icing (AVR POWER PANEL) | H18: =SUBTOTAL(9,H3:H17) -> 2190307.5 | I18: 1 | J18: компл.
A19: 17 | C19: opn | D19: 2CTB812111R2300 | E19: ⚠ KONTROL — Ограничитель перенапряжения OVR T1-T2 3N 100-255 P TS (класс I+II) | I19: 1 | J19: шт | K19: ABB
A20: 18 | C20: sayac | E20: ⚠ KONTROL — Счётчик электроэнергии 3-фазный (тип по ТУ АО «Алматы Энергосбыт») | I20: 1 | J20: шт
A21: 19 | C21: tt | E21: ⚠ KONTROL — Трансформатор тока 400/5 (3 шт на счётчик) | I21: 3 | J21: шт
A22: 20 | B22: =E22 -> ЩУ AFL De-icing (AFL MAST CONTROL PANEL) | E22: ЩУ AFL De-icing (AFL MAST CONTROL PANEL) | I22: 1 | J22: комплект
A23: 21 | C23: korpus | D23: 719-15420 | E23: Мет.Корпус ЩМП-4 (800x650x250) IP54 | F23: =IFERROR(INDEX(FIYAT_KAYNAK!$F$3:$F$47,MATCH("KAZTEK|719-15420",FIYAT_KAYNAK!$A$3:$A$47,0)),"") -> 30540 | G23: =IFERROR(INDEX(FIYAT_KAYNAK!$J$3:$J$47,MATCH("KAZTEK|719-15420",FIYAT_KAYNAK!$A$3:$A$47,0)),"") -> 30540 | H23: =IF(OR(G23="",I23=""),"",G23*I23) -> 30540 | I23: 1 | J23: шт | K23: KAZTEK
A24: 22 | C24: TMŞ | D24: 1SDA067415R1 | E24: Выключатель автоматический XT1N 160 TMD In=80A 3P, Icu 36кА — ввод от ЩАВР | F24: =IFERROR(INDEX(FIYAT_KAYNAK!$F$3:$F$47,MATCH("ABB|1SDA067415R1",FIYAT_KAYNAK!$A$3:$A$47,0)),"") -> 246.1 | G24: =IFERROR(INDEX(FIYAT_KAYNAK!$J$3:$J$47,MATCH("ABB|1SDA067415R1",FIYAT_KAYNAK!$A$3:$A$47,0)),"") -> 53478.207 | H24: =IF(OR(G24="",I24=""),"",G24*I24) -> 53478.207 | I24: 1 | J24: шт | K24: ABB
A25: 23 | C25: OTO | D25: 2CDS251001R0065 | E25: Выключатель автоматический S201-B6 1P 6А, 6кА, хар. B — цепи управления | F25: =IFERROR(INDEX(FIYAT_KAYNAK!$F$3:$F$47,MATCH("ABB|2CDS251001R0065",FIYAT_KAYNAK!$A$3:$A$47,0)),"") -> 11.74 | G25: =IFERROR(INDEX(FIYAT_KAYNAK!$J$3:$J$47,MATCH("ABB|2CDS251001R0065",FIYAT_KAYNAK!$A$3:$A$47,0)),"") -> 2551.1343 | H25: =IF(OR(G25="",I25=""),"",G25*I25) -> 2551.1343 | I25: 1 | J25: шт | K25: ABB
A26: 24 | C26: OTO | D26: 2CDS273001R0634 | E26: Выключатель автоматический S203M-C63 3P 63А, 10кА, хар. C — AFL LIGHTs (K1…K4) | F26: =IFERROR(INDEX(FIYAT_KAYNAK!$F$3:$F$47,MATCH("ABB|2CDS273001R0634",FIYAT_KAYNAK!$A$3:$A$47,0)),"") -> 107.1 | G26: =IFERROR(INDEX(FIYAT_KAYNAK!$J$3:$J$47,MATCH("ABB|2CDS273001R0634",FIYAT_KAYNAK!$A$3:$A$47,0)),"") -> 23273.125 | H26: =IF(OR(G26="",I26=""),"",G26*I26) -> 93092.498 | I26: 4 | J26: шт | K26: ABB
A27: 25 | C27: OTO | D27: 2CDS273001R0324 | E27: Выключатель автоматический S203M-C32 3P 32А, 10кА, хар. C — Резерв | F27: =IFERROR(INDEX(FIYAT_KAYNAK!$F$3:$F$47,MATCH("ABB|2CDS273001R0324",FIYAT_KAYNAK!$A$3:$A$47,0)),"") -> 78.75 | G27: =IFERROR(INDEX(FIYAT_KAYNAK!$J$3:$J$47,MATCH("ABB|2CDS273001R0324",FIYAT_KAYNAK!$A$3:$A$47,0)),"") -> 17112.592 | H27: =IF(OR(G27="",I27=""),"",G27*I27) -> 17112.592 | I27: 1 | J27: шт | K27: ABB
A28: 26 | C28: OTO | D28: 2CDS271001R0164 | E28: Выключатель автоматический S201M-C16 1P 16А, 10кА, хар. C — Резерв | F28: =IFERROR(INDEX(FIYAT_KAYNAK!$F$3:$F$47,MATCH("ABB|2CDS271001R0164",FIYAT_KAYNAK!$A$3:$A$47,0)),"") -> 13.99 | G28: =IFERROR(INDEX(FIYAT_KAYNAK!$J$3:$J$47,MATCH("ABB|2CDS271001R0164",FIYAT_KAYNAK!$A$3:$A$47,0)),"") -> 3040.0655 | H28: =IF(OR(G28="",I28=""),"",G28*I28) -> 3040.0655 | I28: 1 | J28: шт | K28: ABB
A29: 27 | C29: kontaktör | D29: 1SAE351111R0640 | E29: Контактор модульный ESB63-40N 63А 4НО, катушка 230В AC/DC | F29: =IFERROR(INDEX(FIYAT_KAYNAK!$F$3:$F$47,MATCH("ABB|1SAE351111R0640",FIYAT_KAYNAK!$A$3:$A$47,0)),"") -> 183.3 | G29: =IFERROR(INDEX(FIYAT_KAYNAK!$J$3:$J$47,MATCH("ABB|1SAE351111R0640",FIYAT_KAYNAK!$A$3:$A$47,0)),"") -> 39831.594 | H29: =IF(OR(G29="",I29=""),"",G29*I29) -> 159326.38 | I29: 4 | J29: шт | K29: ABB
A30: 28 | C30: Röle | D30: 2CSM208141R1000 | E30: Таймер недельный AW1CO-R-120m, 7 сут, резерв 150 ч, 1 перекл. контакт | F30: =IFERROR(INDEX(FIYAT_KAYNAK!$F$3:$F$47,MATCH("ABB|2CSM208141R1000",FIYAT_KAYNAK!$A$3:$A$47,0)),"") -> 144.4 | G30: =IFERROR(INDEX(FIYAT_KAYNAK!$J$3:$J$47,MATCH("ABB|2CSM208141R1000",FIYAT_KAYNAK!$A$3:$A$47,0)),"") -> 31378.517 | H30: =IF(OR(G30="",I30=""),"",G30*I30) -> 31378.517 | I30: 1 | J30: шт | K30: ABB
A31: 29 | C31: Röle | D31: 1SVR405613R3000 | E31: Реле промежуточное CR-M230AC4, 4 перекл. контакта, 230В AC | F31: =IFERROR(INDEX(FIYAT_KAYNAK!$F$3:$F$47,MATCH("ABB|1SVR405613R3000",FIYAT_KAYNAK!$A$3:$A$47,0)),"") -> 12.83 | G31: =IFERROR(INDEX(FIYAT_KAYNAK!$J$3:$J$47,MATCH("ABB|1SVR405613R3000",FIYAT_KAYNAK!$A$3:$A$47,0)),"") -> 2787.9943 | H31: =IF(OR(G31="",I31=""),"",G31*I31) -> 2787.9943 | I31: 1 | J31: шт | K31: ABB
A32: 30 | C32: Röle Altlığı | D32: 1SVR405651R3000 | E32: Колодка для реле CR-M4SS, 4 перекл., винтовая | F32: =IFERROR(INDEX(FIYAT_KAYNAK!$F$3:$F$47,MATCH("ABB|1SVR405651R3000",FIYAT_KAYNAK!$A$3:$A$47,0)),"") -> 8.5 | G32: =IFERROR(INDEX(FIYAT_KAYNAK!$J$3:$J$47,MATCH("ABB|1SVR405651R3000",FIYAT_KAYNAK!$A$3:$A$47,0)),"") -> 1847.0734 | H32: =IF(OR(G32="",I32=""),"",G32*I32) -> 1847.0734 | I32: 1 | J32: шт | K32: ABB
A33: 31 | C33: blok | D33: 1SFA619210R1026 | E33: Переключатель 3-позиционный C3SS1-10B-20, 2НО (АВТО-ОТКЛ-РУЧН) | F33: =IFERROR(INDEX(FIYAT_KAYNAK!$F$3:$F$47,MATCH("ABB|1SFA619210R1026",FIYAT_KAYNAK!$A$3:$A$47,0)),"") -> 13.13 | G33: =IFERROR(INDEX(FIYAT_KAYNAK!$J$3:$J$47,MATCH("ABB|1SFA619210R1026",FIYAT_KAYNAK!$A$3:$A$47,0)),"") -> 2853.1851 | H33: =IF(OR(G33="",I33=""),"",G33*I33) -> 2853.1851 | I33: 1 | J33: шт | K33: ABB
A34: 32 | C34: Sinyal Lambası | D34: 1SFA619403R5232 | E34: Лампа сигнальная CL2-523G, LED 230В AC, зелёная («FLTs ON») | F34: =IFERROR(INDEX(FIYAT_KAYNAK!$F$3:$F$47,MATCH("ABB|1SFA619403R5232",FIYAT_KAYNAK!$A$3:$A$47,0)),"") -> 9.62 | G34: =IFERROR(INDEX(FIYAT_KAYNAK!$J$3:$J$47,MATCH("ABB|1SFA619403R5232",FIYAT_KAYNAK!$A$3:$A$47,0)),"") -> 2090.4525 | H34: =IF(OR(G34="",I34=""),"",G34*I34) -> 2090.4525 | I34: 1 | J34: шт | K34: ABB
A35: 33 | C35: LOOBAR | D35: 811002 | E35: Шина соединительная типа PIN 3P, 63А, L=1000 мм | F35: =IFERROR(INDEX(FIYAT_KAYNAK!$F$3:$F$47,MATCH("CHINT|811002",FIYAT_KAYNAK!$A$3:$A$47,0)),"") -> 12699 | G35: =IFERROR(INDEX(FIYAT_KAYNAK!$J$3:$J$47,MATCH("CHINT|811002",FIYAT_KAYNAK!$A$3:$A$47,0)),"") -> 7619.4 | H35: =IF(OR(G35="",I35=""),"",G35*I35) -> 7619.4 | I35: 1 | J35: шт | K35: CHINT
A36: 34 | C36: LOOBAR | D36: 130200399_ | E36: Шина «N»/«PE» ШНК 3L+PEN 4х7, 100А, на DIN-рейку в корпусе | F36: =IFERROR(INDEX(FIYAT_KAYNAK!$F$3:$F$47,MATCH("EKT|130200399_",FIYAT_KAYNAK!$A$3:$A$47,0)),"") -> 2567 | G36: =IFERROR(INDEX(FIYAT_KAYNAK!$J$3:$J$47,MATCH("EKT|130200399_",FIYAT_KAYNAK!$A$3:$A$47,0)),"") -> 2567 | H36: =IF(OR(G36="",I36=""),"",G36*I36) -> 2567 | I36: 1 | J36: шт | K36: EKT
A37: 35 | C37: LOOBAR | D37: 130300473_ | E37: Шина медная 3х20х4000 мм (сборные шины 160А, L1/L2/L3/N) | F37: =IFERROR(INDEX(FIYAT_KAYNAK!$F$3:$F$47,MATCH("EKT|130300473_",FIYAT_KAYNAK!$A$3:$A$47,0)),"") -> 4204 | G37: =IFERROR(INDEX(FIYAT_KAYNAK!$J$3:$J$47,MATCH("EKT|130300473_",FIYAT_KAYNAK!$A$3:$A$47,0)),"") -> 4204 | H37: =IF(OR(G37="",I37=""),"",G37*I37) -> 4204 | I37: 1 | J37: шт | K37: EKT
A38: 36 | C38: Klemens | D38: 130301153_ | E38: Зажим наборный ЗНИ 4мм² (35А), серый — цепи управления | F38: =IFERROR(INDEX(FIYAT_KAYNAK!$F$3:$F$47,MATCH("EKT|130301153_",FIYAT_KAYNAK!$A$3:$A$47,0)),"") -> 90 | G38: =IFERROR(INDEX(FIYAT_KAYNAK!$J$3:$J$47,MATCH("EKT|130301153_",FIYAT_KAYNAK!$A$3:$A$47,0)),"") -> 90 | H38: =IF(OR(G38="",I38=""),"",G38*I38) -> 1800 | I38: 20 | J38: шт | K38: EKT
A39: 37 | C39: Klemens | D39: 130301155_ | E39: Зажим наборный ЗНИ 10мм² (70А), серый — силовые отходящие | F39: =IFERROR(INDEX(FIYAT_KAYNAK!$F$3:$F$47,MATCH("EKT|130301155_",FIYAT_KAYNAK!$A$3:$A$47,0)),"") -> 151 | G39: =IFERROR(INDEX(FIYAT_KAYNAK!$J$3:$J$47,MATCH("EKT|130301155_",FIYAT_KAYNAK!$A$3:$A$47,0)),"") -> 151 | H39: =IF(OR(G39="",I39=""),"",G39*I39) -> 1812 | I39: 12 | J39: шт | K39: EKT
A40: 38 | C40: montajный материал | D40: 570003 | E40: DIN-рейка оцинкованная TH35-7.5, 1000 мм | F40: =IFERROR(INDEX(FIYAT_KAYNAK!$F$3:$F$47,MATCH("CHINT|570003",FIYAT_KAYNAK!$A$3:$A$47,0)),"") -> 869 | G40: =IFERROR(INDEX(FIYAT_KAYNAK!$J$3:$J$47,MATCH("CHINT|570003",FIYAT_KAYNAK!$A$3:$A$47,0)),"") -> 521.4 | H40: =IF(OR(G40="",I40=""),"",G40*I40) -> 2607 | I40: 5 | J40: шт | K40: CHINT
...

Sheet СВОД
A1: Almaty International Airport — Apron Floodlighting (De-icing / Cargo / VIP), BK3812 — СВОДНАЯ ВЕДОМОСТЬ
A2: Rev. A · 2026-08-17
A4: Щит | B4: Кол-во компл. | C4: Цена за 1 компл. KZT | D4: Сумма KZT | E4: Модули исп. | F4: Модули всего | G4: Заполнение | H4: Статус
A5: ЩАВР De-icing (AVR POWER PANEL) | B5: 1 | C5: =BOM!H18 -> 2190307.5 | D5: =B5*C5 -> 2190307.5 | E5: 93.2 | F5: 200 | G5: =E5/F5 -> 0.466 | H5: =IF(E5/F5>1,"⛔ КОРПУС МАЛ",IF(E5/F5>0.8,"⚠ РЕЗЕРВ <20%","✅ OK")) -> ✅ OK
A6: ЩУ AFL De-icing (AFL MAST CONTROL PANEL) | B6: 1 | C6: =BOM!H44 -> 471852.82 | D6: =B6*C6 -> 471852.82 | E6: 48.6 | F6: 96 | G6: =E6/F6 -> 0.50625 | H6: =IF(E6/F6>1,"⛔ КОРПУС МАЛ",IF(E6/F6>0.8,"⚠ РЕЗЕРВ <20%","✅ OK")) -> ✅ OK
A7: ЩАВР Cargo (AVR POWER PANEL) | B7: 1 | C7: =BOM!H62 -> 1480453.9 | D7: =B7*C7 -> 1480453.9 | E7: 80 | F7: 150 | G7: =E7/F7 -> 0.53333333 | H7: =IF(E7/F7>1,"⛔ КОРПУС МАЛ",IF(E7/F7>0.8,"⚠ РЕЗЕРВ <20%","✅ OK")) -> ✅ OK
A8: ЩУ AFL Cargo (AFL MAST CONTROL PANEL) | B8: 1 | C8: =BOM!H86 -> 471852.82 | D8: =B8*C8 -> 471852.82 | E8: 48.6 | F8: 96 | G8: =E8/F8 -> 0.50625 | H8: =IF(E8/F8>1,"⛔ КОРПУС МАЛ",IF(E8/F8>0.8,"⚠ РЕЗЕРВ <20%","✅ OK")) -> ✅ OK
A9: SUB 19 AFL LV DB (VIP) | B9: 1 | C9: =BOM!H99 -> 249594.5 | D9: =B9*C9 -> 249594.5 | E9: 23.8 | F9: 96 | G9: =E9/F9 -> 0.24791667 | H9: =IF(E9/F9>1,"⛔ КОРПУС МАЛ",IF(E9/F9>0.8,"⚠ РЕЗЕРВ <20%","✅ OK")) -> ✅ OK
A10: ЩО PB-V1 (VIP) | B10: 1 | C10: =BOM!H111 -> 217693.87 | D10: =B10*C10 -> 217693.87 | E10: 25 | F10: 48 | G10: =E10/F10 -> 0.52083333 | H10: =IF(E10/F10>1,"⛔ КОРПУС МАЛ",IF(E10/F10>0.8,"⚠ РЕЗЕРВ <20%","✅ OK")) -> ✅ OK
A11: ЩО PB-V2 (VIP) | B11: 1 | C11: =BOM!H123 -> 198295.78 | D11: =B11*C11 -> 198295.78 | E11: 20.8 | F11: 48 | G11: =E11/F11 -> 0.43333333 | H11: =IF(E11/F11>1,"⛔ КОРПУС МАЛ",IF(E11/F11>0.8,"⚠ РЕЗЕРВ <20%","✅ OK")) -> ✅ OK
A12: ЩО PB-V3 (VIP) | B12: 1 | C12: =BOM!H135 -> 198295.78 | D12: =B12*C12 -> 198295.78 | E12: 20.8 | F12: 48 | G12: =E12/F12 -> 0.43333333 | H12: =IF(E12/F12>1,"⛔ КОРПУС МАЛ",IF(E12/F12>0.8,"⚠ РЕЗЕРВ <20%","✅ OK")) -> ✅ OK
A13: ЩА AFL INTERNAL DB (в мачте, VIP) | B13: 10 | C13: =BOM!H151 -> 125289.23 | D13: =B13*C13 -> 1252892.3 | E13: 19.5 | F13: 48 | G13: =E13/F13 -> 0.40625 | H13: =IF(E13/F13>1,"⛔ КОРПУС МАЛ",IF(E13/F13>0.8,"⚠ РЕЗЕРВ <20%","✅ OK")) -> ✅ OK
A14: ИТОГО | D14: =SUM(D5:D13) -> 6731239.3

Sheet Kurallar
A1: Almaty International Airport — Apron Floodlighting (De-icing / Cargo / VIP), BK3812 — KURAL VE PARAMETRE TABLOSU
A2: SARI hücreler düzenlenebilir. Değiştirince BOM ve СВОД otomatik güncellenir.
A4: Proje kodu | B4: 260817_ALA_Apron_Floodlighting
A5: Revizyon | B5: A
A6: Tarih | B6: 2026-08-17
A7: Sorumlu | B7: YSF HICH
A8: Müşteri | B8: Almaty International Airport / NACO
A10: PARAMETRELER
A11: ISCILIK_KZT_DK | B11: 100 | C11: KZT / dakika (işveren yükü dahil)
A12: TEST_ETIKET_KATS | B12: 1.15 | C12: Toplam işçilik dakikasına çarpan
A13: MONTAJ_MALZ_YUZDE | B13: 0.03 | C13: Pano malzeme ara toplamının yüzdesi
A14: KUTUP_EK_DK | B14: 2 | C14: OTO/DİF: her ek kutup için ek dakika
A16: İŞÇİLİK ZAMAN NORMLARI (dakika) — her pano için ayrı sütun
A17: TİP | B17: NORM_DK | C17: ЩАВР De-icing (AVR POWER PANEL) adet | D17: ЩАВР De-icing (AVR POWER PANEL) dk | E17: ЩУ AFL De-icing (AFL MAST CONTROL PANEL) adet | F17: ЩУ AFL De-icing (AFL MAST CONTROL PANEL) dk | G17: ЩАВР Cargo (AVR POWER PANEL) adet | H17: ЩАВР Cargo (AVR POWER PANEL) dk | I17: ЩУ AFL Cargo (AFL MAST CONTROL PANEL) adet | J17: ЩУ AFL Cargo (AFL MAST CONTROL PANEL) dk | K17: SUB 19 AFL LV DB (VIP) adet | L17: SUB 19 AFL LV DB (VIP) dk | M17: ЩО PB-V1 (VIP) adet | N17: ЩО PB-V1 (VIP) dk | O17: ЩО PB-V2 (VIP) adet | P17: ЩО PB-V2 (VIP) dk | Q17: ЩО PB-V3 (VIP) adet | R17: ЩО PB-V3 (VIP) dk | S17: ЩА AFL INTERNAL DB (в мачте, VIP) adet | T17: ЩА AFL INTERNAL DB (в мачте, VIP) dk | U17: AÇIKLAMA
A18: korpus | B18: 60 | C18: 1 | D18: =$B18*C18 -> 60 | E18: 1 | F18: =$B18*E18 -> 60 | G18: 1 | H18: =$B18*G18 -> 60 | I18: 1 | J18: =$B18*I18 -> 60 | K18: 1 | L18: =$B18*K18 -> 60 | M18: 1 | N18: =$B18*M18 -> 60 | O18: 1 | P18: =$B18*O18 -> 60 | Q18: 1 | R18: =$B18*Q18 -> 60 | S18: 1 | T18: =$B18*S18 -> 60 | U18: Korpus hazırlık, DIN ray, montaj plakası
A19: TMŞ | B19: 25 | C19: 5 | D19: =$B19*C19 -> 125 | E19: 1 | F19: =$B19*E19 -> 25 | G19: 5 | H19: =$B19*G19 -> 125 | I19: 1 | J19: =$B19*I19 -> 25 | K19: 1 | L19: =$B19*K19 -> 25 | M19: 0 | N19: =$B19*M19 -> 0 | O19: 0 | P19: =$B19*O19 -> 0 | Q19: 0 | R19: =$B19*Q19 -> 0 | S19: 0 | T19: =$B19*S19 -> 0 | U19: MCCB montaj + kablolama
A20: OTO | B20: 4 | C20: 6 | D20: =$B20*C20 -> 24 | E20: 7 | F20: =$B20*E20 -> 28 | G20: 2 | H20: =$B20*G20 -> 8 | I20: 7 | J20: =$B20*I20 -> 28 | K20: 3 | L20: =$B20*K20 -> 12 | M20: 5 | N20: =$B20*M20 -> 20 | O20: 4 | P20: =$B20*O20 -> 16 | Q20: 4 | R20: =$B20*Q20 -> 16 | S20: 3 | T20: =$B20*S20 -> 12 | U20: MCB 1P; her ek kutup için +2 dk (kutup katsayısı)
A21: DİF | B21: 6 | C21: 0 | D21: =$B21*C21 -> 0 | E21: 0 | F21: =$B21*E21 -> 0 | G21: 3 | H21: =$B21*G21 -> 18 | I21: 0 | J21: =$B21*I21 -> 0 | K21: 0 | L21: =$B21*K21 -> 0 | M21: 0 | N21: =$B21*M21 -> 0 | O21: 0 | P21: =$B21*O21 -> 0 | Q21: 0 | R21: =$B21*Q21 -> 0 | S21: 0 | T21: =$B21*S21 -> 0 | U21: RCBO / УЗО
A22: rubilnik | B22: 20 | C22: 1 | D22: =$B22*C22 -> 20 | E22: 0 | F22: =$B22*E22 -> 0 | G22: 1 | H22: =$B22*G22 -> 20 | I22: 0 | J22: =$B22*I22 -> 0 | K22: 0 | L22: =$B22*K22 -> 0 | M22: 0 | N22: =$B22*M22 -> 0 | O22: 0 | P22: =$B22*O22 -> 0 | Q22: 0 | R22: =$B22*Q22 -> 0 | S22: 1 | T22: =$B22*S22 -> 20 | U22: Yük ayırıcı
A23: fu | B23: 5 | C23: 0 | D23: =$B23*C23 -> 0 | E23: 0 | F23: =$B23*E23 -> 0 | G23: 0 | H23: =$B23*G23 -> 0 | I23: 0 | J23: =$B23*I23 -> 0 | K23: 0 | L23: =$B23*K23 -> 0 | M23: 0 | N23: =$B23*M23 -> 0 | O23: 0 | P23: =$B23*O23 -> 0 | Q23: 0 | R23: =$B23*Q23 -> 0 | S23: 0 | T23: =$B23*S23 -> 0 | U23: Sigorta + yuva
A24: kontaktör | B24: 12 | C24: 0 | D24: =$B24*C24 -> 0 | E24: 4 | F24: =$B24*E24 -> 48 | G24: 0 | H24: =$B24*G24 -> 0 | I24: 4 | J24: =$B24*I24 -> 48 | K24: 0 | L24: =$B24*K24 -> 0 | M24: 0 | N24: =$B24*M24 -> 0 | O24: 0 | P24: =$B24*O24 -> 0 | Q24: 0 | R24: =$B24*Q24 -> 0 | S24: 2 | T24: =$B24*S24 -> 24
A25: blok | B25: 3 | C25: 0 | D25: =$B25*C25 -> 0 | E25: 1 | F25: =$B25*E25 -> 3 | G25: 0 | H25: =$B25*G25 -> 0 | I25: 1 | J25: =$B25*I25 -> 3 | K25: 0 | L25: =$B25*K25 -> 0 | M25: 0 | N25: =$B25*M25 -> 0 | O25: 0 | P25: =$B25*O25 -> 0 | Q25: 0 | R25: =$B25*Q25 -> 0 | S25: 1 | T25: =$B25*S25 -> 3 | U25: Yardımcı kontak / interlok
A26: Röle | B26: 6 | C26: 0 | D26: =$B26*C26 -> 0 | E26: 2 | F26: =$B26*E26 -> 12 | G26: 0 | H26: =$B26*G26 -> 0 | I26: 2 | J26: =$B26*I26 -> 12 | K26: 0 | L26: =$B26*K26 -> 0 | M26: 0 | N26: =$B26*M26 -> 0 | O26: 0 | P26: =$B26*O26 -> 0 | Q26: 0 | R26: =$B26*Q26 -> 0 | S26: 1 | T26: =$B26*S26 -> 6
A27: Röle Altlığı | B27: 3 | C27: 0 | D27: =$B27*C27 -> 0 | E27: 1 | F27: =$B27*E27 -> 3 | G27: 0 | H27: =$B27*G27 -> 0 | I27: 1 | J27: =$B27*I27 -> 3 | K27: 0 | L27: =$B27*K27 -> 0 | M27: 0 | N27: =$B27*M27 -> 0 | O27: 0 | P27: =$B27*O27 -> 0 | Q27: 0 | R27: =$B27*Q27 -> 0 | S27: 0 | T27: =$B27*S27 -> 0
A28: İmpuls | B28: 6 | C28: 0 | D28: =$B28*C28 -> 0 | E28: 0 | F28: =$B28*E28 -> 0 | G28: 0 | H28: =$B28*G28 -> 0 | I28: 0 | J28: =$B28*I28 -> 0 | K28: 0 | L28: =$B28*K28 -> 0 | M28: 0 | N28: =$B28*M28 -> 0 | O28: 0 | P28: =$B28*O28 -> 0 | Q28: 0 | R28: =$B28*Q28 -> 0 | S28: 0 | T28: =$B28*S28 -> 0
A29: Sinyal Lambası | B29: 5 | C29: 0 | D29: =$B29*C29 -> 0 | E29: 1 | F29: =$B29*E29 -> 5 | G29: 0 | H29: =$B29*G29 -> 0 | I29: 1 | J29: =$B29*I29 -> 5 | K29: 0 | L29: =$B29*K29 -> 0 | M29: 0 | N29: =$B29*M29 -> 0 | O29: 0 | P29: =$B29*O29 -> 0 | Q29: 0 | R29: =$B29*Q29 -> 0 | S29: 1 | T29: =$B29*S29 -> 5
A30: lamb | B30: 5 | C30: 0 | D30: =$B30*C30 -> 0 | E30: 0 | F30: =$B30*E30 -> 0 | G30: 0 | H30: =$B30*G30 -> 0 | I30: 0 | J30: =$B30*I30 -> 0 | K30: 0 | L30: =$B30*K30 -> 0 | M30: 0 | N30: =$B30*M30 -> 0 | O30: 0 | P30: =$B30*O30 -> 0 | Q30: 0 | R30: =$B30*Q30 -> 0 | S30: 0 | T30: =$B30*S30 -> 0
A31: Klemens | B31: 1.5 | C31: 24 | D31: =$B31*C31 -> 36 | E31: 32 | F31: =$B31*E31 -> 48 | G31: 20 | H31: =$B31*G31 -> 30 | I31: 32 | J31: =$B31*I31 -> 48 | K31: 16 | L31: =$B31*K31 -> 24 | M31: 20 | N31: =$B31*M31 -> 30 | O31: 16 | P31: =$B31*O31 -> 24 | Q31: 16 | R31: =$B31*Q31 -> 24 | S31: 15 | T31: =$B31*S31 -> 22.5 | U31: Adet başına
A32: LOOBAR | B32: 8 | C32: 2 | D32: =$B32*C32 -> 16 | E32: 3 | F32: =$B32*E32 -> 24 | G32: 2 | H32: =$B32*G32 -> 16 | I32: 3 | J32: =$B32*I32 -> 24 | K32: 1 | L32: =$B32*K32 -> 8 | M32: 1 | N32: =$B32*M32 -> 8 | O32: 1 | P32: =$B32*O32 -> 8 | Q32: 1 | R32: =$B32*Q32 -> 8 | S32: 0 | T32: =$B32*S32 -> 0 | U32: HAZIR DIN barası (ШНИ/ШНК) montaj + bağlantı, adet başına. ⚠ İMALAT bara (kesim, delme, bükme, kalaylama) için bu norm YETERSİZ — 30-45 dk/adet ayrıca hesaplanmalı
A33: tt | B33: 10 | C33: 0 | D33: =$B33*C33 -> 0 | E33: 0 | F33: =$B33*E33 -> 0 | G33: 0 | H33: =$B33*G33 -> 0 | I33: 0 | J33: =$B33*I33 -> 0 | K33: 0 | L33: =$B33*K33 -> 0 | M33: 0 | N33: =$B33*M33 -> 0 | O33: 0 | P33: =$B33*O33 -> 0 | Q33: 0 | R33: =$B33*Q33 -> 0 | S33: 0 | T33: =$B33*S33 -> 0 | U33: Akım trafosu
A34: sayac | B34: 20 | C34: 0 | D34: =$B34*C34 -> 0 | E34: 0 | F34: =$B34*E34 -> 0 | G34: 0 | H34: =$B34*G34 -> 0 | I34: 0 | J34: =$B34*I34 -> 0 | K34: 0 | L34: =$B34*K34 -> 0 | M34: 0 | N34: =$B34*M34 -> 0 | O34: 0 | P34: =$B34*O34 -> 0 | Q34: 0 | R34: =$B34*Q34 -> 0 | S34: 0 | T34: =$B34*S34 -> 0 | U34: Sayaç montaj + bağlantı
A35: opn | B35: 8 | C35: 0 | D35: =$B35*C35 -> 0 | E35: 0 | F35: =$B35*E35 -> 0 | G35: 0 | H35: =$B35*G35 -> 0 | I35: 0 | J35: =$B35*I35 -> 0 | K35: 1 | L35: =$B35*K35 -> 8 | M35: 1 | N35: =$B35*M35 -> 8 | O35: 1 | P35: =$B35*O35 -> 8 | Q35: 1 | R35: =$B35*Q35 -> 8 | S35: 0 | T35: =$B35*S35 -> 0 | U35: Parafudr
A36: montajный материал | B36: 3 | C36: 16 | D36: =$B36*C36 -> 48 | E36: 10 | F36: =$B36*E36 -> 30 | G36: 12 | H36: =$B36*G36 -> 36 | I36: 10 | J36: =$B36*I36 -> 30 | K36: 6 | L36: =$B36*K36 -> 18 | M36: 6 | N36: =$B36*M36 -> 18 | O36: 6 | P36: =$B36*O36 -> 18 | Q36: 6 | R36: =$B36*Q36 -> 18 | S36: 4 | T36: =$B36*S36 -> 12 | U36: Kanal/DIN ray, metre başına
A38: TEST/ETİKET ÖNCESİ TOPLAM (dk) | D38: =SUM(D18:D36) -> 329 | F38: =SUM(F18:F36) -> 286 | H38: =SUM(H18:H36) -> 313 | J38: =SUM(J18:J36) -> 286 | L38: =SUM(L18:L36) -> 155 | N38: =SUM(N18:N36) -> 144 | P38: =SUM(P18:P36) -> 134 | R38: =SUM(R18:R36) -> 134 | T38: =SUM(T18:T36) -> 164.5
A39: TEST/ETİKET KATSAYILI (dk) | D39: =Kurallar!$D$38*Kurallar!$B$12 -> 378.35 | F39: =Kurallar!$F$38*Kurallar!$B$12 -> 328.9 | H39: =Kurallar!$H$38*Kurallar!$B$12 -> 359.95 | J39: =Kurallar!$J$38*Kurallar!$B$12 -> 328.9 | L39: =Kurallar!$L$38*Kurallar!$B$12 -> 178.25 | N39: =Kurallar!$N$38*Kurallar!$B$12 -> 165.6 | P39: =Kurallar!$P$38*Kurallar!$B$12 -> 154.1 | R39: =Kurallar!$R$38*Kurallar!$B$12 -> 154.1 | T39: =Kurallar!$T$38*Kurallar!$B$12 -> 189.175
A41: DÖVİZ KURLARI (BOM günü)
A42: EUR | B42: 536.55 | C42: EUR/KZT
A43: TL | B43: 13.5 | C43: TL/KZT
A44: KZT | B44: 1 | C44: baz — değiştirmeyin
A46: MARKA KATSAYILARI (net = liste × katsayı × kur)
...

Sheet FIYAT_KAYNAK
A1: Bu sayfa birleşik fiyat listesinden kopyalanmıştır. Elle değiştirmeyin.
A2: ANAHTAR | B2: MARKA | C2: ARTIKUL | D2: ACIKLAMA | E2: BIRIM | F2: LISTE | G2: PARA | H2: KATSAYI | I2: KUR | J2: NET_KZT | K2: KAYNAK
A3: KAZTEK|719-15923 | B3: KAZTEK | C3: 719-15923 | D3: Мет. Щит ВРУ (2000x800x600)+10 база (TS) | E3: ШТ | F3: 148675 | G3: KZT | H3: =IFERROR(INDEX(Kurallar!$B$48:$B$51,MATCH(B3,Kurallar!$A$48:$A$51,0)),"") -> 1 | I3: =IFERROR(INDEX(Kurallar!$B$42:$B$44,MATCH(G3,Kurallar!$A$42:$A$44,0)),"") -> 1 | J3: =IF(OR(F3="",H3="",H3=0,I3=""),"",F3*H3*I3) -> 148675 | K3: Kaztek 15.07.2026
A4: ABB|1SDA100385R1 | B4: ABB | C4: 1SDA100385R1 | D4: XT5N 400, TMA, In=400A, InN=100%, 4p 280…400 2000…4000 36 | E4: шт | F4: 1810 | G4: EUR | H4: =IFERROR(INDEX(Kurallar!$B$48:$B$51,MATCH(B4,Kurallar!$A$48:$A$51,0)),"") -> 0.405 | I4: =IFERROR(INDEX(Kurallar!$B$42:$B$44,MATCH(G4,Kurallar!$A$42:$A$44,0)),"") -> 536.55 | J4: =IF(OR(F4="",H4="",H4=0,I4=""),"",F4*H4*I4) -> 393317.98 | K4: ABB Kasım 2025
A5: ABB|1SCA022847R3250 | B5: ABB | C5: 1SCA022847R3250 | D5: 400A 4 kutup OTM400E4CM230C | E5: шт | F5: 3945 | G5: EUR | H5: =IFERROR(INDEX(Kurallar!$B$48:$B$51,MATCH(B5,Kurallar!$A$48:$A$51,0)),"") -> 0.405 | I5: =IFERROR(INDEX(Kurallar!$B$42:$B$44,MATCH(G5,Kurallar!$A$42:$A$44,0)),"") -> 536.55 | J5: =IF(OR(F5="",H5="",H5=0,I5=""),"",F5*H5*I5) -> 857259.35 | K5: ABB Kasım 2025
A6: ABB|1SDA067418R1 | B6: ABB | C6: 1SDA067418R1 | D6: XT1N 160, TMD, In=160A 112…160 1600 36 | E6: шт | F6: 317.9 | G6: EUR | H6: =IFERROR(INDEX(Kurallar!$B$48:$B$51,MATCH(B6,Kurallar!$A$48:$A$51,0)),"") -> 0.405 | I6: =IFERROR(INDEX(Kurallar!$B$42:$B$44,MATCH(G6,Kurallar!$A$42:$A$44,0)),"") -> 536.55 | J6: =IF(OR(F6="",H6="",H6=0,I6=""),"",F6*H6*I6) -> 69080.544 | K6: ABB Kasım 2025
A7: ABB|2CDS273001R0634 | B7: ABB | C7: 2CDS273001R0634 | D7: 63 1 S 203 M-C 63 | E7: шт | F7: 107.1 | G7: EUR | H7: =IFERROR(INDEX(Kurallar!$B$48:$B$51,MATCH(B7,Kurallar!$A$48:$A$51,0)),"") -> 0.405 | I7: =IFERROR(INDEX(Kurallar!$B$42:$B$44,MATCH(G7,Kurallar!$A$42:$A$44,0)),"") -> 536.55 | J7: =IF(OR(F7="",H7="",H7=0,I7=""),"",F7*H7*I7) -> 23273.125 | K7: ABB Kasım 2025
A8: ABB|1SDA067416R1 | B8: ABB | C8: 1SDA067416R1 | D8: XT1N 160, TMD, In=100A 70…100 1000 36 | E8: шт | F8: 246.1 | G8: EUR | H8: =IFERROR(INDEX(Kurallar!$B$48:$B$51,MATCH(B8,Kurallar!$A$48:$A$51,0)),"") -> 0.405 | I8: =IFERROR(INDEX(Kurallar!$B$42:$B$44,MATCH(G8,Kurallar!$A$42:$A$44,0)),"") -> 536.55 | J8: =IF(OR(F8="",H8="",H8=0,I8=""),"",F8*H8*I8) -> 53478.207 | K8: ABB Kasım 2025
A9: ABB|2CDS273001R0164 | B9: ABB | C9: 2CDS273001R0164 | D9: 16 1 S 203 M-C 16 | E9: шт | F9: 63.02 | G9: EUR | H9: =IFERROR(INDEX(Kurallar!$B$48:$B$51,MATCH(B9,Kurallar!$A$48:$A$51,0)),"") -> 0.405 | I9: =IFERROR(INDEX(Kurallar!$B$42:$B$44,MATCH(G9,Kurallar!$A$42:$A$44,0)),"") -> 536.55 | J9: =IF(OR(F9="",H9="",H9=0,I9=""),"",F9*H9*I9) -> 13694.419 | K9: ABB Kasım 2025
A10: ABB|2CDS273001R0404 | B10: ABB | C10: 2CDS273001R0404 | D10: 40 1 S 203 M-C 40 | E10: шт | F10: 81.89 | G10: EUR | H10: =IFERROR(INDEX(Kurallar!$B$48:$B$51,MATCH(B10,Kurallar!$A$48:$A$51,0)),"") -> 0.405 | I10: =IFERROR(INDEX(Kurallar!$B$42:$B$44,MATCH(G10,Kurallar!$A$42:$A$44,0)),"") -> 536.55 | J10: =IF(OR(F10="",H10="",H10=0,I10=""),"",F10*H10*I10) -> 17794.922 | K10: ABB Kasım 2025
A11: ABB|2CDS271001R0254 | B11: ABB | C11: 2CDS271001R0254 | D11: S201M-C16 25 10 S 201 M-C 25 | E11: шт | F11: 13.99 | G11: EUR | H11: =IFERROR(INDEX(Kurallar!$B$48:$B$51,MATCH(B11,Kurallar!$A$48:$A$51,0)),"") -> 0.405 | I11: =IFERROR(INDEX(Kurallar!$B$42:$B$44,MATCH(G11,Kurallar!$A$42:$A$44,0)),"") -> 536.55 | J11: =IF(OR(F11="",H11="",H11=0,I11=""),"",F11*H11*I11) -> 3040.0655 | K11: ABB Kasım 2025
A12: EKT|130200208_ | B12: EKT | C12: 130200208_ | D12: Шина медн.5х50х4000 | E12: шт | F12: 17515 | G12: KZT | H12: =IFERROR(INDEX(Kurallar!$B$48:$B$51,MATCH(B12,Kurallar!$A$48:$A$51,0)),"") -> 1 | I12: =IFERROR(INDEX(Kurallar!$B$42:$B$44,MATCH(G12,Kurallar!$A$42:$A$44,0)),"") -> 1 | J12: =IF(OR(F12="",H12="",H12=0,I12=""),"",F12*H12*I12) -> 17515 | K12: EKT 19.06.2025
A13: EKT|130301155_ | B13: EKT | C13: 130301155_ | D13: ЗНИ 10мм ² (70А) серый UNIT (50/1000) | E13: шт | F13: 151 | G13: KZT | H13: =IFERROR(INDEX(Kurallar!$B$48:$B$51,MATCH(B13,Kurallar!$A$48:$A$51,0)),"") -> 1 | I13: =IFERROR(INDEX(Kurallar!$B$42:$B$44,MATCH(G13,Kurallar!$A$42:$A$44,0)),"") -> 1 | J13: =IF(OR(F13="",H13="",H13=0,I13=""),"",F13*H13*I13) -> 151 | K13: EKT 19.06.2025
A14: CHINT|570003 | B14: CHINT | C14: 570003 | D14: DIN-рейка оцинкованная TH35-7.5 100cm | E14: шт | F14: 869 | G14: KZT | H14: =IFERROR(INDEX(Kurallar!$B$48:$B$51,MATCH(B14,Kurallar!$A$48:$A$51,0)),"") -> 0.6 | I14: =IFERROR(INDEX(Kurallar!$B$42:$B$44,MATCH(G14,Kurallar!$A$42:$A$44,0)),"") -> 1 | J14: =IF(OR(F14="",H14="",H14=0,I14=""),"",F14*H14*I14) -> 521.4 | K14: CHINT 13.06.2026
... A47: ABB|2CSM208151R1000 | B47: ABB | C47: 2CSM208151R1000 | D47: 24 saat (150 saat rezerv - 2 modül yatay kadran) 1A/K AD1CO-R-15m | E47: шт | F47: 90.62 | G47: EUR | H47: =IFERROR(INDEX(Kurallar!$B$48:$B$51,MATCH(B47,Kurallar!$A$48:$A$51,0)),"") -> 0.405 | I47: =IFERROR(INDEX(Kurallar!$B$42:$B$44,MATCH(G47,Kurallar!$A$42:$A$44,0)),"") -> 536.55 | J47: =IF(OR(F47="",H47="",H47=0,I47=""),"",F47*H47*I47) -> 19691.975 | K47: ABB Kasım 2025
