Workbook

Sheet BOM
A1: ROW | B1: Наименование1 | C1: Тип | D1: Артикул | E1: Номенклатура | F1: Цена (лист×1,35) | G1: Цена нетто KZT | H1: Сумма KZT | I1: Кол-во | J1: Ед.изм. | K1: Завод | L1: малз (сумма) | M1: мал группа | N1: srk euro | O1: oguzhan | P1: ЛИСТ (источник) | Q1: Валюта
A2: 1 | B2: =E2 -> ЩАВР De-icing (AVR POWER PANEL) | E2: ЩАВР De-icing (AVR POWER PANEL) | I2: 1 | J2: комплект
A3: 2 | C3: korpus | D3: 719-15923 | E3: Мет. Щит ВРУ (2000x800x600)+10 база (TS) | F3: =IFERROR(P3*INDEX(Kurallar!$B$21:$B$28,MATCH(K3,Kurallar!$A$21:$A$28,0)),"") -> 148675 | G3: =IFERROR(F3*INDEX(Kurallar!$C$21:$C$28,MATCH(K3,Kurallar!$A$21:$A$28,0))*INDEX(Kurallar!$B$15:$B$17,MATCH(Q3,Kurallar!$A$15:$A$17,0)),"") -> 148675 | H3: =IF(OR(G3="",I3=""),"",G3*I3) -> 148675 | I3: 1 | J3: шт | K3: KAZTEK | L3: =IF(H3="","",H3) -> 148675 | M3: Корпус | N3: =IF(H3="","",H3/Kurallar!$B$16) -> 277.0944 | P3: 148675 | Q3: KZT
A4: 3 | C4: TMŞ | D4: 1SDA100385R1 | E4: Выключатель автоматический XT5N 400 TMA In=400A InN=100% 4P, Icu 36кА | F4: =IFERROR(P4*INDEX(Kurallar!$B$21:$B$28,MATCH(K4,Kurallar!$A$21:$A$28,0)),"") -> 2443.5 | G4: =IFERROR(F4*INDEX(Kurallar!$C$21:$C$28,MATCH(K4,Kurallar!$A$21:$A$28,0))*INDEX(Kurallar!$B$15:$B$17,MATCH(Q4,Kurallar!$A$15:$A$17,0)),"") -> 393317.98 | H4: =IF(OR(G4="",I4=""),"",G4*I4) -> 786635.95 | I4: 2 | J4: шт | K4: ABB | L4: =IF(H4="","",H4) -> 786635.95 | M4: Аппараты защиты | N4: =IF(H4="","",H4/Kurallar!$B$16) -> 1466.1 | P4: 1810 | Q4: EUR
A5: 4 | C5: rubilnik | D5: 1SCA022847R3250 | E5: Переключатель нагрузки автоматический (АВР) OTM400E4CM230C 400А 4P | F5: =IFERROR(P5*INDEX(Kurallar!$B$21:$B$28,MATCH(K5,Kurallar!$A$21:$A$28,0)),"") -> 5325.75 | G5: =IFERROR(F5*INDEX(Kurallar!$C$21:$C$28,MATCH(K5,Kurallar!$A$21:$A$28,0))*INDEX(Kurallar!$B$15:$B$17,MATCH(Q5,Kurallar!$A$15:$A$17,0)),"") -> 857259.35 | H5: =IF(OR(G5="",I5=""),"",G5*I5) -> 857259.35 | I5: 1 | J5: шт | K5: ABB | L5: =IF(H5="","",H5) -> 857259.35 | M5: Аппараты защиты | N5: =IF(H5="","",H5/Kurallar!$B$16) -> 1597.725 | P5: 3945 | Q5: EUR
A6: 5 | C6: TMŞ | D6: 1SDA067418R1 | E6: Выключатель автоматический XT1N 160 TMD In=160A 3P, Icu 36кА — AFL Mast | F6: =IFERROR(P6*INDEX(Kurallar!$B$21:$B$28,MATCH(K6,Kurallar!$A$21:$A$28,0)),"") -> 429.165 | G6: =IFERROR(F6*INDEX(Kurallar!$C$21:$C$28,MATCH(K6,Kurallar!$A$21:$A$28,0))*INDEX(Kurallar!$B$15:$B$17,MATCH(Q6,Kurallar!$A$15:$A$17,0)),"") -> 69080.544 | H6: =IF(OR(G6="",I6=""),"",G6*I6) -> 69080.544 | I6: 1 | J6: шт | K6: ABB | L6: =IF(H6="","",H6) -> 69080.544 | M6: Аппараты защиты | N6: =IF(H6="","",H6/Kurallar!$B$16) -> 128.7495 | P6: 317.9 | Q6: EUR
A7: 6 | C7: OTO | D7: 2CDS273001R0634 | E7: Выключатель автоматический S203M-C63 3P 63А, 10кА, хар. C — Резерв | F7: =IFERROR(P7*INDEX(Kurallar!$B$21:$B$28,MATCH(K7,Kurallar!$A$21:$A$28,0)),"") -> 144.585 | G7: =IFERROR(F7*INDEX(Kurallar!$C$21:$C$28,MATCH(K7,Kurallar!$A$21:$A$28,0))*INDEX(Kurallar!$B$15:$B$17,MATCH(Q7,Kurallar!$A$15:$A$17,0)),"") -> 23273.125 | H7: =IF(OR(G7="",I7=""),"",G7*I7) -> 23273.125 | I7: 1 | J7: шт | K7: ABB | L7: =IF(H7="","",H7) -> 23273.125 | M7: Аппараты защиты | N7: =IF(H7="","",H7/Kurallar!$B$16) -> 43.3755 | P7: 107.1 | Q7: EUR
A8: 7 | C8: TMŞ | D8: 1SDA067416R1 | E8: Выключатель автоматический XT1N 160 TMD In=100A 3P, Icu 36кА — Резерв / Пункт управления | F8: =IFERROR(P8*INDEX(Kurallar!$B$21:$B$28,MATCH(K8,Kurallar!$A$21:$A$28,0)),"") -> 332.235 | G8: =IFERROR(F8*INDEX(Kurallar!$C$21:$C$28,MATCH(K8,Kurallar!$A$21:$A$28,0))*INDEX(Kurallar!$B$15:$B$17,MATCH(Q8,Kurallar!$A$15:$A$17,0)),"") -> 53478.207 | H8: =IF(OR(G8="",I8=""),"",G8*I8) -> 106956.41 | I8: 2 | J8: шт | K8: ABB | L8: =IF(H8="","",H8) -> 106956.41 | M8: Аппараты защиты | N8: =IF(H8="","",H8/Kurallar!$B$16) -> 199.341 | P8: 246.1 | Q8: EUR
A9: 8 | C9: OTO | D9: 2CDS273001R0164 | E9: Выключатель автоматический S203M-C16 3P 16А, 10кА, хар. C — Резервуар De-icing | F9: =IFERROR(P9*INDEX(Kurallar!$B$21:$B$28,MATCH(K9,Kurallar!$A$21:$A$28,0)),"") -> 85.077 | G9: =IFERROR(F9*INDEX(Kurallar!$C$21:$C$28,MATCH(K9,Kurallar!$A$21:$A$28,0))*INDEX(Kurallar!$B$15:$B$17,MATCH(Q9,Kurallar!$A$15:$A$17,0)),"") -> 13694.419 | H9: =IF(OR(G9="",I9=""),"",G9*I9) -> 13694.419 | I9: 1 | J9: шт | K9: ABB | L9: =IF(H9="","",H9) -> 13694.419 | M9: Аппараты защиты | N9: =IF(H9="","",H9/Kurallar!$B$16) -> 25.5231 | P9: 63.02 | Q9: EUR
A10: 9 | C10: OTO | D10: 2CDS273001R0404 | E10: Выключатель автоматический S203M-C40 3P 40А, 10кА, хар. C — Резерв | F10: =IFERROR(P10*INDEX(Kurallar!$B$21:$B$28,MATCH(K10,Kurallar!$A$21:$A$28,0)),"") -> 110.5515 | G10: =IFERROR(F10*INDEX(Kurallar!$C$21:$C$28,MATCH(K10,Kurallar!$A$21:$A$28,0))*INDEX(Kurallar!$B$15:$B$17,MATCH(Q10,Kurallar!$A$15:$A$17,0)),"") -> 17794.922 | H10: =IF(OR(G10="",I10=""),"",G10*I10) -> 17794.922 | I10: 1 | J10: шт | K10: ABB | L10: =IF(H10="","",H10) -> 17794.922 | M10: Аппараты защиты | N10: =IF(H10="","",H10/Kurallar!$B$16) -> 33.16545 | P10: 81.89 | Q10: EUR
A11: 10 | C11: OTO | D11: 2CDS271001R0254 | E11: Выключатель автоматический S201M-C25 1P 25А, 10кА, хар. C — Камера / Резерв ×2 | F11: =IFERROR(P11*INDEX(Kurallar!$B$21:$B$28,MATCH(K11,Kurallar!$A$21:$A$28,0)),"") -> 18.8865 | G11: =IFERROR(F11*INDEX(Kurallar!$C$21:$C$28,MATCH(K11,Kurallar!$A$21:$A$28,0))*INDEX(Kurallar!$B$15:$B$17,MATCH(Q11,Kurallar!$A$15:$A$17,0)),"") -> 3040.0655 | H11: =IF(OR(G11="",I11=""),"",G11*I11) -> 9120.1964 | I11: 3 | J11: шт | K11: ABB | L11: =IF(H11="","",H11) -> 9120.1964 | M11: Аппараты защиты | N11: =IF(H11="","",H11/Kurallar!$B$16) -> 16.99785 | P11: 13.99 | Q11: EUR
A12: 11 | C12: LOOBAR | D12: 130200208_ | E12: Шина медная 5х50х4000 мм (сборные шины 400А, L1/L2/L3/N) | F12: =IFERROR(P12*INDEX(Kurallar!$B$21:$B$28,MATCH(K12,Kurallar!$A$21:$A$28,0)),"") -> 17515 | G12: =IFERROR(F12*INDEX(Kurallar!$C$21:$C$28,MATCH(K12,Kurallar!$A$21:$A$28,0))*INDEX(Kurallar!$B$15:$B$17,MATCH(Q12,Kurallar!$A$15:$A$17,0)),"") -> 17515 | H12: =IF(OR(G12="",I12=""),"",G12*I12) -> 35030 | I12: 2 | J12: шт | K12: EKT | L12: =IF(H12="","",H12) -> 35030 | M12: Клеммы и шины | N12: =IF(H12="","",H12/Kurallar!$B$16) -> 65.287485 | P12: 17515 | Q12: KZT
A13: 12 | C13: Klemens | D13: 130301155_ | E13: Зажим наборный ЗНИ 10мм² (70А), серый | F13: =IFERROR(P13*INDEX(Kurallar!$B$21:$B$28,MATCH(K13,Kurallar!$A$21:$A$28,0)),"") -> 151 | G13: =IFERROR(F13*INDEX(Kurallar!$C$21:$C$28,MATCH(K13,Kurallar!$A$21:$A$28,0))*INDEX(Kurallar!$B$15:$B$17,MATCH(Q13,Kurallar!$A$15:$A$17,0)),"") -> 151 | H13: =IF(OR(G13="",I13=""),"",G13*I13) -> 3624 | I13: 24 | J13: шт | K13: EKT | L13: =IF(H13="","",H13) -> 3624 | M13: Клеммы и шины | N13: =IF(H13="","",H13/Kurallar!$B$16) -> 6.7542633 | P13: 151 | Q13: KZT
A14: 13 | C14: montajный материал | D14: 570003 | E14: DIN-рейка оцинкованная TH35-7.5, 1000 мм | F14: =IFERROR(P14*INDEX(Kurallar!$B$21:$B$28,MATCH(K14,Kurallar!$A$21:$A$28,0)),"") -> 869 | G14: =IFERROR(F14*INDEX(Kurallar!$C$21:$C$28,MATCH(K14,Kurallar!$A$21:$A$28,0))*INDEX(Kurallar!$B$15:$B$17,MATCH(Q14,Kurallar!$A$15:$A$17,0)),"") -> 521.4 | H14: =IF(OR(G14="",I14=""),"",G14*I14) -> 4171.2 | I14: 8 | J14: шт | K14: CHINT | L14: =IF(H14="","",H14) -> 4171.2 | M14: Монтаж | N14: =IF(H14="","",H14/Kurallar!$B$16) -> 7.7741124 | P14: 869 | Q14: KZT
A15: 14 | C15: montajный материал | D15: 270300105_ | E15: Кабель-канал перфорированный 40х60, ИМПАКТ | F15: =IFERROR(P15*INDEX(Kurallar!$B$21:$B$28,MATCH(K15,Kurallar!$A$21:$A$28,0)),"") -> 1808 | G15: =IFERROR(F15*INDEX(Kurallar!$C$21:$C$28,MATCH(K15,Kurallar!$A$21:$A$28,0))*INDEX(Kurallar!$B$15:$B$17,MATCH(Q15,Kurallar!$A$15:$A$17,0)),"") -> 1808 | H15: =IF(OR(G15="",I15=""),"",G15*I15) -> 14464 | I15: 8 | J15: шт | K15: EKT | L15: =IF(H15="","",H15) -> 14464 | M15: Монтаж | N15: =IF(H15="","",H15/Kurallar!$B$16) -> 26.957413 | P15: 1808 | Q15: KZT
A16: 15 | C16: montajный материал | E16: Монтажные материалы (крепёж, маркировка, наконечники) | G16: =SUM(H3:H15)*Kurallar!$B$34 -> 62693.374 | H16: =IF(G16="","",G16*I16) -> 62693.374 | I16: 1 | J16: компл. | K16: — | L16: =H16 -> 62693.374 | M16: Монтаж
A17: 16 | C17: montajная работа | E17: Сборка щита (норма времени — см. лист «Kurallar») | F17: =I17/60 -> 23.575 | G17: =Kurallar!$B$32 -> 100 | H17: =IF(G17="","",G17*I17) -> 141450 | I17: =Kurallar!$E$59 -> 1414.5 | J17: мин | K17: YSF | M17: Работа
B18: Toplam ЩАВР De-icing (AVR POWER PANEL) | H18: =SUBTOTAL(9,H3:H17) -> 2293922.5 | I18: 1 | J18: компл. | L18: =SUBTOTAL(9,L3:L16) -> 2152472.5 | N18: =IF(H18="","",H18/Kurallar!$B$16) -> 4275.3192
A19: 17 | C19: opn | D19: 2CTB812111R2300 | E19: ⚠ KONTROL — Ограничитель перенапряжения OVR T1-T2 3N 100-255 P TS (класс I+II) | I19: 1 | J19: шт | K19: ABB | M19: Аппараты защиты
A20: 18 | C20: sayac | E20: ⚠ KONTROL — Счётчик электроэнергии 3-фазный (тип по ТУ АО «Алматы Энергосбыт») | I20: 1 | J20: шт | M20: Учёт
A21: 19 | C21: tt | E21: ⚠ KONTROL — Трансформатор тока 400/5 (3 шт на счётчик) | I21: 3 | J21: шт | M21: Учёт
A22: 20 | B22: =E22 -> ЩУ AFL De-icing (AFL MAST CONTROL PANEL) | E22: ЩУ AFL De-icing (AFL MAST CONTROL PANEL) | I22: 1 | J22: комплект
A23: 21 | C23: korpus | D23: 719-15420 | E23: Мет.Корпус ЩМП-4 (800x650x250) IP54 | F23: =IFERROR(P23*INDEX(Kurallar!$B$21:$B$28,MATCH(K23,Kurallar!$A$21:$A$28,0)),"") -> 30540 | G23: =IFERROR(F23*INDEX(Kurallar!$C$21:$C$28,MATCH(K23,Kurallar!$A$21:$A$28,0))*INDEX(Kurallar!$B$15:$B$17,MATCH(Q23,Kurallar!$A$15:$A$17,0)),"") -> 30540 | H23: =IF(OR(G23="",I23=""),"",G23*I23) -> 30540 | I23: 1 | J23: шт | K23: KAZTEK | L23: =IF(H23="","",H23) -> 30540 | M23: Корпус | N23: =IF(H23="","",H23/Kurallar!$B$16) -> 56.919206 | P23: 30540 | Q23: KZT
A24: 22 | C24: TMŞ | D24: 1SDA067415R1 | E24: Выключатель автоматический XT1N 160 TMD In=80A 3P, Icu 36кА — ввод от ЩАВР | F24: =IFERROR(P24*INDEX(Kurallar!$B$21:$B$28,MATCH(K24,Kurallar!$A$21:$A$28,0)),"") -> 332.235 | G24: =IFERROR(F24*INDEX(Kurallar!$C$21:$C$28,MATCH(K24,Kurallar!$A$21:$A$28,0))*INDEX(Kurallar!$B$15:$B$17,MATCH(Q24,Kurallar!$A$15:$A$17,0)),"") -> 53478.207 | H24: =IF(OR(G24="",I24=""),"",G24*I24) -> 53478.207 | I24: 1 | J24: шт | K24: ABB | L24: =IF(H24="","",H24) -> 53478.207 | M24: Аппараты защиты | N24: =IF(H24="","",H24/Kurallar!$B$16) -> 99.6705 | P24: 246.1 | Q24: EUR
A25: 23 | C25: OTO | D25: 2CDS251001R0065 | E25: Выключатель автоматический S201-B6 1P 6А, 6кА, хар. B — цепи управления | F25: =IFERROR(P25*INDEX(Kurallar!$B$21:$B$28,MATCH(K25,Kurallar!$A$21:$A$28,0)),"") -> 15.849 | G25: =IFERROR(F25*INDEX(Kurallar!$C$21:$C$28,MATCH(K25,Kurallar!$A$21:$A$28,0))*INDEX(Kurallar!$B$15:$B$17,MATCH(Q25,Kurallar!$A$15:$A$17,0)),"") -> 2551.1343 | H25: =IF(OR(G25="",I25=""),"",G25*I25) -> 2551.1343 | I25: 1 | J25: шт | K25: ABB | L25: =IF(H25="","",H25) -> 2551.1343 | M25: Аппараты защиты | N25: =IF(H25="","",H25/Kurallar!$B$16) -> 4.7547 | P25: 11.74 | Q25: EUR
A26: 24 | C26: OTO | D26: 2CDS273001R0634 | E26: Выключатель автоматический S203M-C63 3P 63А, 10кА, хар. C — AFL LIGHTs (K1…K4) | F26: =IFERROR(P26*INDEX(Kurallar!$B$21:$B$28,MATCH(K26,Kurallar!$A$21:$A$28,0)),"") -> 144.585 | G26: =IFERROR(F26*INDEX(Kurallar!$C$21:$C$28,MATCH(K26,Kurallar!$A$21:$A$28,0))*INDEX(Kurallar!$B$15:$B$17,MATCH(Q26,Kurallar!$A$15:$A$17,0)),"") -> 23273.125 | H26: =IF(OR(G26="",I26=""),"",G26*I26) -> 93092.498 | I26: 4 | J26: шт | K26: ABB | L26: =IF(H26="","",H26) -> 93092.498 | M26: Аппараты защиты | N26: =IF(H26="","",H26/Kurallar!$B$16) -> 173.502 | P26: 107.1 | Q26: EUR
A27: 25 | C27: OTO | D27: 2CDS273001R0324 | E27: Выключатель автоматический S203M-C32 3P 32А, 10кА, хар. C — Резерв | F27: =IFERROR(P27*INDEX(Kurallar!$B$21:$B$28,MATCH(K27,Kurallar!$A$21:$A$28,0)),"") -> 106.3125 | G27: =IFERROR(F27*INDEX(Kurallar!$C$21:$C$28,MATCH(K27,Kurallar!$A$21:$A$28,0))*INDEX(Kurallar!$B$15:$B$17,MATCH(Q27,Kurallar!$A$15:$A$17,0)),"") -> 17112.592 | H27: =IF(OR(G27="",I27=""),"",G27*I27) -> 17112.592 | I27: 1 | J27: шт | K27: ABB | L27: =IF(H27="","",H27) -> 17112.592 | M27: Аппараты защиты | N27: =IF(H27="","",H27/Kurallar!$B$16) -> 31.89375 | P27: 78.75 | Q27: EUR
A28: 26 | C28: OTO | D28: 2CDS271001R0164 | E28: Выключатель автоматический S201M-C16 1P 16А, 10кА, хар. C — Резерв | F28: =IFERROR(P28*INDEX(Kurallar!$B$21:$B$28,MATCH(K28,Kurallar!$A$21:$A$28,0)),"") -> 18.8865 | G28: =IFERROR(F28*INDEX(Kurallar!$C$21:$C$28,MATCH(K28,Kurallar!$A$21:$A$28,0))*INDEX(Kurallar!$B$15:$B$17,MATCH(Q28,Kurallar!$A$15:$A$17,0)),"") -> 3040.0655 | H28: =IF(OR(G28="",I28=""),"",G28*I28) -> 3040.0655 | I28: 1 | J28: шт | K28: ABB | L28: =IF(H28="","",H28) -> 3040.0655 | M28: Аппараты защиты | N28: =IF(H28="","",H28/Kurallar!$B$16) -> 5.66595 | P28: 13.99 | Q28: EUR
A29: 27 | C29: kontaktör | D29: 1SAE351111R0640 | E29: Контактор модульный ESB63-40N 63А 4НО, катушка 230В AC/DC | F29: =IFERROR(P29*INDEX(Kurallar!$B$21:$B$28,MATCH(K29,Kurallar!$A$21:$A$28,0)),"") -> 247.455 | G29: =IFERROR(F29*INDEX(Kurallar!$C$21:$C$28,MATCH(K29,Kurallar!$A$21:$A$28,0))*INDEX(Kurallar!$B$15:$B$17,MATCH(Q29,Kurallar!$A$15:$A$17,0)),"") -> 39831.594 | H29: =IF(OR(G29="",I29=""),"",G29*I29) -> 159326.38 | I29: 4 | J29: шт | K29: ABB | L29: =IF(H29="","",H29) -> 159326.38 | M29: Управление | N29: =IF(H29="","",H29/Kurallar!$B$16) -> 296.946 | P29: 183.3 | Q29: EUR
A30: 28 | C30: Röle | D30: 2CSM208141R1000 | E30: Таймер недельный AW1CO-R-120m, 7 сут, резерв 150 ч, 1 перекл. контакт | F30: =IFERROR(P30*INDEX(Kurallar!$B$21:$B$28,MATCH(K30,Kurallar!$A$21:$A$28,0)),"") -> 194.94 | G30: =IFERROR(F30*INDEX(Kurallar!$C$21:$C$28,MATCH(K30,Kurallar!$A$21:$A$28,0))*INDEX(Kurallar!$B$15:$B$17,MATCH(Q30,Kurallar!$A$15:$A$17,0)),"") -> 31378.517 | H30: =IF(OR(G30="",I30=""),"",G30*I30) -> 31378.517 | I30: 1 | J30: шт | K30: ABB | L30: =IF(H30="","",H30) -> 31378.517 | M30: Управление | N30: =IF(H30="","",H30/Kurallar!$B$16) -> 58.482 | P30: 144.4 | Q30: EUR
A31: 29 | C31: Röle | D31: 1SVR405613R3000 | E31: Реле промежуточное CR-M230AC4, 4 перекл. контакта, 230В AC | F31: =IFERROR(P31*INDEX(Kurallar!$B$21:$B$28,MATCH(K31,Kurallar!$A$21:$A$28,0)),"") -> 17.3205 | G31: =IFERROR(F31*INDEX(Kurallar!$C$21:$C$28,MATCH(K31,Kurallar!$A$21:$A$28,0))*INDEX(Kurallar!$B$15:$B$17,MATCH(Q31,Kurallar!$A$15:$A$17,0)),"") -> 2787.9943 | H31: =IF(OR(G31="",I31=""),"",G31*I31) -> 2787.9943 | I31: 1 | J31: шт | K31: ABB | L31: =IF(H31="","",H31) -> 2787.9943 | M31: Управление | N31: =IF(H31="","",H31/Kurallar!$B$16) -> 5.19615 | P31: 12.83 | Q31: EUR
A32: 30 | C32: Röle Altlığı | D32: 1SVR405651R3000 | E32: Колодка для реле CR-M4SS, 4 перекл., винтовая | F32: =IFERROR(P32*INDEX(Kurallar!$B$21:$B$28,MATCH(K32,Kurallar!$A$21:$A$28,0)),"") -> 11.475 | G32: =IFERROR(F32*INDEX(Kurallar!$C$21:$C$28,MATCH(K32,Kurallar!$A$21:$A$28,0))*INDEX(Kurallar!$B$15:$B$17,MATCH(Q32,Kurallar!$A$15:$A$17,0)),"") -> 1847.0734 | H32: =IF(OR(G32="",I32=""),"",G32*I32) -> 1847.0734 | I32: 1 | J32: шт | K32: ABB | L32: =IF(H32="","",H32) -> 1847.0734 | M32: Управление | N32: =IF(H32="","",H32/Kurallar!$B$16) -> 3.4425 | P32: 8.5 | Q32: EUR
A33: 31 | C33: blok | D33: 1SFA619210R1026 | E33: Переключатель 3-позиционный C3SS1-10B-20, 2НО (АВТО-ОТКЛ-РУЧН) | F33: =IFERROR(P33*INDEX(Kurallar!$B$21:$B$28,MATCH(K33,Kurallar!$A$21:$A$28,0)),"") -> 17.7255 | G33: =IFERROR(F33*INDEX(Kurallar!$C$21:$C$28,MATCH(K33,Kurallar!$A$21:$A$28,0))*INDEX(Kurallar!$B$15:$B$17,MATCH(Q33,Kurallar!$A$15:$A$17,0)),"") -> 2853.1851 | H33: =IF(OR(G33="",I33=""),"",G33*I33) -> 2853.1851 | I33: 1 | J33: шт | K33: ABB | L33: =IF(H33="","",H33) -> 2853.1851 | M33: Управление | N33: =IF(H33="","",H33/Kurallar!$B$16) -> 5.31765 | P33: 13.13 | Q33: EUR
A34: 32 | C34: Sinyal Lambası | D34: 1SFA619403R5232 | E34: Лампа сигнальная CL2-523G, LED 230В AC, зелёная («FLTs ON») | F34: =IFERROR(P34*INDEX(Kurallar!$B$21:$B$28,MATCH(K34,Kurallar!$A$21:$A$28,0)),"") -> 12.987 | G34: =IFERROR(F34*INDEX(Kurallar!$C$21:$C$28,MATCH(K34,Kurallar!$A$21:$A$28,0))*INDEX(Kurallar!$B$15:$B$17,MATCH(Q34,Kurallar!$A$15:$A$17,0)),"") -> 2090.4525 | H34: =IF(OR(G34="",I34=""),"",G34*I34) -> 2090.4525 | I34: 1 | J34: шт | K34: ABB | L34: =IF(H34="","",H34) -> 2090.4525 | M34: Управление | N34: =IF(H34="","",H34/Kurallar!$B$16) -> 3.8961 | P34: 9.62 | Q34: EUR
... A41: 39 | C41: montajный материал | D41: 270300079_ | E41: Кабель-канал перфорированный 25х40, ИМПАКТ | F41: =IFERROR(P41*INDEX(Kurallar!$B$21:$B$28,MATCH(K41,Kurallar!$A$21:$A$28,0)),"") -> 1094 | G41: =IFERROR(F41*INDEX(Kurallar!$C$21:$C$28,MATCH(K41,Kurallar!$A$21:$A$28,0))*INDEX(Kurallar!$B$15:$B$17,MATCH(Q41,Kurallar!$A$15:$A$17,0)),"") -> 1094 | H41: =IF(OR(G41="",I41=""),"",G41*I41) -> 5470 | I41: 5 | J41: шт | K41: EKT | L41: =IF(H41="","",H41) -> 5470 | M41: Монтаж | N41: =IF(H41="","",H41/Kurallar!$B$16) -> 10.194763 | P41: 1094 | Q41: KZT
A42: 40 | C42: montajный материал | E42: Монтажные материалы (крепёж, маркировка, наконечники) | G42: =SUM(H23:H41)*Kurallar!$B$34 -> 12785.325 | H42: =IF(G42="","",G42*I42) -> 12785.325 | I42: 1 | J42: компл. | K42: — | L42: =H42 -> 12785.325 | M42: Монтаж
A43: 41 | C43: montajная работа | E43: Сборка щита (норма времени — см. лист «Kurallar») | F43: =I43/60 -> 13.876667 | G43: =Kurallar!$B$32 -> 100 | H43: =IF(G43="","",G43*I43) -> 83260 | I43: =Kurallar!$G$59 -> 832.6 | J43: мин | K43: YSF | M43: Работа
B44: Toplam ЩУ AFL De-icing (AFL MAST CONTROL PANEL) | H44: =SUBTOTAL(9,H23:H43) -> 522222.82 | I44: 1 | J44: компл. | L44: =SUBTOTAL(9,L23:L42) -> 438962.82 | N44: =IF(H44="","",H44/Kurallar!$B$16) -> 973.29759
A45: 42 | C45: blok | E45: ⚠ KONTROL — Фотореле (сумеречный выключатель) с выносным датчиком, 230В AC | I45: 1 | J45: шт | M45: Управление
A46: 43 | B46: =E46 -> ЩАВР Cargo (AVR POWER PANEL) | E46: ЩАВР Cargo (AVR POWER PANEL) | I46: 1 | J46: комплект
...

Sheet СВОД
A1: Almaty International Airport — Apron Floodlighting (De-icing / Cargo / VIP), BK3812 — СВОДНАЯ ВЕДОМОСТЬ
A2: Rev. A · 2026-08-17 · EUR/KZT см. лист «Kurallar»
A4: Щит | B4: Кол-во компл. | C4: Цена за 1 компл. KZT | D4: Сумма KZT | E4: Сумма EUR | F4: Модули исп. | G4: Модули всего | H4: Заполнение | I4: Статус
A5: ЩАВР De-icing (AVR POWER PANEL) | B5: 1 | C5: =BOM!H18 -> 2293922.5 | D5: =B5*C5 -> 2293922.5 | E5: =D5/Kurallar!$B$16 -> 4275.3192 | F5: 93.2 | G5: 200 | H5: =F5/G5 -> 0.466 | I5: =IF(F5/G5>1,"⛔ КОРПУС МАЛ",IF(F5/G5>0.8,"⚠ РЕЗЕРВ <20%","✅ OK")) -> ✅ OK
A6: ЩУ AFL De-icing (AFL MAST CONTROL PANEL) | B6: 1 | C6: =BOM!H44 -> 522222.82 | D6: =B6*C6 -> 522222.82 | E6: =D6/Kurallar!$B$16 -> 973.29759 | F6: 48.6 | G6: 96 | H6: =F6/G6 -> 0.50625 | I6: =IF(F6/G6>1,"⛔ КОРПУС МАЛ",IF(F6/G6>0.8,"⚠ РЕЗЕРВ <20%","✅ OK")) -> ✅ OK
A7: ЩАВР Cargo (AVR POWER PANEL) | B7: 1 | C7: =BOM!H62 -> 1573028.9 | D7: =B7*C7 -> 1573028.9 | E7: =D7/Kurallar!$B$16 -> 2931.747 | F7: 80 | G7: 150 | H7: =F7/G7 -> 0.53333333 | I7: =IF(F7/G7>1,"⛔ КОРПУС МАЛ",IF(F7/G7>0.8,"⚠ РЕЗЕРВ <20%","✅ OK")) -> ✅ OK
A8: ЩУ AFL Cargo (AFL MAST CONTROL PANEL) | B8: 1 | C8: =BOM!H86 -> 522222.82 | D8: =B8*C8 -> 522222.82 | E8: =D8/Kurallar!$B$16 -> 973.29759 | F8: 48.6 | G8: 96 | H8: =F8/G8 -> 0.50625 | I8: =IF(F8/G8>1,"⛔ КОРПУС МАЛ",IF(F8/G8>0.8,"⚠ РЕЗЕРВ <20%","✅ OK")) -> ✅ OK
A9: SUB 19 AFL LV DB (VIP) | B9: 1 | C9: =BOM!H99 -> 265464.5 | D9: =B9*C9 -> 265464.5 | E9: =D9/Kurallar!$B$16 -> 494.76191 | F9: 23.8 | G9: 96 | H9: =F9/G9 -> 0.24791667 | I9: =IF(F9/G9>1,"⛔ КОРПУС МАЛ",IF(F9/G9>0.8,"⚠ РЕЗЕРВ <20%","✅ OK")) -> ✅ OK
A10: ЩО PB-V1 (VIP) | B10: 1 | C10: =BOM!H111 -> 232183.87 | D10: =B10*C10 -> 232183.87 | E10: =D10/Kurallar!$B$16 -> 432.73483 | F10: 25 | G10: 48 | H10: =F10/G10 -> 0.52083333 | I10: =IF(F10/G10>1,"⛔ КОРПУС МАЛ",IF(F10/G10>0.8,"⚠ РЕЗЕРВ <20%","✅ OK")) -> ✅ OK
A11: ЩО PB-V2 (VIP) | B11: 1 | C11: =BOM!H123 -> 210025.78 | D11: =B11*C11 -> 210025.78 | E11: =D11/Kurallar!$B$16 -> 391.43748 | F11: 20.8 | G11: 48 | H11: =F11/G11 -> 0.43333333 | I11: =IF(F11/G11>1,"⛔ КОРПУС МАЛ",IF(F11/G11>0.8,"⚠ РЕЗЕРВ <20%","✅ OK")) -> ✅ OK
A12: ЩО PB-V3 (VIP) | B12: 1 | C12: =BOM!H135 -> 210025.78 | D12: =B12*C12 -> 210025.78 | E12: =D12/Kurallar!$B$16 -> 391.43748 | F12: 20.8 | G12: 48 | H12: =F12/G12 -> 0.43333333 | I12: =IF(F12/G12>1,"⛔ КОРПУС МАЛ",IF(F12/G12>0.8,"⚠ РЕЗЕРВ <20%","✅ OK")) -> ✅ OK
A13: ЩА AFL INTERNAL DB (в мачте, VIP) | B13: 10 | C13: =BOM!H151 -> 136156.73 | D13: =B13*C13 -> 1361567.3 | E13: =D13/Kurallar!$B$16 -> 2537.6336 | F13: 19.5 | G13: 48 | H13: =F13/G13 -> 0.40625 | I13: =IF(F13/G13>1,"⛔ КОРПУС МАЛ",IF(F13/G13>0.8,"⚠ РЕЗЕРВ <20%","✅ OK")) -> ✅ OK
A14: ИТОГО | D14: =SUM(D5:D13) -> 7190664.3 | E14: =D14/Kurallar!$B$16 -> 13401.667
A16: Контрольная связка: СВОД!D14 = BOM!H153 | D16: =IF(ROUND(D14,0)=ROUND(BOM!H153,0),"✅ СХОДИТСЯ","⛔ РАСХОЖДЕНИЕ") -> ✅ СХОДИТСЯ

Sheet Kurallar
A1: Almaty International Airport — Apron Floodlighting (De-icing / Cargo / VIP), BK3812 — KURALLAR, KATSAYILAR VE NORMLAR
A3: Sarı hücreler DÜZENLENEBİLİR. Değiştirildiğinde tüm BOM otomatik güncellenir.
A5: PROJE BİLGİLERİ
A6: Proje kodu | B6: 260817_ALA_Apron_Floodlighting
A7: Proje adı | B7: Almaty International Airport — Apron Floodlighting (De-icing / Cargo / VIP), BK3812
A8: Müşteri | B8: Almaty International Airport / NACO
A9: Revizyon | B9: A
A10: Tarih | B10: 2026-08-17
A11: Sorumlu | B11: YSF HICH
A13: DÖVİZ KURLARI (KZT karşılığı)
A14: PARA | B14: KUR | C14: AÇIKLAMA
A15: KZT | B15: 1 | C15: baz — değiştirmeyin
A16: EUR | B16: 536.55 | C16: EUR/KZT — BOM günü kuru
A17: TL | B17: 13.5 | C17: TL/KZT — BOM günü kuru
A19: MARKA KATSAYILARI (F = ЛИСТ × liste çarpanı · G = F × net katsayı × kur)
A20: ЗАВОД | B20: LİSTE ÇARPANI | C20: NET KATSAYI | D20: AÇIKLAMA
A21: ABB | B21: 1.35 | C21: 0.3 | D21: liste(EUR) × 1,35 → sonra × 0,30 (%70 iskonto — "diğer tüm gruplar")
A22: CHINT | B22: 1 | C22: 0.6 | D22: %40 iskonto
A23: CNC | B23: 1 | C23: 0.55 | D23: %45 iskonto
A24: EKT | B24: 1 | C24: 1 | D24: net fiyat
A25: KAZTEK | B25: 1 | C25: 1 | D25: net fiyat — korpus
A26: SAYMAN | B26: 1 | C26: 1 | D26: net fiyat
A27: SCHNEIDER | B27: 1 | C27: 0.6 | D27: proje bazında teyit edilmeli
A28: LEGRAND | B28: 1 | C28: 0.5 | D28: ⚠ TEYİT EDİLMEDİ — teklifte kullanmadan önce onaylat
A29: ABB — ayar sahalı / açık tip | B29: 1.35 | C29: 0.23 | D29: ⚠ %77 iskonto. AYRI KADEMEDİR — "ABB" satırıyla birleştirilmez. Bu BOM'da bu gruptan ürün YOKTUR; ACB/ayar sahalı şalter eklenirse ilgili satırın ЗАВОД hücresi bu satır adıyla değiştirilmelidir.
A31: İŞÇİLİK VE MONTAJ PARAMETRELERİ
A32: ISCILIK_KZT_DK | B32: 100 | C32: KZT / dakika (işveren yükü dahil)
A33: UPLIFT | B33: 1.15 | C33: Test, etiketleme, muayene katsayısı (güç panosu)
A34: MONTAJ_MALZ_YUZDE | B34: 0.03 | C34: Montaj malzemesi = pano malzeme tutarı × bu oran
A36: İŞÇİLİK ZAMAN NORMLARI (dakika) — pano bazında adet ve süre
A37: NORM | B37: NORM_DK | C37: AÇIKLAMA | D37: ЩАВР De-icing (AVR POWER | E37: дк | F37: ЩУ AFL De-icing (AFL MAS | G37: дк | H37: ЩАВР Cargo (AVR POWER PA | I37: дк | J37: ЩУ AFL Cargo (AFL MAST C | K37: дк | L37: SUB 19 AFL LV DB (VIP) | M37: дк | N37: ЩО PB-V1 (VIP) | O37: дк | P37: ЩО PB-V2 (VIP) | Q37: дк | R37: ЩО PB-V3 (VIP) | S37: дк | T37: ЩА AFL INTERNAL DB (в ма | U37: дк
A38: KORPUS_KUCUK | B38: 30 | C38: Korpus hazırlık — küçük (≤500x400) | D38: 0 | E38: =$B38*D38 -> 0 | F38: 0 | G38: =$B38*F38 -> 0 | H38: 0 | I38: =$B38*H38 -> 0 | J38: 0 | K38: =$B38*J38 -> 0 | L38: 0 | M38: =$B38*L38 -> 0 | N38: 1 | O38: =$B38*N38 -> 30 | P38: 1 | Q38: =$B38*P38 -> 30 | R38: 1 | S38: =$B38*R38 -> 30 | T38: 1 | U38: =$B38*T38 -> 30
A39: KORPUS_ORTA | B39: 45 | C39: Korpus hazırlık — orta (≤1000x700) | D39: 0 | E39: =$B39*D39 -> 0 | F39: 1 | G39: =$B39*F39 -> 45 | H39: 0 | I39: =$B39*H39 -> 0 | J39: 1 | K39: =$B39*J39 -> 45 | L39: 1 | M39: =$B39*L39 -> 45 | N39: 0 | O39: =$B39*N39 -> 0 | P39: 0 | Q39: =$B39*P39 -> 0 | R39: 0 | S39: =$B39*R39 -> 0 | T39: 0 | U39: =$B39*T39 -> 0
A40: KORPUS_ZEMIN | B40: 90 | C40: Korpus hazırlık — zemine oturan / ВРУ | D40: 1 | E40: =$B40*D40 -> 90 | F40: 0 | G40: =$B40*F40 -> 0 | H40: 1 | I40: =$B40*H40 -> 90 | J40: 0 | K40: =$B40*J40 -> 0 | L40: 0 | M40: =$B40*L40 -> 0 | N40: 0 | O40: =$B40*N40 -> 0 | P40: 0 | Q40: =$B40*P40 -> 0 | R40: 0 | S40: =$B40*R40 -> 0 | T40: 0 | U40: =$B40*T40 -> 0
A41: OTO_1P | B41: 10 | C41: Otomat 1P (МСВ 1P) | D41: 3 | E41: =$B41*D41 -> 30 | F41: 2 | G41: =$B41*F41 -> 20 | H41: 0 | I41: =$B41*H41 -> 0 | J41: 2 | K41: =$B41*J41 -> 20 | L41: 0 | M41: =$B41*L41 -> 0 | N41: 0 | O41: =$B41*N41 -> 0 | P41: 0 | Q41: =$B41*P41 -> 0 | R41: 0 | S41: =$B41*R41 -> 0 | T41: 2 | U41: =$B41*T41 -> 20
A42: OTO_3P | B42: 18 | C42: Otomat 3P/4P (МСВ 3P) | D42: 3 | E42: =$B42*D42 -> 54 | F42: 5 | G42: =$B42*F42 -> 90 | H42: 2 | I42: =$B42*H42 -> 36 | J42: 5 | K42: =$B42*J42 -> 90 | L42: 3 | M42: =$B42*L42 -> 54 | N42: 5 | O42: =$B42*N42 -> 90 | P42: 4 | Q42: =$B42*P42 -> 72 | R42: 4 | S42: =$B42*R42 -> 72 | T42: 1 | U42: =$B42*T42 -> 18
A43: DIF | B43: 14 | C43: АВДТ / RCBO 1P+N | D43: 0 | E43: =$B43*D43 -> 0 | F43: 0 | G43: =$B43*F43 -> 0 | H43: 3 | I43: =$B43*H43 -> 42 | J43: 0 | K43: =$B43*J43 -> 0 | L43: 0 | M43: =$B43*L43 -> 0 | N43: 0 | O43: =$B43*N43 -> 0 | P43: 0 | Q43: =$B43*P43 -> 0 | R43: 0 | S43: =$B43*R43 -> 0 | T43: 0 | U43: =$B43*T43 -> 0
A44: TMS_250 | B44: 60 | C44: Компакт автомат (MCCB) ≤250A | D44: 3 | E44: =$B44*D44 -> 180 | F44: 1 | G44: =$B44*F44 -> 60 | H44: 5 | I44: =$B44*H44 -> 300 | J44: 1 | K44: =$B44*J44 -> 60 | L44: 1 | M44: =$B44*L44 -> 60 | N44: 0 | O44: =$B44*N44 -> 0 | P44: 0 | Q44: =$B44*P44 -> 0 | R44: 0 | S44: =$B44*R44 -> 0 | T44: 0 | U44: =$B44*T44 -> 0
A45: TMS_630 | B45: 90 | C45: Компакт автомат (MCCB) 315–630A | D45: 2 | E45: =$B45*D45 -> 180 | F45: 0 | G45: =$B45*F45 -> 0 | H45: 0 | I45: =$B45*H45 -> 0 | J45: 0 | K45: =$B45*J45 -> 0 | L45: 0 | M45: =$B45*L45 -> 0 | N45: 0 | O45: =$B45*N45 -> 0 | P45: 0 | Q45: =$B45*P45 -> 0 | R45: 0 | S45: =$B45*R45 -> 0 | T45: 0 | U45: =$B45*T45 -> 0
A46: RUBILNIK | B46: 45 | C46: Выключатель нагрузки (рубильник) | D46: 0 | E46: =$B46*D46 -> 0 | F46: 0 | G46: =$B46*F46 -> 0 | H46: 0 | I46: =$B46*H46 -> 0 | J46: 0 | K46: =$B46*J46 -> 0 | L46: 0 | M46: =$B46*L46 -> 0 | N46: 0 | O46: =$B46*N46 -> 0 | P46: 0 | Q46: =$B46*P46 -> 0 | R46: 0 | S46: =$B46*R46 -> 0 | T46: 1 | U46: =$B46*T46 -> 45
...
