Workbook

Sheet BOM
A1: ROW | C1: Наименование1 | D1: Тип | E1: Артикул | F1: Номенклатура | G1: Цена (прайс) | H1: Цена нетто, KZT | I1: Сумма, KZT | J1: Кол-во | K1: Ед.изм. | L1: Завод | M1: Сумма, KZT
A2: 1 | B2: =F2 -> Щит силовой ЩС-ФК1 (кухонное оборуд. и фанкойлы фудкорта), IP54 | C2: =F2 -> Щит силовой ЩС-ФК1 (кухонное оборуд. и фанкойлы фудкорта), IP54 | D2: pano | F2: Щит силовой ЩС-ФК1 (кухонное оборуд. и фанкойлы фудкорта), IP54 | J2: 2 | K2: комплект
A3: 2 | B3: =B2 -> Щит силовой ЩС-ФК1 (кухонное оборуд. и фанкойлы фудкорта), IP54 | C3: =F3 -> Корпус металлический ЩРн-54 (540x440x120) IP54 | D3: korpus | E3: 714-15104 | F3: Корпус металлический ЩРн-54 (540x440x120) IP54 | G3: 40000 | H3: =G3*Kurallar!$B$8 -> 24000 | I3: =H3*J3 -> 24000 | J3: 1 | K3: шт. | L3: kaztek | M3: 24000
A4: 3 | B4: =B3 -> Щит силовой ЩС-ФК1 (кухонное оборуд. и фанкойлы фудкорта), IP54 | C4: =F4 -> Автоматический выключатель Acti9 iC60N 3P C63A, 6kA | D4: OTO | E4: A9F74363 | F4: Автоматический выключатель Acti9 iC60N 3P C63A, 6kA | G4: 240 | H4: =G4*Kurallar!$B$7*Kurallar!$B$6 -> 1512 | I4: =H4*J4 -> 1512 | J4: 1 | K4: шт. | L4: Schneider | M4: 1512
A5: 4 | B5: =B4 -> Щит силовой ЩС-ФК1 (кухонное оборуд. и фанкойлы фудкорта), IP54 | C5: =F5 -> Выключатель диф. тока (АВДТ) Acti9 iC60 3P+N C32A 30mA тип AC | D5: DİF | E5: A9DE3732 | F5: Выключатель диф. тока (АВДТ) Acti9 iC60 3P+N C32A 30mA тип AC | G5: 7726 | H5: =G5*Kurallar!$B$7*Kurallar!$B$6 -> 48673.8 | I5: =H5*J5 -> 48673.8 | J5: 1 | K5: шт. | L5: Schneider | M5: 48673.8
A6: 5 | B6: =B5 -> Щит силовой ЩС-ФК1 (кухонное оборуд. и фанкойлы фудкорта), IP54 | C6: =F6 -> Выключатель диф. тока (АВДТ) Acti9 iC60 3P+N C16A 30mA тип AC | D6: DİF | E6: A9DE3716 | F6: Выключатель диф. тока (АВДТ) Acti9 iC60 3P+N C16A 30mA тип AC | G6: 7318 | H6: =G6*Kurallar!$B$7*Kurallar!$B$6 -> 46103.4 | I6: =H6*J6 -> 92206.8 | J6: 2 | K6: шт. | L6: Schneider | M6: 92206.8
A7: 6 | B7: =B6 -> Щит силовой ЩС-ФК1 (кухонное оборуд. и фанкойлы фудкорта), IP54 | C7: =F7 -> Выключатель диф. тока (АВДТ) Acti9 iC60 1P+N C16A 30mA тип AC | D7: DİF | E7: A9D34616 | F7: Выключатель диф. тока (АВДТ) Acti9 iC60 1P+N C16A 30mA тип AC | G7: 3995 | H7: =G7*Kurallar!$B$7*Kurallar!$B$6 -> 25168.5 | I7: =H7*J7 -> 201348 | J7: 8 | K7: шт. | L7: Schneider | M7: 201348
A8: 7 | B8: =B7 -> Щит силовой ЩС-ФК1 (кухонное оборуд. и фанкойлы фудкорта), IP54 | C8: =F8 -> Автоматический выключатель Easy9 3P C13A, 4,5kA | D8: OTO | E8: EZ9F34313 | F8: Автоматический выключатель Easy9 3P C13A, 4,5kA | G8: 1081 | H8: =G8*Kurallar!$B$7*Kurallar!$B$6 -> 6810.3 | I8: =H8*J8 -> 13620.6 | J8: 2 | K8: шт. | L8: Schneider | M8: 13620.6
A9: 8 | B9: =B8 -> Щит силовой ЩС-ФК1 (кухонное оборуд. и фанкойлы фудкорта), IP54 | C9: =F9 -> Автоматический выключатель Easy9 1P C10A, 4,5kA | D9: OTO | E9: EZ9F34110 | F9: Автоматический выключатель Easy9 1P C10A, 4,5kA | G9: 250 | H9: =G9*Kurallar!$B$7*Kurallar!$B$6 -> 1575 | I9: =H9*J9 -> 11025 | J9: 7 | K9: шт. | L9: Schneider | M9: 11025
A10: 9 | B10: =B9 -> Щит силовой ЩС-ФК1 (кухонное оборуд. и фанкойлы фудкорта), IP54 | C10: =F10 -> Контактор модульный SE A9C20844 iCT40A 4НО 220/240В АС 50ГЦ | D10: kontaktör | E10: 54139 | F10: Контактор модульный SE A9C20844 iCT40A 4НО 220/240В АС 50ГЦ | G10: 4500 | H10: =G10*Kurallar!$B$7*Kurallar!$B$6 -> 28350 | I10: =H10*J10 -> 28350 | J10: 1 | K10: шт. | L10: Schneider | M10: 28350
A11: 10 | B11: =B10 -> Щит силовой ЩС-ФК1 (кухонное оборуд. и фанкойлы фудкорта), IP54 | C11: =F11 -> Контактор модульный SE A9C20532 iCT25A 2НО 220В АС | D11: kontaktör | E11: 78061 | F11: Контактор модульный SE A9C20532 iCT25A 2НО 220В АС | G11: 1850 | H11: =G11*Kurallar!$B$7*Kurallar!$B$6 -> 11655 | I11: =H11*J11 -> 11655 | J11: 1 | K11: шт. | L11: Schneider | M11: 11655
A12: 11 | B12: =B11 -> Щит силовой ЩС-ФК1 (кухонное оборуд. и фанкойлы фудкорта), IP54 | C12: =F12 -> Шина "PE" земля ШНИ 6х9 12-К-З на DIN-рейку в изоляторе | D12: LOOBAR | E12: 130200401_ | F12: Шина "PE" земля ШНИ 6х9 12-К-З на DIN-рейку в изоляторе | G12: 547 | H12: =G12*Kurallar!$B$9 -> 547 | I12: =H12*J12 -> 547 | J12: 1 | K12: шт. | L12: UNIT | M12: 547
A13: 12 | B13: =B12 -> Щит силовой ЩС-ФК1 (кухонное оборуд. и фанкойлы фудкорта), IP54 | C13: =F13 -> Шина "N" нулевая 6х9мм 14/2 (крепеж по краям) | D13: LOOBAR | E13: 130200007_ | F13: Шина "N" нулевая 6х9мм 14/2 (крепеж по краям) | G13: 494 | H13: =G13*Kurallar!$B$9 -> 494 | I13: =H13*J13 -> 494 | J13: 1 | K13: шт. | L13: IEK | M13: 494
A14: 13 | B14: =B13 -> Щит силовой ЩС-ФК1 (кухонное оборуд. и фанкойлы фудкорта), IP54 | C14: =F14 -> DIN-рейка оцинкованная 1000 мм | D14: montajный материал | E14: 130200351_ | F14: DIN-рейка оцинкованная 1000 мм | G14: 549 | H14: =G14*Kurallar!$B$9 -> 549 | I14: =H14*J14 -> 1647 | J14: 3 | K14: м | L14: UNIT | M14: 1647
A15: 14 | B15: =B14 -> Щит силовой ЩС-ФК1 (кухонное оборуд. и фанкойлы фудкорта), IP54 | C15: =F15 -> Кабель-канал перфорированный 40х40 (2 м) | D15: montajный материал | E15: 280100020_ | F15: Кабель-канал перфорированный 40х40 (2 м) | G15: 1486 | H15: =G15*Kurallar!$B$9 -> 1486 | I15: =H15*J15 -> 2972 | J15: 2 | K15: шт. | L15: IEK | M15: 2972
A16: 15 | B16: =B15 -> Щит силовой ЩС-ФК1 (кухонное оборуд. и фанкойлы фудкорта), IP54 | C16: =F16 -> Монтажные материалы (клеммы, наконечники, провод ПВ3, маркировка, крепеж) | D16: montajный материал | F16: Монтажные материалы (клеммы, наконечники, провод ПВ3, маркировка, крепеж) | H16: =SUM(I3:I15)*Kurallar!$B$10 -> 13141.536 | I16: =H16*J16 -> 13141.536 | J16: 1 | K16: компл. | L16: — | M16: 13141.536
A17: 16 | B17: =B16 -> Щит силовой ЩС-ФК1 (кухонное оборуд. и фанкойлы фудкорта), IP54 | C17: =F17 -> Сборка щита: монтаж аппаратов, ошиновка, маркировка, испытания | D17: montajная работа | F17: Сборка щита: монтаж аппаратов, ошиновка, маркировка, испытания | G17: =J17/60 -> 2.6666667 | H17: =Kurallar!$B$11 -> 100 | I17: =H17*J17 -> 16000 | J17: =ROUND((Kurallar!$B$29*1+Kurallar!$B$32*1+Kurallar!$B$32*2+Kurallar!$B$31*8+Kurallar!$B$29*2+Kurallar!$B$28*7+Kurallar!$B$34*1+Kurallar!$B$33*1+Kurallar!$B$21*1+Kurallar!$B$21*1+Kurallar!$B$22*3+Kurallar!$B$23*4+Kurallar!$B$24)*Kurallar!$B$26,0) -> 160 | K17: мин | L17: — | M17: 16000
A18: 17 | B18: =B17 -> Щит силовой ЩС-ФК1 (кухонное оборуд. и фанкойлы фудкорта), IP54 | C18: Итого ЩС-ФК1 | F18: ИТОГО по щиту ЩС-ФК1 | I18: =SUBTOTAL(9,I3:I17) -> 467192.74 | M18: 467192.74
A19: 18 | B19: =F19 -> Щит силовой ЩС-ФК2 (кухонное оборуд. и фанкойлы фудкорта), IP54 | C19: =F19 -> Щит силовой ЩС-ФК2 (кухонное оборуд. и фанкойлы фудкорта), IP54 | D19: pano | F19: Щит силовой ЩС-ФК2 (кухонное оборуд. и фанкойлы фудкорта), IP54 | J19: 2 | K19: комплект
A20: 19 | B20: =B19 -> Щит силовой ЩС-ФК2 (кухонное оборуд. и фанкойлы фудкорта), IP54 | C20: =F20 -> Мет. Корпус ЩРН- 48 (660x310x120) IP31 (TS) | D20: korpus | E20: 714-15040 | F20: Мет. Корпус ЩРН- 48 (660x310x120) IP31 (TS) | G20: 40000 | H20: =G20*Kurallar!$B$8 -> 24000 | I20: =H20*J20 -> 24000 | J20: 1 | K20: шт. | L20: kaztek | M20: 24000
A21: 20 | B21: =B20 -> Щит силовой ЩС-ФК2 (кухонное оборуд. и фанкойлы фудкорта), IP54 | C21: =F21 -> Автоматический выключатель Acti9 iC60N 3P C63A, 6kA | D21: OTO | E21: A9F74363 | F21: Автоматический выключатель Acti9 iC60N 3P C63A, 6kA | G21: 4200 | H21: =G21*Kurallar!$B$7*Kurallar!$B$6 -> 26460 | I21: =H21*J21 -> 26460 | J21: 1 | K21: шт. | L21: Schneider | M21: 26460
A22: 21 | B22: =B21 -> Щит силовой ЩС-ФК2 (кухонное оборуд. и фанкойлы фудкорта), IP54 | C22: =F22 -> Выключатель диф. тока (АВДТ) Acti9 iC60 3P+N C32A 30mA тип AC | D22: DİF | E22: A9DE3732 | F22: Выключатель диф. тока (АВДТ) Acti9 iC60 3P+N C32A 30mA тип AC | G22: 7726 | H22: =G22*Kurallar!$B$7*Kurallar!$B$6 -> 48673.8 | I22: =H22*J22 -> 48673.8 | J22: 1 | K22: шт. | L22: Schneider | M22: 48673.8
A23: 22 | B23: =B22 -> Щит силовой ЩС-ФК2 (кухонное оборуд. и фанкойлы фудкорта), IP54 | C23: =F23 -> Выключатель диф. тока (АВДТ) Acti9 iC60 1P+N C25A 30mA тип AC | D23: DİF | E23: A9D34625 | F23: Выключатель диф. тока (АВДТ) Acti9 iC60 1P+N C25A 30mA тип AC | G23: 4200 | H23: =G23*Kurallar!$B$7*Kurallar!$B$6 -> 26460 | I23: =H23*J23 -> 52920 | J23: 2 | K23: шт. | L23: Schneider | M23: 52920
A24: 23 | B24: =B23 -> Щит силовой ЩС-ФК2 (кухонное оборуд. и фанкойлы фудкорта), IP54 | C24: =F24 -> Выключатель диф. тока (АВДТ) Acti9 iC60 1P+N C16A 30mA тип AC | D24: DİF | E24: A9D34616 | F24: Выключатель диф. тока (АВДТ) Acti9 iC60 1P+N C16A 30mA тип AC | G24: 3995 | H24: =G24*Kurallar!$B$7*Kurallar!$B$6 -> 25168.5 | I24: =H24*J24 -> 251685 | J24: 10 | K24: шт. | L24: Schneider | M24: 251685
A25: 24 | B25: =B24 -> Щит силовой ЩС-ФК2 (кухонное оборуд. и фанкойлы фудкорта), IP54 | C25: =F25 -> Автоматический выключатель Easy9 1P C16A, 4,5kA | D25: OTO | E25: EZ9F34116 | F25: Автоматический выключатель Easy9 1P C16A, 4,5kA | G25: 250 | H25: =G25*Kurallar!$B$7*Kurallar!$B$6 -> 1575 | I25: =H25*J25 -> 1575 | J25: 1 | K25: шт. | L25: Schneider | M25: 1575
A26: 25 | B26: =B25 -> Щит силовой ЩС-ФК2 (кухонное оборуд. и фанкойлы фудкорта), IP54 | C26: =F26 -> Автоматический выключатель Easy9 1P C10A, 4,5kA | D26: OTO | E26: EZ9F34110 | F26: Автоматический выключатель Easy9 1P C10A, 4,5kA | G26: 250 | H26: =G26*Kurallar!$B$7*Kurallar!$B$6 -> 1575 | I26: =H26*J26 -> 4725 | J26: 3 | K26: шт. | L26: Schneider | M26: 4725
A27: 26 | B27: =B26 -> Щит силовой ЩС-ФК2 (кухонное оборуд. и фанкойлы фудкорта), IP54 | C27: =F27 -> Контактор модульный SE A9C20532 iCT25A 2НО 220В АС | D27: kontaktör | E27: 78061 | F27: Контактор модульный SE A9C20532 iCT25A 2НО 220В АС | G27: 1850 | H27: =G27*Kurallar!$B$7*Kurallar!$B$6 -> 11655 | I27: =H27*J27 -> 23310 | J27: 2 | K27: шт. | L27: Schneider | M27: 23310
A28: 27 | B28: =B27 -> Щит силовой ЩС-ФК2 (кухонное оборуд. и фанкойлы фудкорта), IP54 | C28: =F28 -> Контактор модульный SE A9C22712 iCT16A 2НО 230/240В АС | D28: kontaktör | E28: 74552 | F28: Контактор модульный SE A9C22712 iCT16A 2НО 230/240В АС | G28: 1850 | H28: =G28*Kurallar!$B$7*Kurallar!$B$6 -> 11655 | I28: =H28*J28 -> 11655 | J28: 1 | K28: шт. | L28: Schneider | M28: 11655
A29: 28 | B29: =B28 -> Щит силовой ЩС-ФК2 (кухонное оборуд. и фанкойлы фудкорта), IP54 | C29: =F29 -> Шина "PE" земля ШНИ 6х9 12-К-З на DIN-рейку в изоляторе | D29: LOOBAR | E29: 130200401_ | F29: Шина "PE" земля ШНИ 6х9 12-К-З на DIN-рейку в изоляторе | G29: 547 | H29: =G29*Kurallar!$B$9 -> 547 | I29: =H29*J29 -> 547 | J29: 1 | K29: шт. | L29: UNIT | M29: 547
A30: 29 | B30: =B29 -> Щит силовой ЩС-ФК2 (кухонное оборуд. и фанкойлы фудкорта), IP54 | C30: =F30 -> Шина "N" нулевая 6х9мм 14/2 (крепеж по краям) | D30: LOOBAR | E30: 130200007_ | F30: Шина "N" нулевая 6х9мм 14/2 (крепеж по краям) | G30: 494 | H30: =G30*Kurallar!$B$9 -> 494 | I30: =H30*J30 -> 494 | J30: 1 | K30: шт. | L30: IEK | M30: 494
A31: 30 | B31: =B30 -> Щит силовой ЩС-ФК2 (кухонное оборуд. и фанкойлы фудкорта), IP54 | C31: =F31 -> DIN-рейка оцинкованная 1000 мм | D31: montajный материал | E31: 130200351_ | F31: DIN-рейка оцинкованная 1000 мм | G31: 549 | H31: =G31*Kurallar!$B$9 -> 549 | I31: =H31*J31 -> 2196 | J31: 4 | K31: м | L31: UNIT | M31: 2196
A32: 31 | B32: =B31 -> Щит силовой ЩС-ФК2 (кухонное оборуд. и фанкойлы фудкорта), IP54 | C32: =F32 -> Кабель-канал перфорированный 40х40 (2 м) | D32: montajный материал | E32: 280100020_ | F32: Кабель-канал перфорированный 40х40 (2 м) | G32: 1486 | H32: =G32*Kurallar!$B$9 -> 1486 | I32: =H32*J32 -> 2972 | J32: 2 | K32: шт. | L32: IEK | M32: 2972
A33: 32 | B33: =B32 -> Щит силовой ЩС-ФК2 (кухонное оборуд. и фанкойлы фудкорта), IP54 | C33: =F33 -> Монтажные материалы (клеммы, наконечники, провод ПВ3, маркировка, крепеж) | D33: montajный материал | F33: Монтажные материалы (клеммы, наконечники, провод ПВ3, маркировка, крепеж) | H33: =SUM(I20:I32)*Kurallar!$B$10 -> 13536.384 | I33: =H33*J33 -> 13536.384 | J33: 1 | K33: компл. | L33: — | M33: 13536.384
A34: 33 | B34: =B33 -> Щит силовой ЩС-ФК2 (кухонное оборуд. и фанкойлы фудкорта), IP54 | C34: =F34 -> Сборка щита: монтаж аппаратов, ошиновка, маркировка, испытания | D34: montajная работа | F34: Сборка щита: монтаж аппаратов, ошиновка, маркировка, испытания | G34: =J34/60 -> 2.5 | H34: =Kurallar!$B$11 -> 100 | I34: =H34*J34 -> 15000 | J34: =ROUND((Kurallar!$B$29*1+Kurallar!$B$32*1+Kurallar!$B$31*2+Kurallar!$B$31*10+Kurallar!$B$28*1+Kurallar!$B$28*3+Kurallar!$B$33*2+Kurallar!$B$33*1+Kurallar!$B$21*1+Kurallar!$B$21*1+Kurallar!$B$22*4+Kurallar!$B$23*4+Kurallar!$B$24)*Kurallar!$B$26,0) -> 150 | K34: мин | L34: — | M34: 15000
A35: 34 | B35: =B34 -> Щит силовой ЩС-ФК2 (кухонное оборуд. и фанкойлы фудкорта), IP54 | C35: Итого ЩС-ФК2 | F35: ИТОГО по щиту ЩС-ФК2 | I35: =SUBTOTAL(9,I20:I34) -> 479749.18 | M35: 479749.18
A36: 35 | B36: =F36 -> Щит силовой ЩС-ФК3 (кухонное оборуд. и фанкойлы фудкорта), IP54 | C36: =F36 -> Щит силовой ЩС-ФК3 (кухонное оборуд. и фанкойлы фудкорта), IP54 | D36: pano | F36: Щит силовой ЩС-ФК3 (кухонное оборуд. и фанкойлы фудкорта), IP54 | J36: 2 | K36: комплект
A37: 36 | B37: =B36 -> Щит силовой ЩС-ФК3 (кухонное оборуд. и фанкойлы фудкорта), IP54 | C37: =F37 -> Мет. Корпус ЩРН-72 (540x600x120) S/U IP31 | D37: korpus | E37: 714-15067 | F37: Мет. Корпус ЩРН-72 (540x600x120) S/U IP31 | G37: 40000 | H37: =G37*Kurallar!$B$8 -> 24000 | I37: =H37*J37 -> 24000 | J37: 1 | K37: шт. | L37: kaztek | M37: 24000
A38: 37 | B38: =B37 -> Щит силовой ЩС-ФК3 (кухонное оборуд. и фанкойлы фудкорта), IP54 | C38: =F38 -> Автоматический выключатель SE A9N18367 C120N 3P 100A 10кА | D38: OTO | E38: 68644 | F38: Автоматический выключатель SE A9N18367 C120N 3P 100A 10кА | G38: 7800 | H38: =G38*Kurallar!$B$7*Kurallar!$B$6 -> 49140 | I38: =H38*J38 -> 49140 | J38: 1 | K38: шт. | L38: Schneider | M38: 49140
A39: 38 | B39: =B38 -> Щит силовой ЩС-ФК3 (кухонное оборуд. и фанкойлы фудкорта), IP54 | C39: =F39 -> Выключатель диф. тока (АВДТ) Acti9 iC60 3P+N C32A 30mA тип AC | D39: DİF | E39: A9DE3732 | F39: Выключатель диф. тока (АВДТ) Acti9 iC60 3P+N C32A 30mA тип AC | G39: 7726 | H39: =G39*Kurallar!$B$7*Kurallar!$B$6 -> 48673.8 | I39: =H39*J39 -> 48673.8 | J39: 1 | K39: шт. | L39: Schneider | M39: 48673.8
A40: 39 | B40: =B39 -> Щит силовой ЩС-ФК3 (кухонное оборуд. и фанкойлы фудкорта), IP54 | C40: =F40 -> Выключатель диф. тока (АВДТ) Acti9 iC60 1P+N C25A 30mA тип AC | D40: DİF | E40: A9D34625 | F40: Выключатель диф. тока (АВДТ) Acti9 iC60 1P+N C25A 30mA тип AC | G40: 4200 | H40: =G40*Kurallar!$B$7*Kurallar!$B$6 -> 26460 | I40: =H40*J40 -> 52920 | J40: 2 | K40: шт. | L40: Schneider | M40: 52920
...

Sheet Sayfa1
A1: 37 | B1: =E1 -> Автоматический выключатель Acti9 C120N 3P C100A, 10kA | C1: OTO | D1: A9N18367 | E1: Автоматический выключатель Acti9 C120N 3P C100A, 10kA | F1: 8710 | G1: =F1*Kurallar!$B$7*Kurallar!$B$6 -> 54873 | H1: =G1*I1 -> 54873 | I1: 1 | J1: шт. | K1: Schneider
A2: 55 | B2: =E2 -> Автоматический выключатель Acti9 C120N 3P C125A, 10kA | C2: OTO | D2: A9N18369 | E2: Автоматический выключатель Acti9 C120N 3P C125A, 10kA | F2: 9358 | G2: =F2*Kurallar!$B$7*Kurallar!$B$6 -> 58955.4 | H2: =G2*I2 -> 58955.4 | I2: 1 | J2: шт. | K2: Schneider

Sheet Sayfa2
A1: Артикул | B1: Номенклатура | C1: Цена (прайс) | D1: Цена нетто, KZT | E1: Сумма, KZT | F1: Кол-во | G1: Ед.изм. | H1: Завод | I1: malz | J1: 2.3
B2: Щит силовой ЩС-ФК1 (кухонное оборуд. и фанкойлы фудкорта) | C2: =ROUNDUP(J2,-3) -> 1075000 | D2: =C2*0.7 -> 752500 | E2: =D2*F2 -> 1505000 | F2: 2 | G2: комплект | H2: tekled electric | I2: 467192.74 | J2: =2.3*I2 -> 1074543.3
B3: Щит силовой ЩС-ФК2 (кухонное оборуд. и фанкойлы фудкорта) | C3: =ROUNDUP(J3,-3) -> 1104000 | D3: =C3*0.7 -> 772800 | E3: =D3*F3 -> 1545600 | F3: 2 | G3: комплект | H3: tekled electric | I3: 479749.18 | J3: =2.3*I3 -> 1103423.1
B4: Щит силовой ЩС-ФК3 (кухонное оборуд. и фанкойлы фудкорта) | C4: =ROUNDUP(J4,-3) -> 1306000 | D4: =C4*0.7 -> 914200 | E4: =D4*F4 -> 1828400 | F4: 2 | G4: комплект | H4: tekled electric | I4: 567641.16 | J4: =2.3*I4 -> 1305574.7
B5: Щит силовой ЩС-ФК4 (кухонное оборуд. и фанкойлы фудкорта) | C5: =ROUNDUP(J5,-3) -> 1528000 | D5: =C5*0.7 -> 1069600 | E5: =D5*F5 -> 2139200 | F5: 2 | G5: комплект | H5: tekled electric | I5: 663983.69 | J5: =2.3*I5 -> 1527162.5
B6: Щит силовой ЩС-КМ (корейский магазин) | C6: =ROUNDUP(J6,-3) -> 930000 | D6: =C6*0.7 -> 651000 | E6: =D6*F6 -> 1302000 | F6: 2 | G6: комплект | H6: tekled electric | I6: 404255.11 | J6: =2.3*I6 -> 929786.76
B7: Щит освещения ЩО-ФК (освещение фудкорта) | C7: =ROUNDUP(J7,-3) -> 666000 | D7: =C7*0.7 -> 466200 | E7: =D7*F7 -> 932400 | F7: 2 | G7: комплект | H7: tekled electric | I7: 289149.77 | J7: =2.3*I7 -> 665044.47
C8: =SUM(C2:C7) -> 6609000 | D8: =C8*0.7 -> 4626300 | E8: =SUM(E2:E7) -> 9252600 | I8: =SUM(I2:I7) -> 2871971.7
C9: =2*C8 -> 13218000 | D9: =C9*0.7 -> 9252600 | I9: =1.16*I8 -> 3331487.1
I10: =1.4*I9 -> 4664082

Sheet СВОД
A1: № | B1: Щит | C1: Наименование | D1: Корпус | E1: Модулей занято | F1: Модулей в корпусе | G1: Заполнение, % | H1: Кол-во щитов | I1: Цена за щит, KZT | J1: Сумма, KZT
A2: 1 | B2: ЩС-ФК1 | C2: Щит силовой ЩС-ФК1 (кухонное оборуд. и фанкойлы фудкорта), IP54 | D2: Корпус металлический ЩРн-54 (540x440x120) IP54 | E2: 54 | F2: 54 | G2: =E2/F2 -> 1 | H2: 1 | I2: =BOM!I18 -> 467192.74 | J2: =I2*H2 -> 467192.74
A3: 2 | B3: ЩС-ФК2 | C3: Щит силовой ЩС-ФК2 (кухонное оборуд. и фанкойлы фудкорта), IP54 | D3: Корпус металлический ЩРн-48 (660x310x120) IP54 | E3: 40 | F3: 48 | G3: =E3/F3 -> 0.83333333 | H3: 1 | I3: =BOM!I35 -> 479749.18 | J3: =I3*H3 -> 479749.18
A4: 3 | B4: ЩС-ФК3 | C4: Щит силовой ЩС-ФК3 (кухонное оборуд. и фанкойлы фудкорта), IP54 | D4: Корпус металлический ЩРн-72 (540x600x120) IP31 | E4: 56.5 | F4: 72 | G4: =E4/F4 -> 0.78472222 | H4: 1 | I4: =BOM!I53 -> 567641.16 | J4: =I4*H4 -> 567641.16
A5: 4 | B5: ЩС-ФК4 | C5: Щит силовой ЩС-ФК4 (кухонное оборуд. и фанкойлы фудкорта), IP54 | D5: Корпус металлический ЩРн-72 (540x600x120) IP31 | E5: 61.5 | F5: 72 | G5: =E5/F5 -> 0.85416667 | H5: 1 | I5: =BOM!I70 -> 663983.69 | J5: =I5*H5 -> 663983.69
A6: 5 | B6: ЩС-КМ | C6: Щит силовой ЩС-КМ (корейский магазин), IP54 | D6: Корпус металлический ЩРн-54 (540x440x120) IP54 | E6: 45 | F6: 54 | G6: =E6/F6 -> 0.83333333 | H6: 1 | I6: =BOM!I87 -> 404255.11 | J6: =I6*H6 -> 404255.11
A7: 6 | B7: ЩО-ФК | C7: Щит освещения ЩО-ФК (освещение фудкорта), IP54 | D7: Корпус металлический ЩРн-54 (540x440x120) IP54 | E7: 49 | F7: 54 | G7: =E7/F7 -> 0.90740741 | H7: 1 | I7: =BOM!I103 -> 289149.77 | J7: =I7*H7 -> 289149.77
C8: ИТОГО по проекту, KZT (без НДС) | J8: =SUBTOTAL(9,J2:J7) -> 2871971.7

Sheet Kurallar
A1: KURALLAR / PARAMETRELER — ADPAS Family Park Abu Dhabi Plaza (ЩС-ФК1..ФК4, ЩС-КМ, ЩО-ФК)
A2: Sarı hücreler = düzenlenebilir. BOM ve СВОД sayfaları bu hücrelere formülle bağlıdır.
A4: PARAMETRE | B4: DEĞER | C4: AÇIKLAMA
A5: KUR VE İSKONTO
A6: TL/KZT kuru | B6: 10.5 | C6: Piyasa 05.08.2026 ~10,30-10,63. BOM günü güncellenmeli.
A7: Schneider iskonto katsayısı | B7: 0.6 | C7: Liste TL x iskonto x TL/KZT = net KZT
A8: TEKSAN korpus katsayısı | B8: 0.6 | C8: Kaztek listesi zaten net KZT
A9: EKT / IEK / UNIT katsayısı | B9: 1 | C9: Liste net KZT
A10: Montaj malzemesi oranı | B10: 0.03 | C10: Pano malzeme ara toplamının %'si
A11: İşçilik birim fiyat (KZT/dakika) | B11: 100 | C11: Sütun G = bu hücre, Sütun I = dakika
A12: İŞÇİLİK ZAMAN NORMLARI (dakika)
A13: OTO 1P | B13: 10
A14: OTO 3P | B14: 18
A15: DİF 1P+N (2P) | B15: 14
A16: DİF 3P+N (4P) | B16: 22
A17: Kontaktör 1P | B17: 15
A18: Kontaktör 3P | B18: 20
A19: Ayırıcı iSW 1P | B19: 10
A20: Ayırıcı iSW 3P | B20: 18
A21: Bara (N/PE) adet başı | B21: 10
A22: DIN ray (dakika/m) | B22: 5
A23: Kablo kanalı (dakika/m) | B23: 5
A24: Korpus hazırlık - küçük (ЩРн-48/54) | B24: 30
... A26: Test/etiket/kontrol çarpanı | B26: 1.15
A27: MODÜL GENİŞLİKLERİ (modül)
A28: OTO 1P | B28: 1
A29: OTO 3P | B29: 3
A30: C120N 3P | B30: 4.5
A31: DİF 1P+N (2P) | B31: 2
A32: DİF 3P+N (4P) | B32: 6
A33: Kontaktör 1P | B33: 1
A34: Kontaktör 3P | B34: 3
A35: iSW 1P | B35: 1
A36: iSW 3P | B36: 3
A45: NOTLAR / KONTROL LİSTESİ
A47: № | B47: KONU | C47: AÇIKLAMA
A48: 1 | B48: SAYIM — ÇİFT KAYNAK | C48: Tek hat şemaları (лист 2-7) ve spesifikasyon СО (лист 1.1-1.3) ayrı ayrı sayıldı. BOM ŞEMA esas alınarak kuruldu.
A49: 2 | B49: ЩС-ФК1 — UYUŞMAZLIK | C49: СО'da АВДТ 2P C16 30mA = 10 ad. Şemada 2P C16 = 8 ad (QFD4,7,8,9,12,14,17,19) + 4P C16 30mA = 2 ad (QFD10, QFD11). BOM'a şema girildi. Projeciye teyit ettirilmeli.
A50: 3 | B50: ЩС-ФК3 — HATALI ARTİKÜL | C50: СО: 'iC60N C100A 3P — A9F79310'. iC60N serisinde 100A yok; A9F79310 = 3P C10A. Şemada giriş In<=100A. BOM'a C120N 3P C100A (A9N18367) girildi.
A51: 4 | B51: ЩС-ФК2/ФК3/ФК4/ЩС-КМ/ЩО-ФК | C51: Şema ile СО birebir uyuşuyor. Düzeltme yapılmadı.
...
