Workbook

Sheet BOM
A1: 260803 — Атырау, стадион «Мунайшы». Реконструкция ФОК. BOM щитового оборудования 0,4 кВ — CHINT
A2: Основание: Альбом 8 «Электроосвещение и силовое электрооборудование» 2023-227/2-ЭОМ (схемы + спецификация ЭОМ.СО + ЭОМ.ОЛ). Все замечания — на листе Kurallar.
A4: ROW | B4: Наименование1 | C4: Тип матер. | D4: Артикул | E4: Номенклатура | F4: Цена списка, KZT | G4: Цена нетто, KZT | H4: Сумма, KZT | I4: Кол. | J4: Ед.изм. | K4: Завод
A5: 1 | B5: ВРУ | E5: ВРУ — вводно-распределительное устройство, тип ВРУ1-21-10-УХЛ4, 1700х700х400 (Альбом 8 ЭОМ, лист 3 / ЭОМ.ОЛ) без счетчик | I5: 1 | J5: комплект
A6: 2 | B6: =$B$5 -> ВРУ | C6: korpus | D6: 250200231_ | E6: 1700*700*450 | F6: 111090 | G6: =IF(F6="","",F6*INDEX(Kurallar!$B$5:$B$9,MATCH(K6,Kurallar!$A$5:$A$9,0))) -> 111090 | H6: =IF(G6="","",G6*I6) -> 111090 | I6: 1 | J6: шт. | K6: EKT
A7: 3 | B7: =$B$5 -> ВРУ | C7: rubilnik | D7: 270100163_ | E7: Рубильник ВР-32-35 А71220-250А на 2 направления (+6 камер) UNIT | F7: 19726 | G7: =IF(F7="","",F7*INDEX(Kurallar!$B$5:$B$9,MATCH(K7,Kurallar!$A$5:$A$9,0))) -> 19726 | H7: =IF(G7="","",G7*I7) -> 19726 | I7: 1 | J7: шт. | K7: UNIT
A8: 4 | B8: =$B$5 -> ВРУ | C8: fu | D8: 270200150_ | E8: Основание контактное ППН-35, габарит 1 UNIT (F1-F3) | F8: 3650 | G8: =IF(F8="","",F8*INDEX(Kurallar!$B$5:$B$9,MATCH(K8,Kurallar!$A$5:$A$9,0))) -> 3650 | H8: =IF(G8="","",G8*I8) -> 10950 | I8: 3 | J8: шт. | K8: UNIT
A9: 5 | B9: =$B$5 -> ВРУ | C9: fu | D9: 270200162_ | E9: Плавкая вставка ППН-35 (125А), габарит 1 UNIT (F1-F3) | F9: 2007 | G9: =IF(F9="","",F9*INDEX(Kurallar!$B$5:$B$9,MATCH(K9,Kurallar!$A$5:$A$9,0))) -> 2007 | H9: =IF(G9="","",G9*I9) -> 6021 | I9: 3 | J9: шт. | K9: UNIT
A10: 6 | B10: =$B$5 -> ВРУ | C10: tt | D10: ITT20-3-05-0100 | E10: Трансформатор тока ТТИ-30 100/5А 5ВА класс 0,5S IEK (Т1-Т3) | F10: 5047 | G10: =IF(F10="","",F10*INDEX(Kurallar!$B$5:$B$9,MATCH(K10,Kurallar!$A$5:$A$9,0))) -> 5047 | H10: =IF(G10="","",G10*I10) -> 15141 | I10: 3 | J10: шт. | K10: IEK
A11: 7 | B11: =$B$5 -> ВРУ | C11: sayac | E11: Счётчик Меркурий 234 ART-03 P, 3х230/400В, 5(10)А, 0,5S/1,0 — поставка заказчика | G11: =IF(F11="","",F11*INDEX(Kurallar!$B$5:$B$9,MATCH(K11,Kurallar!$A$5:$A$9,0))) | H11: =IF(G11="","",G11*I11) | I11: 1 | J11: шт. | K11: ЗАКАЗЧИК
A12: 8 | B12: =$B$5 -> ВРУ | C12: opn | D12: 252494 | E12: Ограничитель имп. перенапр. NU6-IIG 1Р In=15kA Uc=440В Im=40kA (разрядник 1ф) | F12: 5275 | G12: =IF(F12="","",F12*INDEX(Kurallar!$B$5:$B$9,MATCH(K12,Kurallar!$A$5:$A$9,0))) -> 3165 | H12: =IF(G12="","",G12*I12) -> 9495 | I12: 3 | J12: шт. | K12: CHINT
A13: 9 | B13: =$B$5 -> ВРУ | C13: OTO | D13: 814012 | E13: Авт. выкл. NXB-63 1P 6A 6кА х-ка C (цепи управления, ВА47-63 1п 6А) | F13: 1436 | G13: =IF(F13="","",F13*INDEX(Kurallar!$B$5:$B$9,MATCH(K13,Kurallar!$A$5:$A$9,0))) -> 861.6 | H13: =IF(G13="","",G13*I13) -> 1723.2 | I13: 2 | J13: шт. | K13: CHINT
A14: 10 | B14: =$B$5 -> ВРУ | C14: lamb | D14: 593071 | E14: Индикатор ND16-22DS/4 зелёный АС230В (светодиодная матрица 220В) | F14: 836 | G14: =IF(F14="","",F14*INDEX(Kurallar!$B$5:$B$9,MATCH(K14,Kurallar!$A$5:$A$9,0))) -> 501.6 | H14: =IF(G14="","",G14*I14) -> 1003.2 | I14: 2 | J14: шт. | K14: CHINT
A15: 11 | B15: =$B$5 -> ВРУ | C15: fu | D15: 270200149_ | E15: Основание контактное ППН-33, габарит 00 UNIT (F4-F21, 6 групп х 3 фазы) | F15: 1990 | G15: =IF(F15="","",F15*INDEX(Kurallar!$B$5:$B$9,MATCH(K15,Kurallar!$A$5:$A$9,0))) -> 1990 | H15: =IF(G15="","",G15*I15) -> 35820 | I15: 18 | J15: шт. | K15: UNIT
A16: 12 | B16: =$B$5 -> ВРУ | C16: fu | D16: 270200155_ | E16: Плавкая вставка ППН-33 (40А), габарит 00 UNIT (F4-F6, F10-F12) | F16: 775 | G16: =IF(F16="","",F16*INDEX(Kurallar!$B$5:$B$9,MATCH(K16,Kurallar!$A$5:$A$9,0))) -> 775 | H16: =IF(G16="","",G16*I16) -> 4650 | I16: 6 | J16: шт. | K16: UNIT
A17: 13 | B17: =$B$5 -> ВРУ | C17: fu | D17: 270200181_ | E17: Плавкая вставка ППН-33 (20А), габарит 00 UNIT (F7-F9, F16-F18) | F17: 775 | G17: =IF(F17="","",F17*INDEX(Kurallar!$B$5:$B$9,MATCH(K17,Kurallar!$A$5:$A$9,0))) -> 775 | H17: =IF(G17="","",G17*I17) -> 4650 | I17: 6 | J17: шт. | K17: UNIT
A18: 14 | B18: =$B$5 -> ВРУ | C18: fu | D18: 270200157_ | E18: Плавкая вставка ППН-33 (63А), габарит 00 UNIT (F13-F15) | F18: 920 | G18: =IF(F18="","",F18*INDEX(Kurallar!$B$5:$B$9,MATCH(K18,Kurallar!$A$5:$A$9,0))) -> 920 | H18: =IF(G18="","",G18*I18) -> 2760 | I18: 3 | J18: шт. | K18: UNIT
A19: 15 | B19: =$B$5 -> ВРУ | C19: fu | D19: 270200180_ | E19: Плавкая вставка ППН-33 (10А), габарит 00 UNIT (F19-F21) | F19: 775 | G19: =IF(F19="","",F19*INDEX(Kurallar!$B$5:$B$9,MATCH(K19,Kurallar!$A$5:$A$9,0))) -> 775 | H19: =IF(G19="","",G19*I19) -> 2325 | I19: 3 | J19: шт. | K19: UNIT
A20: 16 | B20: =$B$5 -> ВРУ | C20: LOOBAR | D20: 130200153_ | E20: Шина алюминиевая АД31Т 4х40х4000 (L1/L2/L3/N + PE, раскрой по компоновке) | F20: 1281 | G20: =IF(F20="","",F20*INDEX(Kurallar!$B$5:$B$9,MATCH(K20,Kurallar!$A$5:$A$9,0))) -> 1281 | H20: =IF(G20="","",G20*I20) -> 3843 | I20: 3 | J20: шт. | K20: EKT
A21: 17 | B21: =$B$5 -> ВРУ | C21: LOOBAR | D21: 130500104_ | E21: Изолятор SM30 с болтом (М8) 380А UNIT (шинодержатель) | F21: 234 | G21: =IF(F21="","",F21*INDEX(Kurallar!$B$5:$B$9,MATCH(K21,Kurallar!$A$5:$A$9,0))) -> 234 | H21: =IF(G21="","",G21*I21) -> 4680 | I21: 20 | J21: шт. | K21: UNIT
A22: 18 | B22: =$B$5 -> ВРУ | C22: Klemens | D22: 130301155_ | E22: Зажим наборный ЗНИ 10мм² (70А) серый UNIT | F22: 151 | G22: =IF(F22="","",F22*INDEX(Kurallar!$B$5:$B$9,MATCH(K22,Kurallar!$A$5:$A$9,0))) -> 151 | H22: =IF(G22="","",G22*I22) -> 1510 | I22: 10 | J22: шт. | K22: UNIT
A23: 19 | B23: =$B$5 -> ВРУ | C23: Klemens | D23: 130301156_ | E23: Зажим наборный ЗНИ 10мм² (70А) синий UNIT | F23: 144 | G23: =IF(F23="","",F23*INDEX(Kurallar!$B$5:$B$9,MATCH(K23,Kurallar!$A$5:$A$9,0))) -> 144 | H23: =IF(G23="","",G23*I23) -> 1440 | I23: 10 | J23: шт. | K23: UNIT
... A27: 23 | B27: =$B$5 -> ВРУ | C27: montaj | D27: 100300074_ | E27: Провод ПВ3-6 жёлто-зелёный ГОСТ (PE) | F27: 319 | G27: =IF(F27="","",F27*INDEX(Kurallar!$B$5:$B$9,MATCH(K27,Kurallar!$A$5:$A$9,0))) -> 319 | H27: =IF(G27="","",G27*I27) -> 4785 | I27: 15 | J27: м | K27: EKT
A28: 24 | B28: =$B$5 -> ВРУ | C28: montajный материал | E28: Монтажный материал (наконечники, маркировка, стяжки, крепёж) — % от материала панели | G28: =ROUND(Kurallar!$B$12*SUBTOTAL(9,H6:H27),0) -> 7987 | H28: =G28*I28 -> 7987 | I28: 1 | J28: компл. | K28: TEKLED
A29: 25 | B29: =$B$5 -> ВРУ | C29: montajная работа | E29: Монтажные работы (сборка, маркировка, испытание, контроль) — норма времени | F29: =I29/60 -> 19.416667 | G29: =Kurallar!$B$13 -> 100 | H29: =G29*I29 -> 116500 | I29: 1165 | J29: мин | K29: TEKLED
B30: ="Итого "&$B$5 -> Итого ВРУ | E30: — ИТОГО ПО ПАНЕЛИ — | H30: =SUBTOTAL(9,H6:H29) -> 390713.4
A31: 26 | B31: ЩО1 | E31: ЩО1 — щит освещения, ЩРН-П 18 мод. IP41 (Альбом 8 ЭОМ, лист 4) | I31: 1 | J31: комплект
A32: 27 | B32: =$B$31 -> ЩО1 | C32: korpus | D32: 250600008_ | E32: Щит распределительный пластиковый навесной ЩРН-П 18 мод. IP41, с шинами N и PE, IEK | F32: 3480 | G32: =IF(F32="","",F32*INDEX(Kurallar!$B$5:$B$9,MATCH(K32,Kurallar!$A$5:$A$9,0))) -> 3480 | H32: =IF(G32="","",G32*I32) -> 3480 | I32: 1 | J32: шт. | K32: IEK
A33: 28 | B33: =$B$31 -> ЩО1 | C33: rubilnik | D33: 193180 | E33: Выключатель нагрузки NXHB-125 3P 20A | F33: 3372 | G33: =IF(F33="","",F33*INDEX(Kurallar!$B$5:$B$9,MATCH(K33,Kurallar!$A$5:$A$9,0))) -> 2023.2 | H33: =IF(G33="","",G33*I33) -> 2023.2 | I33: 1 | J33: шт. | K33: CHINT
A34: 29 | B34: =$B$31 -> ЩО1 | C34: OTO | D34: 814040 | E34: Авт. выкл. NXB-63 1P 16A 6кА х-ка B | F34: 1419 | G34: =IF(F34="","",F34*INDEX(Kurallar!$B$5:$B$9,MATCH(K34,Kurallar!$A$5:$A$9,0))) -> 851.4 | H34: =IF(G34="","",G34*I34) -> 7662.6 | I34: 9 | J34: шт. | K34: CHINT
A35: 30 | B35: =$B$31 -> ЩО1 | C35: montajный материал | E35: Монтажный материал (наконечники, маркировка, стяжки, крепёж) — % от материала панели | G35: =ROUND(Kurallar!$B$12*SUBTOTAL(9,H32:H34),0) -> 395 | H35: =G35*I35 -> 395 | I35: 1 | J35: компл. | K35: TEKLED
A36: 31 | B36: =$B$31 -> ЩО1 | C36: montajная работа | E36: Монтажные работы (сборка, маркировка, испытание, контроль) — норма времени | F36: =I36/60 -> 3.1666667 | G36: =Kurallar!$B$13 -> 100 | H36: =G36*I36 -> 19000 | I36: 190 | J36: мин | K36: TEKLED
B37: ="Итого "&$B$31 -> Итого ЩО1 | E37: — ИТОГО ПО ПАНЕЛИ — | H37: =SUBTOTAL(9,H32:H36) -> 32560.8
A38: 32 | B38: ЩО2 | E38: ЩО2 — щит освещения, ЩРН-П 24 мод. IP41 (Альбом 8 ЭОМ, лист 5) | I38: 1 | J38: комплект
A39: 33 | B39: =$B$38 -> ЩО2 | C39: korpus | D39: 250600009_ | E39: Щит распределительный пластиковый навесной ЩРН-П 24 мод. IP41, с шинами N и PE, IEK | F39: 7040 | G39: =IF(F39="","",F39*INDEX(Kurallar!$B$5:$B$9,MATCH(K39,Kurallar!$A$5:$A$9,0))) -> 7040 | H39: =IF(G39="","",G39*I39) -> 7040 | I39: 1 | J39: шт. | K39: IEK
A40: 34 | B40: =$B$38 -> ЩО2 | C40: rubilnik | D40: 193180 | E40: Выключатель нагрузки NXHB-125 3P 20A | F40: 3372 | G40: =IF(F40="","",F40*INDEX(Kurallar!$B$5:$B$9,MATCH(K40,Kurallar!$A$5:$A$9,0))) -> 2023.2 | H40: =IF(G40="","",G40*I40) -> 2023.2 | I40: 1 | J40: шт. | K40: CHINT
A41: 35 | B41: =$B$38 -> ЩО2 | C41: OTO | D41: 814040 | E41: Авт. выкл. NXB-63 1P 16A 6кА х-ка B | F41: 1419 | G41: =IF(F41="","",F41*INDEX(Kurallar!$B$5:$B$9,MATCH(K41,Kurallar!$A$5:$A$9,0))) -> 851.4 | H41: =IF(G41="","",G41*I41) -> 10216.8 | I41: 12 | J41: шт. | K41: CHINT
A42: 36 | B42: =$B$38 -> ЩО2 | C42: montajный материал | E42: Монтажный материал (наконечники, маркировка, стяжки, крепёж) — % от материала панели | G42: =ROUND(Kurallar!$B$12*SUBTOTAL(9,H39:H41),0) -> 578 | H42: =G42*I42 -> 578 | I42: 1 | J42: компл. | K42: TEKLED
A43: 37 | B43: =$B$38 -> ЩО2 | C43: montajная работа | E43: Монтажные работы (сборка, маркировка, испытание, контроль) — норма времени | F43: =I43/60 -> 3.7333333 | G43: =Kurallar!$B$13 -> 100 | H43: =G43*I43 -> 22400 | I43: 224 | J43: мин | K43: TEKLED
B44: ="Итого "&$B$38 -> Итого ЩО2 | E44: — ИТОГО ПО ПАНЕЛИ — | H44: =SUBTOTAL(9,H39:H43) -> 42258
...

Sheet СВОД
A1: СВОД по щитам — 260803 Атырау, стадион «Мунайшы» (ЭОМ), CHINT
A3: № | B3: Щит | C3: Кол. компл. | D3: Материал + монтаж, KZT | E3: в т.ч. работы, KZT | F3: Позиций без цены | G3: Примечание
A4: 1 | B4: ВРУ | C4: =BOM!I5 -> 1 | D4: =BOM!H30 -> 390713.4 | E4: =BOM!H29 -> 116500 | F4: =COUNTIFS(BOM!$B$6:$B$27,BOM!$B$6,BOM!$F$6:$F$27,"") -> 1 | G4: =IF(F4>0,"ВНИМАНИЕ: есть позиции без цены — см. Kurallar","") -> ВНИМАНИЕ: есть позиции без цены — см. Kurallar
A5: 2 | B5: ЩО1 | C5: =BOM!I31 -> 1 | D5: =BOM!H37 -> 32560.8 | E5: =BOM!H36 -> 19000 | F5: =COUNTIFS(BOM!$B$32:$B$34,BOM!$B$32,BOM!$F$32:$F$34,"") -> 0 | G5: =IF(F5>0,"ВНИМАНИЕ: есть позиции без цены — см. Kurallar","")
A6: 3 | B6: ЩО2 | C6: =BOM!I38 -> 1 | D6: =BOM!H44 -> 42258 | E6: =BOM!H43 -> 22400 | F6: =COUNTIFS(BOM!$B$39:$B$41,BOM!$B$39,BOM!$F$39:$F$41,"") -> 0 | G6: =IF(F6>0,"ВНИМАНИЕ: есть позиции без цены — см. Kurallar","")
A7: 4 | B7: ЩО3 | C7: =BOM!I45 -> 1 | D7: =BOM!H51 -> 28507 | E7: =BOM!H50 -> 16700 | F7: =COUNTIFS(BOM!$B$46:$B$48,BOM!$B$46,BOM!$F$46:$F$48,"") -> 0 | G7: =IF(F7>0,"ВНИМАНИЕ: есть позиции без цены — см. Kurallar","")
A8: 5 | B8: ЩО4 | C8: =BOM!I52 -> 1 | D8: =BOM!H58 -> 30483.4 | E8: =BOM!H57 -> 17800 | F8: =COUNTIFS(BOM!$B$53:$B$55,BOM!$B$53,BOM!$F$53:$F$55,"") -> 0 | G8: =IF(F8>0,"ВНИМАНИЕ: есть позиции без цены — см. Kurallar","")
A9: 6 | B9: ЩАО1 | C9: =BOM!I59 -> 1 | D9: =BOM!H65 -> 24986.2 | E9: =BOM!H64 -> 14400 | F9: =COUNTIFS(BOM!$B$60:$B$62,BOM!$B$60,BOM!$F$60:$F$62,"") -> 0 | G9: =IF(F9>0,"ВНИМАНИЕ: есть позиции без цены — см. Kurallar","")
A10: 7 | B10: ЩАО2 | C10: =BOM!I66 -> 1 | D10: =BOM!H72 -> 22909.8 | E10: =BOM!H71 -> 13200 | F10: =COUNTIFS(BOM!$B$67:$B$69,BOM!$B$67,BOM!$F$67:$F$69,"") -> 0 | G10: =IF(F10>0,"ВНИМАНИЕ: есть позиции без цены — см. Kurallar","")
A11: 8 | B11: ЩАО3 | C11: =BOM!I73 -> 1 | D11: =BOM!H79 -> 22909.8 | E11: =BOM!H78 -> 13200 | F11: =COUNTIFS(BOM!$B$74:$B$76,BOM!$B$74,BOM!$F$74:$F$76,"") -> 0 | G11: =IF(F11>0,"ВНИМАНИЕ: есть позиции без цены — см. Kurallar","")
A12: 9 | B12: ЩАО4 | C12: =BOM!I80 -> 1 | D12: =BOM!H86 -> 16878.6 | E12: =BOM!H85 -> 9800 | F12: =COUNTIFS(BOM!$B$81:$B$83,BOM!$B$81,BOM!$F$81:$F$83,"") -> 0 | G12: =IF(F12>0,"ВНИМАНИЕ: есть позиции без цены — см. Kurallar","")
A13: 10 | B13: ЩС1 | C13: =BOM!I87 -> 1 | D13: =BOM!H94 -> 32146.8 | E13: =BOM!H93 -> 14600 | F13: =COUNTIFS(BOM!$B$88:$B$91,BOM!$B$88,BOM!$F$88:$F$91,"") -> 0 | G13: =IF(F13>0,"ВНИМАНИЕ: есть позиции без цены — см. Kurallar","")
A14: 11 | B14: ЩС2 | C14: =BOM!I95 -> 1 | D14: =BOM!H104 -> 46816.4 | E14: =BOM!H103 -> 18300 | F14: =COUNTIFS(BOM!$B$96:$B$101,BOM!$B$96,BOM!$F$96:$F$101,"") -> 0 | G14: =IF(F14>0,"ВНИМАНИЕ: есть позиции без цены — см. Kurallar","")
A15: 12 | B15: ЩС3 | C15: =BOM!I105 -> 1 | D15: =BOM!H111 -> 35436.8 | E15: =BOM!H110 -> 15100 | F15: =COUNTIFS(BOM!$B$106:$B$108,BOM!$B$106,BOM!$F$106:$F$108,"") -> 0 | G15: =IF(F15>0,"ВНИМАНИЕ: есть позиции без цены — см. Kurallar","")
A16: 13 | B16: ЩС4 | C16: =BOM!I112 -> 1 | D16: =BOM!H118 -> 35436.8 | E16: =BOM!H117 -> 15100 | F16: =COUNTIFS(BOM!$B$113:$B$115,BOM!$B$113,BOM!$F$113:$F$115,"") -> 0 | G16: =IF(F16>0,"ВНИМАНИЕ: есть позиции без цены — см. Kurallar","")
A17: 14 | B17: ЩВ | C17: =BOM!I119 -> 1 | D17: =BOM!H136 -> 213963.6 | E17: =BOM!H135 -> 75200 | F17: =COUNTIFS(BOM!$B$120:$B$133,BOM!$B$120,BOM!$F$120:$F$133,"") -> 0 | G17: =IF(F17>0,"ВНИМАНИЕ: есть позиции без цены — см. Kurallar","")
A18: 15 | B18: КМ блоки | C18: =BOM!I137 -> 1 | D18: =BOM!H144 -> 160839 | E18: =BOM!H143 -> 40500 | F18: =COUNTIFS(BOM!$B$138:$B$141,BOM!$B$138,BOM!$F$138:$F$141,"") -> 0 | G18: =IF(F18>0,"ВНИМАНИЕ: есть позиции без цены — см. Kurallar","")
A19: 16 | B19: ЯТП | C19: =BOM!I145 -> 1 | D19: =BOM!H149 -> 102076 | E19: =BOM!H148 -> 12000 | F19: =COUNTIFS(BOM!$B$146:$B$146,BOM!$B$146,BOM!$F$146:$F$146,"") -> 0 | G19: =IF(F19>0,"ВНИМАНИЕ: есть позиции без цены — см. Kurallar","")
B20: ИТОГО ПО ПРОЕКТУ | D20: =SUM(D4:D19) -> 1238922.4 | E20: =SUM(E4:E19) -> 433800 | F20: =SUM(F4:F19) -> 1
B22: Проверка модулей корпусов (занято / установлено / резерв)
B23: Щит | C23: Занято мод. | D23: Корпус, мод. | E23: Резерв % | F23: Статус
B24: ЩО1 | C24: 12 | D24: 18 | E24: =1-C24/D24 -> 0.33333333 | F24: =IF(E24>=Kurallar!$B$14,"ОК","МАЛО — увеличить корпус") -> ОК
B25: ЩО2 | C25: 15 | D25: 24 | E25: =1-C25/D25 -> 0.375 | F25: =IF(E25>=Kurallar!$B$14,"ОК","МАЛО — увеличить корпус") -> ОК
B26: ЩО3 | C26: 10 | D26: 18 | E26: =1-C26/D26 -> 0.44444444 | F26: =IF(E26>=Kurallar!$B$14,"ОК","МАЛО — увеличить корпус") -> ОК
B27: ЩО4 | C27: 11 | D27: 18 | E27: =1-C27/D27 -> 0.38888889 | F27: =IF(E27>=Kurallar!$B$14,"ОК","МАЛО — увеличить корпус") -> ОК
B28: ЩАО1 | C28: 8 | D28: 12 | E28: =1-C28/D28 -> 0.33333333 | F28: =IF(E28>=Kurallar!$B$14,"ОК","МАЛО — увеличить корпус") -> ОК
B29: ЩАО2 | C29: 7 | D29: 12 | E29: =1-C29/D29 -> 0.41666667 | F29: =IF(E29>=Kurallar!$B$14,"ОК","МАЛО — увеличить корпус") -> ОК
B30: ЩАО3 | C30: 7 | D30: 12 | E30: =1-C30/D30 -> 0.41666667 | F30: =IF(E30>=Kurallar!$B$14,"ОК","МАЛО — увеличить корпус") -> ОК
B31: ЩАО4 | C31: 4 | D31: 12 | E31: =1-C31/D31 -> 0.66666667 | F31: =IF(E31>=Kurallar!$B$14,"ОК","МАЛО — увеличить корпус") -> ОК
B32: ЩС1 | C32: 10 | D32: 18 | E32: =1-C32/D32 -> 0.44444444 | F32: =IF(E32>=Kurallar!$B$14,"ОК","МАЛО — увеличить корпус") -> ОК
B33: ЩС2 | C33: 15 | D33: 24 | E33: =1-C33/D33 -> 0.375 | F33: =IF(E33>=Kurallar!$B$14,"ОК","МАЛО — увеличить корпус") -> ОК
B34: ЩС3 | C34: 11 | D34: 18 | E34: =1-C34/D34 -> 0.38888889 | F34: =IF(E34>=Kurallar!$B$14,"ОК","МАЛО — увеличить корпус") -> ОК
B35: ЩС4 | C35: 11 | D35: 18 | E35: =1-C35/D35 -> 0.38888889 | F35: =IF(E35>=Kurallar!$B$14,"ОК","МАЛО — увеличить корпус") -> ОК
B36: ЩВ | C36: 40 | D36: 72 | E36: =1-C36/D36 -> 0.44444444 | F36: =IF(E36>=Kurallar!$B$14,"ОК","МАЛО — увеличить корпус") -> ОК

Sheet Kurallar
A1: KURALLAR / ПАРАМЕТРЫ — 260803 Атырау, стадион «Мунайшы» (ЭОМ) — CHINT BOM
A3: 1. КОЭФФИЦИЕНТЫ ПО ЗАВОДАМ (жёлтые ячейки — редактируемые)
A4: Завод | B4: Коэффициент нетто | C4: Примечание
A5: CHINT | B5: 0.6 | C5: список x 0,60 (скидка 40%)
A6: IEK | B6: 1 | C6: прайс EKT, нетто
A7: UNIT | B7: 1 | C7: прайс EKT, нетто
A8: EKT | B8: 1 | C8: прайс EKT, нетто
A9: ЗАКАЗЧИК | B9: 0 | C9: поставка заказчика — цена не считается
A11: 2. ОБЩИЕ ПАРАМЕТРЫ
A12: Монтажный материал, % от материала панели | B12: 0.03
A13: Ставка монтажных работ, KZT/мин | B13: 100
A14: Резерв корпуса (модули), мин. % | B14: 0.2
A15: Множитель на испытание/маркировку/контроль | B15: 1.15
A17: 3. НОРМЫ ВРЕМЕНИ, мин (жёлтые — редактируемые)
A18: Корпус навесной малый (до 24 мод.), подготовка | B18: 30
A19: Корпус навесной средний (ЩМП), подготовка | B19: 45
A20: Корпус напольный / ВРУ, подготовка | B20: 90
A21: Автомат 1P | B21: 10
A22: Автомат 3P | B22: 18
A23: АВДТ / диф.автомат 1P+N (2 мод.) | B23: 14
A24: Рубильник модульный (ВН/NXHB) | B24: 45
A25: Рубильник 250А (ВР-32-35) | B25: 60
A26: ОПН / разрядник 1P | B26: 15
A27: Независимый расцепитель | B27: 15
A28: Индикатор / сигнальная лампа | B28: 10
A29: Предохранитель ППН (основание+вставка), за фазу | B29: 12
... A33: DIN-рейка и кабель-канал, за метр | B33: 5
A35: 4. ВОЗРАСТ ПРАЙС-ЛИСТОВ
A36: Дата BOM | B36: 2026-08-03
A37: Источник | B37: Дата прайса | C37: Возраст, мес. | D37: YAS_DURUM (формула) | E37: Используется в этом BOM
A38: CHINT — 260728 stok+fiyat | B38: 2026-07-28 | C38: =DATEDIF(B38,Kurallar!$B$36,"m") -> 0 | D38: =IF(C38>18,"ЗАПРЕЩЕНО",IF(C38>12,"ПРЕДУПРЕЖДЕНИЕ","ОК")) -> ОК | E38: ДА
A39: EKT / IEK / UNIT — 19062025 EKT PRICE | B39: 2025-06-19 | C39: =DATEDIF(B39,Kurallar!$B$36,"m") -> 13 | D39: =IF(C39>18,"ЗАПРЕЩЕНО",IF(C39>12,"ПРЕДУПРЕЖДЕНИЕ","ОК")) -> ПРЕДУПРЕЖДЕНИЕ | E39: ДА
A40: САЙМАН 2026 | B40: 2026-01-01 | C40: =DATEDIF(B40,Kurallar!$B$36,"m") -> 7 | D40: =IF(C40>18,"ЗАПРЕЩЕНО",IF(C40>12,"ПРЕДУПРЕЖДЕНИЕ","ОК")) -> ОК | E40: нет
A41: CNC — 04.02.2025 | B41: 2025-02-04 | C41: =DATEDIF(B41,Kurallar!$B$36,"m") -> 17 | D41: =IF(C41>18,"ЗАПРЕЩЕНО",IF(C41>12,"ПРЕДУПРЕЖДЕНИЕ","ОК")) -> ПРЕДУПРЕЖДЕНИЕ | E41: нет
A42: Legrand — 10.2025 | B42: 2025-10-01 | C42: =DATEDIF(B42,Kurallar!$B$36,"m") -> 10 | D42: =IF(C42>18,"ЗАПРЕЩЕНО",IF(C42>12,"ПРЕДУПРЕЖДЕНИЕ","ОК")) -> ОК | E42: нет
A43: ABB — 11.2025 | B43: 2025-11-01 | C43: =DATEDIF(B43,Kurallar!$B$36,"m") -> 9 | D43: =IF(C43>18,"ЗАПРЕЩЕНО",IF(C43>12,"ПРЕДУПРЕЖДЕНИЕ","ОК")) -> ОК | E43: нет
A44: Schneider — 07.2025 | B44: 2025-07-01 | C44: =DATEDIF(B44,Kurallar!$B$36,"m") -> 13 | D44: =IF(C44>18,"ЗАПРЕЩЕНО",IF(C44>12,"ПРЕДУПРЕЖДЕНИЕ","ОК")) -> ПРЕДУПРЕЖДЕНИЕ | E44: нет
A45: KLEMSAN — 11.2022 | B45: 2022-11-01 | C45: =DATEDIF(B45,Kurallar!$B$36,"m") -> 45 | D45: =IF(C45>18,"ЗАПРЕЩЕНО",IF(C45>12,"ПРЕДУПРЕЖДЕНИЕ","ОК")) -> ЗАПРЕЩЕНО | E45: нет
A46: ONKA — 07.2022 | B46: 2022-07-01 | C46: =DATEDIF(B46,Kurallar!$B$36,"m") -> 49 | D46: =IF(C46>18,"ЗАПРЕЩЕНО",IF(C46>12,"ПРЕДУПРЕЖДЕНИЕ","ОК")) -> ЗАПРЕЩЕНО | E46: нет
A47: EKF — 22.02.2022 | B47: 2022-02-22 | C47: =DATEDIF(B47,Kurallar!$B$36,"m") -> 53 | D47: =IF(C47>18,"ЗАПРЕЩЕНО",IF(C47>12,"ПРЕДУПРЕЖДЕНИЕ","ОК")) -> ЗАПРЕЩЕНО | E47: нет
...
