Workbook
Name DURUM_LIST: KURALLAR!$J$2:$J$11
Name FIYAT_ACK: OFFSET(FIYAT!$D$2,0,0,COUNTA(FIYAT!$C:$C)-1,1)
Name FIYAT_ART: OFFSET(FIYAT!$Q$2,0,0,COUNTA(FIYAT!$C:$C)-1,1)
Name FIYAT_KOD: OFFSET(FIYAT!$C$2,0,0,COUNTA(FIYAT!$C:$C)-1,1)
Name FIYAT_LISTE: OFFSET(FIYAT!$E$2,0,0,COUNTA(FIYAT!$C:$C)-1,1)
Name FIYAT_MARKA: OFFSET(FIYAT!$J$2,0,0,COUNTA(FIYAT!$C:$C)-1,1)
Name FIYAT_NET: OFFSET(FIYAT!$F$2,0,0,COUNTA(FIYAT!$C:$C)-1,1)
Name ISKONTO: KURALLAR!$B$52
Name KAR_ORANI: KURALLAR!$B$51
Name KUR_AD: KURALLAR!$A$5:$A$8
Name KUR_DEG: KURALLAR!$B$5:$B$8
Name MARKA_AD: KURALLAR!$A$12:$A$26
Name MARKA_KAT: KURALLAR!$E$12:$E$26
Name MARKA_PARA: KURALLAR!$B$12:$B$26
Name MARKA_TIP: KURALLAR!$F$12:$F$26
Name NDS_ORANI: KURALLAR!$B$53

Sheet KURALLAR
A1: KURALLAR - TEK GERCEK KAYNAK
J2: OK
A3: BLOK 1: KUR TABLOSU | J3: FIYAT_YOK
A4: PARA | B4: KZT | C4: TARIH | J4: MUADIL
A5: KZT | B5: 1 | J5: MUADIL_ONAY
A6: USD | B6: 548 | C6: 2026-09-09 (VARSAYIM) | J6: CIHAZ_BELIRSIZ
A7: EUR | B7: 590 | C7: VARSAYIM - kullanilmadi | J7: VARSAYIM
A8: TRY | B8: 16.5 | C8: VARSAYIM - kullanilmadi | J8: KAPSAM_DISI
J9: KONTROL
A10: BLOK 2: MARKA KURAL TABLOSU | J10: OKUNAMADI
A11: MARKA | B11: PARA | C11: KATSAYI1 | D11: KATSAYI2 | E11: TOPLAM | F11: GIRDI_TIPI | G11: NOT | J11: FIYAT_ESKI
A12: ABB | B12: EUR | C12: 1.35 | D12: 0.3 | E12: =C12*D12 -> 0.405 | F12: LISTE | G12: standart
A13: ABB-ACIK | B13: EUR | C13: 1.35 | D13: 0.23 | E13: =C13*D13 -> 0.3105 | F13: LISTE | G13: ayar sahali / acik tip
A14: SCHNEIDER | B14: EUR | C14: 0.6 | D14: 1 | E14: =C14*D14 -> 0.6 | F14: LISTE
A15: CHINT | B15: KZT | C15: 0.6 | D15: 1 | E15: =C15*D15 -> 0.6 | F15: LISTE
A16: CNC | B16: KZT | C16: 0.55 | D16: 1 | E16: =C16*D16 -> 0.55 | F16: LISTE | G16: liste 2025-02-04, guvenilmez
A17: LEGRAND | B17: TRY | C17: 0.5 | D17: 1 | E17: =C17*D17 -> 0.5 | F17: LISTE | G17: teyitsiz
A18: IEK | B18: KZT | C18: 1 | D18: 1 | E18: =C18*D18 -> 1 | F18: LISTE
A19: EKF | B19: KZT | C19: 1 | D19: 1 | E19: =C19*D19 -> 1 | F19: LISTE | G19: referans, fiyat yasak
A20: EKT | B20: KZT | C20: 1 | D20: 1 | E20: =C20*D20 -> 1 | F20: LISTE | G20: yas 14.9 ay - GUNCELLE
A21: SAIMAN | B21: KZT | C21: 1 | D21: 1 | E21: =C21*D21 -> 1 | F21: LISTE
A22: KAZTEK | B22: KZT | C22: 0.6 | D22: 1 | E22: =C22*D22 -> 0.6 | F22: LISTE | G22: korpus
A23: BAKIR-BARA | B23: KZT | C23: 1 | D23: 1 | E23: =C23*D23 -> 1 | F23: NET | G23: kg fiyatindan hesaplanir
A24: ALUM-BARA | B24: KZT | C24: 1 | D24: 1 | E24: =C24*D24 -> 1 | F24: NET | G24: kg fiyatindan hesaplanir
A25: MUADIL-NET | B25: KZT | C25: 1 | D25: 1 | E25: =C25*D25 -> 1 | F25: NET
A26: ISCILIK | B26: KZT | C26: 1 | D26: 1 | E26: =C26*D26 -> 1 | F26: NET
A28: BLOK 3: ISCILIK (sari)
A29: ISCILIK_SAAT_UCRETI | B29: 6000
A30: ISCILIK_G_SABIT | B30: 100
A31: TEST_ETIKET_CARPANI | B31: 1.15
A32: Normlar(dk): MCB1P=2,MCB3P=5,MCCB<=250A=25,moduler=20,klemens=2/ad,DINray+kanal=2/m,korpus kucuk=5/orta=22/ayakli=45
A34: BLOK 6: OTOMATIK TAMAMLAMA PARAMETRELERI (sari)
A35: BARA_DERATING | B35: 0.85
A36: BARA_FIRE | B36: 1.15
A37: BARA_N_ORANI | B37: 1
A38: BARA_PE_ORANI | B38: 0.5
A39: BARA_KOPRU_M | B39: 0.3
A40: BARA_BOY_M | B40: 4
A41: KABLO_FIRE | B41: 1.1
A42: KABLO_M_MODULER | B42: 1.2
...

Sheet FIYAT
A1: SIRA | B1: TIP | C1: ARTIKUL | D1: ACIKLAMA | E1: LISTE_FIYAT | F1: NET_KZT | G1: TOPLAM_ADET | H1: TOPLAM_TUTAR | I1: PARA | J1: MARKA | K1: KATSAYI | L1: BIRIM | M1: KAYNAK | N1: DURUM | O1: NOT | P1: PANO(LAR) | Q1: KOD (SISTEM ANAHTARI - DOKUNMA)
A2: 1 | B2: MCCB | C2: 131363 | D2: Авт. выкл. NXM-125S/3Р 125A 25кА (R) | E2: 19760 | F2: =IF($E2="","",IF(INDEX(MARKA_TIP,MATCH($J2,MARKA_AD,0))="NET",$E2,$E2*INDEX(MARKA_KAT,MATCH($J2,MARKA_AD,0))*INDEX(KUR_DEG,MATCH($I2,KUR_AD,0)))) -> 11856 | G2: =SUMIF(BOM!$P:$P,$Q2,BOM!$I:$I) -> 2 | H2: =IF($F2="","",$F2*$G2) -> 23712 | I2: =IF($E2="","",INDEX(MARKA_PARA,MATCH($J2,MARKA_AD,0))) -> KZT | J2: CHINT | K2: =IF($E2="","",INDEX(MARKA_KAT,MATCH($J2,MARKA_AD,0))) -> 0.6 | L2: шт | M2: birlesik.csv (CHINT) ARTIKUL 131363 | N2: OK | O2: Eski NM1-125S serisi yerine NXM-125S serisine gecildi (kullanici talebi), ayni akim/kA. | P2: =_xlfn.TEXTJOIN(", ",TRUE(),IF(COUNTIF(BOM!$P$3:$P$25,$Q2)>0,"ЩР.2",""),IF(COUNTIF(BOM!$P$28:$P$42,$Q2)>0,"ЩР.1",""),IF(COUNTIF(BOM!$P$45:$P$64,$Q2)>0,"ЩУ.1",""),IF(COUNTIF(BOM!$P$67:$P$88,$Q2)>0,"ЩУ.2",""),IF(COUNTIF(BOM!$P$91:$P$104,$Q2)>0,"ЩО.1","")) -> ЩР.2, ЩУ.2 | Q2: CHINT-NXM125S3P125
A3: 2 | B3: MCCB | C3: 131361 | D3: Авт. выкл. NXM-125S/3Р 80A 25кА (R) | E3: 19418 | F3: =IF($E3="","",IF(INDEX(MARKA_TIP,MATCH($J3,MARKA_AD,0))="NET",$E3,$E3*INDEX(MARKA_KAT,MATCH($J3,MARKA_AD,0))*INDEX(KUR_DEG,MATCH($I3,KUR_AD,0)))) -> 11650.8 | G3: =SUMIF(BOM!$P:$P,$Q3,BOM!$I:$I) -> 1 | H3: =IF($F3="","",$F3*$G3) -> 11650.8 | I3: =IF($E3="","",INDEX(MARKA_PARA,MATCH($J3,MARKA_AD,0))) -> KZT | J3: CHINT | K3: =IF($E3="","",INDEX(MARKA_KAT,MATCH($J3,MARKA_AD,0))) -> 0.6 | L3: шт | M3: birlesik.csv (CHINT) ARTIKUL 131361 | N3: OK | O3: Eski NM1-125S serisi yerine NXM-125S serisine gecildi (kullanici talebi), ayni akim/kA. | P3: =_xlfn.TEXTJOIN(", ",TRUE(),IF(COUNTIF(BOM!$P$3:$P$25,$Q3)>0,"ЩР.2",""),IF(COUNTIF(BOM!$P$28:$P$42,$Q3)>0,"ЩР.1",""),IF(COUNTIF(BOM!$P$45:$P$64,$Q3)>0,"ЩУ.1",""),IF(COUNTIF(BOM!$P$67:$P$88,$Q3)>0,"ЩУ.2",""),IF(COUNTIF(BOM!$P$91:$P$104,$Q3)>0,"ЩО.1","")) -> ЩР.2 | Q3: CHINT-NXM125S3P80
A4: 3 | B4: DIF | C4: 105544 | D4: Диф. авт. выкл. NXBLE-63Y 1P+N 25А 30mA электронный тип AC, х-ка С, 4.5kA | E4: 4939 | F4: =IF($E4="","",IF(INDEX(MARKA_TIP,MATCH($J4,MARKA_AD,0))="NET",$E4,$E4*INDEX(MARKA_KAT,MATCH($J4,MARKA_AD,0))*INDEX(KUR_DEG,MATCH($I4,KUR_AD,0)))) -> 2963.4 | G4: =SUMIF(BOM!$P:$P,$Q4,BOM!$I:$I) -> 42 | H4: =IF($F4="","",$F4*$G4) -> 124462.8 | I4: =IF($E4="","",INDEX(MARKA_PARA,MATCH($J4,MARKA_AD,0))) -> KZT | J4: CHINT | K4: =IF($E4="","",INDEX(MARKA_KAT,MATCH($J4,MARKA_AD,0))) -> 0.6 | L4: шт | M4: birlesik.csv (CHINT 260827) ARTIKUL 105544 | N4: OK | P4: =_xlfn.TEXTJOIN(", ",TRUE(),IF(COUNTIF(BOM!$P$3:$P$25,$Q4)>0,"ЩР.2",""),IF(COUNTIF(BOM!$P$28:$P$42,$Q4)>0,"ЩР.1",""),IF(COUNTIF(BOM!$P$45:$P$64,$Q4)>0,"ЩУ.1",""),IF(COUNTIF(BOM!$P$67:$P$88,$Q4)>0,"ЩУ.2",""),IF(COUNTIF(BOM!$P$91:$P$104,$Q4)>0,"ЩО.1","")) -> ЩР.2, ЩР.1 | Q4: CHINT-NXBLE63Y-1PN25-30
A5: 4 | B5: MCB | C5: 296831 | D5: Авт. выкл. NXB-63S 3P 40А 4.5kA х-ка C | E5: 2807 | F5: =IF($E5="","",IF(INDEX(MARKA_TIP,MATCH($J5,MARKA_AD,0))="NET",$E5,$E5*INDEX(MARKA_KAT,MATCH($J5,MARKA_AD,0))*INDEX(KUR_DEG,MATCH($I5,KUR_AD,0)))) -> 1684.2 | G5: =SUMIF(BOM!$P:$P,$Q5,BOM!$I:$I) -> 4 | H5: =IF($F5="","",$F5*$G5) -> 6736.8 | I5: =IF($E5="","",INDEX(MARKA_PARA,MATCH($J5,MARKA_AD,0))) -> KZT | J5: CHINT | K5: =IF($E5="","",INDEX(MARKA_KAT,MATCH($J5,MARKA_AD,0))) -> 0.6 | L5: шт | M5: birlesik.csv (CHINT 260827) ARTIKUL 296831 | N5: OK | P5: =_xlfn.TEXTJOIN(", ",TRUE(),IF(COUNTIF(BOM!$P$3:$P$25,$Q5)>0,"ЩР.2",""),IF(COUNTIF(BOM!$P$28:$P$42,$Q5)>0,"ЩР.1",""),IF(COUNTIF(BOM!$P$45:$P$64,$Q5)>0,"ЩУ.1",""),IF(COUNTIF(BOM!$P$67:$P$88,$Q5)>0,"ЩУ.2",""),IF(COUNTIF(BOM!$P$91:$P$104,$Q5)>0,"ЩО.1","")) -> ЩР.2, ЩУ.1 | Q5: CHINT-NXB63S-3P40C
A6: 5 | B6: UZO | C6: 200325 | D6: УЗО NL1-63 6kA 4P 63A 30mA тип AC | E6: 19129 | F6: =IF($E6="","",IF(INDEX(MARKA_TIP,MATCH($J6,MARKA_AD,0))="NET",$E6,$E6*INDEX(MARKA_KAT,MATCH($J6,MARKA_AD,0))*INDEX(KUR_DEG,MATCH($I6,KUR_AD,0)))) -> 11477.4 | G6: =SUMIF(BOM!$P:$P,$Q6,BOM!$I:$I) -> 2 | H6: =IF($F6="","",$F6*$G6) -> 22954.8 | I6: =IF($E6="","",INDEX(MARKA_PARA,MATCH($J6,MARKA_AD,0))) -> KZT | J6: CHINT | K6: =IF($E6="","",INDEX(MARKA_KAT,MATCH($J6,MARKA_AD,0))) -> 0.6 | L6: шт | M6: birlesik.csv (CHINT 260827) ARTIKUL 200325 | N6: OK | P6: =_xlfn.TEXTJOIN(", ",TRUE(),IF(COUNTIF(BOM!$P$3:$P$25,$Q6)>0,"ЩР.2",""),IF(COUNTIF(BOM!$P$28:$P$42,$Q6)>0,"ЩР.1",""),IF(COUNTIF(BOM!$P$45:$P$64,$Q6)>0,"ЩУ.1",""),IF(COUNTIF(BOM!$P$67:$P$88,$Q6)>0,"ЩУ.2",""),IF(COUNTIF(BOM!$P$91:$P$104,$Q6)>0,"ЩО.1","")) -> ЩР.2 | Q6: CHINT-NL163-4P63-30AC
A7: 6 | B7: MCB | C7: 814012 | D7: Авт. выкл. NXB-63 1P 6A 6кА х-ка C | E7: 1436 | F7: =IF($E7="","",IF(INDEX(MARKA_TIP,MATCH($J7,MARKA_AD,0))="NET",$E7,$E7*INDEX(MARKA_KAT,MATCH($J7,MARKA_AD,0))*INDEX(KUR_DEG,MATCH($I7,KUR_AD,0)))) -> 861.6 | G7: =SUMIF(BOM!$P:$P,$Q7,BOM!$I:$I) -> 1 | H7: =IF($F7="","",$F7*$G7) -> 861.6 | I7: =IF($E7="","",INDEX(MARKA_PARA,MATCH($J7,MARKA_AD,0))) -> KZT | J7: CHINT | K7: =IF($E7="","",INDEX(MARKA_KAT,MATCH($J7,MARKA_AD,0))) -> 0.6 | L7: шт | M7: birlesik.csv (CHINT 260827) ARTIKUL 814012 | N7: VARSAYIM | O7: otomatik eklendi: kumanda/sayac koruma MCB | P7: =_xlfn.TEXTJOIN(", ",TRUE(),IF(COUNTIF(BOM!$P$3:$P$25,$Q7)>0,"ЩР.2",""),IF(COUNTIF(BOM!$P$28:$P$42,$Q7)>0,"ЩР.1",""),IF(COUNTIF(BOM!$P$45:$P$64,$Q7)>0,"ЩУ.1",""),IF(COUNTIF(BOM!$P$67:$P$88,$Q7)>0,"ЩУ.2",""),IF(COUNTIF(BOM!$P$91:$P$104,$Q7)>0,"ЩО.1","")) -> ЩР.2, ЩР.1, ЩУ.1, ЩУ.2 | Q7: CHINT-NXB63-1P6C
A8: 7 | B8: BARA | C8: 811004 | D8: Шина соединительная типа PIN 1P, 100А, L=1000мм | E8: 5972 | F8: =IF($E8="","",IF(INDEX(MARKA_TIP,MATCH($J8,MARKA_AD,0))="NET",$E8,$E8*INDEX(MARKA_KAT,MATCH($J8,MARKA_AD,0))*INDEX(KUR_DEG,MATCH($I8,KUR_AD,0)))) -> 3583.2 | G8: =SUMIF(BOM!$P:$P,$Q8,BOM!$I:$I) -> 4 | H8: =IF($F8="","",$F8*$G8) -> 14332.8 | I8: =IF($E8="","",INDEX(MARKA_PARA,MATCH($J8,MARKA_AD,0))) -> KZT | J8: CHINT | K8: =IF($E8="","",INDEX(MARKA_KAT,MATCH($J8,MARKA_AD,0))) -> 0.6 | L8: шт | M8: birlesik.csv (CHINT 260827) ARTIKUL 811004 | N8: VARSAYIM | O8: tarak/pin bara - Q'ya hesap | P8: =_xlfn.TEXTJOIN(", ",TRUE(),IF(COUNTIF(BOM!$P$3:$P$25,$Q8)>0,"ЩР.2",""),IF(COUNTIF(BOM!$P$28:$P$42,$Q8)>0,"ЩР.1",""),IF(COUNTIF(BOM!$P$45:$P$64,$Q8)>0,"ЩУ.1",""),IF(COUNTIF(BOM!$P$67:$P$88,$Q8)>0,"ЩУ.2",""),IF(COUNTIF(BOM!$P$91:$P$104,$Q8)>0,"ЩО.1","")) -> ЩР.2, ЩР.1 | Q8: CHINT-PINBUS-1P100A
A9: 8 | B9: KORPUS | C9: 714-15112 | D9: Щит мет. ЩРн-7-2 PR (1320x750x300) IP54 (TS) | E9: 73730 | F9: =IF($E9="","",IF(INDEX(MARKA_TIP,MATCH($J9,MARKA_AD,0))="NET",$E9,$E9*INDEX(MARKA_KAT,MATCH($J9,MARKA_AD,0))*INDEX(KUR_DEG,MATCH($I9,KUR_AD,0)))) -> 44238 | G9: =SUMIF(BOM!$P:$P,$Q9,BOM!$I:$I) -> 1 | H9: =IF($F9="","",$F9*$G9) -> 44238 | I9: =IF($E9="","",INDEX(MARKA_PARA,MATCH($J9,MARKA_AD,0))) -> KZT | J9: KAZTEK | K9: =IF($E9="","",INDEX(MARKA_KAT,MATCH($J9,MARKA_AD,0))) -> 0.6 | L9: шт | M9: Kaztek resmi liste (2607 15 Kaztek pano fiyat listesi.XLSX) ARTIKUL 714-15121 | N9: VARSAYIM | O9: ONCEKI SECIM (ЩРН-72, 660x440x120) YANLIS: panoda 2 adet MCCB (NXM-125S govdeli ana giris+alt salter) VE dogrudan baglantili sayac var - 120mm derinlik MCCB kablo payi ve sayac montaji icin YETERSIZ. 650x500x220 IP31'e yukseltildi (derinlik 120->220mm). Modul kapasitesi teyit edilmedi, benzer/daha genis taban alani nedeniyle en az eski ЩРН-72 kadar (72 modul) kabul edildi - TEYIT GEREKIR. | P9: =_xlfn.TEXTJOIN(", ",TRUE(),IF(COUNTIF(BOM!$P$3:$P$25,$Q9)>0,"ЩР.2",""),IF(COUNTIF(BOM!$P$28:$P$42,$Q9)>0,"ЩР.1",""),IF(COUNTIF(BOM!$P$45:$P$64,$Q9)>0,"ЩУ.1",""),IF(COUNTIF(BOM!$P$67:$P$88,$Q9)>0,"ЩУ.2",""),IF(COUNTIF(BOM!$P$91:$P$104,$Q9)>0,"ЩО.1","")) -> ЩР.2 | Q9: KAZTEK-SHRN3-650X500X220
A10: 9 | B10: KORPUS | C10: 719-15560 | D10: Мет. Корпус ЩМП-3 (650x500x150) IP31 | E10: 25050 | F10: =IF($E10="","",IF(INDEX(MARKA_TIP,MATCH($J10,MARKA_AD,0))="NET",$E10,$E10*INDEX(MARKA_KAT,MATCH($J10,MARKA_AD,0))*INDEX(KUR_DEG,MATCH($I10,KUR_AD,0)))) -> 15030 | G10: =SUMIF(BOM!$P:$P,$Q10,BOM!$I:$I) -> 1 | H10: =IF($F10="","",$F10*$G10) -> 15030 | I10: =IF($E10="","",INDEX(MARKA_PARA,MATCH($J10,MARKA_AD,0))) -> KZT | J10: KAZTEK | K10: =IF($E10="","",INDEX(MARKA_KAT,MATCH($J10,MARKA_AD,0))) -> 0.6 | L10: шт | M10: Kaztek resmi liste (2607 15 Kaztek pano fiyat listesi.XLSX) ARTIKUL 719-15560 | N10: VARSAYIM | O10: ONCEKI SECIM (ЩРН-72, 660x440x120) YANLIS: panoda 1 adet MCCB (NXM-63S govdeli ana giris, muadil 40A) var - 120mm derinlik MCCB kablo payi icin YETERSIZ. Sayac yok, bu yuzden ЩР.2'ye gore daha az derinlik (150mm) yeterli kabul edildi. Modul kapasitesi teyit edilmedi, en az eski ЩРН-72 kadar (72 modul) kabul edildi - TEYIT GEREKIR. | P10: =_xlfn.TEXTJOIN(", ",TRUE(),IF(COUNTIF(BOM!$P$3:$P$25,$Q10)>0,"ЩР.2",""),IF(COUNTIF(BOM!$P$28:$P$42,$Q10)>0,"ЩР.1",""),IF(COUNTIF(BOM!$P$45:$P$64,$Q10)>0,"ЩУ.1",""),IF(COUNTIF(BOM!$P$67:$P$88,$Q10)>0,"ЩУ.2",""),IF(COUNTIF(BOM!$P$91:$P$104,$Q10)>0,"ЩО.1","")) -> ЩР.1 | Q10: KAZTEK-SMP3-650X500X150
A11: 10 | B11: SAYAC | C11: 200200048 | D11: Счетчик LM СА4-Э720 Дала 3ф (10-100А) 1 тариф. Т1 (dogrudan, dahili tarifikator) | E11: 39360 | F11: =IF($E11="","",IF(INDEX(MARKA_TIP,MATCH($J11,MARKA_AD,0))="NET",$E11,$E11*INDEX(MARKA_KAT,MATCH($J11,MARKA_AD,0))*INDEX(KUR_DEG,MATCH($I11,KUR_AD,0)))) -> 39360 | G11: =SUMIF(BOM!$P:$P,$Q11,BOM!$I:$I) -> 2 | H11: =IF($F11="","",$F11*$G11) -> 78720 | I11: =IF($E11="","",INDEX(MARKA_PARA,MATCH($J11,MARKA_AD,0))) -> KZT | J11: EKT | K11: =IF($E11="","",INDEX(MARKA_KAT,MATCH($J11,MARKA_AD,0))) -> 1 | L11: шт | M11: birlesik.csv (EKT/Saiman 250612) ARTIKUL 200200048 | N11: MUADIL | O11: kod LM - SHR.2'de 'R T1' notasyonu tam eslesmiyor; SHU.1'de kod LM birebir eslesiyor | P11: =_xlfn.TEXTJOIN(", ",TRUE(),IF(COUNTIF(BOM!$P$3:$P$25,$Q11)>0,"ЩР.2",""),IF(COUNTIF(BOM!$P$28:$P$42,$Q11)>0,"ЩР.1",""),IF(COUNTIF(BOM!$P$45:$P$64,$Q11)>0,"ЩУ.1",""),IF(COUNTIF(BOM!$P$67:$P$88,$Q11)>0,"ЩУ.2",""),IF(COUNTIF(BOM!$P$91:$P$104,$Q11)>0,"ЩО.1","")) -> ЩР.2, ЩУ.1 | Q11: EKT-SAYAC-DALA-10-100
A12: 11 | B12: BARA | C12: YNN10-69-24D-K07 | D12: Шина N ноль DIN-изол ШНИ-6х9-24-Д-С | E12: 900 | F12: =IF($E12="","",IF(INDEX(MARKA_TIP,MATCH($J12,MARKA_AD,0))="NET",$E12,$E12*INDEX(MARKA_KAT,MATCH($J12,MARKA_AD,0))*INDEX(KUR_DEG,MATCH($I12,KUR_AD,0)))) -> 900 | G12: =SUMIF(BOM!$P:$P,$Q12,BOM!$I:$I) -> 5 | H12: =IF($F12="","",$F12*$G12) -> 4500 | I12: =IF($E12="","",INDEX(MARKA_PARA,MATCH($J12,MARKA_AD,0))) -> KZT | J12: EKT | K12: =IF($E12="","",INDEX(MARKA_KAT,MATCH($J12,MARKA_AD,0))) -> 1 | L12: шт | M12: birlesik.csv (EKT 250612) | N12: VARSAYIM | O12: izoleli notr barasi - her panoda zorunlu | P12: =_xlfn.TEXTJOIN(", ",TRUE(),IF(COUNTIF(BOM!$P$3:$P$25,$Q12)>0,"ЩР.2",""),IF(COUNTIF(BOM!$P$28:$P$42,$Q12)>0,"ЩР.1",""),IF(COUNTIF(BOM!$P$45:$P$64,$Q12)>0,"ЩУ.1",""),IF(COUNTIF(BOM!$P$67:$P$88,$Q12)>0,"ЩУ.2",""),IF(COUNTIF(BOM!$P$91:$P$104,$Q12)>0,"ЩО.1","")) -> ЩР.2, ЩР.1, ЩУ.1, ЩУ.2, ЩО.1 | Q12: EKT-SHINA-N24
A13: 12 | B13: BARA | C13: 130200401 | D13: Шина PE земля ШНИ 6х9 12-К-З | E13: 514 | F13: =IF($E13="","",IF(INDEX(MARKA_TIP,MATCH($J13,MARKA_AD,0))="NET",$E13,$E13*INDEX(MARKA_KAT,MATCH($J13,MARKA_AD,0))*INDEX(KUR_DEG,MATCH($I13,KUR_AD,0)))) -> 514 | G13: =SUMIF(BOM!$P:$P,$Q13,BOM!$I:$I) -> 5 | H13: =IF($F13="","",$F13*$G13) -> 2570 | I13: =IF($E13="","",INDEX(MARKA_PARA,MATCH($J13,MARKA_AD,0))) -> KZT | J13: EKT | K13: =IF($E13="","",INDEX(MARKA_KAT,MATCH($J13,MARKA_AD,0))) -> 1 | L13: шт | M13: birlesik.csv (EKT 250612) | N13: VARSAYIM | O13: ГЗШ topraklama barasi - her panoda zorunlu | P13: =_xlfn.TEXTJOIN(", ",TRUE(),IF(COUNTIF(BOM!$P$3:$P$25,$Q13)>0,"ЩР.2",""),IF(COUNTIF(BOM!$P$28:$P$42,$Q13)>0,"ЩР.1",""),IF(COUNTIF(BOM!$P$45:$P$64,$Q13)>0,"ЩУ.1",""),IF(COUNTIF(BOM!$P$67:$P$88,$Q13)>0,"ЩУ.2",""),IF(COUNTIF(BOM!$P$91:$P$104,$Q13)>0,"ЩО.1","")) -> ЩР.2, ЩР.1, ЩУ.1, ЩУ.2, ЩО.1 | Q13: EKT-SHINA-PE12
A14: 13 | B14: DIN | C14: YDN10-0100 | D14: DIN-рейка (100см) оцинкованная | E14: 686 | F14: =IF($E14="","",IF(INDEX(MARKA_TIP,MATCH($J14,MARKA_AD,0))="NET",$E14,$E14*INDEX(MARKA_KAT,MATCH($J14,MARKA_AD,0))*INDEX(KUR_DEG,MATCH($I14,KUR_AD,0)))) -> 686 | G14: =SUMIF(BOM!$P:$P,$Q14,BOM!$I:$I) -> 0 | H14: =IF($F14="","",$F14*$G14) -> 0 | I14: =IF($E14="","",INDEX(MARKA_PARA,MATCH($J14,MARKA_AD,0))) -> KZT | J14: EKT | K14: =IF($E14="","",INDEX(MARKA_KAT,MATCH($J14,MARKA_AD,0))) -> 1 | L14: шт | M14: birlesik.csv (EKT 250612) | N14: VARSAYIM | O14: otomatik hesap - Q'ya metraj | P14: =_xlfn.TEXTJOIN(", ",TRUE(),IF(COUNTIF(BOM!$P$3:$P$25,$Q14)>0,"ЩР.2",""),IF(COUNTIF(BOM!$P$28:$P$42,$Q14)>0,"ЩР.1",""),IF(COUNTIF(BOM!$P$45:$P$64,$Q14)>0,"ЩУ.1",""),IF(COUNTIF(BOM!$P$67:$P$88,$Q14)>0,"ЩУ.2",""),IF(COUNTIF(BOM!$P$91:$P$104,$Q14)>0,"ЩО.1","")) -> ЩР.2, ЩР.1, ЩУ.1, ЩУ.2, ЩО.1 | Q14: EKT-DINRAY-100
A15: 14 | B15: KANAL | C15: 280100252 | D15: Кабель-канал 40х40 белый | E15: 238 | F15: =IF($E15="","",IF(INDEX(MARKA_TIP,MATCH($J15,MARKA_AD,0))="NET",$E15,$E15*INDEX(MARKA_KAT,MATCH($J15,MARKA_AD,0))*INDEX(KUR_DEG,MATCH($I15,KUR_AD,0)))) -> 238 | G15: =SUMIF(BOM!$P:$P,$Q15,BOM!$I:$I) -> 6 | H15: =IF($F15="","",$F15*$G15) -> 1428 | I15: =IF($E15="","",INDEX(MARKA_PARA,MATCH($J15,MARKA_AD,0))) -> KZT | J15: EKT | K15: =IF($E15="","",INDEX(MARKA_KAT,MATCH($J15,MARKA_AD,0))) -> 1 | L15: м | M15: birlesik.csv (EKT 250612) | N15: VARSAYIM | O15: otomatik hesap - Q'ya metraj | P15: =_xlfn.TEXTJOIN(", ",TRUE(),IF(COUNTIF(BOM!$P$3:$P$25,$Q15)>0,"ЩР.2",""),IF(COUNTIF(BOM!$P$28:$P$42,$Q15)>0,"ЩР.1",""),IF(COUNTIF(BOM!$P$45:$P$64,$Q15)>0,"ЩУ.1",""),IF(COUNTIF(BOM!$P$67:$P$88,$Q15)>0,"ЩУ.2",""),IF(COUNTIF(BOM!$P$91:$P$104,$Q15)>0,"ЩО.1","")) -> ЩР.2, ЩР.1 | Q15: EKT-KANAL-40X40
A16: 15 | B16: KABLO | C16: 100300025 | D16: ПВ3-2,5 белый ГОСТ (pano ici kablo) | E16: 144 | F16: =IF($E16="","",IF(INDEX(MARKA_TIP,MATCH($J16,MARKA_AD,0))="NET",$E16,$E16*INDEX(MARKA_KAT,MATCH($J16,MARKA_AD,0))*INDEX(KUR_DEG,MATCH($I16,KUR_AD,0)))) -> 144 | G16: =SUMIF(BOM!$P:$P,$Q16,BOM!$I:$I) -> 31 | H16: =IF($F16="","",$F16*$G16) -> 4464 | I16: =IF($E16="","",INDEX(MARKA_PARA,MATCH($J16,MARKA_AD,0))) -> KZT | J16: EKT | K16: =IF($E16="","",INDEX(MARKA_KAT,MATCH($J16,MARKA_AD,0))) -> 1 | L16: м | M16: birlesik.csv (EKT 250612) | N16: VARSAYIM | O16: otomatik hesap - Q'ya metraj | P16: =_xlfn.TEXTJOIN(", ",TRUE(),IF(COUNTIF(BOM!$P$3:$P$25,$Q16)>0,"ЩР.2",""),IF(COUNTIF(BOM!$P$28:$P$42,$Q16)>0,"ЩР.1",""),IF(COUNTIF(BOM!$P$45:$P$64,$Q16)>0,"ЩУ.1",""),IF(COUNTIF(BOM!$P$67:$P$88,$Q16)>0,"ЩУ.2",""),IF(COUNTIF(BOM!$P$91:$P$104,$Q16)>0,"ЩО.1","")) -> ЩР.2, ЩУ.2, ЩО.1 | Q16: EKT-PVGV-2.5
A17: 16 | B17: KABLO | C17: 100300030 | D17: ПВ3-4 белый ГОСТ (pano ici kablo) | E17: 242 | F17: =IF($E17="","",IF(INDEX(MARKA_TIP,MATCH($J17,MARKA_AD,0))="NET",$E17,$E17*INDEX(MARKA_KAT,MATCH($J17,MARKA_AD,0))*INDEX(KUR_DEG,MATCH($I17,KUR_AD,0)))) -> 242 | G17: =SUMIF(BOM!$P:$P,$Q17,BOM!$I:$I) -> 59 | H17: =IF($F17="","",$F17*$G17) -> 14278 | I17: =IF($E17="","",INDEX(MARKA_PARA,MATCH($J17,MARKA_AD,0))) -> KZT | J17: EKT | K17: =IF($E17="","",INDEX(MARKA_KAT,MATCH($J17,MARKA_AD,0))) -> 1 | L17: м | M17: birlesik.csv (EKT 250612) | N17: VARSAYIM | O17: otomatik hesap - Q'ya metraj | P17: =_xlfn.TEXTJOIN(", ",TRUE(),IF(COUNTIF(BOM!$P$3:$P$25,$Q17)>0,"ЩР.2",""),IF(COUNTIF(BOM!$P$28:$P$42,$Q17)>0,"ЩР.1",""),IF(COUNTIF(BOM!$P$45:$P$64,$Q17)>0,"ЩУ.1",""),IF(COUNTIF(BOM!$P$67:$P$88,$Q17)>0,"ЩУ.2",""),IF(COUNTIF(BOM!$P$91:$P$104,$Q17)>0,"ЩО.1","")) -> ЩР.2, ЩР.1, ЩУ.2, ЩО.1 | Q17: EKT-PVGV-4
A18: 17 | B18: KABLO | C18: 100300031 | D18: ПВ3-6 белый ГОСТ (pano ici kablo) | E18: 361 | F18: =IF($E18="","",IF(INDEX(MARKA_TIP,MATCH($J18,MARKA_AD,0))="NET",$E18,$E18*INDEX(MARKA_KAT,MATCH($J18,MARKA_AD,0))*INDEX(KUR_DEG,MATCH($I18,KUR_AD,0)))) -> 361 | G18: =SUMIF(BOM!$P:$P,$Q18,BOM!$I:$I) -> 17 | H18: =IF($F18="","",$F18*$G18) -> 6137 | I18: =IF($E18="","",INDEX(MARKA_PARA,MATCH($J18,MARKA_AD,0))) -> KZT | J18: EKT | K18: =IF($E18="","",INDEX(MARKA_KAT,MATCH($J18,MARKA_AD,0))) -> 1 | L18: м | M18: birlesik.csv (EKT 250612) | N18: VARSAYIM | O18: otomatik hesap - Q'ya metraj | P18: =_xlfn.TEXTJOIN(", ",TRUE(),IF(COUNTIF(BOM!$P$3:$P$25,$Q18)>0,"ЩР.2",""),IF(COUNTIF(BOM!$P$28:$P$42,$Q18)>0,"ЩР.1",""),IF(COUNTIF(BOM!$P$45:$P$64,$Q18)>0,"ЩУ.1",""),IF(COUNTIF(BOM!$P$67:$P$88,$Q18)>0,"ЩУ.2",""),IF(COUNTIF(BOM!$P$91:$P$104,$Q18)>0,"ЩО.1","")) -> ЩР.2, ЩР.1, ЩУ.1 | Q18: EKT-PVGV-6
... A23: 22 | B23: YUKSUK | C23: 260200024 | D23: Наконечник-гильза Е4009 4мм2 izole (100 ad/paket) | E23: 1245 | F23: =IF($E23="","",IF(INDEX(MARKA_TIP,MATCH($J23,MARKA_AD,0))="NET",$E23,$E23*INDEX(MARKA_KAT,MATCH($J23,MARKA_AD,0))*INDEX(KUR_DEG,MATCH($I23,KUR_AD,0)))) -> 1245 | G23: =SUMIF(BOM!$P:$P,$Q23,BOM!$I:$I) -> 6 | H23: =IF($F23="","",$F23*$G23) -> 7470 | I23: =IF($E23="","",INDEX(MARKA_PARA,MATCH($J23,MARKA_AD,0))) -> KZT | J23: EKT | K23: =IF($E23="","",INDEX(MARKA_KAT,MATCH($J23,MARKA_AD,0))) -> 1 | L23: упак | M23: birlesik.csv (EKT 250612) ARTIKUL 260200024 | N23: VARSAYIM | O23: <=10mm2 uc yuksugu - otomatik, 1 paket=100ad | P23: =_xlfn.TEXTJOIN(", ",TRUE(),IF(COUNTIF(BOM!$P$3:$P$25,$Q23)>0,"ЩР.2",""),IF(COUNTIF(BOM!$P$28:$P$42,$Q23)>0,"ЩР.1",""),IF(COUNTIF(BOM!$P$45:$P$64,$Q23)>0,"ЩУ.1",""),IF(COUNTIF(BOM!$P$67:$P$88,$Q23)>0,"ЩУ.2",""),IF(COUNTIF(BOM!$P$91:$P$104,$Q23)>0,"ЩО.1","")) -> ЩР.2, ЩР.1, ЩУ.1, ЩУ.2, ЩО.1 | Q23: EKT-YUKSUK-4MM-PAK100
A24: 23 | B24: MONTAJ | C24: MONTAJ-MALZEME-KOMPLE | D24: Montaj malzemesi (etiket, sema cebi, kilit-menteşe, numaralandirma, vida-dubel takimi) | G24: =SUMIF(BOM!$P:$P,$Q24,BOM!$I:$I) -> 5 | H24: =IF($F24="","",$F24*$G24) | I24: =IF($E24="","",INDEX(MARKA_PARA,MATCH($J24,MARKA_AD,0))) | J24: YOK | K24: =IF($E24="","",INDEX(MARKA_KAT,MATCH($J24,MARKA_AD,0))) | L24: шт | N24: FIYAT_YOK | O24: katalogda net eslesme yok - fiyat girilecek | P24: =_xlfn.TEXTJOIN(", ",TRUE(),IF(COUNTIF(BOM!$P$3:$P$25,$Q24)>0,"ЩР.2",""),IF(COUNTIF(BOM!$P$28:$P$42,$Q24)>0,"ЩР.1",""),IF(COUNTIF(BOM!$P$45:$P$64,$Q24)>0,"ЩУ.1",""),IF(COUNTIF(BOM!$P$67:$P$88,$Q24)>0,"ЩУ.2",""),IF(COUNTIF(BOM!$P$91:$P$104,$Q24)>0,"ЩО.1","")) -> ЩР.2, ЩР.1, ЩУ.1, ЩУ.2, ЩО.1 | Q24: MONTAJ-MALZEME-KOMPLE
A25: 24 | B25: ISCILIK | C25: ISCILIK-MONTAJ | D25: Montaj + test + etiketleme iscilik | E25: =KURALLAR!$B$29 -> 6000 | F25: =KURALLAR!$B$30 -> 100 | G25: =SUMIF(BOM!$P:$P,$Q25,BOM!$I:$I) -> 575 | H25: =IF($F25="","",$F25*$G25) -> 57500 | I25: =IF($E25="","",INDEX(MARKA_PARA,MATCH($J25,MARKA_AD,0))) -> KZT | J25: ISCILIK | K25: =IF($E25="","",INDEX(MARKA_KAT,MATCH($J25,MARKA_AD,0))) -> 1 | L25: мин. | M25: KURALLAR ISCILIK_SAAT_UCRETI(bilgi,saat)+ISCILIK_G_SABIT(dakika ucreti,100 KZT) | N25: VARSAYIM | O25: dakika bazli iscilik: FIYAT!LISTE_FIYAT=saat ucreti(bilgi), NET_KZT=dakika ucreti(100 KZT, gercek hesap), Qty=dakika. Q'ya hesap | P25: =_xlfn.TEXTJOIN(", ",TRUE(),IF(COUNTIF(BOM!$P$3:$P$25,$Q25)>0,"ЩР.2",""),IF(COUNTIF(BOM!$P$28:$P$42,$Q25)>0,"ЩР.1",""),IF(COUNTIF(BOM!$P$45:$P$64,$Q25)>0,"ЩУ.1",""),IF(COUNTIF(BOM!$P$67:$P$88,$Q25)>0,"ЩУ.2",""),IF(COUNTIF(BOM!$P$91:$P$104,$Q25)>0,"ЩО.1","")) -> ЩР.2, ЩР.1, ЩУ.1, ЩУ.2, ЩО.1 | Q25: ISCILIK-MONTAJ
A26: 25 | B26: MCCB | C26: 205886 | D26: Авт. выкл. NXM-63S/3Р 32A 25кА (R) | E26: 17405 | F26: =IF($E26="","",IF(INDEX(MARKA_TIP,MATCH($J26,MARKA_AD,0))="NET",$E26,$E26*INDEX(MARKA_KAT,MATCH($J26,MARKA_AD,0))*INDEX(KUR_DEG,MATCH($I26,KUR_AD,0)))) -> 10443 | G26: =SUMIF(BOM!$P:$P,$Q26,BOM!$I:$I) -> 1 | H26: =IF($F26="","",$F26*$G26) -> 10443 | I26: =IF($E26="","",INDEX(MARKA_PARA,MATCH($J26,MARKA_AD,0))) -> KZT | J26: CHINT | K26: =IF($E26="","",INDEX(MARKA_KAT,MATCH($J26,MARKA_AD,0))) -> 0.6 | L26: шт | M26: birlesik.csv (CHINT) ARTIKUL 205886 | N26: OK | O26: Eski NM1-63S serisinde 32A trip yoktu (FIYAT_YOK idi); NXM-63S serisine gecilince (kullanici talebi) TAM ESLESEN 32A bulundu, istenen deger artik gercek urunle karsilaniyor. | P26: =_xlfn.TEXTJOIN(", ",TRUE(),IF(COUNTIF(BOM!$P$3:$P$25,$Q26)>0,"ЩР.2",""),IF(COUNTIF(BOM!$P$28:$P$42,$Q26)>0,"ЩР.1",""),IF(COUNTIF(BOM!$P$45:$P$64,$Q26)>0,"ЩУ.1",""),IF(COUNTIF(BOM!$P$67:$P$88,$Q26)>0,"ЩУ.2",""),IF(COUNTIF(BOM!$P$91:$P$104,$Q26)>0,"ЩО.1","")) -> ЩР.1 | Q26: CHINT-NXM63S3P32
A27: 26 | B27: MCB | C27: 296833 | D27: Авт. выкл. NXB-63S 3P 63А 4.5kA х-ка C | E27: 3641 | F27: =IF($E27="","",IF(INDEX(MARKA_TIP,MATCH($J27,MARKA_AD,0))="NET",$E27,$E27*INDEX(MARKA_KAT,MATCH($J27,MARKA_AD,0))*INDEX(KUR_DEG,MATCH($I27,KUR_AD,0)))) -> 2184.6 | G27: =SUMIF(BOM!$P:$P,$Q27,BOM!$I:$I) -> 1 | H27: =IF($F27="","",$F27*$G27) -> 2184.6 | I27: =IF($E27="","",INDEX(MARKA_PARA,MATCH($J27,MARKA_AD,0))) -> KZT | J27: CHINT | K27: =IF($E27="","",INDEX(MARKA_KAT,MATCH($J27,MARKA_AD,0))) -> 0.6 | L27: шт | M27: birlesik.csv (CHINT 260827) ARTIKUL 296833 | N27: OK | P27: =_xlfn.TEXTJOIN(", ",TRUE(),IF(COUNTIF(BOM!$P$3:$P$25,$Q27)>0,"ЩР.2",""),IF(COUNTIF(BOM!$P$28:$P$42,$Q27)>0,"ЩР.1",""),IF(COUNTIF(BOM!$P$45:$P$64,$Q27)>0,"ЩУ.1",""),IF(COUNTIF(BOM!$P$67:$P$88,$Q27)>0,"ЩУ.2",""),IF(COUNTIF(BOM!$P$91:$P$104,$Q27)>0,"ЩО.1","")) -> ЩУ.1 | Q27: CHINT-NXB63S-3P63C
A28: 27 | B28: DIF | C28: CHINT-NXBLE125-3PN50-30 | D28: Диф. автомат NXBLE-125 3P+N 50A х-ка C 30mA | F28: =IF($E28="","",IF(INDEX(MARKA_TIP,MATCH($J28,MARKA_AD,0))="NET",$E28,$E28*INDEX(MARKA_KAT,MATCH($J28,MARKA_AD,0))*INDEX(KUR_DEG,MATCH($I28,KUR_AD,0)))) | G28: =SUMIF(BOM!$P:$P,$Q28,BOM!$I:$I) -> 1 | H28: =IF($F28="","",$F28*$G28) | I28: =IF($E28="","",INDEX(MARKA_PARA,MATCH($J28,MARKA_AD,0))) | J28: CHINT | K28: =IF($E28="","",INDEX(MARKA_KAT,MATCH($J28,MARKA_AD,0))) | L28: шт | N28: FIYAT_YOK | O28: SHU.1 semasinda istenen deger (50A C 30mA) korundu - DEGISTIRILMEDI. Katalogda bu kademe/hassasiyette SADECE 80A/300mA (yangin tipi) var, kisi korumali 50A/30mA versiyonu yok; fiyat/tedarik teyidi bekleniyor. | P28: =_xlfn.TEXTJOIN(", ",TRUE(),IF(COUNTIF(BOM!$P$3:$P$25,$Q28)>0,"ЩР.2",""),IF(COUNTIF(BOM!$P$28:$P$42,$Q28)>0,"ЩР.1",""),IF(COUNTIF(BOM!$P$45:$P$64,$Q28)>0,"ЩУ.1",""),IF(COUNTIF(BOM!$P$67:$P$88,$Q28)>0,"ЩУ.2",""),IF(COUNTIF(BOM!$P$91:$P$104,$Q28)>0,"ЩО.1","")) -> ЩУ.1 | Q28: CHINT-NXBLE125-3PN50-30
A29: 28 | B29: MCCB | C29: 131362 | D29: Авт. выкл. NXM-125S/3Р 100A 25кА (R) | E29: 19443 | F29: =IF($E29="","",IF(INDEX(MARKA_TIP,MATCH($J29,MARKA_AD,0))="NET",$E29,$E29*INDEX(MARKA_KAT,MATCH($J29,MARKA_AD,0))*INDEX(KUR_DEG,MATCH($I29,KUR_AD,0)))) -> 11665.8 | G29: =SUMIF(BOM!$P:$P,$Q29,BOM!$I:$I) -> 1 | H29: =IF($F29="","",$F29*$G29) -> 11665.8 | I29: =IF($E29="","",INDEX(MARKA_PARA,MATCH($J29,MARKA_AD,0))) -> KZT | J29: CHINT | K29: =IF($E29="","",INDEX(MARKA_KAT,MATCH($J29,MARKA_AD,0))) -> 0.6 | L29: шт | M29: birlesik.csv (CHINT) ARTIKUL 131362 | N29: OK | O29: Eski NM1-125S serisinde 100A trip yoktu (FIYAT_YOK idi); NXM-125S serisine gecilince (kullanici talebi) TAM ESLESEN 100A bulundu, istenen deger artik gercek urunle karsilaniyor. | P29: =_xlfn.TEXTJOIN(", ",TRUE(),IF(COUNTIF(BOM!$P$3:$P$25,$Q29)>0,"ЩР.2",""),IF(COUNTIF(BOM!$P$28:$P$42,$Q29)>0,"ЩР.1",""),IF(COUNTIF(BOM!$P$45:$P$64,$Q29)>0,"ЩУ.1",""),IF(COUNTIF(BOM!$P$67:$P$88,$Q29)>0,"ЩУ.2",""),IF(COUNTIF(BOM!$P$91:$P$104,$Q29)>0,"ЩО.1","")) -> ЩУ.2 | Q29: CHINT-NXM125S3P100
A30: 29 | B30: MCB | C30: 296830 | D30: Авт. выкл. NXB-63S 3P 32А 4.5kA х-ка C | E30: 2606 | F30: =IF($E30="","",IF(INDEX(MARKA_TIP,MATCH($J30,MARKA_AD,0))="NET",$E30,$E30*INDEX(MARKA_KAT,MATCH($J30,MARKA_AD,0))*INDEX(KUR_DEG,MATCH($I30,KUR_AD,0)))) -> 1563.6 | G30: =SUMIF(BOM!$P:$P,$Q30,BOM!$I:$I) -> 2 | H30: =IF($F30="","",$F30*$G30) -> 3127.2 | I30: =IF($E30="","",INDEX(MARKA_PARA,MATCH($J30,MARKA_AD,0))) -> KZT | J30: CHINT | K30: =IF($E30="","",INDEX(MARKA_KAT,MATCH($J30,MARKA_AD,0))) -> 0.6 | L30: шт | M30: birlesik.csv (CHINT 260827) ARTIKUL 296830 | N30: OK | P30: =_xlfn.TEXTJOIN(", ",TRUE(),IF(COUNTIF(BOM!$P$3:$P$25,$Q30)>0,"ЩР.2",""),IF(COUNTIF(BOM!$P$28:$P$42,$Q30)>0,"ЩР.1",""),IF(COUNTIF(BOM!$P$45:$P$64,$Q30)>0,"ЩУ.1",""),IF(COUNTIF(BOM!$P$67:$P$88,$Q30)>0,"ЩУ.2",""),IF(COUNTIF(BOM!$P$91:$P$104,$Q30)>0,"ЩО.1","")) -> ЩУ.1 | Q30: CHINT-NXB63S-3P32C
A31: 30 | B31: MCB | C31: 296829 | D31: Авт. выкл. NXB-63S 3P 25А 4.5kA х-ка C | E31: 2429 | F31: =IF($E31="","",IF(INDEX(MARKA_TIP,MATCH($J31,MARKA_AD,0))="NET",$E31,$E31*INDEX(MARKA_KAT,MATCH($J31,MARKA_AD,0))*INDEX(KUR_DEG,MATCH($I31,KUR_AD,0)))) -> 1457.4 | G31: =SUMIF(BOM!$P:$P,$Q31,BOM!$I:$I) -> 2 | H31: =IF($F31="","",$F31*$G31) -> 2914.8 | I31: =IF($E31="","",INDEX(MARKA_PARA,MATCH($J31,MARKA_AD,0))) -> KZT | J31: CHINT | K31: =IF($E31="","",INDEX(MARKA_KAT,MATCH($J31,MARKA_AD,0))) -> 0.6 | L31: шт | M31: birlesik.csv (CHINT 260827) ARTIKUL 296829 | N31: OK | P31: =_xlfn.TEXTJOIN(", ",TRUE(),IF(COUNTIF(BOM!$P$3:$P$25,$Q31)>0,"ЩР.2",""),IF(COUNTIF(BOM!$P$28:$P$42,$Q31)>0,"ЩР.1",""),IF(COUNTIF(BOM!$P$45:$P$64,$Q31)>0,"ЩУ.1",""),IF(COUNTIF(BOM!$P$67:$P$88,$Q31)>0,"ЩУ.2",""),IF(COUNTIF(BOM!$P$91:$P$104,$Q31)>0,"ЩО.1","")) -> ЩУ.2, ЩО.1 | Q31: CHINT-NXB63S-3P25C
A32: 31 | B32: MCB | C32: 296827 | D32: Авт. выкл. NXB-63S 3P 16А 4.5kA х-ка C | E32: 2337 | F32: =IF($E32="","",IF(INDEX(MARKA_TIP,MATCH($J32,MARKA_AD,0))="NET",$E32,$E32*INDEX(MARKA_KAT,MATCH($J32,MARKA_AD,0))*INDEX(KUR_DEG,MATCH($I32,KUR_AD,0)))) -> 1402.2 | G32: =SUMIF(BOM!$P:$P,$Q32,BOM!$I:$I) -> 5 | H32: =IF($F32="","",$F32*$G32) -> 7011 | I32: =IF($E32="","",INDEX(MARKA_PARA,MATCH($J32,MARKA_AD,0))) -> KZT | J32: CHINT | K32: =IF($E32="","",INDEX(MARKA_KAT,MATCH($J32,MARKA_AD,0))) -> 0.6 | L32: шт | M32: birlesik.csv (CHINT 260827) ARTIKUL 296827 | N32: OK | P32: =_xlfn.TEXTJOIN(", ",TRUE(),IF(COUNTIF(BOM!$P$3:$P$25,$Q32)>0,"ЩР.2",""),IF(COUNTIF(BOM!$P$28:$P$42,$Q32)>0,"ЩР.1",""),IF(COUNTIF(BOM!$P$45:$P$64,$Q32)>0,"ЩУ.1",""),IF(COUNTIF(BOM!$P$67:$P$88,$Q32)>0,"ЩУ.2",""),IF(COUNTIF(BOM!$P$91:$P$104,$Q32)>0,"ЩО.1","")) -> ЩУ.2 | Q32: CHINT-NXB63S-3P16C
A33: 32 | B33: MCB | C33: 296710 | D33: Авт. выкл. NXB-63S 1P 16А 4.5kA х-ка C | E33: 783 | F33: =IF($E33="","",IF(INDEX(MARKA_TIP,MATCH($J33,MARKA_AD,0))="NET",$E33,$E33*INDEX(MARKA_KAT,MATCH($J33,MARKA_AD,0))*INDEX(KUR_DEG,MATCH($I33,KUR_AD,0)))) -> 469.8 | G33: =SUMIF(BOM!$P:$P,$Q33,BOM!$I:$I) -> 12 | H33: =IF($F33="","",$F33*$G33) -> 5637.6 | I33: =IF($E33="","",INDEX(MARKA_PARA,MATCH($J33,MARKA_AD,0))) -> KZT | J33: CHINT | K33: =IF($E33="","",INDEX(MARKA_KAT,MATCH($J33,MARKA_AD,0))) -> 0.6 | L33: шт | M33: birlesik.csv (CHINT 260827) ARTIKUL 296710 | N33: OK | P33: =_xlfn.TEXTJOIN(", ",TRUE(),IF(COUNTIF(BOM!$P$3:$P$25,$Q33)>0,"ЩР.2",""),IF(COUNTIF(BOM!$P$28:$P$42,$Q33)>0,"ЩР.1",""),IF(COUNTIF(BOM!$P$45:$P$64,$Q33)>0,"ЩУ.1",""),IF(COUNTIF(BOM!$P$67:$P$88,$Q33)>0,"ЩУ.2",""),IF(COUNTIF(BOM!$P$91:$P$104,$Q33)>0,"ЩО.1","")) -> ЩО.1 | Q33: CHINT-NXB63S-1P16C
A34: 33 | B34: SAYAC | C34: 200200046 | D34: Счетчик ND СА4У-Э720 Дала 3ф (5-7,5А) 1 тариф. Saiman (AT'li) | E34: 22850 | F34: =IF($E34="","",IF(INDEX(MARKA_TIP,MATCH($J34,MARKA_AD,0))="NET",$E34,$E34*INDEX(MARKA_KAT,MATCH($J34,MARKA_AD,0))*INDEX(KUR_DEG,MATCH($I34,KUR_AD,0)))) -> 22850 | G34: =SUMIF(BOM!$P:$P,$Q34,BOM!$I:$I) -> 1 | H34: =IF($F34="","",$F34*$G34) -> 22850 | I34: =IF($E34="","",INDEX(MARKA_PARA,MATCH($J34,MARKA_AD,0))) -> KZT | J34: EKT | K34: =IF($E34="","",INDEX(MARKA_KAT,MATCH($J34,MARKA_AD,0))) -> 1 | L34: шт | M34: birlesik.csv (EKT/Saiman 250612) ARTIKUL 200200046 | N34: OK | O34: kod ND - semayla birebir eslesiyor | P34: =_xlfn.TEXTJOIN(", ",TRUE(),IF(COUNTIF(BOM!$P$3:$P$25,$Q34)>0,"ЩР.2",""),IF(COUNTIF(BOM!$P$28:$P$42,$Q34)>0,"ЩР.1",""),IF(COUNTIF(BOM!$P$45:$P$64,$Q34)>0,"ЩУ.1",""),IF(COUNTIF(BOM!$P$67:$P$88,$Q34)>0,"ЩУ.2",""),IF(COUNTIF(BOM!$P$91:$P$104,$Q34)>0,"ЩО.1","")) -> ЩУ.2 | Q34: EKT-SAYAC-DALA-ND-5-7.5
A35: 34 | B35: AT | C35: 255298 | D35: Трансформатор тока BH-0.66 60 I 400/5A класс точности 0.5 | E35: 6065 | F35: =IF($E35="","",IF(INDEX(MARKA_TIP,MATCH($J35,MARKA_AD,0))="NET",$E35,$E35*INDEX(MARKA_KAT,MATCH($J35,MARKA_AD,0))*INDEX(KUR_DEG,MATCH($I35,KUR_AD,0)))) -> 3639 | G35: =SUMIF(BOM!$P:$P,$Q35,BOM!$I:$I) -> 3 | H35: =IF($F35="","",$F35*$G35) -> 10917 | I35: =IF($E35="","",INDEX(MARKA_PARA,MATCH($J35,MARKA_AD,0))) -> KZT | J35: CHINT | K35: =IF($E35="","",INDEX(MARKA_KAT,MATCH($J35,MARKA_AD,0))) -> 0.6 | L35: шт | M35: birlesik.csv (CHINT 260827) ARTIKUL 255298 | N35: KONTROL | O35: SHU.2 sayaci icin AT; oran (400/5) semadaki yuke (~88A) gore buyuk - dogruluk sinifi icin daha kucuk oranli AT onerilir, MUHENDIS KONTROLU | P35: =_xlfn.TEXTJOIN(", ",TRUE(),IF(COUNTIF(BOM!$P$3:$P$25,$Q35)>0,"ЩР.2",""),IF(COUNTIF(BOM!$P$28:$P$42,$Q35)>0,"ЩР.1",""),IF(COUNTIF(BOM!$P$45:$P$64,$Q35)>0,"ЩУ.1",""),IF(COUNTIF(BOM!$P$67:$P$88,$Q35)>0,"ЩУ.2",""),IF(COUNTIF(BOM!$P$91:$P$104,$Q35)>0,"ЩО.1","")) -> ЩУ.2 | Q35: CHINT-CT-BH066-400-5
A36: 35 | B36: BARA | C36: 811002 | D36: Шина соединительная типа PIN 3P, 63А, L=1000мм | E36: 12699 | F36: =IF($E36="","",IF(INDEX(MARKA_TIP,MATCH($J36,MARKA_AD,0))="NET",$E36,$E36*INDEX(MARKA_KAT,MATCH($J36,MARKA_AD,0))*INDEX(KUR_DEG,MATCH($I36,KUR_AD,0)))) -> 7619.4 | G36: =SUMIF(BOM!$P:$P,$Q36,BOM!$I:$I) -> 1 | H36: =IF($F36="","",$F36*$G36) -> 7619.4 | I36: =IF($E36="","",INDEX(MARKA_PARA,MATCH($J36,MARKA_AD,0))) -> KZT | J36: CHINT | K36: =IF($E36="","",INDEX(MARKA_KAT,MATCH($J36,MARKA_AD,0))) -> 0.6 | L36: шт | M36: birlesik.csv (CHINT 260827) ARTIKUL 811002 | N36: VARSAYIM | O36: 3 fazli cikisli dagitim panolari icin tarak/pin bara | P36: =_xlfn.TEXTJOIN(", ",TRUE(),IF(COUNTIF(BOM!$P$3:$P$25,$Q36)>0,"ЩР.2",""),IF(COUNTIF(BOM!$P$28:$P$42,$Q36)>0,"ЩР.1",""),IF(COUNTIF(BOM!$P$45:$P$64,$Q36)>0,"ЩУ.1",""),IF(COUNTIF(BOM!$P$67:$P$88,$Q36)>0,"ЩУ.2",""),IF(COUNTIF(BOM!$P$91:$P$104,$Q36)>0,"ЩО.1","")) -> ЩУ.1, ЩУ.2 | Q36: CHINT-PIN3P-63A
A37: 36 | B37: BARA | C37: 130200407 | D37: Шина соединительная PIN (штырь) 1ф 63А (22см) | E37: 507 | F37: =IF($E37="","",IF(INDEX(MARKA_TIP,MATCH($J37,MARKA_AD,0))="NET",$E37,$E37*INDEX(MARKA_KAT,MATCH($J37,MARKA_AD,0))*INDEX(KUR_DEG,MATCH($I37,KUR_AD,0)))) -> 507 | G37: =SUMIF(BOM!$P:$P,$Q37,BOM!$I:$I) -> 1 | H37: =IF($F37="","",$F37*$G37) -> 507 | I37: =IF($E37="","",INDEX(MARKA_PARA,MATCH($J37,MARKA_AD,0))) -> KZT | J37: EKT | K37: =IF($E37="","",INDEX(MARKA_KAT,MATCH($J37,MARKA_AD,0))) -> 1 | L37: шт | M37: birlesik.csv (EKT 250612) ARTIKUL 130200407 | N37: VARSAYIM | O37: kucuk pano icin kisa pin-bara | P37: =_xlfn.TEXTJOIN(", ",TRUE(),IF(COUNTIF(BOM!$P$3:$P$25,$Q37)>0,"ЩР.2",""),IF(COUNTIF(BOM!$P$28:$P$42,$Q37)>0,"ЩР.1",""),IF(COUNTIF(BOM!$P$45:$P$64,$Q37)>0,"ЩУ.1",""),IF(COUNTIF(BOM!$P$67:$P$88,$Q37)>0,"ЩУ.2",""),IF(COUNTIF(BOM!$P$91:$P$104,$Q37)>0,"ЩО.1","")) -> ЩО.1 | Q37: EKT-PIN1P-63A-22CM
A38: 37 | B38: KABLO | C38: 100300079 | D38: ПВ3-10 белый ГОСТ (pano ici kablo) | E38: 591 | F38: =IF($E38="","",IF(INDEX(MARKA_TIP,MATCH($J38,MARKA_AD,0))="NET",$E38,$E38*INDEX(MARKA_KAT,MATCH($J38,MARKA_AD,0))*INDEX(KUR_DEG,MATCH($I38,KUR_AD,0)))) -> 591 | G38: =SUMIF(BOM!$P:$P,$Q38,BOM!$I:$I) -> 2 | H38: =IF($F38="","",$F38*$G38) -> 1182 | I38: =IF($E38="","",INDEX(MARKA_PARA,MATCH($J38,MARKA_AD,0))) -> KZT | J38: EKT | K38: =IF($E38="","",INDEX(MARKA_KAT,MATCH($J38,MARKA_AD,0))) -> 1 | L38: м | M38: birlesik.csv (EKT 250612) ARTIKUL 100300079 | N38: VARSAYIM | O38: otomatik hesap - Q'ya metraj | P38: =_xlfn.TEXTJOIN(", ",TRUE(),IF(COUNTIF(BOM!$P$3:$P$25,$Q38)>0,"ЩР.2",""),IF(COUNTIF(BOM!$P$28:$P$42,$Q38)>0,"ЩР.1",""),IF(COUNTIF(BOM!$P$45:$P$64,$Q38)>0,"ЩУ.1",""),IF(COUNTIF(BOM!$P$67:$P$88,$Q38)>0,"ЩУ.2",""),IF(COUNTIF(BOM!$P$91:$P$104,$Q38)>0,"ЩО.1","")) -> ЩУ.1 | Q38: EKT-PVGV-10
A39: 38 | B39: KABLO | C39: 100300015 | D39: ПВ3-16 белый ГОСТ (pano ici kablo) | E39: 961 | F39: =IF($E39="","",IF(INDEX(MARKA_TIP,MATCH($J39,MARKA_AD,0))="NET",$E39,$E39*INDEX(MARKA_KAT,MATCH($J39,MARKA_AD,0))*INDEX(KUR_DEG,MATCH($I39,KUR_AD,0)))) -> 961 | G39: =SUMIF(BOM!$P:$P,$Q39,BOM!$I:$I) -> 2 | H39: =IF($F39="","",$F39*$G39) -> 1922 | I39: =IF($E39="","",INDEX(MARKA_PARA,MATCH($J39,MARKA_AD,0))) -> KZT | J39: EKT | K39: =IF($E39="","",INDEX(MARKA_KAT,MATCH($J39,MARKA_AD,0))) -> 1 | L39: м | M39: birlesik.csv (EKT 250612) ARTIKUL 100300015 | N39: VARSAYIM | O39: otomatik hesap - Q'ya metraj | P39: =_xlfn.TEXTJOIN(", ",TRUE(),IF(COUNTIF(BOM!$P$3:$P$25,$Q39)>0,"ЩР.2",""),IF(COUNTIF(BOM!$P$28:$P$42,$Q39)>0,"ЩР.1",""),IF(COUNTIF(BOM!$P$45:$P$64,$Q39)>0,"ЩУ.1",""),IF(COUNTIF(BOM!$P$67:$P$88,$Q39)>0,"ЩУ.2",""),IF(COUNTIF(BOM!$P$91:$P$104,$Q39)>0,"ЩО.1","")) -> ЩУ.1 | Q39: EKT-PVGV-16
A40: 39 | B40: KANAL | C40: 280100249 | D40: Кабель-канал 25х25 белый | E40: 122 | F40: =IF($E40="","",IF(INDEX(MARKA_TIP,MATCH($J40,MARKA_AD,0))="NET",$E40,$E40*INDEX(MARKA_KAT,MATCH($J40,MARKA_AD,0))*INDEX(KUR_DEG,MATCH($I40,KUR_AD,0)))) -> 122 | G40: =SUMIF(BOM!$P:$P,$Q40,BOM!$I:$I) -> 0 | H40: =IF($F40="","",$F40*$G40) -> 0 | I40: =IF($E40="","",INDEX(MARKA_PARA,MATCH($J40,MARKA_AD,0))) -> KZT | J40: EKT | K40: =IF($E40="","",INDEX(MARKA_KAT,MATCH($J40,MARKA_AD,0))) -> 1 | L40: м | M40: birlesik.csv (EKT 250612) ARTIKUL 280100249 | N40: VARSAYIM | O40: otomatik hesap - Q'ya metraj | P40: =_xlfn.TEXTJOIN(", ",TRUE(),IF(COUNTIF(BOM!$P$3:$P$25,$Q40)>0,"ЩР.2",""),IF(COUNTIF(BOM!$P$28:$P$42,$Q40)>0,"ЩР.1",""),IF(COUNTIF(BOM!$P$45:$P$64,$Q40)>0,"ЩУ.1",""),IF(COUNTIF(BOM!$P$67:$P$88,$Q40)>0,"ЩУ.2",""),IF(COUNTIF(BOM!$P$91:$P$104,$Q40)>0,"ЩО.1","")) -> ЩУ.1, ЩУ.2, ЩО.1 | Q40: EKT-KANAL-25X25
A41: 40 | B41: KORPUS | C41: 716-15015 | D41: Щит ЩУРн-3/30 окошко (490х540х165) S/U36 IP31(TS) | E41: 20380 | F41: =IF($E41="","",IF(INDEX(MARKA_TIP,MATCH($J41,MARKA_AD,0))="NET",$E41,$E41*INDEX(MARKA_KAT,MATCH($J41,MARKA_AD,0))*INDEX(KUR_DEG,MATCH($I41,KUR_AD,0)))) -> 12228 | G41: =SUMIF(BOM!$P:$P,$Q41,BOM!$I:$I) -> 1 | H41: =IF($F41="","",$F41*$G41) -> 12228 | I41: =IF($E41="","",INDEX(MARKA_PARA,MATCH($J41,MARKA_AD,0))) -> KZT | J41: KAZTEK | K41: =IF($E41="","",INDEX(MARKA_KAT,MATCH($J41,MARKA_AD,0))) -> 0.6 | L41: шт | M41: Kaztek resmi liste (2607 15 Kaztek pano fiyat listesi.XLSX) ARTIKUL 719-15415 | N41: VARSAYIM | O41: ONCEKI SECIM (395x310x120) YANLIS: panoda dogrudan baglantili sayac var - 120mm derinlik sayac montaji icin dar. 150mm'ye yukseltildi (ayni taban 395x310). ONCEKI 989-100-1336 (al-sat/jenerik grup kodu) zaten KULLANILMAMISTI. Modul kapasitesi (24) ayni taban alani nedeniyle degismedi kabul edildi. | P41: =_xlfn.TEXTJOIN(", ",TRUE(),IF(COUNTIF(BOM!$P$3:$P$25,$Q41)>0,"ЩР.2",""),IF(COUNTIF(BOM!$P$28:$P$42,$Q41)>0,"ЩР.1",""),IF(COUNTIF(BOM!$P$45:$P$64,$Q41)>0,"ЩУ.1",""),IF(COUNTIF(BOM!$P$67:$P$88,$Q41)>0,"ЩУ.2",""),IF(COUNTIF(BOM!$P$91:$P$104,$Q41)>0,"ЩО.1","")) -> ЩУ.1 | Q41: KAZTEK-SMP1-395X310X150
A42: 41 | B42: KORPUS | C42: 714-15112 | D42: Щит мет. ЩРн-7-2 PR (1320x750x300) IP54 (TS) | E42: 73730 | F42: =IF($E42="","",IF(INDEX(MARKA_TIP,MATCH($J42,MARKA_AD,0))="NET",$E42,$E42*INDEX(MARKA_KAT,MATCH($J42,MARKA_AD,0))*INDEX(KUR_DEG,MATCH($I42,KUR_AD,0)))) -> 44238 | G42: =SUMIF(BOM!$P:$P,$Q42,BOM!$I:$I) -> 1 | H42: =IF($F42="","",$F42*$G42) -> 44238 | I42: =IF($E42="","",INDEX(MARKA_PARA,MATCH($J42,MARKA_AD,0))) -> KZT | J42: KAZTEK | K42: =IF($E42="","",INDEX(MARKA_KAT,MATCH($J42,MARKA_AD,0))) -> 0.6 | L42: шт | M42: Kaztek resmi liste (2607 15 Kaztek pano fiyat listesi.XLSX) ARTIKUL 714-15123 | N42: VARSAYIM | O42: ONCEKI SECIM (540x310x120) YANLIS: panoda 2 adet MCCB (NXM-125S ana giris + QF3 100A muadil) VE AT'li (3xCT) sayac var - bu panonun EN AGIR derinlik ihtiyaci. 120mm'den 220mm'ye yukseltildi, taban da genisletildi (540x310->540x400). ONCEKI 989-100-1337 (al-sat/jenerik grup kodu) zaten KULLANILMAMISTI. Modul kapasitesi teyit edilmedi, en az eski ЩРН-36 kadar (36 modul) kabul edildi - TEYIT GEREKIR. | P42: =_xlfn.TEXTJOIN(", ",TRUE(),IF(COUNTIF(BOM!$P$3:$P$25,$Q42)>0,"ЩР.2",""),IF(COUNTIF(BOM!$P$28:$P$42,$Q42)>0,"ЩР.1",""),IF(COUNTIF(BOM!$P$45:$P$64,$Q42)>0,"ЩУ.1",""),IF(COUNTIF(BOM!$P$67:$P$88,$Q42)>0,"ЩУ.2",""),IF(COUNTIF(BOM!$P$91:$P$104,$Q42)>0,"ЩО.1","")) -> ЩУ.2 | Q42: KAZTEK-SHRN2-540X400X220
A43: 42 | B43: KORPUS | C43: 714-15027 | D43: Мет. Корпус ЩРН-18 (395x310x120) IP54 | E43: 10270 | F43: =IF($E43="","",IF(INDEX(MARKA_TIP,MATCH($J43,MARKA_AD,0))="NET",$E43,$E43*INDEX(MARKA_KAT,MATCH($J43,MARKA_AD,0))*INDEX(KUR_DEG,MATCH($I43,KUR_AD,0)))) -> 6162 | G43: =SUMIF(BOM!$P:$P,$Q43,BOM!$I:$I) -> 1 | H43: =IF($F43="","",$F43*$G43) -> 6162 | I43: =IF($E43="","",INDEX(MARKA_PARA,MATCH($J43,MARKA_AD,0))) -> KZT | J43: KAZTEK | K43: =IF($E43="","",INDEX(MARKA_KAT,MATCH($J43,MARKA_AD,0))) -> 0.6 | L43: шт | M43: Kaztek resmi liste (2607 15 Kaztek pano fiyat listesi.XLSX) ARTIKUL 714-15027 | N43: VARSAYIM | O43: modul hesabina gore secildi; ONCEKI 989-101-0057 (al-sat/jenerik grup kodu) KULLANILMADI; olcusu semada teyit edilmedi, Kaztek katalogunda ЩРН-18 icin 4 farkli govde var (448x268, 395x310, 265x440 x2) - EN YAYGIN 395x310x120 secildi, TEYIT GEREKIR | P43: =_xlfn.TEXTJOIN(", ",TRUE(),IF(COUNTIF(BOM!$P$3:$P$25,$Q43)>0,"ЩР.2",""),IF(COUNTIF(BOM!$P$28:$P$42,$Q43)>0,"ЩР.1",""),IF(COUNTIF(BOM!$P$45:$P$64,$Q43)>0,"ЩУ.1",""),IF(COUNTIF(BOM!$P$67:$P$88,$Q43)>0,"ЩУ.2",""),IF(COUNTIF(BOM!$P$91:$P$104,$Q43)>0,"ЩО.1","")) -> ЩО.1 | Q43: KAZTEK-SRN18

Sheet BOM
A1: ROW | B1: Наименование1 | C1: Тип | D1: Артикул | E1: Номенклатура | F1: Цена | G1: net | H1: H(G×I) | I1: Qty | J1: Ед.изм | K1: Завод | L1: tutar | M1: DURUM | N1: NOT | O1: KAYNAK | P1: ANAHTAR (sistem-dokunma)
A2: 1 | B2: ЩР.2 (Fitness Center, Блок 1В — 41-22-2022-1В-ЭОМ л.16) | I2: 1 | J2: компл
A3: 2 | B3: =E3 -> Щит мет. ЩРн-7-2 PR (1320x750x300) IP54 (TS) | C3: Korpus | D3: =IF($P3="","",INDEX(FIYAT_KOD,MATCH($P3,FIYAT_ART,0))) -> 714-15112 | E3: =IF($P3="","",INDEX(FIYAT_ACK,MATCH($P3,FIYAT_ART,0))) -> Щит мет. ЩРн-7-2 PR (1320x750x300) IP54 (TS) | F3: =IF($P3="","",INDEX(FIYAT_LISTE,MATCH($P3,FIYAT_ART,0))) -> 73730 | G3: =IF($P3="","",INDEX(FIYAT_NET,MATCH($P3,FIYAT_ART,0))) -> 44238 | H3: =IF(OR($G3="",$I3=""),"",$G3*$I3) -> 44238 | I3: 1 | J3: шт | K3: =IF($P3="","",INDEX(FIYAT_MARKA,MATCH($P3,FIYAT_ART,0))) -> KAZTEK | L3: =IF($H3="","",$H3) -> 44238 | M3: KONTROL | N3: otomatik hesap: DIN modul=49 (14xNXBLE-63Y 1P+N x2mod=28 + 3 yedek x2mod=6 + 2xNXB-63S 3P x3mod=6 + 2xNL1-63 4P x4mod=8 + 1xkumanda MCB=1); kapasite (varsayim, teyitsiz) = 72 -> doluluk %68, yedek %32 (SADECE GENISLIK/MODUL SAYISI kontrolu - yukseklik/yerlesim TEYIT EDILMEDI). Korpus 660x440x120 -> 650x500x220 IP31'e yukseltildi: panoda 2 MCCB (NXM-125S x2) + dogrudan sayac var, 120mm derinlik yetersizdi. YERLESIM: 650mm genislikte 1 DIN sirasina ~34 modul sigar (kenar bosluklari dusulunce); 49 modulun DIF/MCB/UZO/kumanda kismi (43 modul, sayac ve MCCB'ler haric) 2 SIRAYA bolunmek zorunda (DIN ray 2 adet zaten bu sekilde alinmis). SAYAC (LM SA4-Э720, 3 fazli) standart 17.5mm DIN modulu DEGIL - kendi basina ayri bir yukseklik bandi ister (tahmini ~150-190mm, tam govde olcusu KATALOGDA YOK), MCB satirlariyla AYNI SIRAYA konulamaz. 2 MCCB (NXM-125S govde, tahmini ~105mm gen. x 150mm yuk.) da ayri bir bant ister. 500mm pano yuksekliginde: ust bant (2xMCCB+sayac yan yana) ~150-190mm + 2 modul sirasi ~200-230mm + ust/alt bosluk ~60mm = pano yuksekligine YAKLASIK SIGAR ama REZERV PAYI (kural: >=%20 yedek) BIRAKMAZ. Kesin dogrulama icin Kaztek'ten bu govde+cihaz listesi icin GENEL YERLESIM (GA) cizimi istenmeli - TEYIT GEREKIR, fabrikasyona gecmeden onaylanmali. | P3: KAZTEK-SHRN3-650X500X220
A4: 3 | B4: =E4 -> Авт. выкл. NXM-125S/3Р 125A 25кА (R) | C4: MCCB | D4: =IF($P4="","",INDEX(FIYAT_KOD,MATCH($P4,FIYAT_ART,0))) -> 131363 | E4: =IF($P4="","",INDEX(FIYAT_ACK,MATCH($P4,FIYAT_ART,0))) -> Авт. выкл. NXM-125S/3Р 125A 25кА (R) | F4: =IF($P4="","",INDEX(FIYAT_LISTE,MATCH($P4,FIYAT_ART,0))) -> 19760 | G4: =IF($P4="","",INDEX(FIYAT_NET,MATCH($P4,FIYAT_ART,0))) -> 11856 | H4: =IF(OR($G4="",$I4=""),"",$G4*$I4) -> 11856 | I4: 1 | J4: шт | K4: =IF($P4="","",INDEX(FIYAT_MARKA,MATCH($P4,FIYAT_ART,0))) -> CHINT | L4: =IF($H4="","",$H4) -> 11856 | M4: OK | N4: Ana giris (Н-ЩР.2 от ЩС.1, см.лист9). | P4: CHINT-NXM125S3P125
A5: 4 | B5: =E5 -> Авт. выкл. NXM-125S/3Р 80A 25кА (R) | C5: MCCB | D5: =IF($P5="","",INDEX(FIYAT_KOD,MATCH($P5,FIYAT_ART,0))) -> 131361 | E5: =IF($P5="","",INDEX(FIYAT_ACK,MATCH($P5,FIYAT_ART,0))) -> Авт. выкл. NXM-125S/3Р 80A 25кА (R) | F5: =IF($P5="","",INDEX(FIYAT_LISTE,MATCH($P5,FIYAT_ART,0))) -> 19418 | G5: =IF($P5="","",INDEX(FIYAT_NET,MATCH($P5,FIYAT_ART,0))) -> 11650.8 | H5: =IF(OR($G5="",$I5=""),"",$G5*$I5) -> 11650.8 | I5: 1 | J5: шт | K5: =IF($P5="","",INDEX(FIYAT_MARKA,MATCH($P5,FIYAT_ART,0))) -> CHINT | L5: =IF($H5="","",$H5) -> 11650.8 | M5: KONTROL | N5: Sayac yaninda gorulen ayrik 3P koruma; sauna alt-dagitimini besledigi varsayildi (2x24kW~53.6A icin 80A uygun). Baglanti topolojisi semada net degil - MUHENDIS ONAYI ONERILIR. | P5: CHINT-NXM125S3P80
A6: 5 | B6: =E6 -> Счетчик LM СА4-Э720 Дала 3ф (10-100А) 1 тариф. Т1 (dogrudan, dahili tarifikator) | C6: Sayac | D6: =IF($P6="","",INDEX(FIYAT_KOD,MATCH($P6,FIYAT_ART,0))) -> 200200048 | E6: =IF($P6="","",INDEX(FIYAT_ACK,MATCH($P6,FIYAT_ART,0))) -> Счетчик LM СА4-Э720 Дала 3ф (10-100А) 1 тариф. Т1 (dogrudan, dahili tarifikator) | F6: =IF($P6="","",INDEX(FIYAT_LISTE,MATCH($P6,FIYAT_ART,0))) -> 39360 | G6: =IF($P6="","",INDEX(FIYAT_NET,MATCH($P6,FIYAT_ART,0))) -> 39360 | H6: =IF(OR($G6="",$I6=""),"",$G6*$I6) -> 39360 | I6: 1 | J6: шт | K6: =IF($P6="","",INDEX(FIYAT_MARKA,MATCH($P6,FIYAT_ART,0))) -> EKT | L6: =IF($H6="","",$H6) -> 39360 | M6: MUADIL | N6: Semada: ДАЛА СА4-Э720 R T1 3x220/380V 10(100)A. 'R' varyanti katalogda yok; model/akim/tarife esdegeri kullanildi. | P6: EKT-SAYAC-DALA-10-100
A7: 6 | B7: =E7 -> Авт. выкл. NXB-63S 3P 40А 4.5kA х-ка C | C7: MCB | D7: =IF($P7="","",INDEX(FIYAT_KOD,MATCH($P7,FIYAT_ART,0))) -> 296831 | E7: =IF($P7="","",INDEX(FIYAT_ACK,MATCH($P7,FIYAT_ART,0))) -> Авт. выкл. NXB-63S 3P 40А 4.5kA х-ка C | F7: =IF($P7="","",INDEX(FIYAT_LISTE,MATCH($P7,FIYAT_ART,0))) -> 2807 | G7: =IF($P7="","",INDEX(FIYAT_NET,MATCH($P7,FIYAT_ART,0))) -> 1684.2 | H7: =IF(OR($G7="",$I7=""),"",$G7*$I7) -> 3368.4 | I7: 2 | J7: шт | K7: =IF($P7="","",INDEX(FIYAT_MARKA,MATCH($P7,FIYAT_ART,0))) -> CHINT | L7: =IF($H7="","",$H7) -> 3368.4 | M7: OK | N7: GrN2.16/2.17 sauna elektro-pec, 24kW/26.8A - semada acik. | P7: CHINT-NXB63S-3P40C
A8: 7 | B8: =E8 -> УЗО NL1-63 6kA 4P 63A 30mA тип AC | C8: UZO | D8: =IF($P8="","",INDEX(FIYAT_KOD,MATCH($P8,FIYAT_ART,0))) -> 200325 | E8: =IF($P8="","",INDEX(FIYAT_ACK,MATCH($P8,FIYAT_ART,0))) -> УЗО NL1-63 6kA 4P 63A 30mA тип AC | F8: =IF($P8="","",INDEX(FIYAT_LISTE,MATCH($P8,FIYAT_ART,0))) -> 19129 | G8: =IF($P8="","",INDEX(FIYAT_NET,MATCH($P8,FIYAT_ART,0))) -> 11477.4 | H8: =IF(OR($G8="",$I8=""),"",$G8*$I8) -> 22954.8 | I8: 2 | J8: шт | K8: =IF($P8="","",INDEX(FIYAT_MARKA,MATCH($P8,FIYAT_ART,0))) -> CHINT | L8: =IF($H8="","",$H8) -> 22954.8 | M8: OK | N8: Sauna devrelerinde MCB ile seri UZO. | P8: CHINT-NL163-4P63-30AC
A9: 8 | B9: =E9 -> Диф. авт. выкл. NXBLE-63Y 1P+N 25А 30mA электронный тип AC, х-ка С, 4.5kA | C9: DIF | D9: =IF($P9="","",INDEX(FIYAT_KOD,MATCH($P9,FIYAT_ART,0))) -> 105544 | E9: =IF($P9="","",INDEX(FIYAT_ACK,MATCH($P9,FIYAT_ART,0))) -> Диф. авт. выкл. NXBLE-63Y 1P+N 25А 30mA электронный тип AC, х-ка С, 4.5kA | F9: =IF($P9="","",INDEX(FIYAT_LISTE,MATCH($P9,FIYAT_ART,0))) -> 4939 | G9: =IF($P9="","",INDEX(FIYAT_NET,MATCH($P9,FIYAT_ART,0))) -> 2963.4 | H9: =IF(OR($G9="",$I9=""),"",$G9*$I9) -> 50377.8 | I9: 17 | J9: шт | K9: =IF($P9="","",INDEX(FIYAT_MARKA,MATCH($P9,FIYAT_ART,0))) -> CHINT | L9: =IF($H9="","",$H9) -> 50377.8 | M9: OK | N9: GrN1.2,2.2,3.2,4.2,5.2,2.6-2.13,2.15 = 14 adet rozet grubu cikisi. GrN2.14 ve 2 etiketsiz poz 'Rezerv' - cihazsiz. | P9: CHINT-NXBLE63Y-1PN25-30
A10: 9 | B10: =E10 -> Авт. выкл. NXB-63 1P 6A 6кА х-ка C | C10: MCB | D10: =IF($P10="","",INDEX(FIYAT_KOD,MATCH($P10,FIYAT_ART,0))) -> 814012 | E10: =IF($P10="","",INDEX(FIYAT_ACK,MATCH($P10,FIYAT_ART,0))) -> Авт. выкл. NXB-63 1P 6A 6кА х-ка C | F10: =IF($P10="","",INDEX(FIYAT_LISTE,MATCH($P10,FIYAT_ART,0))) -> 1436 | G10: =IF($P10="","",INDEX(FIYAT_NET,MATCH($P10,FIYAT_ART,0))) -> 861.6 | H10: =IF(OR($G10="",$I10=""),"",$G10*$I10) -> 0 | I10: 0 | J10: шт | K10: =IF($P10="","",INDEX(FIYAT_MARKA,MATCH($P10,FIYAT_ART,0))) -> CHINT | L10: =IF($H10="","",$H10) -> 0 | M10: VARSAYIM | N10: Sayac gerilim olcu devresi icin otomatik kumanda MCB eklendi. | P10: CHINT-NXB63-1P6C
A11: 10 | B11: =E11 -> Шина соединительная типа PIN 1P, 100А, L=1000мм | C11: Bara | D11: =IF($P11="","",INDEX(FIYAT_KOD,MATCH($P11,FIYAT_ART,0))) -> 811004 | E11: =IF($P11="","",INDEX(FIYAT_ACK,MATCH($P11,FIYAT_ART,0))) -> Шина соединительная типа PIN 1P, 100А, L=1000мм | F11: =IF($P11="","",INDEX(FIYAT_LISTE,MATCH($P11,FIYAT_ART,0))) -> 5972 | G11: =IF($P11="","",INDEX(FIYAT_NET,MATCH($P11,FIYAT_ART,0))) -> 3583.2 | H11: =IF(OR($G11="",$I11=""),"",$G11*$I11) -> 7166.4 | I11: 2 | J11: шт | K11: =IF($P11="","",INDEX(FIYAT_MARKA,MATCH($P11,FIYAT_ART,0))) -> CHINT | L11: =IF($H11="","",$H11) -> 7166.4 | M11: VARSAYIM | N11: otomatik hesap: 17 poz(14 aktif+3 yedek) x1P+N(2mod)=34mod (~0.6m); TARAK_MOD_ADET(12) asildigi icin 57mod(1m) PIN bara secildi. DUZELTME: bu 34 modul 2 AYRI DIN sirasina bolunuyor (bkz korpus notu) - tek parca 1m/57mod tarak bara iki farkli rayin arasindaki bosluktan GECEMEZ, her sira icin AYRI parca gerekir -> adet 1'den 2'ye cikarildi (1m'lik parca sahada olculup kesilir). Ana salter<=125A -> bakir bara yerine pin-bara (KURALLAR kurali). | P11: CHINT-PINBUS-1P100A
A12: 11 | B12: =E12 -> Шина N ноль DIN-изол ШНИ-6х9-24-Д-С | C12: Bara | D12: =IF($P12="","",INDEX(FIYAT_KOD,MATCH($P12,FIYAT_ART,0))) -> YNN10-69-24D-K07 | E12: =IF($P12="","",INDEX(FIYAT_ACK,MATCH($P12,FIYAT_ART,0))) -> Шина N ноль DIN-изол ШНИ-6х9-24-Д-С | F12: =IF($P12="","",INDEX(FIYAT_LISTE,MATCH($P12,FIYAT_ART,0))) -> 900 | G12: =IF($P12="","",INDEX(FIYAT_NET,MATCH($P12,FIYAT_ART,0))) -> 900 | H12: =IF(OR($G12="",$I12=""),"",$G12*$I12) -> 900 | I12: 1 | J12: шт | K12: =IF($P12="","",INDEX(FIYAT_MARKA,MATCH($P12,FIYAT_ART,0))) -> EKT | L12: =IF($H12="","",$H12) -> 900 | M12: VARSAYIM | N12: izoleli notr barasi - zorunlu. | P12: EKT-SHINA-N24
A13: 12 | B13: =E13 -> Шина PE земля ШНИ 6х9 12-К-З | C13: Bara | D13: =IF($P13="","",INDEX(FIYAT_KOD,MATCH($P13,FIYAT_ART,0))) -> 130200401 | E13: =IF($P13="","",INDEX(FIYAT_ACK,MATCH($P13,FIYAT_ART,0))) -> Шина PE земля ШНИ 6х9 12-К-З | F13: =IF($P13="","",INDEX(FIYAT_LISTE,MATCH($P13,FIYAT_ART,0))) -> 514 | G13: =IF($P13="","",INDEX(FIYAT_NET,MATCH($P13,FIYAT_ART,0))) -> 514 | H13: =IF(OR($G13="",$I13=""),"",$G13*$I13) -> 514 | I13: 1 | J13: шт | K13: =IF($P13="","",INDEX(FIYAT_MARKA,MATCH($P13,FIYAT_ART,0))) -> EKT | L13: =IF($H13="","",$H13) -> 514 | M13: VARSAYIM | N13: ГЗШ topraklama barasi - zorunlu. | P13: EKT-SHINA-PE12
A14: 13 | B14: =E14 -> DIN-рейка (100см) оцинкованная | C14: DIN | D14: =IF($P14="","",INDEX(FIYAT_KOD,MATCH($P14,FIYAT_ART,0))) -> YDN10-0100 | E14: =IF($P14="","",INDEX(FIYAT_ACK,MATCH($P14,FIYAT_ART,0))) -> DIN-рейка (100см) оцинкованная | F14: =IF($P14="","",INDEX(FIYAT_LISTE,MATCH($P14,FIYAT_ART,0))) -> 686 | G14: =IF($P14="","",INDEX(FIYAT_NET,MATCH($P14,FIYAT_ART,0))) -> 686 | H14: =IF(OR($G14="",$I14=""),"",$G14*$I14) -> 0 | I14: 0 | J14: шт | K14: =IF($P14="","",INDEX(FIYAT_MARKA,MATCH($P14,FIYAT_ART,0))) -> EKT | L14: =IF($H14="","",$H14) -> 0 | M14: VARSAYIM | N14: 49 modul x~18mm + klemens payi x DINRAY_FIRE ~1.0m -> 2 sira icin 2x1m. | P14: EKT-DINRAY-100
... A25: 24 | B25: =E25 -> Montaj + test + etiketleme iscilik | C25: Iscilik | D25: =IF($P25="","",INDEX(FIYAT_KOD,MATCH($P25,FIYAT_ART,0))) -> ISCILIK-MONTAJ | E25: =IF($P25="","",INDEX(FIYAT_ACK,MATCH($P25,FIYAT_ART,0))) -> Montaj + test + etiketleme iscilik | F25: =IF($P25="","",INDEX(FIYAT_LISTE,MATCH($P25,FIYAT_ART,0))) -> 6000 | G25: =IF($P25="","",INDEX(FIYAT_NET,MATCH($P25,FIYAT_ART,0))) -> 100 | H25: =IF(OR($G25="",$I25=""),"",$G25*$I25) -> 20000 | I25: 200 | J25: мин. | K25: =IF($P25="","",INDEX(FIYAT_MARKA,MATCH($P25,FIYAT_ART,0))) -> ISCILIK | L25: =IF($H25="","",$H25) -> 20000 | M25: VARSAYIM | N25: dk: kumanda10+sauna MCB3Px2=36+RCBOx14=630+UZO4Px2=90+sayac90+klemensx59=236+tarakbara10+DIN(2m)+kanal(3m)=25+korpus(orta)45+MCCBx2(ana+alt)=120; toplam1292dk x1.15(TEST_ETIKET_CARPANI)=1485.8 dk (Qty, dakika bazli). | P25: ISCILIK-MONTAJ
B26: Toplam ЩР.2 | H26: =SUBTOTAL(9,H3:H25) -> 253816.2 | L26: =SUBTOTAL(9,L3:L25) -> 253816.2
A27: 26 | B27: ЩР.1 (Entertainment rooms, Блок 1В — 41-22-2022-1В-ЭОМ л.2) | I27: 1 | J27: компл
A28: 27 | B28: =E28 -> Мет. Корпус ЩМП-3 (650x500x150) IP31 | C28: Korpus | D28: =IF($P28="","",INDEX(FIYAT_KOD,MATCH($P28,FIYAT_ART,0))) -> 719-15560 | E28: =IF($P28="","",INDEX(FIYAT_ACK,MATCH($P28,FIYAT_ART,0))) -> Мет. Корпус ЩМП-3 (650x500x150) IP31 | F28: =IF($P28="","",INDEX(FIYAT_LISTE,MATCH($P28,FIYAT_ART,0))) -> 25050 | G28: =IF($P28="","",INDEX(FIYAT_NET,MATCH($P28,FIYAT_ART,0))) -> 15030 | H28: =IF(OR($G28="",$I28=""),"",$G28*$I28) -> 15030 | I28: 1 | J28: шт | K28: =IF($P28="","",INDEX(FIYAT_MARKA,MATCH($P28,FIYAT_ART,0))) -> KAZTEK | L28: =IF($H28="","",$H28) -> 15030 | M28: KONTROL | N28: otomatik hesap: DIN modul=51 (25xNXBLE-63Y 1P+N x2mod=50 + kumanda MCB=1); kapasite (varsayim, teyitsiz) = 72 -> doluluk %71, yedek %29 (SADECE GENISLIK/MODUL SAYISI kontrolu - yukseklik/yerlesim TEYIT EDILMEDI). 650mm genislikte 1 DIN sirasina ~34 modul sigar (kenar bosluklari dusulunce); 51 modul 2 SIRAYA bolunmek zorunda (DIN ray 2 adet zaten bu sekilde alinmis, PIN bara da 2 parcaya cikarildi). Korpus 660x440x120 -> 650x500x150 IP31'e yukseltildi: panoda MCCB (NXM-63S ana giris) var, 120mm derinlik yetersizdi. Kesin yerlesim dogrulamasi icin Kaztek'ten GA cizimi istenmeli - TEYIT GEREKIR. | P28: KAZTEK-SMP3-650X500X150
A29: 28 | B29: =E29 -> Авт. выкл. NXM-63S/3Р 32A 25кА (R) | C29: MCCB | D29: =IF($P29="","",INDEX(FIYAT_KOD,MATCH($P29,FIYAT_ART,0))) -> 205886 | E29: =IF($P29="","",INDEX(FIYAT_ACK,MATCH($P29,FIYAT_ART,0))) -> Авт. выкл. NXM-63S/3Р 32A 25кА (R) | F29: =IF($P29="","",INDEX(FIYAT_LISTE,MATCH($P29,FIYAT_ART,0))) -> 17405 | G29: =IF($P29="","",INDEX(FIYAT_NET,MATCH($P29,FIYAT_ART,0))) -> 10443 | H29: =IF(OR($G29="",$I29=""),"",$G29*$I29) -> 10443 | I29: 1 | J29: шт | K29: =IF($P29="","",INDEX(FIYAT_MARKA,MATCH($P29,FIYAT_ART,0))) -> CHINT | L29: =IF($H29="","",$H29) -> 10443 | M29: OK | N29: Ana giris; semada 32A 15kA isteniyordu. Eski NM1-63S serisinde 32A yoktu; NXM-63S/3P 32A 25kA (kullanici talebiyle NXM serisine gecildi) akimda TAM ESLESIYOR, kA'da 15->25kA (daha yuksek, sorun degil). | P29: CHINT-NXM63S3P32
A30: 29 | B30: =E30 -> Диф. авт. выкл. NXBLE-63Y 1P+N 25А 30mA электронный тип AC, х-ка С, 4.5kA | C30: DIF | D30: =IF($P30="","",INDEX(FIYAT_KOD,MATCH($P30,FIYAT_ART,0))) -> 105544 | E30: =IF($P30="","",INDEX(FIYAT_ACK,MATCH($P30,FIYAT_ART,0))) -> Диф. авт. выкл. NXBLE-63Y 1P+N 25А 30mA электронный тип AC, х-ка С, 4.5kA | F30: =IF($P30="","",INDEX(FIYAT_LISTE,MATCH($P30,FIYAT_ART,0))) -> 4939 | G30: =IF($P30="","",INDEX(FIYAT_NET,MATCH($P30,FIYAT_ART,0))) -> 2963.4 | H30: =IF(OR($G30="",$I30=""),"",$G30*$I30) -> 74085 | I30: 25 | J30: шт | K30: =IF($P30="","",INDEX(FIYAT_MARKA,MATCH($P30,FIYAT_ART,0))) -> CHINT | L30: =IF($H30="","",$H30) -> 74085 | M30: OK | N30: QF1-QF25 = semada (kullanicinin gonderdigi tek hat semasi) 25 pozisyonun HEPSI 'CHINT NXBLE-63Y 1P+N 25A C 30mA' olarak donatili gosterilmis (Розеточная группа cikislari) - ONCEKI VARSAYIM (QF23-25 'Резерв'/cihazsiz) YANLISTI, sema uzerinde tum 25 pozisyon icin cihaz cizili; 22->25 adet olarak duzeltildi. | P30: CHINT-NXBLE63Y-1PN25-30
A31: 30 | B31: =E31 -> Авт. выкл. NXB-63 1P 6A 6кА х-ка C | C31: MCB | D31: =IF($P31="","",INDEX(FIYAT_KOD,MATCH($P31,FIYAT_ART,0))) -> 814012 | E31: =IF($P31="","",INDEX(FIYAT_ACK,MATCH($P31,FIYAT_ART,0))) -> Авт. выкл. NXB-63 1P 6A 6кА х-ка C | F31: =IF($P31="","",INDEX(FIYAT_LISTE,MATCH($P31,FIYAT_ART,0))) -> 1436 | G31: =IF($P31="","",INDEX(FIYAT_NET,MATCH($P31,FIYAT_ART,0))) -> 861.6 | H31: =IF(OR($G31="",$I31=""),"",$G31*$I31) -> 861.6 | I31: 1 | J31: шт | K31: =IF($P31="","",INDEX(FIYAT_MARKA,MATCH($P31,FIYAT_ART,0))) -> CHINT | L31: =IF($H31="","",$H31) -> 861.6 | M31: VARSAYIM | N31: Priz grubu panosu icin otomatik kumanda/test MCB eklendi. | P31: CHINT-NXB63-1P6C
A32: 31 | B32: =E32 -> Шина соединительная типа PIN 1P, 100А, L=1000мм | C32: Bara | D32: =IF($P32="","",INDEX(FIYAT_KOD,MATCH($P32,FIYAT_ART,0))) -> 811004 | E32: =IF($P32="","",INDEX(FIYAT_ACK,MATCH($P32,FIYAT_ART,0))) -> Шина соединительная типа PIN 1P, 100А, L=1000мм | F32: =IF($P32="","",INDEX(FIYAT_LISTE,MATCH($P32,FIYAT_ART,0))) -> 5972 | G32: =IF($P32="","",INDEX(FIYAT_NET,MATCH($P32,FIYAT_ART,0))) -> 3583.2 | H32: =IF(OR($G32="",$I32=""),"",$G32*$I32) -> 7166.4 | I32: 2 | J32: шт | K32: =IF($P32="","",INDEX(FIYAT_MARKA,MATCH($P32,FIYAT_ART,0))) -> CHINT | L32: =IF($H32="","",$H32) -> 7166.4 | M32: VARSAYIM | N32: otomatik hesap: 25 poz(tumu aktif) x1P+N(2mod)=50mod; TARAK_MOD_ADET(12) asildigi icin 57mod(1m) PIN bara secildi. DUZELTME: 50 modul 2 AYRI DIN sirasina bolunuyor (bkz korpus notu, DIN ray 2 adet) - tek parca 1m/57mod tarak bara iki rayin arasindan GECEMEZ, her sira icin AYRI parca gerekir -> adet 1'den 2'ye cikarildi (1m'lik parca sahada olculup kesilir). | P32: CHINT-PINBUS-1P100A
A33: 32 | B33: =E33 -> Шина N ноль DIN-изол ШНИ-6х9-24-Д-С | C33: Bara | D33: =IF($P33="","",INDEX(FIYAT_KOD,MATCH($P33,FIYAT_ART,0))) -> YNN10-69-24D-K07 | E33: =IF($P33="","",INDEX(FIYAT_ACK,MATCH($P33,FIYAT_ART,0))) -> Шина N ноль DIN-изол ШНИ-6х9-24-Д-С | F33: =IF($P33="","",INDEX(FIYAT_LISTE,MATCH($P33,FIYAT_ART,0))) -> 900 | G33: =IF($P33="","",INDEX(FIYAT_NET,MATCH($P33,FIYAT_ART,0))) -> 900 | H33: =IF(OR($G33="",$I33=""),"",$G33*$I33) -> 900 | I33: 1 | J33: шт | K33: =IF($P33="","",INDEX(FIYAT_MARKA,MATCH($P33,FIYAT_ART,0))) -> EKT | L33: =IF($H33="","",$H33) -> 900 | M33: VARSAYIM | N33: izoleli notr barasi - zorunlu. | P33: EKT-SHINA-N24
A34: 33 | B34: =E34 -> Шина PE земля ШНИ 6х9 12-К-З | C34: Bara | D34: =IF($P34="","",INDEX(FIYAT_KOD,MATCH($P34,FIYAT_ART,0))) -> 130200401 | E34: =IF($P34="","",INDEX(FIYAT_ACK,MATCH($P34,FIYAT_ART,0))) -> Шина PE земля ШНИ 6х9 12-К-З | F34: =IF($P34="","",INDEX(FIYAT_LISTE,MATCH($P34,FIYAT_ART,0))) -> 514 | G34: =IF($P34="","",INDEX(FIYAT_NET,MATCH($P34,FIYAT_ART,0))) -> 514 | H34: =IF(OR($G34="",$I34=""),"",$G34*$I34) -> 514 | I34: 1 | J34: шт | K34: =IF($P34="","",INDEX(FIYAT_MARKA,MATCH($P34,FIYAT_ART,0))) -> EKT | L34: =IF($H34="","",$H34) -> 514 | M34: VARSAYIM | N34: ГЗШ topraklama barasi - zorunlu. | P34: EKT-SHINA-PE12
A35: 34 | B35: =E35 -> DIN-рейка (100см) оцинкованная | C35: DIN | D35: =IF($P35="","",INDEX(FIYAT_KOD,MATCH($P35,FIYAT_ART,0))) -> YDN10-0100 | E35: =IF($P35="","",INDEX(FIYAT_ACK,MATCH($P35,FIYAT_ART,0))) -> DIN-рейка (100см) оцинкованная | F35: =IF($P35="","",INDEX(FIYAT_LISTE,MATCH($P35,FIYAT_ART,0))) -> 686 | G35: =IF($P35="","",INDEX(FIYAT_NET,MATCH($P35,FIYAT_ART,0))) -> 686 | H35: =IF(OR($G35="",$I35=""),"",$G35*$I35) -> 0 | I35: 0 | J35: шт | K35: =IF($P35="","",INDEX(FIYAT_MARKA,MATCH($P35,FIYAT_ART,0))) -> EKT | L35: =IF($H35="","",$H35) -> 0 | M35: VARSAYIM | N35: 51 modul x~18mm x1.10 ~1.0m -> 2 sira icin 2x1m. | P35: EKT-DINRAY-100
A36: 35 | B36: =E36 -> Кабель-канал 40х40 белый | C36: Kanal | D36: =IF($P36="","",INDEX(FIYAT_KOD,MATCH($P36,FIYAT_ART,0))) -> 280100252 | E36: =IF($P36="","",INDEX(FIYAT_ACK,MATCH($P36,FIYAT_ART,0))) -> Кабель-канал 40х40 белый | F36: =IF($P36="","",INDEX(FIYAT_LISTE,MATCH($P36,FIYAT_ART,0))) -> 238 | G36: =IF($P36="","",INDEX(FIYAT_NET,MATCH($P36,FIYAT_ART,0))) -> 238 | H36: =IF(OR($G36="",$I36=""),"",$G36*$I36) -> 714 | I36: 3 | J36: м | K36: =IF($P36="","",INDEX(FIYAT_MARKA,MATCH($P36,FIYAT_ART,0))) -> EKT | L36: =IF($H36="","",$H36) -> 714 | M36: VARSAYIM | N36: 51mod>24 -> 40x40; ~2.76m x1.10=3.04m. | P36: EKT-KANAL-40X40
A37: 36 | B37: =E37 -> ПВ3-4 белый ГОСТ (pano ici kablo) | C37: Kablo | D37: =IF($P37="","",INDEX(FIYAT_KOD,MATCH($P37,FIYAT_ART,0))) -> 100300030 | E37: =IF($P37="","",INDEX(FIYAT_ACK,MATCH($P37,FIYAT_ART,0))) -> ПВ3-4 белый ГОСТ (pano ici kablo) | F37: =IF($P37="","",INDEX(FIYAT_LISTE,MATCH($P37,FIYAT_ART,0))) -> 242 | G37: =IF($P37="","",INDEX(FIYAT_NET,MATCH($P37,FIYAT_ART,0))) -> 242 | H37: =IF(OR($G37="",$I37=""),"",$G37*$I37) -> 4356 | I37: 18 | J37: м | K37: =IF($P37="","",INDEX(FIYAT_MARKA,MATCH($P37,FIYAT_ART,0))) -> EKT | L37: =IF($H37="","",$H37) -> 4356 | M37: VARSAYIM | N37: 25devre x2ilet x1.2m x1.10=66.00m (DIF 22->25 duzeltmesi ile guncellendi). | P37: EKT-PVGV-4
