Workbook

Sheet Kurallar
A1: PARAMETRE | B1: DEĞER | C1: AÇIKLAMA
A2: CHINT net katsayısı | B2: 0.6 | C2: Liste × 0,60 (%40 indirim). Kaynak: CHINT 13.06.2026 (KZT)
A3: EKT / IEK / UNIT katsayısı | B3: 1 | C3: Kaynak: EKT 19.06.2025 (KZT)
A4: САЙМАН katsayısı | B4: 1 | C4: Kaynak: САЙМАН 2026 (KZT)
A5: Montaj malzemesi oranı | B5: 0.03 | C5: Her panonun malzeme ara toplamının %3'ü
A6: İşçilik birim fiyat (KZT/dk) | B6: 100 | C6: Montajная работа
A7: Test/etiket/kontrol çarpanı | B7: 1.15 | C7: Toplam dakika × 1,15
A8: ZAMAN NORMLARI | C8: dakika
A9: Korpus hazırlık — küçük (ЩМП-1/2) | B9: 30 | C9: dk/adet
A10: Korpus hazırlık — orta (ЩМП-3/4) | B10: 45 | C10: dk/adet
A11: Korpus hazırlık — büyük (ЩМП-5/6) | B11: 60 | C11: dk/adet
A12: Korpus hazırlık — dikili (ЩМП-18) | B12: 90 | C12: dk/adet
A13: АВР NXZM-63 | B13: 60 | C13: dk/adet
A14: АВР NXZM-125 | B14: 90 | C14: dk/adet
A15: TMŞ (MCCB) NXM ≤125A | B15: 60 | C15: dk/adet
A16: Sayaç | B16: 90 | C16: dk/adet
A17: Akım trafosu | B17: 20 | C17: dk/adet
A18: Sinyal lambası | B18: 15 | C18: dk/adet
A19: Диф.авт. (RCBO) 1P+N | B19: 12 | C19: dk/adet
A20: Авт.выкл. (MCB) 1P | B20: 10 | C20: dk/adet
... A25: DIN ray / kablo kanalı | B25: 5 | C25: dk/m
A27: PROJE | B27: 260727 Almaty Superski — 26 pano — CHINT (GPT listesinden YSF formatına dönüştürüldü ve fiyatlandırıldı)
A28: ÖNEMLİ — pano adedi | B28: Talepte 36 pano denildi; yüklenen GPT dosyasında 26 pano var. Eksik 10 pano için şema/liste gönderilmeli.
A29: SİLİNEN GPT SATIRLARI | B29: GPT'nin BARA / KLEMENS / DIN / KANAL / KABLO / GİRİŞ / MONTAJ / İŞÇİLİK satırlarının tamamı silindi (fiyatsız, 'KONTROL' kodlu, adetler cihaz sayısıyla uyumsuzdu). Bu kalemler her pano için cihaz sayısından yeniden hesaplandı.
A30: FİYAT LİSTESİ YAŞI
A31: CHINT 13.06.2026 | B31: 1,5 ay — GÜNCEL
A32: САЙМАН 2026 | B32: GÜNCEL
A33: EKT 19.06.2025 | B33: UYARI: 13 ay — korpus, klemens, bara, kablo fiyatları bu listeden. 2026 listesi istenmeli.
A34: Teksan 14.04.2025 | B34: KULLANILMADI — eldeki Teksan dosyası aydınlatma stoğu, korpus stoğu değil. GPT'nin 'TEKSAN F' korpusları fiyatlandırılamadı; EKT ЩМП muadilleri kullanıldı.
A35: KORPUS DEĞİŞİMİ
A36: GPT 400×300×200 | B36: → ЩМП-1 IP31 395×310×220 EKT
A37: GPT 600×500×220 | B37: → ЩМП-3 IP31 650×500×220 EKT
A38: GPT 700×600×250 / 800×600×250 | B38: → ЩМП-4 IP31 800×650×250 EKT
A39: GPT 1000×600×250 | B39: → ЩМП-5 IP31 1000×650×300 EKT
A40: GPT 1000×800×300 | B40: → ЩМП-6 IP31 1200×750×300 EKT (EKT'de 800 mm genişlik yalnız IP54 ЩМП-16'da var)
A41: GPT 1800×800×400 dikili | B41: → ЩМП-18 IP54 1800×800×400 EKT (EKT'de bu ölçü sadece IP54; proje IP31 istiyor — IP54 üstü koruma, kabul edilebilir)
A42: CİHAZ MUADİLLERİ / STOK
A43: АВР NXZM 4 kutup | B43: GPT tüm АВР'leri 4P seçmiş. CHINT KZ stoğunda NXZM-63 ve NXZM-125 için 4 KUTUP YOK — sadece 3B (3 kutup) var. 3B ile fiyatlandırıldı. 4P zorunluysa özel sipariş ve teslim süresi CHINT'ten alınmalı.
A44: АВР 32A | B44: CHINT'te 32A yok → NXZM-63S/3B 40A alındı (4 panoda).
A45: АВР 50A | B45: CHINT'te 50A yok → NXZM-63S/3B 63A alındı (7 panoda). STOK 0 — sipariş süresi sorulmalı.
...

Sheet BOM
A1: ROW | B1: Наименование1 | C1: Тип | D1: Артикул | E1: Номенклатура | F1: Цена (лист) | G1: Цена нетто | H1: Сумма | I1: Ед.изм. | J1: Кол-во | K1: Завод | L1: malz | M1: Сумма
A2: 1 | B2: =E2 -> L3-ЩР-1 — Здание оператора L3 | C2: пано | D2: ASM-ETN-027-EOM-DGD-0001 | E2: L3-ЩР-1 — Здание оператора L3 | I2: комплект | J2: 1
A3: 2 | B3: =B2 -> L3-ЩР-1 — Здание оператора L3 | C3: korpus | D3: 714-15117 | E3: Щит мет. ЩРн-5-2 PR (1000x650x300) IP31 (TS) | F3: 55770 | G3: =0.5*F3 -> 27885 | H3: =G3*J3 -> 27885 | I3: шт. | J3: 1 | K3: kaztek | M3: 27885
A4: 3 | B4: =B3 -> L3-ЩР-1 — Здание оператора L3 | C4: ats | D4: 256759 | E4: Устройство автоматического ввода резерва NXZM-63S/3B 40A (АВР) | F4: 201862 | G4: =F4*Kurallar!$B$2 -> 121117.2 | H4: =G4*J4 -> 121117.2 | I4: шт. | J4: 1 | K4: CHINT | M4: 121117.2
A5: 4 | B5: =B4 -> L3-ЩР-1 — Здание оператора L3 | C5: sayac | D5: IB | E5: ДАЛА СА4-Э720 R TX OP P П RS1 Д W (3x220/380V 5-100A) | F5: 88000 | G5: =F5*Kurallar!$B$4 -> 88000 | H5: =G5*J5 -> 88000 | I5: шт. | J5: 1 | K5: САЙМАН | M5: 88000
A6: 5 | B6: =B5 -> L3-ЩР-1 — Здание оператора L3 | C6: OTO | D6: 814039 | E6: Авт. выкл. NXB-63 1P 10A 6кА х-ка B | F6: 1419 | G6: =F6*Kurallar!$B$2 -> 851.4 | H6: =G6*J6 -> 851.4 | I6: шт. | J6: 1 | K6: CHINT | M6: 851.4
A7: 6 | B7: =B6 -> L3-ЩР-1 — Здание оператора L3 | C7: OTO | D7: 814014 | E7: Авт. выкл. NXB-63 1P 16A 6кА х-ка C | F7: 1389 | G7: =F7*Kurallar!$B$2 -> 833.4 | H7: =G7*J7 -> 2500.2 | I7: шт. | J7: 3 | K7: CHINT | M7: 2500.2
A8: 7 | B8: =B7 -> L3-ЩР-1 — Здание оператора L3 | C8: OTO | D8: 814171 | E8: Авт. выкл. NXB-63 3P 20A 6кА х-ка C | F8: 5884 | G8: =F8*Kurallar!$B$2 -> 3530.4 | H8: =G8*J8 -> 3530.4 | I8: шт. | J8: 1 | K8: CHINT | M8: 3530.4
A9: 8 | B9: =B8 -> L3-ЩР-1 — Здание оператора L3 | C9: DİF | D9: 515380 | E9: Диф. авт. выкл. NXBLE-63YH 1P+N C16 30mA тип AC, 6kA | F9: 5104 | G9: =F9*Kurallar!$B$2 -> 3062.4 | H9: =G9*J9 -> 9187.2 | I9: шт. | J9: 3 | K9: CHINT | M9: 9187.2
A10: 9 | B10: =B9 -> L3-ЩР-1 — Здание оператора L3 | C10: DİF | D10: 515387 | E10: Диф. авт. выкл. NXBLE-63YH 1P+N C20 30mA тип AC, 6kA | F10: 5632 | G10: =F10*Kurallar!$B$2 -> 3379.2 | H10: =G10*J10 -> 6758.4 | I10: шт. | J10: 2 | K10: CHINT | M10: 6758.4
A11: 10 | B11: =B10 -> L3-ЩР-1 — Здание оператора L3 | C11: LOOBAR | D11: YNN10-69-24D-K07 | E11: Шина N "ноль" на DIN-изол ШНИ-6х9-24-Д-С IEK | F11: 530 | G11: =F11*Kurallar!$B$3 -> 530 | H11: =G11*J11 -> 530 | I11: шт. | J11: 1 | K11: pys | M11: 530
A12: 11 | B12: =B11 -> L3-ЩР-1 — Здание оператора L3 | C12: LOOBAR | D12: 130200409_ | E12: Шина РЕ "земля" в комб DIN-изол ШНИ-8х12-8-КС-Ж IEK | F12: 634 | G12: =F12*Kurallar!$B$3 -> 634 | H12: =G12*J12 -> 1268 | I12: шт. | J12: 2 | K12: pys | M12: 1268
A13: 12 | B13: =B12 -> L3-ЩР-1 — Здание оператора L3 | C13: Klemens | D13: 701-03300-1 | E13: Проходная клеммная колодка SAK-2.5 (TEKLED ELECTRIC)2500/50 | F13: 140 | G13: =0.6*F13 -> 84 | H13: =G13*J13 -> 1344 | I13: шт. | J13: 16 | K13: tekled electric | M13: 1344
A14: 13 | B14: =B13 -> L3-ЩР-1 — Здание оператора L3 | C14: Klemens | D14: 701-03300-1 | E14: Проходная клеммная колодка SAK-2.5 (TEKLED ELECTRIC)2500/50 | F14: 140 | G14: =0.6*F14 -> 84 | H14: =G14*J14 -> 1008 | I14: шт. | J14: 12 | K14: tekled electric | M14: 1008
A15: 14 | B15: =B14 -> L3-ЩР-1 — Здание оператора L3 | C15: montajный материал | D15: 570003 | E15: DIN-рейка оцинкованная TH35-7.5 100cm | F15: 869 | G15: =F15*Kurallar!$B$2 -> 521.4 | H15: =G15*J15 -> 521.4 | I15: м | J15: 1 | K15: CHINT | M15: 521.4
A16: 15 | B16: =B15 -> L3-ЩР-1 — Здание оператора L3 | C16: montajный материал | D16: 270300105_ | E16: Кабель-канал перф. 40х60 ИМПАКТ IEK (2 м) | F16: 1808 | G16: =F16*Kurallar!$B$3 -> 1808 | H16: =G16*J16 -> 1808 | I16: шт. | J16: 1 | K16: IEK | M16: 1808
A17: 16 | B17: =B16 -> L3-ЩР-1 — Здание оператора L3 | C17: montajный материал | D17: 100300025_ | E17: Провод ПВ3-2,5 белый ГОСТ | F17: 127 | G17: =F17*Kurallar!$B$3 -> 127 | H17: =G17*J17 -> 2032 | I17: м | J17: 16 | K17: EKT | M17: 2032
A18: 17 | B18: =B17 -> L3-ЩР-1 — Здание оператора L3 | C18: montajный материал | D18: 100300015_ | E18: Провод ПВ3-16 белый ГОСТ | F18: 918 | G18: =F18*Kurallar!$B$3 -> 918 | H18: =G18*J18 -> 7344 | I18: м | J18: 8 | K18: EKT | M18: 7344
A19: 18 | B19: =B18 -> L3-ЩР-1 — Здание оператора L3 | C19: montajный материал | D19: 100300076_ | E19: Провод ПВ3-1,5 жёлто-зелёный ГОСТ | F19: 79 | G19: =F19*Kurallar!$B$3 -> 79 | H19: =G19*J19 -> 395 | I19: м | J19: 5 | K19: EKT | M19: 395
A20: 19 | B20: =B19 -> L3-ЩР-1 — Здание оператора L3 | C20: montajный материал | D20: MM-3% | E20: Монтажные материалы (крепёж, наконечники, маркировка, стяжки, сальники) — 3% от материалов | G20: =SUM(H3:H19)*Kurallar!$B$5 -> 8282.406 | H20: =G20*J20 -> 8282.406 | I20: шт. | J20: 1 | K20: - | M20: 8282.406
A21: 20 | B21: =B20 -> L3-ЩР-1 — Здание оператора L3 | C21: montajная работа | D21: ISC | E21: Сборка, монтаж, маркировка и испытание щита (норма времени, мин) | F21: =J21/60 -> 5.6833333 | G21: =Kurallar!$B$6 -> 100 | H21: =G21*J21 -> 34100 | I21: мин | J21: =ROUND((Kurallar!$B$10+1*Kurallar!$B$13+0*Kurallar!$B$14+0*Kurallar!$B$15+1*Kurallar!$B$16+0*Kurallar!$B$17+0*Kurallar!$B$18+5*Kurallar!$B$19+4*Kurallar!$B$20+1*Kurallar!$B$21+28*Kurallar!$B$22+3*Kurallar!$B$23+0*Kurallar!$B$24+3*Kurallar!$B$25)*Kurallar!$B$7,0)-200 -> 341 | K21: - | M21: 34100
B22: Toplam L3-ЩР-1 | H22: =SUBTOTAL(9,H3:H21) -> 0 | L22: =SUBTOTAL(9,H3:H19) -> 0 | M22: 318462.61
A23: 1 | B23: =E23 -> L5LS-ЩР-1 — Здание оператора нижней станции L5 LS | C23: пано | D23: ASM-ETN-028-EOM-DGD-0001 | E23: L5LS-ЩР-1 — Здание оператора нижней станции L5 LS | I23: комплект | J23: 1
A24: 2 | B24: =B23 -> L5LS-ЩР-1 — Здание оператора нижней станции L5 LS | C24: korpus | D24: 714-15117 | E24: Щит мет. ЩРн-5-2 PR (1000x650x300) IP31 (TS) | F24: 55770 | G24: =0.5*F24 -> 27885 | H24: =G24*J24 -> 27885 | I24: шт. | J24: 1 | K24: kaztek | M24: 27885
A25: 3 | B25: =B24 -> L5LS-ЩР-1 — Здание оператора нижней станции L5 LS | C25: ats | D25: 256759 | E25: Устройство автоматического ввода резерва NXZM-63S/3B 40A (АВР) | F25: 201862 | G25: =F25*Kurallar!$B$2 -> 121117.2 | H25: =G25*J25 -> 121117.2 | I25: шт. | J25: 1 | K25: CHINT | M25: 121117.2
A26: 4 | B26: =B25 -> L5LS-ЩР-1 — Здание оператора нижней станции L5 LS | C26: sayac | D26: IB | E26: ДАЛА СА4-Э720 R TX OP P П RS1 Д W (3x220/380V 5-100A) | F26: 88000 | G26: =F26*Kurallar!$B$4 -> 88000 | H26: =G26*J26 -> 88000 | I26: шт. | J26: 1 | K26: САЙМАН | M26: 88000
A27: 5 | B27: =B26 -> L5LS-ЩР-1 — Здание оператора нижней станции L5 LS | C27: OTO | D27: 814039 | E27: Авт. выкл. NXB-63 1P 10A 6кА х-ка B | F27: 1419 | G27: =F27*Kurallar!$B$2 -> 851.4 | H27: =G27*J27 -> 851.4 | I27: шт. | J27: 1 | K27: CHINT | M27: 851.4
A28: 6 | B28: =B27 -> L5LS-ЩР-1 — Здание оператора нижней станции L5 LS | C28: OTO | D28: 814014 | E28: Авт. выкл. NXB-63 1P 16A 6кА х-ка C | F28: 1389 | G28: =F28*Kurallar!$B$2 -> 833.4 | H28: =G28*J28 -> 2500.2 | I28: шт. | J28: 3 | K28: CHINT | M28: 2500.2
A29: 7 | B29: =B28 -> L5LS-ЩР-1 — Здание оператора нижней станции L5 LS | C29: OTO | D29: 814173 | E29: Авт. выкл. NXB-63 3P 32A 6кА х-ка C | F29: 6060 | G29: =F29*Kurallar!$B$2 -> 3636 | H29: =G29*J29 -> 3636 | I29: шт. | J29: 1 | K29: CHINT | M29: 3636
A30: 8 | B30: =B29 -> L5LS-ЩР-1 — Здание оператора нижней станции L5 LS | C30: DİF | D30: 515380 | E30: Диф. авт. выкл. NXBLE-63YH 1P+N C16 30mA тип AC, 6kA | F30: 5104 | G30: =F30*Kurallar!$B$2 -> 3062.4 | H30: =G30*J30 -> 15312 | I30: шт. | J30: 5 | K30: CHINT | M30: 15312
A31: 9 | B31: =B30 -> L5LS-ЩР-1 — Здание оператора нижней станции L5 LS | C31: DİF | D31: 515387 | E31: Диф. авт. выкл. NXBLE-63YH 1P+N C20 30mA тип AC, 6kA | F31: 5632 | G31: =F31*Kurallar!$B$2 -> 3379.2 | H31: =G31*J31 -> 20275.2 | I31: шт. | J31: 6 | K31: CHINT | M31: 20275.2
A32: 10 | B32: =B31 -> L5LS-ЩР-1 — Здание оператора нижней станции L5 LS | C32: LOOBAR | D32: YNN10-69-24D-K07 | E32: Шина N "ноль" на DIN-изол ШНИ-6х9-24-Д-С IEK | F32: 530 | G32: =F32*Kurallar!$B$3 -> 530 | H32: =G32*J32 -> 530 | I32: шт. | J32: 1 | K32: pys | M32: 530
A33: 11 | B33: =B32 -> L5LS-ЩР-1 — Здание оператора нижней станции L5 LS | C33: LOOBAR | D33: 130200409_ | E33: Шина РЕ "земля" в комб DIN-изол ШНИ-8х12-8-КС-Ж IEK | F33: 634 | G33: =F33*Kurallar!$B$3 -> 634 | H33: =G33*J33 -> 1902 | I33: шт. | J33: 3 | K33: pys | M33: 1902
A34: 12 | B34: =B33 -> L5LS-ЩР-1 — Здание оператора нижней станции L5 LS | C34: Klemens | D34: 701-03300-1 | E34: Проходная клеммная колодка SAK-2.5 (TEKLED ELECTRIC)2500/50 | F34: 140 | G34: =0.6*F34 -> 84 | H34: =G34*J34 -> 1848 | I34: шт. | J34: 22 | K34: tekled electric | M34: 1848
A35: 13 | B35: =B34 -> L5LS-ЩР-1 — Здание оператора нижней станции L5 LS | C35: Klemens | D35: 701-03300-1 | E35: Проходная клеммная колодка SAK-2.5 (TEKLED ELECTRIC)2500/50 | F35: 140 | G35: =0.6*F35 -> 84 | H35: =G35*J35 -> 1512 | I35: шт. | J35: 18 | K35: tekled electric | M35: 1512
A36: 14 | B36: =B35 -> L5LS-ЩР-1 — Здание оператора нижней станции L5 LS | C36: montajный материал | D36: 570003 | E36: DIN-рейка оцинкованная TH35-7.5 100cm | F36: 869 | G36: =F36*Kurallar!$B$2 -> 521.4 | H36: =G36*J36 -> 521.4 | I36: м | J36: 1 | K36: CHINT | M36: 521.4
A37: 15 | B37: =B36 -> L5LS-ЩР-1 — Здание оператора нижней станции L5 LS | C37: montajный материал | D37: 270300105_ | E37: Кабель-канал перф. 40х60 ИМПАКТ IEK (2 м) | F37: 1808 | G37: =F37*Kurallar!$B$3 -> 1808 | H37: =G37*J37 -> 1808 | I37: шт. | J37: 1 | K37: IEK | M37: 1808
A38: 16 | B38: =B37 -> L5LS-ЩР-1 — Здание оператора нижней станции L5 LS | C38: montajный материал | D38: 100300025_ | E38: Провод ПВ3-2,5 белый ГОСТ | F38: 127 | G38: =F38*Kurallar!$B$3 -> 127 | H38: =G38*J38 -> 3048 | I38: м | J38: 24 | K38: EKT | M38: 3048
A39: 17 | B39: =B38 -> L5LS-ЩР-1 — Здание оператора нижней станции L5 LS | C39: montajный материал | D39: 100300015_ | E39: Провод ПВ3-16 белый ГОСТ | F39: 918 | G39: =F39*Kurallar!$B$3 -> 918 | H39: =G39*J39 -> 7344 | I39: м | J39: 8 | K39: EKT | M39: 7344
A40: 18 | B40: =B39 -> L5LS-ЩР-1 — Здание оператора нижней станции L5 LS | C40: montajный материал | D40: 100300076_ | E40: Провод ПВ3-1,5 жёлто-зелёный ГОСТ | F40: 79 | G40: =F40*Kurallar!$B$3 -> 79 | H40: =G40*J40 -> 553 | I40: м | J40: 7 | K40: EKT | M40: 553
...

Sheet Sayfa1
A1: Артикул | B1: Номенклатура | C1: Цена (лист) | D1: Цена нетто | E1: Сумма | F1: Ед.изм. | G1: Кол-во | H1: Завод | I1: malz | J1: Сумма | K1: 2.3
A2: ASM-ETN-027-EOM-DGD-0001 | B2: L3-ЩР-1 — Здание оператора L3 | C2: =ROUNDUP(K2,-3) -> 733000 | D2: =0.7*C2 -> 513100 | E2: =D2*G2 -> 513100 | F2: комплект | G2: 1 | J2: 318462.61 | K2: =2.3*J2 -> 732463.99
A3: ASM-ETN-028-EOM-DGD-0001 | B3: L5LS-ЩР-1 — Здание оператора нижней станции L5 LS | C3: =ROUNDUP(K3,-3) -> 802000 | D3: =0.7*C3 -> 561400 | E3: =D3*G3 -> 561400 | F3: комплект | G3: 1 | J3: 348302.7 | K3: =2.3*J3 -> 801096.21
A4: ASM-ETN-004-EOM-DGD-0001 | B4: L5US-ВРУ-1 — Гараж для подвижного состава канатной дороги верхней станции L5 US — ВРУ-1 | C4: =ROUNDUP(K4,-3) -> 1344000 | D4: =0.7*C4 -> 940800 | E4: =D4*G4 -> 940800 | F4: комплект | G4: 1 | J4: 584194.85 | K4: =2.3*J4 -> 1343648.2
A5: ASM-ETN-004-EOM-DGD-0001 | B5: L5US-ЩС-1 — Гараж верхней станции L5 US — ЩС-1 | C5: =ROUNDUP(K5,-3) -> 226000 | D5: =0.7*C5 -> 158200 | E5: =D5*G5 -> 158200 | F5: комплект | G5: 1 | J5: 97941.842 | K5: =2.3*J5 -> 225266.24
A6: ASM-ETN-004-EOM-DGD-0001 | B6: L5US-ЩО-1 — Гараж верхней станции L5 US — ЩО-1 | C6: =ROUNDUP(K6,-3) -> 69000 | D6: =0.7*C6 -> 48300 | E6: =D6*G6 -> 48300 | F6: комплект | G6: 1 | J6: 29646.466 | K6: =2.3*J6 -> 68186.872
A7: ASM-ETN-005-EOM-DGD-0001 | B7: L6LS-ВРУ-1 — Гараж для подвижного состава канатной дороги нижней станции L6 LS — ВРУ-1 | C7: =ROUNDUP(K7,-3) -> 1305000 | D7: =0.7*C7 -> 913500 | E7: =D7*G7 -> 913500 | F7: комплект | G7: 1 | J7: 567125.93 | K7: =2.3*J7 -> 1304389.7
A8: ASM-ETN-005-EOM-DGD-0001 | B8: L6LS-ЩС-1 — Гараж нижней станции L6 LS — ЩС-1 | C8: =ROUNDUP(K8,-3) -> 252000 | D8: =0.7*C8 -> 176400 | E8: =D8*G8 -> 176400 | F8: комплект | G8: 1 | J8: 109227.06 | K8: =2.3*J8 -> 251222.25
A9: ASM-ETN-005-EOM-DGD-0001 | B9: L6LS-ЩО-1 — Гараж нижней станции L6 LS — ЩО-1 | C9: =ROUNDUP(K9,-3) -> 68000 | D9: =0.7*C9 -> 47600 | E9: =D9*G9 -> 47600 | F9: комплект | G9: 1 | J9: 29380.466 | K9: =2.3*J9 -> 67575.072
A10: ASM-ETN-029-EOM-DGD-0001 | B10: L6US-ЩР-1 — Здание оператора верхней станции L6 US | C10: =ROUNDUP(K10,-3) -> 788000 | D10: =0.7*C10 -> 551600 | E10: =D10*G10 -> 551600 | F10: комплект | G10: 1 | J10: 342470.11 | K10: =2.3*J10 -> 787681.24
A11: ASM-ETN-030-EOM-DGD-0001 | B11: L7LS-ЩР-1 — Здание оператора нижней станции L7 LS | C11: =ROUNDUP(K11,-3) -> 728000 | D11: =0.7*C11 -> 509600 | E11: =D11*G11 -> 509600 | F11: комплект | G11: 1 | J11: 316412.41 | K11: =2.3*J11 -> 727748.53
A12: ASM-ETN-031-EOM-DGD-0001 | B12: L7LS-WC-ЩР-1 — Кассы и общественные туалеты нижней станций L7 LS | C12: =ROUNDUP(K12,-3) -> 803000 | D12: =0.7*C12 -> 562100 | E12: =D12*G12 -> 562100 | F12: комплект | G12: 1 | J12: 348950.39 | K12: =2.3*J12 -> 802585.9
A13: ASM-ETN-032-EOM-DGD-0001 | B13: L7US-ЩР-1 — Здание оператора верхней станции L7 US | C13: =ROUNDUP(K13,-3) -> 695000 | D13: =0.7*C13 -> 486500 | E13: =D13*G13 -> 486500 | F13: комплект | G13: 1 | J13: 302109.21 | K13: =2.3*J13 -> 694851.17
... A27: ASM-ETN-042-EOM-DGD-0001 | B27: L15US-ЩР-1 — Здание оператора верхней станции L15 US | C27: =ROUNDUP(K27,-3) -> 768000 | D27: =0.7*C27 -> 537600 | E27: =D27*G27 -> 537600 | F27: комплект | G27: 1 | J27: 333713.86 | K27: =2.3*J27 -> 767541.88

Sheet СВОД
A1: № | B1: Щит | C1: Наименование объекта | D1: Корпус | E1: Кол-во компл. | F1: Цена за 1 компл. | G1: Сумма
A2: 1 | B2: L3-ЩР-1 | C2: Здание оператора L3 | D2: ЩМП-4 IP31 (800х650х250) EKT | E2: 1 | F2: =BOM!H22 -> 0 | G2: =E2*F2 -> 0
A3: 2 | B3: L5LS-ЩР-1 | C3: Здание оператора нижней станции L5 LS | D3: ЩМП-5 IP31 (1000х650х300) EKT | E3: 1 | F3: =BOM!H43 -> 0 | G3: =E3*F3 -> 0
A4: 3 | B4: L5US-ВРУ-1 | C4: Гараж для подвижного состава канатной дороги верхней станции L5 US — ВРУ-1 | D4: ЩМП-18 IP54 (1800х800х400) EKT | E4: 1 | F4: =BOM!H74 -> 0 | G4: =E4*F4 -> 0
A5: 4 | B5: L5US-ЩС-1 | C5: Гараж верхней станции L5 US — ЩС-1 | D5: ЩМП-4 IP31 (800х650х250) EKT | E5: 1 | F5: =BOM!H92 -> 0 | G5: =E5*F5 -> 0
A6: 5 | B6: L5US-ЩО-1 | C6: Гараж верхней станции L5 US — ЩО-1 | D6: ЩМП-1 IP31 (395х310х220) EKT | E6: 1 | F6: =BOM!H108 -> 0 | G6: =E6*F6 -> 0
A7: 6 | B7: L6LS-ВРУ-1 | C7: Гараж для подвижного состава канатной дороги нижней станции L6 LS — ВРУ-1 | D7: ЩМП-18 IP54 (1800х800х400) EKT | E7: 1 | F7: =BOM!H139 -> 0 | G7: =E7*F7 -> 0
A8: 7 | B8: L6LS-ЩС-1 | C8: Гараж нижней станции L6 LS — ЩС-1 | D8: ЩМП-4 IP31 (800х650х250) EKT | E8: 1 | F8: =BOM!H157 -> 0 | G8: =E8*F8 -> 0
A9: 8 | B9: L6LS-ЩО-1 | C9: Гараж нижней станции L6 LS — ЩО-1 | D9: ЩМП-1 IP31 (395х310х220) EKT | E9: 1 | F9: =BOM!H173 -> 0 | G9: =E9*F9 -> 0
A10: 9 | B10: L6US-ЩР-1 | C10: Здание оператора верхней станции L6 US | D10: ЩМП-5 IP31 (1000х650х300) EKT | E10: 1 | F10: =BOM!H194 -> 0 | G10: =E10*F10 -> 0
A11: 10 | B11: L7LS-ЩР-1 | C11: Здание оператора нижней станции L7 LS | D11: ЩМП-5 IP31 (1000х650х300) EKT | E11: 1 | F11: =BOM!H215 -> 0 | G11: =E11*F11 -> 0
A12: 11 | B12: L7LS-WC-ЩР-1 | C12: Кассы и общественные туалеты нижней станций L7 LS | D12: ЩМП-5 IP31 (1000х650х300) EKT | E12: 1 | F12: =BOM!H236 -> 0 | G12: =E12*F12 -> 0
A13: 12 | B13: L7US-ЩР-1 | C13: Здание оператора верхней станции L7 US | D13: ЩМП-4 IP31 (800х650х250) EKT | E13: 1 | F13: =BOM!H257 -> 0 | G13: =E13*F13 -> 0
A14: 13 | B14: L8-ЩР-1 | C14: Здание оператора L8 | D14: ЩМП-4 IP31 (800х650х250) EKT | E14: 1 | F14: =BOM!H278 -> 0 | G14: =E14*F14 -> 0
A15: 14 | B15: L10US-ЩР-1 | C15: Здание оператора верхней станции L10 US | D15: ЩМП-5 IP31 (1000х650х300) EKT | E15: 1 | F15: =BOM!H299 -> 0 | G15: =E15*F15 -> 0
A16: 15 | B16: L11LS-GARAJ-ЩР-1 | C16: Гараж для подвижного состава канатной дороги, гараж снегоходов нижней станции L11 LS | D16: ЩМП-5 IP31 (1000х650х300) EKT | E16: 1 | F16: =BOM!H321 -> 0 | G16: =E16*F16 -> 0
A17: 16 | B17: L11LS-OP-ЩР-1 | C17: Здание оператора нижней станции L11 LS | D17: ЩМП-5 IP31 (1000х650х300) EKT | E17: 1 | F17: =BOM!H342 -> 0 | G17: =E17*F17 -> 0
A18: 17 | B18: L11US-ЩР-1 | C18: Здание оператора верхней станции L11 US | D18: ЩМП-5 IP31 (1000х650х300) EKT | E18: 1 | F18: =BOM!H363 -> 0 | G18: =E18*F18 -> 0
A19: 18 | B19: L12LS-GARAJ-ЩР-1 | C19: Гараж для подвижного состава канатной дороги нижней станции L12 LS | D19: ЩМП-4 IP31 (800х650х250) EKT | E19: 1 | F19: =BOM!H383 -> 0 | G19: =E19*F19 -> 0
A20: 19 | B20: L12LS-OP-ЩР-1 | C20: Здание оператора нижней станции L12 LS | D20: ЩМП-5 IP31 (1000х650х300) EKT | E20: 1 | F20: =BOM!H404 -> 0 | G20: =E20*F20 -> 0
A21: 20 | B21: L12US-ЩР-1 | C21: Здание оператора верхней станции L12 US | D21: ЩМП-6 IP31 (1200х750х300) EKT | E21: 1 | F21: =BOM!H424 -> 0 | G21: =E21*F21 -> 0
A22: 21 | B22: L12US-ЩСВ | C22: Здание оператора верхней станции L12 US — ЩСВ | D22: ЩМП-3 IP31 (650х500х220) EKT | E22: 1 | F22: =BOM!H442 -> 0 | G22: =E22*F22 -> 0
A23: 22 | B23: L14LS-ЩР-1 | C23: Здание оператора нижней станции L14 LS | D23: ЩМП-5 IP31 (1000х650х300) EKT | E23: 1 | F23: =BOM!H463 -> 0 | G23: =E23*F23 -> 0
A24: 23 | B24: L14US-ЩР-1 | C24: Пункт спасателей, здание оператора верхней станции L14 US | D24: ЩМП-6 IP31 (1200х750х300) EKT | E24: 1 | F24: =BOM!H483 -> 0 | G24: =E24*F24 -> 0
A25: 24 | B25: L14US-ЩСВ | C25: Пункт спасателей, здание оператора верхней станции L14 US — ЩСВ | D25: ЩМП-4 IP31 (800х650х250) EKT | E25: 1 | F25: =BOM!H501 -> 0 | G25: =E25*F25 -> 0
A26: 25 | B26: L15LS-ЩР-1 | C26: Здание оператора нижней станции L15 LS | D26: ЩМП-5 IP31 (1000х650х300) EKT | E26: 1 | F26: =BOM!H522 -> 0 | G26: =E26*F26 -> 0
A27: 26 | B27: L15US-ЩР-1 | C27: Здание оператора верхней станции L15 US | D27: ЩМП-5 IP31 (1000х650х300) EKT | E27: 1 | F27: =BOM!H543 -> 0 | G27: =E27*F27 -> 0
B28: ИТОГО | E28: =SUM(E2:E27) -> 26 | G28: =SUM(G2:G27) -> 0
