Workbook

Sheet Kurallar
A1: PARAMETRE | B1: DEĞER | C1: AÇIKLAMA
A2: CHINT net katsayısı | B2: 0.6 | C2: Liste × 0,60 (%40 indirim). Liste: CHINT 13.06.2026 (KZT)
A3: EKT / IEK / UNIT katsayısı | B3: 1 | C3: Liste: EKT 19.06.2025 (KZT)
A4: САЙМАН katsayısı | B4: 1 | C4: Liste: САЙМАН 2026 (KZT)
A5: Montaj malzemesi oranı | B5: 0.03 | C5: Pano malzeme ara toplamının %3'ü
A6: İşçilik birim fiyat (KZT/dk) | B6: 100 | C6: Montajная работа
A7: Test/etiket/kontrol çarpanı | B7: 1.15 | C7: Toplam dakika × 1,15
A8: ZAMAN NORMLARI | C8: dakika
A9: Korpus hazırlık (orta boy) | B9: 45 | C9: dk/adet
A10: АВР / MCCB ≤250A | B10: 60 | C10: dk/adet
A11: Sayaç (trafosuz) | B11: 90 | C11: dk/adet
A12: Диф.авт. (RCBO) 1P+N | B12: 12 | C12: dk/adet
A13: Авт.выкл. (MCB) 1P | B13: 10 | C13: dk/adet
A14: Авт.выкл. (MCB) 3P | B14: 18 | C14: dk/adet
A15: Klemens | B15: 4 | C15: dk/adet
A16: DIN ray / kablo kanalı | B16: 5 | C16: dk/m
A17: HESAPLANAN İŞÇİLİK (dk) | C17: ЩР-1 toplam dakika
B18: =ROUND((B9+B10+B11+5*B12+4*B13+1*B14+20*B15+6*B16)*B7,0) -> 486
A20: PROJE | B20: 260727 İda Yakup Bey — ЩР-1 — CHINT
A21: Şema verisi | B21: Ру=11,2 kW · Кс=0,8 · Рр=9,0 kW · cosφ=0,9 · Iр=15,1 A · Un=380 V
A22: FİYAT LİSTESİ YAŞI
A23: CHINT 13.06.2026 | B23: 1,5 ay — GÜNCEL
A24: САЙМАН 2026 | B24: GÜNCEL
A25: EKT 19.06.2025 | B25: UYARI: 13 ay — 2026 listesi istenmeli
A26: Teksan 14.04.2025 | B26: KULLANILMADI: dosya aydınlatma stoğu, korpus stoğu değil. Korpus EKT'den alındı.
A27: KONTROL / RİSK
A28: АВР NXZM-63 | B28: Şemada 3P 32A. CHINT'te 32A YOK. 40A alındı (art.256759), stok sadece 3 ad. Şemada 2. besleme (rezerv) görünmüyor — АВР gerçekten var mı? Alternatif: NXM-63S/3P 32A giriş şalteri (KONTROL bölümünde).
A29: NXB-63 1P B10A | B29: STOK 0 (art.814039). Alternatif NXB-63 1P C10 (art.814013, stok 3720) KONTROL bölümünde.
A30: NXBLE-63 1P+N | B30: Düz NXBLE-63 serisi stokta sadece 2P/4P. 1P+N için NXBLE-63YH (6kA, tip AC) alındı. Tip A isteniyorsa: 515381 (C16), 515388 (C20) — aynı fiyat.
A31: Sayaç | B31: Şemada Дала САР4-Э721 ТХ PLC IP П RS 10(100A). САЙМАН 2026 listesinde Э721 yok; Дала СА4-Э720 R ТХ IР П RS Д 10-100A (kod LI) eşdeğer alındı. Sayaç ЭСО/müşteri temini ise satır silinecek.
A32: Şema görseli | B32: Görsel alttan kesik — kablo/yük tablosu okunamadı, çift kaynak doğrulama YAPILAMADI.
A33: Parafudr (ОПН) | B33: Şemada yok. Bina giriş panosu — eklenmesi değerlendirilmeli.
A34: Faz dağılımı | B34: 8 adet tek fazlı çıkış L1/L2/L3'e dengeli dağıtılacak (montaj notu).
A35: Korpus seçimi | B35: 19 modül DIN + АВР bloğu (~180×165 mm) → ЩМП-3 IP31 650×500×220. АВР iptal olursa ЩМП-2 500×400×220 yeterli.

Sheet BOM
A1: ROW | B1: Наименование1 | C1: Тип | D1: Артикул | E1: Номенклатура | F1: Цена (лист) | G1: Цена нетто | H1: Сумма | I1: Кол-во | J1: Ед.изм. | K1: Завод | L1: malz | M1: mal grup
A2: 1 | B2: =E2 -> ЩР-1 (260727 sprksy) (ELL-L3) | C2: пано | E2: ЩР-1 (260727 sprksy) (ELL-L3) | I2: 1 | J2: комплект
A3: 2 | B3: =B2 -> ЩР-1 (260727 sprksy) (ELL-L3) | C3: korpus | D3: 714-15117 | E3: Щит мет. ЩРн-5-2 PR (1000x650x300) IP31 (TS) | F3: 55770 | G3: =0.6*F3 -> 33462 | H3: =G3*I3 -> 33462 | I3: 1 | J3: шт. | K3: kaztek
A4: 3 | B4: =B3 -> ЩР-1 (260727 sprksy) (ELL-L3) | C4: ats | D4: 256759 | E4: Устройство автоматического ввода резерва NXZM-63S/3B 40A (АВР) | F4: 201862 | G4: =F4*Kurallar!$B$2 -> 121117.2 | H4: =G4*I4 -> 121117.2 | I4: 1 | J4: шт. | K4: CHINT
A5: 4 | B5: =B4 -> ЩР-1 (260727 sprksy) (ELL-L3) | C5: sayac | D5: IB | E5: ДАЛА СА4-Э720 R TX OP P П RS1 Д W (3x220/380V 5-100A) | F5: 88000 | G5: =F5*Kurallar!$B$4 -> 88000 | H5: =G5*I5 -> 88000 | I5: 1 | J5: шт. | K5: САЙМАН
A6: 5 | B6: =B5 -> ЩР-1 (260727 sprksy) (ELL-L3) | C6: DİF | D6: 515380 | E6: Диф. авт. выкл. NXBLE-63YH 1P+N C16 30mA тип AC, 6kA | F6: 5104 | G6: =F6*Kurallar!$B$2 -> 3062.4 | H6: =G6*I6 -> 9187.2 | I6: 3 | J6: шт. | K6: CHINT
A7: 6 | B7: =B6 -> ЩР-1 (260727 sprksy) (ELL-L3) | C7: DİF | D7: 515387 | E7: Диф. авт. выкл. NXBLE-63YH 1P+N C20 30mA тип AC, 6kA | F7: 5632 | G7: =F7*Kurallar!$B$2 -> 3379.2 | H7: =G7*I7 -> 6758.4 | I7: 2 | J7: шт. | K7: CHINT
A8: 7 | B8: =B7 -> ЩР-1 (260727 sprksy) (ELL-L3) | C8: OTO | D8: 814014 | E8: Авт. выкл. NXB-63 1P 16A 6кА х-ка C | F8: 1389 | G8: =F8*Kurallar!$B$2 -> 833.4 | H8: =G8*I8 -> 2500.2 | I8: 3 | J8: шт. | K8: CHINT
A9: 8 | B9: =B8 -> ЩР-1 (260727 sprksy) (ELL-L3) | C9: OTO | D9: 814039 | E9: Авт. выкл. NXB-63 1P 10A 6кА х-ка B | F9: 1419 | G9: =F9*Kurallar!$B$2 -> 851.4 | H9: =G9*I9 -> 851.4 | I9: 1 | J9: шт. | K9: CHINT
A10: 9 | B10: =B9 -> ЩР-1 (260727 sprksy) (ELL-L3) | C10: OTO | D10: 814171 | E10: Авт. выкл. NXB-63 3P 20A 6кА х-ка C | F10: 5884 | G10: =F10*Kurallar!$B$2 -> 3530.4 | H10: =G10*I10 -> 3530.4 | I10: 1 | J10: шт. | K10: CHINT
A11: 10 | B11: =B10 -> ЩР-1 (260727 sprksy) (ELL-L3) | C11: LOOBAR | D11: 130200007_ | E11: Шина "N" нулевая 6х9мм 14/2 (крепеж по краям) IEK | F11: 494 | G11: =F11*Kurallar!$B$3 -> 494 | H11: =G11*I11 -> 494 | I11: 1 | J11: шт. | K11: pys
A12: 11 | B12: =B11 -> ЩР-1 (260727 sprksy) (ELL-L3) | C12: LOOBAR | D12: 130200409_ | E12: Шина РЕ "земля" в комб DIN-изол "Стойка" ШНИ-8х12-8-КС-Ж IEK | F12: 634 | G12: =F12*Kurallar!$B$3 -> 634 | H12: =G12*I12 -> 634 | I12: 1 | J12: шт. | K12: pys
A13: 12 | B13: =B12 -> ЩР-1 (260727 sprksy) (ELL-L3) | C13: Klemens | D13: 130301153_ | E13: ЗНИ 4мм² (35А) серый UNIT | F13: 90 | G13: =F13*Kurallar!$B$3 -> 90 | H13: =G13*I13 -> 1800 | I13: 20 | J13: шт. | K13: pys
A14: 13 | B14: =B13 -> ЩР-1 (260727 sprksy) (ELL-L3) | C14: montajный материал | D14: 570003 | E14: DIN-рейка оцинкованная TH35-7.5 100cm | F14: 869 | G14: =F14*Kurallar!$B$2 -> 521.4 | H14: =G14*I14 -> 1042.8 | I14: 2 | J14: м | K14: pys
A15: 14 | B15: =B14 -> ЩР-1 (260727 sprksy) (ELL-L3) | C15: montajный материал | D15: 270300105_ | E15: Кабель-канал перф. 40х60 ИМПАКТ IEK (2 м) | F15: 1808 | G15: =F15*Kurallar!$B$3 -> 1808 | H15: =G15*I15 -> 3616 | I15: 2 | J15: шт. | K15: pys
A16: 15 | B16: =B15 -> ЩР-1 (260727 sprksy) (ELL-L3) | C16: montajный материал | D16: 100300025_ | E16: Провод ПВ3-2,5 белый ГОСТ | F16: 127 | G16: =F16*Kurallar!$B$3 -> 127 | H16: =G16*I16 -> 3175 | I16: 25 | J16: м | K16: pys
A17: 16 | B17: =B16 -> ЩР-1 (260727 sprksy) (ELL-L3) | C17: montajный материал | D17: 100300031_ | E17: Провод ПВ3-6 белый ГОСТ | F17: 319 | G17: =F17*Kurallar!$B$3 -> 319 | H17: =G17*I17 -> 1914 | I17: 6 | J17: м | K17: pys
A18: 17 | B18: =B17 -> ЩР-1 (260727 sprksy) (ELL-L3) | C18: montajный материал | D18: 100300076_ | E18: Провод ПВ3-1,5 жёлто-зелёный ГОСТ | F18: 79 | G18: =F18*Kurallar!$B$3 -> 79 | H18: =G18*I18 -> 237 | I18: 3 | J18: м | K18: pys
A19: 18 | B19: =B18 -> ЩР-1 (260727 sprksy) (ELL-L3) | C19: montajный материал | D19: MM-3% | E19: Монтажные материалы (крепёж, маркировка, наконечники, стяжки) — 3% от материалов | G19: =SUM(H3:H18)*Kurallar!$B$5 -> 8349.588 | H19: =G19*I19 -> 8349.588 | I19: 1 | J19: компл. | K19: -
A20: 19 | B20: =B19 -> ЩР-1 (260727 sprksy) (ELL-L3) | C20: montajная работа | D20: ISC-01 | E20: Сборка, монтаж, маркировка и испытание щита (норма времени, мин) | F20: =I20/60 -> 8.1 | G20: =Kurallar!$B$6 -> 100 | H20: =G20*I20 -> 48600 | I20: =Kurallar!$B$18 -> 486 | J20: мин | K20: -
A21: 20 | B21: =B20 -> ЩР-1 (260727 sprksy) (ELL-L3) | H21: =SUM(H3:H20) -> 335269.19
A22: 1 | B22: =E22 -> ЩР-1 (260727 sprksy) (L5LS-ЩР-1) | C22: пано | E22: ЩР-1 (260727 sprksy) (L5LS-ЩР-1) | I22: 1 | J22: комплект
A23: 2 | B23: =B22 -> ЩР-1 (260727 sprksy) (L5LS-ЩР-1) | C23: korpus | D23: 714-15117 | E23: Щит мет. ЩРн-5-2 PR (1000x650x300) IP31 (TS) | F23: 55770 | G23: =0.6*F23 -> 33462 | H23: =G23*I23 -> 33462 | I23: 1 | J23: шт. | K23: kaztek
A24: 3 | B24: =B23 -> ЩР-1 (260727 sprksy) (L5LS-ЩР-1) | C24: ats | D24: 256759 | E24: Устройство автоматического ввода резерва NXZM-63S/3B 40A (АВР) | F24: 201862 | G24: =F24*Kurallar!$B$2 -> 121117.2 | H24: =G24*I24 -> 121117.2 | I24: 1 | J24: шт. | K24: CHINT
A25: 4 | B25: =B24 -> ЩР-1 (260727 sprksy) (L5LS-ЩР-1) | C25: sayac | D25: IB | E25: ДАЛА СА4-Э720 R TX OP P П RS1 Д W (3x220/380V 5-100A) | F25: 88000 | G25: =F25*Kurallar!$B$4 -> 88000 | H25: =G25*I25 -> 88000 | I25: 1 | J25: шт. | K25: САЙМАН
A26: 5 | B26: =B25 -> ЩР-1 (260727 sprksy) (L5LS-ЩР-1) | C26: DİF | D26: 515380 | E26: Диф. авт. выкл. NXBLE-63YH 1P+N C16 30mA тип AC, 6kA | F26: 5104 | G26: =F26*Kurallar!$B$2 -> 3062.4 | H26: =G26*I26 -> 15312 | I26: 5 | J26: шт. | K26: CHINT
A27: 6 | B27: =B26 -> ЩР-1 (260727 sprksy) (L5LS-ЩР-1) | C27: DİF | D27: 515387 | E27: Диф. авт. выкл. NXBLE-63YH 1P+N C20 30mA тип AC, 6kA | F27: 5632 | G27: =F27*Kurallar!$B$2 -> 3379.2 | H27: =G27*I27 -> 20275.2 | I27: 6 | J27: шт. | K27: CHINT
A28: 7 | B28: =B27 -> ЩР-1 (260727 sprksy) (L5LS-ЩР-1) | C28: OTO | D28: 814014 | E28: Авт. выкл. NXB-63 1P 16A 6кА х-ка C | F28: 1389 | G28: =F28*Kurallar!$B$2 -> 833.4 | H28: =G28*I28 -> 2500.2 | I28: 3 | J28: шт. | K28: CHINT
A29: 8 | B29: =B28 -> ЩР-1 (260727 sprksy) (L5LS-ЩР-1) | C29: OTO | D29: 814039 | E29: Авт. выкл. NXB-63 1P 10A 6кА х-ка B | F29: 1419 | G29: =F29*Kurallar!$B$2 -> 851.4 | H29: =G29*I29 -> 851.4 | I29: 1 | J29: шт. | K29: CHINT
A30: 9 | B30: =B29 -> ЩР-1 (260727 sprksy) (L5LS-ЩР-1) | C30: OTO | D30: 814171 | E30: 3*32 | F30: 5884 | G30: =F30*Kurallar!$B$2 -> 3530.4 | H30: =G30*I30 -> 3530.4 | I30: 1 | J30: шт. | K30: CHINT
A31: 10 | B31: =B30 -> ЩР-1 (260727 sprksy) (L5LS-ЩР-1) | C31: LOOBAR | D31: 130200007_ | E31: Шина "N" нулевая 6х9мм 14/2 (крепеж по краям) IEK | F31: 494 | G31: =F31*Kurallar!$B$3 -> 494 | H31: =G31*I31 -> 494 | I31: 1 | J31: шт. | K31: pys
A32: 11 | B32: =B31 -> ЩР-1 (260727 sprksy) (L5LS-ЩР-1) | C32: LOOBAR | D32: 130200409_ | E32: Шина РЕ "земля" в комб DIN-изол "Стойка" ШНИ-8х12-8-КС-Ж IEK | F32: 634 | G32: =F32*Kurallar!$B$3 -> 634 | H32: =G32*I32 -> 634 | I32: 1 | J32: шт. | K32: pys
A33: 12 | B33: =B32 -> ЩР-1 (260727 sprksy) (L5LS-ЩР-1) | C33: Klemens | D33: 130301153_ | E33: ЗНИ 4мм² (35А) серый UNIT | F33: 90 | G33: =F33*Kurallar!$B$3 -> 90 | H33: =G33*I33 -> 1800 | I33: 20 | J33: шт. | K33: pys
A34: 13 | B34: =B33 -> ЩР-1 (260727 sprksy) (L5LS-ЩР-1) | C34: montajный материал | D34: 570003 | E34: DIN-рейка оцинкованная TH35-7.5 100cm | F34: 869 | G34: =F34*Kurallar!$B$2 -> 521.4 | H34: =G34*I34 -> 1042.8 | I34: 2 | J34: м | K34: pys
A35: 14 | B35: =B34 -> ЩР-1 (260727 sprksy) (L5LS-ЩР-1) | C35: montajный материал | D35: 270300105_ | E35: Кабель-канал перф. 40х60 ИМПАКТ IEK (2 м) | F35: 1808 | G35: =F35*Kurallar!$B$3 -> 1808 | H35: =G35*I35 -> 3616 | I35: 2 | J35: шт. | K35: pys
A36: 15 | B36: =B35 -> ЩР-1 (260727 sprksy) (L5LS-ЩР-1) | C36: montajный материал | D36: 100300025_ | E36: Провод ПВ3-2,5 белый ГОСТ | F36: 127 | G36: =F36*Kurallar!$B$3 -> 127 | H36: =G36*I36 -> 3175 | I36: 25 | J36: м | K36: pys
A37: 16 | B37: =B36 -> ЩР-1 (260727 sprksy) (L5LS-ЩР-1) | C37: montajный материал | D37: 100300031_ | E37: Провод ПВ3-6 белый ГОСТ | F37: 319 | G37: =F37*Kurallar!$B$3 -> 319 | H37: =G37*I37 -> 1914 | I37: 6 | J37: м | K37: pys
A38: 17 | B38: =B37 -> ЩР-1 (260727 sprksy) (L5LS-ЩР-1) | C38: montajный материал | D38: 100300076_ | E38: Провод ПВ3-1,5 жёлто-зелёный ГОСТ | F38: 79 | G38: =F38*Kurallar!$B$3 -> 79 | H38: =G38*I38 -> 237 | I38: 3 | J38: м | K38: pys
A39: 18 | B39: =B38 -> ЩР-1 (260727 sprksy) (L5LS-ЩР-1) | C39: montajный материал | D39: MM-3% | E39: Монтажные материалы (крепёж, маркировка, наконечники, стяжки) — 3% от материалов | G39: =SUM(H23:H38)*Kurallar!$B$5 -> 8938.836 | H39: =G39*I39 -> 8938.836 | I39: 1 | J39: компл. | K39: -
A40: 19 | B40: =B39 -> ЩР-1 (260727 sprksy) (L5LS-ЩР-1) | C40: montajная работа | D40: ISC-01 | E40: Сборка, монтаж, маркировка и испытание щита (норма времени, мин) | F40: =I40/60 -> 8.1 | G40: =Kurallar!$B$6 -> 100 | H40: =G40*I40 -> 48600 | I40: =Kurallar!$B$18 -> 486 | J40: мин | K40: -
...

Sheet СВОД
A1: № | B1: Наименование щита | C1: Кол-во компл. | D1: Цена за 1 компл. | E1: Сумма | F1: Примечание
A2: 1 | B2: ЩР-1 (шкаф распределительный, ввод + учёт, 10 отходящих линий) | C2: 1 | D2: =BOM!#REF! -> #REF! | E2: =C2*D2 -> #REF! | F2: АВР ve sayaç dahil. KONTROL satırları hariç.
B3: ИТОГО | E3: =SUM(E2:E2) -> #REF!
