Workbook

Sheet Kurallar
A1: PARAMETRE | B1: DEĞER | C1: AÇIKLAMA
A2: CHINT net katsayısı | B2: 0.6 | C2: Liste × 0,60 (%40 indirim). Kaynak: CHINT 13.06.2026 (KZT)
A3: EKT / IEK / UNIT katsayısı | B3: 1 | C3: Kaynak: EKT 19.06.2025 (KZT)
A4: САЙМАН katsayısı | B4: 1 | C4: Kaynak: САЙМАН 2026 (KZT)
A5: Montaj malzemesi oranı | B5: 0.03 | C5: Pano malzeme ara toplamının %3'ü
A6: İşçilik birim fiyat (KZT/dk) | B6: 100 | C6: Montajная работа
A7: Test/etiket/kontrol çarpanı | B7: 1.15 | C7: Toplam dakika × 1,15
A8: ZAMAN NORMLARI | C8: dakika
A9: Korpus hazırlık (orta boy) | B9: 45 | C9: dk/adet × 1
A10: АВР / MCCB ≤250A | B10: 60 | C10: dk/adet × 1
A11: Sayaç (trafosuz) | B11: 90 | C11: dk/adet × 1
A12: Диф.авт. (RCBO) 1P+N | B12: 12 | C12: dk/adet × 8
A13: Авт.выкл. (MCB) 1P | B13: 10 | C13: dk/adet × 5
A14: Авт.выкл. (MCB) 3P | B14: 18 | C14: dk/adet × 1
A15: Klemens | B15: 4 | C15: dk/adet × 6
A16: Bara / tarak | B16: 10 | C16: dk/adet × 2
A17: DIN ray / kablo kanalı | B17: 5 | C17: dk/m × 9
A18: HESAPLANAN İŞÇİLİK (dk) | B18: =ROUND((B9+B10+B11+8*B12+5*B13+1*B14+6*B15+2*B16+9*B17)*B7,0) -> 515 | C18: ЩР-1 toplam dakika
A20: PROJE | B20: 260727 İda Yakup Bey — ЩР-1 — CHINT — v2 (tam şema + spesifikasyon ile)
A21: Şema verisi | B21: Ру=24,5 kW · Кс=0,75 · Рр=18,4 kW · cosφ=0,9 · Iр=31,0 A · Un=380 V · IP31 · навесной
A22: FİYAT LİSTESİ YAŞI
A23: CHINT 13.06.2026 | B23: 1,5 ay — GÜNCEL
A24: САЙМАН 2026 | B24: GÜNCEL
A25: EKT 19.06.2025 | B25: UYARI: 13 ay — 2026 listesi istenmeli
A26: Teksan 14.04.2025 | B26: KULLANILMADI: dosya aydınlatma stoğu, korpus stoğu değil. Korpus EKT'den alındı.
A27: ÇİFT KAYNAK DOĞRULAMA (şema / spesifikasyon)
A28: АВР NXZM-63 40A | B28: Şema: 3P 40A · Spek: H/4P B40A → ÇELİŞKİ. CHINT stokta 4 kutuplu NXZM-63 YOK; sadece NXZM-63S/3B (3 kutup) var, stok 3 adet. 4P zorunluysa özel sipariş/teslim süresi sorulacak.
A29: Sayaç САР4-Э721 | B29: Şema ✓ Spek ✓ (uyumlu). Ancak САЙМАН 2026 listesinde Э721 YOK; Дала СА4-Э720 R ТХ IР П RS Д 10-100A (kod LI) eşdeğer alındı. ЭСО/müşteri temini ise satır silinecek.
A30: NXB-63 3P C32A | B30: Şema 1 ad ✓ Spek 1 ad ✓ (Гр.8 Вентиляция)
A31: NXBLE-63 C20A 30mA | B31: Şema 5 ad ✓ Spek 5 ad ✓ (Гр.3,4,5,6,7 Электрический радиатор)
A32: NXBLE-63 C16A 30mA | B32: Şema 3 ad ✓ Spek 3 ad ✓ (Гр.1,2 Розетка + 1 РЕЗЕРВ)
A33: NXB-63 1P C16A | B33: Şema 3 ad ✓ Spek 3 ad ✓ (АПС Прибор, СКС Шкаф АПС + 1 РЕЗЕРВ)
A34: NXB-63 1P B10A | B34: Şema 2 ad ✓ Spek 2 ad ✓ (№1, №2 Освещения)
A35: Toplam çıkış | B35: 14 hat = 12 numaralı + 2 РЕЗЕРВ. Şema ve spesifikasyon tam uyumlu.
A36: KONTROL / RİSK
A37: NXBLE-63 1P+N | B37: Düz NXBLE-63 serisi CHINT stokta sadece 2P/4P. 1P+N için NXBLE-63YH (6kA, tip AC) alındı. Tip A istenirse KONTROL bölümündeki 515381/515388 kullanılacak (fiyat aynı).
A38: NXB-63 1P B10A | B38: STOK 0 (art.814039, 2 adet gerekli). Alternatif NXB-63 1P C10 (art.814013, stok 3720) KONTROL bölümünde.
A39: АВР stok | B39: NXZM-63S/3B 40A stok sadece 3 adet — sipariş öncesi rezerv yapılmalı.
A40: Шины 3L+N+PE | B40: Spekte istenen bara seti: N barası ШНИ-6х9-24-Д-С ×1, PE barası ШНИ-6х9-24-Д-С (sarı-yeşil markalama) ×1, faz dağıtımı için PIN 1P 63A tarak ×2 (kesilerek 3 faza bölünür).
A41: Klemens | B41: Çıkış kabloları (ВВГнг-LS) doğrudan otomat klemensine bağlanıyor — çıkış klemens sırası yok. 6 ad ЗНИ sadece АВР kumanda/yardımcı devre için.
...

Sheet BOM
A1: ROW | B1: Наименование1 | C1: Тип | D1: Артикул | E1: Номенклатура | F1: Цена (лист) | G1: Цена нетто | H1: Сумма | I1: Кол-во | J1: Ед.изм. | K1: Завод | L1: malz | M1: mal grup
A2: 1 | B2: =E2 -> ЩР-1 Щит силовой распределительный навесной 380В IP31 (ввод АВР + учёт, 14 отходящих линий) | C2: пано | E2: ЩР-1 Щит силовой распределительный навесной 380В IP31 (ввод АВР + учёт, 14 отходящих линий) | I2: 1 | J2: комплект
A3: 2 | C3: korpus | D3: 250200068_ | E3: ЩМП-3 IP31 (650х500х220) EKT | F3: 16158 | G3: =F3*Kurallar!$B$3 -> 16158 | H3: =G3*I3 -> 16158 | I3: 1 | J3: шт. | K3: EKT
A4: 3 | C4: rubilnik | D4: 256759 | E4: Устройство автоматического ввода резерва NXZM-63S/3B 40A (АВР) | F4: 201862 | G4: =F4*Kurallar!$B$2 -> 121117.2 | H4: =G4*I4 -> 121117.2 | I4: 1 | J4: шт. | K4: CHINT
A5: 4 | C5: sayac | D5: LI | E5: Счётчик Дала CA4-Э720 R ТХ IР П RS Д (3х220/380V 10-100A) | F5: 39100 | G5: =F5*Kurallar!$B$4 -> 39100 | H5: =G5*I5 -> 39100 | I5: 1 | J5: шт. | K5: САЙМАН
A6: 5 | C6: DİF | D6: 515380 | E6: Диф. авт. выкл. NXBLE-63YH 1P+N C16 30mA тип AC, 6kA | F6: 5104 | G6: =F6*Kurallar!$B$2 -> 3062.4 | H6: =G6*I6 -> 9187.2 | I6: 3 | J6: шт. | K6: CHINT
A7: 6 | C7: DİF | D7: 515387 | E7: Диф. авт. выкл. NXBLE-63YH 1P+N C20 30mA тип AC, 6kA | F7: 5632 | G7: =F7*Kurallar!$B$2 -> 3379.2 | H7: =G7*I7 -> 16896 | I7: 5 | J7: шт. | K7: CHINT
A8: 7 | C8: OTO | D8: 814014 | E8: Авт. выкл. NXB-63 1P 16A 6кА х-ка C | F8: 1389 | G8: =F8*Kurallar!$B$2 -> 833.4 | H8: =G8*I8 -> 2500.2 | I8: 3 | J8: шт. | K8: CHINT
A9: 8 | C9: OTO | D9: 814039 | E9: Авт. выкл. NXB-63 1P 10A 6кА х-ка B | F9: 1419 | G9: =F9*Kurallar!$B$2 -> 851.4 | H9: =G9*I9 -> 1702.8 | I9: 2 | J9: шт. | K9: CHINT
A10: 9 | C10: OTO | D10: 814173 | E10: Авт. выкл. NXB-63 3P 32A 6кА х-ка C | F10: 6060 | G10: =F10*Kurallar!$B$2 -> 3636 | H10: =G10*I10 -> 3636 | I10: 1 | J10: шт. | K10: CHINT
A11: 10 | C11: LOOBAR | D11: YNN10-69-24D-K07 | E11: Шина N "ноль" на DIN-изол ШНИ-6х9-24-Д-С IEK | F11: 530 | G11: =F11*Kurallar!$B$3 -> 530 | H11: =G11*I11 -> 530 | I11: 1 | J11: шт. | K11: IEK
A12: 11 | C12: LOOBAR | D12: YNN10-69-24D-K07 | E12: Шина PE "земля" на DIN-изол ШНИ-6х9-24-Д-С IEK (маркировка ж/з) | F12: 530 | G12: =F12*Kurallar!$B$3 -> 530 | H12: =G12*I12 -> 530 | I12: 1 | J12: шт. | K12: IEK
A13: 12 | C13: LOOBAR | D13: 811000 | E13: Шина соединительная типа PIN 1P, 63А, L=1000мм | F13: 4465 | G13: =F13*Kurallar!$B$2 -> 2679 | H13: =G13*I13 -> 5358 | I13: 2 | J13: шт. | K13: CHINT
A14: 13 | C14: Klemens | D14: 130301153_ | E14: ЗНИ 4мм² (35А) серый UNIT | F14: 90 | G14: =F14*Kurallar!$B$3 -> 90 | H14: =G14*I14 -> 540 | I14: 6 | J14: шт. | K14: UNIT
A15: 14 | C15: montajный материал | D15: 570003 | E15: DIN-рейка оцинкованная TH35-7.5 100cm | F15: 869 | G15: =F15*Kurallar!$B$2 -> 521.4 | H15: =G15*I15 -> 1564.2 | I15: 3 | J15: м | K15: CHINT
A16: 15 | C16: montajный материал | D16: 270300105_ | E16: Кабель-канал перф. 40х60 ИМПАКТ IEK (2 м) | F16: 1808 | G16: =F16*Kurallar!$B$3 -> 1808 | H16: =G16*I16 -> 5424 | I16: 3 | J16: шт. | K16: IEK
A17: 16 | C17: montajный материал | D17: 100300025_ | E17: Провод ПВ3-2,5 белый ГОСТ | F17: 127 | G17: =F17*Kurallar!$B$3 -> 127 | H17: =G17*I17 -> 5080 | I17: 40 | J17: м | K17: EKT
A18: 17 | C18: montajный материал | D18: 100300079_ | E18: Провод ПВ3-10 белый ГОСТ | F18: 565 | G18: =F18*Kurallar!$B$3 -> 565 | H18: =G18*I18 -> 4520 | I18: 8 | J18: м | K18: EKT
A19: 18 | C19: montajный материал | D19: 100300076_ | E19: Провод ПВ3-1,5 жёлто-зелёный ГОСТ | F19: 79 | G19: =F19*Kurallar!$B$3 -> 79 | H19: =G19*I19 -> 395 | I19: 5 | J19: м | K19: EKT
A20: 19 | C20: montajный материал | D20: MM-3% | E20: Монтажные материалы (крепёж, маркировка, наконечники, стяжки) — 3% от материалов | G20: =SUM(H3:H19)*Kurallar!$B$5 -> 7027.158 | H20: =G20*I20 -> 7027.158 | I20: 1 | J20: компл. | K20: -
A21: 20 | C21: montajная работа | D21: ISC-01 | E21: Сборка, монтаж, маркировка и испытание щита (норма времени, мин) | F21: =I21/60 -> 8.5833333 | G21: =Kurallar!$B$6 -> 100 | H21: =G21*I21 -> 51500 | I21: =Kurallar!$B$18 -> 515 | J21: мин | K21: -
B22: Toplam ЩР-1 | H22: =SUBTOTAL(9,H3:H21) -> 292765.76 | L22: =SUBTOTAL(9,H3:H19) -> 234238.6
B23: KONTROL EDİLECEK — onaya kadar Qty=0, toplama DAHİL DEĞİL
A24: 1 | C24: OTO | D24: 814013 | E24: Авт. выкл. NXB-63 1P 10A 6кА х-ка C — B10 stok 0 olduğu için alternatif (2 ад) | F24: 1362 | G24: =F24*Kurallar!$B$2 -> 817.2 | H24: =G24*I24 -> 0 | I24: 0 | J24: шт. | K24: CHINT
A25: 2 | C25: DİF | D25: 515381 | E25: Диф. авт. выкл. NXBLE-63YH 1P+N C16 30mA тип A, 6kA — tip A istenirse (3 ад) | F25: 5104 | G25: =F25*Kurallar!$B$2 -> 3062.4 | H25: =G25*I25 -> 0 | I25: 0 | J25: шт. | K25: CHINT
A26: 3 | C26: DİF | D26: 515388 | E26: Диф. авт. выкл. NXBLE-63YH 1P+N C20 30mA тип A, 6kA — tip A istenirse (5 ад) | F26: 5632 | G26: =F26*Kurallar!$B$2 -> 3379.2 | H26: =G26*I26 -> 0 | I26: 0 | J26: шт. | K26: CHINT
A27: 4 | C27: rubilnik | D27: - | E27: АВР NXZM-63 4P 40A — spesifikasyonda H/4P isteniyor, CHINT KZ stoğunda 4 kutup YOK (özel sipariş) | F27: 0 | G27: =F27*Kurallar!$B$2 -> 0 | H27: =G27*I27 -> 0 | I27: 0 | J27: шт. | K27: CHINT
A28: 5 | C28: opn | D28: - | E28: Ограничитель перенапряжения (ОПН/парафудр) 3P+N — şema ve spekte yok, teyit edilecek | F28: 0 | G28: =F28*Kurallar!$B$2 -> 0 | H28: =G28*I28 -> 0 | I28: 0 | J28: шт. | K28: CHINT

Sheet СВОД
A1: № | B1: Наименование щита | C1: Кол-во компл. | D1: Цена за 1 компл. | E1: Сумма | F1: Примечание
A2: 1 | B2: ЩР-1 Щит силовой распределительный навесной 380В IP31 (ввод АВР + учёт, 14 отходящих линий) | C2: 1 | D2: =BOM!H22 -> 292765.76 | E2: =C2*D2 -> 292765.76 | F2: АВР 3B 40A + sayaç dahil. KONTROL satırları hariç.
B3: ИТОГО | E3: =SUM(E2:E2) -> 292765.76
