Workbook
Name ALUM_KG_KZT: KURALLAR!$B$148
Name ALUM_KG_USD: KURALLAR!$B$145
Name BAKIR_KG_KZT: KURALLAR!$B$147
Name BAKIR_KG_USD: KURALLAR!$B$144
Name BARA_AL_A: KURALLAR!$I$152:$I$214
Name BARA_AL_KGM: KURALLAR!$H$152:$H$214
Name BARA_ART: KURALLAR!$A$152:$A$214
Name BARA_BOY_M: KURALLAR!$B$116
Name BARA_CU_A: KURALLAR!$F$152:$F$214
Name BARA_DERATING: KURALLAR!$B$111
Name BARA_FIRE: KURALLAR!$B$112
Name BARA_KGM: KURALLAR!$E$152:$E$214
Name BARA_KOPRU_M: KURALLAR!$B$115
Name BARA_N_ORANI: KURALLAR!$B$113
Name BARA_PE_ORANI: KURALLAR!$B$114
Name BARA_TABLO: KURALLAR!$A$152:$J$214
Name DINRAY_FIRE: KURALLAR!$B$120
Name DURUM_LIST: KURALLAR!$A$218:$A$227
Name FIYAT_ACK: FIYAT!$D$2:$D$32
Name FIYAT_ART: FIYAT!$R$2:$R$32
Name FIYAT_KOD: FIYAT!$C$2:$C$32
Name FIYAT_LISTE: FIYAT!$E$2:$E$32
Name FIYAT_MARKA: FIYAT!$J$2:$J$32
Name FIYAT_MODUL: FIYAT!$Q$2:$Q$32
Name FIYAT_NET: FIYAT!$F$2:$F$32
Name GARANTI: KURALLAR!$B$141
Name ISCILIK_CARPANI: KURALLAR!$B$33
Name ISCILIK_DK_UCRETI: KURALLAR!$B$31
Name ISCILIK_SAAT_UCRETI: KURALLAR!$B$30
Name ISKONTO: KURALLAR!$B$136
Name KABLO_FIRE: KURALLAR!$B$117
Name KABLO_M_MCCB: KURALLAR!$B$119
Name KABLO_M_MODULER: KURALLAR!$B$118
Name KANAL_FIRE: KURALLAR!$B$121
Name KAR_ORANI: KURALLAR!$B$135
Name KLEMENS_YEDEK: KURALLAR!$B$122
Name KORPUS_KULLANILABILIR_ORAN: KURALLAR!$B$126
Name KORPUS_YEDEK_ORANI: KURALLAR!$B$127
Name KUR_AD: KURALLAR!$A$5:$A$8
Name KUR_DEG: KURALLAR!$B$5:$B$8
Name MARKA_AD: KURALLAR!$A$12:$A$27
Name MARKA_KAT: KURALLAR!$E$12:$E$27
Name MARKA_PARA: KURALLAR!$B$12:$B$27
Name MARKA_TIP: KURALLAR!$F$12:$F$27
Name MODUL_GENISLIK_MM: KURALLAR!$B$124
Name MONTAJ_SARF_DK_KZT: KURALLAR!$B$32
Name NDS_ORANI: KURALLAR!$B$137
Name NORM_AD: KURALLAR!$A$37:$A$72
Name NORM_DK: KURALLAR!$B$37:$B$72
Name ODEME_SARTI: KURALLAR!$B$140
Name SC1_DERINLIK_MM: KURALLAR!$D$131
Name SC1_GENISLIK_MM: KURALLAR!$B$131
Name SC1_YUKSEKLIK_MM: KURALLAR!$C$131
Name SIRA_YUKSEKLIK_MM: KURALLAR!$B$125
Name TARAK_MOD_ADET: KURALLAR!$B$123
Name TEKLIF_GECERLILIK: KURALLAR!$B$138
Name URETIM_SURESI: KURALLAR!$B$139
Name USD_KZT: KURALLAR!$B$146
Name YAUO_DERINLIK_MM: KURALLAR!$D$132
Name YAUO_GENISLIK_MM: KURALLAR!$B$132

Sheet KURALLAR
A1: KURALLAR — YSF HICH / 260914 AKT RHM OKEZ
A3: BLOK 1 — KUR TABLOSU
A4: PARA | B4: KZT | C4: TARIH
A5: KZT | B5: 1
A6: USD | B6: 505 | C6: 2026-08-27 (kur.py)
A7: EUR | B7: 585 | C7: 2026-08-27 (kur.py)
A8: TRY | B8: 13.5 | C8: 2026-08-27 (kur.py)
A10: BLOK 2 — MARKA KURAL TABLOSU
A11: MARKA | B11: PARA | C11: KATSAYI1 | D11: KATSAYI2 | E11: TOPLAM | F11: GIRDI_TIPI | G11: NOT
A12: ABB | B12: EUR | C12: 0.405 | D12: 1 | E12: =C12*D12 -> 0.405 | F12: LISTE | G12: 1.35 x 0.30 standart
A13: ABB-ACIK | B13: EUR | C13: 0.3105 | D13: 1 | E13: =C13*D13 -> 0.3105 | F13: LISTE | G13: 1.35 x 0.23 ayar sahali/acik tip
A14: SCHNEIDER | B14: TRY | C14: 0.6 | D14: 1 | E14: =C14*D14 -> 0.6 | F14: LISTE
A15: CHINT | B15: KZT | C15: 0.6 | D15: 1 | E15: =C15*D15 -> 0.6 | F15: LISTE | G15: ana marka - bu proje
A16: CNC | B16: KZT | C16: 0.55 | D16: 1 | E16: =C16*D16 -> 0.55 | F16: LISTE | G16: liste 2025-02-04, 18 aydan eski - guvenilmez
A17: LEGRAND | B17: TRY | C17: 0.5 | D17: 1 | E17: =C17*D17 -> 0.5 | F17: LISTE | G17: iskonto teyitsiz
A18: IEK | B18: KZT | C18: 1 | D18: 1 | E18: =C18*D18 -> 1 | F18: LISTE | G18: EKT birlesik listesi icinde
A19: EKF | B19: KZT | C19: 0.67 | D19: 1 | E19: =C19*D19 -> 0.67 | F19: LISTE
A20: EKT | B20: KZT | C20: 1 | D20: 1 | E20: =C20*D20 -> 1 | F20: LISTE
A21: SAIMAN | B21: KZT | C21: 1 | D21: 1 | E21: =C21*D21 -> 1 | F21: LISTE
A22: KAZTEK | B22: KZT | C22: 0.6 | D22: 1 | E22: =C22*D22 -> 0.6 | F22: LISTE | G22: korpus
A23: HARMONY | B23: KZT | C23: 0.92 | D23: 1 | E23: =C23*D23 -> 0.92 | F23: LISTE
A24: BAKIR-BARA | B24: KZT | C24: 1 | D24: 1 | E24: =C24*D24 -> 1 | F24: NET | G24: kg fiyatindan hesaplanir
A25: ALUM-BARA | B25: KZT | C25: 1 | D25: 1 | E25: =C25*D25 -> 1 | F25: NET | G25: kg fiyatindan hesaplanir
A26: MUADIL-NET | B26: KZT | C26: 1 | D26: 1 | E26: =C26*D26 -> 1 | F26: NET
A27: ISCILIK | B27: KZT | C27: 1 | D27: 1 | E27: =C27*D27 -> 1 | F27: NET
A29: BLOK 3 — ISCILIK
A30: ISCILIK_SAAT_UCRETI (KZT/saat) | B30: 3500 | C30: ORNEK DEGER - kendi atolye oranınla degistir
A31: ISCILIK_DK_UCRETI (KZT/dk) | B31: =B30/60 -> 58.333333
A32: MONTAJ_SARF_DK_KZT | B32: 50 | C32: ORNEK DEGER - montaj sarf malzemesi/dk
A33: ISCILIK_CARPANI | B33: 1
A34: TEST_ETIKET_CARPANI | B34: 1.15
A36: NORM_ANAHTAR | B36: DK/BIRIM | C36: ACIKLAMA
A37: MCB_1P | B37: 10 | C37: modüler 1P koruma
A38: MCB_2P | B38: 14 | C38: modüler 2P
A39: MCB_3P | B39: 18 | C39: modüler 3P
A40: MCB_4P | B40: 22 | C40: modüler 4P
A41: DIF_1PN | B41: 20 | C41: AVDT 1P+N
A42: DIF_3PN | B42: 28 | C42: AVDT 3P+N
A43: UZO_2P | B43: 15 | C43: kaçak akım rölesi 2P
A44: UZO_4P | B44: 22 | C44: kaçak akım rölesi 4P
...

Sheet FIYAT
A1: SIRA | B1: TIP | C1: ARTIKUL | D1: ACIKLAMA | E1: LISTE_FIYAT | F1: NET_KZT | G1: TOPLAM_ADET | H1: TOPLAM_TUTAR | I1: PARA | J1: MARKA | K1: KATSAYI | L1: BIRIM | M1: KAYNAK | N1: DURUM | O1: NOT | P1: PANO(LAR) | Q1: MODUL | R1: KOD
A2: 1 | B2: korpus | C2: 719-15437 | D2: Мет.Корпус Щит (1600x600x400+10см база) | E2: 130600 | F2: =IF($E2="","",IF(INDEX(MARKA_TIP,MATCH($J2,MARKA_AD,0))="NET",$E2,$E2*INDEX(MARKA_KAT,MATCH($J2,MARKA_AD,0))*INDEX(KUR_DEG,MATCH($I2,KUR_AD,0)))) -> 78360 | G2: =SUMIF(BOM!$P:$P,$R2,BOM!$I:$I) -> 1 | H2: =IF($F2="","",$F2*$G2) -> 78360 | I2: KZT | J2: KAZTEK | K2: =INDEX(MARKA_KAT,MATCH($J2,MARKA_AD,0)) -> 0.6 | L2: шт | M2: KAZTEK2607 | N2: VARSAYIM | O2: Korpus olcusu semada verilmedi, modul hesabina gore secildi - KONTROL (govde tipi ЩРВ/ЩРН teyidi de gerekli) | P2: ЩС-1 | Q2: 0 | R2: KAZTEK-SC1-KORPUS
A3: 2 | B3: mccb | C3: 131369 | D3: Авт. выкл. NXM-250S/3Р 250A 36кА (R) | E3: 36869 | F3: =IF($E3="","",IF(INDEX(MARKA_TIP,MATCH($J3,MARKA_AD,0))="NET",$E3,$E3*INDEX(MARKA_KAT,MATCH($J3,MARKA_AD,0))*INDEX(KUR_DEG,MATCH($I3,KUR_AD,0)))) -> 22121.4 | G3: =SUMIF(BOM!$P:$P,$R3,BOM!$I:$I) -> 1 | H3: =IF($F3="","",$F3*$G3) -> 22121.4 | I3: KZT | J3: CHINT | K3: =INDEX(MARKA_KAT,MATCH($J3,MARKA_AD,0)) -> 0.6 | L3: шт | M3: CHINT2608 | N3: CIHAZ_BELIRSIZ | O3: Semada QS1 rubilnik sembolu; proje spesifikasyon tablosunda '250A otomatik sigorta' yaziyor - celiski, muhendis teyidi gerekli | P3: ЩС-1 | Q3: 0 | R3: CHINT-NH40-250-3P
A4: 3 | B4: mccb | C4: 131360 | D4: Авт. выкл. NXM-125S/3Р 63A 25кА (R) | E4: 18263 | F4: =IF($E4="","",IF(INDEX(MARKA_TIP,MATCH($J4,MARKA_AD,0))="NET",$E4,$E4*INDEX(MARKA_KAT,MATCH($J4,MARKA_AD,0))*INDEX(KUR_DEG,MATCH($I4,KUR_AD,0)))) -> 10957.8 | G4: =SUMIF(BOM!$P:$P,$R4,BOM!$I:$I) -> 4 | H4: =IF($F4="","",$F4*$G4) -> 43831.2 | I4: KZT | J4: CHINT | K4: =INDEX(MARKA_KAT,MATCH($J4,MARKA_AD,0)) -> 0.6 | L4: шт | M4: CHINT2608 | N4: OK | P4: ЩС-1 | Q4: 3 | R4: CHINT-NXB63-3P-63A
A5: 4 | B5: mccb | C5: 844301 | D5: Авт. выкл. NXM-125S/3Р 40A 25кА (R) | E5: 20174 | F5: =IF($E5="","",IF(INDEX(MARKA_TIP,MATCH($J5,MARKA_AD,0))="NET",$E5,$E5*INDEX(MARKA_KAT,MATCH($J5,MARKA_AD,0))*INDEX(KUR_DEG,MATCH($I5,KUR_AD,0)))) -> 12104.4 | G5: =SUMIF(BOM!$P:$P,$R5,BOM!$I:$I) -> 1 | H5: =IF($F5="","",$F5*$G5) -> 12104.4 | I5: KZT | J5: CHINT | K5: =INDEX(MARKA_KAT,MATCH($J5,MARKA_AD,0)) -> 0.6 | L5: шт | M5: CHINT2608 | N5: OK | P5: ЩС-1 | Q5: 3 | R5: CHINT-NXB63-3P-40A
A6: 5 | B6: mccb | C6: 844300 | D6: Авт. выкл. NXM-125S/3Р 32A 25кА (R) | E6: 19700 | F6: =IF($E6="","",IF(INDEX(MARKA_TIP,MATCH($J6,MARKA_AD,0))="NET",$E6,$E6*INDEX(MARKA_KAT,MATCH($J6,MARKA_AD,0))*INDEX(KUR_DEG,MATCH($I6,KUR_AD,0)))) -> 11820 | G6: =SUMIF(BOM!$P:$P,$R6,BOM!$I:$I) -> 3 | H6: =IF($F6="","",$F6*$G6) -> 35460 | I6: KZT | J6: CHINT | K6: =INDEX(MARKA_KAT,MATCH($J6,MARKA_AD,0)) -> 0.6 | L6: шт | M6: CHINT2608 | N6: OK | P6: ЩС-1 | Q6: 3 | R6: CHINT-NXB63-3P-32A
A7: 6 | B7: mcb | C7: 814168 | D7: Авт. выкл. NXB-63 3P 6A 6кА х-ка C | E7: 5441 | F7: =IF($E7="","",IF(INDEX(MARKA_TIP,MATCH($J7,MARKA_AD,0))="NET",$E7,$E7*INDEX(MARKA_KAT,MATCH($J7,MARKA_AD,0))*INDEX(KUR_DEG,MATCH($I7,KUR_AD,0)))) -> 3264.6 | G7: =SUMIF(BOM!$P:$P,$R7,BOM!$I:$I) -> 1 | H7: =IF($F7="","",$F7*$G7) -> 3264.6 | I7: KZT | J7: CHINT | K7: =INDEX(MARKA_KAT,MATCH($J7,MARKA_AD,0)) -> 0.6 | L7: шт | M7: CHINT2608 | N7: OK | P7: ЯУО | Q7: 3 | R7: CHINT-NXB63-3P-6A
A8: 7 | B8: mcb | C8: 814008 | D8: Авт. выкл. NXB-63 1P 1A 6кА х-ка C | E8: 1845 | F8: =IF($E8="","",IF(INDEX(MARKA_TIP,MATCH($J8,MARKA_AD,0))="NET",$E8,$E8*INDEX(MARKA_KAT,MATCH($J8,MARKA_AD,0))*INDEX(KUR_DEG,MATCH($I8,KUR_AD,0)))) -> 1107 | G8: =SUMIF(BOM!$P:$P,$R8,BOM!$I:$I) -> 1 | H8: =IF($F8="","",$F8*$G8) -> 1107 | I8: KZT | J8: CHINT | K8: =INDEX(MARKA_KAT,MATCH($J8,MARKA_AD,0)) -> 0.6 | L8: шт | M8: CHINT2608 | N8: CIHAZ_BELIRSIZ | O8: 1A cok dusuk kademe - QF2 kumanda/zaman rolesi devresi korumasi varsayildi, teyit gerekli | P8: ЯУО | Q8: 1 | R8: CHINT-NXB63-1P-1A
A9: 8 | B9: mcb | C9: 814169 | D9: Авт. выкл. NXB-63 3P 10A 6кА х-ка C | E9: 5878 | F9: =IF($E9="","",IF(INDEX(MARKA_TIP,MATCH($J9,MARKA_AD,0))="NET",$E9,$E9*INDEX(MARKA_KAT,MATCH($J9,MARKA_AD,0))*INDEX(KUR_DEG,MATCH($I9,KUR_AD,0)))) -> 3526.8 | G9: =SUMIF(BOM!$P:$P,$R9,BOM!$I:$I) -> 1 | H9: =IF($F9="","",$F9*$G9) -> 3526.8 | I9: KZT | J9: CHINT | K9: =INDEX(MARKA_KAT,MATCH($J9,MARKA_AD,0)) -> 0.6 | L9: шт | M9: CHINT2608 | N9: VARSAYIM | O9: Mevcut kuyu panosuna QF5 olarak monte edilecek (yeni pano degil); kutup sayisi (3P) semada yazmiyor, ЯУО girisi 3P oldugu icin 3P varsayildi | P9: QF5 | Q9: 3 | R9: CHINT-NXB63-3P-10A
A10: 9 | B10: kontaktor | C10: 836704 | D10: Контактор NXC-09 9A 220В/АС3 1НО+1НЗ (KM1) | E10: 5214 | F10: =IF($E10="","",IF(INDEX(MARKA_TIP,MATCH($J10,MARKA_AD,0))="NET",$E10,$E10*INDEX(MARKA_KAT,MATCH($J10,MARKA_AD,0))*INDEX(KUR_DEG,MATCH($I10,KUR_AD,0)))) -> 3128.4 | G10: =SUMIF(BOM!$P:$P,$R10,BOM!$I:$I) -> 1 | H10: =IF($F10="","",$F10*$G10) -> 3128.4 | I10: KZT | J10: CHINT | K10: =INDEX(MARKA_KAT,MATCH($J10,MARKA_AD,0)) -> 0.6 | L10: шт | M10: CHINT2608 | N10: CIHAZ_BELIRSIZ | O10: Aydinlatma yuku akimi semada verilmemis, en kucuk govde NXC-09 (9A) varsayildi | P10: ЯУО | Q10: 3 | R10: CHINT-NXC09-220V
A11: 10 | B11: termik | C11: 837101 | D11: Тепловое реле NXR-12 4-6A (KK1) | E11: 4445 | F11: =IF($E11="","",IF(INDEX(MARKA_TIP,MATCH($J11,MARKA_AD,0))="NET",$E11,$E11*INDEX(MARKA_KAT,MATCH($J11,MARKA_AD,0))*INDEX(KUR_DEG,MATCH($I11,KUR_AD,0)))) -> 2667 | G11: =SUMIF(BOM!$P:$P,$R11,BOM!$I:$I) -> 1 | H11: =IF($F11="","",$F11*$G11) -> 2667 | I11: KZT | J11: CHINT | K11: =INDEX(MARKA_KAT,MATCH($J11,MARKA_AD,0)) -> 0.6 | L11: шт | M11: CHINT2608 | N11: CIHAZ_BELIRSIZ | O11: Yuk akimi belirsiz, orta aralik (4-6A) varsayildi - gercek yuk akimina gore degistirilmeli | P11: ЯУО | Q11: 0 | R11: CHINT-NXR12-4-6A
A12: 11 | B12: buton | C12: 574843 | D12: Кнопка управления NP2-BA42 без подсветки красная 1НЗ (SB1 Стоп) | E12: 1621 | F12: =IF($E12="","",IF(INDEX(MARKA_TIP,MATCH($J12,MARKA_AD,0))="NET",$E12,$E12*INDEX(MARKA_KAT,MATCH($J12,MARKA_AD,0))*INDEX(KUR_DEG,MATCH($I12,KUR_AD,0)))) -> 972.6 | G12: =SUMIF(BOM!$P:$P,$R12,BOM!$I:$I) -> 1 | H12: =IF($F12="","",$F12*$G12) -> 972.6 | I12: KZT | J12: CHINT | K12: =INDEX(MARKA_KAT,MATCH($J12,MARKA_AD,0)) -> 0.6 | L12: шт | M12: CHINT2608 | N12: OK | P12: ЯУО | Q12: 0 | R12: CHINT-NP2-BA42-KIRMIZI
A13: 12 | B13: buton | C13: 573763 | D13: Кнопка управления NP2-BA35 зеленая 1НЗ+1НО (SB2 Пуск) | E13: 1784 | F13: =IF($E13="","",IF(INDEX(MARKA_TIP,MATCH($J13,MARKA_AD,0))="NET",$E13,$E13*INDEX(MARKA_KAT,MATCH($J13,MARKA_AD,0))*INDEX(KUR_DEG,MATCH($I13,KUR_AD,0)))) -> 1070.4 | G13: =SUMIF(BOM!$P:$P,$R13,BOM!$I:$I) -> 1 | H13: =IF($F13="","",$F13*$G13) -> 1070.4 | I13: KZT | J13: CHINT | K13: =INDEX(MARKA_KAT,MATCH($J13,MARKA_AD,0)) -> 0.6 | L13: шт | M13: CHINT2608 | N13: OK | P13: ЯУО | Q13: 0 | R13: CHINT-NP2-BA35-YESIL
A14: 13 | B14: lamb | C14: 593075 | D14: Индикатор ND16-22D/2 красный AC/DC230В (HLR1) | E14: 571 | F14: =IF($E14="","",IF(INDEX(MARKA_TIP,MATCH($J14,MARKA_AD,0))="NET",$E14,$E14*INDEX(MARKA_KAT,MATCH($J14,MARKA_AD,0))*INDEX(KUR_DEG,MATCH($I14,KUR_AD,0)))) -> 342.6 | G14: =SUMIF(BOM!$P:$P,$R14,BOM!$I:$I) -> 1 | H14: =IF($F14="","",$F14*$G14) -> 342.6 | I14: KZT | J14: CHINT | K14: =INDEX(MARKA_KAT,MATCH($J14,MARKA_AD,0)) -> 0.6 | L14: шт | M14: CHINT2608 | N14: OK | P14: ЯУО | Q14: 0 | R14: CHINT-ND16-22D-KIRMIZI
A15: 14 | B15: buton | C15: 574849 | D15: Переключатель NP2-BD33 3 положения с фиксацией 2НО (SA1/SA2) | E15: 1836 | F15: =IF($E15="","",IF(INDEX(MARKA_TIP,MATCH($J15,MARKA_AD,0))="NET",$E15,$E15*INDEX(MARKA_KAT,MATCH($J15,MARKA_AD,0))*INDEX(KUR_DEG,MATCH($I15,KUR_AD,0)))) -> 1101.6 | G15: =SUMIF(BOM!$P:$P,$R15,BOM!$I:$I) -> 2 | H15: =IF($F15="","",$F15*$G15) -> 2203.2 | I15: KZT | J15: CHINT | K15: =INDEX(MARKA_KAT,MATCH($J15,MARKA_AD,0)) -> 0.6 | L15: шт | M15: CHINT2608 | N15: VARSAYIM | O15: Kontak sayisi (2NO) semadaki tam kumanda mantigina gore teyit edilmeli | P15: ЯУО | Q15: 0 | R15: CHINT-NP2-BD33-3POZ
A16: 15 | B16: role | C16: 310024 | D16: Таймер электронный NKG3 AC230В (KT1) | E16: 18847 | F16: =IF($E16="","",IF(INDEX(MARKA_TIP,MATCH($J16,MARKA_AD,0))="NET",$E16,$E16*INDEX(MARKA_KAT,MATCH($J16,MARKA_AD,0))*INDEX(KUR_DEG,MATCH($I16,KUR_AD,0)))) -> 11308.2 | G16: =SUMIF(BOM!$P:$P,$R16,BOM!$I:$I) -> 1 | H16: =IF($F16="","",$F16*$G16) -> 11308.2 | I16: KZT | J16: CHINT | K16: =INDEX(MARKA_KAT,MATCH($J16,MARKA_AD,0)) -> 0.6 | L16: шт | M16: CHINT2608 | N16: OK | P16: ЯУО | Q16: 4 | R16: CHINT-NKG3-TIMER
A17: 16 | B17: role | C17: 130300434 | D17: Фотореле ФР-7Е с выносн. фотоэлементом 220В 8А 2НО (FR1+BL1 birlikte) | E17: 14264 | F17: =IF($E17="","",IF(INDEX(MARKA_TIP,MATCH($J17,MARKA_AD,0))="NET",$E17,$E17*INDEX(MARKA_KAT,MATCH($J17,MARKA_AD,0))*INDEX(KUR_DEG,MATCH($I17,KUR_AD,0)))) -> 14264 | G17: =SUMIF(BOM!$P:$P,$R17,BOM!$I:$I) -> 1 | H17: =IF($F17="","",$F17*$G17) -> 14264 | I17: KZT | J17: EKT | K17: =INDEX(MARKA_KAT,MATCH($J17,MARKA_AD,0)) -> 1 | L17: шт | M17: EKT-birlesik | N17: MUADIL | O17: FR1 (fotorole) + BL1 (fotodatcik) tek urunde birlesik - CHINT'te esdegeri yok, cift sayim onlemek icin tek satir | P17: ЯУО | Q17: 2 | R17: EKT-FR7E-FOTORELE
A18: 17 | B18: klemens | C18: 030300417 | D18: Клемма проходная (0,08-2,5мм 32А) | E18: 113 | F18: =IF($E18="","",IF(INDEX(MARKA_TIP,MATCH($J18,MARKA_AD,0))="NET",$E18,$E18*INDEX(MARKA_KAT,MATCH($J18,MARKA_AD,0))*INDEX(KUR_DEG,MATCH($I18,KUR_AD,0)))) -> 113 | G18: =SUMIF(BOM!$P:$P,$R18,BOM!$I:$I) -> 14 | H18: =IF($F18="","",$F18*$G18) -> 1582 | I18: KZT | J18: EKT | K18: =INDEX(MARKA_KAT,MATCH($J18,MARKA_AD,0)) -> 1 | L18: шт | M18: EKT-birlesik | N18: OK | P18: ЩС-1, ЯУО | Q18: 0 | R18: EKT-KLEMENS-2.5MM
A19: 18 | B19: kanal | C19: 280100020_ | D19: Кабель.канал перф. 40х40 ИМПАКТ IEK (36) | E19: 1634 | F19: =IF($E19="","",IF(INDEX(MARKA_TIP,MATCH($J19,MARKA_AD,0))="NET",$E19,$E19*INDEX(MARKA_KAT,MATCH($J19,MARKA_AD,0))*INDEX(KUR_DEG,MATCH($I19,KUR_AD,0)))) -> 1634 | G19: =SUMIF(BOM!$P:$P,$R19,BOM!$I:$I) -> 0 | H19: =IF($F19="","",$F19*$G19) -> 0 | I19: KZT | J19: EKT | K19: =INDEX(MARKA_KAT,MATCH($J19,MARKA_AD,0)) -> 1 | L19: м | M19: EKT-birlesik | N19: MUADIL_ONAY | O19: Kalici kural: kablo kanali her zaman perforeli metal lotok - plastik kapakli kanalin muadili degil, MUHENDIS ONAYI GEREKLI | P19: ЩС-1 | Q19: 0 | R19: EKT-LOTOK-PERF-50X50
A20: 20 | B20: izolator | C20: YIS42-3-200 | D20: Изолятор шинный плоский ИШП 3P (5 и 15-10-30мм) | E20: 3011 | F20: =IF($E20="","",IF(INDEX(MARKA_TIP,MATCH($J20,MARKA_AD,0))="NET",$E20,$E20*INDEX(MARKA_KAT,MATCH($J20,MARKA_AD,0))*INDEX(KUR_DEG,MATCH($I20,KUR_AD,0)))) -> 3011 | G20: =SUMIF(BOM!$P:$P,$R20,BOM!$I:$I) -> 2 | H20: =IF($F20="","",$F20*$G20) -> 6022 | I20: KZT | J20: EKT | K20: =INDEX(MARKA_KAT,MATCH($J20,MARKA_AD,0)) -> 1 | L20: шт | M20: EKT-birlesik | N20: OK | P20: ЩС-1 | Q20: 0 | R20: EKT-IZOLATOR-YIS42
A21: 21 | B21: bara | C21: 130200362 | D21: Шина "N" нулевая 8х12мм комб. с изол. ШНИ 12-КС-С | E21: 903 | F21: =IF($E21="","",IF(INDEX(MARKA_TIP,MATCH($J21,MARKA_AD,0))="NET",$E21,$E21*INDEX(MARKA_KAT,MATCH($J21,MARKA_AD,0))*INDEX(KUR_DEG,MATCH($I21,KUR_AD,0)))) -> 903 | G21: =SUMIF(BOM!$P:$P,$R21,BOM!$I:$I) -> 2 | H21: =IF($F21="","",$F21*$G21) -> 1806 | I21: KZT | J21: EKT | K21: =INDEX(MARKA_KAT,MATCH($J21,MARKA_AD,0)) -> 1 | L21: шт | M21: EKT-birlesik | N21: MUADIL | O21: Ozel GZS/PE barasi bulunamadi, izoleli notr-toprak barasi tipi PE icin de kullanildi | P21: ЩС-1 | Q21: 0 | R21: EKT-SINASI-N-PE
A22: 22 | B22: aksesuar | C22: 3158640 | D22: Комплект Болт+Шайба+Гайка M8x30мм | E22: 557 | F22: =IF($E22="","",IF(INDEX(MARKA_TIP,MATCH($J22,MARKA_AD,0))="NET",$E22,$E22*INDEX(MARKA_KAT,MATCH($J22,MARKA_AD,0))*INDEX(KUR_DEG,MATCH($I22,KUR_AD,0)))) -> 557 | G22: =SUMIF(BOM!$P:$P,$R22,BOM!$I:$I) -> 72 | H22: =IF($F22="","",$F22*$G22) -> 40104 | I22: KZT | J22: EKT | K22: =INDEX(MARKA_KAT,MATCH($J22,MARKA_AD,0)) -> 1 | L22: шт | M22: EKT-birlesik | N22: OK | P22: ЩС-1 | Q22: 0 | R22: EKT-BOLT-M8-SET
A23: 23 | B23: pabuc | C23: 260100132 | D23: Наконечник медный луженый ТМЛ 35-10-9 | E23: 387 | F23: =IF($E23="","",IF(INDEX(MARKA_TIP,MATCH($J23,MARKA_AD,0))="NET",$E23,$E23*INDEX(MARKA_KAT,MATCH($J23,MARKA_AD,0))*INDEX(KUR_DEG,MATCH($I23,KUR_AD,0)))) -> 387 | G23: =SUMIF(BOM!$P:$P,$R23,BOM!$I:$I) -> 32 | H23: =IF($F23="","",$F23*$G23) -> 12384 | I23: KZT | J23: EKT | K23: =INDEX(MARKA_KAT,MATCH($J23,MARKA_AD,0)) -> 1 | L23: шт | M23: EKT-birlesik | N23: VARSAYIM | O23: 8 cikis kablosu (25-70mm2 araligi) icin temsili kesit, gercek kablo kesitine gore revize edilmeli | P23: ЩС-1 | Q23: 0 | R23: EKT-TMLUG-35
A24: 24 | B24: pabuc | C24: 260100141 | D24: Наконечник медный луженый ТМЛ 150-16-19 | E24: 2299 | F24: =IF($E24="","",IF(INDEX(MARKA_TIP,MATCH($J24,MARKA_AD,0))="NET",$E24,$E24*INDEX(MARKA_KAT,MATCH($J24,MARKA_AD,0))*INDEX(KUR_DEG,MATCH($I24,KUR_AD,0)))) -> 2299 | G24: =SUMIF(BOM!$P:$P,$R24,BOM!$I:$I) -> 4 | H24: =IF($F24="","",$F24*$G24) -> 9196 | I24: KZT | J24: EKT | K24: =INDEX(MARKA_KAT,MATCH($J24,MARKA_AD,0)) -> 1 | L24: шт | M24: EKT-birlesik | N24: VARSAYIM | O24: Giris kablosu (H-VRU, AVBbShV-4x120mm2) icin temsili kesit | P24: ЩС-1 | Q24: 0 | R24: EKT-TMLUG-150
A25: 25 | B25: pabuc | C25: 311100817 | D25: Наконечник НШВИ 1,5-8 изолированный (100шт/пак.) | E25: 428 | F25: =IF($E25="","",IF(INDEX(MARKA_TIP,MATCH($J25,MARKA_AD,0))="NET",$E25,$E25*INDEX(MARKA_KAT,MATCH($J25,MARKA_AD,0))*INDEX(KUR_DEG,MATCH($I25,KUR_AD,0)))) -> 428 | G25: =SUMIF(BOM!$P:$P,$R25,BOM!$I:$I) -> 0.2 | H25: =IF($F25="","",$F25*$G25) -> 85.6 | I25: KZT | J25: EKT | K25: =INDEX(MARKA_KAT,MATCH($J25,MARKA_AD,0)) -> 1 | L25: пак(100шт) | M25: EKT-birlesik | N25: VARSAYIM | O25: Fiyat 100'luk paket icin - BOM adedi paket kesri olarak yazildi | P25: ЯУО | Q25: 0 | R25: EKT-NSHVI-1.5-PAKET
A26: 26 | B26: korpus | C26: 713-09053 | D26: Щит мет.ЩРв-36 (550х320х120) | E26: 11400 | F26: =IF($E26="","",IF(INDEX(MARKA_TIP,MATCH($J26,MARKA_AD,0))="NET",$E26,$E26*INDEX(MARKA_KAT,MATCH($J26,MARKA_AD,0))*INDEX(KUR_DEG,MATCH($I26,KUR_AD,0)))) -> 6840 | G26: =SUMIF(BOM!$P:$P,$R26,BOM!$I:$I) -> 1 | H26: =IF($F26="","",$F26*$G26) -> 6840 | I26: KZT | J26: KAZTEK | K26: =INDEX(MARKA_KAT,MATCH($J26,MARKA_AD,0)) -> 0.6 | L26: шт | M26: KAZTEK2607 | N26: VARSAYIM | O26: Korpus olcusu semada verilmedi, dogru panel + kapak uzeri cihazlarina gore secildi - KONTROL | P26: ЯУО | Q26: 0 | R26: KAZTEK-YAUO-KORPUS
A27: 27 | B27: bara | C27: (hesap - katalog degil) | D27: Шина медная 3х25мм (Cu, m basi) | F27: =INDEX(BARA_KGM,MATCH("3X25",BARA_ART,0))*BAKIR_KG_KZT -> 4816.185 | G27: =SUMIF(BOM!$P:$P,$R27,BOM!$I:$I) -> 3.105 | H27: =IF($F27="","",$F27*$G27) -> 14954.254 | I27: KZT | J27: BAKIR-BARA | K27: =INDEX(MARKA_KAT,MATCH($J27,MARKA_AD,0)) -> 1 | L27: м | M27: metal fiyati (BLOK 8) | N27: OK | O27: Fiyat BARA_TABLO kg/m x BAKIR_KG_KZT formulunden gelir, fiyat listesinde aranmaz | P27: ЩС-1 | Q27: 0 | R27: BARA-CU-3X25
A28: 28 | B28: din | D28: DIN rayi TH35 (35x7,5mm delikli celik) | F28: =IF($E28="","",IF(INDEX(MARKA_TIP,MATCH($J28,MARKA_AD,0))="NET",$E28,$E28*INDEX(MARKA_KAT,MATCH($J28,MARKA_AD,0))*INDEX(KUR_DEG,MATCH($I28,KUR_AD,0)))) | G28: =SUMIF(BOM!$P:$P,$R28,BOM!$I:$I) -> 0 | H28: =IF($F28="","",$F28*$G28) | I28: KZT | J28: EKT | K28: =INDEX(MARKA_KAT,MATCH($J28,MARKA_AD,0)) -> 1 | L28: м | M28: - | N28: FIYAT_YOK | O28: birlesik.csv'de metrajli DIN TH35 rayi bulunamadi, fiyat listesine eklenmeli | P28: ЩС-1, ЯУО | Q28: 0 | R28: EKT-DIN-TH35
A29: 29 | B29: kablo | D29: ПуГВ 1х1,5 kumanda kablosu | E29: 90 | F29: =IF($E29="","",IF(INDEX(MARKA_TIP,MATCH($J29,MARKA_AD,0))="NET",$E29,$E29*INDEX(MARKA_KAT,MATCH($J29,MARKA_AD,0))*INDEX(KUR_DEG,MATCH($I29,KUR_AD,0)))) -> 90 | G29: =SUMIF(BOM!$P:$P,$R29,BOM!$I:$I) -> 15 | H29: =IF($F29="","",$F29*$G29) -> 1350 | I29: KZT | J29: EKT | K29: =INDEX(MARKA_KAT,MATCH($J29,MARKA_AD,0)) -> 1 | L29: м | M29: - | N29: FIYAT_YOK | O29: birlesik.csv'de kucuk kesitli (1,5mm2) ПуГВ bulunamadi (sadece 25-95mm2 mevcut), fiyat listesine eklenmeli | P29: ЯУО | Q29: 0 | R29: EKT-KBL-PUGV-1.5
A30: 30 | B30: монтажный материал | D30: Montaj sarf malzemesi (vida, dubel, spiral, kablo bagi) | F30: =IF($E30="","",IF(INDEX(MARKA_TIP,MATCH($J30,MARKA_AD,0))="NET",$E30,$E30*INDEX(MARKA_KAT,MATCH($J30,MARKA_AD,0))*INDEX(KUR_DEG,MATCH($I30,KUR_AD,0)))) | G30: =SUMIF(BOM!$P:$P,$R30,BOM!$I:$I) -> 2 | H30: =IF($F30="","",$F30*$G30) | I30: KZT | J30: EKT | K30: =INDEX(MARKA_KAT,MATCH($J30,MARKA_AD,0)) -> 1 | L30: компл | M30: - | N30: FIYAT_YOK | O30: Sabit paket fiyati fiyat listesinde yok, atolye sarf ortalamasi girilmeli | P30: QF5, ЩС-1, ЯУО | Q30: 0 | R30: MONTAJ-MALZEME
A31: 31 | B31: монтажная работа | D31: Iscilik (montaj+kablaj+test) | F31: =ISCILIK_DK_UCRETI -> 58.333333 | G31: =SUMIF(BOM!$P:$P,$R31,BOM!$I:$I) -> 918.2 | H31: =IF($F31="","",$F31*$G31) -> 53561.667 | I31: KZT | J31: ISCILIK | K31: =INDEX(MARKA_KAT,MATCH($J31,MARKA_AD,0)) -> 1 | L31: dk | M31: KURALLAR BLOK3 | N31: OK | P31: QF5, ЩС-1, ЯУО | Q31: 0 | R31: ISCILIK-MONTAJ
A32: 32 | B32: монтажный материал | D32: Montaj sarf malzemesi (dakika bazli) | F32: =MONTAJ_SARF_DK_KZT -> 50 | G32: =SUMIF(BOM!$P:$P,$R32,BOM!$I:$I) -> 918.2 | H32: =IF($F32="","",$F32*$G32) -> 45910 | I32: KZT | J32: ISCILIK | K32: =INDEX(MARKA_KAT,MATCH($J32,MARKA_AD,0)) -> 1 | L32: dk | M32: KURALLAR BLOK3 | N32: OK | P32: QF5, ЩС-1, ЯУО | Q32: 0 | R32: MONTAJ-SARF-DK

Sheet BOM
A1: ROW | B1: Наименование1 | C1: Тип | D1: Артикул | E1: Номенклатура | F1: Цена | G1: net | H1: H | I1: Qty | J1: Ед.изм | K1: Завод | L1: tutar | M1: DURUM | N1: NOT | O1: KAYNAK | P1: ANAHTAR | Q1: NORM_ANAHTAR | R1: ISCILIK_DK | S1: MODUL
B2: ЩС-1 (ВРУ) — Однолинейная схема ВРУ / Елемес СЗ, 1 компл | E2: ЩС-1 (ВРУ) — Однолинейная схема ВРУ / Елемес СЗ, 1 компл | I2: 1 | J2: компл
A3: 2 | B3: =E3 -> Мет.Корпус Щит (1600x600x400+10см база) | C3: korpus | D3: =IF($P3="","",INDEX(FIYAT_KOD,MATCH($P3,FIYAT_ART,0))) -> 719-15437 | E3: =IF($P3="","",INDEX(FIYAT_ACK,MATCH($P3,FIYAT_ART,0))) -> Мет.Корпус Щит (1600x600x400+10см база) | F3: =IF($P3="","",INDEX(FIYAT_LISTE,MATCH($P3,FIYAT_ART,0))) -> 130600 | G3: =IF($P3="","",INDEX(FIYAT_NET,MATCH($P3,FIYAT_ART,0))) -> 78360 | H3: =IF(OR($G3="",$I3=""),"",$G3*$I3) -> 78360 | I3: 1 | J3: шт | K3: KAZTEK | L3: =IF($H3="","",$H3) -> 78360 | M3: VARSAYIM | N3: Korpus olcusu semada verilmedi, modul hesabina gore secildi - KONTROL (govde tipi ЩРВ/ЩРН teyidi de gerekli) | O3: KAZTEK2607 | P3: KAZTEK-SC1-KORPUS | Q3: KORPUS_ORTA | R3: =IF($I3="","",$I3*INDEX(NORM_DK,MATCH($Q3,NORM_AD,0))) -> 45 | S3: =IF($I3="","",$I3*INDEX(FIYAT_MODUL,MATCH($P3,FIYAT_ART,0))) -> 0
A4: 3 | B4: =E4 -> Авт. выкл. NXM-250S/3Р 250A 36кА (R) | C4: mccb | D4: 131369 | E4: Авт. выкл. NXM-250S/3Р 250A 36кА (R) | F4: 36869 | G4: =IF($P4="","",INDEX(FIYAT_NET,MATCH($P4,FIYAT_ART,0))) -> 22121.4 | H4: =IF(OR($G4="",$I4=""),"",$G4*$I4) -> 22121.4 | I4: 1 | J4: шт | K4: CHINT | L4: =IF($H4="","",$H4) -> 22121.4 | M4: CIHAZ_BELIRSIZ | N4: Semada QS1 rubilnik sembolu; proje spesifikasyon tablosunda '250A otomatik sigorta' yaziyor - celiski, muhendis teyidi gerekli | O4: CHINT2608 | P4: CHINT-NH40-250-3P | Q4: RUBILNIK | R4: =IF($I4="","",$I4*INDEX(NORM_DK,MATCH($Q4,NORM_AD,0))) -> 40 | S4: =IF($I4="","",$I4*INDEX(FIYAT_MODUL,MATCH($P4,FIYAT_ART,0))) -> 0
A5: 4 | B5: =E5 -> QF1,QF2,QF3,QF6 — Авт.выкл. NXB-63 3P 63A C | C5: oto | D5: =IF($P5="","",INDEX(FIYAT_KOD,MATCH($P5,FIYAT_ART,0))) -> 131360 | E5: QF1,QF2,QF3,QF6 — Авт.выкл. NXB-63 3P 63A C | F5: =IF($P5="","",INDEX(FIYAT_LISTE,MATCH($P5,FIYAT_ART,0))) -> 18263 | G5: =IF($P5="","",INDEX(FIYAT_NET,MATCH($P5,FIYAT_ART,0))) -> 10957.8 | H5: =IF(OR($G5="",$I5=""),"",$G5*$I5) -> 43831.2 | I5: 4 | J5: шт | K5: CHINT | L5: =IF($H5="","",$H5) -> 43831.2 | M5: OK | O5: CHINT2608 | P5: CHINT-NXB63-3P-63A | Q5: MCB_3P | R5: =IF($I5="","",$I5*INDEX(NORM_DK,MATCH($Q5,NORM_AD,0))) -> 72 | S5: =IF($I5="","",$I5*INDEX(FIYAT_MODUL,MATCH($P5,FIYAT_ART,0))) -> 12
A6: 5 | B6: =E6 -> QF5 — Авт.выкл. NXB-63 3P 40A C | C6: oto | D6: =IF($P6="","",INDEX(FIYAT_KOD,MATCH($P6,FIYAT_ART,0))) -> 844301 | E6: QF5 — Авт.выкл. NXB-63 3P 40A C | F6: =IF($P6="","",INDEX(FIYAT_LISTE,MATCH($P6,FIYAT_ART,0))) -> 20174 | G6: =IF($P6="","",INDEX(FIYAT_NET,MATCH($P6,FIYAT_ART,0))) -> 12104.4 | H6: =IF(OR($G6="",$I6=""),"",$G6*$I6) -> 12104.4 | I6: 1 | J6: шт | K6: CHINT | L6: =IF($H6="","",$H6) -> 12104.4 | M6: OK | O6: CHINT2608 | P6: CHINT-NXB63-3P-40A | Q6: MCB_3P | R6: =IF($I6="","",$I6*INDEX(NORM_DK,MATCH($Q6,NORM_AD,0))) -> 18 | S6: =IF($I6="","",$I6*INDEX(FIYAT_MODUL,MATCH($P6,FIYAT_ART,0))) -> 3
A7: 6 | B7: =E7 -> QF4,QF7,QF8 — Авт.выкл. NXB-63 3P 32A C | C7: oto | D7: =IF($P7="","",INDEX(FIYAT_KOD,MATCH($P7,FIYAT_ART,0))) -> 844300 | E7: QF4,QF7,QF8 — Авт.выкл. NXB-63 3P 32A C | F7: =IF($P7="","",INDEX(FIYAT_LISTE,MATCH($P7,FIYAT_ART,0))) -> 19700 | G7: =IF($P7="","",INDEX(FIYAT_NET,MATCH($P7,FIYAT_ART,0))) -> 11820 | H7: =IF(OR($G7="",$I7=""),"",$G7*$I7) -> 35460 | I7: 3 | J7: шт | K7: CHINT | L7: =IF($H7="","",$H7) -> 35460 | M7: OK | O7: CHINT2608 | P7: CHINT-NXB63-3P-32A | Q7: MCB_3P | R7: =IF($I7="","",$I7*INDEX(NORM_DK,MATCH($Q7,NORM_AD,0))) -> 54 | S7: =IF($I7="","",$I7*INDEX(FIYAT_MODUL,MATCH($P7,FIYAT_ART,0))) -> 9
A8: 7 | B8: =E8 -> Bakır bara 3х25мм — L1,L2,L3 (faz) | C8: bara | D8: =IF($P8="","",INDEX(FIYAT_KOD,MATCH($P8,FIYAT_ART,0))) -> (hesap - katalog degil) | E8: Bakır bara 3х25мм — L1,L2,L3 (faz) | F8: =IF($P8="","",INDEX(FIYAT_LISTE,MATCH($P8,FIYAT_ART,0))) -> 0 | G8: =IF($P8="","",INDEX(FIYAT_NET,MATCH($P8,FIYAT_ART,0))) -> 4816.185 | H8: =IF(OR($G8="",$I8=""),"",$G8*$I8) -> 9969.503 | I8: =(SC1_GENISLIK_MM/1000-0.1)*3*BARA_FIRE -> 2.07 | J8: м | K8: BAKIR-BARA | L8: =IF($H8="","",$H8) -> 9969.503 | M8: OK | N8: In=250A(QS1), gerekli≥In/derating=294A → 3x25(300A) secildi. L=(0.70-0.10)x3xFIRE(1.15) | O8: metal fiyati (BLOK 8) | P8: BARA-CU-3X25 | Q8: BARA_M | R8: =IF($I8="","",$I8*INDEX(NORM_DK,MATCH($Q8,NORM_AD,0))) -> 93.15 | S8: =IF($I8="","",$I8*INDEX(FIYAT_MODUL,MATCH($P8,FIYAT_ART,0))) -> 0
A9: 8 | B9: =E9 -> Bakır bara 3х25мм — N (notr, ВРУ tam kesit) | C9: bara | D9: =IF($P9="","",INDEX(FIYAT_KOD,MATCH($P9,FIYAT_ART,0))) -> (hesap - katalog degil) | E9: Bakır bara 3х25мм — N (notr, ВРУ tam kesit) | F9: =IF($P9="","",INDEX(FIYAT_LISTE,MATCH($P9,FIYAT_ART,0))) -> 0 | G9: =IF($P9="","",INDEX(FIYAT_NET,MATCH($P9,FIYAT_ART,0))) -> 4816.185 | H9: =IF(OR($G9="",$I9=""),"",$G9*$I9) -> 3323.1676 | I9: =(SC1_GENISLIK_MM/1000-0.1)*BARA_N_ORANI*BARA_FIRE -> 0.69 | J9: м | K9: BAKIR-BARA | L9: =IF($H9="","",$H9) -> 3323.1676 | M9: OK | N9: N=fazin %100'u (ВРУ/harmonik kural), L=(0.70-0.10)x1.00xFIRE | O9: metal fiyati (BLOK 8) | P9: BARA-CU-3X25 | Q9: BARA_M | R9: =IF($I9="","",$I9*INDEX(NORM_DK,MATCH($Q9,NORM_AD,0))) -> 31.05 | S9: =IF($I9="","",$I9*INDEX(FIYAT_MODUL,MATCH($P9,FIYAT_ART,0))) -> 0
A10: 9 | B10: =E10 -> Bakır bara 3х25мм — PE (topraklama, min 3x25) | C10: bara | D10: =IF($P10="","",INDEX(FIYAT_KOD,MATCH($P10,FIYAT_ART,0))) -> (hesap - katalog degil) | E10: Bakır bara 3х25мм — PE (topraklama, min 3x25) | F10: =IF($P10="","",INDEX(FIYAT_LISTE,MATCH($P10,FIYAT_ART,0))) -> 0 | G10: =IF($P10="","",INDEX(FIYAT_NET,MATCH($P10,FIYAT_ART,0))) -> 4816.185 | H10: =IF(OR($G10="",$I10=""),"",$G10*$I10) -> 1661.5838 | I10: =(SC1_GENISLIK_MM/1000-0.1)*BARA_PE_ORANI*BARA_FIRE -> 0.345 | J10: м | K10: BAKIR-BARA | L10: =IF($H10="","",$H10) -> 1661.5838 | M10: OK | N10: PE=fazin %50'si, L=(0.70-0.10)x0.50xFIRE | O10: metal fiyati (BLOK 8) | P10: BARA-CU-3X25 | Q10: BARA_M | R10: =IF($I10="","",$I10*INDEX(NORM_DK,MATCH($Q10,NORM_AD,0))) -> 15.525 | S10: =IF($I10="","",$I10*INDEX(FIYAT_MODUL,MATCH($P10,FIYAT_ART,0))) -> 0
A11: 10 | B11: =E11 -> Bara izolatoru ИШП 3P | C11: izolator | D11: =IF($P11="","",INDEX(FIYAT_KOD,MATCH($P11,FIYAT_ART,0))) -> YIS42-3-200 | E11: Bara izolatoru ИШП 3P | F11: =IF($P11="","",INDEX(FIYAT_LISTE,MATCH($P11,FIYAT_ART,0))) -> 3011 | G11: =IF($P11="","",INDEX(FIYAT_NET,MATCH($P11,FIYAT_ART,0))) -> 3011 | H11: =IF(OR($G11="",$I11=""),"",$G11*$I11) -> 6022 | I11: 2 | J11: шт | K11: EKT | L11: =IF($H11="","",$H11) -> 6022 | M11: OK | O11: EKT-birlesik | P11: EKT-IZOLATOR-YIS42 | Q11: IZOLATOR_BARA | R11: =IF($I11="","",$I11*INDEX(NORM_DK,MATCH($Q11,NORM_AD,0))) -> 12 | S11: =IF($I11="","",$I11*INDEX(FIYAT_MODUL,MATCH($P11,FIYAT_ART,0))) -> 0
A12: 11 | B12: =E12 -> Izoleli notr barasi (N) | C12: bara | D12: =IF($P12="","",INDEX(FIYAT_KOD,MATCH($P12,FIYAT_ART,0))) -> 130200362 | E12: Izoleli notr barasi (N) | F12: =IF($P12="","",INDEX(FIYAT_LISTE,MATCH($P12,FIYAT_ART,0))) -> 903 | G12: =IF($P12="","",INDEX(FIYAT_NET,MATCH($P12,FIYAT_ART,0))) -> 903 | H12: =IF(OR($G12="",$I12=""),"",$G12*$I12) -> 903 | I12: 1 | J12: шт | K12: EKT | L12: =IF($H12="","",$H12) -> 903 | M12: MUADIL | N12: Ozel GZS/PE barasi bulunamadi, izoleli notr-toprak barasi tipi PE icin de kullanildi | O12: EKT-birlesik | P12: EKT-SINASI-N-PE | Q12: CIVATA_TAKIMI | R12: =IF($I12="","",$I12*INDEX(NORM_DK,MATCH($Q12,NORM_AD,0))) -> 3 | S12: =IF($I12="","",$I12*INDEX(FIYAT_MODUL,MATCH($P12,FIYAT_ART,0))) -> 0
A13: 12 | B13: =E13 -> Topraklama barasi (PE / ГЗШ yerine) | C13: bara | D13: =IF($P13="","",INDEX(FIYAT_KOD,MATCH($P13,FIYAT_ART,0))) -> 130200362 | E13: Topraklama barasi (PE / ГЗШ yerine) | F13: =IF($P13="","",INDEX(FIYAT_LISTE,MATCH($P13,FIYAT_ART,0))) -> 903 | G13: =IF($P13="","",INDEX(FIYAT_NET,MATCH($P13,FIYAT_ART,0))) -> 903 | H13: =IF(OR($G13="",$I13=""),"",$G13*$I13) -> 903 | I13: 1 | J13: шт | K13: EKT | L13: =IF($H13="","",$H13) -> 903 | M13: MUADIL | N13: Ozel ГЗШ urunu bulunamadi, N barasi tipi PE icin de kullanildi - MUADIL | O13: EKT-birlesik | P13: EKT-SINASI-N-PE | Q13: CIVATA_TAKIMI | R13: =IF($I13="","",$I13*INDEX(NORM_DK,MATCH($Q13,NORM_AD,0))) -> 3 | S13: =IF($I13="","",$I13*INDEX(FIYAT_MODUL,MATCH($P13,FIYAT_ART,0))) -> 0
A14: 13 | B14: =E14 -> Комплект Болт+Шайба+Гайка M8x30мм | C14: aksesuar | D14: =IF($P14="","",INDEX(FIYAT_KOD,MATCH($P14,FIYAT_ART,0))) -> 3158640 | E14: =IF($P14="","",INDEX(FIYAT_ACK,MATCH($P14,FIYAT_ART,0))) -> Комплект Болт+Шайба+Гайка M8x30мм | F14: =IF($P14="","",INDEX(FIYAT_LISTE,MATCH($P14,FIYAT_ART,0))) -> 557 | G14: =IF($P14="","",INDEX(FIYAT_NET,MATCH($P14,FIYAT_ART,0))) -> 557 | H14: =IF(OR($G14="",$I14=""),"",$G14*$I14) -> 40104 | I14: 72 | J14: шт | K14: EKT | L14: =IF($H14="","",$H14) -> 40104 | M14: OK | N14: 9 baglanti noktasi (1 giris+8 cikis) x 4 iletken(L1,L2,L3,N) x 2 takim = 72 | O14: EKT-birlesik | P14: EKT-BOLT-M8-SET | Q14: CIVATA_TAKIMI | R14: =IF($I14="","",$I14*INDEX(NORM_DK,MATCH($Q14,NORM_AD,0))) -> 216 | S14: =IF($I14="","",$I14*INDEX(FIYAT_MODUL,MATCH($P14,FIYAT_ART,0))) -> 0
A15: 14 | B15: =E15 -> Kablo pabucu — cikis kablolari (25-70мм2, temsili) | C15: pabuc | D15: =IF($P15="","",INDEX(FIYAT_KOD,MATCH($P15,FIYAT_ART,0))) -> 260100132 | E15: Kablo pabucu — cikis kablolari (25-70мм2, temsili) | F15: =IF($P15="","",INDEX(FIYAT_LISTE,MATCH($P15,FIYAT_ART,0))) -> 387 | G15: =IF($P15="","",INDEX(FIYAT_NET,MATCH($P15,FIYAT_ART,0))) -> 387 | H15: =IF(OR($G15="",$I15=""),"",$G15*$I15) -> 12384 | I15: 32 | J15: шт | K15: EKT | L15: =IF($H15="","",$H15) -> 12384 | M15: VARSAYIM | N15: 8 cikis x 4 iletken = 32 uc. Gercek kesitler: 4x50,4x50,4x70,4x25,4x50,4x70,4x50,4x50 mm2 - tek kesit ile temsil edildi, KONTROL | O15: EKT-birlesik | P15: EKT-TMLUG-35 | Q15: PABUC_YUKSUK | R15: =IF($I15="","",$I15*INDEX(NORM_DK,MATCH($Q15,NORM_AD,0))) -> 64 | S15: =IF($I15="","",$I15*INDEX(FIYAT_MODUL,MATCH($P15,FIYAT_ART,0))) -> 0
A16: 15 | B16: =E16 -> Kablo pabucu — giris kablosu (АВБбШв-4х120мм2) | C16: pabuc | D16: =IF($P16="","",INDEX(FIYAT_KOD,MATCH($P16,FIYAT_ART,0))) -> 260100141 | E16: Kablo pabucu — giris kablosu (АВБбШв-4х120мм2) | F16: =IF($P16="","",INDEX(FIYAT_LISTE,MATCH($P16,FIYAT_ART,0))) -> 2299 | G16: =IF($P16="","",INDEX(FIYAT_NET,MATCH($P16,FIYAT_ART,0))) -> 2299 | H16: =IF(OR($G16="",$I16=""),"",$G16*$I16) -> 9196 | I16: 4 | J16: шт | K16: EKT | L16: =IF($H16="","",$H16) -> 9196 | M16: VARSAYIM | N16: 1 giris x 4 iletken = 4 uc | O16: EKT-birlesik | P16: EKT-TMLUG-150 | Q16: PABUC_YUKSUK | R16: =IF($I16="","",$I16*INDEX(NORM_DK,MATCH($Q16,NORM_AD,0))) -> 8 | S16: =IF($I16="","",$I16*INDEX(FIYAT_MODUL,MATCH($P16,FIYAT_ART,0))) -> 0
A17: 16 | B17: =E17 -> Yedek/test klemensi | C17: klemens | D17: =IF($P17="","",INDEX(FIYAT_KOD,MATCH($P17,FIYAT_ART,0))) -> 030300417 | E17: Yedek/test klemensi | F17: =IF($P17="","",INDEX(FIYAT_LISTE,MATCH($P17,FIYAT_ART,0))) -> 113 | G17: =IF($P17="","",INDEX(FIYAT_NET,MATCH($P17,FIYAT_ART,0))) -> 113 | H17: =IF(OR($G17="",$I17=""),"",$G17*$I17) -> 452 | I17: 4 | J17: шт | K17: EKT | L17: =IF($H17="","",$H17) -> 452 | M17: OK | N17: KLEMENS_YEDEK min 4 adet | O17: EKT-birlesik | P17: EKT-KLEMENS-2.5MM | Q17: KLEMENS | R17: =IF($I17="","",$I17*INDEX(NORM_DK,MATCH($Q17,NORM_AD,0))) -> 16 | S17: =IF($I17="","",$I17*INDEX(FIYAT_MODUL,MATCH($P17,FIYAT_ART,0))) -> 0
A18: 21 | B18: =E18 -> Iscilik — montaj+kablaj+test (dk bazli, KURALLAR BLOK3) | C18: монтажная работа | D18: =IF($P18="","",INDEX(FIYAT_KOD,MATCH($P18,FIYAT_ART,0))) -> 0 | E18: Iscilik — montaj+kablaj+test (dk bazli, KURALLAR BLOK3) | F18: =IF($P18="","",INDEX(FIYAT_LISTE,MATCH($P18,FIYAT_ART,0))) -> 0 | G18: =IF($P18="","",INDEX(FIYAT_NET,MATCH($P18,FIYAT_ART,0))) -> 58.333333 | H18: =IF(OR($G18="",$I18=""),"",$G18*$I18) -> 47290.833 | I18: =ROUND((SUM(R3:R17)+INDEX(NORM_DK,MATCH("SABIT_HAZIRLIK",NORM_AD,0))+INDEX(NORM_DK,MATCH("SABIT_TEST",NORM_AD,0))+INDEX(NORM_DK,MATCH("SABIT_AMBALAJ",NORM_AD,0)))*ISCILIK_CARPANI,1) -> 810.7 | J18: dk | K18: ISCILIK | L18: =IF($H18="","",$H18) -> 47290.833 | M18: OK | O18: KURALLAR BLOK3 | P18: ISCILIK-MONTAJ | R18: 0 | S18: =IF($I18="","",$I18*INDEX(FIYAT_MODUL,MATCH($P18,FIYAT_ART,0))) -> 0
A19: 22 | B19: =E19 -> Montaj sarf malzemesi (dk bazli) | C19: монтажный материал | D19: =IF($P19="","",INDEX(FIYAT_KOD,MATCH($P19,FIYAT_ART,0))) -> 0 | E19: Montaj sarf malzemesi (dk bazli) | F19: =IF($P19="","",INDEX(FIYAT_LISTE,MATCH($P19,FIYAT_ART,0))) -> 0 | G19: =IF($P19="","",INDEX(FIYAT_NET,MATCH($P19,FIYAT_ART,0))) -> 50 | H19: =IF(OR($G19="",$I19=""),"",$G19*$I19) -> 40535 | I19: =I18 -> 810.7 | J19: dk | K19: ISCILIK | L19: =IF($H19="","",$H19) -> 40535 | M19: OK | O19: KURALLAR BLOK3 | P19: MONTAJ-SARF-DK | R19: 0 | S19: =IF($I19="","",$I19*INDEX(FIYAT_MODUL,MATCH($P19,FIYAT_ART,0))) -> 0
B20: Toplam ЩС-1 (ВРУ) | H20: =SUBTOTAL(9,H3:H19) -> 364621.09 | L20: =SUBTOTAL(9,L3:L19) -> 364621.09
B22: ЯУО — Ящик управления освещением (наружное освещение), 1 компл | E22: ЯУО — Ящик управления освещением (наружное освещение), 1 компл | I22: 1 | J22: компл | N22: OZET'te 10 komplekt olarak carpilir
A23: 26 | B23: =E23 -> Щит мет. ЩРн-1-2 PR (395x310x220) IP54 (TS) | C23: korpus | D23: 714-15126 | E23: Щит мет. ЩРн-1-2 PR (395x310x220) IP54 (TS) | F23: 15275 | G23: =IF($P23="","",INDEX(FIYAT_NET,MATCH($P23,FIYAT_ART,0))) -> 6840 | H23: =IF(OR($G23="",$I23=""),"",$G23*$I23) -> 6840 | I23: 1 | J23: шт | K23: KAZTEK | L23: =IF($H23="","",$H23) -> 6840 | M23: VARSAYIM | N23: Korpus olcusu semada verilmedi, dogru panel + kapak uzeri cihazlarina gore secildi - KONTROL | O23: KAZTEK2607 | P23: KAZTEK-YAUO-KORPUS | Q23: KORPUS_KUCUK | R23: =IF($I23="","",$I23*INDEX(NORM_DK,MATCH($Q23,NORM_AD,0))) -> 30 | S23: =IF($I23="","",$I23*INDEX(FIYAT_MODUL,MATCH($P23,FIYAT_ART,0))) -> 0
A24: 27 | B24: =E24 -> QF1 — Авт.выкл. 3P 6A C (giris) | C24: oto | D24: =IF($P24="","",INDEX(FIYAT_KOD,MATCH($P24,FIYAT_ART,0))) -> 814168 | E24: QF1 — Авт.выкл. 3P 6A C (giris) | F24: =IF($P24="","",INDEX(FIYAT_LISTE,MATCH($P24,FIYAT_ART,0))) -> 5441 | G24: =IF($P24="","",INDEX(FIYAT_NET,MATCH($P24,FIYAT_ART,0))) -> 3264.6 | H24: =IF(OR($G24="",$I24=""),"",$G24*$I24) -> 3264.6 | I24: 1 | J24: шт | K24: CHINT | L24: =IF($H24="","",$H24) -> 3264.6 | M24: OK | O24: CHINT2608 | P24: CHINT-NXB63-3P-6A | Q24: MCB_3P | R24: =IF($I24="","",$I24*INDEX(NORM_DK,MATCH($Q24,NORM_AD,0))) -> 18 | S24: =IF($I24="","",$I24*INDEX(FIYAT_MODUL,MATCH($P24,FIYAT_ART,0))) -> 3
A25: 28 | B25: =E25 -> QF2 — Авт.выкл. 1P 1A C | C25: oto | D25: =IF($P25="","",INDEX(FIYAT_KOD,MATCH($P25,FIYAT_ART,0))) -> 814008 | E25: QF2 — Авт.выкл. 1P 1A C | F25: =IF($P25="","",INDEX(FIYAT_LISTE,MATCH($P25,FIYAT_ART,0))) -> 1845 | G25: =IF($P25="","",INDEX(FIYAT_NET,MATCH($P25,FIYAT_ART,0))) -> 1107 | H25: =IF(OR($G25="",$I25=""),"",$G25*$I25) -> 1107 | I25: 1 | J25: шт | K25: CHINT | L25: =IF($H25="","",$H25) -> 1107 | M25: CIHAZ_BELIRSIZ | N25: 1A cok dusuk kademe - QF2 kumanda/zaman rolesi devresi korumasi varsayildi, teyit gerekli | O25: CHINT2608 | P25: CHINT-NXB63-1P-1A | Q25: MCB_1P | R25: =IF($I25="","",$I25*INDEX(NORM_DK,MATCH($Q25,NORM_AD,0))) -> 10 | S25: =IF($I25="","",$I25*INDEX(FIYAT_MODUL,MATCH($P25,FIYAT_ART,0))) -> 1
A26: 29 | B26: =E26 -> KM1 — Контактор NXC-09 9A | C26: kontaktor | D26: =IF($P26="","",INDEX(FIYAT_KOD,MATCH($P26,FIYAT_ART,0))) -> 836704 | E26: KM1 — Контактор NXC-09 9A | F26: =IF($P26="","",INDEX(FIYAT_LISTE,MATCH($P26,FIYAT_ART,0))) -> 5214 | G26: =IF($P26="","",INDEX(FIYAT_NET,MATCH($P26,FIYAT_ART,0))) -> 3128.4 | H26: =IF(OR($G26="",$I26=""),"",$G26*$I26) -> 3128.4 | I26: 1 | J26: шт | K26: CHINT | L26: =IF($H26="","",$H26) -> 3128.4 | M26: CIHAZ_BELIRSIZ | N26: Aydinlatma yuku akimi semada verilmemis, en kucuk govde NXC-09 (9A) varsayildi | O26: CHINT2608 | P26: CHINT-NXC09-220V | Q26: KONTAKTOR | R26: =IF($I26="","",$I26*INDEX(NORM_DK,MATCH($Q26,NORM_AD,0))) -> 25 | S26: =IF($I26="","",$I26*INDEX(FIYAT_MODUL,MATCH($P26,FIYAT_ART,0))) -> 3
A27: 30 | B27: =E27 -> KK1 — Тепловое реле NXR-12 4-6A | C27: termik | D27: =IF($P27="","",INDEX(FIYAT_KOD,MATCH($P27,FIYAT_ART,0))) -> 837101 | E27: KK1 — Тепловое реле NXR-12 4-6A | F27: =IF($P27="","",INDEX(FIYAT_LISTE,MATCH($P27,FIYAT_ART,0))) -> 4445 | G27: =IF($P27="","",INDEX(FIYAT_NET,MATCH($P27,FIYAT_ART,0))) -> 2667 | H27: =IF(OR($G27="",$I27=""),"",$G27*$I27) -> 2667 | I27: 1 | J27: шт | K27: CHINT | L27: =IF($H27="","",$H27) -> 2667 | M27: CIHAZ_BELIRSIZ | N27: Yuk akimi belirsiz, orta aralik (4-6A) varsayildi - gercek yuk akimina gore degistirilmeli | O27: CHINT2608 | P27: CHINT-NXR12-4-6A | Q27: TERMIK | R27: =IF($I27="","",$I27*INDEX(NORM_DK,MATCH($Q27,NORM_AD,0))) -> 15 | S27: =IF($I27="","",$I27*INDEX(FIYAT_MODUL,MATCH($P27,FIYAT_ART,0))) -> 0
A28: 31 | B28: =E28 -> SB1 — Кнопка «Стоп» красная 1НЗ | C28: buton | D28: =IF($P28="","",INDEX(FIYAT_KOD,MATCH($P28,FIYAT_ART,0))) -> 574843 | E28: SB1 — Кнопка «Стоп» красная 1НЗ | F28: =IF($P28="","",INDEX(FIYAT_LISTE,MATCH($P28,FIYAT_ART,0))) -> 1621 | G28: =IF($P28="","",INDEX(FIYAT_NET,MATCH($P28,FIYAT_ART,0))) -> 972.6 | H28: =IF(OR($G28="",$I28=""),"",$G28*$I28) -> 972.6 | I28: 1 | J28: шт | K28: CHINT | L28: =IF($H28="","",$H28) -> 972.6 | M28: OK | O28: CHINT2608 | P28: CHINT-NP2-BA42-KIRMIZI | Q28: LAMBA_BUTON | R28: =IF($I28="","",$I28*INDEX(NORM_DK,MATCH($Q28,NORM_AD,0))) -> 8 | S28: =IF($I28="","",$I28*INDEX(FIYAT_MODUL,MATCH($P28,FIYAT_ART,0))) -> 0
A29: 32 | B29: =E29 -> SB2 — Кнопка «Пуск» зеленая 1НЗ+1НО | C29: buton | D29: =IF($P29="","",INDEX(FIYAT_KOD,MATCH($P29,FIYAT_ART,0))) -> 573763 | E29: SB2 — Кнопка «Пуск» зеленая 1НЗ+1НО | F29: =IF($P29="","",INDEX(FIYAT_LISTE,MATCH($P29,FIYAT_ART,0))) -> 1784 | G29: =IF($P29="","",INDEX(FIYAT_NET,MATCH($P29,FIYAT_ART,0))) -> 1070.4 | H29: =IF(OR($G29="",$I29=""),"",$G29*$I29) -> 1070.4 | I29: 1 | J29: шт | K29: CHINT | L29: =IF($H29="","",$H29) -> 1070.4 | M29: OK | O29: CHINT2608 | P29: CHINT-NP2-BA35-YESIL | Q29: LAMBA_BUTON | R29: =IF($I29="","",$I29*INDEX(NORM_DK,MATCH($Q29,NORM_AD,0))) -> 8 | S29: =IF($I29="","",$I29*INDEX(FIYAT_MODUL,MATCH($P29,FIYAT_ART,0))) -> 0
A30: 33 | B30: =E30 -> HLR1 — Лампа сигнальная красная | C30: lamb | D30: =IF($P30="","",INDEX(FIYAT_KOD,MATCH($P30,FIYAT_ART,0))) -> 593075 | E30: HLR1 — Лампа сигнальная красная | F30: =IF($P30="","",INDEX(FIYAT_LISTE,MATCH($P30,FIYAT_ART,0))) -> 571 | G30: =IF($P30="","",INDEX(FIYAT_NET,MATCH($P30,FIYAT_ART,0))) -> 342.6 | H30: =IF(OR($G30="",$I30=""),"",$G30*$I30) -> 342.6 | I30: 1 | J30: шт | K30: CHINT | L30: =IF($H30="","",$H30) -> 342.6 | M30: OK | O30: CHINT2608 | P30: CHINT-ND16-22D-KIRMIZI | Q30: LAMBA_BUTON | R30: =IF($I30="","",$I30*INDEX(NORM_DK,MATCH($Q30,NORM_AD,0))) -> 8 | S30: =IF($I30="","",$I30*INDEX(FIYAT_MODUL,MATCH($P30,FIYAT_ART,0))) -> 0
A31: 34 | B31: =E31 -> SA1 — Переключатель «Местн-0-Дист» 3 полож. | C31: buton | D31: =IF($P31="","",INDEX(FIYAT_KOD,MATCH($P31,FIYAT_ART,0))) -> 574849 | E31: SA1 — Переключатель «Местн-0-Дист» 3 полож. | F31: =IF($P31="","",INDEX(FIYAT_LISTE,MATCH($P31,FIYAT_ART,0))) -> 1836 | G31: =IF($P31="","",INDEX(FIYAT_NET,MATCH($P31,FIYAT_ART,0))) -> 1101.6 | H31: =IF(OR($G31="",$I31=""),"",$G31*$I31) -> 1101.6 | I31: 1 | J31: шт | K31: CHINT | L31: =IF($H31="","",$H31) -> 1101.6 | M31: VARSAYIM | N31: Kontak sayisi (2NO) semadaki tam kumanda mantigina gore teyit edilmeli | O31: CHINT2608 | P31: CHINT-NP2-BD33-3POZ | Q31: LAMBA_BUTON | R31: =IF($I31="","",$I31*INDEX(NORM_DK,MATCH($Q31,NORM_AD,0))) -> 8 | S31: =IF($I31="","",$I31*INDEX(FIYAT_MODUL,MATCH($P31,FIYAT_ART,0))) -> 0
A32: 35 | B32: =E32 -> SA2 — Переключатель «ПР-0-ФР» 3 полож. | C32: buton | D32: =IF($P32="","",INDEX(FIYAT_KOD,MATCH($P32,FIYAT_ART,0))) -> 574849 | E32: SA2 — Переключатель «ПР-0-ФР» 3 полож. | F32: =IF($P32="","",INDEX(FIYAT_LISTE,MATCH($P32,FIYAT_ART,0))) -> 1836 | G32: =IF($P32="","",INDEX(FIYAT_NET,MATCH($P32,FIYAT_ART,0))) -> 1101.6 | H32: =IF(OR($G32="",$I32=""),"",$G32*$I32) -> 1101.6 | I32: 1 | J32: шт | K32: CHINT | L32: =IF($H32="","",$H32) -> 1101.6 | M32: VARSAYIM | N32: Kontak sayisi (2NO) semadaki tam kumanda mantigina gore teyit edilmeli | O32: CHINT2608 | P32: CHINT-NP2-BD33-3POZ | Q32: LAMBA_BUTON | R32: =IF($I32="","",$I32*INDEX(NORM_DK,MATCH($Q32,NORM_AD,0))) -> 8 | S32: =IF($I32="","",$I32*INDEX(FIYAT_MODUL,MATCH($P32,FIYAT_ART,0))) -> 0
A33: 36 | B33: =E33 -> KT1 — Таймер цифровой NKG3 | C33: role | D33: =IF($P33="","",INDEX(FIYAT_KOD,MATCH($P33,FIYAT_ART,0))) -> 310024 | E33: KT1 — Таймер цифровой NKG3 | F33: =IF($P33="","",INDEX(FIYAT_LISTE,MATCH($P33,FIYAT_ART,0))) -> 18847 | G33: =IF($P33="","",INDEX(FIYAT_NET,MATCH($P33,FIYAT_ART,0))) -> 11308.2 | H33: =IF(OR($G33="",$I33=""),"",$G33*$I33) -> 11308.2 | I33: 1 | J33: шт | K33: CHINT | L33: =IF($H33="","",$H33) -> 11308.2 | M33: OK | O33: CHINT2608 | P33: CHINT-NKG3-TIMER | Q33: ZAMAN_ROLESI | R33: =IF($I33="","",$I33*INDEX(NORM_DK,MATCH($Q33,NORM_AD,0))) -> 15 | S33: =IF($I33="","",$I33*INDEX(FIYAT_MODUL,MATCH($P33,FIYAT_ART,0))) -> 4
A34: 37 | B34: =E34 -> FR1+BL1 — Фотореле с выносным фотоэлементом | C34: role | D34: =IF($P34="","",INDEX(FIYAT_KOD,MATCH($P34,FIYAT_ART,0))) -> 130300434 | E34: FR1+BL1 — Фотореле с выносным фотоэлементом | F34: =IF($P34="","",INDEX(FIYAT_LISTE,MATCH($P34,FIYAT_ART,0))) -> 14264 | G34: =IF($P34="","",INDEX(FIYAT_NET,MATCH($P34,FIYAT_ART,0))) -> 14264 | H34: =IF(OR($G34="",$I34=""),"",$G34*$I34) -> 14264 | I34: 1 | J34: шт | K34: EKT | L34: =IF($H34="","",$H34) -> 14264 | M34: MUADIL | N34: FR1 (fotorole) + BL1 (fotodatcik) tek urunde birlesik - CHINT'te esdegeri yok, cift sayim onlemek icin tek satir | O34: EKT-birlesik | P34: EKT-FR7E-FOTORELE | Q34: ROLE | R34: =IF($I34="","",$I34*INDEX(NORM_DK,MATCH($Q34,NORM_AD,0))) -> 12 | S34: =IF($I34="","",$I34*INDEX(FIYAT_MODUL,MATCH($P34,FIYAT_ART,0))) -> 2
A35: 38 | B35: =E35 -> Клемма проходная (0,08-2,5мм 32А) | C35: klemens | D35: =IF($P35="","",INDEX(FIYAT_KOD,MATCH($P35,FIYAT_ART,0))) -> 030300417 | E35: =IF($P35="","",INDEX(FIYAT_ACK,MATCH($P35,FIYAT_ART,0))) -> Клемма проходная (0,08-2,5мм 32А) | F35: =IF($P35="","",INDEX(FIYAT_LISTE,MATCH($P35,FIYAT_ART,0))) -> 113 | G35: =IF($P35="","",INDEX(FIYAT_NET,MATCH($P35,FIYAT_ART,0))) -> 113 | H35: =IF(OR($G35="",$I35=""),"",$G35*$I35) -> 1130 | I35: 10 | J35: шт | K35: EKT | L35: =IF($H35="","",$H35) -> 1130 | M35: OK | N35: Giris(4)+cikis aydinlatma hatti(2)+BL1 uzak sensor(2)+yedek(2)=10, KLEMENS_YEDEK dahil - hesap | O35: EKT-birlesik | P35: EKT-KLEMENS-2.5MM | Q35: KLEMENS | R35: =IF($I35="","",$I35*INDEX(NORM_DK,MATCH($Q35,NORM_AD,0))) -> 40 | S35: =IF($I35="","",$I35*INDEX(FIYAT_MODUL,MATCH($P35,FIYAT_ART,0))) -> 0
A36: 39 | B36: =E36 -> Yuksuk НШВИ 1,5-8 (20 adet, 100'luk paketten) | C36: pabuc | D36: =IF($P36="","",INDEX(FIYAT_KOD,MATCH($P36,FIYAT_ART,0))) -> 311100817 | E36: Yuksuk НШВИ 1,5-8 (20 adet, 100'luk paketten) | F36: =IF($P36="","",INDEX(FIYAT_LISTE,MATCH($P36,FIYAT_ART,0))) -> 428 | G36: =IF($P36="","",INDEX(FIYAT_NET,MATCH($P36,FIYAT_ART,0))) -> 428 | H36: =IF(OR($G36="",$I36=""),"",$G36*$I36) -> 85.6 | I36: 0.2 | J36: пак(100шт) | K36: EKT | L36: =IF($H36="","",$H36) -> 85.6 | M36: VARSAYIM | N36: ~20 uc x 1,5mm2, paketin 0,2'si. Iscilik PABUC_YUKSUK normuna dahil edilmedi (kalem kucuk, genel montaj isciligi icinde) | O36: EKT-birlesik | P36: EKT-NSHVI-1.5-PAKET | R36: 0 | S36: =IF($I36="","",$I36*INDEX(FIYAT_MODUL,MATCH($P36,FIYAT_ART,0))) -> 0
A37: 41 | B37: =E37 -> ПуГВ 1х1,5 kumanda kablosu | C37: kablo | D37: =IF($P37="","",INDEX(FIYAT_KOD,MATCH($P37,FIYAT_ART,0))) -> 0 | E37: =IF($P37="","",INDEX(FIYAT_ACK,MATCH($P37,FIYAT_ART,0))) -> ПуГВ 1х1,5 kumanda kablosu | F37: 45 | G37: =IF($P37="","",INDEX(FIYAT_NET,MATCH($P37,FIYAT_ART,0))) -> 90 | H37: =IF(OR($G37="",$I37=""),"",$G37*$I37) -> 1350 | I37: 15 | J37: м | K37: EKT | L37: =IF($H37="","",$H37) -> 1350 | M37: FIYAT_YOK | N37: Kumanda kablaji temsili metraj (kontaktor-buton-lamba-selektor-timer-fotorole arasi), FIYAT_YOK - kesit kucuk, listede yok | O37: - | P37: EKT-KBL-PUGV-1.5 | Q37: KABLO_IC_M | R37: =IF($I37="","",$I37*INDEX(NORM_DK,MATCH($Q37,NORM_AD,0))) -> 45 | S37: =IF($I37="","",$I37*INDEX(FIYAT_MODUL,MATCH($P37,FIYAT_ART,0))) -> 0
A38: 42 | B38: =E38 -> Montaj sarf malzemesi (vida, dubel, spiral, kablo bagi) | C38: монтажный материал | D38: =IF($P38="","",INDEX(FIYAT_KOD,MATCH($P38,FIYAT_ART,0))) -> 0 | E38: =IF($P38="","",INDEX(FIYAT_ACK,MATCH($P38,FIYAT_ART,0))) -> Montaj sarf malzemesi (vida, dubel, spiral, kablo bagi) | F38: =IF($P38="","",INDEX(FIYAT_LISTE,MATCH($P38,FIYAT_ART,0))) -> 0 | G38: =IF($P38="","",INDEX(FIYAT_NET,MATCH($P38,FIYAT_ART,0))) | H38: =IF(OR($G38="",$I38=""),"",$G38*$I38) | I38: 1 | J38: компл | K38: EKT | L38: =IF($H38="","",$H38) | M38: FIYAT_YOK | N38: Sabit paket fiyati fiyat listesinde yok, atolye sarf ortalamasi girilmeli | O38: - | P38: MONTAJ-MALZEME | R38: 0 | S38: =IF($I38="","",$I38*INDEX(FIYAT_MODUL,MATCH($P38,FIYAT_ART,0))) -> 0
A39: 43 | B39: =E39 -> Iscilik — montaj+kablaj+test (dk bazli) | C39: монтажная работа | D39: =IF($P39="","",INDEX(FIYAT_KOD,MATCH($P39,FIYAT_ART,0))) -> 0 | E39: Iscilik — montaj+kablaj+test (dk bazli) | F39: =IF($P39="","",INDEX(FIYAT_LISTE,MATCH($P39,FIYAT_ART,0))) -> 0 | G39: =IF($P39="","",INDEX(FIYAT_NET,MATCH($P39,FIYAT_ART,0))) -> 58.333333 | H39: =IF(OR($G39="",$I39=""),"",$G39*$I39) -> 5395.8333 | I39: =ROUND((SUM(R23:R38)+INDEX(NORM_DK,MATCH("SABIT_HAZIRLIK",NORM_AD,0))+INDEX(NORM_DK,MATCH("SABIT_TEST",NORM_AD,0))+INDEX(NORM_DK,MATCH("SABIT_AMBALAJ",NORM_AD,0)))*ISCILIK_CARPANI,1)/4 -> 92.5 | J39: dk | K39: ISCILIK | L39: =IF($H39="","",$H39) -> 5395.8333 | M39: OK | O39: KURALLAR BLOK3 | P39: ISCILIK-MONTAJ | R39: 0 | S39: =IF($I39="","",$I39*INDEX(FIYAT_MODUL,MATCH($P39,FIYAT_ART,0))) -> 0
A40: 44 | B40: =E40 -> Montaj sarf malzemesi (dk bazli) | C40: монтажный материал | D40: =IF($P40="","",INDEX(FIYAT_KOD,MATCH($P40,FIYAT_ART,0))) -> 0 | E40: Montaj sarf malzemesi (dk bazli) | F40: =IF($P40="","",INDEX(FIYAT_LISTE,MATCH($P40,FIYAT_ART,0))) -> 0 | G40: =IF($P40="","",INDEX(FIYAT_NET,MATCH($P40,FIYAT_ART,0))) -> 50 | H40: =IF(OR($G40="",$I40=""),"",$G40*$I40) -> 4625 | I40: =I39 -> 92.5 | J40: dk | K40: ISCILIK | L40: =IF($H40="","",$H40) -> 4625 | M40: OK | O40: KURALLAR BLOK3 | P40: MONTAJ-SARF-DK | R40: 0 | S40: =IF($I40="","",$I40*INDEX(FIYAT_MODUL,MATCH($P40,FIYAT_ART,0))) -> 0
B41: Toplam ЯУО (1 компл) | H41: =SUBTOTAL(9,H23:H40) -> 59754.433 | L41: =SUBTOTAL(9,L23:L40) -> 59754.433
...

Sheet OZET
A1: SIRA | B1: PANO | C1: ADET | D1: MALZEME | E1: ISCILIK | F1: BIRIM | G1: TOPLAM | H1: MODUL | I1: KAPASITE | J1: DOLULUK% | K1: YEDEK% | L1: BARA m | M1: BARA kg | N1: BARA TUTARI | O1: FIYAT_YOK | P1: MUADIL | Q1: VARSAYIM
A2: 1 | B2: ЩС-1 (ВРУ) | C2: 1 | D2: =BOM!$L$20-E2 -> 317330.25 | E2: =BOM!$L$18 -> 47290.833 | F2: =D2+E2 -> 364621.09 | G2: =F2*C2 -> 364621.09 | H2: =SUM(BOM!$S$3:$S$17) -> 24 | I2: =INT(SC1_GENISLIK_MM/MODUL_GENISLIK_MM)*INT(SC1_YUKSEKLIK_MM/SIRA_YUKSEKLIK_MM)*KORPUS_KULLANILABILIR_ORAN -> 56 | J2: =IF(I2=0,"",H2/I2) -> 0.42857143 | K2: =IF(I2=0,"",1-J2) -> 0.57142857 | L2: =SUM(BOM!$I$8:$I$10) -> 3.105 | M2: =L2*INDEX(BARA_KGM,MATCH("3X25",BARA_ART,0)) -> 2.0493 | N2: =SUM(BOM!$L$8:$L$10) -> 14954.254 | O2: =COUNTIF(BOM!$M$3:$M$17,"FIYAT_YOK") -> 0 | P2: =COUNTIF(BOM!$M$3:$M$17,"MUADIL")+COUNTIF(BOM!$M$3:$M$17,"MUADIL_ONAY") -> 2 | Q2: =COUNTIF(BOM!$M$3:$M$17,"VARSAYIM")+COUNTIF(BOM!$M$3:$M$17,"CIHAZ_BELIRSIZ") -> 4
A3: 2 | B3: ЯУО (х10) | C3: 10 | D3: =BOM!$L$41-E3 -> 54358.6 | E3: =BOM!$L$39 -> 5395.8333 | F3: =D3+E3 -> 59754.433 | G3: =F3*C3 -> 597544.33 | H3: =SUM(BOM!$S$23:$S$35) -> 13 | I3: =INT(YAUO_GENISLIK_MM/MODUL_GENISLIK_MM)*INT(YAUO_YUKSEKLIK_MM/SIRA_YUKSEKLIK_MM)*KORPUS_KULLANILABILIR_ORAN -> 43.4 | J3: =IF(I3=0,"",H3/I3) -> 0.29953917 | K3: =IF(I3=0,"",1-J3) -> 0.70046083 | O3: =COUNTIF(BOM!$M$23:$M$38,"FIYAT_YOK") -> 2 | P3: =COUNTIF(BOM!$M$23:$M$38,"MUADIL")+COUNTIF(BOM!$M$23:$M$38,"MUADIL_ONAY") -> 1 | Q3: =COUNTIF(BOM!$M$23:$M$38,"VARSAYIM")+COUNTIF(BOM!$M$23:$M$38,"CIHAZ_BELIRSIZ") -> 7
A4: 3 | B4: QF5 montaj (х10) | C4: 10 | D4: =BOM!$L$48-E4 -> 4276.8 | E4: =BOM!$L$46 -> 875 | F4: =D4+E4 -> 5151.8 | G4: =F4*C4 -> 51518 | O4: =COUNTIF(BOM!$M$44:$M$45,"FIYAT_YOK") -> 1 | P4: =COUNTIF(BOM!$M$44:$M$45,"MUADIL")+COUNTIF(BOM!$M$44:$M$45,"MUADIL_ONAY") -> 0 | Q4: =COUNTIF(BOM!$M$44:$M$45,"VARSAYIM")+COUNTIF(BOM!$M$44:$M$45,"CIHAZ_BELIRSIZ") -> 1
B6: GENEL TOPLAM | G6: =SUM(G2:G4) -> 1013683.4 | O6: =SUM(O2:O4) -> 3 | P6: =SUM(P2:P4) -> 3 | Q6: =SUM(Q2:Q4) -> 12
B8: DURUM DAMGASI | C8: =IF(O6>0,"TEKLİFE HAZIR DEĞİL",IF(P6+Q6>0,"ŞARTLI","TEKLİFE HAZIR")) -> TEKLİFE HAZIR DEĞİL
B9: Etkilenen kalem (FIYAT_YOK+MUADIL+VARSAYIM) | C9: =O6+P6+Q6 -> 18

Sheet TEKLIF
A1: KOMMERCHESKOE PREDLOZHENIE / TEKLİF
A2: =IF(COUNTIF(FIYAT!$N:$N,"FIYAT_YOK")>0,"ТЕКЛИФ ЭКСИК — "&COUNTIF(FIYAT!$N:$N,"FIYAT_YOK")&" KALEM FİYATSIZ","") -> ТЕКЛИФ ЭКСИК — 3 KALEM FİYATSIZ
A4: Teklif No | B4: 260914-AKT-RHM-OKEZ-01
A5: Tarih | B5: 2026-09-14
A6: Geçerlilik | B6: =TEKLIF_GECERLILIK&" gün" -> 30 gün
A7: Müşteri | B7: ТОО «Construction NS» (loyiha) / Заказчик
A8: Proje | B8: Строительство ВЛ 0,4кВ месторождения Елемес Северо-Западный — ОК/EZ/04/11/25/2-ЭС
A9: Para birimi | B9: KZT
A11: № | B11: Наименование | C11: Кол-во | D11: Ед.изм | E11: Цена за ед. (KZT) | F11: Сумма (KZT)
A12: 1 | B12: ЩС-1 (ВРУ) — IP31, вводной рубильник 250А, 8 отх. автоматов, медные шины | C12: =OZET!C2 -> 1 | D12: компл | E12: =IF(OZET!F2="","",OZET!F2*(1+KAR_ORANI)) -> 455776.36 | F12: =$E12*$C12 -> 455776.36
A13: 2 | B13: ЯУО — Ящик управления наружным освещением (фотореле+таймер+контактор) | C13: =OZET!C3 -> 10 | D13: компл | E13: =IF(OZET!F3="","",OZET!F3*(1+KAR_ORANI)) -> 74693.042 | F13: =$E13*$C13 -> 746930.42
A14: 3 | B14: Монтаж QF5 10А в существующие щиты скважин (10 шт.) | C14: =OZET!C4 -> 10 | D14: компл | E14: =IF(OZET!F4="","",OZET!F4*(1+KAR_ORANI)) -> 6439.75 | F14: =$E14*$C14 -> 64397.5
B16: Итого | F16: =SUM(F12:F14) -> 1267104.3
B17: Скидка (ISKONTO) | F17: =-F16*ISKONTO -> 0
B18: Итого со скидкой | F18: =F16+F17 -> 1267104.3
B19: НДС (NDS_ORANI) | F19: =F18*NDS_ORANI -> 152052.51
B20: Всего с НДС | F20: =F18+F19 -> 1419156.8
B22: Срок изготовления | F22: =URETIM_SURESI&" iş günü" -> 20 iş günü
B23: Условия оплаты | F23: =ODEME_SARTI -> 50% avans, 50% teslimatta
B24: Гарантия | F24: =GARANTI -> 12 ay
